<mujoco model="morphology">
  <option timestep="0.01"/>
  <default>
    <default class="/"/>
  </default>
  <asset>
    <texture name="texplane" type="2d" builtin="checker" rgb1="0.1 0.2 0.3" rgb2="0.2 0.3 0.4" width="300" height="300"/>
    <material name="MatPlane" class="/" texture="texplane" texrepeat="20 20" specular="1" shininess="1" reflectance="0.5"/>
  </asset>
  <worldbody>
    <light name="//unnamed_light_0" class="/" directional="true" pos="0 0 1.5" dir="0 0 -1.3" cutoff="1e+02" exponent="1" diffuse="1 1 1" specular="0.1 0.1 0.1"/>
    <geom name="ground" class="/" type="plane" size="15 15 0.5" material="MatPlane" rgba="1 1 1 1"/>
    <body name="body" pos="0 0 0.85">
      <geom name="geom0" class="/" type="capsule" contype="1" conaffinity="1" condim="3" size="0.052" rgba="0.72 0.58 0.36 1" friction="0.4 0.1 0.1" fromto="0 0 0 -0.2 0 -0.74"/>
      <body name="body1" pos="-0.12 0 -0.42">
        <geom name="geom1" class="/" type="capsule" contype="1" conaffinity="1" condim="3" size="0.042" rgba="0.27 0.8 0.26 1" friction="0.4 0.1 0.1" fromto="0 0 0 0.2 0 0.052"/>
        <body name="body2" pos="0.12 0 0.032">
          <geom name="geom2" class="/" type="capsule" contype="1" conaffinity="1" condim="3" size="0.067" rgba="0.27 0.38 0.46 1" friction="0.4 0.1 0.1" fromto="0 0 0 0.45 0 -0.32"/>
          <joint name="joint2" class="/" type="hinge" axis="0 1 0" limited="true" stiffness="20" range="-67 67" armature="0.1" damping="2"/>
        </body>
        <body name="body3" pos="0.003 0 0.00079">
          <geom name="geom3" class="/" type="capsule" contype="1" conaffinity="1" condim="3" size="0.059" rgba="0.74 0.2 0.31 1" friction="0.4 0.1 0.1" fromto="0 0 0 -0.17 0 0.11"/>
          <joint name="joint3" class="/" type="hinge" axis="0 1 0" limited="true" stiffness="20" range="-47 47" armature="0.1" damping="2"/>
        </body>
      </body>
      <body name="body4" pos="-0.16 0 -0.58">
        <geom name="geom4" class="/" type="capsule" contype="1" conaffinity="1" condim="3" size="0.043" rgba="0.2 0.67 0.52 1" friction="0.4 0.1 0.1" fromto="0 0 0 0.52 0 -0.18"/>
        <joint name="joint4" class="/" type="hinge" axis="0 1 0" limited="true" stiffness="20" range="-58 58" armature="0.1" damping="2"/>
      </body>
      <joint name="rootx" class="/" type="slide" axis="1 0 0" limited="false" stiffness="0" armature="0" damping="0"/>
      <joint name="rootz" class="/" type="slide" axis="0 0 1" limited="false" stiffness="0" armature="0" damping="0"/>
      <joint name="rooty" class="/" type="hinge" axis="0 1 0" limited="false" stiffness="0" armature="0" damping="0"/>
    </body>
  </worldbody>
  <actuator>
    <motor name="motor2" class="/" ctrllimited="true" ctrlrange="-1 1" gear="1.4e+02" joint="joint2"/>
    <motor name="motor3" class="/" ctrllimited="true" ctrlrange="-1 1" gear="1.6e+02" joint="joint3"/>
    <motor name="motor4" class="/" ctrllimited="true" ctrlrange="-1 1" gear="1.8e+02" joint="joint4"/>
  </actuator>
  <sensor>
    <subtreelinvel name="velocity" body="body"/>
  </sensor>
</mujoco>
