<mujoco model="morphology">
  <option timestep="0.01"/>
  <default>
    <default class="/"/>
  </default>
  <asset>
    <texture name="texplane" type="2d" builtin="checker" rgb1="0.1 0.2 0.3" rgb2="0.2 0.3 0.4" width="300" height="300"/>
    <material name="MatPlane" class="/" texture="texplane" texrepeat="20 20" specular="1" shininess="1" reflectance="0.5"/>
  </asset>
  <worldbody>
    <light name="//unnamed_light_0" class="/" directional="true" pos="0 0 1.5" dir="0 0 -1.3" cutoff="1e+02" exponent="1" diffuse="1 1 1" specular="0.1 0.1 0.1"/>
    <geom name="ground" class="/" type="plane" size="15 15 0.5" material="MatPlane" rgba="1 1 1 1"/>
    <body name="body" pos="0 0 0.74">
      <geom name="geom0" class="/" type="capsule" contype="1" conaffinity="1" condim="3" size="0.049" rgba="0.35 0.52 0.88 1" friction="0.4 0.1 0.1" fromto="0 0 0 0.21 0 -0.64"/>
      <body name="body1" pos="0.091 0 -0.27">
        <geom name="geom1" class="/" type="capsule" contype="1" conaffinity="1" condim="3" size="0.051" rgba="0.42 0.74 0.88 1" friction="0.4 0.1 0.1" fromto="0 0 0 0.64 0 -0.085"/>
        <joint name="joint1" class="/" type="hinge" axis="0 1 0" limited="true" stiffness="20" range="-42 42" armature="0.1" damping="2"/>
      </body>
      <body name="body2" pos="0.0099 0 -0.03">
        <geom name="geom2" class="/" type="capsule" contype="1" conaffinity="1" condim="3" size="0.059" rgba="0.1 0.49 0.74 1" friction="0.4 0.1 0.1" fromto="0 0 0 -0.38 0 -0.27"/>
        <joint name="joint2" class="/" type="hinge" axis="0 1 0" limited="true" stiffness="20" range="-38 38" armature="0.1" damping="2"/>
      </body>
      <body name="body3" pos="0.015 0 -0.046">
        <geom name="geom3" class="/" type="capsule" contype="1" conaffinity="1" condim="3" size="0.07" rgba="0.65 0.21 0.8 1" friction="0.4 0.1 0.1" fromto="0 0 0 0.71 0 0.64"/>
        <body name="body4" pos="0.48 0 0.43">
          <geom name="geom4" class="/" type="capsule" contype="1" conaffinity="1" condim="3" size="0.062" rgba="0.69 0.52 0.98 1" friction="0.4 0.1 0.1" fromto="0 0 0 -0.13 0 0.46"/>
          <joint name="joint4" class="/" type="hinge" axis="0 1 0" limited="true" stiffness="20" range="-35 35" armature="0.1" damping="2"/>
        </body>
        <joint name="joint3" class="/" type="hinge" axis="0 1 0" limited="true" stiffness="20" range="-46 46" armature="0.1" damping="2"/>
      </body>
      <joint name="rootx" class="/" type="slide" axis="1 0 0" limited="false" stiffness="0" armature="0" damping="0"/>
      <joint name="rootz" class="/" type="slide" axis="0 0 1" limited="false" stiffness="0" armature="0" damping="0"/>
      <joint name="rooty" class="/" type="hinge" axis="0 1 0" limited="false" stiffness="0" armature="0" damping="0"/>
    </body>
  </worldbody>
  <actuator>
    <motor name="motor1" class="/" ctrllimited="true" ctrlrange="-1 1" gear="1.2e+02" joint="joint1"/>
    <motor name="motor2" class="/" ctrllimited="true" ctrlrange="-1 1" gear="2e+02" joint="joint2"/>
    <motor name="motor4" class="/" ctrllimited="true" ctrlrange="-1 1" gear="1.9e+02" joint="joint4"/>
    <motor name="motor3" class="/" ctrllimited="true" ctrlrange="-1 1" gear="1.4e+02" joint="joint3"/>
  </actuator>
  <sensor>
    <subtreelinvel name="velocity" body="body"/>
  </sensor>
</mujoco>
