<mujoco model="morphology">
  <option timestep="0.01"/>
  <default>
    <default class="/"/>
  </default>
  <asset>
    <texture name="texplane" type="2d" builtin="checker" rgb1="0.1 0.2 0.3" rgb2="0.2 0.3 0.4" width="300" height="300"/>
    <material name="MatPlane" class="/" texture="texplane" texrepeat="20 20" specular="1" shininess="1" reflectance="0.5"/>
  </asset>
  <worldbody>
    <light name="//unnamed_light_0" class="/" directional="true" pos="0 0 1.5" dir="0 0 -1.3" cutoff="1e+02" exponent="1" diffuse="1 1 1" specular="0.1 0.1 0.1"/>
    <geom name="ground" class="/" type="plane" size="15 15 0.5" material="MatPlane" rgba="1 1 1 1"/>
    <body name="body" pos="0 0 0.31">
      <geom name="geom0" class="/" type="capsule" contype="1" conaffinity="1" condim="3" size="0.065" rgba="0.93 0.17 0.019 1" friction="0.4 0.1 0.1" fromto="0 0 0 -0.69 0 -0.21"/>
      <body name="body1" pos="-0.063 0 -0.019">
        <geom name="geom1" class="/" type="capsule" contype="1" conaffinity="1" condim="3" size="0.052" rgba="0.087 0.63 0.55 1" friction="0.4 0.1 0.1" fromto="0 0 0 -0.54 0 0.7"/>
        <body name="body2" pos="-0.43 0 0.56">
          <geom name="geom2" class="/" type="capsule" contype="1" conaffinity="1" condim="3" size="0.065" rgba="0.2 0.7 0.23 1" friction="0.4 0.1 0.1" fromto="0 0 0 0.11 0 0.3"/>
          <body name="body3" pos="0.097 0 0.26">
            <geom name="geom3" class="/" type="capsule" contype="1" conaffinity="1" condim="3" size="0.053" rgba="0.019 0.44 0.54 1" friction="0.4 0.1 0.1" fromto="0 0 0 0.34 0 -0.37"/>
            <body name="body4" pos="0.0062 0 -0.0069">
              <geom name="geom4" class="/" type="capsule" contype="1" conaffinity="1" condim="3" size="0.056" rgba="0.84 0.82 0.25 1" friction="0.4 0.1 0.1" fromto="0 0 0 -0.53 0 -0.083"/>
            </body>
            <joint name="joint3" class="/" type="hinge" axis="0 1 0" limited="true" stiffness="20" range="-55 55" armature="0.1" damping="2"/>
          </body>
          <joint name="joint2" class="/" type="hinge" axis="0 1 0" limited="true" stiffness="20" range="-42 42" armature="0.1" damping="2"/>
        </body>
        <joint name="joint1" class="/" type="hinge" axis="0 1 0" limited="true" stiffness="20" range="-38 38" armature="0.1" damping="2"/>
      </body>
      <joint name="rootx" class="/" type="slide" axis="1 0 0" limited="false" stiffness="0" armature="0" damping="0"/>
      <joint name="rootz" class="/" type="slide" axis="0 0 1" limited="false" stiffness="0" armature="0" damping="0"/>
      <joint name="rooty" class="/" type="hinge" axis="0 1 0" limited="false" stiffness="0" armature="0" damping="0"/>
    </body>
  </worldbody>
  <actuator>
    <motor name="motor3" class="/" ctrllimited="true" ctrlrange="-1 1" gear="1.1e+02" joint="joint3"/>
    <motor name="motor2" class="/" ctrllimited="true" ctrlrange="-1 1" gear="1.2e+02" joint="joint2"/>
    <motor name="motor1" class="/" ctrllimited="true" ctrlrange="-1 1" gear="1.2e+02" joint="joint1"/>
  </actuator>
  <sensor>
    <subtreelinvel name="velocity" body="body"/>
  </sensor>
</mujoco>
