<mujoco model="morphology">
  <default>
    <default class="/"/>
  </default>
  <asset>
    <texture name="texplane" type="2d" builtin="checker" rgb1="0.1 0.2 0.3" rgb2="0.2 0.3 0.4" width="300" height="300"/>
    <material name="MatPlane" class="/" texture="texplane" texrepeat="20 20"/>
  </asset>
  <worldbody>
    <light name="//unnamed_light_0" class="/" directional="true" pos="0 0 1.5" dir="0 0 -1.3" cutoff="1e+02" exponent="1" diffuse="1 1 1" specular="0.1 0.1 0.1"/>
    <geom name="ground" class="/" type="plane" size="15 15 0.5" material="MatPlane" rgba="1 1 1 1"/>
    <body name="root" pos="0 0 0.05">
      <geom name="//unnamed_geom_1" class="/" type="capsule" size="0.05" rgba="0.6 0.6 0.6 1" fromto="0 0 0 1 0 0"/>
      <joint name="rootx" class="/" type="slide" axis="1 0 0" limited="false" stiffness="0" armature="0" damping="0"/>
      <joint name="rootz" class="/" type="slide" axis="0 0 1" limited="false" stiffness="0" armature="0" damping="0"/>
      <joint name="rooty" class="/" type="hinge" axis="0 1 0" limited="false" stiffness="0" armature="0" damping="0"/>
      <body name="//unnamed_body_1" pos="1 0 0">
        <joint name="joint1" class="/" type="hinge" pos="0 0 0" axis="0 1 0" limited="true" range="-40 40"/>
        <geom name="//unnamed_geom_2" class="/" type="capsule" size="0.05" rgba="0.4 0.6 0.7 1" fromto="0 0 0 1 0 0"/>
      </body>
    </body>
  </worldbody>
  <actuator>
    <motor name="//unnamed_actuator_0" class="/" ctrllimited="true" ctrlrange="-1 1" gear="2e+02" joint="joint1"/>
  </actuator>
</mujoco>
