<mujoco model="morphology">
  <default>
    <default class="/"/>
  </default>
  <asset>
    <texture name="texplane" type="2d" builtin="checker" rgb1="0.1 0.2 0.3" rgb2="0.2 0.3 0.4" width="300" height="300"/>
    <material name="MatPlane" class="/" texture="texplane" texrepeat="20 20" specular="1" shininess="1" reflectance="0.5"/>
  </asset>
  <worldbody>
    <light name="//unnamed_light_0" class="/" directional="true" pos="0 0 1.5" dir="0 0 -1.3" cutoff="1e+02" exponent="1" diffuse="1 1 1" specular="0.1 0.1 0.1"/>
    <geom name="ground" class="/" type="plane" size="15 15 0.5" material="MatPlane" rgba="1 1 1 1"/>
    <body name="body" pos="0 0 0.23">
      <geom name="geom0" class="/" type="capsule" size="0.049" rgba="0.78 0.86 0.76 1" fromto="0 0 0 0.026 0 0.44"/>
      <body name="body1" pos="0.0056 0 0.094">
        <geom name="geom1" class="/" type="capsule" size="0.047" rgba="0.78 0.083 0.93 1" fromto="0 0 0 0.37 0 -0.052"/>
      </body>
      <body name="body2" pos="0.024 0 0.4">
        <geom name="geom2" class="/" type="capsule" size="0.065" rgba="0.15 0.97 0.4 1" fromto="0 0 0 -0.55 0 0.2"/>
        <body name="body3" pos="-0.27 0 0.1">
          <geom name="geom3" class="/" type="capsule" size="0.043" rgba="0.51 0.39 0.5 1" fromto="0 0 0 0.59 0 0.74"/>
          <body name="body4" pos="0.35 0 0.44">
            <geom name="geom4" class="/" type="capsule" size="0.054" rgba="0.74 0.095 0.34 1" fromto="0 0 0 -0.42 0 0.12"/>
            <joint name="joint4" class="/" type="hinge" axis="0 1 0" limited="true" range="-68 68" armature="0.2"/>
          </body>
          <joint name="joint3" class="/" type="hinge" axis="0 1 0" limited="true" range="-55 55" armature="0.2"/>
        </body>
        <body name="body5" pos="-0.41 0 0.15">
          <geom name="geom5" class="/" type="capsule" size="0.045" rgba="0.051 0.56 0.056 1" fromto="0 0 0 0.15 0 -0.68"/>
          <body name="body6" pos="0.064 0 -0.29">
            <geom name="geom6" class="/" type="capsule" size="0.043" rgba="0.65 0.11 0.84 1" fromto="0 0 0 -0.3 0 -0.35"/>
            <body name="body7" pos="-0.25 0 -0.29">
              <geom name="geom7" class="/" type="capsule" size="0.053" rgba="0.93 0.88 0.92 1" fromto="0 0 0 -0.57 0 0.67"/>
              <body name="body8" pos="-0.18 0 0.21">
                <geom name="geom8" class="/" type="capsule" size="0.057" rgba="0.5 0.49 0.91 1" fromto="0 0 0 -0.25 0 -0.1"/>
                <joint name="joint8" class="/" type="hinge" axis="0 1 0" limited="true" range="-44 44" armature="0.2"/>
              </body>
              <body name="body9" pos="-0.52 0 0.6">
                <geom name="geom9" class="/" type="capsule" size="0.055" rgba="0.71 0.9 0.76 1" fromto="0 0 0 -0.43 0 -0.17"/>
                <body name="body10" pos="-0.13 0 -0.05">
                  <geom name="geom10" class="/" type="capsule" size="0.07" rgba="0.38 0.2 0.65 1" fromto="0 0 0 -0.16 0 0.7"/>
                  <joint name="joint10" class="/" type="hinge" axis="0 1 0" limited="true" range="-32 32" armature="0.2"/>
                </body>
                <joint name="joint9" class="/" type="hinge" axis="0 1 0" limited="true" range="-67 67" armature="0.2"/>
              </body>
            </body>
          </body>
          <joint name="joint5" class="/" type="hinge" axis="0 1 0" limited="true" range="-54 54" armature="0.2"/>
        </body>
        <joint name="joint2" class="/" type="hinge" axis="0 1 0" limited="true" range="-55 55" armature="0.2"/>
      </body>
      <joint name="rootx" class="/" type="slide" axis="1 0 0" limited="false" stiffness="0" armature="0" damping="0"/>
      <joint name="rootz" class="/" type="slide" axis="0 0 1" limited="false" stiffness="0" armature="0" damping="0"/>
      <joint name="rooty" class="/" type="hinge" axis="0 1 0" limited="false" stiffness="0" armature="0" damping="0"/>
    </body>
  </worldbody>
  <actuator>
    <motor name="motor4" class="/" ctrllimited="true" ctrlrange="-1 1" gear="1.6e+02" joint="joint4"/>
    <motor name="motor3" class="/" ctrllimited="true" ctrlrange="-1 1" gear="1.1e+02" joint="joint3"/>
    <motor name="motor8" class="/" ctrllimited="true" ctrlrange="-1 1" gear="1.1e+02" joint="joint8"/>
    <motor name="motor10" class="/" ctrllimited="true" ctrlrange="-1 1" gear="1.4e+02" joint="joint10"/>
    <motor name="motor9" class="/" ctrllimited="true" ctrlrange="-1 1" gear="1.3e+02" joint="joint9"/>
    <motor name="motor5" class="/" ctrllimited="true" ctrlrange="-1 1" gear="2e+02" joint="joint5"/>
    <motor name="motor2" class="/" ctrllimited="true" ctrlrange="-1 1" gear="1.2e+02" joint="joint2"/>
  </actuator>
  <sensor>
    <subtreelinvel name="velocity" body="body"/>
  </sensor>
</mujoco>
