<mujoco model="morphology">
  <default>
    <default class="/"/>
  </default>
  <asset>
    <texture name="texplane" type="2d" builtin="checker" rgb1="0.1 0.2 0.3" rgb2="0.2 0.3 0.4" width="300" height="300"/>
    <material name="MatPlane" class="/" texture="texplane" texrepeat="20 20" specular="1" shininess="1" reflectance="0.5"/>
  </asset>
  <worldbody>
    <light name="//unnamed_light_0" class="/" directional="true" pos="0 0 1.5" dir="0 0 -1.3" cutoff="1e+02" exponent="1" diffuse="1 1 1" specular="0.1 0.1 0.1"/>
    <geom name="ground" class="/" type="plane" size="15 15 0.5" material="MatPlane" rgba="1 1 1 1"/>
    <body name="body" pos="0 0 0.58">
      <geom name="geom0" class="/" type="capsule" size="0.065 0.23" rgba="0.15 0.33 0.37 1" pos="0.01 0 -0.23" zaxis="0.021 0 -0.45"/>
      <body name="body1" pos="0.015 0 -0.32">
        <geom name="geom1" class="/" type="capsule" size="0.066 0.29" rgba="0.39 0.62 0.49 1" pos="-0.25 0 0.15" zaxis="-0.5 0 0.3"/>
        <joint name="joint1" class="/" type="hinge" axis="0 1 0" limited="true" range="-30 30"/>
      </body>
      <body name="body2" pos="0.0092 0 -0.2">
        <geom name="geom2" class="/" type="capsule" size="0.057 0.25" rgba="0.12 0.37 0.58 1" pos="0.21 0 -0.14" zaxis="0.42 0 -0.28"/>
        <body name="body3" pos="0.13 0 -0.089">
          <geom name="geom3" class="/" type="capsule" size="0.042 0.47" rgba="0.96 0.75 0.75 1" pos="0.3 0 0.36" zaxis="0.6 0 0.72"/>
          <body name="body4" pos="0.35 0 0.42">
            <geom name="geom4" class="/" type="capsule" size="0.041 0.078" rgba="0.5 0.85 0.57 1" pos="-0.045 0 0.064" zaxis="-0.089 0 0.13"/>
            <body name="body5" pos="-0.082 0 0.12">
              <geom name="geom5" class="/" type="capsule" size="0.052 0.37" rgba="0.65 0.19 0.99 1" pos="-0.35 0 0.11" zaxis="-0.71 0 0.23"/>
              <joint name="joint5" class="/" type="hinge" axis="0 1 0" limited="true" range="-39 39"/>
            </body>
            <body name="body6" pos="-0.021 0 0.029">
              <geom name="geom6" class="/" type="capsule" size="0.048 0.22" rgba="0.79 0.45 0.97 1" pos="0.078 0 0.2" zaxis="0.16 0 0.4"/>
              <body name="body7" pos="0.12 0 0.31">
                <geom name="geom7" class="/" type="capsule" size="0.059 0.13" rgba="0.53 0.77 0.55 1" pos="-0.089 0 0.089" zaxis="-0.18 0 0.18"/>
                <body name="body8" pos="-0.059 0 0.058">
                  <geom name="geom8" class="/" type="capsule" size="0.061 0.2" rgba="0.91 0.75 0.77 1" pos="-0.19 0 -0.041" zaxis="-0.38 0 -0.081"/>
                </body>
                <body name="body9" pos="-0.077 0 0.076">
                  <geom name="geom9" class="/" type="capsule" size="0.058 0.24" rgba="0.45 0.13 0.02 1" pos="0.17 0 0.17" zaxis="0.34 0 0.33"/>
                  <body name="body10" pos="0.29 0 0.28">
                    <geom name="geom10" class="/" type="capsule" size="0.047 0.34" rgba="0.36 0.69 0.28 1" pos="0.19 0 -0.28" zaxis="0.39 0 -0.57"/>
                  </body>
                  <joint name="joint9" class="/" type="hinge" axis="0 1 0" limited="true" range="-51 51"/>
                </body>
                <joint name="joint7" class="/" type="hinge" axis="0 1 0" limited="true" range="-46 46"/>
              </body>
            </body>
            <joint name="joint4" class="/" type="hinge" axis="0 1 0" limited="true" range="-54 54"/>
          </body>
          <joint name="joint3" class="/" type="hinge" axis="0 1 0" limited="true" range="-54 54"/>
        </body>
        <joint name="joint2" class="/" type="hinge" axis="0 1 0" limited="true" range="-65 65"/>
      </body>
      <joint name="rootx" class="/" type="slide" axis="1 0 0" limited="false" stiffness="0" armature="0" damping="0"/>
      <joint name="rootz" class="/" type="slide" axis="0 0 1" limited="false" stiffness="0" armature="0" damping="0"/>
      <joint name="rooty" class="/" type="hinge" axis="0 1 0" limited="false" stiffness="0" armature="0" damping="0"/>
    </body>
  </worldbody>
  <actuator>
    <motor name="motor1" class="/" ctrllimited="true" ctrlrange="-1 1" gear="1.1e+02" joint="joint1"/>
    <motor name="motor5" class="/" ctrllimited="true" ctrlrange="-1 1" gear="1.2e+02" joint="joint5"/>
    <motor name="motor9" class="/" ctrllimited="true" ctrlrange="-1 1" gear="1.4e+02" joint="joint9"/>
    <motor name="motor7" class="/" ctrllimited="true" ctrlrange="-1 1" gear="1.4e+02" joint="joint7"/>
    <motor name="motor4" class="/" ctrllimited="true" ctrlrange="-1 1" gear="1.5e+02" joint="joint4"/>
    <motor name="motor3" class="/" ctrllimited="true" ctrlrange="-1 1" gear="1.6e+02" joint="joint3"/>
    <motor name="motor2" class="/" ctrllimited="true" ctrlrange="-1 1" gear="2e+02" joint="joint2"/>
  </actuator>
  <sensor>
    <subtreelinvel name="velocity" body="body"/>
  </sensor>
</mujoco>
