<mujoco model="morphology">
  <default>
    <default class="/"/>
  </default>
  <asset>
    <texture name="texplane" type="2d" builtin="checker" rgb1="0.1 0.2 0.3" rgb2="0.2 0.3 0.4" width="300" height="300"/>
    <material name="MatPlane" class="/" texture="texplane" texrepeat="20 20" specular="1" shininess="1" reflectance="0.5"/>
  </asset>
  <worldbody>
    <light name="//unnamed_light_0" class="/" directional="true" pos="0 0 1.5" dir="0 0 -1.3" cutoff="1e+02" exponent="1" diffuse="1 1 1" specular="0.1 0.1 0.1"/>
    <geom name="ground" class="/" type="plane" size="15 15 0.5" material="MatPlane" rgba="1 1 1 1"/>
    <body name="body" pos="0 0 1.5">
      <geom name="geom0" class="/" type="capsule" size="0.066 0.15" rgba="0.67 0.006 0.7 1" pos="0.14 0 0.058" zaxis="0.28 0 0.12"/>
      <body name="body1" pos="0.0021 0 0.0009">
        <geom name="geom1" class="/" type="capsule" size="0.046 0.14" rgba="0.13 0.48 0.27 1" pos="0.018 0 -0.14" zaxis="0.037 0 -0.28"/>
        <body name="body2" pos="0.032 0 -0.24">
          <geom name="geom2" class="/" type="capsule" size="0.062 0.38" rgba="0.26 0.91 0.87 1" pos="0.32 0 -0.19" zaxis="0.65 0 -0.38"/>
          <body name="body3" pos="0.62 0 -0.36">
            <geom name="geom3" class="/" type="capsule" size="0.043 0.37" rgba="0.73 0.55 0.96 1" pos="-0.16 0 -0.33" zaxis="-0.33 0 -0.67"/>
            <joint name="joint3" class="/" type="hinge" axis="0 1 0" limited="true" range="-50 50"/>
          </body>
          <body name="body4" pos="0.37 0 -0.22">
            <geom name="geom4" class="/" type="capsule" size="0.044 0.34" rgba="0.71 0.9 0.67 1" pos="-0.32 0 -0.12" zaxis="-0.64 0 -0.24"/>
            <body name="body5" pos="-0.35 0 -0.13">
              <geom name="geom5" class="/" type="capsule" size="0.069 0.08" rgba="0.77 0.65 0.22 1" pos="0.07 0 -0.038" zaxis="0.14 0 -0.077"/>
            </body>
            <body name="body6" pos="-0.51 0 -0.19">
              <geom name="geom6" class="/" type="capsule" size="0.061 0.12" rgba="0.36 0.69 0.98 1" pos="0.089 0 -0.074" zaxis="0.18 0 -0.15"/>
              <body name="body7" pos="0.028 0 -0.024">
                <geom name="geom7" class="/" type="capsule" size="0.056 0.41" rgba="0.28 0.81 0.95 1" pos="-0.22 0 -0.35" zaxis="-0.44 0 -0.7"/>
              </body>
              <body name="body8" pos="0.17 0 -0.14">
                <geom name="geom8" class="/" type="capsule" size="0.051 0.16" rgba="0.44 0.75 0.0044 1" pos="0.15 0 0.07" zaxis="0.3 0 0.14"/>
                <body name="body9" pos="0.077 0 0.037">
                  <geom name="geom9" class="/" type="capsule" size="0.061 0.19" rgba="0.59 0.65 0.25 1" pos="0.019 0 -0.19" zaxis="0.039 0 -0.37"/>
                </body>
                <joint name="joint8" class="/" type="hinge" axis="0 1 0" limited="true" range="-45 45"/>
              </body>
              <joint name="joint6" class="/" type="hinge" axis="0 1 0" limited="true" range="-33 33"/>
            </body>
            <joint name="joint4" class="/" type="hinge" axis="0 1 0" limited="true" range="-58 58"/>
          </body>
          <joint name="joint2" class="/" type="hinge" axis="0 1 0" limited="true" range="-47 47"/>
        </body>
      </body>
      <body name="body10" pos="0.2 0 0.083">
        <geom name="geom10" class="/" type="capsule" size="0.046 0.29" rgba="0.38 0.66 0.79 1" pos="0.093 0 0.27" zaxis="0.19 0 0.55"/>
        <joint name="joint10" class="/" type="hinge" axis="0 1 0" limited="true" range="-66 66"/>
      </body>
      <joint name="rootx" class="/" type="slide" axis="1 0 0" limited="false" stiffness="0" armature="0" damping="0"/>
      <joint name="rootz" class="/" type="slide" axis="0 0 1" limited="false" stiffness="0" armature="0" damping="0"/>
      <joint name="rooty" class="/" type="hinge" axis="0 1 0" limited="false" stiffness="0" armature="0" damping="0"/>
    </body>
  </worldbody>
  <actuator>
    <motor name="motor3" class="/" ctrllimited="true" ctrlrange="-1 1" gear="1.2e+02" joint="joint3"/>
    <motor name="motor8" class="/" ctrllimited="true" ctrlrange="-1 1" gear="1.8e+02" joint="joint8"/>
    <motor name="motor6" class="/" ctrllimited="true" ctrlrange="-1 1" gear="1.3e+02" joint="joint6"/>
    <motor name="motor4" class="/" ctrllimited="true" ctrlrange="-1 1" gear="1.2e+02" joint="joint4"/>
    <motor name="motor2" class="/" ctrllimited="true" ctrlrange="-1 1" gear="1.7e+02" joint="joint2"/>
    <motor name="motor10" class="/" ctrllimited="true" ctrlrange="-1 1" gear="1e+02" joint="joint10"/>
  </actuator>
  <sensor>
    <subtreelinvel name="velocity" body="body"/>
  </sensor>
</mujoco>
