<mujoco model="morphology">
  <default>
    <default class="/"/>
  </default>
  <asset>
    <texture name="texplane" type="2d" builtin="checker" rgb1="0.1 0.2 0.3" rgb2="0.2 0.3 0.4" width="300" height="300"/>
    <material name="MatPlane" class="/" texture="texplane" texrepeat="20 20" specular="1" shininess="1" reflectance="0.5"/>
  </asset>
  <worldbody>
    <light name="//unnamed_light_0" class="/" directional="true" pos="0 0 1.5" dir="0 0 -1.3" cutoff="1e+02" exponent="1" diffuse="1 1 1" specular="0.1 0.1 0.1"/>
    <geom name="ground" class="/" type="plane" size="15 15 0.5" material="MatPlane" rgba="1 1 1 1"/>
    <body name="body" pos="0 0 0.11">
      <geom name="geom0" class="/" type="capsule" size="0.054" rgba="0.62 0.078 0.82 1" fromto="0 0 0 -0.18 0 0.59"/>
      <body name="body1" pos="-0.047 0 0.15">
        <geom name="geom1" class="/" type="capsule" size="0.052" rgba="0.19 0.01 0.37 1" fromto="0 0 0 -0.18 0 -0.16"/>
        <joint name="joint1" class="/" type="hinge" axis="0 1 0" limited="true" range="-42 42" armature="0.2"/>
      </body>
      <body name="body2" pos="-0.012 0 0.039">
        <geom name="geom2" class="/" type="capsule" size="0.046" rgba="0.14 0.85 0.041 1" fromto="0 0 0 0.31 0 0.071"/>
        <body name="body3" pos="0.095 0 0.022">
          <geom name="geom3" class="/" type="capsule" size="0.043" rgba="0.81 0.09 0.76 1" fromto="0 0 0 0.11 0 0.61"/>
          <body name="body4" pos="0.041 0 0.23">
            <geom name="geom4" class="/" type="capsule" size="0.062" rgba="0.66 0.7 0.15 1" fromto="0 0 0 0.52 0 0.16"/>
            <joint name="joint4" class="/" type="hinge" axis="0 1 0" limited="true" range="-67 67" armature="0.2"/>
          </body>
          <joint name="joint3" class="/" type="hinge" axis="0 1 0" limited="true" range="-35 35" armature="0.2"/>
        </body>
        <joint name="joint2" class="/" type="hinge" axis="0 1 0" limited="true" range="-54 54" armature="0.2"/>
      </body>
      <joint name="rootx" class="/" type="slide" axis="1 0 0" limited="false" stiffness="0" armature="0" damping="0"/>
      <joint name="rootz" class="/" type="slide" axis="0 0 1" limited="false" stiffness="0" armature="0" damping="0"/>
      <joint name="rooty" class="/" type="hinge" axis="0 1 0" limited="false" stiffness="0" armature="0" damping="0"/>
    </body>
  </worldbody>
  <actuator>
    <motor name="motor1" class="/" ctrllimited="true" ctrlrange="-1 1" gear="1.7e+02" joint="joint1"/>
    <motor name="motor4" class="/" ctrllimited="true" ctrlrange="-1 1" gear="1.8e+02" joint="joint4"/>
    <motor name="motor3" class="/" ctrllimited="true" ctrlrange="-1 1" gear="1.9e+02" joint="joint3"/>
    <motor name="motor2" class="/" ctrllimited="true" ctrlrange="-1 1" gear="1.5e+02" joint="joint2"/>
  </actuator>
  <sensor>
    <subtreelinvel name="velocity" body="body"/>
  </sensor>
</mujoco>
