<mujoco model="morphology">
  <option timestep="0.01"/>
  <default>
    <default class="/"/>
  </default>
  <asset>
    <texture name="texplane" type="2d" builtin="checker" rgb1="0.1 0.2 0.3" rgb2="0.2 0.3 0.4" width="300" height="300"/>
    <material name="MatPlane" class="/" texture="texplane" texrepeat="20 20" specular="1" shininess="1" reflectance="0.5"/>
  </asset>
  <worldbody>
    <light name="//unnamed_light_0" class="/" directional="true" pos="0 0 1.5" dir="0 0 -1.3" cutoff="1e+02" exponent="1" diffuse="1 1 1" specular="0.1 0.1 0.1"/>
    <geom name="ground" class="/" type="plane" size="15 15 0.5" material="MatPlane" rgba="1 1 1 1"/>
    <body name="body" pos="0 0 0.1">
      <geom name="geom0" class="/" type="capsule" contype="1" conaffinity="1" condim="3" size="0.063" rgba="0.99 0.55 0.13 1" friction="0.4 0.1 0.1" fromto="0 0 0 0.57 0 0.59"/>
      <body name="body1" pos="0.12 0 0.13">
        <geom name="geom1" class="/" type="capsule" contype="1" conaffinity="1" condim="3" size="0.067" rgba="0.28 0.11 0.9 1" friction="0.4 0.1 0.1" fromto="0 0 0 -0.55 0 0.087"/>
        <body name="body2" pos="-0.27 0 0.043">
          <geom name="geom2" class="/" type="capsule" contype="1" conaffinity="1" condim="3" size="0.041" rgba="0.23 0.88 0.22 1" friction="0.4 0.1 0.1" fromto="0 0 0 -0.22 0 0.64"/>
          <body name="body3" pos="-0.13 0 0.37">
            <geom name="geom3" class="/" type="capsule" contype="1" conaffinity="1" condim="3" size="0.061" rgba="0.49 0.94 0.62 1" friction="0.4 0.1 0.1" fromto="0 0 0 -0.7 0 -0.47"/>
            <joint name="joint3" class="/" type="hinge" axis="0 1 0" limited="true" stiffness="20" range="-62 62" armature="0.1" damping="2"/>
          </body>
          <body name="body4" pos="-0.018 0 0.052">
            <geom name="geom4" class="/" type="capsule" contype="1" conaffinity="1" condim="3" size="0.054" rgba="0.039 0.95 0.35 1" friction="0.4 0.1 0.1" fromto="0 0 0 0.3 0 0.1"/>
            <body name="body5" pos="0.23 0 0.079">
              <geom name="geom5" class="/" type="capsule" contype="1" conaffinity="1" condim="3" size="0.057" rgba="0.51 0.89 0.11 1" friction="0.4 0.1 0.1" fromto="0 0 0 0.00014 0 0.065"/>
              <body name="body6" pos="0.00011 0 0.051">
                <geom name="geom6" class="/" type="capsule" contype="1" conaffinity="1" condim="3" size="0.052" rgba="0.19 0.43 0.87 1" friction="0.4 0.1 0.1" fromto="0 0 0 -0.11 0 0.22"/>
                <body name="body7" pos="-0.017 0 0.036">
                  <geom name="geom7" class="/" type="capsule" contype="1" conaffinity="1" condim="3" size="0.054" rgba="0.12 0.54 0.039 1" friction="0.4 0.1 0.1" fromto="0 0 0 -0.21 0 0.013"/>
                  <body name="body8" pos="-0.16 0 0.011">
                    <geom name="geom8" class="/" type="capsule" contype="1" conaffinity="1" condim="3" size="0.045" rgba="0.5 0.38 0.76 1" friction="0.4 0.1 0.1" fromto="0 0 0 0.037 0 0.15"/>
                    <body name="body9" pos="0.0027 0 0.011">
                      <geom name="geom9" class="/" type="capsule" contype="1" conaffinity="1" condim="3" size="0.051" rgba="0.27 0.81 0.038 1" friction="0.4 0.1 0.1" fromto="0 0 0 0.023 0 -0.099"/>
                      <joint name="joint9" class="/" type="hinge" axis="0 1 0" limited="true" stiffness="20" range="-30 30" armature="0.1" damping="2"/>
                    </body>
                  </body>
                  <joint name="joint7" class="/" type="hinge" axis="0 1 0" limited="true" stiffness="20" range="-49 49" armature="0.1" damping="2"/>
                </body>
              </body>
              <joint name="joint5" class="/" type="hinge" axis="0 1 0" limited="true" stiffness="20" range="-39 39" armature="0.1" damping="2"/>
            </body>
            <joint name="joint4" class="/" type="hinge" axis="0 1 0" limited="true" stiffness="20" range="-30 30" armature="0.1" damping="2"/>
          </body>
          <joint name="joint2" class="/" type="hinge" axis="0 1 0" limited="true" stiffness="20" range="-54 54" armature="0.1" damping="2"/>
        </body>
        <joint name="joint1" class="/" type="hinge" axis="0 1 0" limited="true" stiffness="20" range="-46 46" armature="0.1" damping="2"/>
      </body>
      <body name="body10" pos="0.32 0 0.33">
        <geom name="geom10" class="/" type="capsule" contype="1" conaffinity="1" condim="3" size="0.062" rgba="0.83 0.046 0.082 1" friction="0.4 0.1 0.1" fromto="0 0 0 -0.64 0 0.6"/>
        <joint name="joint10" class="/" type="hinge" axis="0 1 0" limited="true" stiffness="20" range="-43 43" armature="0.1" damping="2"/>
      </body>
      <joint name="rootx" class="/" type="slide" axis="1 0 0" limited="false" stiffness="0" armature="0" damping="0"/>
      <joint name="rootz" class="/" type="slide" axis="0 0 1" limited="false" stiffness="0" armature="0" damping="0"/>
      <joint name="rooty" class="/" type="hinge" axis="0 1 0" limited="false" stiffness="0" armature="0" damping="0"/>
    </body>
  </worldbody>
  <actuator>
    <motor name="motor3" class="/" ctrllimited="true" ctrlrange="-1 1" gear="1.1e+02" joint="joint3"/>
    <motor name="motor9" class="/" ctrllimited="true" ctrlrange="-1 1" gear="1.2e+02" joint="joint9"/>
    <motor name="motor7" class="/" ctrllimited="true" ctrlrange="-1 1" gear="1.4e+02" joint="joint7"/>
    <motor name="motor5" class="/" ctrllimited="true" ctrlrange="-1 1" gear="1.9e+02" joint="joint5"/>
    <motor name="motor4" class="/" ctrllimited="true" ctrlrange="-1 1" gear="1.5e+02" joint="joint4"/>
    <motor name="motor2" class="/" ctrllimited="true" ctrlrange="-1 1" gear="1.2e+02" joint="joint2"/>
    <motor name="motor1" class="/" ctrllimited="true" ctrlrange="-1 1" gear="1.5e+02" joint="joint1"/>
    <motor name="motor10" class="/" ctrllimited="true" ctrlrange="-1 1" gear="1.2e+02" joint="joint10"/>
  </actuator>
  <sensor>
    <subtreelinvel name="velocity" body="body"/>
  </sensor>
</mujoco>
