<mujoco model="morphology">
  <option timestep="0.01"/>
  <default>
    <default class="/"/>
  </default>
  <asset>
    <texture name="texplane" type="2d" builtin="checker" rgb1="0.1 0.2 0.3" rgb2="0.2 0.3 0.4" width="300" height="300"/>
    <material name="MatPlane" class="/" texture="texplane" texrepeat="20 20" specular="1" shininess="1" reflectance="0.5"/>
  </asset>
  <worldbody>
    <light name="//unnamed_light_0" class="/" directional="true" pos="0 0 1.5" dir="0 0 -1.3" cutoff="1e+02" exponent="1" diffuse="1 1 1" specular="0.1 0.1 0.1"/>
    <geom name="ground" class="/" type="plane" size="15 15 0.5" material="MatPlane" rgba="1 1 1 1"/>
    <body name="body" pos="0 0 1.7">
      <geom name="geom0" class="/" type="capsule" contype="1" conaffinity="1" condim="3" size="0.048" rgba="0.38 0.68 0.91 1" friction="0.6 0.1 0.1" fromto="0 0 0 0.38 0 -0.29"/>
      <body name="body1" pos="0.38 0 -0.29">
        <geom name="geom1" class="/" type="capsule" contype="1" conaffinity="1" condim="3" size="0.065" rgba="0.12 0.048 0.31 1" friction="0.6 0.1 0.1" fromto="0 0 0 0.61 0 -0.32"/>
        <body name="body2" pos="0.53 0 -0.28">
          <geom name="geom2" class="/" type="capsule" contype="1" conaffinity="1" condim="3" size="0.054" rgba="0.76 0.63 0.43 1" friction="0.6 0.1 0.1" fromto="0 0 0 0.66 0 0.53"/>
          <body name="body3" pos="0.41 0 0.33">
            <geom name="geom3" class="/" type="capsule" contype="1" conaffinity="1" condim="3" size="0.063" rgba="0.45 0.096 0.41 1" friction="0.6 0.1 0.1" fromto="0 0 0 0.71 0 -0.59"/>
            <body name="body4" pos="0.58 0 -0.48">
              <geom name="geom4" class="/" type="capsule" contype="1" conaffinity="1" condim="3" size="0.06" rgba="0.15 0.91 0.34 1" friction="0.6 0.1 0.1" fromto="0 0 0 -0.65 0 -0.5"/>
              <body name="body5" pos="-0.19 0 -0.15">
                <geom name="geom5" class="/" type="capsule" contype="1" conaffinity="1" condim="3" size="0.068" rgba="0.81 0.79 0.34 1" friction="0.6 0.1 0.1" fromto="0 0 0 0.22 0 -0.13"/>
                <joint name="joint5" class="/" type="hinge" axis="0 1 0" limited="true" stiffness="1e+02" range="-36 36" armature="0.2" damping="3.5"/>
              </body>
              <body name="body6" pos="-0.57 0 -0.44">
                <geom name="geom6" class="/" type="capsule" contype="1" conaffinity="1" condim="3" size="0.059" rgba="0.67 0.65 0.34 1" friction="0.6 0.1 0.1" fromto="0 0 0 -0.09 0 0.22"/>
                <body name="body7" pos="-0.084 0 0.21">
                  <geom name="geom7" class="/" type="capsule" contype="1" conaffinity="1" condim="3" size="0.05" rgba="0.41 0.47 0.18 1" friction="0.6 0.1 0.1" fromto="0 0 0 -0.61 0 -0.15"/>
                  <body name="body8" pos="-0.24 0 -0.06">
                    <geom name="geom8" class="/" type="capsule" contype="1" conaffinity="1" condim="3" size="0.043" rgba="0.045 0.9 0.76 1" friction="0.6 0.1 0.1" fromto="0 0 0 0.39 0 -0.55"/>
                    <joint name="joint8" class="/" type="hinge" axis="0 1 0" limited="true" stiffness="1e+02" range="-43 43" armature="0.2" damping="3.5"/>
                  </body>
                  <joint name="joint7" class="/" type="hinge" axis="0 1 0" limited="true" stiffness="1e+02" range="-49 49" armature="0.2" damping="3.5"/>
                </body>
                <joint name="joint6" class="/" type="hinge" axis="0 1 0" limited="true" stiffness="1e+02" range="-63 63" armature="0.2" damping="3.5"/>
              </body>
              <body name="body9" pos="-0.2 0 -0.16">
                <geom name="geom9" class="/" type="capsule" contype="1" conaffinity="1" condim="3" size="0.052" rgba="0.38 0.26 0.071 1" friction="0.6 0.1 0.1" fromto="0 0 0 0.041 0 -0.11"/>
                <joint name="joint9" class="/" type="hinge" axis="0 1 0" limited="true" stiffness="1e+02" range="-67 67" armature="0.2" damping="3.5"/>
              </body>
              <joint name="joint4" class="/" type="hinge" axis="0 1 0" limited="true" stiffness="1e+02" range="-30 30" armature="0.2" damping="3.5"/>
            </body>
            <joint name="joint3" class="/" type="hinge" axis="0 1 0" limited="true" stiffness="1e+02" range="-30 30" armature="0.2" damping="3.5"/>
          </body>
          <body name="body10" pos="0.15 0 0.12">
            <geom name="geom10" class="/" type="capsule" contype="1" conaffinity="1" condim="3" size="0.049" rgba="0.95 0.56 0.69 1" friction="0.6 0.1 0.1" fromto="0 0 0 -0.42 0 0.45"/>
            <joint name="joint10" class="/" type="hinge" axis="0 1 0" limited="true" stiffness="1e+02" range="-54 54" armature="0.2" damping="3.5"/>
          </body>
          <joint name="joint2" class="/" type="hinge" axis="0 1 0" limited="true" stiffness="1e+02" range="-63 63" armature="0.2" damping="3.5"/>
        </body>
        <joint name="joint1" class="/" type="hinge" axis="0 1 0" limited="true" stiffness="1e+02" range="-50 50" armature="0.2" damping="3.5"/>
      </body>
      <joint name="rootx" class="/" type="slide" axis="1 0 0" limited="false" stiffness="0" armature="0" damping="0"/>
      <joint name="rootz" class="/" type="slide" axis="0 0 1" limited="false" stiffness="0" armature="0" damping="0"/>
      <joint name="rooty" class="/" type="hinge" axis="0 1 0" limited="false" stiffness="0" armature="0" damping="0"/>
    </body>
  </worldbody>
  <actuator>
    <motor name="motor5" class="/" ctrllimited="true" ctrlrange="-1 1" gear="1.2e+02" joint="joint5"/>
    <motor name="motor8" class="/" ctrllimited="true" ctrlrange="-1 1" gear="1e+02" joint="joint8"/>
    <motor name="motor7" class="/" ctrllimited="true" ctrlrange="-1 1" gear="1.8e+02" joint="joint7"/>
    <motor name="motor6" class="/" ctrllimited="true" ctrlrange="-1 1" gear="1e+02" joint="joint6"/>
    <motor name="motor9" class="/" ctrllimited="true" ctrlrange="-1 1" gear="1.2e+02" joint="joint9"/>
    <motor name="motor4" class="/" ctrllimited="true" ctrlrange="-1 1" gear="2e+02" joint="joint4"/>
    <motor name="motor3" class="/" ctrllimited="true" ctrlrange="-1 1" gear="1.2e+02" joint="joint3"/>
    <motor name="motor10" class="/" ctrllimited="true" ctrlrange="-1 1" gear="1.4e+02" joint="joint10"/>
    <motor name="motor2" class="/" ctrllimited="true" ctrlrange="-1 1" gear="1.3e+02" joint="joint2"/>
    <motor name="motor1" class="/" ctrllimited="true" ctrlrange="-1 1" gear="1.9e+02" joint="joint1"/>
  </actuator>
  <sensor>
    <subtreelinvel name="velocity" body="body"/>
  </sensor>
</mujoco>
