<mujoco model="morphology">
  <default>
    <default class="/"/>
  </default>
  <asset>
    <texture name="texplane" type="2d" builtin="checker" rgb1="0.1 0.2 0.3" rgb2="0.2 0.3 0.4" width="300" height="300"/>
    <material name="MatPlane" class="/" texture="texplane" texrepeat="20 20" specular="1" shininess="1" reflectance="0.5"/>
  </asset>
  <worldbody>
    <light name="//unnamed_light_0" class="/" directional="true" pos="0 0 1.5" dir="0 0 -1.3" cutoff="1e+02" exponent="1" diffuse="1 1 1" specular="0.1 0.1 0.1"/>
    <geom name="ground" class="/" type="plane" size="15 15 0.5" material="MatPlane" rgba="1 1 1 1"/>
    <body name="body" pos="0 0 1.5">
      <geom name="geom0" class="/" type="capsule" size="0.07" rgba="0.82 0.25 0.5 1" fromto="0 0 0 0.28 0 -0.59"/>
      <body name="body1" pos="0.11 0 -0.22">
        <geom name="geom1" class="/" type="capsule" size="0.049" rgba="0.95 0.95 0.24 1" fromto="0 0 0 -0.24 0 -0.15"/>
        <body name="body2" pos="-0.18 0 -0.11">
          <geom name="geom2" class="/" type="capsule" size="0.065" rgba="0.88 0.69 0.2 1" fromto="0 0 0 0.21 0 -0.71"/>
          <body name="body3" pos="0.1 0 -0.36">
            <geom name="geom3" class="/" type="capsule" size="0.052" rgba="0.025 0.49 0.17 1" fromto="0 0 0 -0.52 0 0.049"/>
            <body name="body4" pos="-0.053 0 0.005">
              <geom name="geom4" class="/" type="capsule" size="0.068" rgba="0.31 0.83 0.82 1" fromto="0 0 0 -0.62 0 -0.7"/>
              <joint name="joint4" class="/" type="hinge" axis="0 1 0" limited="true" range="-69 69"/>
            </body>
            <joint name="joint3" class="/" type="hinge" axis="0 1 0" limited="true" range="-59 59"/>
          </body>
          <joint name="joint2" class="/" type="hinge" axis="0 1 0" limited="true" range="-45 45"/>
        </body>
        <joint name="joint1" class="/" type="hinge" axis="0 1 0" limited="true" range="-60 60"/>
      </body>
      <body name="body5" pos="0.19 0 -0.4">
        <geom name="geom5" class="/" type="capsule" size="0.051" rgba="0.96 0.53 0.38 1" fromto="0 0 0 0.26 0 0.65"/>
        <joint name="joint5" class="/" type="hinge" axis="0 1 0" limited="true" range="-44 44"/>
      </body>
      <joint name="rootx" class="/" type="slide" axis="1 0 0" limited="false" stiffness="0" armature="0" damping="0"/>
      <joint name="rootz" class="/" type="slide" axis="0 0 1" limited="false" stiffness="0" armature="0" damping="0"/>
      <joint name="rooty" class="/" type="hinge" axis="0 1 0" limited="false" stiffness="0" armature="0" damping="0"/>
    </body>
  </worldbody>
  <actuator>
    <motor name="motor4" class="/" ctrllimited="true" ctrlrange="-1 1" gear="1.8e+02" joint="joint4"/>
    <motor name="motor3" class="/" ctrllimited="true" ctrlrange="-1 1" gear="1.1e+02" joint="joint3"/>
    <motor name="motor2" class="/" ctrllimited="true" ctrlrange="-1 1" gear="1.1e+02" joint="joint2"/>
    <motor name="motor1" class="/" ctrllimited="true" ctrlrange="-1 1" gear="1e+02" joint="joint1"/>
    <motor name="motor5" class="/" ctrllimited="true" ctrlrange="-1 1" gear="1.6e+02" joint="joint5"/>
  </actuator>
  <sensor>
    <subtreelinvel name="velocity" body="body"/>
  </sensor>
</mujoco>
