<mujoco model="morphology">
  <option timestep="0.01"/>
  <default>
    <default class="/"/>
  </default>
  <asset>
    <texture name="texplane" type="2d" builtin="checker" rgb1="0.1 0.2 0.3" rgb2="0.2 0.3 0.4" width="300" height="300"/>
    <material name="MatPlane" class="/" texture="texplane" texrepeat="20 20" specular="1" shininess="1" reflectance="0.5"/>
  </asset>
  <worldbody>
    <light name="//unnamed_light_0" class="/" directional="true" pos="0 0 1.5" dir="0 0 -1.3" cutoff="1e+02" exponent="1" diffuse="1 1 1" specular="0.1 0.1 0.1"/>
    <geom name="ground" class="/" type="plane" size="15 15 0.5" material="MatPlane" rgba="1 1 1 1"/>
    <body name="body" pos="0 0 1.5">
      <geom name="geom0" class="/" type="capsule" contype="1" conaffinity="1" condim="3" size="0.062" rgba="0.79 0.78 0.28 1" friction="0.4 0.1 0.1" fromto="0 0 0 0.092 0 -0.74"/>
      <body name="body1" pos="0.058 0 -0.47">
        <geom name="geom1" class="/" type="capsule" contype="1" conaffinity="1" condim="3" size="0.044" rgba="0.53 0.95 0.53 1" friction="0.4 0.1 0.1" fromto="0 0 0 -0.63 0 -0.66"/>
        <joint name="joint1" class="/" type="hinge" axis="0 1 0" limited="true" stiffness="20" range="-32 32" armature="0.1" damping="2"/>
      </body>
      <body name="body2" pos="0.031 0 -0.25">
        <geom name="geom2" class="/" type="capsule" contype="1" conaffinity="1" condim="3" size="0.052" rgba="0.39 0.12 0.82 1" friction="0.4 0.1 0.1" fromto="0 0 0 -0.73 0 -0.51"/>
        <body name="body3" pos="-0.52 0 -0.36">
          <geom name="geom3" class="/" type="capsule" contype="1" conaffinity="1" condim="3" size="0.044" rgba="0.42 0.63 0.53 1" friction="0.4 0.1 0.1" fromto="0 0 0 0.21 0 -0.14"/>
          <body name="body4" pos="0.079 0 -0.053">
            <geom name="geom4" class="/" type="capsule" contype="1" conaffinity="1" condim="3" size="0.041" rgba="0.092 0.73 0.2 1" friction="0.4 0.1 0.1" fromto="0 0 0 -0.35 0 -0.74"/>
            <joint name="joint4" class="/" type="hinge" axis="0 1 0" limited="true" stiffness="20" range="-64 64" armature="0.1" damping="2"/>
          </body>
          <joint name="joint3" class="/" type="hinge" axis="0 1 0" limited="true" stiffness="20" range="-55 55" armature="0.1" damping="2"/>
        </body>
        <body name="body5" pos="-0.26 0 -0.18">
          <geom name="geom5" class="/" type="capsule" contype="1" conaffinity="1" condim="3" size="0.051" rgba="0.37 0.049 0.37 1" friction="0.4 0.1 0.1" fromto="0 0 0 -0.073 0 0.28"/>
          <body name="body6" pos="-0.062 0 0.23">
            <geom name="geom6" class="/" type="capsule" contype="1" conaffinity="1" condim="3" size="0.044" rgba="0.32 0.77 0.3 1" friction="0.4 0.1 0.1" fromto="0 0 0 -0.55 0 -0.013"/>
            <body name="body7" pos="-0.23 0 -0.0054">
              <geom name="geom7" class="/" type="capsule" contype="1" conaffinity="1" condim="3" size="0.066" rgba="0.34 0.33 0.66 1" friction="0.4 0.1 0.1" fromto="0 0 0 0.22 0 0.49"/>
              <joint name="joint7" class="/" type="hinge" axis="0 1 0" limited="true" stiffness="20" range="-38 38" armature="0.1" damping="2"/>
            </body>
            <body name="body8" pos="-0.45 0 -0.011">
              <geom name="geom8" class="/" type="capsule" contype="1" conaffinity="1" condim="3" size="0.058" rgba="0.21 0.48 0.41 1" friction="0.4 0.1 0.1" fromto="0 0 0 -0.13 0 0.34"/>
              <body name="body9" pos="-0.12 0 0.32">
                <geom name="geom9" class="/" type="capsule" contype="1" conaffinity="1" condim="3" size="0.055" rgba="0.29 0.53 0.94 1" friction="0.4 0.1 0.1" fromto="0 0 0 0.18 0 0.28"/>
                <body name="body10" pos="0.0027 0 0.0042">
                  <geom name="geom10" class="/" type="capsule" contype="1" conaffinity="1" condim="3" size="0.061" rgba="0.81 0.49 0.65 1" friction="0.4 0.1 0.1" fromto="0 0 0 -0.58 0 0.6"/>
                  <joint name="joint10" class="/" type="hinge" axis="0 1 0" limited="true" stiffness="20" range="-35 35" armature="0.1" damping="2"/>
                </body>
                <joint name="joint9" class="/" type="hinge" axis="0 1 0" limited="true" stiffness="20" range="-60 60" armature="0.1" damping="2"/>
              </body>
              <joint name="joint8" class="/" type="hinge" axis="0 1 0" limited="true" stiffness="20" range="-53 53" armature="0.1" damping="2"/>
            </body>
            <joint name="joint6" class="/" type="hinge" axis="0 1 0" limited="true" stiffness="20" range="-51 51" armature="0.1" damping="2"/>
          </body>
          <joint name="joint5" class="/" type="hinge" axis="0 1 0" limited="true" stiffness="20" range="-65 65" armature="0.1" damping="2"/>
        </body>
        <joint name="joint2" class="/" type="hinge" axis="0 1 0" limited="true" stiffness="20" range="-67 67" armature="0.1" damping="2"/>
      </body>
      <joint name="rootx" class="/" type="slide" axis="1 0 0" limited="false" stiffness="0" armature="0" damping="0"/>
      <joint name="rootz" class="/" type="slide" axis="0 0 1" limited="false" stiffness="0" armature="0" damping="0"/>
      <joint name="rooty" class="/" type="hinge" axis="0 1 0" limited="false" stiffness="0" armature="0" damping="0"/>
    </body>
  </worldbody>
  <actuator>
    <motor name="motor1" class="/" ctrllimited="true" ctrlrange="-1 1" gear="1.7e+02" joint="joint1"/>
    <motor name="motor4" class="/" ctrllimited="true" ctrlrange="-1 1" gear="1.3e+02" joint="joint4"/>
    <motor name="motor3" class="/" ctrllimited="true" ctrlrange="-1 1" gear="1.6e+02" joint="joint3"/>
    <motor name="motor7" class="/" ctrllimited="true" ctrlrange="-1 1" gear="1e+02" joint="joint7"/>
    <motor name="motor10" class="/" ctrllimited="true" ctrlrange="-1 1" gear="1.7e+02" joint="joint10"/>
    <motor name="motor9" class="/" ctrllimited="true" ctrlrange="-1 1" gear="1.3e+02" joint="joint9"/>
    <motor name="motor8" class="/" ctrllimited="true" ctrlrange="-1 1" gear="2e+02" joint="joint8"/>
    <motor name="motor6" class="/" ctrllimited="true" ctrlrange="-1 1" gear="1.7e+02" joint="joint6"/>
    <motor name="motor5" class="/" ctrllimited="true" ctrlrange="-1 1" gear="1.6e+02" joint="joint5"/>
    <motor name="motor2" class="/" ctrllimited="true" ctrlrange="-1 1" gear="1.4e+02" joint="joint2"/>
  </actuator>
  <sensor>
    <subtreelinvel name="velocity" body="body"/>
  </sensor>
</mujoco>
