<mujoco model="morphology">
  <default>
    <default class="/"/>
  </default>
  <asset>
    <texture name="texplane" type="2d" builtin="checker" rgb1="0.1 0.2 0.3" rgb2="0.2 0.3 0.4" width="300" height="300"/>
    <material name="MatPlane" class="/" texture="texplane" texrepeat="20 20" specular="1" shininess="1" reflectance="0.5"/>
  </asset>
  <worldbody>
    <light name="//unnamed_light_0" class="/" directional="true" pos="0 0 1.5" dir="0 0 -1.3" cutoff="1e+02" exponent="1" diffuse="1 1 1" specular="0.1 0.1 0.1"/>
    <geom name="ground" class="/" type="plane" size="15 15 0.5" material="MatPlane" rgba="1 1 1 1"/>
    <body name="body" pos="0 0 0.9">
      <geom name="geom0" class="/" type="capsule" size="0.056" rgba="0.99 0.14 0.38 1" fromto="0 0 0 0.22 0 -0.31"/>
      <body name="body1" pos="0.008 0 -0.011">
        <geom name="geom1" class="/" type="capsule" size="0.06" rgba="0.62 0.33 0.34 1" fromto="0 0 0 0.063 0 0.29"/>
        <body name="body2" pos="0.011 0 0.053">
          <geom name="geom2" class="/" type="capsule" size="0.044" rgba="0.29 0.21 0.042 1" fromto="0 0 0 -0.66 0 0.32"/>
          <body name="body3" pos="-0.36 0 0.17">
            <geom name="geom3" class="/" type="capsule" size="0.053" rgba="0.87 0.47 0.75 1" fromto="0 0 0 -0.66 0 -0.38"/>
            <body name="body4" pos="-0.26 0 -0.15">
              <geom name="geom4" class="/" type="capsule" size="0.07" rgba="0.84 0.19 0.67 1" fromto="0 0 0 0.074 0 -0.39"/>
              <body name="body5" pos="0.018 0 -0.092">
                <geom name="geom5" class="/" type="capsule" size="0.041" rgba="0.079 0.61 0.32 1" fromto="0 0 0 0.56 0 -0.16"/>
                <body name="body6" pos="0.37 0 -0.11">
                  <geom name="geom6" class="/" type="capsule" size="0.042" rgba="0.43 0.41 0.86 1" fromto="0 0 0 -0.67 0 -0.66"/>
                  <joint name="joint6" class="/" type="hinge" axis="0 1 0" limited="true" range="-69 69" armature="0.2"/>
                </body>
                <joint name="joint5" class="/" type="hinge" axis="0 1 0" limited="true" range="-52 52" armature="0.2"/>
              </body>
              <joint name="joint4" class="/" type="hinge" axis="0 1 0" limited="true" range="-60 60" armature="0.2"/>
            </body>
            <joint name="joint3" class="/" type="hinge" axis="0 1 0" limited="true" range="-43 43" armature="0.2"/>
          </body>
          <joint name="joint2" class="/" type="hinge" axis="0 1 0" limited="true" range="-63 63" armature="0.2"/>
        </body>
        <joint name="joint1" class="/" type="hinge" axis="0 1 0" limited="true" range="-37 37" armature="0.2"/>
      </body>
      <body name="body7" pos="0.089 0 -0.13">
        <geom name="geom7" class="/" type="capsule" size="0.049" rgba="0.97 0.15 0.58 1" fromto="0 0 0 0.69 0 0.15"/>
        <joint name="joint7" class="/" type="hinge" axis="0 1 0" limited="true" range="-47 47" armature="0.2"/>
      </body>
      <joint name="rootx" class="/" type="slide" axis="1 0 0" limited="false" stiffness="0" armature="0" damping="0"/>
      <joint name="rootz" class="/" type="slide" axis="0 0 1" limited="false" stiffness="0" armature="0" damping="0"/>
      <joint name="rooty" class="/" type="hinge" axis="0 1 0" limited="false" stiffness="0" armature="0" damping="0"/>
    </body>
  </worldbody>
  <actuator>
    <motor name="motor6" class="/" ctrllimited="true" ctrlrange="-1 1" gear="1.1e+02" joint="joint6"/>
    <motor name="motor5" class="/" ctrllimited="true" ctrlrange="-1 1" gear="1.2e+02" joint="joint5"/>
    <motor name="motor4" class="/" ctrllimited="true" ctrlrange="-1 1" gear="1.6e+02" joint="joint4"/>
    <motor name="motor3" class="/" ctrllimited="true" ctrlrange="-1 1" gear="1.2e+02" joint="joint3"/>
    <motor name="motor2" class="/" ctrllimited="true" ctrlrange="-1 1" gear="1.7e+02" joint="joint2"/>
    <motor name="motor1" class="/" ctrllimited="true" ctrlrange="-1 1" gear="1.1e+02" joint="joint1"/>
    <motor name="motor7" class="/" ctrllimited="true" ctrlrange="-1 1" gear="2e+02" joint="joint7"/>
  </actuator>
  <sensor>
    <subtreelinvel name="velocity" body="body"/>
  </sensor>
</mujoco>
