<mujoco model="morphology">
  <default>
    <default class="/"/>
  </default>
  <asset>
    <texture name="texplane" type="2d" builtin="checker" rgb1="0.1 0.2 0.3" rgb2="0.2 0.3 0.4" width="300" height="300"/>
    <material name="MatPlane" class="/" texture="texplane" texrepeat="20 20" specular="1" shininess="1" reflectance="0.5"/>
  </asset>
  <worldbody>
    <light name="//unnamed_light_0" class="/" directional="true" pos="0 0 1.5" dir="0 0 -1.3" cutoff="1e+02" exponent="1" diffuse="1 1 1" specular="0.1 0.1 0.1"/>
    <geom name="ground" class="/" type="plane" size="15 15 0.5" material="MatPlane" rgba="1 1 1 1"/>
    <body name="body" pos="0 0 0.1">
      <geom name="geom0" class="/" type="capsule" size="0.053 0.22" rgba="0.99 0.92 0.63 1" pos="-0.039 0 0.22" zaxis="-0.078 0 0.44"/>
      <body name="body1" pos="-0.068 0 0.38">
        <geom name="geom1" class="/" type="capsule" size="0.045 0.27" rgba="0.93 0.44 0.49 1" pos="0.19 0 0.2" zaxis="0.38 0 0.39"/>
        <body name="body2" pos="0.33 0 0.34">
          <geom name="geom2" class="/" type="capsule" size="0.056 0.13" rgba="0.9 0.24 0.69 1" pos="-0.016 0 0.13" zaxis="-0.032 0 0.26"/>
          <body name="body3" pos="-0.0069 0 0.056">
            <geom name="geom3" class="/" type="capsule" size="0.048 0.37" rgba="0.81 0.68 0.66 1" pos="0.25 0 0.27" zaxis="0.5 0 0.54"/>
            <joint name="joint3" class="/" type="hinge" axis="0 1 0" limited="true" range="-35 35"/>
          </body>
          <joint name="joint2" class="/" type="hinge" axis="0 1 0" limited="true" range="-62 62"/>
        </body>
        <joint name="joint1" class="/" type="hinge" axis="0 1 0" limited="true" range="-54 54"/>
      </body>
      <joint name="rootx" class="/" type="slide" axis="1 0 0" limited="false" stiffness="0" armature="0" damping="0"/>
      <joint name="rootz" class="/" type="slide" axis="0 0 1" limited="false" stiffness="0" armature="0" damping="0"/>
      <joint name="rooty" class="/" type="hinge" axis="0 1 0" limited="false" stiffness="0" armature="0" damping="0"/>
    </body>
  </worldbody>
  <actuator>
    <motor name="motor3" class="/" ctrllimited="true" ctrlrange="-1 1" gear="1.5e+02" joint="joint3"/>
    <motor name="motor2" class="/" ctrllimited="true" ctrlrange="-1 1" gear="1.5e+02" joint="joint2"/>
    <motor name="motor1" class="/" ctrllimited="true" ctrlrange="-1 1" gear="1.9e+02" joint="joint1"/>
  </actuator>
  <sensor>
    <subtreelinvel name="velocity" body="body"/>
  </sensor>
</mujoco>
