<mujoco model="morphology">
  <default>
    <default class="/"/>
  </default>
  <asset>
    <texture name="texplane" type="2d" builtin="checker" rgb1="0.1 0.2 0.3" rgb2="0.2 0.3 0.4" width="300" height="300"/>
    <material name="MatPlane" class="/" texture="texplane" texrepeat="20 20" specular="1" shininess="1" reflectance="0.5"/>
  </asset>
  <worldbody>
    <light name="//unnamed_light_0" class="/" directional="true" pos="0 0 1.5" dir="0 0 -1.3" cutoff="1e+02" exponent="1" diffuse="1 1 1" specular="0.1 0.1 0.1"/>
    <geom name="ground" class="/" type="plane" size="15 15 0.5" material="MatPlane" rgba="1 1 1 1"/>
    <body name="body" pos="0 0 0.52">
      <geom name="geom0" class="/" type="capsule" size="0.069 0.33" rgba="0.17 0.045 0.85 1" pos="0.32 0 -0.081" zaxis="0.64 0 -0.16"/>
      <body name="body1" pos="0.056 0 -0.014">
        <geom name="geom1" class="/" type="capsule" size="0.044 0.21" rgba="0.66 0.15 0.54 1" pos="-0.065 0 -0.2" zaxis="-0.13 0 -0.41"/>
        <joint name="joint1" class="/" type="hinge" axis="0 1 0" limited="true" range="-51 51"/>
      </body>
      <body name="body2" pos="0.39 0 -0.098">
        <geom name="geom2" class="/" type="capsule" size="0.068 0.35" rgba="0.88 0.39 0.41 1" pos="0.23 0 0.27" zaxis="0.46 0 0.54"/>
        <body name="body3" pos="0.14 0 0.16">
          <geom name="geom3" class="/" type="capsule" size="0.065 0.23" rgba="0.2 0.92 0.81 1" pos="-0.14 0 0.18" zaxis="-0.28 0 0.37"/>
          <body name="body4" pos="-0.19 0 0.25">
            <geom name="geom4" class="/" type="capsule" size="0.066 0.18" rgba="0.14 0.15 0.3 1" pos="-0.17 0 -0.048" zaxis="-0.34 0 -0.096"/>
            <joint name="joint4" class="/" type="hinge" axis="0 1 0" limited="true" range="-66 66"/>
          </body>
          <body name="body5" pos="-0.12 0 0.15">
            <geom name="geom5" class="/" type="capsule" size="0.051 0.082" rgba="0.0086 0.93 0.52 1" pos="0.069 0 0.044" zaxis="0.14 0 0.088"/>
            <body name="body6" pos="0.099 0 0.063">
              <geom name="geom6" class="/" type="capsule" size="0.067 0.25" rgba="0.8 0.6 0.64 1" pos="-0.12 0 0.22" zaxis="-0.24 0 0.43"/>
              <body name="body7" pos="-0.24 0 0.43">
                <geom name="geom7" class="/" type="capsule" size="0.059 0.16" rgba="0.95 0.22 0.55 1" pos="-0.15 0 -0.039" zaxis="-0.31 0 -0.079"/>
                <joint name="joint7" class="/" type="hinge" axis="0 1 0" limited="true" range="-65 65"/>
              </body>
            </body>
          </body>
        </body>
        <body name="body8" pos="0.44 0 0.51">
          <geom name="geom8" class="/" type="capsule" size="0.065 0.39" rgba="0.71 0.79 0.54 1" pos="-0.19 0 0.34" zaxis="-0.39 0 0.67"/>
          <body name="body9" pos="-0.27 0 0.47">
            <geom name="geom9" class="/" type="capsule" size="0.052 0.3" rgba="0.26 0.73 0.43 1" pos="-0.29 0 0.033" zaxis="-0.59 0 0.067"/>
          </body>
          <body name="body10" pos="-0.091 0 0.16">
            <geom name="geom10" class="/" type="capsule" size="0.061 0.27" rgba="0.42 0.6 0.92 1" pos="0.27 0 -0.053" zaxis="0.54 0 -0.11"/>
            <joint name="joint10" class="/" type="hinge" axis="0 1 0" limited="true" range="-39 39"/>
          </body>
        </body>
        <joint name="joint2" class="/" type="hinge" axis="0 1 0" limited="true" range="-61 61"/>
      </body>
      <joint name="rootx" class="/" type="slide" axis="1 0 0" limited="false" stiffness="0" armature="0" damping="0"/>
      <joint name="rootz" class="/" type="slide" axis="0 0 1" limited="false" stiffness="0" armature="0" damping="0"/>
      <joint name="rooty" class="/" type="hinge" axis="0 1 0" limited="false" stiffness="0" armature="0" damping="0"/>
    </body>
  </worldbody>
  <actuator>
    <motor name="motor1" class="/" ctrllimited="true" ctrlrange="-1 1" gear="1.9e+02" joint="joint1"/>
    <motor name="motor4" class="/" ctrllimited="true" ctrlrange="-1 1" gear="1.3e+02" joint="joint4"/>
    <motor name="motor7" class="/" ctrllimited="true" ctrlrange="-1 1" gear="1.5e+02" joint="joint7"/>
    <motor name="motor10" class="/" ctrllimited="true" ctrlrange="-1 1" gear="1.3e+02" joint="joint10"/>
    <motor name="motor2" class="/" ctrllimited="true" ctrlrange="-1 1" gear="1.9e+02" joint="joint2"/>
  </actuator>
  <sensor>
    <subtreelinvel name="velocity" body="body"/>
  </sensor>
</mujoco>
