<mujoco model="morphology">
  <option timestep="0.01"/>
  <default>
    <default class="/"/>
  </default>
  <asset>
    <texture name="texplane" type="2d" builtin="checker" rgb1="0.1 0.2 0.3" rgb2="0.2 0.3 0.4" width="300" height="300"/>
    <material name="MatPlane" class="/" texture="texplane" texrepeat="20 20" specular="1" shininess="1" reflectance="0.5"/>
  </asset>
  <worldbody>
    <light name="//unnamed_light_0" class="/" directional="true" pos="0 0 1.5" dir="0 0 -1.3" cutoff="1e+02" exponent="1" diffuse="1 1 1" specular="0.1 0.1 0.1"/>
    <geom name="ground" class="/" type="plane" size="15 15 0.5" material="MatPlane" rgba="1 1 1 1"/>
    <body name="body" pos="0 0 0.79">
      <geom name="geom0" class="/" type="capsule" contype="1" conaffinity="1" condim="3" size="0.069" rgba="0.037 0.19 0.75 1" friction="0.6 0.1 0.1" fromto="0 0 0 -0.53 0 -0.33"/>
      <body name="body1" pos="-0.19 0 -0.12">
        <geom name="geom1" class="/" type="capsule" contype="1" conaffinity="1" condim="3" size="0.062" rgba="0.14 0.8 0.77 1" friction="0.6 0.1 0.1" fromto="0 0 0 0.62 0 -0.57"/>
        <body name="body2" pos="0.21 0 -0.19">
          <geom name="geom2" class="/" type="capsule" contype="1" conaffinity="1" condim="3" size="0.063" rgba="0.3 0.2 0.76 1" friction="0.6 0.1 0.1" fromto="0 0 0 0.17 0 0.51"/>
          <body name="body3" pos="0.16 0 0.47">
            <geom name="geom3" class="/" type="capsule" contype="1" conaffinity="1" condim="3" size="0.06" rgba="0.16 0.54 0.38 1" friction="0.6 0.1 0.1" fromto="0 0 0 0.64 0 0.15"/>
            <body name="body4" pos="0.2 0 0.047">
              <geom name="geom4" class="/" type="capsule" contype="1" conaffinity="1" condim="3" size="0.059" rgba="0.31 0.98 0.21 1" friction="0.6 0.1 0.1" fromto="0 0 0 -0.18 0 0.39"/>
            </body>
            <joint name="joint3" class="/" type="hinge" axis="0 1 0" limited="true" stiffness="1e+02" range="-53 53" armature="0.2" damping="3.5"/>
          </body>
          <joint name="joint2" class="/" type="hinge" axis="0 1 0" limited="true" stiffness="1e+02" range="-38 38" armature="0.2" damping="3.5"/>
        </body>
        <joint name="joint1" class="/" type="hinge" axis="0 1 0" limited="true" stiffness="1e+02" range="-30 30" armature="0.2" damping="3.5"/>
      </body>
      <joint name="rootx" class="/" type="slide" axis="1 0 0" limited="false" stiffness="0" armature="0" damping="0"/>
      <joint name="rootz" class="/" type="slide" axis="0 0 1" limited="false" stiffness="0" armature="0" damping="0"/>
      <joint name="rooty" class="/" type="hinge" axis="0 1 0" limited="false" stiffness="0" armature="0" damping="0"/>
    </body>
  </worldbody>
  <actuator>
    <motor name="motor3" class="/" ctrllimited="true" ctrlrange="-1 1" gear="1.6e+02" joint="joint3"/>
    <motor name="motor2" class="/" ctrllimited="true" ctrlrange="-1 1" gear="1.3e+02" joint="joint2"/>
    <motor name="motor1" class="/" ctrllimited="true" ctrlrange="-1 1" gear="1.3e+02" joint="joint1"/>
  </actuator>
  <sensor>
    <subtreelinvel name="velocity" body="body"/>
  </sensor>
</mujoco>
