<mujoco model="morphology">
  <default>
    <default class="/"/>
  </default>
  <asset>
    <texture name="texplane" type="2d" builtin="checker" rgb1="0.1 0.2 0.3" rgb2="0.2 0.3 0.4" width="300" height="300"/>
    <material name="MatPlane" class="/" texture="texplane" texrepeat="20 20" specular="1" shininess="1" reflectance="0.5"/>
  </asset>
  <worldbody>
    <light name="//unnamed_light_0" class="/" directional="true" pos="0 0 1.5" dir="0 0 -1.3" cutoff="1e+02" exponent="1" diffuse="1 1 1" specular="0.1 0.1 0.1"/>
    <geom name="ground" class="/" type="plane" size="15 15 0.5" material="MatPlane" rgba="1 1 1 1"/>
    <body name="body" pos="0 0 0.94">
      <geom name="geom0" class="/" type="capsule" size="0.054" rgba="0.054 0.84 0.82 1" fromto="0 0 0 -0.66 0 -0.73"/>
      <body name="body1" pos="-0.42 0 -0.47">
        <geom name="geom1" class="/" type="capsule" size="0.048" rgba="0.68 0.75 0.9 1" fromto="0 0 0 -0.2 0 0.47"/>
        <body name="body2" pos="-0.18 0 0.43">
          <geom name="geom2" class="/" type="capsule" size="0.049" rgba="0.022 0.67 0.13 1" fromto="0 0 0 -0.56 0 0.059"/>
          <body name="body3" pos="-0.11 0 0.011">
            <geom name="geom3" class="/" type="capsule" size="0.061" rgba="0.75 0.44 0.54 1" fromto="0 0 0 -0.19 0 0.64"/>
            <joint name="joint3" class="/" type="hinge" axis="0 1 0" limited="true" range="-63 63"/>
          </body>
          <joint name="joint2" class="/" type="hinge" axis="0 1 0" limited="true" range="-59 59"/>
        </body>
        <body name="body4" pos="-0.17 0 0.4">
          <geom name="geom4" class="/" type="capsule" size="0.042" rgba="0.37 0.94 0.43 1" fromto="0 0 0 -0.57 0 -0.56"/>
          <body name="body5" pos="-0.51 0 -0.5">
            <geom name="geom5" class="/" type="capsule" size="0.056" rgba="0.71 0.38 0.31 1" fromto="0 0 0 0.51 0 -0.26"/>
            <joint name="joint5" class="/" type="hinge" axis="0 1 0" limited="true" range="-55 55"/>
          </body>
        </body>
        <body name="body6" pos="-0.18 0 0.43">
          <geom name="geom6" class="/" type="capsule" size="0.059" rgba="0.94 0.88 0.42 1" fromto="0 0 0 0.58 0 0.48"/>
          <joint name="joint6" class="/" type="hinge" axis="0 1 0" limited="true" range="-40 40"/>
        </body>
        <joint name="joint1" class="/" type="hinge" axis="0 1 0" limited="true" range="-34 34"/>
      </body>
      <joint name="rootx" class="/" type="slide" axis="1 0 0" limited="false" stiffness="0" armature="0" damping="0"/>
      <joint name="rootz" class="/" type="slide" axis="0 0 1" limited="false" stiffness="0" armature="0" damping="0"/>
      <joint name="rooty" class="/" type="hinge" axis="0 1 0" limited="false" stiffness="0" armature="0" damping="0"/>
    </body>
  </worldbody>
  <actuator>
    <motor name="motor3" class="/" ctrllimited="true" ctrlrange="-1 1" gear="1.5e+02" joint="joint3"/>
    <motor name="motor2" class="/" ctrllimited="true" ctrlrange="-1 1" gear="1e+02" joint="joint2"/>
    <motor name="motor5" class="/" ctrllimited="true" ctrlrange="-1 1" gear="1.3e+02" joint="joint5"/>
    <motor name="motor6" class="/" ctrllimited="true" ctrlrange="-1 1" gear="2e+02" joint="joint6"/>
    <motor name="motor1" class="/" ctrllimited="true" ctrlrange="-1 1" gear="1.2e+02" joint="joint1"/>
  </actuator>
  <sensor>
    <subtreelinvel name="velocity" body="body"/>
  </sensor>
</mujoco>
