<mujoco model="morphology">
  <default>
    <default class="/"/>
  </default>
  <asset>
    <texture name="texplane" type="2d" builtin="checker" rgb1="0.1 0.2 0.3" rgb2="0.2 0.3 0.4" width="300" height="300"/>
    <material name="MatPlane" class="/" texture="texplane" texrepeat="20 20" specular="1" shininess="1" reflectance="0.5"/>
  </asset>
  <worldbody>
    <light name="//unnamed_light_0" class="/" directional="true" pos="0 0 1.5" dir="0 0 -1.3" cutoff="1e+02" exponent="1" diffuse="1 1 1" specular="0.1 0.1 0.1"/>
    <geom name="ground" class="/" type="plane" size="15 15 0.5" material="MatPlane" rgba="1 1 1 1"/>
    <body name="body" pos="0 0 1.5">
      <geom name="geom0" class="/" type="capsule" size="0.063" rgba="0.7 0.84 0.26 1" fromto="0 0 0 -0.59 0 -0.15"/>
      <body name="body1" pos="-0.33 0 -0.083">
        <geom name="geom1" class="/" type="capsule" size="0.043" rgba="0.61 0.79 0.62 1" fromto="0 0 0 0.17 0 -0.68"/>
        <body name="body2" pos="0.13 0 -0.5">
          <geom name="geom2" class="/" type="capsule" size="0.059" rgba="0.8 0.97 0.64 1" fromto="0 0 0 -0.43 0 0.24"/>
          <joint name="joint2" class="/" type="hinge" axis="0 1 0" limited="true" range="-45 45" armature="0.2"/>
        </body>
        <body name="body3" pos="0.16 0 -0.62">
          <geom name="geom3" class="/" type="capsule" size="0.048" rgba="0.43 0.74 0.0065 1" fromto="0 0 0 0.2 0 0.29"/>
          <body name="body4" pos="0.0062 0 0.0091">
            <geom name="geom4" class="/" type="capsule" size="0.055" rgba="0.47 0.56 0.96 1" fromto="0 0 0 -0.74 0 -0.003"/>
            <body name="body5" pos="-0.46 0 -0.0019">
              <geom name="geom5" class="/" type="capsule" size="0.063" rgba="0.57 0.99 0.9 1" fromto="0 0 0 0.33 0 -0.69"/>
            </body>
            <joint name="joint4" class="/" type="hinge" axis="0 1 0" limited="true" range="-34 34" armature="0.2"/>
          </body>
        </body>
        <joint name="joint1" class="/" type="hinge" axis="0 1 0" limited="true" range="-36 36" armature="0.2"/>
      </body>
      <joint name="rootx" class="/" type="slide" axis="1 0 0" limited="false" stiffness="0" armature="0" damping="0"/>
      <joint name="rootz" class="/" type="slide" axis="0 0 1" limited="false" stiffness="0" armature="0" damping="0"/>
      <joint name="rooty" class="/" type="hinge" axis="0 1 0" limited="false" stiffness="0" armature="0" damping="0"/>
    </body>
  </worldbody>
  <actuator>
    <motor name="motor2" class="/" ctrllimited="true" ctrlrange="-1 1" gear="1.3e+02" joint="joint2"/>
    <motor name="motor4" class="/" ctrllimited="true" ctrlrange="-1 1" gear="1.1e+02" joint="joint4"/>
    <motor name="motor1" class="/" ctrllimited="true" ctrlrange="-1 1" gear="1.2e+02" joint="joint1"/>
  </actuator>
  <sensor>
    <subtreelinvel name="velocity" body="body"/>
  </sensor>
</mujoco>
