<mujoco model="morphology">
  <default>
    <default class="/"/>
  </default>
  <asset>
    <texture name="texplane" type="2d" builtin="checker" rgb1="0.1 0.2 0.3" rgb2="0.2 0.3 0.4" width="300" height="300"/>
    <material name="MatPlane" class="/" texture="texplane" texrepeat="20 20" specular="1" shininess="1" reflectance="0.5"/>
  </asset>
  <worldbody>
    <light name="//unnamed_light_0" class="/" directional="true" pos="0 0 1.5" dir="0 0 -1.3" cutoff="1e+02" exponent="1" diffuse="1 1 1" specular="0.1 0.1 0.1"/>
    <geom name="ground" class="/" type="plane" size="15 15 0.5" material="MatPlane" rgba="1 1 1 1"/>
    <body name="body" pos="0 0 0.17">
      <geom name="geom0" class="/" type="capsule" size="0.065" rgba="0.52 0.84 0.73 1" fromto="0 0 0 0.37 0 0.42"/>
      <body name="body1" pos="0.041 0 0.047">
        <geom name="geom1" class="/" type="capsule" size="0.07" rgba="0.048 0.6 0.45 1" fromto="0 0 0 0.65 0 -0.11"/>
        <joint name="joint1" class="/" type="hinge" axis="0 1 0" limited="true" range="-37 37"/>
      </body>
      <body name="body2" pos="0.36 0 0.41">
        <geom name="geom2" class="/" type="capsule" size="0.065" rgba="0.55 0.67 0.14 1" fromto="0 0 0 0.53 0 -0.18"/>
        <body name="body3" pos="0.53 0 -0.18">
          <geom name="geom3" class="/" type="capsule" size="0.054" rgba="0.11 0.81 0.72 1" fromto="0 0 0 0.41 0 -0.26"/>
          <body name="body4" pos="0.006 0 -0.0039">
            <geom name="geom4" class="/" type="capsule" size="0.066" rgba="0.0016 0.83 0.1 1" fromto="0 0 0 0.53 0 0.65"/>
            <body name="body5" pos="0.32 0 0.4">
              <geom name="geom5" class="/" type="capsule" size="0.057" rgba="0.46 0.89 0.66 1" fromto="0 0 0 0.57 0 -0.047"/>
              <body name="body6" pos="0.48 0 -0.04">
                <geom name="geom6" class="/" type="capsule" size="0.052" rgba="0.37 0.4 0.62 1" fromto="0 0 0 -0.16 0 0.56"/>
                <body name="body7" pos="-0.085 0 0.3">
                  <geom name="geom7" class="/" type="capsule" size="0.048" rgba="0.57 0.85 0.28 1" fromto="0 0 0 0.74 0 -0.15"/>
                  <body name="body8" pos="0.51 0 -0.1">
                    <geom name="geom8" class="/" type="capsule" size="0.06" rgba="0.22 0.76 0.94 1" fromto="0 0 0 -0.00072 0 -0.54"/>
                    <joint name="joint8" class="/" type="hinge" axis="0 1 0" limited="true" range="-37 37"/>
                  </body>
                  <joint name="joint7" class="/" type="hinge" axis="0 1 0" limited="true" range="-40 40"/>
                </body>
                <joint name="joint6" class="/" type="hinge" axis="0 1 0" limited="true" range="-51 51"/>
              </body>
              <joint name="joint5" class="/" type="hinge" axis="0 1 0" limited="true" range="-42 42"/>
            </body>
            <joint name="joint4" class="/" type="hinge" axis="0 1 0" limited="true" range="-43 43"/>
          </body>
        </body>
        <body name="body9" pos="0.36 0 -0.12">
          <geom name="geom9" class="/" type="capsule" size="0.055" rgba="0.02 0.71 0.8 1" fromto="0 0 0 0.085 0 0.067"/>
          <body name="body10" pos="0.077 0 0.06">
            <geom name="geom10" class="/" type="capsule" size="0.07" rgba="0.85 0.95 0.86 1" fromto="0 0 0 0.55 0 0.64"/>
            <joint name="joint10" class="/" type="hinge" axis="0 1 0" limited="true" range="-37 37"/>
          </body>
          <joint name="joint9" class="/" type="hinge" axis="0 1 0" limited="true" range="-38 38"/>
        </body>
        <joint name="joint2" class="/" type="hinge" axis="0 1 0" limited="true" range="-63 63"/>
      </body>
      <joint name="rootx" class="/" type="slide" axis="1 0 0" limited="false" stiffness="0" armature="0" damping="0"/>
      <joint name="rootz" class="/" type="slide" axis="0 0 1" limited="false" stiffness="0" armature="0" damping="0"/>
      <joint name="rooty" class="/" type="hinge" axis="0 1 0" limited="false" stiffness="0" armature="0" damping="0"/>
    </body>
  </worldbody>
  <actuator>
    <motor name="motor1" class="/" ctrllimited="true" ctrlrange="-1 1" gear="1.5e+02" joint="joint1"/>
    <motor name="motor8" class="/" ctrllimited="true" ctrlrange="-1 1" gear="1.2e+02" joint="joint8"/>
    <motor name="motor7" class="/" ctrllimited="true" ctrlrange="-1 1" gear="1.2e+02" joint="joint7"/>
    <motor name="motor6" class="/" ctrllimited="true" ctrlrange="-1 1" gear="1.8e+02" joint="joint6"/>
    <motor name="motor5" class="/" ctrllimited="true" ctrlrange="-1 1" gear="1.1e+02" joint="joint5"/>
    <motor name="motor4" class="/" ctrllimited="true" ctrlrange="-1 1" gear="1.3e+02" joint="joint4"/>
    <motor name="motor10" class="/" ctrllimited="true" ctrlrange="-1 1" gear="1.8e+02" joint="joint10"/>
    <motor name="motor9" class="/" ctrllimited="true" ctrlrange="-1 1" gear="1.7e+02" joint="joint9"/>
    <motor name="motor2" class="/" ctrllimited="true" ctrlrange="-1 1" gear="1.5e+02" joint="joint2"/>
  </actuator>
  <sensor>
    <subtreelinvel name="velocity" body="body"/>
  </sensor>
</mujoco>
