<mujoco model="morphology">
  <default>
    <default class="/"/>
  </default>
  <asset>
    <texture name="texplane" type="2d" builtin="checker" rgb1="0.1 0.2 0.3" rgb2="0.2 0.3 0.4" width="300" height="300"/>
    <material name="MatPlane" class="/" texture="texplane" texrepeat="20 20" specular="1" shininess="1" reflectance="0.5"/>
  </asset>
  <worldbody>
    <light name="//unnamed_light_0" class="/" directional="true" pos="0 0 1.5" dir="0 0 -1.3" cutoff="1e+02" exponent="1" diffuse="1 1 1" specular="0.1 0.1 0.1"/>
    <geom name="ground" class="/" type="plane" size="15 15 0.5" material="MatPlane" rgba="1 1 1 1"/>
    <body name="body" pos="0 0 0.65">
      <geom name="geom0" class="/" type="capsule" size="0.069" rgba="0.61 0.022 0.4 1" fromto="0 0 0 0.33 0 -0.55"/>
      <body name="body1" pos="0.15 0 -0.25">
        <geom name="geom1" class="/" type="capsule" size="0.053" rgba="0.68 0.4 0.93 1" fromto="0 0 0 0.14 0 0.087"/>
        <body name="body2" pos="0.12 0 0.075">
          <geom name="geom2" class="/" type="capsule" size="0.063" rgba="0.044 0.7 0.61 1" fromto="0 0 0 0.43 0 0.31"/>
          <body name="body3" pos="0.43 0 0.31">
            <geom name="geom3" class="/" type="capsule" size="0.067" rgba="0.78 0.8 0.2 1" fromto="0 0 0 -0.26 0 0.29"/>
            <joint name="joint3" class="/" type="hinge" axis="0 1 0" limited="true" range="-50 50"/>
          </body>
          <joint name="joint2" class="/" type="hinge" axis="0 1 0" limited="true" range="-41 41"/>
        </body>
        <body name="body4" pos="0.12 0 0.076">
          <geom name="geom4" class="/" type="capsule" size="0.063" rgba="0.2 0.85 0.56 1" fromto="0 0 0 0.079 0 0.57"/>
          <body name="body5" pos="0.075 0 0.55">
            <geom name="geom5" class="/" type="capsule" size="0.06" rgba="0.52 0.84 0.75 1" fromto="0 0 0 -0.62 0 0.29"/>
            <body name="body6" pos="-0.08 0 0.037">
              <geom name="geom6" class="/" type="capsule" size="0.067" rgba="0.67 0.96 0.13 1" fromto="0 0 0 -0.14 0 -0.23"/>
              <joint name="joint6" class="/" type="hinge" axis="0 1 0" limited="true" range="-32 32"/>
            </body>
            <body name="body7" pos="-0.3 0 0.14">
              <geom name="geom7" class="/" type="capsule" size="0.049" rgba="0.64 0.54 0.18 1" fromto="0 0 0 0.52 0 0.42"/>
              <body name="body8" pos="0.28 0 0.22">
                <geom name="geom8" class="/" type="capsule" size="0.063" rgba="0.43 0.62 0.85 1" fromto="0 0 0 -0.11 0 0.58"/>
                <joint name="joint8" class="/" type="hinge" axis="0 1 0" limited="true" range="-68 68"/>
              </body>
              <joint name="joint7" class="/" type="hinge" axis="0 1 0" limited="true" range="-59 59"/>
            </body>
            <body name="body9" pos="-0.54 0 0.25">
              <geom name="geom9" class="/" type="capsule" size="0.056" rgba="0.58 0.71 0.25 1" fromto="0 0 0 -0.14 0 -0.077"/>
              <joint name="joint9" class="/" type="hinge" axis="0 1 0" limited="true" range="-55 55"/>
            </body>
            <joint name="joint5" class="/" type="hinge" axis="0 1 0" limited="true" range="-47 47"/>
          </body>
        </body>
        <joint name="joint1" class="/" type="hinge" axis="0 1 0" limited="true" range="-49 49"/>
      </body>
      <joint name="rootx" class="/" type="slide" axis="1 0 0" limited="false" stiffness="0" armature="0" damping="0"/>
      <joint name="rootz" class="/" type="slide" axis="0 0 1" limited="false" stiffness="0" armature="0" damping="0"/>
      <joint name="rooty" class="/" type="hinge" axis="0 1 0" limited="false" stiffness="0" armature="0" damping="0"/>
    </body>
  </worldbody>
  <actuator>
    <motor name="motor3" class="/" ctrllimited="true" ctrlrange="-1 1" gear="1.1e+02" joint="joint3"/>
    <motor name="motor2" class="/" ctrllimited="true" ctrlrange="-1 1" gear="1.7e+02" joint="joint2"/>
    <motor name="motor6" class="/" ctrllimited="true" ctrlrange="-1 1" gear="1.7e+02" joint="joint6"/>
    <motor name="motor8" class="/" ctrllimited="true" ctrlrange="-1 1" gear="1.5e+02" joint="joint8"/>
    <motor name="motor7" class="/" ctrllimited="true" ctrlrange="-1 1" gear="1.4e+02" joint="joint7"/>
    <motor name="motor9" class="/" ctrllimited="true" ctrlrange="-1 1" gear="1.8e+02" joint="joint9"/>
    <motor name="motor5" class="/" ctrllimited="true" ctrlrange="-1 1" gear="1e+02" joint="joint5"/>
    <motor name="motor1" class="/" ctrllimited="true" ctrlrange="-1 1" gear="1.4e+02" joint="joint1"/>
  </actuator>
  <sensor>
    <subtreelinvel name="velocity" body="body"/>
  </sensor>
</mujoco>
