<mujoco model="morphology">
  <option timestep="0.01"/>
  <default>
    <default class="/"/>
  </default>
  <asset>
    <texture name="texplane" type="2d" builtin="checker" rgb1="0.1 0.2 0.3" rgb2="0.2 0.3 0.4" width="300" height="300"/>
    <material name="MatPlane" class="/" texture="texplane" texrepeat="20 20" specular="1" shininess="1" reflectance="0.5"/>
  </asset>
  <worldbody>
    <light name="//unnamed_light_0" class="/" directional="true" pos="0 0 1.5" dir="0 0 -1.3" cutoff="1e+02" exponent="1" diffuse="1 1 1" specular="0.1 0.1 0.1"/>
    <geom name="ground" class="/" type="plane" size="15 15 0.5" material="MatPlane" rgba="1 1 1 1"/>
    <body name="body" pos="0 0 0.68">
      <geom name="geom0" class="/" type="capsule" contype="1" conaffinity="1" condim="3" size="0.042" rgba="0.56 0.78 0.5 1" friction="0.4 0.1 0.1" fromto="0 0 0 0.29 0 0.49"/>
      <body name="body1" pos="0.16 0 0.27">
        <geom name="geom1" class="/" type="capsule" contype="1" conaffinity="1" condim="3" size="0.064" rgba="0.44 0.17 0.7 1" friction="0.4 0.1 0.1" fromto="0 0 0 0.7 0 0.11"/>
        <body name="body2" pos="0.069 0 0.011">
          <geom name="geom2" class="/" type="capsule" contype="1" conaffinity="1" condim="3" size="0.058" rgba="0.42 0.53 0.1 1" friction="0.4 0.1 0.1" fromto="0 0 0 0.46 0 -0.64"/>
          <body name="body3" pos="0.44 0 -0.62">
            <geom name="geom3" class="/" type="capsule" contype="1" conaffinity="1" condim="3" size="0.065" rgba="0.36 0.64 0.0051 1" friction="0.4 0.1 0.1" fromto="0 0 0 0.66 0 0.67"/>
            <body name="body4" pos="0.64 0 0.66">
              <geom name="geom4" class="/" type="capsule" contype="1" conaffinity="1" condim="3" size="0.053" rgba="0.89 0.048 0.032 1" friction="0.4 0.1 0.1" fromto="0 0 0 -0.38 0 0.11"/>
              <body name="body5" pos="-0.17 0 0.05">
                <geom name="geom5" class="/" type="capsule" contype="1" conaffinity="1" condim="3" size="0.062" rgba="0.94 0.24 0.89 1" friction="0.4 0.1 0.1" fromto="0 0 0 -0.45 0 -0.43"/>
              </body>
              <body name="body6" pos="-0.17 0 0.049">
                <geom name="geom6" class="/" type="capsule" contype="1" conaffinity="1" condim="3" size="0.057" rgba="0.69 0.56 0.0066 1" friction="0.4 0.1 0.1" fromto="0 0 0 -0.13 0 0.36"/>
                <joint name="joint6" class="/" type="hinge" axis="0 1 0" limited="true" stiffness="20" range="-43 43" armature="0.1" damping="2"/>
              </body>
              <joint name="joint4" class="/" type="hinge" axis="0 1 0" limited="true" stiffness="20" range="-38 38" armature="0.1" damping="2"/>
            </body>
            <body name="body7" pos="0.37 0 0.38">
              <geom name="geom7" class="/" type="capsule" contype="1" conaffinity="1" condim="3" size="0.058" rgba="0.08 0.024 0.74 1" friction="0.4 0.1 0.1" fromto="0 0 0 0.19 0 -0.62"/>
              <joint name="joint7" class="/" type="hinge" axis="0 1 0" limited="true" stiffness="20" range="-33 33" armature="0.1" damping="2"/>
            </body>
            <joint name="joint3" class="/" type="hinge" axis="0 1 0" limited="true" stiffness="20" range="-62 62" armature="0.1" damping="2"/>
          </body>
          <joint name="joint2" class="/" type="hinge" axis="0 1 0" limited="true" stiffness="20" range="-38 38" armature="0.1" damping="2"/>
        </body>
        <joint name="joint1" class="/" type="hinge" axis="0 1 0" limited="true" stiffness="20" range="-66 66" armature="0.1" damping="2"/>
      </body>
      <joint name="rootx" class="/" type="slide" axis="1 0 0" limited="false" stiffness="0" armature="0" damping="0"/>
      <joint name="rootz" class="/" type="slide" axis="0 0 1" limited="false" stiffness="0" armature="0" damping="0"/>
      <joint name="rooty" class="/" type="hinge" axis="0 1 0" limited="false" stiffness="0" armature="0" damping="0"/>
    </body>
  </worldbody>
  <actuator>
    <motor name="motor6" class="/" ctrllimited="true" ctrlrange="-1 1" gear="1.1e+02" joint="joint6"/>
    <motor name="motor4" class="/" ctrllimited="true" ctrlrange="-1 1" gear="1.1e+02" joint="joint4"/>
    <motor name="motor7" class="/" ctrllimited="true" ctrlrange="-1 1" gear="1.9e+02" joint="joint7"/>
    <motor name="motor3" class="/" ctrllimited="true" ctrlrange="-1 1" gear="1.6e+02" joint="joint3"/>
    <motor name="motor2" class="/" ctrllimited="true" ctrlrange="-1 1" gear="1.7e+02" joint="joint2"/>
    <motor name="motor1" class="/" ctrllimited="true" ctrlrange="-1 1" gear="1.6e+02" joint="joint1"/>
  </actuator>
  <sensor>
    <subtreelinvel name="velocity" body="body"/>
  </sensor>
</mujoco>
