<mujoco model="morphology">
  <option timestep="0.01"/>
  <default>
    <default class="/"/>
  </default>
  <asset>
    <texture name="texplane" type="2d" builtin="checker" rgb1="0.1 0.2 0.3" rgb2="0.2 0.3 0.4" width="300" height="300"/>
    <material name="MatPlane" class="/" texture="texplane" texrepeat="20 20" specular="1" shininess="1" reflectance="0.5"/>
  </asset>
  <worldbody>
    <light name="//unnamed_light_0" class="/" directional="true" pos="0 0 1.5" dir="0 0 -1.3" cutoff="1e+02" exponent="1" diffuse="1 1 1" specular="0.1 0.1 0.1"/>
    <geom name="ground" class="/" type="plane" size="15 15 0.5" material="MatPlane" rgba="1 1 1 1"/>
    <body name="body" pos="0 0 1.5">
      <geom name="geom0" class="/" type="capsule" contype="1" conaffinity="1" condim="3" size="0.049" rgba="0.79 0.16 0.57 1" friction="0.4 0.1 0.1" fromto="0 0 0 -0.19 0 0.15"/>
      <body name="body1" pos="-0.018 0 0.014">
        <geom name="geom1" class="/" type="capsule" contype="1" conaffinity="1" condim="3" size="0.068" rgba="0.21 0.33 0.054 1" friction="0.4 0.1 0.1" fromto="0 0 0 -0.58 0 -0.61"/>
        <body name="body2" pos="-0.58 0 -0.6">
          <geom name="geom2" class="/" type="capsule" contype="1" conaffinity="1" condim="3" size="0.061" rgba="0.18 0.79 0.15 1" friction="0.4 0.1 0.1" fromto="0 0 0 -0.35 0 -0.012"/>
          <body name="body3" pos="-0.34 0 -0.012">
            <geom name="geom3" class="/" type="capsule" contype="1" conaffinity="1" condim="3" size="0.061" rgba="0.17 0.22 0.53 1" friction="0.4 0.1 0.1" fromto="0 0 0 -0.41 0 -0.74"/>
          </body>
          <body name="body4" pos="-0.0076 0 -0.00027">
            <geom name="geom4" class="/" type="capsule" contype="1" conaffinity="1" condim="3" size="0.065" rgba="0.64 0.62 0.64 1" friction="0.4 0.1 0.1" fromto="0 0 0 0.51 0 -0.36"/>
            <body name="body5" pos="0.37 0 -0.27">
              <geom name="geom5" class="/" type="capsule" contype="1" conaffinity="1" condim="3" size="0.062" rgba="0.48 0.96 0.043 1" friction="0.4 0.1 0.1" fromto="0 0 0 0.5 0 0.38"/>
              <joint name="joint5" class="/" type="hinge" axis="0 1 0" limited="true" stiffness="20" range="-43 43" armature="0.1" damping="2"/>
            </body>
            <body name="body6" pos="0.41 0 -0.29">
              <geom name="geom6" class="/" type="capsule" contype="1" conaffinity="1" condim="3" size="0.04" rgba="0.97 0.15 0.99 1" friction="0.4 0.1 0.1" fromto="0 0 0 -0.15 0 -0.51"/>
              <joint name="joint6" class="/" type="hinge" axis="0 1 0" limited="true" stiffness="20" range="-36 36" armature="0.1" damping="2"/>
            </body>
            <joint name="joint4" class="/" type="hinge" axis="0 1 0" limited="true" stiffness="20" range="-70 70" armature="0.1" damping="2"/>
          </body>
        </body>
        <joint name="joint1" class="/" type="hinge" axis="0 1 0" limited="true" stiffness="20" range="-37 37" armature="0.1" damping="2"/>
      </body>
      <joint name="rootx" class="/" type="slide" axis="1 0 0" limited="false" stiffness="0" armature="0" damping="0"/>
      <joint name="rootz" class="/" type="slide" axis="0 0 1" limited="false" stiffness="0" armature="0" damping="0"/>
      <joint name="rooty" class="/" type="hinge" axis="0 1 0" limited="false" stiffness="0" armature="0" damping="0"/>
    </body>
  </worldbody>
  <actuator>
    <motor name="motor5" class="/" ctrllimited="true" ctrlrange="-1 1" gear="1.3e+02" joint="joint5"/>
    <motor name="motor6" class="/" ctrllimited="true" ctrlrange="-1 1" gear="2e+02" joint="joint6"/>
    <motor name="motor4" class="/" ctrllimited="true" ctrlrange="-1 1" gear="1.7e+02" joint="joint4"/>
    <motor name="motor1" class="/" ctrllimited="true" ctrlrange="-1 1" gear="1.3e+02" joint="joint1"/>
  </actuator>
  <sensor>
    <subtreelinvel name="velocity" body="body"/>
  </sensor>
</mujoco>
