<mujoco model="morphology">
    <option timestep="0.01" />
    <custom>
        <!-- brax custom params -->
        <numeric data="1.0 -1.0 0.5 0.5 0.5"
            name="init_qpos" />
        <numeric data="1000" name="constraint_limit_stiffness" />
        <numeric data="4000" name="constraint_stiffness" />
        <numeric data="10" name="constraint_ang_damping" />
        <numeric data="20" name="constraint_vel_damping" />
        <numeric data="0.5" name="joint_scale_pos" />
        <numeric data="0.2" name="joint_scale_ang" />
        <numeric data="0.0" name="ang_damping" />
        <numeric data="1" name="spring_mass_scale" />
        <numeric data="1" name="spring_inertia_scale" />
        <numeric data="15" name="solver_maxls" />
    </custom>
    <default>
        <default class="/" />
        <default class="0/" />
        <default class="0/1/" />
        <default class="0/2/" />
        <default class="0/2/3/" />
        <default class="0/2/4/" />
        <default class="0/2/4/5/" />
        <default class="0/2/4/5/6/" />
        <default class="0/2/4/5/7/" />
        <default class="0/2/4/5/7/8/" />
        <default class="0/2/4/5/7/8/9/" />
        <default class="0/2/4/5/7/8/9/10/" />
    </default>
    <asset>
        <texture name="texplane" type="2d" builtin="checker"
            rgb1="0.10000000000000001 0.20000000000000001 0.29999999999999999"
            rgb2="0.20000000000000001 0.29999999999999999 0.40000000000000002" width="300"
            height="300" />
        <material name="MatPlane" class="/" texture="texplane" texrepeat="20 20" specular="1.0"
            shininess="1.0" reflectance="0.5" />
    </asset>
    <worldbody>
        <light name="//unnamed_light_0" class="/" directional="true" pos="0 0 1.5" dir="0 0 -1.3"
            cutoff="100.0" exponent="1.0" diffuse="1 1 1"
            specular="0.10000000000000001 0.10000000000000001 0.10000000000000001" />
        <geom name="ground" class="/" type="plane" size="15 15 0.5" material="MatPlane"
            rgba="1 1 1 1" />
        <site name="body" class="/"
            size="9.9999999999999995e-07 9.9999999999999995e-07 9.9999999999999995e-07"
            pos="0 0 1.6446825361251831" />
        <body pos="0 0 1.6446825361251831" name="0/">
            <joint name="0/rootx/" class="/" type="slide" axis="1 0 0" stiffness="0.0"
                armature="0.0" damping="0.0" />
            <joint name="0/rootz/" class="/" type="slide" axis="0 0 1" stiffness="0.0"
                armature="0.0" damping="0.0" />
            <joint name="0/rooty/" class="/" type="hinge" axis="0 1 0" stiffness="0.0"
                armature="0.0" damping="0.0" />
            <geom name="0/geom" class="0/" type="capsule" contype="1" conaffinity="1" condim="3"
                size="0.048470334428519793"
                rgba="0.00033081932194189978 0.012455012886624872 0.63742753509390848 1"
                friction="0.59999999999999998 0.10000000000000001 0.10000000000000001"
                fromto="0 0 0 0.43986990955996008 0 0.037582513527956607" />
            <site name="0/end0" class="0/" size="0.0050000000000000001"
                pos="0.43986990955996008 0 0.037582513527956607" />
            <site name="0/attach1" class="0/"
                size="9.9999999999999995e-07 9.9999999999999995e-07 9.9999999999999995e-07"
                pos="0.17738829841916118 0 0.015156067692169723" />
            <body pos="0.17738829841916118 0 0.015156067692169723" name="0/1/">
                <joint name="0/1/joint/" class="0/" type="hinge" axis="0 1 0" limited="true"
                    stiffness="100.0" range="-59.967968634045079 59.967968634045079" armature="0.2"
                    damping="3.5" />
                <geom name="0/1/geom" class="0/1/" type="capsule" contype="1" conaffinity="1"
                    condim="3" size="0.06845958618526804"
                    rgba="0.87108043698540449 0.28535127249538017 0.63559308946676174 1"
                    friction="0.59999999999999998 0.10000000000000001 0.10000000000000001"
                    fromto="0 0 0 0.078363312647046768 0 0.48536182802937633" />
                <site name="0/1/end1" class="0/1/" size="0.0050000000000000001"
                    pos="0.078363312647046768 0 0.48536182802937633" />
            </body>
            <site name="0/attach2" class="0/"
                size="9.9999999999999995e-07 9.9999999999999995e-07 9.9999999999999995e-07"
                pos="0.049972686477538997 0 0.0042696695653705171" />
            <body name="0/2/">
                <geom name="0/2/geom" class="0/2/" type="capsule" contype="1" conaffinity="1"
                    condim="3" size="0.061582705385352127"
                    rgba="0.38364079381896388 0.36142282893249611 0.64819929378094321 1"
                    friction="0.59999999999999998 0.10000000000000001 0.10000000000000001"
                    fromto="0 0 0 0.22686783030327318 0 -0.57716451326855656" />
                <site name="0/2/end2" class="0/2/" size="0.0050000000000000001"
                    pos="0.22686783030327318 0 -0.57716451326855656" />
                <site name="0/2/attach3" class="0/2/"
                    size="9.9999999999999995e-07 9.9999999999999995e-07 9.9999999999999995e-07"
                    pos="0.078730536243448446 0 -0.20029490990229112" />
                <body pos="0.078730536243448446 0 -0.20029490990229112" name="0/2/3/">
                    <joint name="0/2/3/joint/" class="0/2/" type="hinge" axis="0 1 0" limited="true"
                        stiffness="100.0" range="-54.477055309290478 54.477055309290478"
                        armature="0.2" damping="3.5" />
                    <geom name="0/2/3/geom" class="0/2/3/" type="capsule" contype="1"
                        conaffinity="1" condim="3" size="0.063611005932166856"
                        rgba="0.95500026637347413 0.37561256668505105 0.46587947609537039 1"
                        friction="0.59999999999999998 0.10000000000000001 0.10000000000000001"
                        fromto="0 0 0 -0.51610147707469145 0 -0.20343566848311156" />
                    <site name="0/2/3/end3" class="0/2/3/" size="0.0050000000000000001"
                        pos="-0.51610147707469145 0 -0.20343566848311156" />
                </body>
            </body>
        </body>
    </worldbody>
    <actuator>
        <motor name="0/1/motor" class="0/1/" ctrllimited="true" ctrlrange="-1 1" gear="150"
            joint="0/1/joint/" />
        <motor name="0/2/3/motor" class="0/2/3/" ctrllimited="true" ctrlrange="-1 1" gear="150"
            joint="0/2/3/joint/" />
    </actuator>
    <sensor>
        <subtreelinvel name="velocity" body="0/" />
    </sensor>
</mujoco>