<mujoco model="morphology">
  <option timestep="0.01"/>
  <default>
    <default class="/"/>
  </default>
  <asset>
    <texture name="texplane" type="2d" builtin="checker" rgb1="0.1 0.2 0.3" rgb2="0.2 0.3 0.4" width="300" height="300"/>
    <material name="MatPlane" class="/" texture="texplane" texrepeat="20 20" specular="1" shininess="1" reflectance="0.5"/>
  </asset>
  <worldbody>
    <light name="//unnamed_light_0" class="/" directional="true" pos="0 0 1.5" dir="0 0 -1.3" cutoff="1e+02" exponent="1" diffuse="1 1 1" specular="0.1 0.1 0.1"/>
    <geom name="ground" class="/" type="plane" size="15 15 0.5" material="MatPlane" rgba="1 1 1 1"/>
    <body name="body" pos="0 0 0.32">
      <geom name="geom0" class="/" type="capsule" contype="1" conaffinity="1" condim="3" size="0.055" rgba="0.34 0.018 0.27 1" friction="0.4 0.1 0.1" fromto="0 0 0 0.19 0 -0.22"/>
      <body name="body1" pos="0.074 0 -0.085">
        <geom name="geom1" class="/" type="capsule" contype="1" conaffinity="1" condim="3" size="0.058" rgba="0.79 0.82 0.97 1" friction="0.4 0.1 0.1" fromto="0 0 0 0.48 0 0.43"/>
        <body name="body2" pos="0.44 0 0.39">
          <geom name="geom2" class="/" type="capsule" contype="1" conaffinity="1" condim="3" size="0.04" rgba="0.6 0.83 0.21 1" friction="0.4 0.1 0.1" fromto="0 0 0 -0.52 0 0.6"/>
          <body name="body3" pos="-0.4 0 0.46">
            <geom name="geom3" class="/" type="capsule" contype="1" conaffinity="1" condim="3" size="0.049" rgba="0.6 0.46 0.47 1" friction="0.4 0.1 0.1" fromto="0 0 0 0.53 0 0.46"/>
            <joint name="joint3" class="/" type="hinge" axis="0 1 0" limited="true" stiffness="20" range="-37 37" armature="0.1" damping="2"/>
          </body>
          <joint name="joint2" class="/" type="hinge" axis="0 1 0" limited="true" stiffness="20" range="-42 42" armature="0.1" damping="2"/>
        </body>
        <joint name="joint1" class="/" type="hinge" axis="0 1 0" limited="true" stiffness="20" range="-57 57" armature="0.1" damping="2"/>
      </body>
      <joint name="rootx" class="/" type="slide" axis="1 0 0" limited="false" stiffness="0" armature="0" damping="0"/>
      <joint name="rootz" class="/" type="slide" axis="0 0 1" limited="false" stiffness="0" armature="0" damping="0"/>
      <joint name="rooty" class="/" type="hinge" axis="0 1 0" limited="false" stiffness="0" armature="0" damping="0"/>
    </body>
  </worldbody>
  <actuator>
    <motor name="motor3" class="/" ctrllimited="true" ctrlrange="-1 1" gear="1.7e+02" joint="joint3"/>
    <motor name="motor2" class="/" ctrllimited="true" ctrlrange="-1 1" gear="1.1e+02" joint="joint2"/>
    <motor name="motor1" class="/" ctrllimited="true" ctrlrange="-1 1" gear="1.5e+02" joint="joint1"/>
  </actuator>
  <sensor>
    <subtreelinvel name="velocity" body="body"/>
  </sensor>
</mujoco>
