<mujoco model="morphology">
  <option timestep="0.01"/>
  <default>
    <default class="/"/>
    <default class="0/"/>
    <default class="0/1/"/>
    <default class="0/1/2/"/>
    <default class="0/1/2/3/"/>
    <default class="0/1/4/"/>
  </default>
  <asset>
    <texture name="texplane" type="2d" builtin="checker" rgb1="0.10000000000000001 0.20000000000000001 0.29999999999999999" rgb2="0.20000000000000001 0.29999999999999999 0.40000000000000002" width="300" height="300"/>
    <material name="MatPlane" class="/" texture="texplane" texrepeat="20 20" specular="1" shininess="1" reflectance="0.5"/>
  </asset>
  <worldbody>
    <light name="//unnamed_light_0" class="/" directional="true" pos="0 0 1.5" dir="0 0 -1.3" cutoff="100" exponent="1" diffuse="1 1 1" specular="0.10000000000000001 0.10000000000000001 0.10000000000000001"/>
    <geom name="ground" class="/" type="plane" size="15 15 0.5" material="MatPlane" rgba="1 1 1 1"/>
    <site name="body" class="/" size="9.9999999999999995e-07 9.9999999999999995e-07 9.9999999999999995e-07" pos="0 0 1.8326958179473878"/>
    <body pos="0 0 1.8326958179473878" name="0/">
      <freejoint name="0/"/>
      <geom name="0/geom" class="0/" type="capsule" contype="1" conaffinity="1" condim="3" size="0.056336503868757944" rgba="0.51586993821538762 0.61249467600173113 0.79622961463894038 1" friction="0.59999999999999998 0.10000000000000001 0.10000000000000001" fromto="0 0 0 -0.43156729249210818 -0.12117074761130098 -0.15046444284141547"/>
      <site name="0/end0" class="0/" size="0.0050000000000000001" pos="-0.43156729249210818 -0.12117074761130098 -0.15046444284141547"/>
      <site name="0/attach1" class="0/" size="9.9999999999999995e-07 9.9999999999999995e-07 9.9999999999999995e-07" pos="-0.25242642817930977 -0.070873533632988789 -0.088007600518389531"/>
      <body pos="-0.25242642817930977 -0.070873533632988789 -0.088007600518389531" name="0/1/">
        <joint name="0/1/joint/" class="0/" type="hinge" axis="0 0 1" limited="true" range="-47.766716354235307 47.766716354235307"/>
        <geom name="0/1/geom" class="0/1/" type="capsule" contype="1" conaffinity="1" condim="3" size="0.063706996767526392" rgba="0.85477594510078159 0.98047718480625101 0.46260916157016541 1" friction="0.59999999999999998 0.10000000000000001 0.10000000000000001" fromto="0 0 0 -0.72107445991919961 0.67867791697864366 -0.5461494859470013"/>
        <site name="0/1/end1" class="0/1/" size="0.0050000000000000001" pos="-0.72107445991919961 0.67867791697864366 -0.5461494859470013"/>
        <site name="0/1/attach2" class="0/1/" size="9.9999999999999995e-07 9.9999999999999995e-07 9.9999999999999995e-07" pos="-0.68761960971353808 0.64719008969801139 -0.5208104256170828"/>
        <body pos="-0.68761960971353808 0.64719008969801139 -0.5208104256170828" name="0/1/2/">
          <joint name="0/1/2/joint/" class="0/1/" type="hinge" axis="0 0.62693732136325564 0.77906969847496021" limited="true" range="-56.100287347911099 56.100287347911099"/>
          <geom name="0/1/2/geom" class="0/1/2/" type="capsule" contype="1" conaffinity="1" condim="3" size="0.053043907416873759" rgba="0.60600735552925122 0.67594450006045426 0.79038586049161919 1" friction="0.59999999999999998 0.10000000000000001 0.10000000000000001" fromto="0 0 0 -0.29225928404024504 -0.33219860461701373 -0.74099356337821343"/>
          <site name="0/1/2/end2" class="0/1/2/" size="0.0050000000000000001" pos="-0.29225928404024504 -0.33219860461701373 -0.74099356337821343"/>
          <site name="0/1/2/attach3" class="0/1/2/" size="9.9999999999999995e-07 9.9999999999999995e-07 9.9999999999999995e-07" pos="-0.22861567318255083 -0.25985763933632522 -0.57963168859443348"/>
          <body pos="-0.22861567318255083 -0.25985763933632522 -0.57963168859443348" name="0/1/2/3/">
            <joint name="0/1/2/3/joint/" class="0/1/2/" type="hinge" axis="-5.5511151231257827e-17 -0.91249595886582324 0.40908571846685382" limited="true" range="-34.955247133298805 34.955247133298805"/>
            <geom name="0/1/2/3/geom" class="0/1/2/3/" type="capsule" contype="1" conaffinity="1" condim="3" size="0.054040971527308093" rgba="0.71262871134664996 0.58466625759809698 0.63437658733802837 1" friction="0.59999999999999998 0.10000000000000001 0.10000000000000001" fromto="0 0 0 0.40160477413835327 -0.025147401928936275 -0.54424609170085891"/>
            <site name="0/1/2/3/end3" class="0/1/2/3/" size="0.0050000000000000001" pos="0.40160477413835327 -0.025147401928936275 -0.54424609170085891"/>
          </body>
        </body>
        <site name="0/1/attach4" class="0/1/" size="9.9999999999999995e-07 9.9999999999999995e-07 9.9999999999999995e-07" pos="-0.43246917367547411 0.40704156680356585 -0.32755676427265407"/>
        <body pos="-0.43246917367547411 0.40704156680356585 -0.32755676427265407" name="0/1/4/">
          <joint name="0/1/4/joint/" class="0/1/" type="hinge" axis="0 0.62693732136325564 0.77906969847496021" limited="true" range="-44.227890075155798 44.227890075155798"/>
          <geom name="0/1/4/geom" class="0/1/4/" type="capsule" contype="1" conaffinity="1" condim="3" size="0.046020311166298025" rgba="0.11247287981213705 0.71702080662030421 0.091753527426313819 1" friction="0.59999999999999998 0.10000000000000001 0.10000000000000001" fromto="0 0 0 -0.20093127839928582 -0.73777268498444371 -0.16214292941306652"/>
          <site name="0/1/4/end4" class="0/1/4/" size="0.0050000000000000001" pos="-0.20093127839928582 -0.73777268498444371 -0.16214292941306652"/>
        </body>
      </body>
      <camera name="0/iso" class="0/" mode="trackcom" pos="-2.2999999999999998 -2.2999999999999998 1" xyaxes="0.45000000000000001 -0.45000000000000001 0 0.29999999999999999 0.14999999999999999 0.93999999999999995"/>
    </body>
  </worldbody>
  <actuator>
    <motor name="0/1/motor" class="0/1/" ctrllimited="true" ctrlrange="-1 1" gear="93" joint="0/1/joint/"/>
    <motor name="0/1/2/motor" class="0/1/2/" ctrllimited="true" ctrlrange="-1 1" gear="64" joint="0/1/2/joint/"/>
    <motor name="0/1/2/3/motor" class="0/1/2/3/" ctrllimited="true" ctrlrange="-1 1" gear="89" joint="0/1/2/3/joint/"/>
    <motor name="0/1/4/motor" class="0/1/4/" ctrllimited="true" ctrlrange="-1 1" gear="64" joint="0/1/4/joint/"/>
  </actuator>
  <sensor>
    <subtreelinvel name="velocity" body="0/"/>
  </sensor>
</mujoco>
