<mujoco model="morphology">
  <option timestep="0.01"/>
  <default>
    <default class="/"/>
    <default class="0/"/>
    <default class="0/1/"/>
    <default class="0/1/2/"/>
    <default class="0/1/2/3/"/>
    <default class="0/1/2/3/4/"/>
    <default class="0/1/2/3/4/5/"/>
    <default class="0/1/2/3/4/5/6/"/>
    <default class="0/1/2/3/4/5/7/"/>
    <default class="0/1/2/3/4/5/7/8/"/>
    <default class="0/1/2/3/4/5/7/9/"/>
    <default class="0/1/2/3/4/5/7/10/"/>
  </default>
  <asset>
    <texture name="texplane" type="2d" builtin="checker" rgb1="0.10000000000000001 0.20000000000000001 0.29999999999999999" rgb2="0.20000000000000001 0.29999999999999999 0.40000000000000002" width="300" height="300"/>
    <material name="MatPlane" class="/" texture="texplane" texrepeat="20 20" specular="1" shininess="1" reflectance="0.5"/>
  </asset>
  <worldbody>
    <light name="//unnamed_light_0" class="/" directional="true" pos="0 0 1.5" dir="0 0 -1.3" cutoff="100" exponent="1" diffuse="1 1 1" specular="0.10000000000000001 0.10000000000000001 0.10000000000000001"/>
    <geom name="ground" class="/" type="plane" size="15 15 0.5" material="MatPlane" rgba="1 1 1 1"/>
    <site name="body" class="/" size="9.9999999999999995e-07 9.9999999999999995e-07 9.9999999999999995e-07" pos="0 0 0.10000000000000001"/>
    <body pos="0 0 0.10000000000000001" name="0/">
      <freejoint name="0/"/>
      <geom name="0/geom" class="0/" type="capsule" contype="1" conaffinity="1" condim="3" size="0.054507168964480435" rgba="0.62453659283921414 0.35127093726801051 0.13264525095161073 1" friction="0.59999999999999998 0.10000000000000001 0.10000000000000001" fromto="0 0 0 -0.47782906776087697 0.60289610987872799 0.70110744806416259"/>
      <site name="0/end0" class="0/" size="0.0050000000000000001" pos="-0.47782906776087697 0.60289610987872799 0.70110744806416259"/>
      <site name="0/attach1" class="0/" size="9.9999999999999995e-07 9.9999999999999995e-07 9.9999999999999995e-07" pos="-0.37178074090435209 0.46909068020791811 0.5455052111339882"/>
      <body pos="-0.37178074090435209 0.46909068020791811 0.5455052111339882" name="0/1/">
        <joint name="0/1/joint/" class="0/" type="hinge" axis="0 0 1" limited="true" range="-46.941618258758034 46.941618258758034"/>
        <geom name="0/1/geom" class="0/1/" type="capsule" contype="1" conaffinity="1" condim="3" size="0.053397911091499009" rgba="0.35703282944848747 0.95921609927979223 0.54367943420057374 1" friction="0.59999999999999998 0.10000000000000001 0.10000000000000001" fromto="0 0 0 0.094912398398448561 -0.40941290420990467 0.19776220794332899"/>
        <site name="0/1/end1" class="0/1/" size="0.0050000000000000001" pos="0.094912398398448561 -0.40941290420990467 0.19776220794332899"/>
        <site name="0/1/attach2" class="0/1/" size="9.9999999999999995e-07 9.9999999999999995e-07 9.9999999999999995e-07" pos="0.053048165939884581 -0.22882788810457569 0.11053268698968166"/>
        <body pos="0.053048165939884581 -0.22882788810457569 0.11053268698968166" name="0/1/2/">
          <joint name="0/1/2/joint/" class="0/1/" type="hinge" axis="0.97889928331289056 0.18400154348040226 -0.088879835319036538" limited="true" range="-57.35434846707939 57.35434846707939"/>
          <geom name="0/1/2/geom" class="0/1/2/" type="capsule" contype="1" conaffinity="1" condim="3" size="0.058498902455957388" rgba="0.20629463175000951 0.26519814324474433 0.55359092312412106 1" friction="0.59999999999999998 0.10000000000000001 0.10000000000000001" fromto="0 0 0 0.54423130843692968 -0.49984575675627285 -0.54233497869187386"/>
          <site name="0/1/2/end2" class="0/1/2/" size="0.0050000000000000001" pos="0.54423130843692968 -0.49984575675627285 -0.54233497869187386"/>
          <site name="0/1/2/attach3" class="0/1/2/" size="9.9999999999999995e-07 9.9999999999999995e-07 9.9999999999999995e-07" pos="0.37825386874207162 -0.34740484117017612 -0.37693587389069461"/>
          <body pos="0.37825386874207162 -0.34740484117017612 -0.37693587389069461" name="0/1/2/3/">
            <joint name="0/1/2/3/joint/" class="0/1/2/" type="hinge" axis="0 -0.73532433675295628 0.67771536781957697" limited="true" range="-68.047700978646233 68.047700978646233"/>
            <geom name="0/1/2/3/geom" class="0/1/2/3/" type="capsule" contype="1" conaffinity="1" condim="3" size="0.047681439258531064" rgba="0.36061347943699162 0.65778041739896276 0.42045307785985231 1" friction="0.59999999999999998 0.10000000000000001 0.10000000000000001" fromto="0 0 0 0.14911600088260679 0.63995662927067287 0.38039596653990992"/>
            <site name="0/1/2/3/end3" class="0/1/2/3/" size="0.0050000000000000001" pos="0.14911600088260679 0.63995662927067287 0.38039596653990992"/>
            <site name="0/1/2/3/attach4" class="0/1/2/3/" size="9.9999999999999995e-07 9.9999999999999995e-07 9.9999999999999995e-07" pos="0.045250738608270287 0.19420122575950019 0.11543495230326807"/>
            <body pos="0.045250738608270287 0.19420122575950019 0.11543495230326807" name="0/1/2/3/4/">
              <joint name="0/1/2/3/4/joint/" class="0/1/2/3/" type="hinge" axis="5.5511151231257827e-17 -0.51095750751741875 0.85960597107720638" limited="true" range="-33.847037841946324 33.847037841946324"/>
              <geom name="0/1/2/3/4/geom" class="0/1/2/3/4/" type="capsule" contype="1" conaffinity="1" condim="3" size="0.039131892345375716" rgba="0.94286008612857419 0.0030921355780813009 0.94060806899888749 1" friction="0.59999999999999998 0.10000000000000001 0.10000000000000001" fromto="0 0 0 0.7005754277901759 -0.27598148006891771 0.090976021610610358"/>
              <site name="0/1/2/3/4/end4" class="0/1/2/3/4/" size="0.0050000000000000001" pos="0.7005754277901759 -0.27598148006891771 0.090976021610610358"/>
              <site name="0/1/2/3/4/attach5" class="0/1/2/3/4/" size="9.9999999999999995e-07 9.9999999999999995e-07 9.9999999999999995e-07" pos="0.28828507294583045 -0.11356570321674915 0.037436410107993846"/>
              <body pos="0.28828507294583045 -0.11356570321674915 0.037436410107993846" name="0/1/2/3/4/5/">
                <joint name="0/1/2/3/4/5/joint/" class="0/1/2/3/4/" type="hinge" axis="0.38313570921628054 0.87725697883267839 -0.28918371567690199" limited="true" range="-62.712404817235061 62.712404817235061"/>
                <geom name="0/1/2/3/4/5/geom" class="0/1/2/3/4/5/" type="capsule" contype="1" conaffinity="1" condim="3" size="0.047216132642779782" rgba="0.9859398175762506 0.77863056951092324 0.44415725421471663 1" friction="0.59999999999999998 0.10000000000000001 0.10000000000000001" fromto="0 0 0 -0.34553371325959009 -0.67072308343969544 0.62072627155992377"/>
                <site name="0/1/2/3/4/5/end5" class="0/1/2/3/4/5/" size="0.0050000000000000001" pos="-0.34553371325959009 -0.67072308343969544 0.62072627155992377"/>
                <site name="0/1/2/3/4/5/attach6" class="0/1/2/3/4/5/" size="9.9999999999999995e-07 9.9999999999999995e-07 9.9999999999999995e-07" pos="-0.28370090976391066 -0.550698069882811 0.50964812172643492"/>
                <body pos="-0.28370090976391066 -0.550698069882811 0.50964812172643492" name="0/1/2/3/4/5/6/">
                  <joint name="0/1/2/3/4/5/6/joint/" class="0/1/2/3/4/5/" type="hinge" axis="-5.5511151231257827e-17 0.67922324239237108 0.73393173183477645" limited="true" range="-43.941008244774324 43.941008244774324"/>
                  <geom name="0/1/2/3/4/5/6/geom" class="0/1/2/3/4/5/6/" type="capsule" contype="1" conaffinity="1" condim="3" size="0.057982811104787556" rgba="0.30313304735417368 0.93799296736612459 0.41083379298432654 1" friction="0.59999999999999998 0.10000000000000001 0.10000000000000001" fromto="0 0 0 -0.7302288581640517 0.13250327115746741 0.33618848724113404"/>
                  <site name="0/1/2/3/4/5/6/end6" class="0/1/2/3/4/5/6/" size="0.0050000000000000001" pos="-0.7302288581640517 0.13250327115746741 0.33618848724113404"/>
                </body>
                <site name="0/1/2/3/4/5/attach7" class="0/1/2/3/4/5/" size="9.9999999999999995e-07 9.9999999999999995e-07 9.9999999999999995e-07" pos="-0.30809243207736176 -0.59804498981584597 0.55346572366307889"/>
                <body pos="-0.30809243207736176 -0.59804498981584597 0.55346572366307889" name="0/1/2/3/4/5/7/">
                  <joint name="0/1/2/3/4/5/7/joint/" class="0/1/2/3/4/5/" type="hinge" axis="-5.5511151231257827e-17 0.67922324239237108 0.73393173183477645" limited="true" range="-35.102558863621539 35.102558863621539"/>
                  <geom name="0/1/2/3/4/5/7/geom" class="0/1/2/3/4/5/7/" type="capsule" contype="1" conaffinity="1" condim="3" size="0.042535218294033263" rgba="0.83812721638333321 0.67711312003624724 0.050167494477075691 1" friction="0.59999999999999998 0.10000000000000001 0.10000000000000001" fromto="0 0 0 0.4480986362328534 -0.074606804955300809 -0.35674386236400091"/>
                  <site name="0/1/2/3/4/5/7/end7" class="0/1/2/3/4/5/7/" size="0.0050000000000000001" pos="0.4480986362328534 -0.074606804955300809 -0.35674386236400091"/>
                  <site name="0/1/2/3/4/5/7/attach8" class="0/1/2/3/4/5/7/" size="9.9999999999999995e-07 9.9999999999999995e-07 9.9999999999999995e-07" pos="0.32157950672336305 -0.053541826722419208 -0.25601844328307211"/>
                  <body pos="0.32157950672336305 -0.053541826722419208 -0.25601844328307211" name="0/1/2/3/4/5/7/8/">
                    <joint name="0/1/2/3/4/5/7/8/joint/" class="0/1/2/3/4/5/7/" type="hinge" axis="0 -0.97882390627401505 0.20470408033666077" limited="true" range="-31.556038239038863 31.556038239038863"/>
                    <geom name="0/1/2/3/4/5/7/8/geom" class="0/1/2/3/4/5/7/8/" type="capsule" contype="1" conaffinity="1" condim="3" size="0.05845452067537478" rgba="0.71355697004662977 0.51681506580840531 0.019434842609058478 1" friction="0.59999999999999998 0.10000000000000001 0.10000000000000001" fromto="0 0 0 0.2805831406680368 -0.38398842541537626 -0.063627580683590312"/>
                    <site name="0/1/2/3/4/5/7/8/end8" class="0/1/2/3/4/5/7/8/" size="0.0050000000000000001" pos="0.2805831406680368 -0.38398842541537626 -0.063627580683590312"/>
                  </body>
                  <site name="0/1/2/3/4/5/7/attach9" class="0/1/2/3/4/5/7/" size="9.9999999999999995e-07 9.9999999999999995e-07 9.9999999999999995e-07" pos="0.13303031277174671 -0.022149066735715043 -0.10590915426268491"/>
                  <body pos="0.13303031277174671 -0.022149066735715043 -0.10590915426268491" name="0/1/2/3/4/5/7/9/">
                    <geom name="0/1/2/3/4/5/7/9/geom" class="0/1/2/3/4/5/7/9/" type="capsule" contype="1" conaffinity="1" condim="3" size="0.06298010226397413" rgba="0.59950815211373953 0.726614511772677 0.21966665697619048 1" friction="0.59999999999999998 0.10000000000000001 0.10000000000000001" fromto="0 0 0 0.11207620653979156 0.42097731368328484 0.32856564210748118"/>
                    <site name="0/1/2/3/4/5/7/9/end9" class="0/1/2/3/4/5/7/9/" size="0.0050000000000000001" pos="0.11207620653979156 0.42097731368328484 0.32856564210748118"/>
                  </body>
                  <site name="0/1/2/3/4/5/7/attach10" class="0/1/2/3/4/5/7/" size="9.9999999999999995e-07 9.9999999999999995e-07 9.9999999999999995e-07" pos="0.20421436677726534 -0.03400095469896601 -0.1625807714274829"/>
                  <body pos="0.20421436677726534 -0.03400095469896601 -0.1625807714274829" name="0/1/2/3/4/5/7/10/">
                    <joint name="0/1/2/3/4/5/7/10/joint/" class="0/1/2/3/4/5/7/" type="hinge" axis="0.63099049001553076 0.15880749424336793 0.75936235176765454" limited="true" range="-38.56528929622273 38.56528929622273"/>
                    <geom name="0/1/2/3/4/5/7/10/geom" class="0/1/2/3/4/5/7/10/" type="capsule" contype="1" conaffinity="1" condim="3" size="0.068832747492141882" rgba="0.9165553878447299 0.51317213389381156 0.61101350381814057 1" friction="0.59999999999999998 0.10000000000000001 0.10000000000000001" fromto="0 0 0 0.73242111526828202 0.57453593540450631 0.28618324958334806"/>
                    <site name="0/1/2/3/4/5/7/10/end10" class="0/1/2/3/4/5/7/10/" size="0.0050000000000000001" pos="0.73242111526828202 0.57453593540450631 0.28618324958334806"/>
                  </body>
                </body>
              </body>
            </body>
          </body>
        </body>
      </body>
      <camera name="0/iso" class="0/" mode="trackcom" pos="-2.2999999999999998 -2.2999999999999998 1" xyaxes="0.45000000000000001 -0.45000000000000001 0 0.29999999999999999 0.14999999999999999 0.93999999999999995"/>
    </body>
  </worldbody>
  <actuator>
    <motor name="0/1/motor" class="0/1/" ctrllimited="true" ctrlrange="-1 1" gear="58" joint="0/1/joint/"/>
    <motor name="0/1/2/motor" class="0/1/2/" ctrllimited="true" ctrlrange="-1 1" gear="67" joint="0/1/2/joint/"/>
    <motor name="0/1/2/3/motor" class="0/1/2/3/" ctrllimited="true" ctrlrange="-1 1" gear="80" joint="0/1/2/3/joint/"/>
    <motor name="0/1/2/3/4/motor" class="0/1/2/3/4/" ctrllimited="true" ctrlrange="-1 1" gear="58" joint="0/1/2/3/4/joint/"/>
    <motor name="0/1/2/3/4/5/motor" class="0/1/2/3/4/5/" ctrllimited="true" ctrlrange="-1 1" gear="64" joint="0/1/2/3/4/5/joint/"/>
    <motor name="0/1/2/3/4/5/6/motor" class="0/1/2/3/4/5/6/" ctrllimited="true" ctrlrange="-1 1" gear="90" joint="0/1/2/3/4/5/6/joint/"/>
    <motor name="0/1/2/3/4/5/7/motor" class="0/1/2/3/4/5/7/" ctrllimited="true" ctrlrange="-1 1" gear="50" joint="0/1/2/3/4/5/7/joint/"/>
    <motor name="0/1/2/3/4/5/7/8/motor" class="0/1/2/3/4/5/7/8/" ctrllimited="true" ctrlrange="-1 1" gear="72" joint="0/1/2/3/4/5/7/8/joint/"/>
    <motor name="0/1/2/3/4/5/7/10/motor" class="0/1/2/3/4/5/7/10/" ctrllimited="true" ctrlrange="-1 1" gear="82" joint="0/1/2/3/4/5/7/10/joint/"/>
  </actuator>
  <sensor>
    <subtreelinvel name="velocity" body="0/"/>
  </sensor>
</mujoco>
