<mujoco model="morphology">
  <option timestep="0.01"/>
  <default>
    <default class="/"/>
    <default class="0/"/>
    <default class="0/1/"/>
    <default class="0/1/2/"/>
    <default class="0/1/2/3/"/>
    <default class="0/1/2/3/4/"/>
    <default class="0/1/2/3/4/5/"/>
    <default class="0/1/2/3/4/5/6/"/>
    <default class="0/1/2/3/4/5/7/"/>
  </default>
  <asset>
    <texture name="texplane" type="2d" builtin="checker" rgb1="0.10000000000000001 0.20000000000000001 0.29999999999999999" rgb2="0.20000000000000001 0.29999999999999999 0.40000000000000002" width="300" height="300"/>
    <material name="MatPlane" class="/" texture="texplane" texrepeat="20 20" specular="1" shininess="1" reflectance="0.5"/>
  </asset>
  <worldbody>
    <light name="//unnamed_light_0" class="/" directional="true" pos="0 0 1.5" dir="0 0 -1.3" cutoff="100" exponent="1" diffuse="1 1 1" specular="0.10000000000000001 0.10000000000000001 0.10000000000000001"/>
    <geom name="ground" class="/" type="plane" size="15 15 0.5" material="MatPlane" rgba="1 1 1 1"/>
    <site name="body" class="/" size="9.9999999999999995e-07 9.9999999999999995e-07 9.9999999999999995e-07" pos="0 0 1.2394549608230592"/>
    <body pos="0 0 1.2394549608230592" name="0/">
      <freejoint name="0/"/>
      <geom name="0/geom" class="0/" type="capsule" contype="1" conaffinity="1" condim="3" size="0.03647214121056324" rgba="0.62316046877954323 0.48137556613810828 0.12364297425976611 1" friction="0.59999999999999998 0.10000000000000001 0.10000000000000001" fromto="0 0 0 -0.49329169180551491 0.63422859188518466 -0.19662059656362663"/>
      <site name="0/end0" class="0/" size="0.0050000000000000001" pos="-0.49329169180551491 0.63422859188518466 -0.19662059656362663"/>
      <site name="0/attach1" class="0/" size="9.9999999999999995e-07 9.9999999999999995e-07 9.9999999999999995e-07" pos="-0.34125606155464461 0.43875531452781391 -0.13602088078605212"/>
      <body pos="-0.34125606155464461 0.43875531452781391 -0.13602088078605212" name="0/1/">
        <joint name="0/1/joint/" class="0/" type="hinge" axis="0 1 0" limited="true" range="-53.699059147865427 53.699059147865427"/>
        <geom name="0/1/geom" class="0/1/" type="capsule" contype="1" conaffinity="1" condim="3" size="0.035345967259620525" rgba="0.12581054960879368 0.72406046469507013 0.52602116580858249 1" friction="0.59999999999999998 0.10000000000000001 0.10000000000000001" fromto="0 0 0 0.22850712387470118 0.63041008225584116 -0.61354593715840089"/>
        <site name="0/1/end1" class="0/1/" size="0.0050000000000000001" pos="0.22850712387470118 0.63041008225584116 -0.61354593715840089"/>
        <site name="0/1/attach2" class="0/1/" size="9.9999999999999995e-07 9.9999999999999995e-07 9.9999999999999995e-07" pos="0.17605867884326917 0.48571424964544851 -0.47272087309188171"/>
        <body pos="0.17605867884326917 0.48571424964544851 -0.47272087309188171" name="0/1/2/">
          <joint name="0/1/2/joint/" class="0/1/" type="hinge" axis="-5.5511151231257827e-17 0.69745653994625578 0.71662708216072668" limited="true" range="-54.76986833234038 54.76986833234038"/>
          <geom name="0/1/2/geom" class="0/1/2/" type="capsule" contype="1" conaffinity="1" condim="3" size="0.068226576431637487" rgba="0.85490065610347132 0.34275512897403915 0.86858177266368009 1" friction="0.59999999999999998 0.10000000000000001 0.10000000000000001" fromto="0 0 0 0.35660087811895536 -0.13877056939513055 -0.5307132007385974"/>
          <site name="0/1/2/end2" class="0/1/2/" size="0.0050000000000000001" pos="0.35660087811895536 -0.13877056939513055 -0.5307132007385974"/>
          <site name="0/1/2/attach3" class="0/1/2/" size="9.9999999999999995e-07 9.9999999999999995e-07 9.9999999999999995e-07" pos="0.27118337449890167 -0.10553050650972343 -0.40359013535405996"/>
          <body pos="0.27118337449890167 -0.10553050650972343 -0.40359013535405996" name="0/1/2/3/">
            <joint name="0/1/2/3/joint/" class="0/1/2/" type="hinge" axis="-5.5511151231257827e-17 -0.96747300879740861 0.25297426202775886" limited="true" range="-68.179627718976207 68.179627718976207"/>
            <geom name="0/1/2/3/geom" class="0/1/2/3/" type="capsule" contype="1" conaffinity="1" condim="3" size="0.055793075648931725" rgba="0.20718368533446418 0.77031060622814806 0.9790231058461708 1" friction="0.59999999999999998 0.10000000000000001 0.10000000000000001" fromto="0 0 0 0.077316778160228639 -0.70878382062452827 0.11638310451797018"/>
            <site name="0/1/2/3/end3" class="0/1/2/3/" size="0.0050000000000000001" pos="0.077316778160228639 -0.70878382062452827 0.11638310451797018"/>
            <site name="0/1/2/3/attach4" class="0/1/2/3/" size="9.9999999999999995e-07 9.9999999999999995e-07 9.9999999999999995e-07" pos="0.073525386613328997 -0.67402710869162741 0.1106760131314547"/>
            <body pos="0.073525386613328997 -0.67402710869162741 0.1106760131314547" name="0/1/2/3/4/">
              <joint name="0/1/2/3/4/joint/" class="0/1/2/3/" type="hinge" axis="0 0.16203131367712742 0.98678561673144805" limited="true" range="-36.828693846225271 36.828693846225271"/>
              <geom name="0/1/2/3/4/geom" class="0/1/2/3/4/" type="capsule" contype="1" conaffinity="1" condim="3" size="0.069759299293636237" rgba="0.46987628989037011 0.19571686073182359 0.98728086226264833 1" friction="0.59999999999999998 0.10000000000000001 0.10000000000000001" fromto="0 0 0 0.33624115193392412 -0.34181772515294906 -0.1705445707483968"/>
              <site name="0/1/2/3/4/end4" class="0/1/2/3/4/" size="0.0050000000000000001" pos="0.33624115193392412 -0.34181772515294906 -0.1705445707483968"/>
              <site name="0/1/2/3/4/attach5" class="0/1/2/3/4/" size="9.9999999999999995e-07 9.9999999999999995e-07 9.9999999999999995e-07" pos="0.0012541639055198394 -0.0012749642650462191 -0.00063612334089625734"/>
              <body pos="0.0012541639055198394 -0.0012749642650462191 -0.00063612334089625734" name="0/1/2/3/4/5/">
                <joint name="0/1/2/3/4/5/joint/" class="0/1/2/3/4/" type="hinge" axis="0.75063533340154398 0.59121482776762002 0.29497732739459187" limited="true" range="-45.34225045253396 45.34225045253396"/>
                <geom name="0/1/2/3/4/5/geom" class="0/1/2/3/4/5/" type="capsule" contype="1" conaffinity="1" condim="3" size="0.062402329679940853" rgba="0.29946903805724856 0.77893727257310363 0.016405477278434111 1" friction="0.59999999999999998 0.10000000000000001 0.10000000000000001" fromto="0 0 0 -0.297566206435041 -0.5208446533739215 0.50756705683409686"/>
                <site name="0/1/2/3/4/5/end5" class="0/1/2/3/4/5/" size="0.0050000000000000001" pos="-0.297566206435041 -0.5208446533739215 0.50756705683409686"/>
                <site name="0/1/2/3/4/5/attach6" class="0/1/2/3/4/5/" size="9.9999999999999995e-07 9.9999999999999995e-07 9.9999999999999995e-07" pos="-0.18679608588269336 -0.32695830540964194 0.31862334327371045"/>
                <body pos="-0.18679608588269336 -0.32695830540964194 0.31862334327371045" name="0/1/2/3/4/5/6/">
                  <joint name="0/1/2/3/4/5/6/joint/" class="0/1/2/3/4/5/" type="hinge" axis="0.92552386385254115 -0.27120832933588396 0.26429456963453113" limited="true" range="-34.62717322481997 34.62717322481997"/>
                  <geom name="0/1/2/3/4/5/6/geom" class="0/1/2/3/4/5/6/" type="capsule" contype="1" conaffinity="1" condim="3" size="0.055161147614248243" rgba="0.88019317586830192 0.69790191680196878 0.055837809323199816 1" friction="0.59999999999999998 0.10000000000000001 0.10000000000000001" fromto="0 0 0 -0.39167637298646302 -0.48004435383134314 -0.5501958114876746"/>
                  <site name="0/1/2/3/4/5/6/end6" class="0/1/2/3/4/5/6/" size="0.0050000000000000001" pos="-0.39167637298646302 -0.48004435383134314 -0.5501958114876746"/>
                </body>
                <site name="0/1/2/3/4/5/attach7" class="0/1/2/3/4/5/" size="9.9999999999999995e-07 9.9999999999999995e-07 9.9999999999999995e-07" pos="-0.038411650740564941 -0.067233786911408314 0.065519834218083189"/>
                <body pos="-0.038411650740564941 -0.067233786911408314 0.065519834218083189" name="0/1/2/3/4/5/7/">
                  <geom name="0/1/2/3/4/5/7/geom" class="0/1/2/3/4/5/7/" type="capsule" contype="1" conaffinity="1" condim="3" size="0.038346520681988627" rgba="0.53790743414682307 0.83629363548722069 0.91088669025384317 1" friction="0.59999999999999998 0.10000000000000001 0.10000000000000001" fromto="0 0 0 -0.29243310443237963 0.27327001669172013 0.70305937894929982"/>
                  <site name="0/1/2/3/4/5/7/end7" class="0/1/2/3/4/5/7/" size="0.0050000000000000001" pos="-0.29243310443237963 0.27327001669172013 0.70305937894929982"/>
                </body>
              </body>
            </body>
          </body>
        </body>
      </body>
      <camera name="0/iso" class="0/" mode="trackcom" pos="-2.2999999999999998 -2.2999999999999998 1" xyaxes="0.45000000000000001 -0.45000000000000001 0 0.29999999999999999 0.14999999999999999 0.93999999999999995"/>
    </body>
  </worldbody>
  <actuator>
    <motor name="0/1/motor" class="0/1/" ctrllimited="true" ctrlrange="-1 1" gear="72" joint="0/1/joint/"/>
    <motor name="0/1/2/motor" class="0/1/2/" ctrllimited="true" ctrlrange="-1 1" gear="73" joint="0/1/2/joint/"/>
    <motor name="0/1/2/3/motor" class="0/1/2/3/" ctrllimited="true" ctrlrange="-1 1" gear="83" joint="0/1/2/3/joint/"/>
    <motor name="0/1/2/3/4/motor" class="0/1/2/3/4/" ctrllimited="true" ctrlrange="-1 1" gear="78" joint="0/1/2/3/4/joint/"/>
    <motor name="0/1/2/3/4/5/motor" class="0/1/2/3/4/5/" ctrllimited="true" ctrlrange="-1 1" gear="91" joint="0/1/2/3/4/5/joint/"/>
    <motor name="0/1/2/3/4/5/6/motor" class="0/1/2/3/4/5/6/" ctrllimited="true" ctrlrange="-1 1" gear="82" joint="0/1/2/3/4/5/6/joint/"/>
  </actuator>
  <sensor>
    <subtreelinvel name="velocity" body="0/"/>
  </sensor>
</mujoco>
