<mujoco model="morphology">
  <option timestep="0.01"/>
  <default>
    <default class="/"/>
    <default class="0/"/>
    <default class="0/1/"/>
    <default class="0/1/2/"/>
    <default class="0/1/2/3/"/>
    <default class="0/1/2/3/4/"/>
    <default class="0/5/"/>
    <default class="0/5/6/"/>
    <default class="0/5/7/"/>
    <default class="0/5/7/8/"/>
  </default>
  <asset>
    <texture name="texplane" type="2d" builtin="checker" rgb1="0.10000000000000001 0.20000000000000001 0.29999999999999999" rgb2="0.20000000000000001 0.29999999999999999 0.40000000000000002" width="300" height="300"/>
    <material name="MatPlane" class="/" texture="texplane" texrepeat="20 20" specular="1" shininess="1" reflectance="0.5"/>
  </asset>
  <worldbody>
    <light name="//unnamed_light_0" class="/" directional="true" pos="0 0 1.5" dir="0 0 -1.3" cutoff="100" exponent="1" diffuse="1 1 1" specular="0.10000000000000001 0.10000000000000001 0.10000000000000001"/>
    <geom name="ground" class="/" type="plane" size="15 15 0.5" material="MatPlane" rgba="1 1 1 1"/>
    <site name="body" class="/" size="9.9999999999999995e-07 9.9999999999999995e-07 9.9999999999999995e-07" pos="0 0 0.10000000000000001"/>
    <body pos="0 0 0.10000000000000001" name="0/">
      <freejoint name="0/"/>
      <geom name="0/geom" class="0/" type="capsule" contype="1" conaffinity="1" condim="3" size="0.067791914363728098" rgba="0.02365000805588735 0.91632380358193988 0.37287469121501693 1" friction="0.59999999999999998 0.10000000000000001 0.10000000000000001" fromto="0 0 0 0.091817806140963576 0.60097885843797627 0.67795678175428398"/>
      <site name="0/end0" class="0/" size="0.0050000000000000001" pos="0.091817806140963576 0.60097885843797627 0.67795678175428398"/>
      <site name="0/attach1" class="0/" size="9.9999999999999995e-07 9.9999999999999995e-07 9.9999999999999995e-07" pos="0.0023980237266032016 0.015695883209283241 0.017706330793423378"/>
      <body pos="0.0023980237266032016 0.015695883209283241 0.017706330793423378" name="0/1/">
        <joint name="0/1/joint/" class="0/" type="hinge" axis="0 0 1" limited="true" range="-64.877538379221363 64.877538379221363"/>
        <geom name="0/1/geom" class="0/1/" type="capsule" contype="1" conaffinity="1" condim="3" size="0.039989482944919948" rgba="0.20892985421419852 0.15649331112296228 0.45595655278870784 1" friction="0.59999999999999998 0.10000000000000001 0.10000000000000001" fromto="0 0 0 -0.71993626422296286 -0.46742243895083757 0.32481320814570269"/>
        <site name="0/1/end1" class="0/1/" size="0.0050000000000000001" pos="-0.71993626422296286 -0.46742243895083757 0.32481320814570269"/>
        <site name="0/1/attach2" class="0/1/" size="9.9999999999999995e-07 9.9999999999999995e-07 9.9999999999999995e-07" pos="-0.68759824279963166 -0.44642680698214893 0.31022328261259513"/>
        <body pos="-0.68759824279963166 -0.44642680698214893 0.31022328261259513" name="0/1/2/">
          <joint name="0/1/2/joint/" class="0/1/" type="hinge" axis="0 0.57064977419258844 0.82119354309075498" limited="true" range="-51.966050940644656 51.966050940644656"/>
          <geom name="0/1/2/geom" class="0/1/2/" type="capsule" contype="1" conaffinity="1" condim="3" size="0.05141829298877891" rgba="0.35487123257651121 0.92532599260628967 0.57438488116774167 1" friction="0.59999999999999998 0.10000000000000001 0.10000000000000001" fromto="0 0 0 0.41145592279796328 -0.49798451873707966 0.58241595462952578"/>
          <site name="0/1/2/end2" class="0/1/2/" size="0.0050000000000000001" pos="0.41145592279796328 -0.49798451873707966 0.58241595462952578"/>
          <site name="0/1/2/attach3" class="0/1/2/" size="9.9999999999999995e-07 9.9999999999999995e-07 9.9999999999999995e-07" pos="0.23828914060103973 -0.28840100829159454 0.33729833406517884"/>
          <body pos="0.23828914060103973 -0.28840100829159454 0.33729833406517884" name="0/1/2/3/">
            <joint name="0/1/2/3/joint/" class="0/1/2/" type="hinge" axis="-5.5511151231257827e-17 0.7600486240489186 0.64986620860092847" limited="true" range="-47.256335916417498 47.256335916417498"/>
            <geom name="0/1/2/3/geom" class="0/1/2/3/" type="capsule" contype="1" conaffinity="1" condim="3" size="0.041128234176471878" rgba="0.72768571360748813 0.40072888230265269 0.68849102209353397 1" friction="0.59999999999999998 0.10000000000000001 0.10000000000000001" fromto="0 0 0 0.42466197094120717 0.23829854961497499 0.56135883518978513"/>
            <site name="0/1/2/3/end3" class="0/1/2/3/" size="0.0050000000000000001" pos="0.42466197094120717 0.23829854961497499 0.56135883518978513"/>
            <site name="0/1/2/3/attach4" class="0/1/2/3/" size="9.9999999999999995e-07 9.9999999999999995e-07 9.9999999999999995e-07" pos="0.011928659709497094 0.0066937529191124371 0.015768444028687656"/>
            <body pos="0.011928659709497094 0.0066937529191124371 0.015768444028687656" name="0/1/2/3/4/">
              <joint name="0/1/2/3/4/joint/" class="0/1/2/3/" type="hinge" axis="5.5511151231257827e-17 -0.92049549866246583 0.39075316625990159" limited="true" range="-64.177058299672922 64.177058299672922"/>
              <geom name="0/1/2/3/4/geom" class="0/1/2/3/4/" type="capsule" contype="1" conaffinity="1" condim="3" size="0.063028807330811593" rgba="0.30931507153235227 0.24320341234945519 0.70576618383588086 1" friction="0.59999999999999998 0.10000000000000001 0.10000000000000001" fromto="0 0 0 0.027419688775604634 -0.39768355038291087 -0.41713582192251047"/>
              <site name="0/1/2/3/4/end4" class="0/1/2/3/4/" size="0.0050000000000000001" pos="0.027419688775604634 -0.39768355038291087 -0.41713582192251047"/>
            </body>
          </body>
        </body>
      </body>
      <site name="0/attach5" class="0/" size="9.9999999999999995e-07 9.9999999999999995e-07 9.9999999999999995e-07" pos="0.079146182785557864 0.51803876153568051 0.5843930891471637"/>
      <body pos="0.079146182785557864 0.51803876153568051 0.5843930891471637" name="0/5/">
        <joint name="0/5/joint/" class="0/" type="hinge" axis="0 0 1" limited="true" range="-55.510145721065854 55.510145721065854"/>
        <geom name="0/5/geom" class="0/5/" type="capsule" contype="1" conaffinity="1" condim="3" size="0.058722417375872582" rgba="0.23761293279945106 0.39564811435153713 0.66064519899263996 1" friction="0.59999999999999998 0.10000000000000001 0.10000000000000001" fromto="0 0 0 0.31052431089940447 0.11894223477860433 -0.21304430345831349"/>
        <site name="0/5/end5" class="0/5/" size="0.0050000000000000001" pos="0.31052431089940447 0.11894223477860433 -0.21304430345831349"/>
        <site name="0/5/attach6" class="0/5/" size="9.9999999999999995e-07 9.9999999999999995e-07 9.9999999999999995e-07" pos="0.3015982606496716 0.11552322915751695 -0.2069203251051201"/>
        <body pos="0.3015982606496716 0.11552322915751695 -0.2069203251051201" name="0/5/6/">
          <joint name="0/5/6/joint/" class="0/5/" type="hinge" axis="-0.61784477153256234 0.38329907135926383 -0.68654909524738428" limited="true" range="-42.753007397133153 42.753007397133153"/>
          <geom name="0/5/6/geom" class="0/5/6/" type="capsule" contype="1" conaffinity="1" condim="3" size="0.062267090942245563" rgba="0.37869792137122571 0.5529432555246705 0.61309060569734031 1" friction="0.59999999999999998 0.10000000000000001 0.10000000000000001" fromto="0 0 0 0.13431504429338825 0.0017222658734151741 0.5486435657621096"/>
          <site name="0/5/6/end6" class="0/5/6/" size="0.0050000000000000001" pos="0.13431504429338825 0.0017222658734151741 0.5486435657621096"/>
        </body>
        <site name="0/5/attach7" class="0/5/" size="9.9999999999999995e-07 9.9999999999999995e-07 9.9999999999999995e-07" pos="0.039405851196394205 0.015093890687903802 -0.027035539008207984"/>
        <body pos="0.039405851196394205 0.015093890687903802 -0.027035539008207984" name="0/5/7/">
          <joint name="0/5/7/joint/" class="0/5/" type="hinge" axis="-0.61784477153256234 0.38329907135926383 -0.68654909524738428" limited="true" range="-39.826738906558674 39.826738906558674"/>
          <geom name="0/5/7/geom" class="0/5/7/" type="capsule" contype="1" conaffinity="1" condim="3" size="0.041104166466902826" rgba="0.77709948683284347 0.26232742765996042 0.71431229917954742 1" friction="0.59999999999999998 0.10000000000000001 0.10000000000000001" fromto="0 0 0 0.39072702554529348 -0.6293835932757228 0.41562810713398668"/>
          <site name="0/5/7/end7" class="0/5/7/" size="0.0050000000000000001" pos="0.39072702554529348 -0.6293835932757228 0.41562810713398668"/>
          <site name="0/5/7/attach8" class="0/5/7/" size="9.9999999999999995e-07 9.9999999999999995e-07 9.9999999999999995e-07" pos="0.31310322393672535 -0.50434707420735059 0.33305733106317875"/>
          <body pos="0.31310322393672535 -0.50434707420735059 0.33305733106317875" name="0/5/7/8/">
            <joint name="0/5/7/8/joint/" class="0/5/7/" type="hinge" axis="2.7755575615628914e-17 0.55105916419288903 0.83446617520366528" limited="true" range="-38.625546594541582 38.625546594541582"/>
            <geom name="0/5/7/8/geom" class="0/5/7/8/" type="capsule" contype="1" conaffinity="1" condim="3" size="0.064021253775815329" rgba="0.81796463694396859 0.44525889883202752 0.40721615491196772 1" friction="0.59999999999999998 0.10000000000000001 0.10000000000000001" fromto="0 0 0 -0.72732167846038365 -0.39440324706087304 -0.65996523152294617"/>
            <site name="0/5/7/8/end8" class="0/5/7/8/" size="0.0050000000000000001" pos="-0.72732167846038365 -0.39440324706087304 -0.65996523152294617"/>
          </body>
        </body>
      </body>
      <camera name="0/iso" class="0/" mode="trackcom" pos="-2.2999999999999998 -2.2999999999999998 1" xyaxes="0.45000000000000001 -0.45000000000000001 0 0.29999999999999999 0.14999999999999999 0.93999999999999995"/>
    </body>
  </worldbody>
  <actuator>
    <motor name="0/1/motor" class="0/1/" ctrllimited="true" ctrlrange="-1 1" gear="81" joint="0/1/joint/"/>
    <motor name="0/1/2/motor" class="0/1/2/" ctrllimited="true" ctrlrange="-1 1" gear="51" joint="0/1/2/joint/"/>
    <motor name="0/1/2/3/motor" class="0/1/2/3/" ctrllimited="true" ctrlrange="-1 1" gear="58" joint="0/1/2/3/joint/"/>
    <motor name="0/1/2/3/4/motor" class="0/1/2/3/4/" ctrllimited="true" ctrlrange="-1 1" gear="74" joint="0/1/2/3/4/joint/"/>
    <motor name="0/5/motor" class="0/5/" ctrllimited="true" ctrlrange="-1 1" gear="61" joint="0/5/joint/"/>
    <motor name="0/5/6/motor" class="0/5/6/" ctrllimited="true" ctrlrange="-1 1" gear="87" joint="0/5/6/joint/"/>
    <motor name="0/5/7/motor" class="0/5/7/" ctrllimited="true" ctrlrange="-1 1" gear="92" joint="0/5/7/joint/"/>
    <motor name="0/5/7/8/motor" class="0/5/7/8/" ctrllimited="true" ctrlrange="-1 1" gear="72" joint="0/5/7/8/joint/"/>
  </actuator>
  <sensor>
    <subtreelinvel name="velocity" body="0/"/>
  </sensor>
</mujoco>
