<mujoco model="morphology">
  <option timestep="0.01"/>
  <default>
    <default class="/"/>
    <default class="0/"/>
    <default class="0/1/"/>
    <default class="0/1/2/"/>
    <default class="0/1/2/3/"/>
    <default class="0/1/4/"/>
    <default class="0/5/"/>
    <default class="0/5/6/"/>
  </default>
  <asset>
    <texture name="texplane" type="2d" builtin="checker" rgb1="0.10000000000000001 0.20000000000000001 0.29999999999999999" rgb2="0.20000000000000001 0.29999999999999999 0.40000000000000002" width="300" height="300"/>
    <material name="MatPlane" class="/" texture="texplane" texrepeat="20 20" specular="1" shininess="1" reflectance="0.5"/>
  </asset>
  <worldbody>
    <light name="//unnamed_light_0" class="/" directional="true" pos="0 0 1.5" dir="0 0 -1.3" cutoff="100" exponent="1" diffuse="1 1 1" specular="0.10000000000000001 0.10000000000000001 0.10000000000000001"/>
    <geom name="ground" class="/" type="plane" size="15 15 0.5" material="MatPlane" rgba="1 1 1 1"/>
    <site name="body" class="/" size="9.9999999999999995e-07 9.9999999999999995e-07 9.9999999999999995e-07" pos="0 0 0.87968525886535642"/>
    <body pos="0 0 0.87968525886535642" name="0/">
      <freejoint name="0/"/>
      <geom name="0/geom" class="0/" type="capsule" contype="1" conaffinity="1" condim="3" size="0.047462317119824488" rgba="0.76501577670292986 0.37485721288708729 0.89078718060546624 1" friction="0.59999999999999998 0.10000000000000001 0.10000000000000001" fromto="0 0 0 0.57789759602826796 0.62066885308311215 -0.22092113060389595"/>
      <site name="0/end0" class="0/" size="0.0050000000000000001" pos="0.57789759602826796 0.62066885308311215 -0.22092113060389595"/>
      <site name="0/attach1" class="0/" size="9.9999999999999995e-07 9.9999999999999995e-07 9.9999999999999995e-07" pos="0.16281993586828197 0.17487053683727249 -0.062243491864456879"/>
      <body pos="0.16281993586828197 0.17487053683727249 -0.062243491864456879" name="0/1/">
        <joint name="0/1/joint/" class="0/" type="hinge" axis="0 1 0" limited="true" range="-61.734407240551576 61.734407240551576"/>
        <geom name="0/1/geom" class="0/1/" type="capsule" contype="1" conaffinity="1" condim="3" size="0.045368395414797716" rgba="0.4910205540046676 0.0030816555002680657 0.2086925629332802 1" friction="0.59999999999999998 0.10000000000000001 0.10000000000000001" fromto="0 0 0 0.20546116574148809 -0.30726620809935062 -0.48184350960966521"/>
        <site name="0/1/end1" class="0/1/" size="0.0050000000000000001" pos="0.20546116574148809 -0.30726620809935062 -0.48184350960966521"/>
        <site name="0/1/attach2" class="0/1/" size="9.9999999999999995e-07 9.9999999999999995e-07 9.9999999999999995e-07" pos="0.11799780497522137 -0.17646516298073237 -0.27672614564561793"/>
        <body pos="0.11799780497522137 -0.17646516298073237 -0.27672614564561793" name="0/1/2/">
          <joint name="0/1/2/joint/" class="0/1/" type="hinge" axis="0.94102926757282945 0.18190746756701631 0.28526056652593806" limited="true" range="-36.820661540689471 36.820661540689471"/>
          <geom name="0/1/2/geom" class="0/1/2/" type="capsule" contype="1" conaffinity="1" condim="3" size="0.035426195304237289" rgba="0.62006837923685587 0.54416388321091991 0.5094730266648273 1" friction="0.59999999999999998 0.10000000000000001 0.10000000000000001" fromto="0 0 0 0.17376593365188009 0.40057694985238101 0.065597232397173633"/>
          <site name="0/1/2/end2" class="0/1/2/" size="0.0050000000000000001" pos="0.17376593365188009 0.40057694985238101 0.065597232397173633"/>
          <site name="0/1/2/attach3" class="0/1/2/" size="9.9999999999999995e-07 9.9999999999999995e-07 9.9999999999999995e-07" pos="0.041354604794659668 0.095333424123182187 0.015611504305805053"/>
          <body pos="0.041354604794659668 0.095333424123182187 0.015611504305805053" name="0/1/2/3/">
            <joint name="0/1/2/3/joint/" class="0/1/2/" type="hinge" axis="0 -0.16160439980160707 0.98685562164116114" limited="true" range="-63.603720713172756 63.603720713172756"/>
            <geom name="0/1/2/3/geom" class="0/1/2/3/" type="capsule" contype="1" conaffinity="1" condim="3" size="0.068450231510835374" rgba="0.76177081730236818 0.77901403861008744 0.15718655072202481 1" friction="0.59999999999999998 0.10000000000000001 0.10000000000000001" fromto="0 0 0 0.44637412488393324 0.10356051987063319 -0.4563271080341964"/>
            <site name="0/1/2/3/end3" class="0/1/2/3/" size="0.0050000000000000001" pos="0.44637412488393324 0.10356051987063319 -0.4563271080341964"/>
          </body>
        </body>
        <site name="0/1/attach4" class="0/1/" size="9.9999999999999995e-07 9.9999999999999995e-07 9.9999999999999995e-07" pos="0.19088083419843235 -0.28546139077585264 -0.44765000108641506"/>
        <body pos="0.19088083419843235 -0.28546139077585264 -0.44765000108641506" name="0/1/4/">
          <geom name="0/1/4/geom" class="0/1/4/" type="capsule" contype="1" conaffinity="1" condim="3" size="0.056861243338082783" rgba="0.91874330956891181 0.69893487875460325 0.0015454807148475025 1" friction="0.59999999999999998 0.10000000000000001 0.10000000000000001" fromto="0 0 0 -0.37610311516511991 -0.55064076207773582 -0.24956097825786228"/>
          <site name="0/1/4/end4" class="0/1/4/" size="0.0050000000000000001" pos="-0.37610311516511991 -0.55064076207773582 -0.24956097825786228"/>
        </body>
      </body>
      <site name="0/attach5" class="0/" size="9.9999999999999995e-07 9.9999999999999995e-07 9.9999999999999995e-07" pos="0.23642960769365359 0.25392819497891128 -0.090383307698277002"/>
      <body pos="0.23642960769365359 0.25392819497891128 -0.090383307698277002" name="0/5/">
        <joint name="0/5/joint/" class="0/" type="hinge" axis="0 1 0" limited="true" range="-49.247856759228995 49.247856759228995"/>
        <geom name="0/5/geom" class="0/5/" type="capsule" contype="1" conaffinity="1" condim="3" size="0.035674055256184271" rgba="0.06340009546845482 0.015528509664368695 0.44391896157847088 1" friction="0.59999999999999998 0.10000000000000001 0.10000000000000001" fromto="0 0 0 -0.41328936879665895 -0.0010496100063375202 0.36207157353581865"/>
        <site name="0/5/end5" class="0/5/" size="0.0050000000000000001" pos="-0.41328936879665895 -0.0010496100063375202 0.36207157353581865"/>
        <site name="0/5/attach6" class="0/5/" size="9.9999999999999995e-07 9.9999999999999995e-07 9.9999999999999995e-07" pos="-0.0089285370317582265 -2.2675351746343531e-05 0.0078220484157967111"/>
        <body pos="-0.0089285370317582265 -2.2675351746343531e-05 0.0078220484157967111" name="0/5/6/">
          <joint name="0/5/6/joint/" class="0/5/" type="hinge" axis="0.65896307713408875 -0.0021804732782251465 0.75217212691660928" limited="true" range="-52.694580841087145 52.694580841087145"/>
          <geom name="0/5/6/geom" class="0/5/6/" type="capsule" contype="1" conaffinity="1" condim="3" size="0.061888656414828928" rgba="0.46993444756832459 0.36326597458898169 0.71822352666426625 1" friction="0.59999999999999998 0.10000000000000001 0.10000000000000001" fromto="0 0 0 -0.20335177817503913 0.65934075018501725 0.59318160510676887"/>
          <site name="0/5/6/end6" class="0/5/6/" size="0.0050000000000000001" pos="-0.20335177817503913 0.65934075018501725 0.59318160510676887"/>
        </body>
      </body>
      <camera name="0/iso" class="0/" mode="trackcom" pos="-2.2999999999999998 -2.2999999999999998 1" xyaxes="0.45000000000000001 -0.45000000000000001 0 0.29999999999999999 0.14999999999999999 0.93999999999999995"/>
    </body>
  </worldbody>
  <actuator>
    <motor name="0/1/motor" class="0/1/" ctrllimited="true" ctrlrange="-1 1" gear="60" joint="0/1/joint/"/>
    <motor name="0/1/2/motor" class="0/1/2/" ctrllimited="true" ctrlrange="-1 1" gear="98" joint="0/1/2/joint/"/>
    <motor name="0/1/2/3/motor" class="0/1/2/3/" ctrllimited="true" ctrlrange="-1 1" gear="76" joint="0/1/2/3/joint/"/>
    <motor name="0/5/motor" class="0/5/" ctrllimited="true" ctrlrange="-1 1" gear="63" joint="0/5/joint/"/>
    <motor name="0/5/6/motor" class="0/5/6/" ctrllimited="true" ctrlrange="-1 1" gear="65" joint="0/5/6/joint/"/>
  </actuator>
  <sensor>
    <subtreelinvel name="velocity" body="0/"/>
  </sensor>
</mujoco>
