<mujoco model="morphology">
  <option timestep="0.01"/>
  <default>
    <default class="/"/>
    <default class="0/"/>
    <default class="0/1/"/>
    <default class="0/1/2/"/>
    <default class="0/1/2/3/"/>
    <default class="0/1/2/3/4/"/>
    <default class="0/1/2/3/4/5/"/>
    <default class="0/1/2/3/4/6/"/>
    <default class="0/1/2/3/4/6/7/"/>
  </default>
  <asset>
    <texture name="texplane" type="2d" builtin="checker" rgb1="0.10000000000000001 0.20000000000000001 0.29999999999999999" rgb2="0.20000000000000001 0.29999999999999999 0.40000000000000002" width="300" height="300"/>
    <material name="MatPlane" class="/" texture="texplane" texrepeat="20 20" specular="1" shininess="1" reflectance="0.5"/>
  </asset>
  <worldbody>
    <light name="//unnamed_light_0" class="/" directional="true" pos="0 0 1.5" dir="0 0 -1.3" cutoff="100" exponent="1" diffuse="1 1 1" specular="0.10000000000000001 0.10000000000000001 0.10000000000000001"/>
    <geom name="ground" class="/" type="plane" size="15 15 0.5" material="MatPlane" rgba="1 1 1 1"/>
    <site name="body" class="/" size="9.9999999999999995e-07 9.9999999999999995e-07 9.9999999999999995e-07" pos="0 0 1.5008791446685792"/>
    <body pos="0 0 1.5008791446685792" name="0/">
      <freejoint name="0/"/>
      <geom name="0/geom" class="0/" type="capsule" contype="1" conaffinity="1" condim="3" size="0.057788911355870838" rgba="0.42121945197522048 0.16035870470840696 0.63046025176141285 1" friction="0.59999999999999998 0.10000000000000001 0.10000000000000001" fromto="0 0 0 -0.23825689577322817 -0.32761651563936683 -0.53113406687518527"/>
      <site name="0/end0" class="0/" size="0.0050000000000000001" pos="-0.23825689577322817 -0.32761651563936683 -0.53113406687518527"/>
      <site name="0/attach1" class="0/" size="9.9999999999999995e-07 9.9999999999999995e-07 9.9999999999999995e-07" pos="-0.2367744229020699 -0.32557803278663533 -0.52782926496154048"/>
      <body pos="-0.2367744229020699 -0.32557803278663533 -0.52782926496154048" name="0/1/">
        <geom name="0/1/geom" class="0/1/" type="capsule" contype="1" conaffinity="1" condim="3" size="0.067897930521804525" rgba="0.98102633584485222 0.87558009540942139 0.16294058011593004 1" friction="0.59999999999999998 0.10000000000000001 0.10000000000000001" fromto="0 0 0 -0.36879972450584386 -0.10134717637788271 -0.42491245570943753"/>
        <site name="0/1/end1" class="0/1/" size="0.0050000000000000001" pos="-0.36879972450584386 -0.10134717637788271 -0.42491245570943753"/>
        <site name="0/1/attach2" class="0/1/" size="9.9999999999999995e-07 9.9999999999999995e-07 9.9999999999999995e-07" pos="-0.1148534675643792 -0.03156204807488712 -0.13232837691219937"/>
        <body pos="-0.1148534675643792 -0.03156204807488712 -0.13232837691219937" name="0/1/2/">
          <geom name="0/1/2/geom" class="0/1/2/" type="capsule" contype="1" conaffinity="1" condim="3" size="0.054179037848881756" rgba="0.049453201600252794 0.88046446089413222 0.099333012218883909 1" friction="0.59999999999999998 0.10000000000000001 0.10000000000000001" fromto="0 0 0 -0.71103346293671033 0.65017098347491831 -0.43576916394270621"/>
          <site name="0/1/2/end2" class="0/1/2/" size="0.0050000000000000001" pos="-0.71103346293671033 0.65017098347491831 -0.43576916394270621"/>
          <site name="0/1/2/attach3" class="0/1/2/" size="9.9999999999999995e-07 9.9999999999999995e-07 9.9999999999999995e-07" pos="-0.55798175439948317 0.51022007391973334 -0.34196877542961762"/>
          <body pos="-0.55798175439948317 0.51022007391973334 -0.34196877542961762" name="0/1/2/3/">
            <joint name="0/1/2/3/joint/" class="0/1/2/" type="hinge" axis="-0.74018041388366795 -0.5585552230391555 0.37436481901840263" limited="true" range="-58.109199664488017 58.109199664488017"/>
            <geom name="0/1/2/3/geom" class="0/1/2/3/" type="capsule" contype="1" conaffinity="1" condim="3" size="0.057848119010791677" rgba="0.18990090643520163 0.4478880941821124 0.41149948814718429 1" friction="0.59999999999999998 0.10000000000000001 0.10000000000000001" fromto="0 0 0 0.065296098654225365 0.42857598033610489 -0.29302748521612143"/>
            <site name="0/1/2/3/end3" class="0/1/2/3/" size="0.0050000000000000001" pos="0.065296098654225365 0.42857598033610489 -0.29302748521612143"/>
            <site name="0/1/2/3/attach4" class="0/1/2/3/" size="9.9999999999999995e-07 9.9999999999999995e-07 9.9999999999999995e-07" pos="0.046692197923655171 0.3064678428208516 -0.20953927751848467"/>
            <body pos="0.046692197923655171 0.3064678428208516 -0.20953927751848467" name="0/1/2/3/4/">
              <joint name="0/1/2/3/4/joint/" class="0/1/2/3/" type="hinge" axis="-0.99218368533877443 0.10301012773371326 -0.070430448897134706" limited="true" range="-60.098187038605531 60.098187038605531"/>
              <geom name="0/1/2/3/4/geom" class="0/1/2/3/4/" type="capsule" contype="1" conaffinity="1" condim="3" size="0.057335750075614783" rgba="0.1180925830513021 0.921574725964039 0.33069376766414482 1" friction="0.59999999999999998 0.10000000000000001 0.10000000000000001" fromto="0 0 0 -0.55669449513115632 0.35062247202217733 0.11187657277147589"/>
              <site name="0/1/2/3/4/end4" class="0/1/2/3/4/" size="0.0050000000000000001" pos="-0.55669449513115632 0.35062247202217733 0.11187657277147589"/>
              <site name="0/1/2/3/4/attach5" class="0/1/2/3/4/" size="9.9999999999999995e-07 9.9999999999999995e-07 9.9999999999999995e-07" pos="-0.13839945886651275 0.087168026302964816 0.027813562495825245"/>
              <body pos="-0.13839945886651275 0.087168026302964816 0.027813562495825245" name="0/1/2/3/4/5/">
                <geom name="0/1/2/3/4/5/geom" class="0/1/2/3/4/5/" type="capsule" contype="1" conaffinity="1" condim="3" size="0.054981813023736406" rgba="0.7498917125782476 0.56463243989195289 0.5991701466046746 1" friction="0.59999999999999998 0.10000000000000001 0.10000000000000001" fromto="0 0 0 -0.3470280938275076 -0.36239834439796492 0.3845367729441338"/>
                <site name="0/1/2/3/4/5/end5" class="0/1/2/3/4/5/" size="0.0050000000000000001" pos="-0.3470280938275076 -0.36239834439796492 0.3845367729441338"/>
              </body>
              <site name="0/1/2/3/4/attach6" class="0/1/2/3/4/" size="9.9999999999999995e-07 9.9999999999999995e-07 9.9999999999999995e-07" pos="-0.40104607239102014 0.25259054387343227 0.080596557887639628"/>
              <body pos="-0.40104607239102014 0.25259054387343227 0.080596557887639628" name="0/1/2/3/4/6/">
                <geom name="0/1/2/3/4/6/geom" class="0/1/2/3/4/6/" type="capsule" contype="1" conaffinity="1" condim="3" size="0.044042639952635305" rgba="0.32793775431004091 0.86673533365126609 0.97535734359424997 1" friction="0.59999999999999998 0.10000000000000001 0.10000000000000001" fromto="0 0 0 0.24252662359745036 0.44932915171866661 -0.26981005618654424"/>
                <site name="0/1/2/3/4/6/end6" class="0/1/2/3/4/6/" size="0.0050000000000000001" pos="0.24252662359745036 0.44932915171866661 -0.26981005618654424"/>
                <site name="0/1/2/3/4/6/attach7" class="0/1/2/3/4/6/" size="9.9999999999999995e-07 9.9999999999999995e-07 9.9999999999999995e-07" pos="0.18238993264487946 0.33791388550139362 -0.20290818898487434"/>
                <body pos="0.18238993264487946 0.33791388550139362 -0.20290818898487434" name="0/1/2/3/4/6/7/">
                  <joint name="0/1/2/3/4/6/7/joint/" class="0/1/2/3/4/6/" type="hinge" axis="-2.7755575615628914e-17 0.51479393860964073 0.85731394527954197" limited="true" range="-57.599396976606315 57.599396976606315"/>
                  <geom name="0/1/2/3/4/6/7/geom" class="0/1/2/3/4/6/7/" type="capsule" contype="1" conaffinity="1" condim="3" size="0.063585062463643621" rgba="0.099232170112244722 0.82706947904960471 0.18172787542475355 1" friction="0.59999999999999998 0.10000000000000001 0.10000000000000001" fromto="0 0 0 0.72129268253999457 -0.095344563122745196 0.042355324778566628"/>
                  <site name="0/1/2/3/4/6/7/end7" class="0/1/2/3/4/6/7/" size="0.0050000000000000001" pos="0.72129268253999457 -0.095344563122745196 0.042355324778566628"/>
                </body>
              </body>
            </body>
          </body>
        </body>
      </body>
      <camera name="0/iso" class="0/" mode="trackcom" pos="-2.2999999999999998 -2.2999999999999998 1" xyaxes="0.45000000000000001 -0.45000000000000001 0 0.29999999999999999 0.14999999999999999 0.93999999999999995"/>
    </body>
  </worldbody>
  <actuator>
    <motor name="0/1/2/3/motor" class="0/1/2/3/" ctrllimited="true" ctrlrange="-1 1" gear="51" joint="0/1/2/3/joint/"/>
    <motor name="0/1/2/3/4/motor" class="0/1/2/3/4/" ctrllimited="true" ctrlrange="-1 1" gear="90" joint="0/1/2/3/4/joint/"/>
    <motor name="0/1/2/3/4/6/7/motor" class="0/1/2/3/4/6/7/" ctrllimited="true" ctrlrange="-1 1" gear="98" joint="0/1/2/3/4/6/7/joint/"/>
  </actuator>
  <sensor>
    <subtreelinvel name="velocity" body="0/"/>
  </sensor>
</mujoco>
