<mujoco model="morphology">
  <option timestep="0.01"/>
  <default>
    <default class="/"/>
    <default class="0/"/>
    <default class="0/1/"/>
    <default class="0/2/"/>
    <default class="0/3/"/>
    <default class="0/3/4/"/>
    <default class="0/3/5/"/>
    <default class="0/3/6/"/>
    <default class="0/3/6/7/"/>
    <default class="0/3/6/8/"/>
    <default class="0/3/6/8/9/"/>
    <default class="0/3/6/8/9/10/"/>
  </default>
  <asset>
    <texture name="texplane" type="2d" builtin="checker" rgb1="0.10000000000000001 0.20000000000000001 0.29999999999999999" rgb2="0.20000000000000001 0.29999999999999999 0.40000000000000002" width="300" height="300"/>
    <material name="MatPlane" class="/" texture="texplane" texrepeat="20 20" specular="1" shininess="1" reflectance="0.5"/>
  </asset>
  <worldbody>
    <light name="//unnamed_light_0" class="/" directional="true" pos="0 0 1.5" dir="0 0 -1.3" cutoff="100" exponent="1" diffuse="1 1 1" specular="0.10000000000000001 0.10000000000000001 0.10000000000000001"/>
    <geom name="ground" class="/" type="plane" size="15 15 0.5" material="MatPlane" rgba="1 1 1 1"/>
    <site name="body" class="/" size="9.9999999999999995e-07 9.9999999999999995e-07 9.9999999999999995e-07" pos="0 0 0.23915765285491944"/>
    <body pos="0 0 0.23915765285491944" name="0/">
      <freejoint name="0/"/>
      <geom name="0/geom" class="0/" type="capsule" contype="1" conaffinity="1" condim="3" size="0.039619736663264599" rgba="0.24208346741536513 0.43391941027637426 0.68650041563967779 1" friction="0.59999999999999998 0.10000000000000001 0.10000000000000001" fromto="0 0 0 -0.71264090197630803 0.15406751239589012 0.35211319610533121"/>
      <site name="0/end0" class="0/" size="0.0050000000000000001" pos="-0.71264090197630803 0.15406751239589012 0.35211319610533121"/>
      <site name="0/attach1" class="0/" size="9.9999999999999995e-07 9.9999999999999995e-07 9.9999999999999995e-07" pos="-0.37602938977031702 0.0812946780194541 0.18579471076439211"/>
      <body pos="-0.37602938977031702 0.0812946780194541 0.18579471076439211" name="0/1/">
        <joint name="0/1/joint/" class="0/" type="hinge" axis="0 1 0" limited="true" range="-45.298187995421436 45.298187995421436"/>
        <geom name="0/1/geom" class="0/1/" type="capsule" contype="1" conaffinity="1" condim="3" size="0.03653899492004755" rgba="0.10021762851582272 0.084596675125512721 0.91227445592820133 1" friction="0.59999999999999998 0.10000000000000001 0.10000000000000001" fromto="0 0 0 -0.32326912632787752 -0.73932286985814311 0.68007126757771141"/>
        <site name="0/1/end1" class="0/1/" size="0.0050000000000000001" pos="-0.32326912632787752 -0.73932286985814311 0.68007126757771141"/>
      </body>
      <site name="0/attach2" class="0/" size="9.9999999999999995e-07 9.9999999999999995e-07 9.9999999999999995e-07" pos="-0.33171869394162395 0.071715044490245516 0.16390096219253286"/>
      <body pos="-0.33171869394162395 0.071715044490245516 0.16390096219253286" name="0/2/">
        <geom name="0/2/geom" class="0/2/" type="capsule" contype="1" conaffinity="1" condim="3" size="0.04440110015994933" rgba="0.57773439153429507 0.79306951173397167 0.4573401746939062 1" friction="0.59999999999999998 0.10000000000000001 0.10000000000000001" fromto="0 0 0 0.0023802253227130921 -0.22834834158307138 -0.042581394493607316"/>
        <site name="0/2/end2" class="0/2/" size="0.0050000000000000001" pos="0.0023802253227130921 -0.22834834158307138 -0.042581394493607316"/>
      </body>
      <site name="0/attach3" class="0/" size="9.9999999999999995e-07 9.9999999999999995e-07 9.9999999999999995e-07" pos="-0.6775223360773529 0.146475147051776 0.33476124444633437"/>
      <body pos="-0.6775223360773529 0.146475147051776 0.33476124444633437" name="0/3/">
        <joint name="0/3/joint/" class="0/" type="hinge" axis="0 0 1" limited="true" range="-57.082637420466511 57.082637420466511"/>
        <geom name="0/3/geom" class="0/3/" type="capsule" contype="1" conaffinity="1" condim="3" size="0.054062898083695313" rgba="0.0046756222357213773 0.9092296023205565 0.52535056760236176 1" friction="0.59999999999999998 0.10000000000000001 0.10000000000000001" fromto="0 0 0 0.069695781672144297 0.69222587027192306 0.019601162979358211"/>
        <site name="0/3/end3" class="0/3/" size="0.0050000000000000001" pos="0.069695781672144297 0.69222587027192306 0.019601162979358211"/>
        <site name="0/3/attach4" class="0/3/" size="9.9999999999999995e-07 9.9999999999999995e-07 9.9999999999999995e-07" pos="0.026463806708964057 0.26284132540466548 0.0074426511319831854"/>
        <body pos="0.026463806708964057 0.26284132540466548 0.0074426511319831854" name="0/3/4/">
          <joint name="0/3/4/joint/" class="0/3/" type="hinge" axis="-3.4694469519536142e-18 -0.028304792411233688 0.99959933909869969" limited="true" range="-39.808845335469677 39.808845335469677"/>
          <geom name="0/3/4/geom" class="0/3/4/" type="capsule" contype="1" conaffinity="1" condim="3" size="0.065468996782361344" rgba="0.051133923246424073 0.21145618036507152 0.9362376114223756 1" friction="0.59999999999999998 0.10000000000000001 0.10000000000000001" fromto="0 0 0 -0.47131344215199406 0.69563825283006864 -0.47974521490785577"/>
          <site name="0/3/4/end4" class="0/3/4/" size="0.0050000000000000001" pos="-0.47131344215199406 0.69563825283006864 -0.47974521490785577"/>
        </body>
        <site name="0/3/attach5" class="0/3/" size="9.9999999999999995e-07 9.9999999999999995e-07 9.9999999999999995e-07" pos="0.067208602667448242 0.66752294550745483 0.018901671563088317"/>
        <body pos="0.067208602667448242 0.66752294550745483 0.018901671563088317" name="0/3/5/">
          <joint name="0/3/5/joint/" class="0/3/" type="hinge" axis="-3.4694469519536142e-18 -0.028304792411233688 0.99959933909869969" limited="true" range="-61.66320352468734 61.66320352468734"/>
          <geom name="0/3/5/geom" class="0/3/5/" type="capsule" contype="1" conaffinity="1" condim="3" size="0.045316077887134584" rgba="0.094605212833716368 0.91959487127299988 0.023313683891740378 1" friction="0.59999999999999998 0.10000000000000001 0.10000000000000001" fromto="0 0 0 -0.31214863428238093 0.62177929504416762 -0.2239956036140538"/>
          <site name="0/3/5/end5" class="0/3/5/" size="0.0050000000000000001" pos="-0.31214863428238093 0.62177929504416762 -0.2239956036140538"/>
        </body>
        <site name="0/3/attach6" class="0/3/" size="9.9999999999999995e-07 9.9999999999999995e-07 9.9999999999999995e-07" pos="0.057417760160620925 0.57027926285725128 0.016148106066336702"/>
        <body pos="0.057417760160620925 0.57027926285725128 0.016148106066336702" name="0/3/6/">
          <joint name="0/3/6/joint/" class="0/3/" type="hinge" axis="-0.99497362101109443 0.1000972519733474 0.0028343675583010729" limited="true" range="-31.055244108872557 31.055244108872557"/>
          <geom name="0/3/6/geom" class="0/3/6/" type="capsule" contype="1" conaffinity="1" condim="3" size="0.05626343213316895" rgba="0.11732200752491895 0.87055747683091056 0.18892537834034395 1" friction="0.59999999999999998 0.10000000000000001 0.10000000000000001" fromto="0 0 0 -0.66790152962626115 -0.17995660781306411 -0.30446292714300283"/>
          <site name="0/3/6/end6" class="0/3/6/" size="0.0050000000000000001" pos="-0.66790152962626115 -0.17995660781306411 -0.30446292714300283"/>
          <site name="0/3/6/attach7" class="0/3/6/" size="9.9999999999999995e-07 9.9999999999999995e-07 9.9999999999999995e-07" pos="-0.53134731418785586 -0.14316400845096863 -0.24221468499665275"/>
          <body pos="-0.53134731418785586 -0.14316400845096863 -0.24221468499665275" name="0/3/6/7/">
            <joint name="0/3/6/7/joint/" class="0/3/6/" type="hinge" axis="0 -0.86086869467516403 0.50882717157034751" limited="true" range="-61.204106851056963 61.204106851056963"/>
            <geom name="0/3/6/7/geom" class="0/3/6/7/" type="capsule" contype="1" conaffinity="1" condim="3" size="0.051887822251675077" rgba="0.51807842275588323 0.8673364158788146 0.63677246348412919 1" friction="0.59999999999999998 0.10000000000000001 0.10000000000000001" fromto="0 0 0 -0.22149723156880219 -0.58970514445915867 -0.2478523192257307"/>
            <site name="0/3/6/7/end7" class="0/3/6/7/" size="0.0050000000000000001" pos="-0.22149723156880219 -0.58970514445915867 -0.2478523192257307"/>
          </body>
          <site name="0/3/6/attach8" class="0/3/6/" size="9.9999999999999995e-07 9.9999999999999995e-07 9.9999999999999995e-07" pos="-0.35233811785578723 -0.094932515767776476 -0.16061333886517185"/>
          <body pos="-0.35233811785578723 -0.094932515767776476 -0.16061333886517185" name="0/3/6/8/">
            <joint name="0/3/6/8/joint/" class="0/3/6/" type="hinge" axis="0.4679647011519853 -0.44967456655893329 -0.76079026194199484" limited="true" range="-67.850585679730045 67.850585679730045"/>
            <geom name="0/3/6/8/geom" class="0/3/6/8/" type="capsule" contype="1" conaffinity="1" condim="3" size="0.048743711615760139" rgba="0.62006229841355298 0.96623007627969648 0.38958852956685852 1" friction="0.59999999999999998 0.10000000000000001 0.10000000000000001" fromto="0 0 0 -0.29409194698207508 0.651436360467744 0.51407030955861832"/>
            <site name="0/3/6/8/end8" class="0/3/6/8/" size="0.0050000000000000001" pos="-0.29409194698207508 0.651436360467744 0.51407030955861832"/>
            <site name="0/3/6/8/attach9" class="0/3/6/8/" size="9.9999999999999995e-07 9.9999999999999995e-07 9.9999999999999995e-07" pos="-0.14980525407312867 0.33183019968340938 0.26185835458994905"/>
            <body pos="-0.14980525407312867 0.33183019968340938 0.26185835458994905" name="0/3/6/8/9/">
              <joint name="0/3/6/8/9/joint/" class="0/3/6/8/" type="hinge" axis="0 -0.61947980230189292 0.78501259514736965" limited="true" range="-39.042540020301217 39.042540020301217"/>
              <geom name="0/3/6/8/9/geom" class="0/3/6/8/9/" type="capsule" contype="1" conaffinity="1" condim="3" size="0.065011088277016627" rgba="0.84738052001250874 0.94926672044889338 0.41193580481657144 1" friction="0.59999999999999998 0.10000000000000001 0.10000000000000001" fromto="0 0 0 -0.0055438716140240318 0.73404944463344313 -0.37909809703232661"/>
              <site name="0/3/6/8/9/end9" class="0/3/6/8/9/" size="0.0050000000000000001" pos="-0.0055438716140240318 0.73404944463344313 -0.37909809703232661"/>
              <site name="0/3/6/8/9/attach10" class="0/3/6/8/9/" size="9.9999999999999995e-07 9.9999999999999995e-07 9.9999999999999995e-07" pos="-0.0020732441981246917 0.27451280588337612 -0.14177148839525336"/>
              <body pos="-0.0020732441981246917 0.27451280588337612 -0.14177148839525336" name="0/3/6/8/9/10/">
                <joint name="0/3/6/8/9/10/joint/" class="0/3/6/8/9/" type="hinge" axis="-2.7755575615628914e-17 0.45886643610074773 0.88850525818376469" limited="true" range="-64.95736661483275 64.95736661483275"/>
                <geom name="0/3/6/8/9/10/geom" class="0/3/6/8/9/10/" type="capsule" contype="1" conaffinity="1" condim="3" size="0.045483494088338516" rgba="0.5820140026522983 0.89450805842896652 0.8629272465289487 1" friction="0.59999999999999998 0.10000000000000001 0.10000000000000001" fromto="0 0 0 -0.09934204396623536 -0.068316397768251047 -0.16779380579576864"/>
                <site name="0/3/6/8/9/10/end10" class="0/3/6/8/9/10/" size="0.0050000000000000001" pos="-0.09934204396623536 -0.068316397768251047 -0.16779380579576864"/>
              </body>
            </body>
          </body>
        </body>
      </body>
      <camera name="0/iso" class="0/" mode="trackcom" pos="-2.2999999999999998 -2.2999999999999998 1" xyaxes="0.45000000000000001 -0.45000000000000001 0 0.29999999999999999 0.14999999999999999 0.93999999999999995"/>
    </body>
  </worldbody>
  <actuator>
    <motor name="0/1/motor" class="0/1/" ctrllimited="true" ctrlrange="-1 1" gear="52" joint="0/1/joint/"/>
    <motor name="0/3/motor" class="0/3/" ctrllimited="true" ctrlrange="-1 1" gear="98" joint="0/3/joint/"/>
    <motor name="0/3/4/motor" class="0/3/4/" ctrllimited="true" ctrlrange="-1 1" gear="78" joint="0/3/4/joint/"/>
    <motor name="0/3/5/motor" class="0/3/5/" ctrllimited="true" ctrlrange="-1 1" gear="65" joint="0/3/5/joint/"/>
    <motor name="0/3/6/motor" class="0/3/6/" ctrllimited="true" ctrlrange="-1 1" gear="63" joint="0/3/6/joint/"/>
    <motor name="0/3/6/7/motor" class="0/3/6/7/" ctrllimited="true" ctrlrange="-1 1" gear="71" joint="0/3/6/7/joint/"/>
    <motor name="0/3/6/8/motor" class="0/3/6/8/" ctrllimited="true" ctrlrange="-1 1" gear="50" joint="0/3/6/8/joint/"/>
    <motor name="0/3/6/8/9/motor" class="0/3/6/8/9/" ctrllimited="true" ctrlrange="-1 1" gear="89" joint="0/3/6/8/9/joint/"/>
    <motor name="0/3/6/8/9/10/motor" class="0/3/6/8/9/10/" ctrllimited="true" ctrlrange="-1 1" gear="87" joint="0/3/6/8/9/10/joint/"/>
  </actuator>
  <sensor>
    <subtreelinvel name="velocity" body="0/"/>
  </sensor>
</mujoco>
