<mujoco model="morphology">
  <option timestep="0.01"/>
  <default>
    <default class="/"/>
    <default class="0/"/>
    <default class="0/1/"/>
    <default class="0/2/"/>
    <default class="0/2/3/"/>
    <default class="0/2/3/4/"/>
    <default class="0/2/3/5/"/>
    <default class="0/2/3/5/6/"/>
    <default class="0/2/3/5/6/7/"/>
    <default class="0/2/3/5/6/7/8/"/>
    <default class="0/2/3/5/6/7/9/"/>
    <default class="0/2/10/"/>
  </default>
  <asset>
    <texture name="texplane" type="2d" builtin="checker" rgb1="0.10000000000000001 0.20000000000000001 0.29999999999999999" rgb2="0.20000000000000001 0.29999999999999999 0.40000000000000002" width="300" height="300"/>
    <material name="MatPlane" class="/" texture="texplane" texrepeat="20 20" specular="1" shininess="1" reflectance="0.5"/>
  </asset>
  <worldbody>
    <light name="//unnamed_light_0" class="/" directional="true" pos="0 0 1.5" dir="0 0 -1.3" cutoff="100" exponent="1" diffuse="1 1 1" specular="0.10000000000000001 0.10000000000000001 0.10000000000000001"/>
    <geom name="ground" class="/" type="plane" size="15 15 0.5" material="MatPlane" rgba="1 1 1 1"/>
    <site name="body" class="/" size="9.9999999999999995e-07 9.9999999999999995e-07 9.9999999999999995e-07" pos="0 0 0.53835833668708799"/>
    <body pos="0 0 0.53835833668708799" name="0/">
      <freejoint name="0/"/>
      <geom name="0/geom" class="0/" type="capsule" contype="1" conaffinity="1" condim="3" size="0.044893820030373711" rgba="0.49237056379214938 0.78061122791594606 0.82923019816317611 1" friction="0.59999999999999998 0.10000000000000001 0.10000000000000001" fromto="0 0 0 0.15255822682032694 -0.094535473026821304 0.27090761530862717"/>
      <site name="0/end0" class="0/" size="0.0050000000000000001" pos="0.15255822682032694 -0.094535473026821304 0.27090761530862717"/>
      <site name="0/attach1" class="0/" size="9.9999999999999995e-07 9.9999999999999995e-07 9.9999999999999995e-07" pos="0.039287598487354039 -0.024345273175362961 0.069765556661502776"/>
      <body pos="0.039287598487354039 -0.024345273175362961 0.069765556661502776" name="0/1/">
        <joint name="0/1/joint/" class="0/" type="hinge" axis="0 1 0" limited="true" range="-65.871574358844939 65.871574358844939"/>
        <geom name="0/1/geom" class="0/1/" type="capsule" contype="1" conaffinity="1" condim="3" size="0.051790947681311345" rgba="0.34077031017625592 0.91196193975445028 0.6242963519655137 1" friction="0.59999999999999998 0.10000000000000001 0.10000000000000001" fromto="0 0 0 -0.60099066228252018 -0.40735265869380788 -0.175695289861725"/>
        <site name="0/1/end1" class="0/1/" size="0.0050000000000000001" pos="-0.60099066228252018 -0.40735265869380788 -0.175695289861725"/>
      </body>
      <site name="0/attach2" class="0/" size="9.9999999999999995e-07 9.9999999999999995e-07 9.9999999999999995e-07" pos="0.10375513186549158 -0.064293749831114133 0.1842447695909333"/>
      <body pos="0.10375513186549158 -0.064293749831114133 0.1842447695909333" name="0/2/">
        <geom name="0/2/geom" class="0/2/" type="capsule" contype="1" conaffinity="1" condim="3" size="0.054524033385897709" rgba="0.60252530696239526 0.67631656658807682 0.63989682541760018 1" friction="0.59999999999999998 0.10000000000000001 0.10000000000000001" fromto="0 0 0 -0.59486376174156175 -0.074265761564610067 -0.095062530870097417"/>
        <site name="0/2/end2" class="0/2/" size="0.0050000000000000001" pos="-0.59486376174156175 -0.074265761564610067 -0.095062530870097417"/>
        <site name="0/2/attach3" class="0/2/" size="9.9999999999999995e-07 9.9999999999999995e-07 9.9999999999999995e-07" pos="-0.28859333581953972 -0.036029432696256199 -0.04611881687822203"/>
        <body pos="-0.28859333581953972 -0.036029432696256199 -0.04611881687822203" name="0/2/3/">
          <joint name="0/2/3/joint/" class="0/2/" type="hinge" axis="0.19874530694200124 -0.60335337959535529 -0.77231146715518384" limited="true" range="-54.958836033108341 54.958836033108341"/>
          <geom name="0/2/3/geom" class="0/2/3/" type="capsule" contype="1" conaffinity="1" condim="3" size="0.064549858638975666" rgba="0.056355291235210214 0.40942959376419408 0.45715406254878144 1" friction="0.59999999999999998 0.10000000000000001 0.10000000000000001" fromto="0 0 0 -0.28662077920993162 0.69225812134943165 -0.20203807673020413"/>
          <site name="0/2/3/end3" class="0/2/3/" size="0.0050000000000000001" pos="-0.28662077920993162 0.69225812134943165 -0.20203807673020413"/>
          <site name="0/2/3/attach4" class="0/2/3/" size="9.9999999999999995e-07 9.9999999999999995e-07 9.9999999999999995e-07" pos="-0.010026470882173856 0.02421633880066552 -0.0070676274728221312"/>
          <body pos="-0.010026470882173856 0.02421633880066552 -0.0070676274728221312" name="0/2/3/4/">
            <joint name="0/2/3/4/joint/" class="0/2/3/" type="hinge" axis="0 0.280165440483999 0.95995173105651865" limited="true" range="-52.071842533372205 52.071842533372205"/>
            <geom name="0/2/3/4/geom" class="0/2/3/4/" type="capsule" contype="1" conaffinity="1" condim="3" size="0.03620216779919716" rgba="0.81292691811016715 0.64843797842369366 0.94731693852851195 1" friction="0.59999999999999998 0.10000000000000001 0.10000000000000001" fromto="0 0 0 -0.02940914304284592 0.4926588543628081 0.2514406090821697"/>
            <site name="0/2/3/4/end4" class="0/2/3/4/" size="0.0050000000000000001" pos="-0.02940914304284592 0.4926588543628081 0.2514406090821697"/>
          </body>
          <site name="0/2/3/attach5" class="0/2/3/" size="9.9999999999999995e-07 9.9999999999999995e-07 9.9999999999999995e-07" pos="-0.10356485928857785 0.25013404515385151 -0.073002540308401517"/>
          <body pos="-0.10356485928857785 0.25013404515385151 -0.073002540308401517" name="0/2/3/5/">
            <joint name="0/2/3/5/joint/" class="0/2/3/" type="hinge" axis="-0.92928967962456532 -0.35455982074275777 0.10347958667358652" limited="true" range="-34.373635482368584 34.373635482368584"/>
            <geom name="0/2/3/5/geom" class="0/2/3/5/" type="capsule" contype="1" conaffinity="1" condim="3" size="0.060982017718497893" rgba="0.68211406669075447 0.061795614064734217 0.16972065769508771 1" friction="0.59999999999999998 0.10000000000000001 0.10000000000000001" fromto="0 0 0 -0.65468337779333907 0.70098987639908206 0.54571901301965342"/>
            <site name="0/2/3/5/end5" class="0/2/3/5/" size="0.0050000000000000001" pos="-0.65468337779333907 0.70098987639908206 0.54571901301965342"/>
            <site name="0/2/3/5/attach6" class="0/2/3/5/" size="9.9999999999999995e-07 9.9999999999999995e-07 9.9999999999999995e-07" pos="-0.49903063562080302 0.53432763905242564 0.41597284301835485"/>
            <body pos="-0.49903063562080302 0.53432763905242564 0.41597284301835485" name="0/2/3/5/6/">
              <joint name="0/2/3/5/6/joint/" class="0/2/3/5/" type="hinge" axis="0 -0.61429451013182867 0.78907683708362419" limited="true" range="-38.827386985235648 38.827386985235648"/>
              <geom name="0/2/3/5/6/geom" class="0/2/3/5/6/" type="capsule" contype="1" conaffinity="1" condim="3" size="0.051812729280927186" rgba="0.26968374991976196 0.97654990641966855 0.47787465128397166 1" friction="0.59999999999999998 0.10000000000000001 0.10000000000000001" fromto="0 0 0 0.19554800452691001 -0.28005206359890089 0.50917485705542331"/>
              <site name="0/2/3/5/6/end6" class="0/2/3/5/6/" size="0.0050000000000000001" pos="0.19554800452691001 -0.28005206359890089 0.50917485705542331"/>
              <site name="0/2/3/5/6/attach7" class="0/2/3/5/6/" size="9.9999999999999995e-07 9.9999999999999995e-07 9.9999999999999995e-07" pos="0.054980268665281225 -0.078739426332602211 0.14315958123040273"/>
              <body pos="0.054980268665281225 -0.078739426332602211 0.14315958123040273" name="0/2/3/5/6/7/">
                <joint name="0/2/3/5/6/7/joint/" class="0/2/3/5/6/" type="hinge" axis="5.5511151231257827e-17 0.87621162704438471 0.48192653447619183" limited="true" range="-67.512910830282493 67.512910830282493"/>
                <geom name="0/2/3/5/6/7/geom" class="0/2/3/5/6/7/" type="capsule" contype="1" conaffinity="1" condim="3" size="0.060752697525068455" rgba="0.85578736434897207 0.17645877016700062 0.27660756591298541 1" friction="0.59999999999999998 0.10000000000000001 0.10000000000000001" fromto="0 0 0 0.62067679579520618 0.41225409100239241 -0.19321872546881325"/>
                <site name="0/2/3/5/6/7/end7" class="0/2/3/5/6/7/" size="0.0050000000000000001" pos="0.62067679579520618 0.41225409100239241 -0.19321872546881325"/>
                <site name="0/2/3/5/6/7/attach8" class="0/2/3/5/6/7/" size="9.9999999999999995e-07 9.9999999999999995e-07 9.9999999999999995e-07" pos="0.57704908850422676 0.38327652822961622 -0.17963727687109429"/>
                <body pos="0.57704908850422676 0.38327652822961622 -0.17963727687109429" name="0/2/3/5/6/7/8/">
                  <joint name="0/2/3/5/6/7/8/joint/" class="0/2/3/5/6/7/" type="hinge" axis="-2.7755575615628914e-17 0.42438817341010227 0.90548035774920987" limited="true" range="-43.57965495178717 43.57965495178717"/>
                  <geom name="0/2/3/5/6/7/8/geom" class="0/2/3/5/6/7/8/" type="capsule" contype="1" conaffinity="1" condim="3" size="0.062517921636572299" rgba="0.9136129602662697 0.44224615117180577 0.39919234758796074 1" friction="0.59999999999999998 0.10000000000000001 0.10000000000000001" fromto="0 0 0 0.64125027522545786 -0.67657688602501986 -0.56401929010229168"/>
                  <site name="0/2/3/5/6/7/8/end8" class="0/2/3/5/6/7/8/" size="0.0050000000000000001" pos="0.64125027522545786 -0.67657688602501986 -0.56401929010229168"/>
                </body>
                <site name="0/2/3/5/6/7/attach9" class="0/2/3/5/6/7/" size="9.9999999999999995e-07 9.9999999999999995e-07 9.9999999999999995e-07" pos="0.23134713374663818 0.15366097617124072 -0.072019122716064241"/>
                <body pos="0.23134713374663818 0.15366097617124072 -0.072019122716064241" name="0/2/3/5/6/7/9/">
                  <joint name="0/2/3/5/6/7/9/joint/" class="0/2/3/5/6/7/" type="hinge" axis="-0.59146903874981605 0.73011390347478011 -0.34219594409225274" limited="true" range="-43.08095094159367 43.08095094159367"/>
                  <geom name="0/2/3/5/6/7/9/geom" class="0/2/3/5/6/7/9/" type="capsule" contype="1" conaffinity="1" condim="3" size="0.036620632271708947" rgba="0.75658706898193218 0.83631047816885618 0.8417353292516544 1" friction="0.59999999999999998 0.10000000000000001 0.10000000000000001" fromto="0 0 0 0.4248522458219921 -0.42532014985202005 -0.38770538112552128"/>
                  <site name="0/2/3/5/6/7/9/end9" class="0/2/3/5/6/7/9/" size="0.0050000000000000001" pos="0.4248522458219921 -0.42532014985202005 -0.38770538112552128"/>
                </body>
              </body>
            </body>
          </body>
        </body>
        <site name="0/2/attach10" class="0/2/" size="9.9999999999999995e-07 9.9999999999999995e-07 9.9999999999999995e-07" pos="-0.45761541130157973 -0.057130992354479514 -0.073129482683781638"/>
        <body pos="-0.45761541130157973 -0.057130992354479514 -0.073129482683781638" name="0/2/10/">
          <geom name="0/2/10/geom" class="0/2/10/" type="capsule" contype="1" conaffinity="1" condim="3" size="0.056556294836911353" rgba="0.48041477137477706 0.92714276689048525 0.15796839971030374 1" friction="0.59999999999999998 0.10000000000000001 0.10000000000000001" fromto="0 0 0 0.034009430822331765 0.29132793571881144 -0.54947361744567602"/>
          <site name="0/2/10/end10" class="0/2/10/" size="0.0050000000000000001" pos="0.034009430822331765 0.29132793571881144 -0.54947361744567602"/>
        </body>
      </body>
      <camera name="0/iso" class="0/" mode="trackcom" pos="-2.2999999999999998 -2.2999999999999998 1" xyaxes="0.45000000000000001 -0.45000000000000001 0 0.29999999999999999 0.14999999999999999 0.93999999999999995"/>
    </body>
  </worldbody>
  <actuator>
    <motor name="0/1/motor" class="0/1/" ctrllimited="true" ctrlrange="-1 1" gear="65" joint="0/1/joint/"/>
    <motor name="0/2/3/motor" class="0/2/3/" ctrllimited="true" ctrlrange="-1 1" gear="67" joint="0/2/3/joint/"/>
    <motor name="0/2/3/4/motor" class="0/2/3/4/" ctrllimited="true" ctrlrange="-1 1" gear="67" joint="0/2/3/4/joint/"/>
    <motor name="0/2/3/5/motor" class="0/2/3/5/" ctrllimited="true" ctrlrange="-1 1" gear="88" joint="0/2/3/5/joint/"/>
    <motor name="0/2/3/5/6/motor" class="0/2/3/5/6/" ctrllimited="true" ctrlrange="-1 1" gear="90" joint="0/2/3/5/6/joint/"/>
    <motor name="0/2/3/5/6/7/motor" class="0/2/3/5/6/7/" ctrllimited="true" ctrlrange="-1 1" gear="91" joint="0/2/3/5/6/7/joint/"/>
    <motor name="0/2/3/5/6/7/8/motor" class="0/2/3/5/6/7/8/" ctrllimited="true" ctrlrange="-1 1" gear="96" joint="0/2/3/5/6/7/8/joint/"/>
    <motor name="0/2/3/5/6/7/9/motor" class="0/2/3/5/6/7/9/" ctrllimited="true" ctrlrange="-1 1" gear="75" joint="0/2/3/5/6/7/9/joint/"/>
  </actuator>
  <sensor>
    <subtreelinvel name="velocity" body="0/"/>
  </sensor>
</mujoco>
