<mujoco model="morphology">
  <option timestep="0.01"/>
  <default>
    <default class="/"/>
    <default class="0/"/>
    <default class="0/1/"/>
    <default class="0/1/2/"/>
    <default class="0/1/2/3/"/>
    <default class="0/1/2/3/4/"/>
    <default class="0/1/2/3/4/5/"/>
    <default class="0/1/2/3/4/5/6/"/>
    <default class="0/7/"/>
  </default>
  <asset>
    <texture name="texplane" type="2d" builtin="checker" rgb1="0.10000000000000001 0.20000000000000001 0.29999999999999999" rgb2="0.20000000000000001 0.29999999999999999 0.40000000000000002" width="300" height="300"/>
    <material name="MatPlane" class="/" texture="texplane" texrepeat="20 20" specular="1" shininess="1" reflectance="0.5"/>
  </asset>
  <worldbody>
    <light name="//unnamed_light_0" class="/" directional="true" pos="0 0 1.5" dir="0 0 -1.3" cutoff="100" exponent="1" diffuse="1 1 1" specular="0.10000000000000001 0.10000000000000001 0.10000000000000001"/>
    <geom name="ground" class="/" type="plane" size="15 15 0.5" material="MatPlane" rgba="1 1 1 1"/>
    <site name="body" class="/" size="9.9999999999999995e-07 9.9999999999999995e-07 9.9999999999999995e-07" pos="0 0 0.98882786035537718"/>
    <body pos="0 0 0.98882786035537718" name="0/">
      <freejoint name="0/"/>
      <geom name="0/geom" class="0/" type="capsule" contype="1" conaffinity="1" condim="3" size="0.035545877138288537" rgba="0.086263893095356203 0.89873950953837878 0.31156291856156892 1" friction="0.59999999999999998 0.10000000000000001 0.10000000000000001" fromto="0 0 0 0.43725778188446496 0.60351475140650357 0.31614302740140543"/>
      <site name="0/end0" class="0/" size="0.0050000000000000001" pos="0.43725778188446496 0.60351475140650357 0.31614302740140543"/>
      <site name="0/attach1" class="0/" size="9.9999999999999995e-07 9.9999999999999995e-07 9.9999999999999995e-07" pos="0.29729385952124798 0.41033284519348773 0.21494730264567236"/>
      <body pos="0.29729385952124798 0.41033284519348773 0.21494730264567236" name="0/1/">
        <joint name="0/1/joint/" class="0/" type="hinge" axis="0 0 1" limited="true" range="-62.305593354417589 62.305593354417589"/>
        <geom name="0/1/geom" class="0/1/" type="capsule" contype="1" conaffinity="1" condim="3" size="0.058379993479713795" rgba="0.35484744629459919 0.27340278950908892 0.42438345154563983 1" friction="0.59999999999999998 0.10000000000000001 0.10000000000000001" fromto="0 0 0 0.071383537588482593 0.024133394844941813 -0.66865373432883746"/>
        <site name="0/1/end1" class="0/1/" size="0.0050000000000000001" pos="0.071383537588482593 0.024133394844941813 -0.66865373432883746"/>
        <site name="0/1/attach2" class="0/1/" size="9.9999999999999995e-07 9.9999999999999995e-07 9.9999999999999995e-07" pos="0.052576419740246357 0.017775071676042586 -0.4924863712922557"/>
        <body pos="0.052576419740246357 0.017775071676042586 -0.4924863712922557" name="0/1/2/">
          <joint name="0/1/2/joint/" class="0/1/" type="hinge" axis="-0.99435700091254797 0.0038264046708985089 -0.10601657117402752" limited="true" range="-64.801248333295234 64.801248333295234"/>
          <geom name="0/1/2/geom" class="0/1/2/" type="capsule" contype="1" conaffinity="1" condim="3" size="0.046137481972136608" rgba="0.67856063518312937 0.087054654629996286 0.89710132111448437 1" friction="0.59999999999999998 0.10000000000000001 0.10000000000000001" fromto="0 0 0 -0.74628008393074952 0.050352373617847501 -0.43551634521776411"/>
          <site name="0/1/2/end2" class="0/1/2/" size="0.0050000000000000001" pos="-0.74628008393074952 0.050352373617847501 -0.43551634521776411"/>
          <site name="0/1/2/attach3" class="0/1/2/" size="9.9999999999999995e-07 9.9999999999999995e-07 9.9999999999999995e-07" pos="-0.28645317802488546 0.019327324625840133 -0.16716919539418956"/>
          <body pos="-0.28645317802488546 0.019327324625840133 -0.16716919539418956" name="0/1/2/3/">
            <geom name="0/1/2/3/geom" class="0/1/2/3/" type="capsule" contype="1" conaffinity="1" condim="3" size="0.069382224489480282" rgba="0.93919246124619826 0.25754727913062259 0.17651875191405941 1" friction="0.59999999999999998 0.10000000000000001 0.10000000000000001" fromto="0 0 0 -0.28510350324715811 -0.58584807180730847 0.39268527669779529"/>
            <site name="0/1/2/3/end3" class="0/1/2/3/" size="0.0050000000000000001" pos="-0.28510350324715811 -0.58584807180730847 0.39268527669779529"/>
            <site name="0/1/2/3/attach4" class="0/1/2/3/" size="9.9999999999999995e-07 9.9999999999999995e-07 9.9999999999999995e-07" pos="-0.14033060723530014 -0.28835989290906339 0.19328336096800577"/>
            <body pos="-0.14033060723530014 -0.28835989290906339 0.19328336096800577" name="0/1/2/3/4/">
              <joint name="0/1/2/3/4/joint/" class="0/1/2/3/" type="hinge" axis="-5.5511151231257827e-17 0.55677936585761234 0.83066042264886741" limited="true" range="-62.36583846269734 62.36583846269734"/>
              <geom name="0/1/2/3/4/geom" class="0/1/2/3/4/" type="capsule" contype="1" conaffinity="1" condim="3" size="0.039415904734510052" rgba="0.5230225950336107 0.30763810565858152 0.52389026429892771 1" friction="0.59999999999999998 0.10000000000000001 0.10000000000000001" fromto="0 0 0 -0.14133086502549275 -0.45337585419305049 -0.3920805217507734"/>
              <site name="0/1/2/3/4/end4" class="0/1/2/3/4/" size="0.0050000000000000001" pos="-0.14133086502549275 -0.45337585419305049 -0.3920805217507734"/>
              <site name="0/1/2/3/4/attach5" class="0/1/2/3/4/" size="9.9999999999999995e-07 9.9999999999999995e-07 9.9999999999999995e-07" pos="-0.024365568351862411 -0.078162405377142516 -0.067595034888020836"/>
              <body pos="-0.024365568351862411 -0.078162405377142516 -0.067595034888020836" name="0/1/2/3/4/5/">
                <joint name="0/1/2/3/4/5/joint/" class="0/1/2/3/4/" type="hinge" axis="0.97330980289349367 -0.1735870515964783 -0.15011849689318746" limited="true" range="-44.039331331717193 44.039331331717193"/>
                <geom name="0/1/2/3/4/5/geom" class="0/1/2/3/4/5/" type="capsule" contype="1" conaffinity="1" condim="3" size="0.036076005034995653" rgba="0.68584885764159254 0.28517031143703508 0.80082540058953566 1" friction="0.59999999999999998 0.10000000000000001 0.10000000000000001" fromto="0 0 0 -0.26988525961183618 -0.33477739702254489 0.17480849514663221"/>
                <site name="0/1/2/3/4/5/end5" class="0/1/2/3/4/5/" size="0.0050000000000000001" pos="-0.26988525961183618 -0.33477739702254489 0.17480849514663221"/>
                <site name="0/1/2/3/4/5/attach6" class="0/1/2/3/4/5/" size="9.9999999999999995e-07 9.9999999999999995e-07 9.9999999999999995e-07" pos="-0.20248303973699577 -0.25116875624055418 0.13115112518574779"/>
                <body pos="-0.20248303973699577 -0.25116875624055418 0.13115112518574779" name="0/1/2/3/4/5/6/">
                  <joint name="0/1/2/3/4/5/6/joint/" class="0/1/2/3/4/5/" type="hinge" axis="0.81360950237966378 -0.51538111561836497 0.26911314219392091" limited="true" range="-51.972580522178347 51.972580522178347"/>
                  <geom name="0/1/2/3/4/5/6/geom" class="0/1/2/3/4/5/6/" type="capsule" contype="1" conaffinity="1" condim="3" size="0.059427992959166037" rgba="0.81099567128042349 0.64121314084376324 0.34800204220757636 1" friction="0.59999999999999998 0.10000000000000001 0.10000000000000001" fromto="0 0 0 0.48238856647431483 -0.73225965712767416 -0.70095904736444237"/>
                  <site name="0/1/2/3/4/5/6/end6" class="0/1/2/3/4/5/6/" size="0.0050000000000000001" pos="0.48238856647431483 -0.73225965712767416 -0.70095904736444237"/>
                </body>
              </body>
            </body>
          </body>
        </body>
      </body>
      <site name="0/attach7" class="0/" size="9.9999999999999995e-07 9.9999999999999995e-07 9.9999999999999995e-07" pos="0.012186156606323733 0.016819655543167548 0.0088107487196849282"/>
      <body pos="0.012186156606323733 0.016819655543167548 0.0088107487196849282" name="0/7/">
        <joint name="0/7/joint/" class="0/" type="hinge" axis="0 1 0" limited="true" range="-30.407725398577959 30.407725398577959"/>
        <geom name="0/7/geom" class="0/7/" type="capsule" contype="1" conaffinity="1" condim="3" size="0.054096960127279284" rgba="0.74706760427076058 0.71414225948617516 0.046184312597225663 1" friction="0.59999999999999998 0.10000000000000001 0.10000000000000001" fromto="0 0 0 -0.28366621318657337 -0.55975389696582334 0.43471728705261636"/>
        <site name="0/7/end7" class="0/7/" size="0.0050000000000000001" pos="-0.28366621318657337 -0.55975389696582334 0.43471728705261636"/>
      </body>
      <camera name="0/iso" class="0/" mode="trackcom" pos="-2.2999999999999998 -2.2999999999999998 1" xyaxes="0.45000000000000001 -0.45000000000000001 0 0.29999999999999999 0.14999999999999999 0.93999999999999995"/>
    </body>
  </worldbody>
  <actuator>
    <motor name="0/1/motor" class="0/1/" ctrllimited="true" ctrlrange="-1 1" gear="64" joint="0/1/joint/"/>
    <motor name="0/1/2/motor" class="0/1/2/" ctrllimited="true" ctrlrange="-1 1" gear="58" joint="0/1/2/joint/"/>
    <motor name="0/1/2/3/4/motor" class="0/1/2/3/4/" ctrllimited="true" ctrlrange="-1 1" gear="74" joint="0/1/2/3/4/joint/"/>
    <motor name="0/1/2/3/4/5/motor" class="0/1/2/3/4/5/" ctrllimited="true" ctrlrange="-1 1" gear="72" joint="0/1/2/3/4/5/joint/"/>
    <motor name="0/1/2/3/4/5/6/motor" class="0/1/2/3/4/5/6/" ctrllimited="true" ctrlrange="-1 1" gear="90" joint="0/1/2/3/4/5/6/joint/"/>
    <motor name="0/7/motor" class="0/7/" ctrllimited="true" ctrlrange="-1 1" gear="51" joint="0/7/joint/"/>
  </actuator>
  <sensor>
    <subtreelinvel name="velocity" body="0/"/>
  </sensor>
</mujoco>
