<mujoco model="morphology">
  <option timestep="0.01"/>
  <default>
    <default class="/"/>
    <default class="0/"/>
    <default class="0/1/"/>
    <default class="0/1/2/"/>
    <default class="0/1/2/3/"/>
  </default>
  <asset>
    <texture name="texplane" type="2d" builtin="checker" rgb1="0.10000000000000001 0.20000000000000001 0.29999999999999999" rgb2="0.20000000000000001 0.29999999999999999 0.40000000000000002" width="300" height="300"/>
    <material name="MatPlane" class="/" texture="texplane" texrepeat="20 20" specular="1" shininess="1" reflectance="0.5"/>
  </asset>
  <worldbody>
    <light name="//unnamed_light_0" class="/" directional="true" pos="0 0 1.5" dir="0 0 -1.3" cutoff="100" exponent="1" diffuse="1 1 1" specular="0.10000000000000001 0.10000000000000001 0.10000000000000001"/>
    <geom name="ground" class="/" type="plane" size="15 15 0.5" material="MatPlane" rgba="1 1 1 1"/>
    <site name="body" class="/" size="9.9999999999999995e-07 9.9999999999999995e-07 9.9999999999999995e-07" pos="0 0 1.0392065405845643"/>
    <body pos="0 0 1.0392065405845643" name="0/">
      <freejoint name="0/"/>
      <geom name="0/geom" class="0/" type="capsule" contype="1" conaffinity="1" condim="3" size="0.062937394482880465" rgba="0.71059615495107431 0.31756388889779408 0.63156921698371304 1" friction="0.59999999999999998 0.10000000000000001 0.10000000000000001" fromto="0 0 0 -0.72065617817479088 0.048356256884083515 0.14141680105570353"/>
      <site name="0/end0" class="0/" size="0.0050000000000000001" pos="-0.72065617817479088 0.048356256884083515 0.14141680105570353"/>
      <site name="0/attach1" class="0/" size="9.9999999999999995e-07 9.9999999999999995e-07 9.9999999999999995e-07" pos="-0.64774729764503058 0.043464048001676726 0.12710964465390218"/>
      <body pos="-0.64774729764503058 0.043464048001676726 0.12710964465390218" name="0/1/">
        <joint name="0/1/joint/" class="0/" type="hinge" axis="0 0 1" limited="true" range="-67.941810640813969 67.941810640813969"/>
        <geom name="0/1/geom" class="0/1/" type="capsule" contype="1" conaffinity="1" condim="3" size="0.039313079964015486" rgba="0.043708816408735029 0.74064899837644493 0.41461269933402234 1" friction="0.59999999999999998 0.10000000000000001 0.10000000000000001" fromto="0 0 0 -0.02475283608382739 0.67981698466391682 -0.41675732246795405"/>
        <site name="0/1/end1" class="0/1/" size="0.0050000000000000001" pos="-0.02475283608382739 0.67981698466391682 -0.41675732246795405"/>
        <site name="0/1/attach2" class="0/1/" size="9.9999999999999995e-07 9.9999999999999995e-07 9.9999999999999995e-07" pos="-0.0076309621055662266 0.2095783138191617 -0.1284806041699629"/>
        <body pos="-0.0076309621055662266 0.2095783138191617 -0.1284806041699629" name="0/1/2/">
          <joint name="0/1/2/joint/" class="0/1/" type="hinge" axis="-0.99951854038590171 -0.026452181226364224 0.016216335381480207" limited="true" range="-58.059624322841621 58.059624322841621"/>
          <geom name="0/1/2/geom" class="0/1/2/" type="capsule" contype="1" conaffinity="1" condim="3" size="0.037168607587289001" rgba="0.25164188035792812 0.29521337841783002 0.57128209816867792 1" friction="0.59999999999999998 0.10000000000000001 0.10000000000000001" fromto="0 0 0 -0.24065517494083299 -0.080223430511817018 -0.62890950886079844"/>
          <site name="0/1/2/end2" class="0/1/2/" size="0.0050000000000000001" pos="-0.24065517494083299 -0.080223430511817018 -0.62890950886079844"/>
          <site name="0/1/2/attach3" class="0/1/2/" size="9.9999999999999995e-07 9.9999999999999995e-07 9.9999999999999995e-07" pos="-0.20060212574838523 -0.066871575479126727 -0.52423798662076004"/>
          <body pos="-0.20060212574838523 -0.066871575479126727 -0.52423798662076004" name="0/1/2/3/">
            <joint name="0/1/2/3/joint/" class="0/1/2/" type="hinge" axis="0.93491421117562701 -0.044903702316857558 -0.35202141307041934" limited="true" range="-30.44120645796994 30.44120645796994"/>
            <geom name="0/1/2/3/geom" class="0/1/2/3/" type="capsule" contype="1" conaffinity="1" condim="3" size="0.054041264214717513" rgba="0.16042128797600419 0.3074559079561523 0.81794218266325081 1" friction="0.59999999999999998 0.10000000000000001 0.10000000000000001" fromto="0 0 0 -0.16677773164353438 0.53634439884889584 -0.41359760407847723"/>
            <site name="0/1/2/3/end3" class="0/1/2/3/" size="0.0050000000000000001" pos="-0.16677773164353438 0.53634439884889584 -0.41359760407847723"/>
          </body>
        </body>
      </body>
      <camera name="0/iso" class="0/" mode="trackcom" pos="-2.2999999999999998 -2.2999999999999998 1" xyaxes="0.45000000000000001 -0.45000000000000001 0 0.29999999999999999 0.14999999999999999 0.93999999999999995"/>
    </body>
  </worldbody>
  <actuator>
    <motor name="0/1/motor" class="0/1/" ctrllimited="true" ctrlrange="-1 1" gear="87" joint="0/1/joint/"/>
    <motor name="0/1/2/motor" class="0/1/2/" ctrllimited="true" ctrlrange="-1 1" gear="75" joint="0/1/2/joint/"/>
    <motor name="0/1/2/3/motor" class="0/1/2/3/" ctrllimited="true" ctrlrange="-1 1" gear="86" joint="0/1/2/3/joint/"/>
  </actuator>
  <sensor>
    <subtreelinvel name="velocity" body="0/"/>
  </sensor>
</mujoco>
