<mujoco model="morphology">
  <option timestep="0.01"/>
  <default>
    <default class="/"/>
    <default class="0/"/>
    <default class="0/1/"/>
    <default class="0/2/"/>
    <default class="0/2/3/"/>
    <default class="0/2/3/4/"/>
    <default class="0/2/3/5/"/>
    <default class="0/2/3/5/6/"/>
    <default class="0/2/3/5/7/"/>
    <default class="0/2/3/5/7/8/"/>
    <default class="0/2/9/"/>
    <default class="0/10/"/>
  </default>
  <asset>
    <texture name="texplane" type="2d" builtin="checker" rgb1="0.10000000000000001 0.20000000000000001 0.29999999999999999" rgb2="0.20000000000000001 0.29999999999999999 0.40000000000000002" width="300" height="300"/>
    <material name="MatPlane" class="/" texture="texplane" texrepeat="20 20" specular="1" shininess="1" reflectance="0.5"/>
  </asset>
  <worldbody>
    <light name="//unnamed_light_0" class="/" directional="true" pos="0 0 1.5" dir="0 0 -1.3" cutoff="100" exponent="1" diffuse="1 1 1" specular="0.10000000000000001 0.10000000000000001 0.10000000000000001"/>
    <geom name="ground" class="/" type="plane" size="15 15 0.5" material="MatPlane" rgba="1 1 1 1"/>
    <site name="body" class="/" size="9.9999999999999995e-07 9.9999999999999995e-07 9.9999999999999995e-07" pos="0 0 1.2806426048278809"/>
    <body pos="0 0 1.2806426048278809" name="0/">
      <freejoint name="0/"/>
      <geom name="0/geom" class="0/" type="capsule" contype="1" conaffinity="1" condim="3" size="0.067290883719079625" rgba="0.55921885196480081 0.45321629731859148 0.082707748662700808 1" friction="0.59999999999999998 0.10000000000000001 0.10000000000000001" fromto="0 0 0 -0.30620686909280215 -0.48843616133035211 -0.27715190412401125"/>
      <site name="0/end0" class="0/" size="0.0050000000000000001" pos="-0.30620686909280215 -0.48843616133035211 -0.27715190412401125"/>
      <site name="0/attach1" class="0/" size="9.9999999999999995e-07 9.9999999999999995e-07 9.9999999999999995e-07" pos="-0.057149390646503311 -0.091160035280877252 -0.051726672507810413"/>
      <body pos="-0.057149390646503311 -0.091160035280877252 -0.051726672507810413" name="0/1/">
        <geom name="0/1/geom" class="0/1/" type="capsule" contype="1" conaffinity="1" condim="3" size="0.041430730111713249" rgba="0.73065617214850487 0.19637242294730983 0.18067693016740694 1" friction="0.59999999999999998 0.10000000000000001 0.10000000000000001" fromto="0 0 0 -0.61702208024551042 0.56896471852442376 0.70086644439197832"/>
        <site name="0/1/end1" class="0/1/" size="0.0050000000000000001" pos="-0.61702208024551042 0.56896471852442376 0.70086644439197832"/>
      </body>
      <site name="0/attach2" class="0/" size="9.9999999999999995e-07 9.9999999999999995e-07 9.9999999999999995e-07" pos="-0.19345301110620819 -0.30858042611015812 -0.1750968897120323"/>
      <body pos="-0.19345301110620819 -0.30858042611015812 -0.1750968897120323" name="0/2/">
        <joint name="0/2/joint/" class="0/" type="hinge" axis="0 1 0" limited="true" range="-50.170902470684311 50.170902470684311"/>
        <geom name="0/2/geom" class="0/2/" type="capsule" contype="1" conaffinity="1" condim="3" size="0.038305305108796789" rgba="0.96063892574412868 0.02086641070786166 0.53844088138134216 1" friction="0.59999999999999998 0.10000000000000001 0.10000000000000001" fromto="0 0 0 0.45910079280768201 -0.42590991299860137 -0.010377779003178489"/>
        <site name="0/2/end2" class="0/2/" size="0.0050000000000000001" pos="0.45910079280768201 -0.42590991299860137 -0.010377779003178489"/>
        <site name="0/2/attach3" class="0/2/" size="9.9999999999999995e-07 9.9999999999999995e-07 9.9999999999999995e-07" pos="0.0023486985226480479 -0.0021788984012058002 -5.3091335486636081e-05"/>
        <body pos="0.0023486985226480479 -0.0021788984012058002 -5.3091335486636081e-05" name="0/2/3/">
          <joint name="0/2/3/joint/" class="0/2/" type="hinge" axis="0.68021824666083963 0.7327921429015718 0.01785531325335242" limited="true" range="-50.824125025570822 50.824125025570822"/>
          <geom name="0/2/3/geom" class="0/2/3/" type="capsule" contype="1" conaffinity="1" condim="3" size="0.050511012277198765" rgba="0.56655710902216372 0.98856870348139858 0.94835705791223412 1" friction="0.59999999999999998 0.10000000000000001 0.10000000000000001" fromto="0 0 0 -0.40941847100381601 0.5071091092308555 -0.39196341175395172"/>
          <site name="0/2/3/end3" class="0/2/3/" size="0.0050000000000000001" pos="-0.40941847100381601 0.5071091092308555 -0.39196341175395172"/>
          <site name="0/2/3/attach4" class="0/2/3/" size="9.9999999999999995e-07 9.9999999999999995e-07 9.9999999999999995e-07" pos="-0.067644492685774105 0.083785028912230747 -0.064760551898094806"/>
          <body pos="-0.067644492685774105 0.083785028912230747 -0.064760551898094806" name="0/2/3/4/">
            <joint name="0/2/3/4/joint/" class="0/2/3/" type="hinge" axis="1.1102230246251565e-16 0.61155141216039977 0.79120469556532635" limited="true" range="-30.211758512721726 30.211758512721726"/>
            <geom name="0/2/3/4/geom" class="0/2/3/4/" type="capsule" contype="1" conaffinity="1" condim="3" size="0.039861051938930289" rgba="0.034417643877907245 0.34796765921144901 0.78784058712559613 1" friction="0.59999999999999998 0.10000000000000001 0.10000000000000001" fromto="0 0 0 0.16818730123114722 0.60654707367213079 0.00021744964870551442"/>
            <site name="0/2/3/4/end4" class="0/2/3/4/" size="0.0050000000000000001" pos="0.16818730123114722 0.60654707367213079 0.00021744964870551442"/>
          </body>
          <site name="0/2/3/attach5" class="0/2/3/" size="9.9999999999999995e-07 9.9999999999999995e-07 9.9999999999999995e-07" pos="-0.13148279483085992 0.16285567869564743 -0.12587718556637459"/>
          <body pos="-0.13148279483085992 0.16285567869564743 -0.12587718556637459" name="0/2/3/5/">
            <geom name="0/2/3/5/geom" class="0/2/3/5/" type="capsule" contype="1" conaffinity="1" condim="3" size="0.049187109354763753" rgba="0.72957066419437733 0.6554474769677322 0.53246311042871375 1" friction="0.59999999999999998 0.10000000000000001 0.10000000000000001" fromto="0 0 0 -0.60162180329325354 -0.12312447689634587 -0.6717036925660187"/>
            <site name="0/2/3/5/end5" class="0/2/3/5/" size="0.0050000000000000001" pos="-0.60162180329325354 -0.12312447689634587 -0.6717036925660187"/>
            <site name="0/2/3/5/attach6" class="0/2/3/5/" size="9.9999999999999995e-07 9.9999999999999995e-07 9.9999999999999995e-07" pos="-0.3814300132097837 -0.078061284667452727 -0.42586213951363633"/>
            <body pos="-0.3814300132097837 -0.078061284667452727 -0.42586213951363633" name="0/2/3/5/6/">
              <joint name="0/2/3/5/6/joint/" class="0/2/3/5/" type="hinge" axis="1.6653345369377348e-16 -0.98361206331846296 0.18029783385941101" limited="true" range="-49.241785597281194 49.241785597281194"/>
              <geom name="0/2/3/5/6/geom" class="0/2/3/5/6/" type="capsule" contype="1" conaffinity="1" condim="3" size="0.048906350145891613" rgba="0.99568893863580477 0.4650556341594666 0.048525795913250569 1" friction="0.59999999999999998 0.10000000000000001 0.10000000000000001" fromto="0 0 0 0.21494904948839988 0.41503496955474439 0.16438945321353038"/>
              <site name="0/2/3/5/6/end6" class="0/2/3/5/6/" size="0.0050000000000000001" pos="0.21494904948839988 0.41503496955474439 0.16438945321353038"/>
            </body>
            <site name="0/2/3/5/attach7" class="0/2/3/5/" size="9.9999999999999995e-07 9.9999999999999995e-07 9.9999999999999995e-07" pos="-0.21515011732190606 -0.044031392320624994 -0.24021258450085337"/>
            <body pos="-0.21515011732190606 -0.044031392320624994 -0.24021258450085337" name="0/2/3/5/7/">
              <geom name="0/2/3/5/7/geom" class="0/2/3/5/7/" type="capsule" contype="1" conaffinity="1" condim="3" size="0.049851325667195107" rgba="0.39505838153690265 0.79020491499694578 0.25993879126402164 1" friction="0.59999999999999998 0.10000000000000001 0.10000000000000001" fromto="0 0 0 0.39263008827144774 -0.58199553760764422 -0.63940279560248481"/>
              <site name="0/2/3/5/7/end7" class="0/2/3/5/7/" size="0.0050000000000000001" pos="0.39263008827144774 -0.58199553760764422 -0.63940279560248481"/>
              <site name="0/2/3/5/7/attach8" class="0/2/3/5/7/" size="9.9999999999999995e-07 9.9999999999999995e-07 9.9999999999999995e-07" pos="0.23600995087588442 -0.34983752479458846 -0.38434502827943234"/>
              <body pos="0.23600995087588442 -0.34983752479458846 -0.38434502827943234" name="0/2/3/5/7/8/">
                <joint name="0/2/3/5/7/8/joint/" class="0/2/3/5/7/" type="hinge" axis="0.91051541743659858 0.27832199985922007 0.30577530803618003" limited="true" range="-62.583801903349695 62.583801903349695"/>
                <geom name="0/2/3/5/7/8/geom" class="0/2/3/5/7/8/" type="capsule" contype="1" conaffinity="1" condim="3" size="0.052982076677266315" rgba="0.2277147879558894 0.51881723554455761 0.75016100012591191 1" friction="0.59999999999999998 0.10000000000000001 0.10000000000000001" fromto="0 0 0 0.39080610765663715 -0.55219811222433102 0.66836320276785344"/>
                <site name="0/2/3/5/7/8/end8" class="0/2/3/5/7/8/" size="0.0050000000000000001" pos="0.39080610765663715 -0.55219811222433102 0.66836320276785344"/>
              </body>
            </body>
          </body>
        </body>
        <site name="0/2/attach9" class="0/2/" size="9.9999999999999995e-07 9.9999999999999995e-07 9.9999999999999995e-07" pos="0.42872069838342741 -0.39772615994081956 -0.0096910498339638339"/>
        <body pos="0.42872069838342741 -0.39772615994081956 -0.0096910498339638339" name="0/2/9/">
          <geom name="0/2/9/geom" class="0/2/9/" type="capsule" contype="1" conaffinity="1" condim="3" size="0.059579043529356557" rgba="0.22159416958195466 0.99705216669084296 0.7013038971683242 1" friction="0.59999999999999998 0.10000000000000001 0.10000000000000001" fromto="0 0 0 -0.65242779689605901 0.14486484537535271 0.51940247610432633"/>
          <site name="0/2/9/end9" class="0/2/9/" size="0.0050000000000000001" pos="-0.65242779689605901 0.14486484537535271 0.51940247610432633"/>
        </body>
      </body>
      <site name="0/attach10" class="0/" size="9.9999999999999995e-07 9.9999999999999995e-07 9.9999999999999995e-07" pos="-0.28136527163169572 -0.44881087617210397 -0.2546674443265361"/>
      <body pos="-0.28136527163169572 -0.44881087617210397 -0.2546674443265361" name="0/10/">
        <joint name="0/10/joint/" class="0/" type="hinge" axis="0 1 0" limited="true" range="-57.931538925701147 57.931538925701147"/>
        <geom name="0/10/geom" class="0/10/" type="capsule" contype="1" conaffinity="1" condim="3" size="0.038333892563032573" rgba="0.69223518802138251 0.68717925728043727 0.16852544406393122 1" friction="0.59999999999999998 0.10000000000000001 0.10000000000000001" fromto="0 0 0 -0.55310048427159764 0.33845132595181382 0.62721223518301938"/>
        <site name="0/10/end10" class="0/10/" size="0.0050000000000000001" pos="-0.55310048427159764 0.33845132595181382 0.62721223518301938"/>
      </body>
      <camera name="0/iso" class="0/" mode="trackcom" pos="-2.2999999999999998 -2.2999999999999998 1" xyaxes="0.45000000000000001 -0.45000000000000001 0 0.29999999999999999 0.14999999999999999 0.93999999999999995"/>
    </body>
  </worldbody>
  <actuator>
    <motor name="0/2/motor" class="0/2/" ctrllimited="true" ctrlrange="-1 1" gear="51" joint="0/2/joint/"/>
    <motor name="0/2/3/motor" class="0/2/3/" ctrllimited="true" ctrlrange="-1 1" gear="57" joint="0/2/3/joint/"/>
    <motor name="0/2/3/4/motor" class="0/2/3/4/" ctrllimited="true" ctrlrange="-1 1" gear="95" joint="0/2/3/4/joint/"/>
    <motor name="0/2/3/5/6/motor" class="0/2/3/5/6/" ctrllimited="true" ctrlrange="-1 1" gear="54" joint="0/2/3/5/6/joint/"/>
    <motor name="0/2/3/5/7/8/motor" class="0/2/3/5/7/8/" ctrllimited="true" ctrlrange="-1 1" gear="63" joint="0/2/3/5/7/8/joint/"/>
    <motor name="0/10/motor" class="0/10/" ctrllimited="true" ctrlrange="-1 1" gear="90" joint="0/10/joint/"/>
  </actuator>
  <sensor>
    <subtreelinvel name="velocity" body="0/"/>
  </sensor>
</mujoco>
