<mujoco model="morphology">
  <option timestep="0.01"/>
  <default>
    <default class="/"/>
    <default class="0/"/>
    <default class="0/1/"/>
    <default class="0/1/2/"/>
    <default class="0/1/3/"/>
    <default class="0/1/3/4/"/>
    <default class="0/1/3/4/5/"/>
    <default class="0/1/3/4/5/6/"/>
    <default class="0/1/3/4/7/"/>
    <default class="0/1/3/4/7/8/"/>
    <default class="0/1/3/4/7/9/"/>
    <default class="0/1/3/4/7/10/"/>
  </default>
  <asset>
    <texture name="texplane" type="2d" builtin="checker" rgb1="0.10000000000000001 0.20000000000000001 0.29999999999999999" rgb2="0.20000000000000001 0.29999999999999999 0.40000000000000002" width="300" height="300"/>
    <material name="MatPlane" class="/" texture="texplane" texrepeat="20 20" specular="1" shininess="1" reflectance="0.5"/>
  </asset>
  <worldbody>
    <light name="//unnamed_light_0" class="/" directional="true" pos="0 0 1.5" dir="0 0 -1.3" cutoff="100" exponent="1" diffuse="1 1 1" specular="0.10000000000000001 0.10000000000000001 0.10000000000000001"/>
    <geom name="ground" class="/" type="plane" size="15 15 0.5" material="MatPlane" rgba="1 1 1 1"/>
    <site name="body" class="/" size="9.9999999999999995e-07 9.9999999999999995e-07 9.9999999999999995e-07" pos="0 0 0.10000000000000001"/>
    <body pos="0 0 0.10000000000000001" name="0/">
      <freejoint name="0/"/>
      <geom name="0/geom" class="0/" type="capsule" contype="1" conaffinity="1" condim="3" size="0.06181276182615579" rgba="0.48720954031082098 0.27504264848455029 0.87078017761788573 1" friction="0.59999999999999998 0.10000000000000001 0.10000000000000001" fromto="0 0 0 0.29462123323665779 0.085013521291679273 0.69715608204467694"/>
      <site name="0/end0" class="0/" size="0.0050000000000000001" pos="0.29462123323665779 0.085013521291679273 0.69715608204467694"/>
      <site name="0/attach1" class="0/" size="9.9999999999999995e-07 9.9999999999999995e-07 9.9999999999999995e-07" pos="0.23087764621551726 0.066620187135492323 0.54632096098116578"/>
      <body pos="0.23087764621551726 0.066620187135492323 0.54632096098116578" name="0/1/">
        <geom name="0/1/geom" class="0/1/" type="capsule" contype="1" conaffinity="1" condim="3" size="0.052776513839980499" rgba="0.6876695048949083 0.13802295022899935 0.14437039737275148 1" friction="0.59999999999999998 0.10000000000000001 0.10000000000000001" fromto="0 0 0 0.15890996760557852 0.53688917032509487 0.12351988748768272"/>
        <site name="0/1/end1" class="0/1/" size="0.0050000000000000001" pos="0.15890996760557852 0.53688917032509487 0.12351988748768272"/>
        <site name="0/1/attach2" class="0/1/" size="9.9999999999999995e-07 9.9999999999999995e-07 9.9999999999999995e-07" pos="0.15455191110985747 0.5221651516151733 0.12013239294515957"/>
        <body pos="0.15455191110985747 0.5221651516151733 0.12013239294515957" name="0/1/2/">
          <joint name="0/1/2/joint/" class="0/1/" type="hinge" axis="-0.96082719995462373 0.27009226952194026 0.062139019720665767" limited="true" range="-68.333572341581785 68.333572341581785"/>
          <geom name="0/1/2/geom" class="0/1/2/" type="capsule" contype="1" conaffinity="1" condim="3" size="0.063994435101423455" rgba="0.30696173798796067 0.34887495751161568 0.91114955281821375 1" friction="0.59999999999999998 0.10000000000000001 0.10000000000000001" fromto="0 0 0 -0.10368523337831514 -0.049131893021514328 0.23613398542380293"/>
          <site name="0/1/2/end2" class="0/1/2/" size="0.0050000000000000001" pos="-0.10368523337831514 -0.049131893021514328 0.23613398542380293"/>
        </body>
        <site name="0/1/attach3" class="0/1/" size="9.9999999999999995e-07 9.9999999999999995e-07 9.9999999999999995e-07" pos="0.088432097936105986 0.29877443439461604 0.068737807652690608"/>
        <body pos="0.088432097936105986 0.29877443439461604 0.068737807652690608" name="0/1/3/">
          <geom name="0/1/3/geom" class="0/1/3/" type="capsule" contype="1" conaffinity="1" condim="3" size="0.063051010954659134" rgba="0.91816186685122791 0.54628363406473224 0.86707005862048492 1" friction="0.59999999999999998 0.10000000000000001 0.10000000000000001" fromto="0 0 0 -0.51796362234814586 -0.27038652249934819 0.5215898718881431"/>
          <site name="0/1/3/end3" class="0/1/3/" size="0.0050000000000000001" pos="-0.51796362234814586 -0.27038652249934819 0.5215898718881431"/>
          <site name="0/1/3/attach4" class="0/1/3/" size="9.9999999999999995e-07 9.9999999999999995e-07 9.9999999999999995e-07" pos="-0.20409931039711529 -0.10654358800838402 0.20552820423928522"/>
          <body pos="-0.20409931039711529 -0.10654358800838402 0.20552820423928522" name="0/1/3/4/">
            <joint name="0/1/3/4/joint/" class="0/1/3/" type="hinge" axis="0.75010712090719989 -0.30435539546847518 0.58711762059534467" limited="true" range="-68.731247959585289 68.731247959585289"/>
            <geom name="0/1/3/4/geom" class="0/1/3/4/" type="capsule" contype="1" conaffinity="1" condim="3" size="0.065050064478710548" rgba="0.7613900879864286 0.41584365584107741 0.35061609775899294 1" friction="0.59999999999999998 0.10000000000000001 0.10000000000000001" fromto="0 0 0 -0.11005670557844227 0.5372478351512171 0.55500188456044919"/>
            <site name="0/1/3/4/end4" class="0/1/3/4/" size="0.0050000000000000001" pos="-0.11005670557844227 0.5372478351512171 0.55500188456044919"/>
            <site name="0/1/3/4/attach5" class="0/1/3/4/" size="9.9999999999999995e-07 9.9999999999999995e-07 9.9999999999999995e-07" pos="-0.038240127788441838 0.18667127788595633 0.19284007164189382"/>
            <body pos="-0.038240127788441838 0.18667127788595633 0.19284007164189382" name="0/1/3/4/5/">
              <joint name="0/1/3/4/5/joint/" class="0/1/3/4/" type="hinge" axis="-0.99000177555521052 -0.098106670660629558 -0.10134873245096493" limited="true" range="-48.749627992438604 48.749627992438604"/>
              <geom name="0/1/3/4/5/geom" class="0/1/3/4/5/" type="capsule" contype="1" conaffinity="1" condim="3" size="0.062494564824765356" rgba="0.14369536352279488 0.66907539656156312 0.40989148270045928 1" friction="0.59999999999999998 0.10000000000000001 0.10000000000000001" fromto="0 0 0 0.11883668691993721 0.18739411976196907 -0.51767233128740231"/>
              <site name="0/1/3/4/5/end5" class="0/1/3/4/5/" size="0.0050000000000000001" pos="0.11883668691993721 0.18739411976196907 -0.51767233128740231"/>
              <site name="0/1/3/4/5/attach6" class="0/1/3/4/5/" size="9.9999999999999995e-07 9.9999999999999995e-07 9.9999999999999995e-07" pos="0.10800175520599506 0.17030846596397017 -0.47047357049162969"/>
              <body pos="0.10800175520599506 0.17030846596397017 -0.47047357049162969" name="0/1/3/4/5/6/">
                <joint name="0/1/3/4/5/6/joint/" class="0/1/3/4/5/" type="hinge" axis="1.1102230246251565e-16 0.94028850377468676 0.3403785094114502" limited="true" range="-38.112377099556369 38.112377099556369"/>
                <geom name="0/1/3/4/5/6/geom" class="0/1/3/4/5/6/" type="capsule" contype="1" conaffinity="1" condim="3" size="0.037061678143040677" rgba="0.034467695494103667 0.73169530420541251 0.87351182638388769 1" friction="0.59999999999999998 0.10000000000000001 0.10000000000000001" fromto="0 0 0 -0.61097267715492132 0.17818545739496716 -0.17919154278470395"/>
                <site name="0/1/3/4/5/6/end6" class="0/1/3/4/5/6/" size="0.0050000000000000001" pos="-0.61097267715492132 0.17818545739496716 -0.17919154278470395"/>
              </body>
            </body>
            <site name="0/1/3/4/attach7" class="0/1/3/4/" size="9.9999999999999995e-07 9.9999999999999995e-07 9.9999999999999995e-07" pos="-0.07276820371588931 0.35522197133494843 0.36696074070300072"/>
            <body pos="-0.07276820371588931 0.35522197133494843 0.36696074070300072" name="0/1/3/4/7/">
              <geom name="0/1/3/4/7/geom" class="0/1/3/4/7/" type="capsule" contype="1" conaffinity="1" condim="3" size="0.063307073408393782" rgba="0.13806768338226871 0.079595028468552598 0.37467340013229511 1" friction="0.59999999999999998 0.10000000000000001 0.10000000000000001" fromto="0 0 0 0.70522535140889064 -0.0249532369701293 0.15829956676686141"/>
              <site name="0/1/3/4/7/end7" class="0/1/3/4/7/" size="0.0050000000000000001" pos="0.70522535140889064 -0.0249532369701293 0.15829956676686141"/>
              <site name="0/1/3/4/7/attach8" class="0/1/3/4/7/" size="9.9999999999999995e-07 9.9999999999999995e-07 9.9999999999999995e-07" pos="0.55019048897097844 -0.019467583833417845 0.12349941174031304"/>
              <body pos="0.55019048897097844 -0.019467583833417845 0.12349941174031304" name="0/1/3/4/7/8/">
                <joint name="0/1/3/4/7/8/joint/" class="0/1/3/4/7/" type="hinge" axis="0.22158920170602098 0.15183937908977146 -0.9632460893483662" limited="true" range="-60.472695758367735 60.472695758367735"/>
                <geom name="0/1/3/4/7/8/geom" class="0/1/3/4/7/8/" type="capsule" contype="1" conaffinity="1" condim="3" size="0.038604259314929529" rgba="0.040605008756350203 0.1682249910406487 0.3608592493714996 1" friction="0.59999999999999998 0.10000000000000001 0.10000000000000001" fromto="0 0 0 -0.065048117026971886 0.41065333491356948 -0.07607511807764078"/>
                <site name="0/1/3/4/7/8/end8" class="0/1/3/4/7/8/" size="0.0050000000000000001" pos="-0.065048117026971886 0.41065333491356948 -0.07607511807764078"/>
              </body>
              <site name="0/1/3/4/7/attach9" class="0/1/3/4/7/" size="9.9999999999999995e-07 9.9999999999999995e-07 9.9999999999999995e-07" pos="0.29359868728296551 -0.010388505749622383 0.065903111547766097"/>
              <body pos="0.29359868728296551 -0.010388505749622383 0.065903111547766097" name="0/1/3/4/7/9/">
                <geom name="0/1/3/4/7/9/geom" class="0/1/3/4/7/9/" type="capsule" contype="1" conaffinity="1" condim="3" size="0.045554751081140057" rgba="0.73791241354407644 0.29024600138582979 0.97377654818683168 1" friction="0.59999999999999998 0.10000000000000001 0.10000000000000001" fromto="0 0 0 0.001844831701268479 0.045771581461402144 0.1164629309316203"/>
                <site name="0/1/3/4/7/9/end9" class="0/1/3/4/7/9/" size="0.0050000000000000001" pos="0.001844831701268479 0.045771581461402144 0.1164629309316203"/>
              </body>
              <site name="0/1/3/4/7/attach10" class="0/1/3/4/7/" size="9.9999999999999995e-07 9.9999999999999995e-07 9.9999999999999995e-07" pos="0.060478625350946481 -0.0021399364997229612 0.013575433969558593"/>
              <body pos="0.060478625350946481 -0.0021399364997229612 0.013575433969558593" name="0/1/3/4/7/10/">
                <geom name="0/1/3/4/7/10/geom" class="0/1/3/4/7/10/" type="capsule" contype="1" conaffinity="1" condim="3" size="0.058219758664378958" rgba="0.21771705526083618 0.83014671410189034 0.96201196881306084 1" friction="0.59999999999999998 0.10000000000000001 0.10000000000000001" fromto="0 0 0 0.42508628778568469 0.52708394773493206 -0.26266001782886234"/>
                <site name="0/1/3/4/7/10/end10" class="0/1/3/4/7/10/" size="0.0050000000000000001" pos="0.42508628778568469 0.52708394773493206 -0.26266001782886234"/>
              </body>
            </body>
          </body>
        </body>
      </body>
      <camera name="0/iso" class="0/" mode="trackcom" pos="-2.2999999999999998 -2.2999999999999998 1" xyaxes="0.45000000000000001 -0.45000000000000001 0 0.29999999999999999 0.14999999999999999 0.93999999999999995"/>
    </body>
  </worldbody>
  <actuator>
    <motor name="0/1/2/motor" class="0/1/2/" ctrllimited="true" ctrlrange="-1 1" gear="62" joint="0/1/2/joint/"/>
    <motor name="0/1/3/4/motor" class="0/1/3/4/" ctrllimited="true" ctrlrange="-1 1" gear="95" joint="0/1/3/4/joint/"/>
    <motor name="0/1/3/4/5/motor" class="0/1/3/4/5/" ctrllimited="true" ctrlrange="-1 1" gear="92" joint="0/1/3/4/5/joint/"/>
    <motor name="0/1/3/4/5/6/motor" class="0/1/3/4/5/6/" ctrllimited="true" ctrlrange="-1 1" gear="61" joint="0/1/3/4/5/6/joint/"/>
    <motor name="0/1/3/4/7/8/motor" class="0/1/3/4/7/8/" ctrllimited="true" ctrlrange="-1 1" gear="65" joint="0/1/3/4/7/8/joint/"/>
  </actuator>
  <sensor>
    <subtreelinvel name="velocity" body="0/"/>
  </sensor>
</mujoco>
