<mujoco model="morphology">
  <option timestep="0.01"/>
  <default>
    <default class="/"/>
    <default class="0/"/>
    <default class="0/1/"/>
    <default class="0/1/2/"/>
    <default class="0/1/2/3/"/>
    <default class="0/1/2/3/4/"/>
    <default class="0/1/2/3/4/5/"/>
    <default class="0/1/2/3/4/5/6/"/>
    <default class="0/1/2/3/7/"/>
    <default class="0/1/8/"/>
    <default class="0/1/8/9/"/>
    <default class="0/1/8/9/10/"/>
  </default>
  <asset>
    <texture name="texplane" type="2d" builtin="checker" rgb1="0.10000000000000001 0.20000000000000001 0.29999999999999999" rgb2="0.20000000000000001 0.29999999999999999 0.40000000000000002" width="300" height="300"/>
    <material name="MatPlane" class="/" texture="texplane" texrepeat="20 20" specular="1" shininess="1" reflectance="0.5"/>
  </asset>
  <worldbody>
    <light name="//unnamed_light_0" class="/" directional="true" pos="0 0 1.5" dir="0 0 -1.3" cutoff="100" exponent="1" diffuse="1 1 1" specular="0.10000000000000001 0.10000000000000001 0.10000000000000001"/>
    <geom name="ground" class="/" type="plane" size="15 15 0.5" material="MatPlane" rgba="1 1 1 1"/>
    <site name="body" class="/" size="9.9999999999999995e-07 9.9999999999999995e-07 9.9999999999999995e-07" pos="0 0 0.89413598775863645"/>
    <body pos="0 0 0.89413598775863645" name="0/">
      <freejoint name="0/"/>
      <geom name="0/geom" class="0/" type="capsule" contype="1" conaffinity="1" condim="3" size="0.037298405831828474" rgba="0.99846503491456495 0.1527190962236683 0.43986388479373673 1" friction="0.59999999999999998 0.10000000000000001 0.10000000000000001" fromto="0 0 0 0.24437146826491152 -0.18853383184953709 0.57566236873524601"/>
      <site name="0/end0" class="0/" size="0.0050000000000000001" pos="0.24437146826491152 -0.18853383184953709 0.57566236873524601"/>
      <site name="0/attach1" class="0/" size="9.9999999999999995e-07 9.9999999999999995e-07 9.9999999999999995e-07" pos="0.091434960266010792 -0.070542537336124908 0.21539202667835608"/>
      <body pos="0.091434960266010792 -0.070542537336124908 0.21539202667835608" name="0/1/">
        <joint name="0/1/joint/" class="0/" type="hinge" axis="0 0 1" limited="true" range="-34.826280160724536 34.826280160724536"/>
        <geom name="0/1/geom" class="0/1/" type="capsule" contype="1" conaffinity="1" condim="3" size="0.061235313085392193" rgba="0.81612383256531562 0.70982854760424252 0.88377830186093076 1" friction="0.59999999999999998 0.10000000000000001 0.10000000000000001" fromto="0 0 0 0.30022434626485039 0.53289962308044569 -0.25982365886033471"/>
        <site name="0/1/end1" class="0/1/" size="0.0050000000000000001" pos="0.30022434626485039 0.53289962308044569 -0.25982365886033471"/>
        <site name="0/1/attach2" class="0/1/" size="9.9999999999999995e-07 9.9999999999999995e-07 9.9999999999999995e-07" pos="0.09229781425921578 0.16382905331233491 -0.079877451992136042"/>
        <body pos="0.09229781425921578 0.16382905331233491 -0.079877451992136042" name="0/1/2/">
          <joint name="0/1/2/joint/" class="0/1/" type="hinge" axis="5.5511151231257827e-17 0.4382500720042789 0.89885308832325017" limited="true" range="-42.157900343513276 42.157900343513276"/>
          <geom name="0/1/2/geom" class="0/1/2/" type="capsule" contype="1" conaffinity="1" condim="3" size="0.037390917721228496" rgba="0.070642210479517575 0.43889722840943013 0.98090982872539734 1" friction="0.59999999999999998 0.10000000000000001 0.10000000000000001" fromto="0 0 0 -0.11229370248529924 -0.69473430818454374 -0.41955538054209329"/>
          <site name="0/1/2/end2" class="0/1/2/" size="0.0050000000000000001" pos="-0.11229370248529924 -0.69473430818454374 -0.41955538054209329"/>
          <site name="0/1/2/attach3" class="0/1/2/" size="9.9999999999999995e-07 9.9999999999999995e-07 9.9999999999999995e-07" pos="-0.049776023487617782 -0.30795236488328342 -0.18597479657377602"/>
          <body pos="-0.049776023487617782 -0.30795236488328342 -0.18597479657377602" name="0/1/2/3/">
            <joint name="0/1/2/3/joint/" class="0/1/2/" type="hinge" axis="0.99056323533104651 -0.11732221216592331 -0.070851784331685791" limited="true" range="-45.894612034747837 45.894612034747837"/>
            <geom name="0/1/2/3/geom" class="0/1/2/3/" type="capsule" contype="1" conaffinity="1" condim="3" size="0.051503652304916665" rgba="0.58967547949008792 0.45398544588784351 0.1638482931151729 1" friction="0.59999999999999998 0.10000000000000001 0.10000000000000001" fromto="0 0 0 0.18009315639625489 -0.18636818264998656 0.30278706251527021"/>
            <site name="0/1/2/3/end3" class="0/1/2/3/" size="0.0050000000000000001" pos="0.18009315639625489 -0.18636818264998656 0.30278706251527021"/>
            <site name="0/1/2/3/attach4" class="0/1/2/3/" size="9.9999999999999995e-07 9.9999999999999995e-07 9.9999999999999995e-07" pos="0.13217194081919015 -0.13677723740704167 0.22221807040535024"/>
            <body pos="0.13217194081919015 -0.13677723740704167 0.22221807040535024" name="0/1/2/3/4/">
              <joint name="0/1/2/3/4/joint/" class="0/1/2/3/" type="hinge" axis="5.5511151231257827e-17 0.85161100653036392 0.5241742969245442" limited="true" range="-38.321078203624396 38.321078203624396"/>
              <geom name="0/1/2/3/4/geom" class="0/1/2/3/4/" type="capsule" contype="1" conaffinity="1" condim="3" size="0.049342204254496064" rgba="0.85799986989574484 0.51728218255363789 0.18602038559001721 1" friction="0.59999999999999998 0.10000000000000001 0.10000000000000001" fromto="0 0 0 -0.099282468398348867 -0.27958000025874358 -0.026838947698534343"/>
              <site name="0/1/2/3/4/end4" class="0/1/2/3/4/" size="0.0050000000000000001" pos="-0.099282468398348867 -0.27958000025874358 -0.026838947698534343"/>
              <site name="0/1/2/3/4/attach5" class="0/1/2/3/4/" size="9.9999999999999995e-07 9.9999999999999995e-07 9.9999999999999995e-07" pos="-0.022591626101384828 -0.063618148633537097 -0.00610717562870339"/>
              <body pos="-0.022591626101384828 -0.063618148633537097 -0.00610717562870339" name="0/1/2/3/4/5/">
                <joint name="0/1/2/3/4/5/joint/" class="0/1/2/3/4/" type="hinge" axis="-6.9388939039072284e-18 -0.09555808276917431 0.99542385586115012" limited="true" range="-40.282945842175629 40.282945842175629"/>
                <geom name="0/1/2/3/4/5/geom" class="0/1/2/3/4/5/" type="capsule" contype="1" conaffinity="1" condim="3" size="0.050083819922118675" rgba="0.84762992058907372 0.77281355427281129 0.77209723980684641 1" friction="0.59999999999999998 0.10000000000000001 0.10000000000000001" fromto="0 0 0 0.51449465099980096 -0.49893043884941435 0.5882457931412044"/>
                <site name="0/1/2/3/4/5/end5" class="0/1/2/3/4/5/" size="0.0050000000000000001" pos="0.51449465099980096 -0.49893043884941435 0.5882457931412044"/>
                <site name="0/1/2/3/4/5/attach6" class="0/1/2/3/4/5/" size="9.9999999999999995e-07 9.9999999999999995e-07 9.9999999999999995e-07" pos="0.37646940782850352 -0.3650806602094821 0.43043507832613653"/>
                <body pos="0.37646940782850352 -0.3650806602094821 0.43043507832613653" name="0/1/2/3/4/5/6/">
                  <joint name="0/1/2/3/4/5/6/joint/" class="0/1/2/3/4/5/" type="hinge" axis="0.83191672103000081 0.35892980362825372 -0.42318313451515877" limited="true" range="-68.963628249710879 68.963628249710879"/>
                  <geom name="0/1/2/3/4/5/6/geom" class="0/1/2/3/4/5/6/" type="capsule" contype="1" conaffinity="1" condim="3" size="0.049656722330943155" rgba="0.72662913730128353 0.36427987639406234 0.035200824892154259 1" friction="0.59999999999999998 0.10000000000000001 0.10000000000000001" fromto="0 0 0 -0.50965897863573906 -0.64228041680252712 -0.22226577778107504"/>
                  <site name="0/1/2/3/4/5/6/end6" class="0/1/2/3/4/5/6/" size="0.0050000000000000001" pos="-0.50965897863573906 -0.64228041680252712 -0.22226577778107504"/>
                </body>
              </body>
            </body>
            <site name="0/1/2/3/attach7" class="0/1/2/3/" size="9.9999999999999995e-07 9.9999999999999995e-07 9.9999999999999995e-07" pos="0.062951447094272348 -0.065144878489065611 0.10583902313767513"/>
            <body pos="0.062951447094272348 -0.065144878489065611 0.10583902313767513" name="0/1/2/3/7/">
              <joint name="0/1/2/3/7/joint/" class="0/1/2/3/" type="hinge" axis="5.5511151231257827e-17 0.85161100653036392 0.5241742969245442" limited="true" range="-45.204810792166818 45.204810792166818"/>
              <geom name="0/1/2/3/7/geom" class="0/1/2/3/7/" type="capsule" contype="1" conaffinity="1" condim="3" size="0.056181875637303882" rgba="0.11290714218403042 0.77686787578716765 0.8587214787438876 1" friction="0.59999999999999998 0.10000000000000001 0.10000000000000001" fromto="0 0 0 -0.64464002985094926 0.047613756102913962 0.052340482184556558"/>
              <site name="0/1/2/3/7/end7" class="0/1/2/3/7/" size="0.0050000000000000001" pos="-0.64464002985094926 0.047613756102913962 0.052340482184556558"/>
            </body>
          </body>
        </body>
        <site name="0/1/attach8" class="0/1/" size="9.9999999999999995e-07 9.9999999999999995e-07 9.9999999999999995e-07" pos="0.059678119327191421 0.10592894177727628 -0.051647334769498385"/>
        <body pos="0.059678119327191421 0.10592894177727628 -0.051647334769498385" name="0/1/8/">
          <joint name="0/1/8/joint/" class="0/1/" type="hinge" axis="5.5511151231257827e-17 0.4382500720042789 0.89885308832325017" limited="true" range="-57.227212757802199 57.227212757802199"/>
          <geom name="0/1/8/geom" class="0/1/8/" type="capsule" contype="1" conaffinity="1" condim="3" size="0.05851562639357473" rgba="0.8940433880448212 0.32612390952825354 0.1976644585671723 1" friction="0.59999999999999998 0.10000000000000001 0.10000000000000001" fromto="0 0 0 -0.61805078183932993 0.40390142207046953 -0.61566890922145445"/>
          <site name="0/1/8/end8" class="0/1/8/" size="0.0050000000000000001" pos="-0.61805078183932993 0.40390142207046953 -0.61566890922145445"/>
          <site name="0/1/8/attach9" class="0/1/8/" size="9.9999999999999995e-07 9.9999999999999995e-07 9.9999999999999995e-07" pos="-0.27218952780029054 0.17787816241256152 -0.27114055124012743"/>
          <body pos="-0.27218952780029054 0.17787816241256152 -0.27114055124012743" name="0/1/8/9/">
            <joint name="0/1/8/9/joint/" class="0/1/8/" type="hinge" axis="5.5511151231257827e-17 0.83612969555583483 0.54853179689942022" limited="true" range="-60.034867128162979 60.034867128162979"/>
            <geom name="0/1/8/9/geom" class="0/1/8/9/" type="capsule" contype="1" conaffinity="1" condim="3" size="0.047910711483480084" rgba="0.59823809923935767 0.55261993373989549 0.49730170798444462 1" friction="0.59999999999999998 0.10000000000000001 0.10000000000000001" fromto="0 0 0 -0.020433622956757436 -0.5882192310711849 -0.68674010774088812"/>
            <site name="0/1/8/9/end9" class="0/1/8/9/" size="0.0050000000000000001" pos="-0.020433622956757436 -0.5882192310711849 -0.68674010774088812"/>
            <site name="0/1/8/9/attach10" class="0/1/8/9/" size="9.9999999999999995e-07 9.9999999999999995e-07 9.9999999999999995e-07" pos="-0.0090254483835487884 -0.25981404861383434 -0.3033303202493704"/>
            <body pos="-0.0090254483835487884 -0.25981404861383434 -0.3033303202493704" name="0/1/8/9/10/">
              <joint name="0/1/8/9/10/joint/" class="0/1/8/9/" type="hinge" axis="0.99974476147656921 -0.014696891831038061 -0.017158475184708644" limited="true" range="-53.666193650828205 53.666193650828205"/>
              <geom name="0/1/8/9/10/geom" class="0/1/8/9/10/" type="capsule" contype="1" conaffinity="1" condim="3" size="0.06979927906217645" rgba="0.96505154093326939 0.50712606745243027 0.40623793028214228 1" friction="0.59999999999999998 0.10000000000000001 0.10000000000000001" fromto="0 0 0 0.46070052545366691 -0.025483474149167074 -0.30210048766684811"/>
              <site name="0/1/8/9/10/end10" class="0/1/8/9/10/" size="0.0050000000000000001" pos="0.46070052545366691 -0.025483474149167074 -0.30210048766684811"/>
            </body>
          </body>
        </body>
      </body>
      <camera name="0/iso" class="0/" mode="trackcom" pos="-2.2999999999999998 -2.2999999999999998 1" xyaxes="0.45000000000000001 -0.45000000000000001 0 0.29999999999999999 0.14999999999999999 0.93999999999999995"/>
    </body>
  </worldbody>
  <actuator>
    <motor name="0/1/motor" class="0/1/" ctrllimited="true" ctrlrange="-1 1" gear="91" joint="0/1/joint/"/>
    <motor name="0/1/2/motor" class="0/1/2/" ctrllimited="true" ctrlrange="-1 1" gear="90" joint="0/1/2/joint/"/>
    <motor name="0/1/2/3/motor" class="0/1/2/3/" ctrllimited="true" ctrlrange="-1 1" gear="78" joint="0/1/2/3/joint/"/>
    <motor name="0/1/2/3/4/motor" class="0/1/2/3/4/" ctrllimited="true" ctrlrange="-1 1" gear="57" joint="0/1/2/3/4/joint/"/>
    <motor name="0/1/2/3/4/5/motor" class="0/1/2/3/4/5/" ctrllimited="true" ctrlrange="-1 1" gear="99" joint="0/1/2/3/4/5/joint/"/>
    <motor name="0/1/2/3/4/5/6/motor" class="0/1/2/3/4/5/6/" ctrllimited="true" ctrlrange="-1 1" gear="56" joint="0/1/2/3/4/5/6/joint/"/>
    <motor name="0/1/2/3/7/motor" class="0/1/2/3/7/" ctrllimited="true" ctrlrange="-1 1" gear="59" joint="0/1/2/3/7/joint/"/>
    <motor name="0/1/8/motor" class="0/1/8/" ctrllimited="true" ctrlrange="-1 1" gear="99" joint="0/1/8/joint/"/>
    <motor name="0/1/8/9/motor" class="0/1/8/9/" ctrllimited="true" ctrlrange="-1 1" gear="66" joint="0/1/8/9/joint/"/>
    <motor name="0/1/8/9/10/motor" class="0/1/8/9/10/" ctrllimited="true" ctrlrange="-1 1" gear="56" joint="0/1/8/9/10/joint/"/>
  </actuator>
  <sensor>
    <subtreelinvel name="velocity" body="0/"/>
  </sensor>
</mujoco>
