<mujoco model="morphology">
  <option timestep="0.01"/>
  <default>
    <default class="/"/>
    <default class="0/"/>
    <default class="0/1/"/>
    <default class="0/1/2/"/>
    <default class="0/1/2/3/"/>
    <default class="0/1/2/3/4/"/>
    <default class="0/1/2/3/5/"/>
    <default class="0/1/2/3/5/6/"/>
    <default class="0/1/2/3/5/7/"/>
    <default class="0/1/2/3/5/7/8/"/>
    <default class="0/1/2/3/5/7/9/"/>
    <default class="0/1/2/10/"/>
  </default>
  <asset>
    <texture name="texplane" type="2d" builtin="checker" rgb1="0.10000000000000001 0.20000000000000001 0.29999999999999999" rgb2="0.20000000000000001 0.29999999999999999 0.40000000000000002" width="300" height="300"/>
    <material name="MatPlane" class="/" texture="texplane" texrepeat="20 20" specular="1" shininess="1" reflectance="0.5"/>
  </asset>
  <worldbody>
    <light name="//unnamed_light_0" class="/" directional="true" pos="0 0 1.5" dir="0 0 -1.3" cutoff="100" exponent="1" diffuse="1 1 1" specular="0.10000000000000001 0.10000000000000001 0.10000000000000001"/>
    <geom name="ground" class="/" type="plane" size="15 15 0.5" material="MatPlane" rgba="1 1 1 1"/>
    <site name="body" class="/" size="9.9999999999999995e-07 9.9999999999999995e-07 9.9999999999999995e-07" pos="0 0 2.1081162452697755"/>
    <body pos="0 0 2.1081162452697755" name="0/">
      <freejoint name="0/"/>
      <geom name="0/geom" class="0/" type="capsule" contype="1" conaffinity="1" condim="3" size="0.054532362057693629" rgba="0.089948247155194894 0.77727303640983136 0.0068383372211445748 1" friction="0.59999999999999998 0.10000000000000001 0.10000000000000001" fromto="0 0 0 0.035741624652195436 0.69887716058531857 -0.67697807042462488"/>
      <site name="0/end0" class="0/" size="0.0050000000000000001" pos="0.035741624652195436 0.69887716058531857 -0.67697807042462488"/>
      <site name="0/attach1" class="0/" size="9.9999999999999995e-07 9.9999999999999995e-07 9.9999999999999995e-07" pos="0.014088524846871672 0.27548127253953975 -0.26684915581694796"/>
      <body pos="0.014088524846871672 0.27548127253953975 -0.26684915581694796" name="0/1/">
        <joint name="0/1/joint/" class="0/" type="hinge" axis="0 1 0" limited="true" range="-42.57887896551469 42.57887896551469"/>
        <geom name="0/1/geom" class="0/1/" type="capsule" contype="1" conaffinity="1" condim="3" size="0.067618878504266983" rgba="0.59063408002940121 0.77280426457163209 0.30945196084229798 1" friction="0.59999999999999998 0.10000000000000001 0.10000000000000001" fromto="0 0 0 -0.54711652665183941 0.0063372487387496346 0.55515026486872454"/>
        <site name="0/1/end1" class="0/1/" size="0.0050000000000000001" pos="-0.54711652665183941 0.0063372487387496346 0.55515026486872454"/>
        <site name="0/1/attach2" class="0/1/" size="9.9999999999999995e-07 9.9999999999999995e-07 9.9999999999999995e-07" pos="-0.10915738776038367 0.0012643696255037456 0.11076023072890542"/>
        <body pos="-0.10915738776038367 0.0012643696255037456 0.11076023072890542" name="0/1/2/">
          <joint name="0/1/2/joint/" class="0/1/" type="hinge" axis="-0.71226438950519921 -0.0080120587799130116 -0.70186554720750693" limited="true" range="-67.864362416009016 67.864362416009016"/>
          <geom name="0/1/2/geom" class="0/1/2/" type="capsule" contype="1" conaffinity="1" condim="3" size="0.065081208596451112" rgba="0.96023308425361475 0.13191269381157866 0.91465282219720934 1" friction="0.59999999999999998 0.10000000000000001 0.10000000000000001" fromto="0 0 0 -0.035236812298586884 0.71487980483417357 -0.51736943106631961"/>
          <site name="0/1/2/end2" class="0/1/2/" size="0.0050000000000000001" pos="-0.035236812298586884 0.71487980483417357 -0.51736943106631961"/>
          <site name="0/1/2/attach3" class="0/1/2/" size="9.9999999999999995e-07 9.9999999999999995e-07 9.9999999999999995e-07" pos="-0.011807272572984449 0.23954439014159964 -0.17336193301954572"/>
          <body pos="-0.011807272572984449 0.23954439014159964 -0.17336193301954572" name="0/1/2/3/">
            <joint name="0/1/2/3/joint/" class="0/1/2/" type="hinge" axis="5.5511151231257827e-17 0.58628517332159724 0.81010474356299433" limited="true" range="-34.086432723167455 34.086432723167455"/>
            <geom name="0/1/2/3/geom" class="0/1/2/3/" type="capsule" contype="1" conaffinity="1" condim="3" size="0.041803031694138355" rgba="0.84877459856559911 0.234853850565237 0.22212786652186589 1" friction="0.59999999999999998 0.10000000000000001 0.10000000000000001" fromto="0 0 0 -0.32514311278757096 -0.19795076544583812 -0.4972712689124536"/>
            <site name="0/1/2/3/end3" class="0/1/2/3/" size="0.0050000000000000001" pos="-0.32514311278757096 -0.19795076544583812 -0.4972712689124536"/>
            <site name="0/1/2/3/attach4" class="0/1/2/3/" size="9.9999999999999995e-07 9.9999999999999995e-07 9.9999999999999995e-07" pos="-0.3163972215372125 -0.19262616898530779 -0.48389537297989083"/>
            <body pos="-0.3163972215372125 -0.19262616898530779 -0.48389537297989083" name="0/1/2/3/4/">
              <joint name="0/1/2/3/4/joint/" class="0/1/2/3/" type="hinge" axis="0.85465534669117993 -0.192023282138817 -0.48238086351846016" limited="true" range="-36.607254218387091 36.607254218387091"/>
              <geom name="0/1/2/3/4/geom" class="0/1/2/3/4/" type="capsule" contype="1" conaffinity="1" condim="3" size="0.053349129995713923" rgba="0.61501618158904958 0.58181840548505293 0.008400158338349617 1" friction="0.59999999999999998 0.10000000000000001 0.10000000000000001" fromto="0 0 0 0.2224578111029859 -0.273461385937534 -0.59650703079915313"/>
              <site name="0/1/2/3/4/end4" class="0/1/2/3/4/" size="0.0050000000000000001" pos="0.2224578111029859 -0.273461385937534 -0.59650703079915313"/>
            </body>
            <site name="0/1/2/3/attach5" class="0/1/2/3/" size="9.9999999999999995e-07 9.9999999999999995e-07 9.9999999999999995e-07" pos="-0.25053512098709796 -0.15252858516755113 -0.38316640464036206"/>
            <body pos="-0.25053512098709796 -0.15252858516755113 -0.38316640464036206" name="0/1/2/3/5/">
              <geom name="0/1/2/3/5/geom" class="0/1/2/3/5/" type="capsule" contype="1" conaffinity="1" condim="3" size="0.060158164474012392" rgba="0.52488799469346681 0.04776237151446372 0.68267495101970066 1" friction="0.59999999999999998 0.10000000000000001 0.10000000000000001" fromto="0 0 0 -0.30374040814380937 0.3872561802326917 -0.42100585988517703"/>
              <site name="0/1/2/3/5/end5" class="0/1/2/3/5/" size="0.0050000000000000001" pos="-0.30374040814380937 0.3872561802326917 -0.42100585988517703"/>
              <site name="0/1/2/3/5/attach6" class="0/1/2/3/5/" size="9.9999999999999995e-07 9.9999999999999995e-07 9.9999999999999995e-07" pos="-0.30000579922126602 0.38249471173119975 -0.41582942567157122"/>
              <body pos="-0.30000579922126602 0.38249471173119975 -0.41582942567157122" name="0/1/2/3/5/6/">
                <joint name="0/1/2/3/5/6/joint/" class="0/1/2/3/5/" type="hinge" axis="0 0.73599129544965847 0.6769909992181089" limited="true" range="-66.665705767505258 66.665705767505258"/>
                <geom name="0/1/2/3/5/6/geom" class="0/1/2/3/5/6/" type="capsule" contype="1" conaffinity="1" condim="3" size="0.039030631610751911" rgba="0.22489032758036998 0.33287019673889651 0.55674869963875973 1" friction="0.59999999999999998 0.10000000000000001 0.10000000000000001" fromto="0 0 0 0.22931095507783328 0.31294086711311175 -0.65539455923710255"/>
                <site name="0/1/2/3/5/6/end6" class="0/1/2/3/5/6/" size="0.0050000000000000001" pos="0.22931095507783328 0.31294086711311175 -0.65539455923710255"/>
              </body>
              <site name="0/1/2/3/5/attach7" class="0/1/2/3/5/" size="9.9999999999999995e-07 9.9999999999999995e-07 9.9999999999999995e-07" pos="-0.2977978393416309 0.37967965622271532 -0.41276903586898145"/>
              <body pos="-0.2977978393416309 0.37967965622271532 -0.41276903586898145" name="0/1/2/3/5/7/">
                <joint name="0/1/2/3/5/7/joint/" class="0/1/2/3/5/" type="hinge" axis="0 0.73599129544965847 0.6769909992181089" limited="true" range="-50.553223003984208 50.553223003984208"/>
                <geom name="0/1/2/3/5/7/geom" class="0/1/2/3/5/7/" type="capsule" contype="1" conaffinity="1" condim="3" size="0.065873552981092057" rgba="0.40361795941704004 0.55719313807052961 0.013725371647867579 1" friction="0.59999999999999998 0.10000000000000001 0.10000000000000001" fromto="0 0 0 0.016443688891996322 -0.53188163538673794 -0.45816553348703232"/>
                <site name="0/1/2/3/5/7/end7" class="0/1/2/3/5/7/" size="0.0050000000000000001" pos="0.016443688891996322 -0.53188163538673794 -0.45816553348703232"/>
                <site name="0/1/2/3/5/7/attach8" class="0/1/2/3/5/7/" size="9.9999999999999995e-07 9.9999999999999995e-07 9.9999999999999995e-07" pos="0.0027780904668593836 -0.089859113150983938 -0.077405094999297486"/>
                <body pos="0.0027780904668593836 -0.089859113150983938 -0.077405094999297486" name="0/1/2/3/5/7/8/">
                  <joint name="0/1/2/3/5/7/8/joint/" class="0/1/2/3/5/7/" type="hinge" axis="0.99972577500445914 0.017742398814776572 0.01528339216374941" limited="true" range="-62.74217450091853 62.74217450091853"/>
                  <geom name="0/1/2/3/5/7/8/geom" class="0/1/2/3/5/7/8/" type="capsule" contype="1" conaffinity="1" condim="3" size="0.059939598258509606" rgba="0.33325065026259126 0.2848010197636327 0.91939354624978853 1" friction="0.59999999999999998 0.10000000000000001 0.10000000000000001" fromto="0 0 0 -0.43715471372116588 -0.25208194260229377 0.00029503999784896706"/>
                  <site name="0/1/2/3/5/7/8/end8" class="0/1/2/3/5/7/8/" size="0.0050000000000000001" pos="-0.43715471372116588 -0.25208194260229377 0.00029503999784896706"/>
                </body>
                <site name="0/1/2/3/5/7/attach9" class="0/1/2/3/5/7/" size="9.9999999999999995e-07 9.9999999999999995e-07 9.9999999999999995e-07" pos="0.01453894243867512 -0.47027139298652576 -0.4050941587684187"/>
                <body pos="0.01453894243867512 -0.47027139298652576 -0.4050941587684187" name="0/1/2/3/5/7/9/">
                  <geom name="0/1/2/3/5/7/9/geom" class="0/1/2/3/5/7/9/" type="capsule" contype="1" conaffinity="1" condim="3" size="0.0648317337032039" rgba="0.7632532153368039 0.080983088873000653 0.91820366321402913 1" friction="0.59999999999999998 0.10000000000000001 0.10000000000000001" fromto="0 0 0 0.51233124594398216 0.19169356973521112 -0.47763578128048123"/>
                  <site name="0/1/2/3/5/7/9/end9" class="0/1/2/3/5/7/9/" size="0.0050000000000000001" pos="0.51233124594398216 0.19169356973521112 -0.47763578128048123"/>
                </body>
              </body>
            </body>
          </body>
          <site name="0/1/2/attach10" class="0/1/2/" size="9.9999999999999995e-07 9.9999999999999995e-07 9.9999999999999995e-07" pos="-0.023805095665755061 0.48295464412018563 -0.34952165073016328"/>
          <body pos="-0.023805095665755061 0.48295464412018563 -0.34952165073016328" name="0/1/2/10/">
            <geom name="0/1/2/10/geom" class="0/1/2/10/" type="capsule" contype="1" conaffinity="1" condim="3" size="0.056230674863623827" rgba="0.094057398236817358 0.3954779195264615 0.92548955394240895 1" friction="0.59999999999999998 0.10000000000000001 0.10000000000000001" fromto="0 0 0 -0.33491841655268129 -0.095532262644680177 0.70283217513912577"/>
            <site name="0/1/2/10/end10" class="0/1/2/10/" size="0.0050000000000000001" pos="-0.33491841655268129 -0.095532262644680177 0.70283217513912577"/>
          </body>
        </body>
      </body>
      <camera name="0/iso" class="0/" mode="trackcom" pos="-2.2999999999999998 -2.2999999999999998 1" xyaxes="0.45000000000000001 -0.45000000000000001 0 0.29999999999999999 0.14999999999999999 0.93999999999999995"/>
    </body>
  </worldbody>
  <actuator>
    <motor name="0/1/motor" class="0/1/" ctrllimited="true" ctrlrange="-1 1" gear="64" joint="0/1/joint/"/>
    <motor name="0/1/2/motor" class="0/1/2/" ctrllimited="true" ctrlrange="-1 1" gear="95" joint="0/1/2/joint/"/>
    <motor name="0/1/2/3/motor" class="0/1/2/3/" ctrllimited="true" ctrlrange="-1 1" gear="91" joint="0/1/2/3/joint/"/>
    <motor name="0/1/2/3/4/motor" class="0/1/2/3/4/" ctrllimited="true" ctrlrange="-1 1" gear="50" joint="0/1/2/3/4/joint/"/>
    <motor name="0/1/2/3/5/6/motor" class="0/1/2/3/5/6/" ctrllimited="true" ctrlrange="-1 1" gear="76" joint="0/1/2/3/5/6/joint/"/>
    <motor name="0/1/2/3/5/7/motor" class="0/1/2/3/5/7/" ctrllimited="true" ctrlrange="-1 1" gear="78" joint="0/1/2/3/5/7/joint/"/>
    <motor name="0/1/2/3/5/7/8/motor" class="0/1/2/3/5/7/8/" ctrllimited="true" ctrlrange="-1 1" gear="53" joint="0/1/2/3/5/7/8/joint/"/>
  </actuator>
  <sensor>
    <subtreelinvel name="velocity" body="0/"/>
  </sensor>
</mujoco>
