<mujoco model="morphology">
  <option timestep="0.01"/>
  <default>
    <default class="/"/>
    <default class="0/"/>
    <default class="0/1/"/>
    <default class="0/1/2/"/>
    <default class="0/1/2/3/"/>
    <default class="0/1/2/4/"/>
    <default class="0/1/2/4/5/"/>
    <default class="0/1/2/4/5/6/"/>
    <default class="0/1/2/4/5/6/7/"/>
    <default class="0/1/2/4/8/"/>
    <default class="0/1/2/4/8/9/"/>
    <default class="0/1/10/"/>
  </default>
  <asset>
    <texture name="texplane" type="2d" builtin="checker" rgb1="0.10000000000000001 0.20000000000000001 0.29999999999999999" rgb2="0.20000000000000001 0.29999999999999999 0.40000000000000002" width="300" height="300"/>
    <material name="MatPlane" class="/" texture="texplane" texrepeat="20 20" specular="1" shininess="1" reflectance="0.5"/>
  </asset>
  <worldbody>
    <light name="//unnamed_light_0" class="/" directional="true" pos="0 0 1.5" dir="0 0 -1.3" cutoff="100" exponent="1" diffuse="1 1 1" specular="0.10000000000000001 0.10000000000000001 0.10000000000000001"/>
    <geom name="ground" class="/" type="plane" size="15 15 0.5" material="MatPlane" rgba="1 1 1 1"/>
    <site name="body" class="/" size="9.9999999999999995e-07 9.9999999999999995e-07 9.9999999999999995e-07" pos="0 0 0.29407626986503599"/>
    <body pos="0 0 0.29407626986503599" name="0/">
      <freejoint name="0/"/>
      <geom name="0/geom" class="0/" type="capsule" contype="1" conaffinity="1" condim="3" size="0.04330735740609435" rgba="0.14368966379440085 0.56905186983533862 0.48336704451146661 1" friction="0.59999999999999998 0.10000000000000001 0.10000000000000001" fromto="0 0 0 0.28471454924597506 0.33575576481181901 0.51777164248694429"/>
      <site name="0/end0" class="0/" size="0.0050000000000000001" pos="0.28471454924597506 0.33575576481181901 0.51777164248694429"/>
      <site name="0/attach1" class="0/" size="9.9999999999999995e-07 9.9999999999999995e-07 9.9999999999999995e-07" pos="0.23259878987145968 0.27429713302120462 0.42299579628498329"/>
      <body pos="0.23259878987145968 0.27429713302120462 0.42299579628498329" name="0/1/">
        <joint name="0/1/joint/" class="0/" type="hinge" axis="0 1 0" limited="true" range="-61.699018965884008 61.699018965884008"/>
        <geom name="0/1/geom" class="0/1/" type="capsule" contype="1" conaffinity="1" condim="3" size="0.035017829551271737" rgba="0.95980345451628502 0.023885986697887995 0.66619609179637151 1" friction="0.59999999999999998 0.10000000000000001 0.10000000000000001" fromto="0 0 0 -0.58209711838518308 -0.49578838773365119 0.14974709043697199"/>
        <site name="0/1/end1" class="0/1/" size="0.0050000000000000001" pos="-0.58209711838518308 -0.49578838773365119 0.14974709043697199"/>
        <site name="0/1/attach2" class="0/1/" size="9.9999999999999995e-07 9.9999999999999995e-07 9.9999999999999995e-07" pos="-0.36706731195489845 -0.3126414906308127 0.094429709791818042"/>
        <body pos="-0.36706731195489845 -0.3126414906308127 0.094429709791818042" name="0/1/2/">
          <geom name="0/1/2/geom" class="0/1/2/" type="capsule" contype="1" conaffinity="1" condim="3" size="0.047743998019009373" rgba="0.62537310220660802 0.16203889750968425 0.70371003741018023 1" friction="0.59999999999999998 0.10000000000000001 0.10000000000000001" fromto="0 0 0 -0.078093677415694396 0.55107849960308863 0.1417202689307997"/>
          <site name="0/1/2/end2" class="0/1/2/" size="0.0050000000000000001" pos="-0.078093677415694396 0.55107849960308863 0.1417202689307997"/>
          <site name="0/1/2/attach3" class="0/1/2/" size="9.9999999999999995e-07 9.9999999999999995e-07 9.9999999999999995e-07" pos="-0.01197063987534861 0.08447242440231495 0.021723683127095501"/>
          <body pos="-0.01197063987534861 0.08447242440231495 0.021723683127095501" name="0/1/2/3/">
            <joint name="0/1/2/3/joint/" class="0/1/2/" type="hinge" axis="-0.99071291800998285 -0.13168541649007254 -0.033865397856528631" limited="true" range="-66.338031604747059 66.338031604747059"/>
            <geom name="0/1/2/3/geom" class="0/1/2/3/" type="capsule" contype="1" conaffinity="1" condim="3" size="0.064003585776130703" rgba="0.087961505414838159 0.59372724994963078 0.3680249043622873 1" friction="0.59999999999999998 0.10000000000000001 0.10000000000000001" fromto="0 0 0 -0.50999711082466082 0.33709952246050645 -0.40510110497105234"/>
            <site name="0/1/2/3/end3" class="0/1/2/3/" size="0.0050000000000000001" pos="-0.50999711082466082 0.33709952246050645 -0.40510110497105234"/>
          </body>
          <site name="0/1/2/attach4" class="0/1/2/" size="9.9999999999999995e-07 9.9999999999999995e-07 9.9999999999999995e-07" pos="-0.024375971134155718 0.17201230680269006 0.044236221150058146"/>
          <body pos="-0.024375971134155718 0.17201230680269006 0.044236221150058146" name="0/1/2/4/">
            <geom name="0/1/2/4/geom" class="0/1/2/4/" type="capsule" contype="1" conaffinity="1" condim="3" size="0.058949257716469972" rgba="0.3567894722429622 0.0086009751462421402 0.90492209956672809 1" friction="0.59999999999999998 0.10000000000000001 0.10000000000000001" fromto="0 0 0 0.69368552376792669 0.49360948903933277 -0.62390825777762793"/>
            <site name="0/1/2/4/end4" class="0/1/2/4/" size="0.0050000000000000001" pos="0.69368552376792669 0.49360948903933277 -0.62390825777762793"/>
            <site name="0/1/2/4/attach5" class="0/1/2/4/" size="9.9999999999999995e-07 9.9999999999999995e-07 9.9999999999999995e-07" pos="0.199279190130425 0.14180215075291036 -0.17923385751265225"/>
            <body pos="0.199279190130425 0.14180215075291036 -0.17923385751265225" name="0/1/2/4/5/">
              <joint name="0/1/2/4/5/joint/" class="0/1/2/4/" type="hinge" axis="-0.75371523241541949 0.40776524073733328 -0.51540358639748995" limited="true" range="-58.579041200384864 58.579041200384864"/>
              <geom name="0/1/2/4/5/geom" class="0/1/2/4/5/" type="capsule" contype="1" conaffinity="1" condim="3" size="0.053944216208497833" rgba="0.18156666338860072 0.59579580843806801 0.68929761613209373 1" friction="0.59999999999999998 0.10000000000000001 0.10000000000000001" fromto="0 0 0 0.12663732436556874 0.13644246702160823 0.20179109357653391"/>
              <site name="0/1/2/4/5/end5" class="0/1/2/4/5/" size="0.0050000000000000001" pos="0.12663732436556874 0.13644246702160823 0.20179109357653391"/>
              <site name="0/1/2/4/5/attach6" class="0/1/2/4/5/" size="9.9999999999999995e-07 9.9999999999999995e-07 9.9999999999999995e-07" pos="0.010236454821487226 0.011029032367796116 0.016311347567734232"/>
              <body pos="0.010236454821487226 0.011029032367796116 0.016311347567734232" name="0/1/2/4/5/6/">
                <geom name="0/1/2/4/5/6/geom" class="0/1/2/4/5/6/" type="capsule" contype="1" conaffinity="1" condim="3" size="0.039701140620069929" rgba="0.046376407422042298 0.43463850401694526 0.77944195548617223 1" friction="0.59999999999999998 0.10000000000000001 0.10000000000000001" fromto="0 0 0 0.41927809424159657 -0.20772318432261616 0.45171412210257689"/>
                <site name="0/1/2/4/5/6/end6" class="0/1/2/4/5/6/" size="0.0050000000000000001" pos="0.41927809424159657 -0.20772318432261616 0.45171412210257689"/>
                <site name="0/1/2/4/5/6/attach7" class="0/1/2/4/5/6/" size="9.9999999999999995e-07 9.9999999999999995e-07 9.9999999999999995e-07" pos="0.31768484457340157 -0.15739078294845829 0.34226145520752743"/>
                <body pos="0.31768484457340157 -0.15739078294845829 0.34226145520752743" name="0/1/2/4/5/6/7/">
                  <joint name="0/1/2/4/5/6/7/joint/" class="0/1/2/4/5/6/" type="hinge" axis="0.76446056188626299 0.26934151832594488 -0.58570913927171531" limited="true" range="-61.565326955837257 61.565326955837257"/>
                  <geom name="0/1/2/4/5/6/7/geom" class="0/1/2/4/5/6/7/" type="capsule" contype="1" conaffinity="1" condim="3" size="0.042182447454694058" rgba="0.37853721781557581 0.085401278483897669 0.70364669297041837 1" friction="0.59999999999999998 0.10000000000000001 0.10000000000000001" fromto="0 0 0 -0.71377064788253963 0.64360512663429459 0.54732615597692957"/>
                  <site name="0/1/2/4/5/6/7/end7" class="0/1/2/4/5/6/7/" size="0.0050000000000000001" pos="-0.71377064788253963 0.64360512663429459 0.54732615597692957"/>
                </body>
              </body>
            </body>
            <site name="0/1/2/4/attach8" class="0/1/2/4/" size="9.9999999999999995e-07 9.9999999999999995e-07 9.9999999999999995e-07" pos="0.3015394868745051 0.21456805272918245 -0.27120787368480892"/>
            <body pos="0.3015394868745051 0.21456805272918245 -0.27120787368480892" name="0/1/2/4/8/">
              <geom name="0/1/2/4/8/geom" class="0/1/2/4/8/" type="capsule" contype="1" conaffinity="1" condim="3" size="0.050080329270463637" rgba="0.37357005405665666 0.53983711076515084 0.90568402892177646 1" friction="0.59999999999999998 0.10000000000000001 0.10000000000000001" fromto="0 0 0 -0.35083741088180476 -0.25331945865857969 -0.4845301278637732"/>
              <site name="0/1/2/4/8/end8" class="0/1/2/4/8/" size="0.0050000000000000001" pos="-0.35083741088180476 -0.25331945865857969 -0.4845301278637732"/>
              <site name="0/1/2/4/8/attach9" class="0/1/2/4/8/" size="9.9999999999999995e-07 9.9999999999999995e-07 9.9999999999999995e-07" pos="-0.28597394591320863 -0.206485291825385 -0.39494930780262733"/>
              <body pos="-0.28597394591320863 -0.206485291825385 -0.39494930780262733" name="0/1/2/4/8/9/">
                <joint name="0/1/2/4/8/9/joint/" class="0/1/2/4/8/" type="hinge" axis="5.5511151231257827e-17 -0.88619364476914586 0.46331503749692432" limited="true" range="-48.470449313716117 48.470449313716117"/>
                <geom name="0/1/2/4/8/9/geom" class="0/1/2/4/8/9/" type="capsule" contype="1" conaffinity="1" condim="3" size="0.060897881560869283" rgba="0.27092812688987833 0.038788951700879593 0.41089376131793143 1" friction="0.59999999999999998 0.10000000000000001 0.10000000000000001" fromto="0 0 0 0.05792944342760209 0.44291771810916036 0.1716686328072472"/>
                <site name="0/1/2/4/8/9/end9" class="0/1/2/4/8/9/" size="0.0050000000000000001" pos="0.05792944342760209 0.44291771810916036 0.1716686328072472"/>
              </body>
            </body>
          </body>
        </body>
        <site name="0/1/attach10" class="0/1/" size="9.9999999999999995e-07 9.9999999999999995e-07 9.9999999999999995e-07" pos="-0.48298337282371756 -0.41137044000272638 0.12424963554265206"/>
        <body pos="-0.48298337282371756 -0.41137044000272638 0.12424963554265206" name="0/1/10/">
          <joint name="0/1/10/joint/" class="0/1/" type="hinge" axis="0.66471500943822603 -0.71518668973045796 0.21601378442110777" limited="true" range="-39.004640257324333 39.004640257324333"/>
          <geom name="0/1/10/geom" class="0/1/10/" type="capsule" contype="1" conaffinity="1" condim="3" size="0.054588458310363561" rgba="0.77906307495802152 0.80354544815097551 0.77828350252665313 1" friction="0.59999999999999998 0.10000000000000001 0.10000000000000001" fromto="0 0 0 -0.10738662927476417 0.2795436116762231 -0.67107014437741552"/>
          <site name="0/1/10/end10" class="0/1/10/" size="0.0050000000000000001" pos="-0.10738662927476417 0.2795436116762231 -0.67107014437741552"/>
        </body>
      </body>
      <camera name="0/iso" class="0/" mode="trackcom" pos="-2.2999999999999998 -2.2999999999999998 1" xyaxes="0.45000000000000001 -0.45000000000000001 0 0.29999999999999999 0.14999999999999999 0.93999999999999995"/>
    </body>
  </worldbody>
  <actuator>
    <motor name="0/1/motor" class="0/1/" ctrllimited="true" ctrlrange="-1 1" gear="82" joint="0/1/joint/"/>
    <motor name="0/1/2/3/motor" class="0/1/2/3/" ctrllimited="true" ctrlrange="-1 1" gear="60" joint="0/1/2/3/joint/"/>
    <motor name="0/1/2/4/5/motor" class="0/1/2/4/5/" ctrllimited="true" ctrlrange="-1 1" gear="65" joint="0/1/2/4/5/joint/"/>
    <motor name="0/1/2/4/5/6/7/motor" class="0/1/2/4/5/6/7/" ctrllimited="true" ctrlrange="-1 1" gear="95" joint="0/1/2/4/5/6/7/joint/"/>
    <motor name="0/1/2/4/8/9/motor" class="0/1/2/4/8/9/" ctrllimited="true" ctrlrange="-1 1" gear="99" joint="0/1/2/4/8/9/joint/"/>
    <motor name="0/1/10/motor" class="0/1/10/" ctrllimited="true" ctrlrange="-1 1" gear="54" joint="0/1/10/joint/"/>
  </actuator>
  <sensor>
    <subtreelinvel name="velocity" body="0/"/>
  </sensor>
</mujoco>
