<mujoco model="morphology">
  <option timestep="0.01"/>
  <default>
    <default class="/"/>
    <default class="0/"/>
    <default class="0/1/"/>
    <default class="0/1/2/"/>
    <default class="0/3/"/>
    <default class="0/3/4/"/>
    <default class="0/3/4/5/"/>
    <default class="0/3/4/5/6/"/>
    <default class="0/3/4/5/6/7/"/>
    <default class="0/3/4/5/6/7/8/"/>
    <default class="0/3/9/"/>
    <default class="0/3/9/10/"/>
  </default>
  <asset>
    <texture name="texplane" type="2d" builtin="checker" rgb1="0.10000000000000001 0.20000000000000001 0.29999999999999999" rgb2="0.20000000000000001 0.29999999999999999 0.40000000000000002" width="300" height="300"/>
    <material name="MatPlane" class="/" texture="texplane" texrepeat="20 20" specular="1" shininess="1" reflectance="0.5"/>
  </asset>
  <worldbody>
    <light name="//unnamed_light_0" class="/" directional="true" pos="0 0 1.5" dir="0 0 -1.3" cutoff="100" exponent="1" diffuse="1 1 1" specular="0.10000000000000001 0.10000000000000001 0.10000000000000001"/>
    <geom name="ground" class="/" type="plane" size="15 15 0.5" material="MatPlane" rgba="1 1 1 1"/>
    <site name="body" class="/" size="9.9999999999999995e-07 9.9999999999999995e-07 9.9999999999999995e-07" pos="0 0 1.0318636059761048"/>
    <body pos="0 0 1.0318636059761048" name="0/">
      <freejoint name="0/"/>
      <geom name="0/geom" class="0/" type="capsule" contype="1" conaffinity="1" condim="3" size="0.068336899560254766" rgba="0.5885581954393293 0.73568601687289281 0.71047255209427806 1" friction="0.59999999999999998 0.10000000000000001 0.10000000000000001" fromto="0 0 0 -0.39978704759067352 0.74430076005457302 -0.2379741963725347"/>
      <site name="0/end0" class="0/" size="0.0050000000000000001" pos="-0.39978704759067352 0.74430076005457302 -0.2379741963725347"/>
      <site name="0/attach1" class="0/" size="9.9999999999999995e-07 9.9999999999999995e-07 9.9999999999999995e-07" pos="-0.36102633650598853 0.67213827531563575 -0.21490179038340906"/>
      <body pos="-0.36102633650598853 0.67213827531563575 -0.21490179038340906" name="0/1/">
        <joint name="0/1/joint/" class="0/" type="hinge" axis="0 1 0" limited="true" range="-56.78363403545027 56.78363403545027"/>
        <geom name="0/1/geom" class="0/1/" type="capsule" contype="1" conaffinity="1" condim="3" size="0.058904904236065717" rgba="0.10885509416582606 0.46019007337524132 0.53504305222264747 1" friction="0.59999999999999998 0.10000000000000001 0.10000000000000001" fromto="0 0 0 -0.74711531201588155 0.28976524823975258 0.14599575128863229"/>
        <site name="0/1/end1" class="0/1/" size="0.0050000000000000001" pos="-0.74711531201588155 0.28976524823975258 0.14599575128863229"/>
        <site name="0/1/attach2" class="0/1/" size="9.9999999999999995e-07 9.9999999999999995e-07 9.9999999999999995e-07" pos="-0.73947488704344722 0.28680194444556184 0.14450271592170186"/>
        <body pos="-0.73947488704344722 0.28680194444556184 0.14450271592170186" name="0/1/2/">
          <joint name="0/1/2/joint/" class="0/1/" type="hinge" axis="-0.39834816048573363 -0.81913674871922371 -0.41271507112695993" limited="true" range="-37.663630237336633 37.663630237336633"/>
          <geom name="0/1/2/geom" class="0/1/2/" type="capsule" contype="1" conaffinity="1" condim="3" size="0.054754319209131826" rgba="0.41804673174326323 0.82976006626687493 0.39982723925951946 1" friction="0.59999999999999998 0.10000000000000001 0.10000000000000001" fromto="0 0 0 0.34700254124267627 0.11708370875171159 -0.49259959716099239"/>
          <site name="0/1/2/end2" class="0/1/2/" size="0.0050000000000000001" pos="0.34700254124267627 0.11708370875171159 -0.49259959716099239"/>
        </body>
      </body>
      <site name="0/attach3" class="0/" size="9.9999999999999995e-07 9.9999999999999995e-07 9.9999999999999995e-07" pos="-0.30618910669163113 0.57004544345405228 -0.18225979816526963"/>
      <body pos="-0.30618910669163113 0.57004544345405228 -0.18225979816526963" name="0/3/">
        <joint name="0/3/joint/" class="0/" type="hinge" axis="0 0 1" limited="true" range="-68.075280982470517 68.075280982470517"/>
        <geom name="0/3/geom" class="0/3/" type="capsule" contype="1" conaffinity="1" condim="3" size="0.058193082565606909" rgba="0.82978058383089504 0.57952216850923233 0.92671453964288952 1" friction="0.59999999999999998 0.10000000000000001 0.10000000000000001" fromto="0 0 0 0.3683287617090214 0.4558009982762885 -0.74960378385174709"/>
        <site name="0/3/end3" class="0/3/" size="0.0050000000000000001" pos="0.3683287617090214 0.4558009982762885 -0.74960378385174709"/>
        <site name="0/3/attach4" class="0/3/" size="9.9999999999999995e-07 9.9999999999999995e-07 9.9999999999999995e-07" pos="0.17293802433343636 0.21400806107393028 -0.35195458755567033"/>
        <body pos="0.17293802433343636 0.21400806107393028 -0.35195458755567033" name="0/3/4/">
          <joint name="0/3/4/joint/" class="0/3/" type="hinge" axis="-0.92203404995888061 0.20112160773458654 -0.33076171123435577" limited="true" range="-63.777729819706614 63.777729819706614"/>
          <geom name="0/3/4/geom" class="0/3/4/" type="capsule" contype="1" conaffinity="1" condim="3" size="0.053014841186629302" rgba="0.35533491055135813 0.90817863094615148 0.52097804784249035 1" friction="0.59999999999999998 0.10000000000000001 0.10000000000000001" fromto="0 0 0 0.71631052165866937 -0.49904484462467735 -0.01627854569669962"/>
          <site name="0/3/4/end4" class="0/3/4/" size="0.0050000000000000001" pos="0.71631052165866937 -0.49904484462467735 -0.01627854569669962"/>
          <site name="0/3/4/attach5" class="0/3/4/" size="9.9999999999999995e-07 9.9999999999999995e-07 9.9999999999999995e-07" pos="0.43701110002788951 -0.30446032819353042 -0.0099313146277625521"/>
          <body pos="0.43701110002788951 -0.30446032819353042 -0.0099313146277625521" name="0/3/4/5/">
            <joint name="0/3/4/5/joint/" class="0/3/4/" type="hinge" axis="-1.7347234759768071e-18 -0.03260206448912719 0.99946841140230458" limited="true" range="-63.145883576087883 63.145883576087883"/>
            <geom name="0/3/4/5/geom" class="0/3/4/5/" type="capsule" contype="1" conaffinity="1" condim="3" size="0.050649829230339616" rgba="0.84838924889253242 0.089044087319362863 0.60455299455590394 1" friction="0.59999999999999998 0.10000000000000001 0.10000000000000001" fromto="0 0 0 0.71677062808117609 0.21929541036277844 0.19969836592275736"/>
            <site name="0/3/4/5/end5" class="0/3/4/5/" size="0.0050000000000000001" pos="0.71677062808117609 0.21929541036277844 0.19969836592275736"/>
            <site name="0/3/4/5/attach6" class="0/3/4/5/" size="9.9999999999999995e-07 9.9999999999999995e-07 9.9999999999999995e-07" pos="0.49947847726353062 0.15281504758657147 0.13915893287945638"/>
            <body pos="0.49947847726353062 0.15281504758657147 0.13915893287945638" name="0/3/4/5/6/">
              <joint name="0/3/4/5/6/joint/" class="0/3/4/5/" type="hinge" axis="-0.38235452587126767 0.68319048460358933 0.62213807012018729" limited="true" range="-62.748249073533536 62.748249073533536"/>
              <geom name="0/3/4/5/6/geom" class="0/3/4/5/6/" type="capsule" contype="1" conaffinity="1" condim="3" size="0.059035028221691058" rgba="0.37884145428568872 0.93355259890004971 0.41522094097972762 1" friction="0.59999999999999998 0.10000000000000001 0.10000000000000001" fromto="0 0 0 0.16315322461588899 -0.44415052865943661 0.51808322671598717"/>
              <site name="0/3/4/5/6/end6" class="0/3/4/5/6/" size="0.0050000000000000001" pos="0.16315322461588899 -0.44415052865943661 0.51808322671598717"/>
              <site name="0/3/4/5/6/attach7" class="0/3/4/5/6/" size="9.9999999999999995e-07 9.9999999999999995e-07 9.9999999999999995e-07" pos="0.14329275273013006 -0.39008454799461656 0.45501749581854173"/>
              <body pos="0.14329275273013006 -0.39008454799461656 0.45501749581854173" name="0/3/4/5/6/7/">
                <geom name="0/3/4/5/6/7/geom" class="0/3/4/5/6/7/" type="capsule" contype="1" conaffinity="1" condim="3" size="0.036323009586903252" rgba="0.83189649650630426 0.50994267066162735 0.095770425378551738 1" friction="0.59999999999999998 0.10000000000000001 0.10000000000000001" fromto="0 0 0 -0.36215621109000007 -0.57221481833947885 0.013053215990335265"/>
                <site name="0/3/4/5/6/7/end7" class="0/3/4/5/6/7/" size="0.0050000000000000001" pos="-0.36215621109000007 -0.57221481833947885 0.013053215990335265"/>
                <site name="0/3/4/5/6/7/attach8" class="0/3/4/5/6/7/" size="9.9999999999999995e-07 9.9999999999999995e-07 9.9999999999999995e-07" pos="-0.22989135898905708 -0.3632334285412771 0.0082859867408158986"/>
                <body pos="-0.22989135898905708 -0.3632334285412771 0.0082859867408158986" name="0/3/4/5/6/7/8/">
                  <joint name="0/3/4/5/6/7/8/joint/" class="0/3/4/5/6/7/" type="hinge" axis="-1.7347234759768071e-18 0.022805807557005661 0.99973991374840732" limited="true" range="-54.849389669282175 54.849389669282175"/>
                  <geom name="0/3/4/5/6/7/8/geom" class="0/3/4/5/6/7/8/" type="capsule" contype="1" conaffinity="1" condim="3" size="0.040808664640218498" rgba="0.80812288231895768 0.20205492806679271 0.2015992384154075 1" friction="0.59999999999999998 0.10000000000000001 0.10000000000000001" fromto="0 0 0 0.53171057541685052 -0.18818037384897313 0.56585369583035283"/>
                  <site name="0/3/4/5/6/7/8/end8" class="0/3/4/5/6/7/8/" size="0.0050000000000000001" pos="0.53171057541685052 -0.18818037384897313 0.56585369583035283"/>
                </body>
              </body>
            </body>
          </body>
        </body>
        <site name="0/3/attach9" class="0/3/" size="9.9999999999999995e-07 9.9999999999999995e-07 9.9999999999999995e-07" pos="0.14532268911313528 0.17983452191629221 -0.29575327523506073"/>
        <body pos="0.14532268911313528 0.17983452191629221 -0.29575327523506073" name="0/3/9/">
          <joint name="0/3/9/joint/" class="0/3/" type="hinge" axis="5.5511151231257827e-17 0.85444124450816661 0.51954803404818617" limited="true" range="-32.113225342677495 32.113225342677495"/>
          <geom name="0/3/9/geom" class="0/3/9/" type="capsule" contype="1" conaffinity="1" condim="3" size="0.067726335822225522" rgba="0.38472127719556382 0.44384745439779205 0.66376487072310442 1" friction="0.59999999999999998 0.10000000000000001 0.10000000000000001" fromto="0 0 0 0.2402924153323025 0.73203611425615711 0.086432600036130625"/>
          <site name="0/3/9/end9" class="0/3/9/" size="0.0050000000000000001" pos="0.2402924153323025 0.73203611425615711 0.086432600036130625"/>
          <site name="0/3/9/attach10" class="0/3/9/" size="9.9999999999999995e-07 9.9999999999999995e-07 9.9999999999999995e-07" pos="0.069229950359481054 0.21090480022524624 0.024901845535437554"/>
          <body pos="0.069229950359481054 0.21090480022524624 0.024901845535437554" name="0/3/9/10/">
            <joint name="0/3/9/10/joint/" class="0/3/9/" type="hinge" axis="-0.95075764510194383 0.30779725999333696 0.03634208333048404" limited="true" range="-48.839182488207705 48.839182488207705"/>
            <geom name="0/3/9/10/geom" class="0/3/9/10/" type="capsule" contype="1" conaffinity="1" condim="3" size="0.066823643482510131" rgba="0.64478554298642443 0.012583169676117834 0.26508986343450325 1" friction="0.59999999999999998 0.10000000000000001 0.10000000000000001" fromto="0 0 0 -0.46789748471641701 0.23969640553368665 -0.39870912496864741"/>
            <site name="0/3/9/10/end10" class="0/3/9/10/" size="0.0050000000000000001" pos="-0.46789748471641701 0.23969640553368665 -0.39870912496864741"/>
          </body>
        </body>
      </body>
      <camera name="0/iso" class="0/" mode="trackcom" pos="-2.2999999999999998 -2.2999999999999998 1" xyaxes="0.45000000000000001 -0.45000000000000001 0 0.29999999999999999 0.14999999999999999 0.93999999999999995"/>
    </body>
  </worldbody>
  <actuator>
    <motor name="0/1/motor" class="0/1/" ctrllimited="true" ctrlrange="-1 1" gear="83" joint="0/1/joint/"/>
    <motor name="0/1/2/motor" class="0/1/2/" ctrllimited="true" ctrlrange="-1 1" gear="53" joint="0/1/2/joint/"/>
    <motor name="0/3/motor" class="0/3/" ctrllimited="true" ctrlrange="-1 1" gear="94" joint="0/3/joint/"/>
    <motor name="0/3/4/motor" class="0/3/4/" ctrllimited="true" ctrlrange="-1 1" gear="87" joint="0/3/4/joint/"/>
    <motor name="0/3/4/5/motor" class="0/3/4/5/" ctrllimited="true" ctrlrange="-1 1" gear="94" joint="0/3/4/5/joint/"/>
    <motor name="0/3/4/5/6/motor" class="0/3/4/5/6/" ctrllimited="true" ctrlrange="-1 1" gear="55" joint="0/3/4/5/6/joint/"/>
    <motor name="0/3/4/5/6/7/8/motor" class="0/3/4/5/6/7/8/" ctrllimited="true" ctrlrange="-1 1" gear="86" joint="0/3/4/5/6/7/8/joint/"/>
    <motor name="0/3/9/motor" class="0/3/9/" ctrllimited="true" ctrlrange="-1 1" gear="66" joint="0/3/9/joint/"/>
    <motor name="0/3/9/10/motor" class="0/3/9/10/" ctrllimited="true" ctrlrange="-1 1" gear="85" joint="0/3/9/10/joint/"/>
  </actuator>
  <sensor>
    <subtreelinvel name="velocity" body="0/"/>
  </sensor>
</mujoco>
