<mujoco model="morphology">
  <option timestep="0.01"/>
  <default>
    <default class="/"/>
    <default class="0/"/>
    <default class="0/1/"/>
    <default class="0/1/2/"/>
    <default class="0/3/"/>
    <default class="0/3/4/"/>
    <default class="0/3/4/5/"/>
  </default>
  <asset>
    <texture name="texplane" type="2d" builtin="checker" rgb1="0.10000000000000001 0.20000000000000001 0.29999999999999999" rgb2="0.20000000000000001 0.29999999999999999 0.40000000000000002" width="300" height="300"/>
    <material name="MatPlane" class="/" texture="texplane" texrepeat="20 20" specular="1" shininess="1" reflectance="0.5"/>
  </asset>
  <worldbody>
    <light name="//unnamed_light_0" class="/" directional="true" pos="0 0 1.5" dir="0 0 -1.3" cutoff="100" exponent="1" diffuse="1 1 1" specular="0.10000000000000001 0.10000000000000001 0.10000000000000001"/>
    <geom name="ground" class="/" type="plane" size="15 15 0.5" material="MatPlane" rgba="1 1 1 1"/>
    <site name="body" class="/" size="9.9999999999999995e-07 9.9999999999999995e-07 9.9999999999999995e-07" pos="0 0 0.68622747659683225"/>
    <body pos="0 0 0.68622747659683225" name="0/">
      <freejoint name="0/"/>
      <geom name="0/geom" class="0/" type="capsule" contype="1" conaffinity="1" condim="3" size="0.058254493093794296" rgba="0.91234059368148634 0.58153029429761571 0.59587251681420417 1" friction="0.59999999999999998 0.10000000000000001 0.10000000000000001" fromto="0 0 0 0.26056703402592385 0.67904016353479135 0.12783834916980596"/>
      <site name="0/end0" class="0/" size="0.0050000000000000001" pos="0.26056703402592385 0.67904016353479135 0.12783834916980596"/>
      <site name="0/attach1" class="0/" size="9.9999999999999995e-07 9.9999999999999995e-07 9.9999999999999995e-07" pos="0.020492078208590545 0.053402550287864343 0.010053740907931348"/>
      <body pos="0.020492078208590545 0.053402550287864343 0.010053740907931348" name="0/1/">
        <joint name="0/1/joint/" class="0/" type="hinge" axis="0 1 0" limited="true" range="-43.897148453216481 43.897148453216481"/>
        <geom name="0/1/geom" class="0/1/" type="capsule" contype="1" conaffinity="1" condim="3" size="0.068233872348226851" rgba="0.91565888114834848 0.63302278787218613 0.3272825226013335 1" friction="0.59999999999999998 0.10000000000000001 0.10000000000000001" fromto="0 0 0 -0.27798405485062949 0.50919696135514481 -0.065938400911391803"/>
        <site name="0/1/end1" class="0/1/" size="0.0050000000000000001" pos="-0.27798405485062949 0.50919696135514481 -0.065938400911391803"/>
        <site name="0/1/attach2" class="0/1/" size="9.9999999999999995e-07 9.9999999999999995e-07 9.9999999999999995e-07" pos="-0.11608520403005454 0.21263893420850261 -0.027535653896866377"/>
        <body pos="-0.11608520403005454 0.21263893420850261 -0.027535653896866377" name="0/1/2/">
          <joint name="0/1/2/joint/" class="0/1/" type="hinge" axis="6.9388939039072284e-18 0.12842260500540223 0.9917195342049212" limited="true" range="-44.483204910834999 44.483204910834999"/>
          <geom name="0/1/2/geom" class="0/1/2/" type="capsule" contype="1" conaffinity="1" condim="3" size="0.06116470921178517" rgba="0.37410305271563715 0.40615906073305308 0.23793919696476395 1" friction="0.59999999999999998 0.10000000000000001 0.10000000000000001" fromto="0 0 0 0.47455058960571073 0.14817146835751271 -0.56874556013143551"/>
          <site name="0/1/2/end2" class="0/1/2/" size="0.0050000000000000001" pos="0.47455058960571073 0.14817146835751271 -0.56874556013143551"/>
        </body>
      </body>
      <site name="0/attach3" class="0/" size="9.9999999999999995e-07 9.9999999999999995e-07 9.9999999999999995e-07" pos="0.13960041672529599 0.36380001083805141 0.068490194411175126"/>
      <body pos="0.13960041672529599 0.36380001083805141 0.068490194411175126" name="0/3/">
        <joint name="0/3/joint/" class="0/" type="hinge" axis="0 0 1" limited="true" range="-32.40447555250713 32.40447555250713"/>
        <geom name="0/3/geom" class="0/3/" type="capsule" contype="1" conaffinity="1" condim="3" size="0.039980858929634065" rgba="0.57221577522034917 0.54323075022220646 0.2223408596633738 1" friction="0.59999999999999998 0.10000000000000001 0.10000000000000001" fromto="0 0 0 0.40551178916891972 -0.61343069704181419 -0.24139504931118683"/>
        <site name="0/3/end3" class="0/3/" size="0.0050000000000000001" pos="0.40551178916891972 -0.61343069704181419 -0.24139504931118683"/>
        <site name="0/3/attach4" class="0/3/" size="9.9999999999999995e-07 9.9999999999999995e-07 9.9999999999999995e-07" pos="0.055879112629088928 -0.084530126930196986 -0.033263992586280496"/>
        <body pos="0.055879112629088928 -0.084530126930196986 -0.033263992586280496" name="0/3/4/">
          <joint name="0/3/4/joint/" class="0/3/" type="hinge" axis="2.7755575615628914e-17 -0.36618377093708304 0.93054255458968571" limited="true" range="-61.020100756573811 61.020100756573811"/>
          <geom name="0/3/4/geom" class="0/3/4/" type="capsule" contype="1" conaffinity="1" condim="3" size="0.069988390101037523" rgba="0.63914119299735417 0.85053080054189822 0.86690414504096758 1" friction="0.59999999999999998 0.10000000000000001 0.10000000000000001" fromto="0 0 0 0.74133113184145616 0.20564334740090306 0.12319740934819023"/>
          <site name="0/3/4/end4" class="0/3/4/" size="0.0050000000000000001" pos="0.74133113184145616 0.20564334740090306 0.12319740934819023"/>
          <site name="0/3/4/attach5" class="0/3/4/" size="9.9999999999999995e-07 9.9999999999999995e-07 9.9999999999999995e-07" pos="0.1079697265915896 0.029950524186273149 0.017942846364856255"/>
          <body pos="0.1079697265915896 0.029950524186273149 0.017942846364856255" name="0/3/4/5/">
            <joint name="0/3/4/5/joint/" class="0/3/4/" type="hinge" axis="1.3877787807814457e-17 -0.51391715318194053 0.85783982168314477" limited="true" range="-39.151015119708504 39.151015119708504"/>
            <geom name="0/3/4/5/geom" class="0/3/4/5/" type="capsule" contype="1" conaffinity="1" condim="3" size="0.041190986530466038" rgba="0.80010267944474034 0.55122412614540328 0.31845759001812535 1" friction="0.59999999999999998 0.10000000000000001 0.10000000000000001" fromto="0 0 0 0.38233153107352602 -0.45824097107176559 -0.3327949213134222"/>
            <site name="0/3/4/5/end5" class="0/3/4/5/" size="0.0050000000000000001" pos="0.38233153107352602 -0.45824097107176559 -0.3327949213134222"/>
          </body>
        </body>
      </body>
      <camera name="0/iso" class="0/" mode="trackcom" pos="-2.2999999999999998 -2.2999999999999998 1" xyaxes="0.45000000000000001 -0.45000000000000001 0 0.29999999999999999 0.14999999999999999 0.93999999999999995"/>
    </body>
  </worldbody>
  <actuator>
    <motor name="0/1/motor" class="0/1/" ctrllimited="true" ctrlrange="-1 1" gear="62" joint="0/1/joint/"/>
    <motor name="0/1/2/motor" class="0/1/2/" ctrllimited="true" ctrlrange="-1 1" gear="78" joint="0/1/2/joint/"/>
    <motor name="0/3/motor" class="0/3/" ctrllimited="true" ctrlrange="-1 1" gear="56" joint="0/3/joint/"/>
    <motor name="0/3/4/motor" class="0/3/4/" ctrllimited="true" ctrlrange="-1 1" gear="87" joint="0/3/4/joint/"/>
    <motor name="0/3/4/5/motor" class="0/3/4/5/" ctrllimited="true" ctrlrange="-1 1" gear="72" joint="0/3/4/5/joint/"/>
  </actuator>
  <sensor>
    <subtreelinvel name="velocity" body="0/"/>
  </sensor>
</mujoco>
