<mujoco model="morphology">
  <option timestep="0.01"/>
  <default>
    <default class="/"/>
    <default class="0/"/>
    <default class="0/1/"/>
    <default class="0/1/2/"/>
    <default class="0/1/2/3/"/>
    <default class="0/1/2/3/4/"/>
  </default>
  <asset>
    <texture name="texplane" type="2d" builtin="checker" rgb1="0.10000000000000001 0.20000000000000001 0.29999999999999999" rgb2="0.20000000000000001 0.29999999999999999 0.40000000000000002" width="300" height="300"/>
    <material name="MatPlane" class="/" texture="texplane" texrepeat="20 20" specular="1" shininess="1" reflectance="0.5"/>
  </asset>
  <worldbody>
    <light name="//unnamed_light_0" class="/" directional="true" pos="0 0 1.5" dir="0 0 -1.3" cutoff="100" exponent="1" diffuse="1 1 1" specular="0.10000000000000001 0.10000000000000001 0.10000000000000001"/>
    <geom name="ground" class="/" type="plane" size="15 15 0.5" material="MatPlane" rgba="1 1 1 1"/>
    <site name="body" class="/" size="9.9999999999999995e-07 9.9999999999999995e-07 9.9999999999999995e-07" pos="0 0 0.10000000000000001"/>
    <body pos="0 0 0.10000000000000001" name="0/">
      <freejoint name="0/"/>
      <geom name="0/geom" class="0/" type="capsule" contype="1" conaffinity="1" condim="3" size="0.059070205948229787" rgba="0.51090367066379661 0.22830723833799016 0.97212608646440068 1" friction="0.59999999999999998 0.10000000000000001 0.10000000000000001" fromto="0 0 0 -0.11206018951559682 0.23620110630052071 0.72040203933370073"/>
      <site name="0/end0" class="0/" size="0.0050000000000000001" pos="-0.11206018951559682 0.23620110630052071 0.72040203933370073"/>
      <site name="0/attach1" class="0/" size="9.9999999999999995e-07 9.9999999999999995e-07 9.9999999999999995e-07" pos="-0.10770349177528353 0.22701803396656084 0.69239410939489421"/>
      <body pos="-0.10770349177528353 0.22701803396656084 0.69239410939489421" name="0/1/">
        <joint name="0/1/joint/" class="0/" type="hinge" axis="0 1 0" limited="true" range="-40.716969231009557 40.716969231009557"/>
        <geom name="0/1/geom" class="0/1/" type="capsule" contype="1" conaffinity="1" condim="3" size="0.058895077632900167" rgba="0.23298932180848331 0.6385157189463827 0.71026778506236476 1" friction="0.59999999999999998 0.10000000000000001 0.10000000000000001" fromto="0 0 0 0.24849582314458618 0.49730611108311806 0.39374618795719973"/>
        <site name="0/1/end1" class="0/1/" size="0.0050000000000000001" pos="0.24849582314458618 0.49730611108311806 0.39374618795719973"/>
        <site name="0/1/attach2" class="0/1/" size="9.9999999999999995e-07 9.9999999999999995e-07 9.9999999999999995e-07" pos="0.018915810682409252 0.037855558815489854 0.029972448848708085"/>
        <body pos="0.018915810682409252 0.037855558815489854 0.029972448848708085" name="0/1/2/">
          <joint name="0/1/2/joint/" class="0/1/" type="hinge" axis="-0.93109950577311562 0.28597995697138595 0.22642697401083614" limited="true" range="-45.242805720640064 45.242805720640064"/>
          <geom name="0/1/2/geom" class="0/1/2/" type="capsule" contype="1" conaffinity="1" condim="3" size="0.059605936802312805" rgba="0.050149687664105547 0.97490437123562346 0.35210924211522876 1" friction="0.59999999999999998 0.10000000000000001 0.10000000000000001" fromto="0 0 0 0.24884090850795548 -0.10016161286423353 0.37658283316195029"/>
          <site name="0/1/2/end2" class="0/1/2/" size="0.0050000000000000001" pos="0.24884090850795548 -0.10016161286423353 0.37658283316195029"/>
          <site name="0/1/2/attach3" class="0/1/2/" size="9.9999999999999995e-07 9.9999999999999995e-07 9.9999999999999995e-07" pos="0.15564431744997659 -0.062648806269102741 0.23554398021736966"/>
          <body pos="0.15564431744997659 -0.062648806269102741 0.23554398021736966" name="0/1/2/3/">
            <joint name="0/1/2/3/joint/" class="0/1/2/" type="hinge" axis="-5.5511151231257827e-17 0.96640115549685879 0.25703853145848776" limited="true" range="-34.902993035165977 34.902993035165977"/>
            <geom name="0/1/2/3/geom" class="0/1/2/3/" type="capsule" contype="1" conaffinity="1" condim="3" size="0.03699569982208184" rgba="0.92899633155097128 0.53441044061973175 0.025740930500663617 1" friction="0.59999999999999998 0.10000000000000001 0.10000000000000001" fromto="0 0 0 -0.58484392159837051 0.55202057761234102 0.68816981516177345"/>
            <site name="0/1/2/3/end3" class="0/1/2/3/" size="0.0050000000000000001" pos="-0.58484392159837051 0.55202057761234102 0.68816981516177345"/>
            <site name="0/1/2/3/attach4" class="0/1/2/3/" size="9.9999999999999995e-07 9.9999999999999995e-07 9.9999999999999995e-07" pos="-0.17074986506422643 0.16116682700981017 0.20091668689828759"/>
            <body pos="-0.17074986506422643 0.16116682700981017 0.20091668689828759" name="0/1/2/3/4/">
              <joint name="0/1/2/3/4/joint/" class="0/1/2/3/" type="hinge" axis="0 -0.78004718354929725 0.62572069762539329" limited="true" range="-45.163165155750775 45.163165155750775"/>
              <geom name="0/1/2/3/4/geom" class="0/1/2/3/4/" type="capsule" contype="1" conaffinity="1" condim="3" size="0.066008501331527497" rgba="0.54820390453067425 0.62699636568389749 0.080259804231928467 1" friction="0.59999999999999998 0.10000000000000001 0.10000000000000001" fromto="0 0 0 0.43746094908197808 -0.064786665818130529 0.092839142108050332"/>
              <site name="0/1/2/3/4/end4" class="0/1/2/3/4/" size="0.0050000000000000001" pos="0.43746094908197808 -0.064786665818130529 0.092839142108050332"/>
            </body>
          </body>
        </body>
      </body>
      <camera name="0/iso" class="0/" mode="trackcom" pos="-2.2999999999999998 -2.2999999999999998 1" xyaxes="0.45000000000000001 -0.45000000000000001 0 0.29999999999999999 0.14999999999999999 0.93999999999999995"/>
    </body>
  </worldbody>
  <actuator>
    <motor name="0/1/motor" class="0/1/" ctrllimited="true" ctrlrange="-1 1" gear="50" joint="0/1/joint/"/>
    <motor name="0/1/2/motor" class="0/1/2/" ctrllimited="true" ctrlrange="-1 1" gear="62" joint="0/1/2/joint/"/>
    <motor name="0/1/2/3/motor" class="0/1/2/3/" ctrllimited="true" ctrlrange="-1 1" gear="58" joint="0/1/2/3/joint/"/>
    <motor name="0/1/2/3/4/motor" class="0/1/2/3/4/" ctrllimited="true" ctrlrange="-1 1" gear="95" joint="0/1/2/3/4/joint/"/>
  </actuator>
  <sensor>
    <subtreelinvel name="velocity" body="0/"/>
  </sensor>
</mujoco>
