<mujoco model="morphology">
  <option timestep="0.01"/>
  <default>
    <default class="/"/>
    <default class="0/"/>
    <default class="0/1/"/>
    <default class="0/2/"/>
    <default class="0/2/3/"/>
    <default class="0/2/3/4/"/>
    <default class="0/2/3/4/5/"/>
    <default class="0/2/3/4/5/6/"/>
    <default class="0/2/3/7/"/>
    <default class="0/2/3/7/8/"/>
    <default class="0/2/3/7/8/9/"/>
    <default class="0/10/"/>
  </default>
  <asset>
    <texture name="texplane" type="2d" builtin="checker" rgb1="0.10000000000000001 0.20000000000000001 0.29999999999999999" rgb2="0.20000000000000001 0.29999999999999999 0.40000000000000002" width="300" height="300"/>
    <material name="MatPlane" class="/" texture="texplane" texrepeat="20 20" specular="1" shininess="1" reflectance="0.5"/>
  </asset>
  <worldbody>
    <light name="//unnamed_light_0" class="/" directional="true" pos="0 0 1.5" dir="0 0 -1.3" cutoff="100" exponent="1" diffuse="1 1 1" specular="0.10000000000000001 0.10000000000000001 0.10000000000000001"/>
    <geom name="ground" class="/" type="plane" size="15 15 0.5" material="MatPlane" rgba="1 1 1 1"/>
    <site name="body" class="/" size="9.9999999999999995e-07 9.9999999999999995e-07 9.9999999999999995e-07" pos="0 0 0.77324995994567869"/>
    <body pos="0 0 0.77324995994567869" name="0/">
      <freejoint name="0/"/>
      <geom name="0/geom" class="0/" type="capsule" contype="1" conaffinity="1" condim="3" size="0.058286365520991125" rgba="0.53131681539357278 0.087090393785219322 0.68147886682230707 1" friction="0.59999999999999998 0.10000000000000001 0.10000000000000001" fromto="0 0 0 -0.60235649590779339 -0.1367480983390057 0.28209050380961198"/>
      <site name="0/end0" class="0/" size="0.0050000000000000001" pos="-0.60235649590779339 -0.1367480983390057 0.28209050380961198"/>
      <site name="0/attach1" class="0/" size="9.9999999999999995e-07 9.9999999999999995e-07 9.9999999999999995e-07" pos="-0.035174868615798272 -0.0079854644636738505 0.016472797216727193"/>
      <body pos="-0.035174868615798272 -0.0079854644636738505 0.016472797216727193" name="0/1/">
        <joint name="0/1/joint/" class="0/" type="hinge" axis="0 0 1" limited="true" range="-39.348695203276876 39.348695203276876"/>
        <geom name="0/1/geom" class="0/1/" type="capsule" contype="1" conaffinity="1" condim="3" size="0.047485996170656797" rgba="0.096959016274733356 0.19012276992587618 0.091708374620212529 1" friction="0.59999999999999998 0.10000000000000001 0.10000000000000001" fromto="0 0 0 -0.23079797287615889 -0.084081606292986999 -0.63293791730475157"/>
        <site name="0/1/end1" class="0/1/" size="0.0050000000000000001" pos="-0.23079797287615889 -0.084081606292986999 -0.63293791730475157"/>
      </body>
      <site name="0/attach2" class="0/" size="9.9999999999999995e-07 9.9999999999999995e-07 9.9999999999999995e-07" pos="-0.41524274967644187 -0.094269185694986574 0.19446297542285798"/>
      <body pos="-0.41524274967644187 -0.094269185694986574 0.19446297542285798" name="0/2/">
        <joint name="0/2/joint/" class="0/" type="hinge" axis="0 1 0" limited="true" range="-50.673322531357066 50.673322531357066"/>
        <geom name="0/2/geom" class="0/2/" type="capsule" contype="1" conaffinity="1" condim="3" size="0.038669352575092061" rgba="0.32773100328396121 0.59226189986170141 0.30675772909429377 1" friction="0.59999999999999998 0.10000000000000001 0.10000000000000001" fromto="0 0 0 0.34004461499453242 -0.55781484849628937 0.10784149799031317"/>
        <site name="0/2/end2" class="0/2/" size="0.0050000000000000001" pos="0.34004461499453242 -0.55781484849628937 0.10784149799031317"/>
        <site name="0/2/attach3" class="0/2/" size="9.9999999999999995e-07 9.9999999999999995e-07 9.9999999999999995e-07" pos="0.23068977567018417 -0.37842734920879678 0.073160785033228592"/>
        <body pos="0.23068977567018417 -0.37842734920879678 0.073160785033228592" name="0/2/3/">
          <geom name="0/2/3/geom" class="0/2/3/" type="capsule" contype="1" conaffinity="1" condim="3" size="0.048196844195484659" rgba="0.194972537321498 0.25901136975569927 0.41747375598082337 1" friction="0.59999999999999998 0.10000000000000001 0.10000000000000001" fromto="0 0 0 0.25552161887260882 0.16270890176548447 -0.61711781576840674"/>
          <site name="0/2/3/end3" class="0/2/3/" size="0.0050000000000000001" pos="0.25552161887260882 0.16270890176548447 -0.61711781576840674"/>
          <site name="0/2/3/attach4" class="0/2/3/" size="9.9999999999999995e-07 9.9999999999999995e-07 9.9999999999999995e-07" pos="0.084064760607244285 0.053530049378727268 -0.2030272885634013"/>
          <body pos="0.084064760607244285 0.053530049378727268 -0.2030272885634013" name="0/2/3/4/">
            <joint name="0/2/3/4/joint/" class="0/2/3/" type="hinge" axis="2.2204460492503131e-16 0.96695508646074235 0.25494678026540823" limited="true" range="-69.691313945014457 69.691313945014457"/>
            <geom name="0/2/3/4/geom" class="0/2/3/4/" type="capsule" contype="1" conaffinity="1" condim="3" size="0.069365691491402565" rgba="0.55053611342657494 0.79452475360467545 0.88332604843653784 1" friction="0.59999999999999998 0.10000000000000001 0.10000000000000001" fromto="0 0 0 0.34096621471647359 -0.38731363930335039 -0.52465299420552935"/>
            <site name="0/2/3/4/end4" class="0/2/3/4/" size="0.0050000000000000001" pos="0.34096621471647359 -0.38731363930335039 -0.52465299420552935"/>
            <site name="0/2/3/4/attach5" class="0/2/3/4/" size="9.9999999999999995e-07 9.9999999999999995e-07 9.9999999999999995e-07" pos="0.034856335839123426 -0.039594346020049929 -0.053634290365795756"/>
            <body pos="0.034856335839123426 -0.039594346020049929 -0.053634290365795756" name="0/2/3/4/5/">
              <joint name="0/2/3/4/5/joint/" class="0/2/3/4/" type="hinge" axis="-5.5511151231257827e-17 -0.80452296334358953 0.59392154486333382" limited="true" range="-40.598159050621568 40.598159050621568"/>
              <geom name="0/2/3/4/5/geom" class="0/2/3/4/5/" type="capsule" contype="1" conaffinity="1" condim="3" size="0.047724938827500188" rgba="0.45124043340129616 0.039621455234082781 0.71993021692694781 1" friction="0.59999999999999998 0.10000000000000001 0.10000000000000001" fromto="0 0 0 -0.62248729874454112 -0.50376418235960707 -0.68421215272309177"/>
              <site name="0/2/3/4/5/end5" class="0/2/3/4/5/" size="0.0050000000000000001" pos="-0.62248729874454112 -0.50376418235960707 -0.68421215272309177"/>
              <site name="0/2/3/4/5/attach6" class="0/2/3/4/5/" size="9.9999999999999995e-07 9.9999999999999995e-07 9.9999999999999995e-07" pos="-0.23287048044521652 -0.18845654748903765 -0.25596154821541173"/>
              <body pos="-0.23287048044521652 -0.18845654748903765 -0.25596154821541173" name="0/2/3/4/5/6/">
                <geom name="0/2/3/4/5/6/geom" class="0/2/3/4/5/6/" type="capsule" contype="1" conaffinity="1" condim="3" size="0.06003555934222652" rgba="0.27247002872478365 0.4009876041930065 0.57997228192279116 1" friction="0.59999999999999998 0.10000000000000001 0.10000000000000001" fromto="0 0 0 0.15628310746028073 -0.034719590350495988 -0.40132102925658303"/>
                <site name="0/2/3/4/5/6/end6" class="0/2/3/4/5/6/" size="0.0050000000000000001" pos="0.15628310746028073 -0.034719590350495988 -0.40132102925658303"/>
              </body>
            </body>
          </body>
          <site name="0/2/3/attach7" class="0/2/3/" size="9.9999999999999995e-07 9.9999999999999995e-07 9.9999999999999995e-07" pos="0.11972874395517641 0.07623985995650695 -0.28916042908741035"/>
          <body pos="0.11972874395517641 0.07623985995650695 -0.28916042908741035" name="0/2/3/7/">
            <joint name="0/2/3/7/joint/" class="0/2/3/" type="hinge" axis="2.2204460492503131e-16 0.96695508646074235 0.25494678026540823" limited="true" range="-31.591290347906327 31.591290347906327"/>
            <geom name="0/2/3/7/geom" class="0/2/3/7/" type="capsule" contype="1" conaffinity="1" condim="3" size="0.068101396736661407" rgba="0.75036603913224542 0.7895901450051197 0.0029696939305262626 1" friction="0.59999999999999998 0.10000000000000001 0.10000000000000001" fromto="0 0 0 -0.72130829266373064 0.43191335360261363 0.14608572151616572"/>
            <site name="0/2/3/7/end7" class="0/2/3/7/" size="0.0050000000000000001" pos="-0.72130829266373064 0.43191335360261363 0.14608572151616572"/>
            <site name="0/2/3/7/attach8" class="0/2/3/7/" size="9.9999999999999995e-07 9.9999999999999995e-07 9.9999999999999995e-07" pos="-0.60872592263664937 0.36449997503828863 0.12328454631454712"/>
            <body pos="-0.60872592263664937 0.36449997503828863 0.12328454631454712" name="0/2/3/7/8/">
              <geom name="0/2/3/7/8/geom" class="0/2/3/7/8/" type="capsule" contype="1" conaffinity="1" condim="3" size="0.055002788415417461" rgba="0.74931587716554604 0.92762511631396372 0.13540563380076076 1" friction="0.59999999999999998 0.10000000000000001 0.10000000000000001" fromto="0 0 0 -0.55369660014967137 -0.15033152454037602 0.26626087585081404"/>
              <site name="0/2/3/7/8/end8" class="0/2/3/7/8/" size="0.0050000000000000001" pos="-0.55369660014967137 -0.15033152454037602 0.26626087585081404"/>
              <site name="0/2/3/7/8/attach9" class="0/2/3/7/8/" size="9.9999999999999995e-07 9.9999999999999995e-07 9.9999999999999995e-07" pos="-0.12318195842251142 -0.033444546346355859 0.059235574373638161"/>
              <body pos="-0.12318195842251142 -0.033444546346355859 0.059235574373638161" name="0/2/3/7/8/9/">
                <joint name="0/2/3/7/8/9/joint/" class="0/2/3/7/8/" type="hinge" axis="0 0.87079215417854083 0.49165132382725912" limited="true" range="-47.912756875054562 47.912756875054562"/>
                <geom name="0/2/3/7/8/9/geom" class="0/2/3/7/8/9/" type="capsule" contype="1" conaffinity="1" condim="3" size="0.048739756609608484" rgba="0.0037546397219763161 0.38136025398027984 0.093878937337488311 1" friction="0.59999999999999998 0.10000000000000001 0.10000000000000001" fromto="0 0 0 0.37374777151118987 -0.65425171720923014 0.37954516837998709"/>
                <site name="0/2/3/7/8/9/end9" class="0/2/3/7/8/9/" size="0.0050000000000000001" pos="0.37374777151118987 -0.65425171720923014 0.37954516837998709"/>
              </body>
            </body>
          </body>
        </body>
      </body>
      <site name="0/attach10" class="0/" size="9.9999999999999995e-07 9.9999999999999995e-07 9.9999999999999995e-07" pos="-0.24997934854657022 -0.056750779264443697 0.11706821600259633"/>
      <body pos="-0.24997934854657022 -0.056750779264443697 0.11706821600259633" name="0/10/">
        <joint name="0/10/joint/" class="0/" type="hinge" axis="0 0 1" limited="true" range="-44.872708489943093 44.872708489943093"/>
        <geom name="0/10/geom" class="0/10/" type="capsule" contype="1" conaffinity="1" condim="3" size="0.052002730978267263" rgba="0.84974781022190315 0.52240731252726524 0.21656823360869448 1" friction="0.59999999999999998 0.10000000000000001 0.10000000000000001" fromto="0 0 0 -0.43404383981294586 0.43752227762620266 0.70302731200250435"/>
        <site name="0/10/end10" class="0/10/" size="0.0050000000000000001" pos="-0.43404383981294586 0.43752227762620266 0.70302731200250435"/>
      </body>
      <camera name="0/iso" class="0/" mode="trackcom" pos="-2.2999999999999998 -2.2999999999999998 1" xyaxes="0.45000000000000001 -0.45000000000000001 0 0.29999999999999999 0.14999999999999999 0.93999999999999995"/>
    </body>
  </worldbody>
  <actuator>
    <motor name="0/1/motor" class="0/1/" ctrllimited="true" ctrlrange="-1 1" gear="55" joint="0/1/joint/"/>
    <motor name="0/2/motor" class="0/2/" ctrllimited="true" ctrlrange="-1 1" gear="76" joint="0/2/joint/"/>
    <motor name="0/2/3/4/motor" class="0/2/3/4/" ctrllimited="true" ctrlrange="-1 1" gear="73" joint="0/2/3/4/joint/"/>
    <motor name="0/2/3/4/5/motor" class="0/2/3/4/5/" ctrllimited="true" ctrlrange="-1 1" gear="98" joint="0/2/3/4/5/joint/"/>
    <motor name="0/2/3/7/motor" class="0/2/3/7/" ctrllimited="true" ctrlrange="-1 1" gear="51" joint="0/2/3/7/joint/"/>
    <motor name="0/2/3/7/8/9/motor" class="0/2/3/7/8/9/" ctrllimited="true" ctrlrange="-1 1" gear="65" joint="0/2/3/7/8/9/joint/"/>
    <motor name="0/10/motor" class="0/10/" ctrllimited="true" ctrlrange="-1 1" gear="78" joint="0/10/joint/"/>
  </actuator>
  <sensor>
    <subtreelinvel name="velocity" body="0/"/>
  </sensor>
</mujoco>
