<mujoco model="morphology">
  <option timestep="0.01"/>
  <default>
    <default class="/"/>
    <default class="0/"/>
    <default class="0/1/"/>
    <default class="0/2/"/>
    <default class="0/2/3/"/>
    <default class="0/2/4/"/>
    <default class="0/2/4/5/"/>
    <default class="0/2/4/5/6/"/>
    <default class="0/2/4/5/7/"/>
    <default class="0/2/4/5/8/"/>
    <default class="0/2/4/9/"/>
    <default class="0/10/"/>
  </default>
  <asset>
    <texture name="texplane" type="2d" builtin="checker" rgb1="0.10000000000000001 0.20000000000000001 0.29999999999999999" rgb2="0.20000000000000001 0.29999999999999999 0.40000000000000002" width="300" height="300"/>
    <material name="MatPlane" class="/" texture="texplane" texrepeat="20 20" specular="1" shininess="1" reflectance="0.5"/>
  </asset>
  <worldbody>
    <light name="//unnamed_light_0" class="/" directional="true" pos="0 0 1.5" dir="0 0 -1.3" cutoff="100" exponent="1" diffuse="1 1 1" specular="0.10000000000000001 0.10000000000000001 0.10000000000000001"/>
    <geom name="ground" class="/" type="plane" size="15 15 0.5" material="MatPlane" rgba="1 1 1 1"/>
    <site name="body" class="/" size="9.9999999999999995e-07 9.9999999999999995e-07 9.9999999999999995e-07" pos="0 0 0.84916887283325193"/>
    <body pos="0 0 0.84916887283325193" name="0/">
      <freejoint name="0/"/>
      <geom name="0/geom" class="0/" type="capsule" contype="1" conaffinity="1" condim="3" size="0.0494672707006482" rgba="0.72208494569027015 0.46383124850338331 0.41194762392329776 1" friction="0.59999999999999998 0.10000000000000001 0.10000000000000001" fromto="0 0 0 -0.21414844513648179 0.57323252468791863 -0.74916887572444424"/>
      <site name="0/end0" class="0/" size="0.0050000000000000001" pos="-0.21414844513648179 0.57323252468791863 -0.74916887572444424"/>
      <site name="0/attach1" class="0/" size="9.9999999999999995e-07 9.9999999999999995e-07 9.9999999999999995e-07" pos="-0.153136984130432 0.40991705534091105 -0.53572867250897194"/>
      <body pos="-0.153136984130432 0.40991705534091105 -0.53572867250897194" name="0/1/">
        <joint name="0/1/joint/" class="0/" type="hinge" axis="0 0 1" limited="true" range="-37.933956674139694 37.933956674139694"/>
        <geom name="0/1/geom" class="0/1/" type="capsule" contype="1" conaffinity="1" condim="3" size="0.052166626693578258" rgba="0.24075887596006418 0.60992251197264369 0.79980986442201107 1" friction="0.59999999999999998 0.10000000000000001 0.10000000000000001" fromto="0 0 0 0.44218960327257273 0.67677026487066705 0.19073556805387915"/>
        <site name="0/1/end1" class="0/1/" size="0.0050000000000000001" pos="0.44218960327257273 0.67677026487066705 0.19073556805387915"/>
      </body>
      <site name="0/attach2" class="0/" size="9.9999999999999995e-07 9.9999999999999995e-07 9.9999999999999995e-07" pos="-0.13791180717557591 0.3691623040323494 -0.48246548540198264"/>
      <body pos="-0.13791180717557591 0.3691623040323494 -0.48246548540198264" name="0/2/">
        <joint name="0/2/joint/" class="0/" type="hinge" axis="0 1 0" limited="true" range="-35.678086593743117 35.678086593743117"/>
        <geom name="0/2/geom" class="0/2/" type="capsule" contype="1" conaffinity="1" condim="3" size="0.042968340705630138" rgba="0.46536666383449166 0.57792519389536978 0.23382628635141456 1" friction="0.59999999999999998 0.10000000000000001 0.10000000000000001" fromto="0 0 0 -0.5069350259472547 0.50166222906680691 0.14133656650145254"/>
        <site name="0/2/end2" class="0/2/" size="0.0050000000000000001" pos="-0.5069350259472547 0.50166222906680691 0.14133656650145254"/>
        <site name="0/2/attach3" class="0/2/" size="9.9999999999999995e-07 9.9999999999999995e-07 9.9999999999999995e-07" pos="-0.16314656083371806 0.1614496201352284 0.045486252802656509"/>
        <body pos="-0.16314656083371806 0.1614496201352284 0.045486252802656509" name="0/2/3/">
          <joint name="0/2/3/joint/" class="0/2/" type="hinge" axis="1.3877787807814457e-17 -0.27117950446711175 0.96252879248205958" limited="true" range="-51.965993796605389 51.965993796605389"/>
          <geom name="0/2/3/geom" class="0/2/3/" type="capsule" contype="1" conaffinity="1" condim="3" size="0.039572520129649805" rgba="0.84469272069934365 0.17666229199153816 0.38157777708286333 1" friction="0.59999999999999998 0.10000000000000001 0.10000000000000001" fromto="0 0 0 0.22744192779543848 0.33448668980301632 -0.22217255837190053"/>
          <site name="0/2/3/end3" class="0/2/3/" size="0.0050000000000000001" pos="0.22744192779543848 0.33448668980301632 -0.22217255837190053"/>
        </body>
        <site name="0/2/attach4" class="0/2/" size="9.9999999999999995e-07 9.9999999999999995e-07 9.9999999999999995e-07" pos="-0.32471018202263396 0.32133276529823362 0.090531172410871955"/>
        <body pos="-0.32471018202263396 0.32133276529823362 0.090531172410871955" name="0/2/4/">
          <joint name="0/2/4/joint/" class="0/2/" type="hinge" axis="1.3877787807814457e-17 -0.27117950446711175 0.96252879248205958" limited="true" range="-47.616036304325462 47.616036304325462"/>
          <geom name="0/2/4/geom" class="0/2/4/" type="capsule" contype="1" conaffinity="1" condim="3" size="0.059001911700485798" rgba="0.8363445953944163 0.53938012407515412 0.23954322197817479 1" friction="0.59999999999999998 0.10000000000000001 0.10000000000000001" fromto="0 0 0 -0.044536394291860182 -0.43736008393658454 0.62893304217937773"/>
          <site name="0/2/4/end4" class="0/2/4/" size="0.0050000000000000001" pos="-0.044536394291860182 -0.43736008393658454 0.62893304217937773"/>
          <site name="0/2/4/attach5" class="0/2/4/" size="9.9999999999999995e-07 9.9999999999999995e-07 9.9999999999999995e-07" pos="-0.016828649983450815 -0.16526213866951178 0.23765044741841812"/>
          <body pos="-0.016828649983450815 -0.16526213866951178 0.23765044741841812" name="0/2/4/5/">
            <geom name="0/2/4/5/geom" class="0/2/4/5/" type="capsule" contype="1" conaffinity="1" condim="3" size="0.060904466573494957" rgba="0.1634184065751787 0.73945743559977251 0.15097514452572069 1" friction="0.59999999999999998 0.10000000000000001 0.10000000000000001" fromto="0 0 0 0.72954030359459465 -0.63215210639668196 0.25557717849418826"/>
            <site name="0/2/4/5/end5" class="0/2/4/5/" size="0.0050000000000000001" pos="0.72954030359459465 -0.63215210639668196 0.25557717849418826"/>
            <site name="0/2/4/5/attach6" class="0/2/4/5/" size="9.9999999999999995e-07 9.9999999999999995e-07 9.9999999999999995e-07" pos="0.45335811668746345 -0.39283818454432018 0.15882328603302046"/>
            <body pos="0.45335811668746345 -0.39283818454432018 0.15882328603302046" name="0/2/4/5/6/">
              <joint name="0/2/4/5/6/joint/" class="0/2/4/5/" type="hinge" axis="-2.7755575615628914e-17 0.37482236217575327 0.92709664912186407" limited="true" range="-54.536576295120234 54.536576295120234"/>
              <geom name="0/2/4/5/6/geom" class="0/2/4/5/6/" type="capsule" contype="1" conaffinity="1" condim="3" size="0.042355108393929343" rgba="0.82599712644444057 0.16630231200018109 0.6374901367281447 1" friction="0.59999999999999998 0.10000000000000001 0.10000000000000001" fromto="0 0 0 0.20295309187663357 0.47764977789031882 0.16041794843207324"/>
              <site name="0/2/4/5/6/end6" class="0/2/4/5/6/" size="0.0050000000000000001" pos="0.20295309187663357 0.47764977789031882 0.16041794843207324"/>
            </body>
            <site name="0/2/4/5/attach7" class="0/2/4/5/" size="9.9999999999999995e-07 9.9999999999999995e-07 9.9999999999999995e-07" pos="0.60885160669086402 -0.52757445168720285 0.21329675001228704"/>
            <body pos="0.60885160669086402 -0.52757445168720285 0.21329675001228704" name="0/2/4/5/7/">
              <joint name="0/2/4/5/7/joint/" class="0/2/4/5/" type="hinge" axis="0.68283072913089782 0.67731513484655681 -0.27383645385952038" limited="true" range="-52.252921503539604 52.252921503539604"/>
              <geom name="0/2/4/5/7/geom" class="0/2/4/5/7/" type="capsule" contype="1" conaffinity="1" condim="3" size="0.036105561881775904" rgba="0.24848776017168117 0.36883593790664815 0.58609742922836372 1" friction="0.59999999999999998 0.10000000000000001 0.10000000000000001" fromto="0 0 0 0.71967839977963144 0.59687852477562431 -0.0077393665497609287"/>
              <site name="0/2/4/5/7/end7" class="0/2/4/5/7/" size="0.0050000000000000001" pos="0.71967839977963144 0.59687852477562431 -0.0077393665497609287"/>
            </body>
            <site name="0/2/4/5/attach8" class="0/2/4/5/" size="9.9999999999999995e-07 9.9999999999999995e-07 9.9999999999999995e-07" pos="0.69072058591842544 -0.59851453191614756 0.24197760919728808"/>
            <body pos="0.69072058591842544 -0.59851453191614756 0.24197760919728808" name="0/2/4/5/8/">
              <joint name="0/2/4/5/8/joint/" class="0/2/4/5/" type="hinge" axis="-2.7755575615628914e-17 0.37482236217575327 0.92709664912186407" limited="true" range="-69.859859058551791 69.859859058551791"/>
              <geom name="0/2/4/5/8/geom" class="0/2/4/5/8/" type="capsule" contype="1" conaffinity="1" condim="3" size="0.03723578997378401" rgba="0.021742336176411636 0.89134967643218088 0.88576537877910955 1" friction="0.59999999999999998 0.10000000000000001 0.10000000000000001" fromto="0 0 0 0.46895878397508817 -0.12765825921395335 -0.25148145448684445"/>
              <site name="0/2/4/5/8/end8" class="0/2/4/5/8/" size="0.0050000000000000001" pos="0.46895878397508817 -0.12765825921395335 -0.25148145448684445"/>
            </body>
          </body>
          <site name="0/2/4/attach9" class="0/2/4/" size="9.9999999999999995e-07 9.9999999999999995e-07 9.9999999999999995e-07" pos="-0.042988462151249268 -0.42215894918577562 0.60707348920565196"/>
          <body pos="-0.042988462151249268 -0.42215894918577562 0.60707348920565196" name="0/2/4/9/">
            <geom name="0/2/4/9/geom" class="0/2/4/9/" type="capsule" contype="1" conaffinity="1" condim="3" size="0.0637555505775982" rgba="0.86911805660076269 0.57694730905514346 0.8000767029259177 1" friction="0.59999999999999998 0.10000000000000001 0.10000000000000001" fromto="0 0 0 0.37595542056521292 0.20180459599926026 0.43444000546976547"/>
            <site name="0/2/4/9/end9" class="0/2/4/9/" size="0.0050000000000000001" pos="0.37595542056521292 0.20180459599926026 0.43444000546976547"/>
          </body>
        </body>
      </body>
      <site name="0/attach10" class="0/" size="9.9999999999999995e-07 9.9999999999999995e-07 9.9999999999999995e-07" pos="-0.016144320599290583 0.043215114873257361 -0.056478684703954771"/>
      <body pos="-0.016144320599290583 0.043215114873257361 -0.056478684703954771" name="0/10/">
        <geom name="0/10/geom" class="0/10/" type="capsule" contype="1" conaffinity="1" condim="3" size="0.057560098638505336" rgba="0.31881156436997615 0.11070247249691811 0.62262605085985889 1" friction="0.59999999999999998 0.10000000000000001 0.10000000000000001" fromto="0 0 0 -0.47960453045221801 -0.30052790061579393 -0.60286071110636774"/>
        <site name="0/10/end10" class="0/10/" size="0.0050000000000000001" pos="-0.47960453045221801 -0.30052790061579393 -0.60286071110636774"/>
      </body>
      <camera name="0/iso" class="0/" mode="trackcom" pos="-2.2999999999999998 -2.2999999999999998 1" xyaxes="0.45000000000000001 -0.45000000000000001 0 0.29999999999999999 0.14999999999999999 0.93999999999999995"/>
    </body>
  </worldbody>
  <actuator>
    <motor name="0/1/motor" class="0/1/" ctrllimited="true" ctrlrange="-1 1" gear="50" joint="0/1/joint/"/>
    <motor name="0/2/motor" class="0/2/" ctrllimited="true" ctrlrange="-1 1" gear="63" joint="0/2/joint/"/>
    <motor name="0/2/3/motor" class="0/2/3/" ctrllimited="true" ctrlrange="-1 1" gear="54" joint="0/2/3/joint/"/>
    <motor name="0/2/4/motor" class="0/2/4/" ctrllimited="true" ctrlrange="-1 1" gear="64" joint="0/2/4/joint/"/>
    <motor name="0/2/4/5/6/motor" class="0/2/4/5/6/" ctrllimited="true" ctrlrange="-1 1" gear="56" joint="0/2/4/5/6/joint/"/>
    <motor name="0/2/4/5/7/motor" class="0/2/4/5/7/" ctrllimited="true" ctrlrange="-1 1" gear="79" joint="0/2/4/5/7/joint/"/>
    <motor name="0/2/4/5/8/motor" class="0/2/4/5/8/" ctrllimited="true" ctrlrange="-1 1" gear="55" joint="0/2/4/5/8/joint/"/>
  </actuator>
  <sensor>
    <subtreelinvel name="velocity" body="0/"/>
  </sensor>
</mujoco>
