<mujoco model="morphology">
  <option timestep="0.01"/>
  <default>
    <default class="/"/>
    <default class="0/"/>
    <default class="0/1/"/>
    <default class="0/2/"/>
    <default class="0/2/3/"/>
    <default class="0/2/3/4/"/>
    <default class="0/2/3/4/5/"/>
    <default class="0/2/3/4/5/6/"/>
    <default class="0/2/3/4/5/7/"/>
    <default class="0/2/3/4/5/7/8/"/>
    <default class="0/2/3/4/5/7/8/9/"/>
    <default class="0/2/3/4/5/7/10/"/>
  </default>
  <asset>
    <texture name="texplane" type="2d" builtin="checker" rgb1="0.10000000000000001 0.20000000000000001 0.29999999999999999" rgb2="0.20000000000000001 0.29999999999999999 0.40000000000000002" width="300" height="300"/>
    <material name="MatPlane" class="/" texture="texplane" texrepeat="20 20" specular="1" shininess="1" reflectance="0.5"/>
  </asset>
  <worldbody>
    <light name="//unnamed_light_0" class="/" directional="true" pos="0 0 1.5" dir="0 0 -1.3" cutoff="100" exponent="1" diffuse="1 1 1" specular="0.10000000000000001 0.10000000000000001 0.10000000000000001"/>
    <geom name="ground" class="/" type="plane" size="15 15 0.5" material="MatPlane" rgba="1 1 1 1"/>
    <site name="body" class="/" size="9.9999999999999995e-07 9.9999999999999995e-07 9.9999999999999995e-07" pos="0 0 0.6339807868003845"/>
    <body pos="0 0 0.6339807868003845" name="0/">
      <freejoint name="0/"/>
      <geom name="0/geom" class="0/" type="capsule" contype="1" conaffinity="1" condim="3" size="0.069239408312006562" rgba="0.028983618900700781 0.59713778164759235 0.059517698026362087 1" friction="0.59999999999999998 0.10000000000000001 0.10000000000000001" fromto="0 0 0 -0.24072216535364432 0.54030887701177166 -0.52425831496177866"/>
      <site name="0/end0" class="0/" size="0.0050000000000000001" pos="-0.24072216535364432 0.54030887701177166 -0.52425831496177866"/>
      <site name="0/attach1" class="0/" size="9.9999999999999995e-07 9.9999999999999995e-07 9.9999999999999995e-07" pos="-0.14000442672186406 0.31424457514178822 -0.30490954055919506"/>
      <body pos="-0.14000442672186406 0.31424457514178822 -0.30490954055919506" name="0/1/">
        <joint name="0/1/joint/" class="0/" type="hinge" axis="0 0 1" limited="true" range="-62.681512039241049 62.681512039241049"/>
        <geom name="0/1/geom" class="0/1/" type="capsule" contype="1" conaffinity="1" condim="3" size="0.053794196365464786" rgba="0.54014187003808978 0.77962031529611031 0.85023846878318698 1" friction="0.59999999999999998 0.10000000000000001 0.10000000000000001" fromto="0 0 0 -0.51545219124715547 -0.077864364179542678 -0.011449889936490543"/>
        <site name="0/1/end1" class="0/1/" size="0.0050000000000000001" pos="-0.51545219124715547 -0.077864364179542678 -0.011449889936490543"/>
      </body>
      <site name="0/attach2" class="0/" size="9.9999999999999995e-07 9.9999999999999995e-07 9.9999999999999995e-07" pos="-0.052693658148251055 0.11827266183775501 -0.11475922206577924"/>
      <body pos="-0.052693658148251055 0.11827266183775501 -0.11475922206577924" name="0/2/">
        <joint name="0/2/joint/" class="0/" type="hinge" axis="0 1 0" limited="true" range="-46.75308144498787 46.75308144498787"/>
        <geom name="0/2/geom" class="0/2/" type="capsule" contype="1" conaffinity="1" condim="3" size="0.057852742447363437" rgba="0.56494904536556512 0.98610336337197502 0.11163074240465509 1" friction="0.59999999999999998 0.10000000000000001 0.10000000000000001" fromto="0 0 0 -0.57899988921213097 0.25003245260949769 0.65870212627601488"/>
        <site name="0/2/end2" class="0/2/" size="0.0050000000000000001" pos="-0.57899988921213097 0.25003245260949769 0.65870212627601488"/>
        <site name="0/2/attach3" class="0/2/" size="9.9999999999999995e-07 9.9999999999999995e-07 9.9999999999999995e-07" pos="-0.33681482567506221 0.14544845086822134 0.38317907475827623"/>
        <body pos="-0.33681482567506221 0.14544845086822134 0.38317907475827623" name="0/2/3/">
          <joint name="0/2/3/joint/" class="0/2/" type="hinge" axis="5.5511151231257827e-17 -0.9349128194768016 0.35487747178137069" limited="true" range="-56.046585267591432 56.046585267591432"/>
          <geom name="0/2/3/geom" class="0/2/3/" type="capsule" contype="1" conaffinity="1" condim="3" size="0.064219243848727764" rgba="0.98097914343447989 0.97985150148291977 0.034936872294176191 1" friction="0.59999999999999998 0.10000000000000001 0.10000000000000001" fromto="0 0 0 0.63424906329867481 0.063864310740443297 -0.083706646396342288"/>
          <site name="0/2/3/end3" class="0/2/3/" size="0.0050000000000000001" pos="0.63424906329867481 0.063864310740443297 -0.083706646396342288"/>
          <site name="0/2/3/attach4" class="0/2/3/" size="9.9999999999999995e-07 9.9999999999999995e-07 9.9999999999999995e-07" pos="0.084372282045786479 0.0084956808772060997 -0.011135248260561151"/>
          <body pos="0.084372282045786479 0.0084956808772060997 -0.011135248260561151" name="0/2/3/4/">
            <joint name="0/2/3/4/joint/" class="0/2/3/" type="hinge" axis="-1.3877787807814457e-17 0.79502946304612343 0.60657081440553406" limited="true" range="-59.680294609656116 59.680294609656116"/>
            <geom name="0/2/3/4/geom" class="0/2/3/4/" type="capsule" contype="1" conaffinity="1" condim="3" size="0.060403769827605688" rgba="0.4136832074781488 0.69691415463301654 0.042330237162864881 1" friction="0.59999999999999998 0.10000000000000001 0.10000000000000001" fromto="0 0 0 0.13116659073035342 0.58853202170213748 0.063442700384473083"/>
            <site name="0/2/3/4/end4" class="0/2/3/4/" size="0.0050000000000000001" pos="0.13116659073035342 0.58853202170213748 0.063442700384473083"/>
            <site name="0/2/3/4/attach5" class="0/2/3/4/" size="9.9999999999999995e-07 9.9999999999999995e-07 9.9999999999999995e-07" pos="0.10886555790958934 0.48846940774709807 0.052656129386217915"/>
            <body pos="0.10886555790958934 0.48846940774709807 0.052656129386217915" name="0/2/3/4/5/">
              <joint name="0/2/3/4/5/joint/" class="0/2/3/4/" type="hinge" axis="-6.9388939039072284e-18 -0.10717728749603456 0.99423992529217609" limited="true" range="-46.092520378966803 46.092520378966803"/>
              <geom name="0/2/3/4/5/geom" class="0/2/3/4/5/" type="capsule" contype="1" conaffinity="1" condim="3" size="0.057351553660276354" rgba="0.43478097618025757 0.94935669518013222 0.2849429782857078 1" friction="0.59999999999999998 0.10000000000000001 0.10000000000000001" fromto="0 0 0 -0.66673106151711781 0.032484767115335655 -0.53876134312651613"/>
              <site name="0/2/3/4/5/end5" class="0/2/3/4/5/" size="0.0050000000000000001" pos="-0.66673106151711781 0.032484767115335655 -0.53876134312651613"/>
              <site name="0/2/3/4/5/attach6" class="0/2/3/4/5/" size="9.9999999999999995e-07 9.9999999999999995e-07 9.9999999999999995e-07" pos="-0.12971331351976148 0.0063199497138469347 -0.10481665404080374"/>
              <body pos="-0.12971331351976148 0.0063199497138469347 -0.10481665404080374" name="0/2/3/4/5/6/">
                <geom name="0/2/3/4/5/6/geom" class="0/2/3/4/5/6/" type="capsule" contype="1" conaffinity="1" condim="3" size="0.036251891826751446" rgba="0.84512372480189457 0.61571713922864568 0.99014857928695543 1" friction="0.59999999999999998 0.10000000000000001 0.10000000000000001" fromto="0 0 0 -0.18564040382199765 0.30833766236284355 0.13030208298549661"/>
                <site name="0/2/3/4/5/6/end6" class="0/2/3/4/5/6/" size="0.0050000000000000001" pos="-0.18564040382199765 0.30833766236284355 0.13030208298549661"/>
              </body>
              <site name="0/2/3/4/5/attach7" class="0/2/3/4/5/" size="9.9999999999999995e-07 9.9999999999999995e-07 9.9999999999999995e-07" pos="-0.082675379439150709 0.0040281465830340167 -0.066806994665550928"/>
              <body pos="-0.082675379439150709 0.0040281465830340167 -0.066806994665550928" name="0/2/3/4/5/7/">
                <joint name="0/2/3/4/5/7/joint/" class="0/2/3/4/5/" type="hinge" axis="-0.62920183781763039 -0.046779066503153499 0.77583294994735175" limited="true" range="-58.79549741404081 58.79549741404081"/>
                <geom name="0/2/3/4/5/7/geom" class="0/2/3/4/5/7/" type="capsule" contype="1" conaffinity="1" condim="3" size="0.06246939965727602" rgba="0.43160478388301804 0.87345394041209012 0.39833891948312039 1" friction="0.59999999999999998 0.10000000000000001 0.10000000000000001" fromto="0 0 0 0.091419208609380798 0.71753801611340773 -0.52837493378358724"/>
                <site name="0/2/3/4/5/7/end7" class="0/2/3/4/5/7/" size="0.0050000000000000001" pos="0.091419208609380798 0.71753801611340773 -0.52837493378358724"/>
                <site name="0/2/3/4/5/7/attach8" class="0/2/3/4/5/7/" size="9.9999999999999995e-07 9.9999999999999995e-07 9.9999999999999995e-07" pos="0.034851288497502117 0.27354343565087086 -0.20142973815079387"/>
                <body pos="0.034851288497502117 0.27354343565087086 -0.20142973815079387" name="0/2/3/4/5/7/8/">
                  <joint name="0/2/3/4/5/7/8/joint/" class="0/2/3/4/5/7/" type="hinge" axis="-0.99477856113417606 0.082179960953209452 -0.06051502561799732" limited="true" range="-36.238198384778862 36.238198384778862"/>
                  <geom name="0/2/3/4/5/7/8/geom" class="0/2/3/4/5/7/8/" type="capsule" contype="1" conaffinity="1" condim="3" size="0.051829212019544615" rgba="0.15145542346698482 0.79947742683594314 0.49752217208122329 1" friction="0.59999999999999998 0.10000000000000001 0.10000000000000001" fromto="0 0 0 -0.47003499917166586 -0.70562651391438025 -0.57568477176085131"/>
                  <site name="0/2/3/4/5/7/8/end8" class="0/2/3/4/5/7/8/" size="0.0050000000000000001" pos="-0.47003499917166586 -0.70562651391438025 -0.57568477176085131"/>
                  <site name="0/2/3/4/5/7/8/attach9" class="0/2/3/4/5/7/8/" size="9.9999999999999995e-07 9.9999999999999995e-07 9.9999999999999995e-07" pos="-0.1343835069333624 -0.20173937194482341 -0.16458888945225378"/>
                  <body pos="-0.1343835069333624 -0.20173937194482341 -0.16458888945225378" name="0/2/3/4/5/7/8/9/">
                    <joint name="0/2/3/4/5/7/8/9/joint/" class="0/2/3/4/5/7/8/" type="hinge" axis="0 -0.63215447705958205 0.77484238212266532" limited="true" range="-39.239623068106283 39.239623068106283"/>
                    <geom name="0/2/3/4/5/7/8/9/geom" class="0/2/3/4/5/7/8/9/" type="capsule" contype="1" conaffinity="1" condim="3" size="0.058460671165780825" rgba="0.82912015936236916 0.33122180519936861 0.63051968067832609 1" friction="0.59999999999999998 0.10000000000000001 0.10000000000000001" fromto="0 0 0 0.56230715109287033 -0.40321280174276458 0.23003754308262625"/>
                    <site name="0/2/3/4/5/7/8/9/end9" class="0/2/3/4/5/7/8/9/" size="0.0050000000000000001" pos="0.56230715109287033 -0.40321280174276458 0.23003754308262625"/>
                  </body>
                </body>
                <site name="0/2/3/4/5/7/attach10" class="0/2/3/4/5/7/" size="9.9999999999999995e-07 9.9999999999999995e-07 9.9999999999999995e-07" pos="0.016114463836162839 0.12648042558689412 -0.093136649199967544"/>
                <body pos="0.016114463836162839 0.12648042558689412 -0.093136649199967544" name="0/2/3/4/5/7/10/">
                  <joint name="0/2/3/4/5/7/10/joint/" class="0/2/3/4/5/7/" type="hinge" axis="-0.99477856113417606 0.082179960953209452 -0.06051502561799732" limited="true" range="-41.927705328299048 41.927705328299048"/>
                  <geom name="0/2/3/4/5/7/10/geom" class="0/2/3/4/5/7/10/" type="capsule" contype="1" conaffinity="1" condim="3" size="0.040150983371065624" rgba="0.87427333341380953 0.29310218094804352 0.70469955846292287 1" friction="0.59999999999999998 0.10000000000000001 0.10000000000000001" fromto="0 0 0 0.73349623161903743 -0.71035833045432062 0.47904988462779041"/>
                  <site name="0/2/3/4/5/7/10/end10" class="0/2/3/4/5/7/10/" size="0.0050000000000000001" pos="0.73349623161903743 -0.71035833045432062 0.47904988462779041"/>
                </body>
              </body>
            </body>
          </body>
        </body>
      </body>
      <camera name="0/iso" class="0/" mode="trackcom" pos="-2.2999999999999998 -2.2999999999999998 1" xyaxes="0.45000000000000001 -0.45000000000000001 0 0.29999999999999999 0.14999999999999999 0.93999999999999995"/>
    </body>
  </worldbody>
  <actuator>
    <motor name="0/1/motor" class="0/1/" ctrllimited="true" ctrlrange="-1 1" gear="93" joint="0/1/joint/"/>
    <motor name="0/2/motor" class="0/2/" ctrllimited="true" ctrlrange="-1 1" gear="66" joint="0/2/joint/"/>
    <motor name="0/2/3/motor" class="0/2/3/" ctrllimited="true" ctrlrange="-1 1" gear="87" joint="0/2/3/joint/"/>
    <motor name="0/2/3/4/motor" class="0/2/3/4/" ctrllimited="true" ctrlrange="-1 1" gear="60" joint="0/2/3/4/joint/"/>
    <motor name="0/2/3/4/5/motor" class="0/2/3/4/5/" ctrllimited="true" ctrlrange="-1 1" gear="73" joint="0/2/3/4/5/joint/"/>
    <motor name="0/2/3/4/5/7/motor" class="0/2/3/4/5/7/" ctrllimited="true" ctrlrange="-1 1" gear="75" joint="0/2/3/4/5/7/joint/"/>
    <motor name="0/2/3/4/5/7/8/motor" class="0/2/3/4/5/7/8/" ctrllimited="true" ctrlrange="-1 1" gear="65" joint="0/2/3/4/5/7/8/joint/"/>
    <motor name="0/2/3/4/5/7/8/9/motor" class="0/2/3/4/5/7/8/9/" ctrllimited="true" ctrlrange="-1 1" gear="88" joint="0/2/3/4/5/7/8/9/joint/"/>
    <motor name="0/2/3/4/5/7/10/motor" class="0/2/3/4/5/7/10/" ctrllimited="true" ctrlrange="-1 1" gear="71" joint="0/2/3/4/5/7/10/joint/"/>
  </actuator>
  <sensor>
    <subtreelinvel name="velocity" body="0/"/>
  </sensor>
</mujoco>
