<mujoco model="morphology">
  <option timestep="0.01"/>
  <default>
    <default class="/"/>
    <default class="0/"/>
    <default class="0/1/"/>
    <default class="0/2/"/>
    <default class="0/2/3/"/>
    <default class="0/2/4/"/>
    <default class="0/2/4/5/"/>
    <default class="0/2/4/6/"/>
    <default class="0/2/4/6/7/"/>
    <default class="0/2/4/6/7/8/"/>
    <default class="0/2/4/6/7/8/9/"/>
    <default class="0/2/4/6/7/8/9/10/"/>
  </default>
  <asset>
    <texture name="texplane" type="2d" builtin="checker" rgb1="0.10000000000000001 0.20000000000000001 0.29999999999999999" rgb2="0.20000000000000001 0.29999999999999999 0.40000000000000002" width="300" height="300"/>
    <material name="MatPlane" class="/" texture="texplane" texrepeat="20 20" specular="1" shininess="1" reflectance="0.5"/>
  </asset>
  <worldbody>
    <light name="//unnamed_light_0" class="/" directional="true" pos="0 0 1.5" dir="0 0 -1.3" cutoff="100" exponent="1" diffuse="1 1 1" specular="0.10000000000000001 0.10000000000000001 0.10000000000000001"/>
    <geom name="ground" class="/" type="plane" size="15 15 0.5" material="MatPlane" rgba="1 1 1 1"/>
    <site name="body" class="/" size="9.9999999999999995e-07 9.9999999999999995e-07 9.9999999999999995e-07" pos="0 0 0.10000000000000001"/>
    <body pos="0 0 0.10000000000000001" name="0/">
      <freejoint name="0/"/>
      <geom name="0/geom" class="0/" type="capsule" contype="1" conaffinity="1" condim="3" size="0.051947668119962043" rgba="0.17008995358205847 0.086740348510780163 0.20043783536801252 1" friction="0.59999999999999998 0.10000000000000001 0.10000000000000001" fromto="0 0 0 -0.015124879015189663 -0.2741727664000243 0.21592200323721134"/>
      <site name="0/end0" class="0/" size="0.0050000000000000001" pos="-0.015124879015189663 -0.2741727664000243 0.21592200323721134"/>
      <site name="0/attach1" class="0/" size="9.9999999999999995e-07 9.9999999999999995e-07 9.9999999999999995e-07" pos="-0.0014429367085019911 -0.0261565033818008 0.020599291031112497"/>
      <body pos="-0.0014429367085019911 -0.0261565033818008 0.020599291031112497" name="0/1/">
        <joint name="0/1/joint/" class="0/" type="hinge" axis="0 0 1" limited="true" range="-38.945167168469467 38.945167168469467"/>
        <geom name="0/1/geom" class="0/1/" type="capsule" contype="1" conaffinity="1" condim="3" size="0.047547189934321929" rgba="0.65490491302895359 0.9993291647498127 0.83727817759508272 1" friction="0.59999999999999998 0.10000000000000001 0.10000000000000001" fromto="0 0 0 0.56936086223393989 0.57127187923443001 0.5186810532045214"/>
        <site name="0/1/end1" class="0/1/" size="0.0050000000000000001" pos="0.56936086223393989 0.57127187923443001 0.5186810532045214"/>
      </body>
      <site name="0/attach2" class="0/" size="9.9999999999999995e-07 9.9999999999999995e-07 9.9999999999999995e-07" pos="-0.009325881156072139 -0.16905276618148818 0.13313580486488313"/>
      <body pos="-0.009325881156072139 -0.16905276618148818 0.13313580486488313" name="0/2/">
        <geom name="0/2/geom" class="0/2/" type="capsule" contype="1" conaffinity="1" condim="3" size="0.040273981876545996" rgba="0.90570183000098181 0.80530982773710724 0.63060642469439665 1" friction="0.59999999999999998 0.10000000000000001 0.10000000000000001" fromto="0 0 0 -0.42801313072803387 -0.51139404775834407 -0.1231489523255499"/>
        <site name="0/2/end2" class="0/2/" size="0.0050000000000000001" pos="-0.42801313072803387 -0.51139404775834407 -0.1231489523255499"/>
        <site name="0/2/attach3" class="0/2/" size="9.9999999999999995e-07 9.9999999999999995e-07 9.9999999999999995e-07" pos="-0.29761666015210597 -0.35559513853376329 -0.085630970783580493"/>
        <body pos="-0.29761666015210597 -0.35559513853376329 -0.085630970783580493" name="0/2/3/">
          <geom name="0/2/3/geom" class="0/2/3/" type="capsule" contype="1" conaffinity="1" condim="3" size="0.060613769204168728" rgba="0.97730961655021098 0.79524015453033947 0.65959582507271697 1" friction="0.59999999999999998 0.10000000000000001 0.10000000000000001" fromto="0 0 0 -0.271627779624253 0.1377616393265455 0.29531815028145925"/>
          <site name="0/2/3/end3" class="0/2/3/" size="0.0050000000000000001" pos="-0.271627779624253 0.1377616393265455 0.29531815028145925"/>
        </body>
        <site name="0/2/attach4" class="0/2/" size="9.9999999999999995e-07 9.9999999999999995e-07 9.9999999999999995e-07" pos="-0.13912921473594334 -0.16623287272572865 -0.040030587387504341"/>
        <body pos="-0.13912921473594334 -0.16623287272572865 -0.040030587387504341" name="0/2/4/">
          <joint name="0/2/4/joint/" class="0/2/" type="hinge" axis="2.7755575615628914e-17 -0.23411775640190127 0.97220824730987543" limited="true" range="-67.130722155939281 67.130722155939281"/>
          <geom name="0/2/4/geom" class="0/2/4/" type="capsule" contype="1" conaffinity="1" condim="3" size="0.062375322524543406" rgba="0.56803803311293299 0.31531441273933047 0.12881389796459819 1" friction="0.59999999999999998 0.10000000000000001 0.10000000000000001" fromto="0 0 0 0.1977873375023208 -0.38780542039387633 0.45019635368044231"/>
          <site name="0/2/4/end4" class="0/2/4/" size="0.0050000000000000001" pos="0.1977873375023208 -0.38780542039387633 0.45019635368044231"/>
          <site name="0/2/4/attach5" class="0/2/4/" size="9.9999999999999995e-07 9.9999999999999995e-07 9.9999999999999995e-07" pos="0.063847530050916035 -0.12518707489156433 0.1453274288607459"/>
          <body pos="0.063847530050916035 -0.12518707489156433 0.1453274288607459" name="0/2/4/5/">
            <joint name="0/2/4/5/joint/" class="0/2/4/" type="hinge" axis="0.94881650821474739 0.20612659004345923 -0.23928865960640427" limited="true" range="-62.365794479512601 62.365794479512601"/>
            <geom name="0/2/4/5/geom" class="0/2/4/5/" type="capsule" contype="1" conaffinity="1" condim="3" size="0.051613249903198627" rgba="0.064829656524055368 0.92633863569160035 0.61141433399122169 1" friction="0.59999999999999998 0.10000000000000001 0.10000000000000001" fromto="0 0 0 0.26766560494311964 -0.67883645491163369 -0.17070767819232846"/>
            <site name="0/2/4/5/end5" class="0/2/4/5/" size="0.0050000000000000001" pos="0.26766560494311964 -0.67883645491163369 -0.17070767819232846"/>
          </body>
          <site name="0/2/4/attach6" class="0/2/4/" size="9.9999999999999995e-07 9.9999999999999995e-07 9.9999999999999995e-07" pos="0.11197998170427992 -0.21956129461532034 0.25488476706896329"/>
          <body pos="0.11197998170427992 -0.21956129461532034 0.25488476706896329" name="0/2/4/6/">
            <joint name="0/2/4/6/joint/" class="0/2/4/" type="hinge" axis="0.94881650821474739 0.20612659004345923 -0.23928865960640427" limited="true" range="-32.387324655436423 32.387324655436423"/>
            <geom name="0/2/4/6/geom" class="0/2/4/6/" type="capsule" contype="1" conaffinity="1" condim="3" size="0.037607145795378813" rgba="0.76564882075850516 0.85018267906095313 0.99003804888002156 1" friction="0.59999999999999998 0.10000000000000001 0.10000000000000001" fromto="0 0 0 0.50287907196268655 0.56639528890529278 0.037499454228937301"/>
            <site name="0/2/4/6/end6" class="0/2/4/6/" size="0.0050000000000000001" pos="0.50287907196268655 0.56639528890529278 0.037499454228937301"/>
            <site name="0/2/4/6/attach7" class="0/2/4/6/" size="9.9999999999999995e-07 9.9999999999999995e-07 9.9999999999999995e-07" pos="0.3373215769884832 0.37992702958725888 0.025153910237988894"/>
            <body pos="0.3373215769884832 0.37992702958725888 0.025153910237988894" name="0/2/4/6/7/">
              <joint name="0/2/4/6/7/joint/" class="0/2/4/6/" type="hinge" axis="-0.74851200542800855 0.66167263846103475 0.043807502121824035" limited="true" range="-51.042755028630928 51.042755028630928"/>
              <geom name="0/2/4/6/7/geom" class="0/2/4/6/7/" type="capsule" contype="1" conaffinity="1" condim="3" size="0.063485759345504711" rgba="0.99369893431799328 0.31533687040264258 0.18542702936454603 1" friction="0.59999999999999998 0.10000000000000001 0.10000000000000001" fromto="0 0 0 -0.26801149792076012 -0.60414206198473464 0.74768021726471012"/>
              <site name="0/2/4/6/7/end7" class="0/2/4/6/7/" size="0.0050000000000000001" pos="-0.26801149792076012 -0.60414206198473464 0.74768021726471012"/>
              <site name="0/2/4/6/7/attach8" class="0/2/4/6/7/" size="9.9999999999999995e-07 9.9999999999999995e-07 9.9999999999999995e-07" pos="-0.11791138556888238 -0.26579168491540983 0.32894115015240966"/>
              <body pos="-0.11791138556888238 -0.26579168491540983 0.32894115015240966" name="0/2/4/6/7/8/">
                <joint name="0/2/4/6/7/8/joint/" class="0/2/4/6/7/" type="hinge" axis="0 0.77781581580368608 0.62849228848542493" limited="true" range="-59.394895785121463 59.394895785121463"/>
                <geom name="0/2/4/6/7/8/geom" class="0/2/4/6/7/8/" type="capsule" contype="1" conaffinity="1" condim="3" size="0.044590788661464487" rgba="0.24309551689514686 0.082245804832438263 0.58858535188126071 1" friction="0.59999999999999998 0.10000000000000001 0.10000000000000001" fromto="0 0 0 -0.64565018095165416 0.014379675073345033 0.25353967290647206"/>
                <site name="0/2/4/6/7/8/end8" class="0/2/4/6/7/8/" size="0.0050000000000000001" pos="-0.64565018095165416 0.014379675073345033 0.25353967290647206"/>
                <site name="0/2/4/6/7/8/attach9" class="0/2/4/6/7/8/" size="9.9999999999999995e-07 9.9999999999999995e-07 9.9999999999999995e-07" pos="-0.59741050408975371 0.013305299351967777 0.23459648624980173"/>
                <body pos="-0.59741050408975371 0.013305299351967777 0.23459648624980173" name="0/2/4/6/7/8/9/">
                  <joint name="0/2/4/6/7/8/9/joint/" class="0/2/4/6/7/8/" type="hinge" axis="-0.36602548096376902 -0.05269520265289538 -0.92911170636399354" limited="true" range="-69.064796551833879 69.064796551833879"/>
                  <geom name="0/2/4/6/7/8/9/geom" class="0/2/4/6/7/8/9/" type="capsule" contype="1" conaffinity="1" condim="3" size="0.038340657540722071" rgba="0.36664928132420138 0.12032409957356183 0.12617374655951019 1" friction="0.59999999999999998 0.10000000000000001 0.10000000000000001" fromto="0 0 0 -0.37687471438626746 -0.14897727932940097 -0.25832774556499788"/>
                  <site name="0/2/4/6/7/8/9/end9" class="0/2/4/6/7/8/9/" size="0.0050000000000000001" pos="-0.37687471438626746 -0.14897727932940097 -0.25832774556499788"/>
                  <site name="0/2/4/6/7/8/9/attach10" class="0/2/4/6/7/8/9/" size="9.9999999999999995e-07 9.9999999999999995e-07 9.9999999999999995e-07" pos="-0.064709661012602004 -0.025579506599916715 -0.04435506073386445"/>
                  <body pos="-0.064709661012602004 -0.025579506599916715 -0.04435506073386445" name="0/2/4/6/7/8/9/10/">
                    <joint name="0/2/4/6/7/8/9/10/joint/" class="0/2/4/6/7/8/9/" type="hinge" axis="5.5511151231257827e-17 -0.8662697014708145 0.49957662506733286" limited="true" range="-60.670800738790334 60.670800738790334"/>
                    <geom name="0/2/4/6/7/8/9/10/geom" class="0/2/4/6/7/8/9/10/" type="capsule" contype="1" conaffinity="1" condim="3" size="0.059768906012667752" rgba="0.7493276809354068 0.89542763707783168 0.28312483415490663 1" friction="0.59999999999999998 0.10000000000000001 0.10000000000000001" fromto="0 0 0 -0.10208297780189968 0.091487822954094522 -0.22671658450186682"/>
                    <site name="0/2/4/6/7/8/9/10/end10" class="0/2/4/6/7/8/9/10/" size="0.0050000000000000001" pos="-0.10208297780189968 0.091487822954094522 -0.22671658450186682"/>
                  </body>
                </body>
              </body>
            </body>
          </body>
        </body>
      </body>
      <camera name="0/iso" class="0/" mode="trackcom" pos="-2.2999999999999998 -2.2999999999999998 1" xyaxes="0.45000000000000001 -0.45000000000000001 0 0.29999999999999999 0.14999999999999999 0.93999999999999995"/>
    </body>
  </worldbody>
  <actuator>
    <motor name="0/1/motor" class="0/1/" ctrllimited="true" ctrlrange="-1 1" gear="82" joint="0/1/joint/"/>
    <motor name="0/2/4/motor" class="0/2/4/" ctrllimited="true" ctrlrange="-1 1" gear="56" joint="0/2/4/joint/"/>
    <motor name="0/2/4/5/motor" class="0/2/4/5/" ctrllimited="true" ctrlrange="-1 1" gear="84" joint="0/2/4/5/joint/"/>
    <motor name="0/2/4/6/motor" class="0/2/4/6/" ctrllimited="true" ctrlrange="-1 1" gear="64" joint="0/2/4/6/joint/"/>
    <motor name="0/2/4/6/7/motor" class="0/2/4/6/7/" ctrllimited="true" ctrlrange="-1 1" gear="90" joint="0/2/4/6/7/joint/"/>
    <motor name="0/2/4/6/7/8/motor" class="0/2/4/6/7/8/" ctrllimited="true" ctrlrange="-1 1" gear="76" joint="0/2/4/6/7/8/joint/"/>
    <motor name="0/2/4/6/7/8/9/motor" class="0/2/4/6/7/8/9/" ctrllimited="true" ctrlrange="-1 1" gear="91" joint="0/2/4/6/7/8/9/joint/"/>
    <motor name="0/2/4/6/7/8/9/10/motor" class="0/2/4/6/7/8/9/10/" ctrllimited="true" ctrlrange="-1 1" gear="99" joint="0/2/4/6/7/8/9/10/joint/"/>
  </actuator>
  <sensor>
    <subtreelinvel name="velocity" body="0/"/>
  </sensor>
</mujoco>
