<mujoco model="morphology">
  <option timestep="0.01"/>
  <default>
    <default class="/"/>
    <default class="0/"/>
    <default class="0/1/"/>
    <default class="0/2/"/>
    <default class="0/2/3/"/>
    <default class="0/4/"/>
  </default>
  <asset>
    <texture name="texplane" type="2d" builtin="checker" rgb1="0.10000000000000001 0.20000000000000001 0.29999999999999999" rgb2="0.20000000000000001 0.29999999999999999 0.40000000000000002" width="300" height="300"/>
    <material name="MatPlane" class="/" texture="texplane" texrepeat="20 20" specular="1" shininess="1" reflectance="0.5"/>
  </asset>
  <worldbody>
    <light name="//unnamed_light_0" class="/" directional="true" pos="0 0 1.5" dir="0 0 -1.3" cutoff="100" exponent="1" diffuse="1 1 1" specular="0.10000000000000001 0.10000000000000001 0.10000000000000001"/>
    <geom name="ground" class="/" type="plane" size="15 15 0.5" material="MatPlane" rgba="1 1 1 1"/>
    <site name="body" class="/" size="9.9999999999999995e-07 9.9999999999999995e-07 9.9999999999999995e-07" pos="0 0 0.89136073589324949"/>
    <body pos="0 0 0.89136073589324949" name="0/">
      <freejoint name="0/"/>
      <geom name="0/geom" class="0/" type="capsule" contype="1" conaffinity="1" condim="3" size="0.04256601216110395" rgba="0.53950646774564825 0.86254871344026296 0.6080514269133801 1" friction="0.59999999999999998 0.10000000000000001 0.10000000000000001" fromto="0 0 0 -0.14801576258814464 -0.56940228471119125 -0.16840136581684773"/>
      <site name="0/end0" class="0/" size="0.0050000000000000001" pos="-0.14801576258814464 -0.56940228471119125 -0.16840136581684773"/>
      <site name="0/attach1" class="0/" size="9.9999999999999995e-07 9.9999999999999995e-07 9.9999999999999995e-07" pos="-0.070211728433384954 -0.27009771043596414 -0.079881701501233596"/>
      <body pos="-0.070211728433384954 -0.27009771043596414 -0.079881701501233596" name="0/1/">
        <joint name="0/1/joint/" class="0/" type="hinge" axis="0 1 0" limited="true" range="-64.616524388936455 64.616524388936455"/>
        <geom name="0/1/geom" class="0/1/" type="capsule" contype="1" conaffinity="1" condim="3" size="0.054126733210347749" rgba="0.79033459572757925 0.88804944407163267 0.79149886454554386 1" friction="0.59999999999999998 0.10000000000000001 0.10000000000000001" fromto="0 0 0 0.7493083679382444 0.41703197979773465 -0.69381121495491493"/>
        <site name="0/1/end1" class="0/1/" size="0.0050000000000000001" pos="0.7493083679382444 0.41703197979773465 -0.69381121495491493"/>
      </body>
      <site name="0/attach2" class="0/" size="9.9999999999999995e-07 9.9999999999999995e-07 9.9999999999999995e-07" pos="-0.11567027417514099 -0.44497232752000487 -0.13160106609526173"/>
      <body pos="-0.11567027417514099 -0.44497232752000487 -0.13160106609526173" name="0/2/">
        <joint name="0/2/joint/" class="0/" type="hinge" axis="0 1 0" limited="true" range="-52.687984357339957 52.687984357339957"/>
        <geom name="0/2/geom" class="0/2/" type="capsule" contype="1" conaffinity="1" condim="3" size="0.045588483758489208" rgba="0.83656184204346251 0.74615430400895622 0.53881747406896496 1" friction="0.59999999999999998 0.10000000000000001 0.10000000000000001" fromto="0 0 0 0.65632992424179237 -0.24532050095676949 -0.65975965574710838"/>
        <site name="0/2/end2" class="0/2/" size="0.0050000000000000001" pos="0.65632992424179237 -0.24532050095676949 -0.65975965574710838"/>
        <site name="0/2/attach3" class="0/2/" size="9.9999999999999995e-07 9.9999999999999995e-07 9.9999999999999995e-07" pos="0.021753290317204931 -0.0081308620572795587 -0.021866964770234622"/>
        <body pos="0.021753290317204931 -0.0081308620572795587 -0.021866964770234622" name="0/2/3/">
          <geom name="0/2/3/geom" class="0/2/3/" type="capsule" contype="1" conaffinity="1" condim="3" size="0.056042295563177247" rgba="0.32926052585921095 0.4502984485815571 0.37490744995057801 1" friction="0.59999999999999998 0.10000000000000001 0.10000000000000001" fromto="0 0 0 -0.11814346777078133 0.43670275637184064 -0.32497370348580917"/>
          <site name="0/2/3/end3" class="0/2/3/" size="0.0050000000000000001" pos="-0.11814346777078133 0.43670275637184064 -0.32497370348580917"/>
        </body>
      </body>
      <site name="0/attach4" class="0/" size="9.9999999999999995e-07 9.9999999999999995e-07 9.9999999999999995e-07" pos="-0.033679470079008983 -0.12956165529620373 -0.038318005205122956"/>
      <body pos="-0.033679470079008983 -0.12956165529620373 -0.038318005205122956" name="0/4/">
        <joint name="0/4/joint/" class="0/" type="hinge" axis="0 0 1" limited="true" range="-30.525451529041785 30.525451529041785"/>
        <geom name="0/4/geom" class="0/4/" type="capsule" contype="1" conaffinity="1" condim="3" size="0.056720336215605627" rgba="0.53147930280002076 0.22217499006717389 0.68264624026404852 1" friction="0.59999999999999998 0.10000000000000001 0.10000000000000001" fromto="0 0 0 0.18251353979710716 -0.27277866789652561 0.31972113877223496"/>
        <site name="0/4/end4" class="0/4/" size="0.0050000000000000001" pos="0.18251353979710716 -0.27277866789652561 0.31972113877223496"/>
      </body>
      <camera name="0/iso" class="0/" mode="trackcom" pos="-2.2999999999999998 -2.2999999999999998 1" xyaxes="0.45000000000000001 -0.45000000000000001 0 0.29999999999999999 0.14999999999999999 0.93999999999999995"/>
    </body>
  </worldbody>
  <actuator>
    <motor name="0/1/motor" class="0/1/" ctrllimited="true" ctrlrange="-1 1" gear="62" joint="0/1/joint/"/>
    <motor name="0/2/motor" class="0/2/" ctrllimited="true" ctrlrange="-1 1" gear="52" joint="0/2/joint/"/>
    <motor name="0/4/motor" class="0/4/" ctrllimited="true" ctrlrange="-1 1" gear="94" joint="0/4/joint/"/>
  </actuator>
  <sensor>
    <subtreelinvel name="velocity" body="0/"/>
  </sensor>
</mujoco>
