<mujoco model="morphology">
  <option timestep="0.01"/>
  <default>
    <default class="/"/>
    <default class="0/"/>
    <default class="0/1/"/>
    <default class="0/1/2/"/>
    <default class="0/1/2/3/"/>
  </default>
  <asset>
    <texture name="texplane" type="2d" builtin="checker" rgb1="0.10000000000000001 0.20000000000000001 0.29999999999999999" rgb2="0.20000000000000001 0.29999999999999999 0.40000000000000002" width="300" height="300"/>
    <material name="MatPlane" class="/" texture="texplane" texrepeat="20 20" specular="1" shininess="1" reflectance="0.5"/>
  </asset>
  <worldbody>
    <light name="//unnamed_light_0" class="/" directional="true" pos="0 0 1.5" dir="0 0 -1.3" cutoff="100" exponent="1" diffuse="1 1 1" specular="0.10000000000000001 0.10000000000000001 0.10000000000000001"/>
    <geom name="ground" class="/" type="plane" size="15 15 0.5" material="MatPlane" rgba="1 1 1 1"/>
    <site name="body" class="/" size="9.9999999999999995e-07 9.9999999999999995e-07 9.9999999999999995e-07" pos="0 0 0.10000000000000001"/>
    <body pos="0 0 0.10000000000000001" name="0/">
      <freejoint name="0/"/>
      <geom name="0/geom" class="0/" type="capsule" contype="1" conaffinity="1" condim="3" size="0.04330588429200264" rgba="0.11428905564997627 0.77705033762087794 0.22129669858057777 1" friction="0.59999999999999998 0.10000000000000001 0.10000000000000001" fromto="0 0 0 0.56804046434715971 -0.15525629075038339 0.056431156890714096"/>
      <site name="0/end0" class="0/" size="0.0050000000000000001" pos="0.56804046434715971 -0.15525629075038339 0.056431156890714096"/>
      <site name="0/attach1" class="0/" size="9.9999999999999995e-07 9.9999999999999995e-07 9.9999999999999995e-07" pos="0.27007561509406897 -0.07381681562038718 0.026830270666096646"/>
      <body pos="0.27007561509406897 -0.07381681562038718 0.026830270666096646" name="0/1/">
        <joint name="0/1/joint/" class="0/" type="hinge" axis="0 0 1" limited="true" range="-35.345136538323111 35.345136538323111"/>
        <geom name="0/1/geom" class="0/1/" type="capsule" contype="1" conaffinity="1" condim="3" size="0.061263203988540432" rgba="0.32167793142094481 0.94745366611484405 0.75366166221370667 1" friction="0.59999999999999998 0.10000000000000001 0.10000000000000001" fromto="0 0 0 -0.10278899473126135 -0.26397379838807827 0.31269282569807011"/>
        <site name="0/1/end1" class="0/1/" size="0.0050000000000000001" pos="-0.10278899473126135 -0.26397379838807827 0.31269282569807011"/>
        <site name="0/1/attach2" class="0/1/" size="9.9999999999999995e-07 9.9999999999999995e-07 9.9999999999999995e-07" pos="-0.078832980704320918 -0.20245203690512162 0.23981660253691103"/>
        <body pos="-0.078832980704320918 -0.20245203690512162 0.23981660253691103" name="0/1/2/">
          <joint name="0/1/2/joint/" class="0/1/" type="hinge" axis="1.6653345369377348e-16 0.76412377037099932 0.64506965790835946" limited="true" range="-55.416223317389139 55.416223317389139"/>
          <geom name="0/1/2/geom" class="0/1/2/" type="capsule" contype="1" conaffinity="1" condim="3" size="0.060716048327253684" rgba="0.83239444513676342 0.44699551408965987 0.85251666871702525 1" friction="0.59999999999999998 0.10000000000000001 0.10000000000000001" fromto="0 0 0 -0.19330800560490924 0.32451195160748059 0.19085307118399131"/>
          <site name="0/1/2/end2" class="0/1/2/" size="0.0050000000000000001" pos="-0.19330800560490924 0.32451195160748059 0.19085307118399131"/>
          <site name="0/1/2/attach3" class="0/1/2/" size="9.9999999999999995e-07 9.9999999999999995e-07 9.9999999999999995e-07" pos="-0.062871488085494795 0.10554425428603273 0.062073045311681951"/>
          <body pos="-0.062871488085494795 0.10554425428603273 0.062073045311681951" name="0/1/2/3/">
            <joint name="0/1/2/3/joint/" class="0/1/2/" type="hinge" axis="-2.7755575615628914e-17 -0.50694846685095063 0.86197636392042098" limited="true" range="-55.968982673138129 55.968982673138129"/>
            <geom name="0/1/2/3/geom" class="0/1/2/3/" type="capsule" contype="1" conaffinity="1" condim="3" size="0.036722090734552876" rgba="0.94502785237631026 0.25837738026075363 0.51575337666639798 1" friction="0.59999999999999998 0.10000000000000001 0.10000000000000001" fromto="0 0 0 -0.72149162807518641 -0.12101001481717821 0.70341210593680126"/>
            <site name="0/1/2/3/end3" class="0/1/2/3/" size="0.0050000000000000001" pos="-0.72149162807518641 -0.12101001481717821 0.70341210593680126"/>
          </body>
        </body>
      </body>
      <camera name="0/iso" class="0/" mode="trackcom" pos="-2.2999999999999998 -2.2999999999999998 1" xyaxes="0.45000000000000001 -0.45000000000000001 0 0.29999999999999999 0.14999999999999999 0.93999999999999995"/>
    </body>
  </worldbody>
  <actuator>
    <motor name="0/1/motor" class="0/1/" ctrllimited="true" ctrlrange="-1 1" gear="85" joint="0/1/joint/"/>
    <motor name="0/1/2/motor" class="0/1/2/" ctrllimited="true" ctrlrange="-1 1" gear="69" joint="0/1/2/joint/"/>
    <motor name="0/1/2/3/motor" class="0/1/2/3/" ctrllimited="true" ctrlrange="-1 1" gear="63" joint="0/1/2/3/joint/"/>
  </actuator>
  <sensor>
    <subtreelinvel name="velocity" body="0/"/>
  </sensor>
</mujoco>
