<mujoco model="morphology">
  <option timestep="0.01"/>
  <default>
    <default class="/"/>
    <default class="0/"/>
    <default class="0/1/"/>
    <default class="0/1/2/"/>
    <default class="0/3/"/>
    <default class="0/3/4/"/>
    <default class="0/3/4/5/"/>
    <default class="0/3/4/6/"/>
    <default class="0/3/4/6/7/"/>
    <default class="0/3/4/6/7/8/"/>
    <default class="0/3/4/6/7/9/"/>
    <default class="0/3/4/6/7/9/10/"/>
  </default>
  <asset>
    <texture name="texplane" type="2d" builtin="checker" rgb1="0.10000000000000001 0.20000000000000001 0.29999999999999999" rgb2="0.20000000000000001 0.29999999999999999 0.40000000000000002" width="300" height="300"/>
    <material name="MatPlane" class="/" texture="texplane" texrepeat="20 20" specular="1" shininess="1" reflectance="0.5"/>
  </asset>
  <worldbody>
    <light name="//unnamed_light_0" class="/" directional="true" pos="0 0 1.5" dir="0 0 -1.3" cutoff="100" exponent="1" diffuse="1 1 1" specular="0.10000000000000001 0.10000000000000001 0.10000000000000001"/>
    <geom name="ground" class="/" type="plane" size="15 15 0.5" material="MatPlane" rgba="1 1 1 1"/>
    <site name="body" class="/" size="9.9999999999999995e-07 9.9999999999999995e-07 9.9999999999999995e-07" pos="0 0 0.91204539537429807"/>
    <body pos="0 0 0.91204539537429807" name="0/">
      <freejoint name="0/"/>
      <geom name="0/geom" class="0/" type="capsule" contype="1" conaffinity="1" condim="3" size="0.041357081089917716" rgba="0.85040811948444961 0.95907806507310089 0.30001002924702902 1" friction="0.59999999999999998 0.10000000000000001 0.10000000000000001" fromto="0 0 0 -0.17867525286782038 0.55335753308451929 0.20481021491017137"/>
      <site name="0/end0" class="0/" size="0.0050000000000000001" pos="-0.17867525286782038 0.55335753308451929 0.20481021491017137"/>
      <site name="0/attach1" class="0/" size="9.9999999999999995e-07 9.9999999999999995e-07 9.9999999999999995e-07" pos="-0.055975535708839057 0.17335632022774733 0.064163118922352144"/>
      <body pos="-0.055975535708839057 0.17335632022774733 0.064163118922352144" name="0/1/">
        <joint name="0/1/joint/" class="0/" type="hinge" axis="0 0 1" limited="true" range="-48.033349638348071 48.033349638348071"/>
        <geom name="0/1/geom" class="0/1/" type="capsule" contype="1" conaffinity="1" condim="3" size="0.035169915095539094" rgba="0.87991329984864641 0.40991515830852043 0.45509919121219344 1" friction="0.59999999999999998 0.10000000000000001 0.10000000000000001" fromto="0 0 0 0.028080034974832246 -0.32964896909889935 0.31143245702787592"/>
        <site name="0/1/end1" class="0/1/" size="0.0050000000000000001" pos="0.028080034974832246 -0.32964896909889935 0.31143245702787592"/>
        <site name="0/1/attach2" class="0/1/" size="9.9999999999999995e-07 9.9999999999999995e-07 9.9999999999999995e-07" pos="0.0080176457152874147 -0.094124122246058331 0.088922791831597375"/>
        <body pos="0.0080176457152874147 -0.094124122246058331 0.088922791831597375" name="0/1/2/">
          <geom name="0/1/2/geom" class="0/1/2/" type="capsule" contype="1" conaffinity="1" condim="3" size="0.052245122194362753" rgba="0.4840155061734388 0.62952195735678007 0.43619508679391539 1" friction="0.59999999999999998 0.10000000000000001 0.10000000000000001" fromto="0 0 0 0.4395711259212427 0.28072428104010738 -0.05545130789201913"/>
          <site name="0/1/2/end2" class="0/1/2/" size="0.0050000000000000001" pos="0.4395711259212427 0.28072428104010738 -0.05545130789201913"/>
        </body>
      </body>
      <site name="0/attach3" class="0/" size="9.9999999999999995e-07 9.9999999999999995e-07 9.9999999999999995e-07" pos="-0.14192539121032827 0.43954315497905694 0.1626849236726762"/>
      <body pos="-0.14192539121032827 0.43954315497905694 0.1626849236726762" name="0/3/">
        <joint name="0/3/joint/" class="0/" type="hinge" axis="0 0 1" limited="true" range="-53.276098303508036 53.276098303508036"/>
        <geom name="0/3/geom" class="0/3/" type="capsule" contype="1" conaffinity="1" condim="3" size="0.038726292444042604" rgba="0.9303088365671357 0.16535007738151797 0.017070234358923631 1" friction="0.59999999999999998 0.10000000000000001 0.10000000000000001" fromto="0 0 0 -0.43284950251247395 0.003936037289012817 -0.35740906455219262"/>
        <site name="0/3/end3" class="0/3/" size="0.0050000000000000001" pos="-0.43284950251247395 0.003936037289012817 -0.35740906455219262"/>
        <site name="0/3/attach4" class="0/3/" size="9.9999999999999995e-07 9.9999999999999995e-07 9.9999999999999995e-07" pos="-0.13519473413035887 0.0012293684334312737 -0.11163192559409597"/>
        <body pos="-0.13519473413035887 0.0012293684334312737 -0.11163192559409597" name="0/3/4/">
          <joint name="0/3/4/joint/" class="0/3/" type="hinge" axis="-5.5511151231257827e-17 0.99993936578128095 0.011012028011651694" limited="true" range="-33.359213544744108 33.359213544744108"/>
          <geom name="0/3/4/geom" class="0/3/4/" type="capsule" contype="1" conaffinity="1" condim="3" size="0.045133070672887417" rgba="0.87746159537577462 0.021525170823124329 0.47884571103211504 1" friction="0.59999999999999998 0.10000000000000001 0.10000000000000001" fromto="0 0 0 -0.069808445709903411 0.33298986972814171 0.27100684038513734"/>
          <site name="0/3/4/end4" class="0/3/4/" size="0.0050000000000000001" pos="-0.069808445709903411 0.33298986972814171 0.27100684038513734"/>
          <site name="0/3/4/attach5" class="0/3/4/" size="9.9999999999999995e-07 9.9999999999999995e-07 9.9999999999999995e-07" pos="-0.026174312426907768 0.12485281396292754 0.10161260056622917"/>
          <body pos="-0.026174312426907768 0.12485281396292754 0.10161260056622917" name="0/3/4/5/">
            <joint name="0/3/4/5/joint/" class="0/3/4/" type="hinge" axis="-0.98703751324507916 -0.12447547325613822 -0.10130549839288328" limited="true" range="-66.521047106373629 66.521047106373629"/>
            <geom name="0/3/4/5/geom" class="0/3/4/5/" type="capsule" contype="1" conaffinity="1" condim="3" size="0.045968494326471321" rgba="0.89399319704462754 0.28742224592357413 0.92852730583826493 1" friction="0.59999999999999998 0.10000000000000001 0.10000000000000001" fromto="0 0 0 0.65574453372879171 0.0080107998574684425 0.66353970956505925"/>
            <site name="0/3/4/5/end5" class="0/3/4/5/" size="0.0050000000000000001" pos="0.65574453372879171 0.0080107998574684425 0.66353970956505925"/>
          </body>
          <site name="0/3/4/attach6" class="0/3/4/" size="9.9999999999999995e-07 9.9999999999999995e-07 9.9999999999999995e-07" pos="-0.044173075714200663 0.21070783882925348 0.17148649504598074"/>
          <body pos="-0.044173075714200663 0.21070783882925348 0.17148649504598074" name="0/3/4/6/">
            <joint name="0/3/4/6/joint/" class="0/3/4/" type="hinge" axis="-0.98703751324507916 -0.12447547325613822 -0.10130549839288328" limited="true" range="-61.90073697147497 61.90073697147497"/>
            <geom name="0/3/4/6/geom" class="0/3/4/6/" type="capsule" contype="1" conaffinity="1" condim="3" size="0.061997984262840249" rgba="0.37242339626540044 0.057091497054942764 0.75300514585689715 1" friction="0.59999999999999998 0.10000000000000001 0.10000000000000001" fromto="0 0 0 0.43368376565952182 0.048085949099425873 -0.62150908824417184"/>
            <site name="0/3/4/6/end6" class="0/3/4/6/" size="0.0050000000000000001" pos="0.43368376565952182 0.048085949099425873 -0.62150908824417184"/>
            <site name="0/3/4/6/attach7" class="0/3/4/6/" size="9.9999999999999995e-07 9.9999999999999995e-07 9.9999999999999995e-07" pos="0.29389883808424505 0.0325868886214997 -0.42118431298893649"/>
            <body pos="0.29389883808424505 0.0325868886214997 -0.42118431298893649" name="0/3/4/6/7/">
              <joint name="0/3/4/6/7/joint/" class="0/3/4/6/" type="hinge" axis="-1.1102230246251565e-16 0.997020338258095 0.077139128201671181" limited="true" range="-69.832008044514083 69.832008044514083"/>
              <geom name="0/3/4/6/7/geom" class="0/3/4/6/7/" type="capsule" contype="1" conaffinity="1" condim="3" size="0.068171888092650568" rgba="0.064309854222842855 0.53094104739535208 0.24720933223370012 1" friction="0.59999999999999998 0.10000000000000001 0.10000000000000001" fromto="0 0 0 -0.6974306628235164 0.59184325557346096 0.36510368053745723"/>
              <site name="0/3/4/6/7/end7" class="0/3/4/6/7/" size="0.0050000000000000001" pos="-0.6974306628235164 0.59184325557346096 0.36510368053745723"/>
              <site name="0/3/4/6/7/attach8" class="0/3/4/6/7/" size="9.9999999999999995e-07 9.9999999999999995e-07 9.9999999999999995e-07" pos="-0.22014128905767147 0.18681303267418864 0.11524356349321382"/>
              <body pos="-0.22014128905767147 0.18681303267418864 0.11524356349321382" name="0/3/4/6/7/8/">
                <joint name="0/3/4/6/7/8/joint/" class="0/3/4/6/7/" type="hinge" axis="-0.70607437117100369 -0.60268534693967557 -0.37179208566035205" limited="true" range="-49.835592488141344 49.835592488141344"/>
                <geom name="0/3/4/6/7/8/geom" class="0/3/4/6/7/8/" type="capsule" contype="1" conaffinity="1" condim="3" size="0.044283131967820855" rgba="0.46795102049891313 0.68082507992642316 0.82230668813975316 1" friction="0.59999999999999998 0.10000000000000001 0.10000000000000001" fromto="0 0 0 -0.51411091669390396 -0.56135925444111423 -0.72864416521258502"/>
                <site name="0/3/4/6/7/8/end8" class="0/3/4/6/7/8/" size="0.0050000000000000001" pos="-0.51411091669390396 -0.56135925444111423 -0.72864416521258502"/>
              </body>
              <site name="0/3/4/6/7/attach9" class="0/3/4/6/7/" size="9.9999999999999995e-07 9.9999999999999995e-07 9.9999999999999995e-07" pos="-0.49674430990617635 0.42153978199386749 0.26004474064639438"/>
              <body pos="-0.49674430990617635 0.42153978199386749 0.26004474064639438" name="0/3/4/6/7/9/">
                <joint name="0/3/4/6/7/9/joint/" class="0/3/4/6/7/" type="hinge" axis="-0.70607437117100369 -0.60268534693967557 -0.37179208566035205" limited="true" range="-42.816077134342777 42.816077134342777"/>
                <geom name="0/3/4/6/7/9/geom" class="0/3/4/6/7/9/" type="capsule" contype="1" conaffinity="1" condim="3" size="0.067558063879591734" rgba="0.43064847212375934 0.60920290429642765 0.48334107182564301 1" friction="0.59999999999999998 0.10000000000000001 0.10000000000000001" fromto="0 0 0 0.43554289779221955 0.52556780959482774 -0.43324391687247621"/>
                <site name="0/3/4/6/7/9/end9" class="0/3/4/6/7/9/" size="0.0050000000000000001" pos="0.43554289779221955 0.52556780959482774 -0.43324391687247621"/>
                <site name="0/3/4/6/7/9/attach10" class="0/3/4/6/7/9/" size="9.9999999999999995e-07 9.9999999999999995e-07 9.9999999999999995e-07" pos="0.29436383141596961 0.35520761533583195 -0.29281005373914776"/>
                <body pos="0.29436383141596961 0.35520761533583195 -0.29281005373914776" name="0/3/4/6/7/9/10/">
                  <joint name="0/3/4/6/7/9/10/joint/" class="0/3/4/6/7/9/" type="hinge" axis="-0.84248062134770485 0.41569501816695237 -0.34267193425310211" limited="true" range="-35.054454171621401 35.054454171621401"/>
                  <geom name="0/3/4/6/7/9/10/geom" class="0/3/4/6/7/9/10/" type="capsule" contype="1" conaffinity="1" condim="3" size="0.054801412860034274" rgba="0.53510041271464914 0.34753222847768583 0.65019780175667918 1" friction="0.59999999999999998 0.10000000000000001 0.10000000000000001" fromto="0 0 0 0.47286538618123841 -0.74961637257615199 -0.1336294685083641"/>
                  <site name="0/3/4/6/7/9/10/end10" class="0/3/4/6/7/9/10/" size="0.0050000000000000001" pos="0.47286538618123841 -0.74961637257615199 -0.1336294685083641"/>
                </body>
              </body>
            </body>
          </body>
        </body>
      </body>
      <camera name="0/iso" class="0/" mode="trackcom" pos="-2.2999999999999998 -2.2999999999999998 1" xyaxes="0.45000000000000001 -0.45000000000000001 0 0.29999999999999999 0.14999999999999999 0.93999999999999995"/>
    </body>
  </worldbody>
  <actuator>
    <motor name="0/1/motor" class="0/1/" ctrllimited="true" ctrlrange="-1 1" gear="64" joint="0/1/joint/"/>
    <motor name="0/3/motor" class="0/3/" ctrllimited="true" ctrlrange="-1 1" gear="93" joint="0/3/joint/"/>
    <motor name="0/3/4/motor" class="0/3/4/" ctrllimited="true" ctrlrange="-1 1" gear="78" joint="0/3/4/joint/"/>
    <motor name="0/3/4/5/motor" class="0/3/4/5/" ctrllimited="true" ctrlrange="-1 1" gear="95" joint="0/3/4/5/joint/"/>
    <motor name="0/3/4/6/motor" class="0/3/4/6/" ctrllimited="true" ctrlrange="-1 1" gear="93" joint="0/3/4/6/joint/"/>
    <motor name="0/3/4/6/7/motor" class="0/3/4/6/7/" ctrllimited="true" ctrlrange="-1 1" gear="67" joint="0/3/4/6/7/joint/"/>
    <motor name="0/3/4/6/7/8/motor" class="0/3/4/6/7/8/" ctrllimited="true" ctrlrange="-1 1" gear="83" joint="0/3/4/6/7/8/joint/"/>
    <motor name="0/3/4/6/7/9/motor" class="0/3/4/6/7/9/" ctrllimited="true" ctrlrange="-1 1" gear="57" joint="0/3/4/6/7/9/joint/"/>
    <motor name="0/3/4/6/7/9/10/motor" class="0/3/4/6/7/9/10/" ctrllimited="true" ctrlrange="-1 1" gear="81" joint="0/3/4/6/7/9/10/joint/"/>
  </actuator>
  <sensor>
    <subtreelinvel name="velocity" body="0/"/>
  </sensor>
</mujoco>
