<mujoco model="morphology">
  <option timestep="0.01"/>
  <default>
    <default class="/"/>
    <default class="0/"/>
    <default class="0/1/"/>
    <default class="0/1/2/"/>
    <default class="0/1/2/3/"/>
    <default class="0/1/2/4/"/>
  </default>
  <asset>
    <texture name="texplane" type="2d" builtin="checker" rgb1="0.10000000000000001 0.20000000000000001 0.29999999999999999" rgb2="0.20000000000000001 0.29999999999999999 0.40000000000000002" width="300" height="300"/>
    <material name="MatPlane" class="/" texture="texplane" texrepeat="20 20" specular="1" shininess="1" reflectance="0.5"/>
  </asset>
  <worldbody>
    <light name="//unnamed_light_0" class="/" directional="true" pos="0 0 1.5" dir="0 0 -1.3" cutoff="100" exponent="1" diffuse="1 1 1" specular="0.10000000000000001 0.10000000000000001 0.10000000000000001"/>
    <geom name="ground" class="/" type="plane" size="15 15 0.5" material="MatPlane" rgba="1 1 1 1"/>
    <site name="body" class="/" size="9.9999999999999995e-07 9.9999999999999995e-07 9.9999999999999995e-07" pos="0 0 0.63740447759628294"/>
    <body pos="0 0 0.63740447759628294" name="0/">
      <freejoint name="0/"/>
      <geom name="0/geom" class="0/" type="capsule" contype="1" conaffinity="1" condim="3" size="0.066940035385578384" rgba="0.18295940248163589 0.78629385805449015 0.04518887498872981 1" friction="0.59999999999999998 0.10000000000000001 0.10000000000000001" fromto="0 0 0 0.38911594732202492 -0.60193040110446483 0.072690725287960611"/>
      <site name="0/end0" class="0/" size="0.0050000000000000001" pos="0.38911594732202492 -0.60193040110446483 0.072690725287960611"/>
      <site name="0/attach1" class="0/" size="9.9999999999999995e-07 9.9999999999999995e-07 9.9999999999999995e-07" pos="0.32415600286603885 -0.50144270407940328 0.060555562209528777"/>
      <body pos="0.32415600286603885 -0.50144270407940328 0.060555562209528777" name="0/1/">
        <geom name="0/1/geom" class="0/1/" type="capsule" contype="1" conaffinity="1" condim="3" size="0.056833393159811216" rgba="0.45765088950171162 0.59437888705679753 0.075772124908265348 1" friction="0.59999999999999998 0.10000000000000001 0.10000000000000001" fromto="0 0 0 -0.31927811688564089 -0.52689643511817352 -0.59796001138442878"/>
        <site name="0/1/end1" class="0/1/" size="0.0050000000000000001" pos="-0.31927811688564089 -0.52689643511817352 -0.59796001138442878"/>
        <site name="0/1/attach2" class="0/1/" size="9.9999999999999995e-07 9.9999999999999995e-07 9.9999999999999995e-07" pos="-0.018821005924840033 -0.03105982027164176 -0.035248920367175626"/>
        <body pos="-0.018821005924840033 -0.03105982027164176 -0.035248920367175626" name="0/1/2/">
          <joint name="0/1/2/joint/" class="0/1/" type="hinge" axis="-1.1102230246251565e-16 -0.75028297488036522 0.66111682598816812" limited="true" range="-69.943050882198065 69.943050882198065"/>
          <geom name="0/1/2/geom" class="0/1/2/" type="capsule" contype="1" conaffinity="1" condim="3" size="0.053663761552241257" rgba="0.57061766330046837 0.47878538322192654 0.95011221425135772 1" friction="0.59999999999999998 0.10000000000000001 0.10000000000000001" fromto="0 0 0 -0.47835869207426979 -0.50005319227406531 0.2366482780507404"/>
          <site name="0/1/2/end2" class="0/1/2/" size="0.0050000000000000001" pos="-0.47835869207426979 -0.50005319227406531 0.2366482780507404"/>
          <site name="0/1/2/attach3" class="0/1/2/" size="9.9999999999999995e-07 9.9999999999999995e-07 9.9999999999999995e-07" pos="-0.34015348881826163 -0.35558011334374046 0.16827694099743776"/>
          <body pos="-0.34015348881826163 -0.35558011334374046 0.16827694099743776" name="0/1/2/3/">
            <joint name="0/1/2/3/joint/" class="0/1/2/" type="hinge" axis="0.75643378070781442 -0.59120820823325604 0.27978704387749148" limited="true" range="-60.759061335397398 60.759061335397398"/>
            <geom name="0/1/2/3/geom" class="0/1/2/3/" type="capsule" contype="1" conaffinity="1" condim="3" size="0.055662850751110257" rgba="0.061152742468714716 0.22802673533128692 0.94823918525899809 1" friction="0.59999999999999998 0.10000000000000001 0.10000000000000001" fromto="0 0 0 -0.1544519049338543 -0.50489109339782789 -0.31659072734898924"/>
            <site name="0/1/2/3/end3" class="0/1/2/3/" size="0.0050000000000000001" pos="-0.1544519049338543 -0.50489109339782789 -0.31659072734898924"/>
          </body>
          <site name="0/1/2/attach4" class="0/1/2/" size="9.9999999999999995e-07 9.9999999999999995e-07 9.9999999999999995e-07" pos="-0.13407827534725927 -0.14015898678723815 0.066329709296921585"/>
          <body pos="-0.13407827534725927 -0.14015898678723815 0.066329709296921585" name="0/1/2/4/">
            <joint name="0/1/2/4/joint/" class="0/1/2/" type="hinge" axis="0.75643378070781442 -0.59120820823325604 0.27978704387749148" limited="true" range="-48.518903931756881 48.518903931756881"/>
            <geom name="0/1/2/4/geom" class="0/1/2/4/" type="capsule" contype="1" conaffinity="1" condim="3" size="0.039247731975921026" rgba="0.045801742172864923 0.75544132584735191 0.16596425806382553 1" friction="0.59999999999999998 0.10000000000000001 0.10000000000000001" fromto="0 0 0 0.37436261976652063 -0.47527045575302324 -0.016159482445258"/>
            <site name="0/1/2/4/end4" class="0/1/2/4/" size="0.0050000000000000001" pos="0.37436261976652063 -0.47527045575302324 -0.016159482445258"/>
          </body>
        </body>
      </body>
      <camera name="0/iso" class="0/" mode="trackcom" pos="-2.2999999999999998 -2.2999999999999998 1" xyaxes="0.45000000000000001 -0.45000000000000001 0 0.29999999999999999 0.14999999999999999 0.93999999999999995"/>
    </body>
  </worldbody>
  <actuator>
    <motor name="0/1/2/motor" class="0/1/2/" ctrllimited="true" ctrlrange="-1 1" gear="75" joint="0/1/2/joint/"/>
    <motor name="0/1/2/3/motor" class="0/1/2/3/" ctrllimited="true" ctrlrange="-1 1" gear="53" joint="0/1/2/3/joint/"/>
    <motor name="0/1/2/4/motor" class="0/1/2/4/" ctrllimited="true" ctrlrange="-1 1" gear="51" joint="0/1/2/4/joint/"/>
  </actuator>
  <sensor>
    <subtreelinvel name="velocity" body="0/"/>
  </sensor>
</mujoco>
