<mujoco model="morphology">
  <option timestep="0.01"/>
  <default>
    <default class="/"/>
    <default class="0/"/>
    <default class="0/1/"/>
    <default class="0/1/2/"/>
    <default class="0/1/2/3/"/>
  </default>
  <asset>
    <texture name="texplane" type="2d" builtin="checker" rgb1="0.10000000000000001 0.20000000000000001 0.29999999999999999" rgb2="0.20000000000000001 0.29999999999999999 0.40000000000000002" width="300" height="300"/>
    <material name="MatPlane" class="/" texture="texplane" texrepeat="20 20" specular="1" shininess="1" reflectance="0.5"/>
  </asset>
  <worldbody>
    <light name="//unnamed_light_0" class="/" directional="true" pos="0 0 1.5" dir="0 0 -1.3" cutoff="100" exponent="1" diffuse="1 1 1" specular="0.10000000000000001 0.10000000000000001 0.10000000000000001"/>
    <geom name="ground" class="/" type="plane" size="15 15 0.5" material="MatPlane" rgba="1 1 1 1"/>
    <site name="body" class="/" size="9.9999999999999995e-07 9.9999999999999995e-07 9.9999999999999995e-07" pos="0 0 0.75765058994293211"/>
    <body pos="0 0 0.75765058994293211" name="0/">
      <freejoint name="0/"/>
      <geom name="0/geom" class="0/" type="capsule" contype="1" conaffinity="1" condim="3" size="0.045413639742487244" rgba="0.18172566311763383 0.96494637753085433 0.72995954054239209 1" friction="0.59999999999999998 0.10000000000000001 0.10000000000000001" fromto="0 0 0 -0.47424853888240098 0.64208283548945921 -0.16822888507542455"/>
      <site name="0/end0" class="0/" size="0.0050000000000000001" pos="-0.47424853888240098 0.64208283548945921 -0.16822888507542455"/>
      <site name="0/attach1" class="0/" size="9.9999999999999995e-07 9.9999999999999995e-07 9.9999999999999995e-07" pos="-0.11607801827967221 0.15715747546771205 -0.041176037448575606"/>
      <body pos="-0.11607801827967221 0.15715747546771205 -0.041176037448575606" name="0/1/">
        <joint name="0/1/joint/" class="0/" type="hinge" axis="0 0 1" limited="true" range="-68.943465632911625 68.943465632911625"/>
        <geom name="0/1/geom" class="0/1/" type="capsule" contype="1" conaffinity="1" condim="3" size="0.036961029840099913" rgba="0.88949083185568589 0.221609389270918 0.12785406047664338 1" friction="0.59999999999999998 0.10000000000000001 0.10000000000000001" fromto="0 0 0 0.54956132000619817 0.26039162485009304 -0.61647456348960228"/>
        <site name="0/1/end1" class="0/1/" size="0.0050000000000000001" pos="0.54956132000619817 0.26039162485009304 -0.61647456348960228"/>
        <site name="0/1/attach2" class="0/1/" size="9.9999999999999995e-07 9.9999999999999995e-07 9.9999999999999995e-07" pos="0.03909633087373722 0.018524515374871132 -0.043856604589930716"/>
        <body pos="0.03909633087373722 0.018524515374871132 -0.043856604589930716" name="0/1/2/">
          <joint name="0/1/2/joint/" class="0/1/" type="hinge" axis="-0.77281037526167184 0.24693843335621074 -0.58462426738846018" limited="true" range="-30.358776635559479 30.358776635559479"/>
          <geom name="0/1/2/geom" class="0/1/2/" type="capsule" contype="1" conaffinity="1" condim="3" size="0.050794721353513553" rgba="0.71495295766486777 0.74580119791053034 0.53855344626903667 1" friction="0.59999999999999998 0.10000000000000001 0.10000000000000001" fromto="0 0 0 0.65824696098232849 -0.07237654111213998 0.3808147055118507"/>
          <site name="0/1/2/end2" class="0/1/2/" size="0.0050000000000000001" pos="0.65824696098232849 -0.07237654111213998 0.3808147055118507"/>
          <site name="0/1/2/attach3" class="0/1/2/" size="9.9999999999999995e-07 9.9999999999999995e-07 9.9999999999999995e-07" pos="0.48161379018177314 -0.052955110090057003 0.27862736108164421"/>
          <body pos="0.48161379018177314 -0.052955110090057003 0.27862736108164421" name="0/1/2/3/">
            <joint name="0/1/2/3/joint/" class="0/1/2/" type="hinge" axis="5.5511151231257827e-17 0.98241416214937727 0.18671479322307882" limited="true" range="-69.088117002099722 69.088117002099722"/>
            <geom name="0/1/2/3/geom" class="0/1/2/3/" type="capsule" contype="1" conaffinity="1" condim="3" size="0.053795333476645515" rgba="0.87602804433332393 0.38184013628611824 0.21836890510636808 1" friction="0.59999999999999998 0.10000000000000001 0.10000000000000001" fromto="0 0 0 0.46302296328616821 0.29537934293731571 -0.018780181121449857"/>
            <site name="0/1/2/3/end3" class="0/1/2/3/" size="0.0050000000000000001" pos="0.46302296328616821 0.29537934293731571 -0.018780181121449857"/>
          </body>
        </body>
      </body>
      <camera name="0/iso" class="0/" mode="trackcom" pos="-2.2999999999999998 -2.2999999999999998 1" xyaxes="0.45000000000000001 -0.45000000000000001 0 0.29999999999999999 0.14999999999999999 0.93999999999999995"/>
    </body>
  </worldbody>
  <actuator>
    <motor name="0/1/motor" class="0/1/" ctrllimited="true" ctrlrange="-1 1" gear="53" joint="0/1/joint/"/>
    <motor name="0/1/2/motor" class="0/1/2/" ctrllimited="true" ctrlrange="-1 1" gear="94" joint="0/1/2/joint/"/>
    <motor name="0/1/2/3/motor" class="0/1/2/3/" ctrllimited="true" ctrlrange="-1 1" gear="52" joint="0/1/2/3/joint/"/>
  </actuator>
  <sensor>
    <subtreelinvel name="velocity" body="0/"/>
  </sensor>
</mujoco>
