<mujoco model="morphology">
  <option timestep="0.01"/>
  <default>
    <default class="/"/>
    <default class="0/"/>
    <default class="0/1/"/>
    <default class="0/1/2/"/>
    <default class="0/1/2/3/"/>
    <default class="0/1/2/3/4/"/>
    <default class="0/1/2/3/4/5/"/>
    <default class="0/1/2/3/4/5/6/"/>
    <default class="0/1/2/3/4/5/6/7/"/>
    <default class="0/1/2/3/4/5/6/8/"/>
    <default class="0/1/2/3/4/5/9/"/>
  </default>
  <asset>
    <texture name="texplane" type="2d" builtin="checker" rgb1="0.10000000000000001 0.20000000000000001 0.29999999999999999" rgb2="0.20000000000000001 0.29999999999999999 0.40000000000000002" width="300" height="300"/>
    <material name="MatPlane" class="/" texture="texplane" texrepeat="20 20" specular="1" shininess="1" reflectance="0.5"/>
  </asset>
  <worldbody>
    <light name="//unnamed_light_0" class="/" directional="true" pos="0 0 1.5" dir="0 0 -1.3" cutoff="100" exponent="1" diffuse="1 1 1" specular="0.10000000000000001 0.10000000000000001 0.10000000000000001"/>
    <geom name="ground" class="/" type="plane" size="15 15 0.5" material="MatPlane" rgba="1 1 1 1"/>
    <site name="body" class="/" size="9.9999999999999995e-07 9.9999999999999995e-07 9.9999999999999995e-07" pos="0 0 0.70965955257415769"/>
    <body pos="0 0 0.70965955257415769" name="0/">
      <freejoint name="0/"/>
      <geom name="0/geom" class="0/" type="capsule" contype="1" conaffinity="1" condim="3" size="0.061392560212186136" rgba="0.23608506224037418 0.38253429358479663 0.82587264824765794 1" friction="0.59999999999999998 0.10000000000000001 0.10000000000000001" fromto="0 0 0 0.49279967721409501 0.244687779568455 -0.32545226121341764"/>
      <site name="0/end0" class="0/" size="0.0050000000000000001" pos="0.49279967721409501 0.244687779568455 -0.32545226121341764"/>
      <site name="0/attach1" class="0/" size="9.9999999999999995e-07 9.9999999999999995e-07 9.9999999999999995e-07" pos="0.33456317089795551 0.16611926346055006 -0.22095051097236476"/>
      <body pos="0.33456317089795551 0.16611926346055006 -0.22095051097236476" name="0/1/">
        <geom name="0/1/geom" class="0/1/" type="capsule" contype="1" conaffinity="1" condim="3" size="0.054069998461815344" rgba="0.21600676083168679 0.066787596390504467 0.44121601987426506 1" friction="0.59999999999999998 0.10000000000000001 0.10000000000000001" fromto="0 0 0 -0.3828283731632442 0.60817508110434648 0.57795843473918684"/>
        <site name="0/1/end1" class="0/1/" size="0.0050000000000000001" pos="-0.3828283731632442 0.60817508110434648 0.57795843473918684"/>
        <site name="0/1/attach2" class="0/1/" size="9.9999999999999995e-07 9.9999999999999995e-07 9.9999999999999995e-07" pos="-0.12975038091587623 0.20612617550994317 0.19588497697106691"/>
        <body pos="-0.12975038091587623 0.20612617550994317 0.19588497697106691" name="0/1/2/">
          <joint name="0/1/2/joint/" class="0/1/" type="hinge" axis="-0.90976629594173331 -0.30091488447744968 -0.28596419193385347" limited="true" range="-32.670075626152467 32.670075626152467"/>
          <geom name="0/1/2/geom" class="0/1/2/" type="capsule" contype="1" conaffinity="1" condim="3" size="0.053365249240765342" rgba="0.342370868200774 0.7377941506895066 0.68412590077024105 1" friction="0.59999999999999998 0.10000000000000001 0.10000000000000001" fromto="0 0 0 0.17088528028599848 0.43199753354820114 -0.58459401478354145"/>
          <site name="0/1/2/end2" class="0/1/2/" size="0.0050000000000000001" pos="0.17088528028599848 0.43199753354820114 -0.58459401478354145"/>
          <site name="0/1/2/attach3" class="0/1/2/" size="9.9999999999999995e-07 9.9999999999999995e-07 9.9999999999999995e-07" pos="0.12207215955612383 0.30859809431736535 -0.41760562248999394"/>
          <body pos="0.12207215955612383 0.30859809431736535 -0.41760562248999394" name="0/1/2/3/">
            <joint name="0/1/2/3/joint/" class="0/1/2/" type="hinge" axis="-0.97346138147785533 0.13600811730165713 -0.1840508918731017" limited="true" range="-63.988758339457839 63.988758339457839"/>
            <geom name="0/1/2/3/geom" class="0/1/2/3/" type="capsule" contype="1" conaffinity="1" condim="3" size="0.052682881385378848" rgba="0.54206085723028508 0.68630431983719331 0.56048178421692063 1" friction="0.59999999999999998 0.10000000000000001 0.10000000000000001" fromto="0 0 0 -0.43425410798078684 0.24653882795746496 0.5810043124160551"/>
            <site name="0/1/2/3/end3" class="0/1/2/3/" size="0.0050000000000000001" pos="-0.43425410798078684 0.24653882795746496 0.5810043124160551"/>
            <site name="0/1/2/3/attach4" class="0/1/2/3/" size="9.9999999999999995e-07 9.9999999999999995e-07 9.9999999999999995e-07" pos="-0.33059484591143923 0.18768841639464939 0.44231482813184053"/>
            <body pos="-0.33059484591143923 0.18768841639464939 0.44231482813184053" name="0/1/2/3/4/">
              <joint name="0/1/2/3/4/joint/" class="0/1/2/3/" type="hinge" axis="-5.5511151231257827e-17 -0.92055207200285638 0.39061986986230979" limited="true" range="-44.779769794823068 44.779769794823068"/>
              <geom name="0/1/2/3/4/geom" class="0/1/2/3/4/" type="capsule" contype="1" conaffinity="1" condim="3" size="0.062210407707558923" rgba="0.8715154724250691 0.82558020757944151 0.79999376326285487 1" friction="0.59999999999999998 0.10000000000000001 0.10000000000000001" fromto="0 0 0 0.47827615754252539 -0.67737527401808306 0.41124011407827998"/>
              <site name="0/1/2/3/4/end4" class="0/1/2/3/4/" size="0.0050000000000000001" pos="0.47827615754252539 -0.67737527401808306 0.41124011407827998"/>
              <site name="0/1/2/3/4/attach5" class="0/1/2/3/4/" size="9.9999999999999995e-07 9.9999999999999995e-07 9.9999999999999995e-07" pos="0.34237551724103438 -0.48490125662935218 0.29438755109864356"/>
              <body pos="0.34237551724103438 -0.48490125662935218 0.29438755109864356" name="0/1/2/3/4/5/">
                <joint name="0/1/2/3/4/5/joint/" class="0/1/2/3/4/" type="hinge" axis="0.85614861912563545 0.44170084436026258 -0.26816022460592182" limited="true" range="-52.660266858726096 52.660266858726096"/>
                <geom name="0/1/2/3/4/5/geom" class="0/1/2/3/4/5/" type="capsule" contype="1" conaffinity="1" condim="3" size="0.046222080782035949" rgba="0.50524621006476544 0.17984630030512927 0.3824171373901003 1" friction="0.59999999999999998 0.10000000000000001 0.10000000000000001" fromto="0 0 0 0.26596587338799083 0.0066285210457820432 -0.23799873808504024"/>
                <site name="0/1/2/3/4/5/end5" class="0/1/2/3/4/5/" size="0.0050000000000000001" pos="0.26596587338799083 0.0066285210457820432 -0.23799873808504024"/>
                <site name="0/1/2/3/4/5/attach6" class="0/1/2/3/4/5/" size="9.9999999999999995e-07 9.9999999999999995e-07 9.9999999999999995e-07" pos="0.13230416384037524 0.0032973438407309635 -0.11839197125666841"/>
                <body pos="0.13230416384037524 0.0032973438407309635 -0.11839197125666841" name="0/1/2/3/4/5/6/">
                  <joint name="0/1/2/3/4/5/6/joint/" class="0/1/2/3/4/5/" type="hinge" axis="5.5511151231257827e-17 0.9996123842561917 0.027840280919048499" limited="true" range="-60.554136896003691 60.554136896003691"/>
                  <geom name="0/1/2/3/4/5/6/geom" class="0/1/2/3/4/5/6/" type="capsule" contype="1" conaffinity="1" condim="3" size="0.051015910018135505" rgba="0.89776850789232565 0.97973575048513994 0.66606947527898408 1" friction="0.59999999999999998 0.10000000000000001 0.10000000000000001" fromto="0 0 0 -0.079420155026617145 0.73443923161026725 -0.46492836504321083"/>
                  <site name="0/1/2/3/4/5/6/end6" class="0/1/2/3/4/5/6/" size="0.0050000000000000001" pos="-0.079420155026617145 0.73443923161026725 -0.46492836504321083"/>
                  <site name="0/1/2/3/4/5/6/attach7" class="0/1/2/3/4/5/6/" size="9.9999999999999995e-07 9.9999999999999995e-07 9.9999999999999995e-07" pos="-0.0061592735787552606 0.056957986961148288 -0.036056602934920058"/>
                  <body pos="-0.0061592735787552606 0.056957986961148288 -0.036056602934920058" name="0/1/2/3/4/5/6/7/">
                    <joint name="0/1/2/3/4/5/6/7/joint/" class="0/1/2/3/4/5/6/" type="hinge" axis="-5.5511151231257827e-17 0.53487431746190139 0.84493163304474805" limited="true" range="-38.926828302376734 38.926828302376734"/>
                    <geom name="0/1/2/3/4/5/6/7/geom" class="0/1/2/3/4/5/6/7/" type="capsule" contype="1" conaffinity="1" condim="3" size="0.055349959634378346" rgba="0.66803390543872687 0.55413219655522494 0.56284061196359914 1" friction="0.59999999999999998 0.10000000000000001 0.10000000000000001" fromto="0 0 0 0.057782482128192036 -0.36132349664246605 -0.40205010506740063"/>
                    <site name="0/1/2/3/4/5/6/7/end7" class="0/1/2/3/4/5/6/7/" size="0.0050000000000000001" pos="0.057782482128192036 -0.36132349664246605 -0.40205010506740063"/>
                  </body>
                  <site name="0/1/2/3/4/5/6/attach8" class="0/1/2/3/4/5/6/" size="9.9999999999999995e-07 9.9999999999999995e-07 9.9999999999999995e-07" pos="-0.046523024578943126 0.43022245943102566 -0.27234741290928011"/>
                  <body pos="-0.046523024578943126 0.43022245943102566 -0.27234741290928011" name="0/1/2/3/4/5/6/8/">
                    <joint name="0/1/2/3/4/5/6/8/joint/" class="0/1/2/3/4/5/6/" type="hinge" axis="-0.99585185397671538 -0.076879887421235804 0.04866793442541581" limited="true" range="-44.98943936554037 44.98943936554037"/>
                    <geom name="0/1/2/3/4/5/6/8/geom" class="0/1/2/3/4/5/6/8/" type="capsule" contype="1" conaffinity="1" condim="3" size="0.044827006849531094" rgba="0.9940100894112599 0.49830540640086718 0.96752376023012066 1" friction="0.59999999999999998 0.10000000000000001 0.10000000000000001" fromto="0 0 0 -0.11472406122542012 0.055158442467519553 0.37382621168541075"/>
                    <site name="0/1/2/3/4/5/6/8/end8" class="0/1/2/3/4/5/6/8/" size="0.0050000000000000001" pos="-0.11472406122542012 0.055158442467519553 0.37382621168541075"/>
                  </body>
                </body>
                <site name="0/1/2/3/4/5/attach9" class="0/1/2/3/4/5/" size="9.9999999999999995e-07 9.9999999999999995e-07 9.9999999999999995e-07" pos="0.22485822850319209 0.0056040178424559342 -0.20121368937332904"/>
                <body pos="0.22485822850319209 0.0056040178424559342 -0.20121368937332904" name="0/1/2/3/4/5/9/">
                  <joint name="0/1/2/3/4/5/9/joint/" class="0/1/2/3/4/5/" type="hinge" axis="5.5511151231257827e-17 0.9996123842561917 0.027840280919048499" limited="true" range="-63.597292367986988 63.597292367986988"/>
                  <geom name="0/1/2/3/4/5/9/geom" class="0/1/2/3/4/5/9/" type="capsule" contype="1" conaffinity="1" condim="3" size="0.052270679621097826" rgba="0.25820272813481582 0.020596394605396751 0.34342371076604117 1" friction="0.59999999999999998 0.10000000000000001 0.10000000000000001" fromto="0 0 0 0.36053318400155709 -0.3572122552983471 0.19679143575546987"/>
                  <site name="0/1/2/3/4/5/9/end9" class="0/1/2/3/4/5/9/" size="0.0050000000000000001" pos="0.36053318400155709 -0.3572122552983471 0.19679143575546987"/>
                </body>
              </body>
            </body>
          </body>
        </body>
      </body>
      <camera name="0/iso" class="0/" mode="trackcom" pos="-2.2999999999999998 -2.2999999999999998 1" xyaxes="0.45000000000000001 -0.45000000000000001 0 0.29999999999999999 0.14999999999999999 0.93999999999999995"/>
    </body>
  </worldbody>
  <actuator>
    <motor name="0/1/2/motor" class="0/1/2/" ctrllimited="true" ctrlrange="-1 1" gear="89" joint="0/1/2/joint/"/>
    <motor name="0/1/2/3/motor" class="0/1/2/3/" ctrllimited="true" ctrlrange="-1 1" gear="80" joint="0/1/2/3/joint/"/>
    <motor name="0/1/2/3/4/motor" class="0/1/2/3/4/" ctrllimited="true" ctrlrange="-1 1" gear="63" joint="0/1/2/3/4/joint/"/>
    <motor name="0/1/2/3/4/5/motor" class="0/1/2/3/4/5/" ctrllimited="true" ctrlrange="-1 1" gear="58" joint="0/1/2/3/4/5/joint/"/>
    <motor name="0/1/2/3/4/5/6/motor" class="0/1/2/3/4/5/6/" ctrllimited="true" ctrlrange="-1 1" gear="79" joint="0/1/2/3/4/5/6/joint/"/>
    <motor name="0/1/2/3/4/5/6/7/motor" class="0/1/2/3/4/5/6/7/" ctrllimited="true" ctrlrange="-1 1" gear="59" joint="0/1/2/3/4/5/6/7/joint/"/>
    <motor name="0/1/2/3/4/5/6/8/motor" class="0/1/2/3/4/5/6/8/" ctrllimited="true" ctrlrange="-1 1" gear="55" joint="0/1/2/3/4/5/6/8/joint/"/>
    <motor name="0/1/2/3/4/5/9/motor" class="0/1/2/3/4/5/9/" ctrllimited="true" ctrlrange="-1 1" gear="98" joint="0/1/2/3/4/5/9/joint/"/>
  </actuator>
  <sensor>
    <subtreelinvel name="velocity" body="0/"/>
  </sensor>
</mujoco>
