<mujoco model="morphology">
  <option timestep="0.01"/>
  <default>
    <default class="/"/>
    <default class="0/"/>
    <default class="0/1/"/>
    <default class="0/1/2/"/>
    <default class="0/1/2/3/"/>
    <default class="0/1/2/3/4/"/>
    <default class="0/1/2/3/4/5/"/>
    <default class="0/1/2/3/4/5/6/"/>
    <default class="0/1/2/3/4/5/7/"/>
    <default class="0/1/2/3/4/8/"/>
    <default class="0/1/2/3/9/"/>
  </default>
  <asset>
    <texture name="texplane" type="2d" builtin="checker" rgb1="0.10000000000000001 0.20000000000000001 0.29999999999999999" rgb2="0.20000000000000001 0.29999999999999999 0.40000000000000002" width="300" height="300"/>
    <material name="MatPlane" class="/" texture="texplane" texrepeat="20 20" specular="1" shininess="1" reflectance="0.5"/>
  </asset>
  <worldbody>
    <light name="//unnamed_light_0" class="/" directional="true" pos="0 0 1.5" dir="0 0 -1.3" cutoff="100" exponent="1" diffuse="1 1 1" specular="0.10000000000000001 0.10000000000000001 0.10000000000000001"/>
    <geom name="ground" class="/" type="plane" size="15 15 0.5" material="MatPlane" rgba="1 1 1 1"/>
    <site name="body" class="/" size="9.9999999999999995e-07 9.9999999999999995e-07 9.9999999999999995e-07" pos="0 0 0.75195804834365843"/>
    <body pos="0 0 0.75195804834365843" name="0/">
      <freejoint name="0/"/>
      <geom name="0/geom" class="0/" type="capsule" contype="1" conaffinity="1" condim="3" size="0.044492793749174822" rgba="0.071353961950680778 0.076488677957046614 0.11134753578792489 1" friction="0.59999999999999998 0.10000000000000001 0.10000000000000001" fromto="0 0 0 0.34473718274440546 0.59581621971301324 -0.41302377729989881"/>
      <site name="0/end0" class="0/" size="0.0050000000000000001" pos="0.34473718274440546 0.59581621971301324 -0.41302377729989881"/>
      <site name="0/attach1" class="0/" size="9.9999999999999995e-07 9.9999999999999995e-07 9.9999999999999995e-07" pos="0.10374092186167432 0.17929752572989305 -0.12429024066037658"/>
      <body pos="0.10374092186167432 0.17929752572989305 -0.12429024066037658" name="0/1/">
        <joint name="0/1/joint/" class="0/" type="hinge" axis="0 1 0" limited="true" range="-46.261776447277342 46.261776447277342"/>
        <geom name="0/1/geom" class="0/1/" type="capsule" contype="1" conaffinity="1" condim="3" size="0.044759212284734881" rgba="0.85888501594267996 0.6186259178256639 0.54733127271956561 1" friction="0.59999999999999998 0.10000000000000001 0.10000000000000001" fromto="0 0 0 -0.10593561008643015 -0.080723814499979452 -0.083534936170989282"/>
        <site name="0/1/end1" class="0/1/" size="0.0050000000000000001" pos="-0.10593561008643015 -0.080723814499979452 -0.083534936170989282"/>
        <site name="0/1/attach2" class="0/1/" size="9.9999999999999995e-07 9.9999999999999995e-07 9.9999999999999995e-07" pos="-0.088595748463871166 -0.067510695965685347 -0.069861684724450479"/>
        <body pos="-0.088595748463871166 -0.067510695965685347 -0.069861684724450479" name="0/1/2/">
          <joint name="0/1/2/joint/" class="0/1/" type="hinge" axis="0.73889243678039129 -0.46824230908434095 -0.48454835347166375" limited="true" range="-42.954847782045213 42.954847782045213"/>
          <geom name="0/1/2/geom" class="0/1/2/" type="capsule" contype="1" conaffinity="1" condim="3" size="0.065022693585881239" rgba="0.35614026968433987 0.52141907170872759 0.84488964610472761 1" friction="0.59999999999999998 0.10000000000000001 0.10000000000000001" fromto="0 0 0 0.22968493121359368 -0.41271433220978099 -0.092791240265850172"/>
          <site name="0/1/2/end2" class="0/1/2/" size="0.0050000000000000001" pos="0.22968493121359368 -0.41271433220978099 -0.092791240265850172"/>
          <site name="0/1/2/attach3" class="0/1/2/" size="9.9999999999999995e-07 9.9999999999999995e-07 9.9999999999999995e-07" pos="0.21671853141397671 -0.38941537652214187 -0.087552897842461258"/>
          <body pos="0.21671853141397671 -0.38941537652214187 -0.087552897842461258" name="0/1/2/3/">
            <geom name="0/1/2/3/geom" class="0/1/2/3/" type="capsule" contype="1" conaffinity="1" condim="3" size="0.036115291305045746" rgba="0.29493575974453268 0.72435036824491883 0.2018181885194309 1" friction="0.59999999999999998 0.10000000000000001 0.10000000000000001" fromto="0 0 0 0.69607086659562989 0.38621295210927187 -0.33105089828200712"/>
            <site name="0/1/2/3/end3" class="0/1/2/3/" size="0.0050000000000000001" pos="0.69607086659562989 0.38621295210927187 -0.33105089828200712"/>
            <site name="0/1/2/3/attach4" class="0/1/2/3/" size="9.9999999999999995e-07 9.9999999999999995e-07 9.9999999999999995e-07" pos="0.41534056174038703 0.23045053625792025 -0.19753572898344862"/>
            <body pos="0.41534056174038703 0.23045053625792025 -0.19753572898344862" name="0/1/2/3/4/">
              <joint name="0/1/2/3/4/joint/" class="0/1/2/3/" type="hinge" axis="-0.59002613987445485 0.61300293760710267 -0.52544890593654592" limited="true" range="-57.449183089516211 57.449183089516211"/>
              <geom name="0/1/2/3/4/geom" class="0/1/2/3/4/" type="capsule" contype="1" conaffinity="1" condim="3" size="0.055160277915064768" rgba="0.7916553780018647 0.76651713108929742 0.32242471745574997 1" friction="0.59999999999999998 0.10000000000000001 0.10000000000000001" fromto="0 0 0 0.046472685018923876 0.22515254565573306 0.36069633809371693"/>
              <site name="0/1/2/3/4/end4" class="0/1/2/3/4/" size="0.0050000000000000001" pos="0.046472685018923876 0.22515254565573306 0.36069633809371693"/>
              <site name="0/1/2/3/4/attach5" class="0/1/2/3/4/" size="9.9999999999999995e-07 9.9999999999999995e-07 9.9999999999999995e-07" pos="0.0254528322056599 0.12331480229556264 0.19755138673302206"/>
              <body pos="0.0254528322056599 0.12331480229556264 0.19755138673302206" name="0/1/2/3/4/5/">
                <joint name="0/1/2/3/4/5/joint/" class="0/1/2/3/4/" type="hinge" axis="-0.99408018562385458 0.057531856200492004 0.092166534448078541" limited="true" range="-58.191998646264722 58.191998646264722"/>
                <geom name="0/1/2/3/4/5/geom" class="0/1/2/3/4/5/" type="capsule" contype="1" conaffinity="1" condim="3" size="0.058187852623290334" rgba="0.92498183386377386 0.79915028982871572 0.82966533921046726 1" friction="0.59999999999999998 0.10000000000000001 0.10000000000000001" fromto="0 0 0 -0.17796516966824061 0.41900259291075437 -0.3469197362989106"/>
                <site name="0/1/2/3/4/5/end5" class="0/1/2/3/4/5/" size="0.0050000000000000001" pos="-0.17796516966824061 0.41900259291075437 -0.3469197362989106"/>
                <site name="0/1/2/3/4/5/attach6" class="0/1/2/3/4/5/" size="9.9999999999999995e-07 9.9999999999999995e-07 9.9999999999999995e-07" pos="-0.1031291546959376 0.24280809162178205 -0.20103674903656743"/>
                <body pos="-0.1031291546959376 0.24280809162178205 -0.20103674903656743" name="0/1/2/3/4/5/6/">
                  <joint name="0/1/2/3/4/5/6/joint/" class="0/1/2/3/4/5/" type="hinge" axis="-0.95043086068973626 -0.23949867006706216 0.19829666180920766" limited="true" range="-66.679846603602613 66.679846603602613"/>
                  <geom name="0/1/2/3/4/5/6/geom" class="0/1/2/3/4/5/6/" type="capsule" contype="1" conaffinity="1" condim="3" size="0.041693152304675671" rgba="0.40007857958113435 0.9087918984018214 0.48767855900416224 1" friction="0.59999999999999998 0.10000000000000001 0.10000000000000001" fromto="0 0 0 0.35143901962227408 0.14593835698895263 0.42228689490795945"/>
                  <site name="0/1/2/3/4/5/6/end6" class="0/1/2/3/4/5/6/" size="0.0050000000000000001" pos="0.35143901962227408 0.14593835698895263 0.42228689490795945"/>
                </body>
                <site name="0/1/2/3/4/5/attach7" class="0/1/2/3/4/5/" size="9.9999999999999995e-07 9.9999999999999995e-07 9.9999999999999995e-07" pos="-0.17175023303767284 0.40437009730592116 -0.33480453318916531"/>
                <body pos="-0.17175023303767284 0.40437009730592116 -0.33480453318916531" name="0/1/2/3/4/5/7/">
                  <joint name="0/1/2/3/4/5/7/joint/" class="0/1/2/3/4/5/" type="hinge" axis="-5.5511151231257827e-17 0.63774114059376785 0.7702507628001154" limited="true" range="-54.807892627850919 54.807892627850919"/>
                  <geom name="0/1/2/3/4/5/7/geom" class="0/1/2/3/4/5/7/" type="capsule" contype="1" conaffinity="1" condim="3" size="0.066167904152700477" rgba="0.93419012444550009 0.44487522561113224 0.67236387142909115 1" friction="0.59999999999999998 0.10000000000000001 0.10000000000000001" fromto="0 0 0 0.19169314702293205 0.0066314107586322724 0.66926770768576649"/>
                  <site name="0/1/2/3/4/5/7/end7" class="0/1/2/3/4/5/7/" size="0.0050000000000000001" pos="0.19169314702293205 0.0066314107586322724 0.66926770768576649"/>
                </body>
              </body>
              <site name="0/1/2/3/4/attach8" class="0/1/2/3/4/" size="9.9999999999999995e-07 9.9999999999999995e-07 9.9999999999999995e-07" pos="0.023486591321006067 0.11378868732346838 0.18229046762288256"/>
              <body pos="0.023486591321006067 0.11378868732346838 0.18229046762288256" name="0/1/2/3/4/8/">
                <joint name="0/1/2/3/4/8/joint/" class="0/1/2/3/4/" type="hinge" axis="-1.1102230246251565e-16 -0.84829694765876196 0.52952081034915688" limited="true" range="-33.330434204624531 33.330434204624531"/>
                <geom name="0/1/2/3/4/8/geom" class="0/1/2/3/4/8/" type="capsule" contype="1" conaffinity="1" condim="3" size="0.038644240491063589" rgba="0.020719629410627438 0.33624624253974666 0.35470107103575865 1" friction="0.59999999999999998 0.10000000000000001 0.10000000000000001" fromto="0 0 0 0.56746591399359492 -0.58577078811000205 0.49966129476625842"/>
                <site name="0/1/2/3/4/8/end8" class="0/1/2/3/4/8/" size="0.0050000000000000001" pos="0.56746591399359492 -0.58577078811000205 0.49966129476625842"/>
              </body>
            </body>
            <site name="0/1/2/3/attach9" class="0/1/2/3/" size="9.9999999999999995e-07 9.9999999999999995e-07 9.9999999999999995e-07" pos="0.53407040311983611 0.29632745302487534 -0.25400357231351683"/>
            <body pos="0.53407040311983611 0.29632745302487534 -0.25400357231351683" name="0/1/2/3/9/">
              <joint name="0/1/2/3/9/joint/" class="0/1/2/3/" type="hinge" axis="-0.59002613987445485 0.61300293760710267 -0.52544890593654592" limited="true" range="-32.334455385718726 32.334455385718726"/>
              <geom name="0/1/2/3/9/geom" class="0/1/2/3/9/" type="capsule" contype="1" conaffinity="1" condim="3" size="0.068263482571243927" rgba="0.19686789578340846 0.86650265817493866 0.31359982674820186 1" friction="0.59999999999999998 0.10000000000000001 0.10000000000000001" fromto="0 0 0 -0.10135760146655071 0.099820837095831116 -0.11624964539823246"/>
              <site name="0/1/2/3/9/end9" class="0/1/2/3/9/" size="0.0050000000000000001" pos="-0.10135760146655071 0.099820837095831116 -0.11624964539823246"/>
            </body>
          </body>
        </body>
      </body>
      <camera name="0/iso" class="0/" mode="trackcom" pos="-2.2999999999999998 -2.2999999999999998 1" xyaxes="0.45000000000000001 -0.45000000000000001 0 0.29999999999999999 0.14999999999999999 0.93999999999999995"/>
    </body>
  </worldbody>
  <actuator>
    <motor name="0/1/motor" class="0/1/" ctrllimited="true" ctrlrange="-1 1" gear="62" joint="0/1/joint/"/>
    <motor name="0/1/2/motor" class="0/1/2/" ctrllimited="true" ctrlrange="-1 1" gear="85" joint="0/1/2/joint/"/>
    <motor name="0/1/2/3/4/motor" class="0/1/2/3/4/" ctrllimited="true" ctrlrange="-1 1" gear="94" joint="0/1/2/3/4/joint/"/>
    <motor name="0/1/2/3/4/5/motor" class="0/1/2/3/4/5/" ctrllimited="true" ctrlrange="-1 1" gear="93" joint="0/1/2/3/4/5/joint/"/>
    <motor name="0/1/2/3/4/5/6/motor" class="0/1/2/3/4/5/6/" ctrllimited="true" ctrlrange="-1 1" gear="50" joint="0/1/2/3/4/5/6/joint/"/>
    <motor name="0/1/2/3/4/5/7/motor" class="0/1/2/3/4/5/7/" ctrllimited="true" ctrlrange="-1 1" gear="63" joint="0/1/2/3/4/5/7/joint/"/>
    <motor name="0/1/2/3/4/8/motor" class="0/1/2/3/4/8/" ctrllimited="true" ctrlrange="-1 1" gear="74" joint="0/1/2/3/4/8/joint/"/>
    <motor name="0/1/2/3/9/motor" class="0/1/2/3/9/" ctrllimited="true" ctrlrange="-1 1" gear="70" joint="0/1/2/3/9/joint/"/>
  </actuator>
  <sensor>
    <subtreelinvel name="velocity" body="0/"/>
  </sensor>
</mujoco>
