<mujoco model="morphology">
  <option timestep="0.01"/>
  <default>
    <default class="/"/>
    <default class="0/"/>
    <default class="0/1/"/>
    <default class="0/2/"/>
    <default class="0/2/3/"/>
    <default class="0/2/3/4/"/>
    <default class="0/2/3/4/5/"/>
    <default class="0/2/3/4/5/6/"/>
    <default class="0/2/3/4/5/6/7/"/>
    <default class="0/2/3/4/5/6/7/8/"/>
    <default class="0/2/9/"/>
    <default class="0/2/9/10/"/>
  </default>
  <asset>
    <texture name="texplane" type="2d" builtin="checker" rgb1="0.10000000000000001 0.20000000000000001 0.29999999999999999" rgb2="0.20000000000000001 0.29999999999999999 0.40000000000000002" width="300" height="300"/>
    <material name="MatPlane" class="/" texture="texplane" texrepeat="20 20" specular="1" shininess="1" reflectance="0.5"/>
  </asset>
  <worldbody>
    <light name="//unnamed_light_0" class="/" directional="true" pos="0 0 1.5" dir="0 0 -1.3" cutoff="100" exponent="1" diffuse="1 1 1" specular="0.10000000000000001 0.10000000000000001 0.10000000000000001"/>
    <geom name="ground" class="/" type="plane" size="15 15 0.5" material="MatPlane" rgba="1 1 1 1"/>
    <site name="body" class="/" size="9.9999999999999995e-07 9.9999999999999995e-07 9.9999999999999995e-07" pos="0 0 0.72464755773544309"/>
    <body pos="0 0 0.72464755773544309" name="0/">
      <freejoint name="0/"/>
      <geom name="0/geom" class="0/" type="capsule" contype="1" conaffinity="1" condim="3" size="0.040045441267250508" rgba="0.34293771782213489 0.33257803609427805 0.045720974108114376 1" friction="0.59999999999999998 0.10000000000000001 0.10000000000000001" fromto="0 0 0 0.075753191842680478 -0.66643313227412126 -0.15089693167406826"/>
      <site name="0/end0" class="0/" size="0.0050000000000000001" pos="0.075753191842680478 -0.66643313227412126 -0.15089693167406826"/>
      <site name="0/attach1" class="0/" size="9.9999999999999995e-07 9.9999999999999995e-07 9.9999999999999995e-07" pos="0.069074849063137628 -0.6076809029790986 -0.13759397493274045"/>
      <body pos="0.069074849063137628 -0.6076809029790986 -0.13759397493274045" name="0/1/">
        <joint name="0/1/joint/" class="0/" type="hinge" axis="0 0 1" limited="true" range="-31.076789691493929 31.076789691493929"/>
        <geom name="0/1/geom" class="0/1/" type="capsule" contype="1" conaffinity="1" condim="3" size="0.038709186596289871" rgba="0.74649038377504029 0.673781340722309 0.22215702807416671 1" friction="0.59999999999999998 0.10000000000000001 0.10000000000000001" fromto="0 0 0 0.52661635956396458 -0.2668623737751894 0.68681984345438374"/>
        <site name="0/1/end1" class="0/1/" size="0.0050000000000000001" pos="0.52661635956396458 -0.2668623737751894 0.68681984345438374"/>
      </body>
      <site name="0/attach2" class="0/" size="9.9999999999999995e-07 9.9999999999999995e-07 9.9999999999999995e-07" pos="0.045922499103104072 -0.40399980746282255 -0.091475541041946384"/>
      <body pos="0.045922499103104072 -0.40399980746282255 -0.091475541041946384" name="0/2/">
        <joint name="0/2/joint/" class="0/" type="hinge" axis="0 0 1" limited="true" range="-39.793520929554539 39.793520929554539"/>
        <geom name="0/2/geom" class="0/2/" type="capsule" contype="1" conaffinity="1" condim="3" size="0.048745196587429693" rgba="0.7609665404067435 0.53756656653799462 0.41880300290458072 1" friction="0.59999999999999998 0.10000000000000001 0.10000000000000001" fromto="0 0 0 -0.73682910850401329 -0.30484661706870031 0.18724163519033188"/>
        <site name="0/2/end2" class="0/2/" size="0.0050000000000000001" pos="-0.73682910850401329 -0.30484661706870031 0.18724163519033188"/>
        <site name="0/2/attach3" class="0/2/" size="9.9999999999999995e-07 9.9999999999999995e-07 9.9999999999999995e-07" pos="-0.67779435673305077 -0.28042230462072054 0.17223983446466176"/>
        <body pos="-0.67779435673305077 -0.28042230462072054 0.17223983446466176" name="0/2/3/">
          <joint name="0/2/3/joint/" class="0/2/" type="hinge" axis="0 0.52337490597891356 0.85210252187841995" limited="true" range="-59.543395276491026 59.543395276491026"/>
          <geom name="0/2/3/geom" class="0/2/3/" type="capsule" contype="1" conaffinity="1" condim="3" size="0.038192019048961946" rgba="0.21598582191533022 0.9007398090976152 0.96926774605171717 1" friction="0.59999999999999998 0.10000000000000001 0.10000000000000001" fromto="0 0 0 -9.9229692386737511e-05 0.18707734286184741 0.039225099158250121"/>
          <site name="0/2/3/end3" class="0/2/3/" size="0.0050000000000000001" pos="-9.9229692386737511e-05 0.18707734286184741 0.039225099158250121"/>
          <site name="0/2/3/attach4" class="0/2/3/" size="9.9999999999999995e-07 9.9999999999999995e-07 9.9999999999999995e-07" pos="-8.3050224715403511e-06 0.015657425706091962 0.0032829420521433136"/>
          <body pos="-8.3050224715403511e-06 0.015657425706091962 0.0032829420521433136" name="0/2/3/4/">
            <joint name="0/2/3/4/joint/" class="0/2/3/" type="hinge" axis="-0.99999986525092854 -0.00050808380788608387 -0.00010653154166161138" limited="true" range="-61.978083028125198 61.978083028125198"/>
            <geom name="0/2/3/4/geom" class="0/2/3/4/" type="capsule" contype="1" conaffinity="1" condim="3" size="0.041024171292855557" rgba="0.060363746349529346 0.77008009219332341 0.65204677563109914 1" friction="0.59999999999999998 0.10000000000000001 0.10000000000000001" fromto="0 0 0 0.086172044241378698 -0.38928215644313452 -0.15515602606738876"/>
            <site name="0/2/3/4/end4" class="0/2/3/4/" size="0.0050000000000000001" pos="0.086172044241378698 -0.38928215644313452 -0.15515602606738876"/>
            <site name="0/2/3/4/attach5" class="0/2/3/4/" size="9.9999999999999995e-07 9.9999999999999995e-07 9.9999999999999995e-07" pos="0.079738786998178005 -0.36021992083489507 -0.14357270299188765"/>
            <body pos="0.079738786998178005 -0.36021992083489507 -0.14357270299188765" name="0/2/3/4/5/">
              <joint name="0/2/3/4/5/joint/" class="0/2/3/4/" type="hinge" axis="0.97950580196677939 0.18710215785642537 0.074573228700958671" limited="true" range="-40.740826320233026 40.740826320233026"/>
              <geom name="0/2/3/4/5/geom" class="0/2/3/4/5/" type="capsule" contype="1" conaffinity="1" condim="3" size="0.044413565631589921" rgba="0.27134116679896858 0.091535716717004667 0.3488336907845383 1" friction="0.59999999999999998 0.10000000000000001 0.10000000000000001" fromto="0 0 0 0.4526522966071711 -0.054617875635463498 0.60545444785780478"/>
              <site name="0/2/3/4/5/end5" class="0/2/3/4/5/" size="0.0050000000000000001" pos="0.4526522966071711 -0.054617875635463498 0.60545444785780478"/>
              <site name="0/2/3/4/5/attach6" class="0/2/3/4/5/" size="9.9999999999999995e-07 9.9999999999999995e-07 9.9999999999999995e-07" pos="0.40859618380808194 -0.049301982381682347 0.54652628235534984"/>
              <body pos="0.40859618380808194 -0.049301982381682347 0.54652628235534984" name="0/2/3/4/5/6/">
                <joint name="0/2/3/4/5/6/joint/" class="0/2/3/4/5/" type="hinge" axis="0.80207399319033668 0.05365758511891211 -0.59480935854012496" limited="true" range="-49.144453733465824 49.144453733465824"/>
                <geom name="0/2/3/4/5/6/geom" class="0/2/3/4/5/6/" type="capsule" contype="1" conaffinity="1" condim="3" size="0.060262809462557493" rgba="0.84264759518553456 0.97607562354643362 0.64544628404134863 1" friction="0.59999999999999998 0.10000000000000001 0.10000000000000001" fromto="0 0 0 -0.72172460619853851 0.10239811915860719 0.37422789668478673"/>
                <site name="0/2/3/4/5/6/end6" class="0/2/3/4/5/6/" size="0.0050000000000000001" pos="-0.72172460619853851 0.10239811915860719 0.37422789668478673"/>
                <site name="0/2/3/4/5/6/attach7" class="0/2/3/4/5/6/" size="9.9999999999999995e-07 9.9999999999999995e-07 9.9999999999999995e-07" pos="-0.18120523525295429 0.025709356605324283 0.093958351252791714"/>
                <body pos="-0.18120523525295429 0.025709356605324283 0.093958351252791714" name="0/2/3/4/5/6/7/">
                  <joint name="0/2/3/4/5/6/7/joint/" class="0/2/3/4/5/6/" type="hinge" axis="-2.7755575615628914e-17 -0.96454367276192265 0.26392329062616104" limited="true" range="-42.452252455018801 42.452252455018801"/>
                  <geom name="0/2/3/4/5/6/7/geom" class="0/2/3/4/5/6/7/" type="capsule" contype="1" conaffinity="1" condim="3" size="0.036266219819648692" rgba="0.66917472167384373 0.79603414313910204 0.27659314490692799 1" friction="0.59999999999999998 0.10000000000000001 0.10000000000000001" fromto="0 0 0 -0.72187727722889772 0.73451548286054225 -0.59755227910122521"/>
                  <site name="0/2/3/4/5/6/7/end7" class="0/2/3/4/5/6/7/" size="0.0050000000000000001" pos="-0.72187727722889772 0.73451548286054225 -0.59755227910122521"/>
                  <site name="0/2/3/4/5/6/7/attach8" class="0/2/3/4/5/6/7/" size="9.9999999999999995e-07 9.9999999999999995e-07 9.9999999999999995e-07" pos="-0.61636246383690696 0.62715337775997804 -0.51020970826514112"/>
                  <body pos="-0.61636246383690696 0.62715337775997804 -0.51020970826514112" name="0/2/3/4/5/6/7/8/">
                    <joint name="0/2/3/4/5/6/7/8/joint/" class="0/2/3/4/5/6/7/" type="hinge" axis="-0.79525155732816533 -0.47030432670534411 0.38260789438975418" limited="true" range="-58.458942502677928 58.458942502677928"/>
                    <geom name="0/2/3/4/5/6/7/8/geom" class="0/2/3/4/5/6/7/8/" type="capsule" contype="1" conaffinity="1" condim="3" size="0.038843444812404412" rgba="0.89997062140096373 0.98983205887951686 0.65193687876569628 1" friction="0.59999999999999998 0.10000000000000001 0.10000000000000001" fromto="0 0 0 0.66084244472716636 -0.56581310477380975 -0.30049808315892201"/>
                    <site name="0/2/3/4/5/6/7/8/end8" class="0/2/3/4/5/6/7/8/" size="0.0050000000000000001" pos="0.66084244472716636 -0.56581310477380975 -0.30049808315892201"/>
                  </body>
                </body>
              </body>
            </body>
          </body>
        </body>
        <site name="0/2/attach9" class="0/2/" size="9.9999999999999995e-07 9.9999999999999995e-07 9.9999999999999995e-07" pos="-0.73562348833590929 -0.30434781860176341 0.18693526524771037"/>
        <body pos="-0.73562348833590929 -0.30434781860176341 0.18693526524771037" name="0/2/9/">
          <geom name="0/2/9/geom" class="0/2/9/" type="capsule" contype="1" conaffinity="1" condim="3" size="0.040911320342603516" rgba="0.85079384437899142 0.47187475112534538 0.42929778025375398 1" friction="0.59999999999999998 0.10000000000000001 0.10000000000000001" fromto="0 0 0 0.085304987615265393 -0.6230626732874962 -0.059420616979015684"/>
          <site name="0/2/9/end9" class="0/2/9/" size="0.0050000000000000001" pos="0.085304987615265393 -0.6230626732874962 -0.059420616979015684"/>
          <site name="0/2/9/attach10" class="0/2/9/" size="9.9999999999999995e-07 9.9999999999999995e-07 9.9999999999999995e-07" pos="0.0090766858336260754 -0.066295585969674081 -0.0063225174451843778"/>
          <body pos="0.0090766858336260754 -0.066295585969674081 -0.0063225174451843778" name="0/2/9/10/">
            <joint name="0/2/9/10/joint/" class="0/2/9/" type="hinge" axis="1.3877787807814457e-17 -0.094937842704721553 0.99548320228046716" limited="true" range="-66.850624269867581 66.850624269867581"/>
            <geom name="0/2/9/10/geom" class="0/2/9/10/" type="capsule" contype="1" conaffinity="1" condim="3" size="0.052835443030587237" rgba="0.19767061079687887 0.30858037882276956 0.017432177088381851 1" friction="0.59999999999999998 0.10000000000000001 0.10000000000000001" fromto="0 0 0 0.049286360879582602 0.20714113141818058 -0.713784743136332"/>
            <site name="0/2/9/10/end10" class="0/2/9/10/" size="0.0050000000000000001" pos="0.049286360879582602 0.20714113141818058 -0.713784743136332"/>
          </body>
        </body>
      </body>
      <camera name="0/iso" class="0/" mode="trackcom" pos="-2.2999999999999998 -2.2999999999999998 1" xyaxes="0.45000000000000001 -0.45000000000000001 0 0.29999999999999999 0.14999999999999999 0.93999999999999995"/>
    </body>
  </worldbody>
  <actuator>
    <motor name="0/1/motor" class="0/1/" ctrllimited="true" ctrlrange="-1 1" gear="73" joint="0/1/joint/"/>
    <motor name="0/2/motor" class="0/2/" ctrllimited="true" ctrlrange="-1 1" gear="83" joint="0/2/joint/"/>
    <motor name="0/2/3/motor" class="0/2/3/" ctrllimited="true" ctrlrange="-1 1" gear="91" joint="0/2/3/joint/"/>
    <motor name="0/2/3/4/motor" class="0/2/3/4/" ctrllimited="true" ctrlrange="-1 1" gear="66" joint="0/2/3/4/joint/"/>
    <motor name="0/2/3/4/5/motor" class="0/2/3/4/5/" ctrllimited="true" ctrlrange="-1 1" gear="67" joint="0/2/3/4/5/joint/"/>
    <motor name="0/2/3/4/5/6/motor" class="0/2/3/4/5/6/" ctrllimited="true" ctrlrange="-1 1" gear="88" joint="0/2/3/4/5/6/joint/"/>
    <motor name="0/2/3/4/5/6/7/motor" class="0/2/3/4/5/6/7/" ctrllimited="true" ctrlrange="-1 1" gear="81" joint="0/2/3/4/5/6/7/joint/"/>
    <motor name="0/2/3/4/5/6/7/8/motor" class="0/2/3/4/5/6/7/8/" ctrllimited="true" ctrlrange="-1 1" gear="69" joint="0/2/3/4/5/6/7/8/joint/"/>
    <motor name="0/2/9/10/motor" class="0/2/9/10/" ctrllimited="true" ctrlrange="-1 1" gear="95" joint="0/2/9/10/joint/"/>
  </actuator>
  <sensor>
    <subtreelinvel name="velocity" body="0/"/>
  </sensor>
</mujoco>
