<mujoco model="morphology">
  <option timestep="0.01"/>
  <default>
    <default class="/"/>
    <default class="0/"/>
    <default class="0/1/"/>
    <default class="0/1/2/"/>
    <default class="0/1/2/3/"/>
    <default class="0/1/2/3/4/"/>
    <default class="0/1/2/3/4/5/"/>
    <default class="0/1/2/6/"/>
    <default class="0/1/2/7/"/>
    <default class="0/1/2/7/8/"/>
    <default class="0/1/2/7/9/"/>
    <default class="0/1/10/"/>
  </default>
  <asset>
    <texture name="texplane" type="2d" builtin="checker" rgb1="0.10000000000000001 0.20000000000000001 0.29999999999999999" rgb2="0.20000000000000001 0.29999999999999999 0.40000000000000002" width="300" height="300"/>
    <material name="MatPlane" class="/" texture="texplane" texrepeat="20 20" specular="1" shininess="1" reflectance="0.5"/>
  </asset>
  <worldbody>
    <light name="//unnamed_light_0" class="/" directional="true" pos="0 0 1.5" dir="0 0 -1.3" cutoff="100" exponent="1" diffuse="1 1 1" specular="0.10000000000000001 0.10000000000000001 0.10000000000000001"/>
    <geom name="ground" class="/" type="plane" size="15 15 0.5" material="MatPlane" rgba="1 1 1 1"/>
    <site name="body" class="/" size="9.9999999999999995e-07 9.9999999999999995e-07 9.9999999999999995e-07" pos="0 0 1.5801696538925172"/>
    <body pos="0 0 1.5801696538925172" name="0/">
      <freejoint name="0/"/>
      <geom name="0/geom" class="0/" type="capsule" contype="1" conaffinity="1" condim="3" size="0.044297555068876893" rgba="0.42450269245042271 0.91084107984544094 0.35320539529626971 1" friction="0.59999999999999998 0.10000000000000001 0.10000000000000001" fromto="0 0 0 0.2144787199321827 -0.58867257807854623 -0.47273650652936755"/>
      <site name="0/end0" class="0/" size="0.0050000000000000001" pos="0.2144787199321827 -0.58867257807854623 -0.47273650652936755"/>
      <site name="0/attach1" class="0/" size="9.9999999999999995e-07 9.9999999999999995e-07 9.9999999999999995e-07" pos="0.1890787606928899 -0.51895815842324278 -0.41675198740985614"/>
      <body pos="0.1890787606928899 -0.51895815842324278 -0.41675198740985614" name="0/1/">
        <joint name="0/1/joint/" class="0/" type="hinge" axis="0 0 1" limited="true" range="-46.078746935685118 46.078746935685118"/>
        <geom name="0/1/geom" class="0/1/" type="capsule" contype="1" conaffinity="1" condim="3" size="0.065180068134264607" rgba="0.72930618972459327 0.48468645507517427 0.29947110568881763 1" friction="0.59999999999999998 0.10000000000000001 0.10000000000000001" fromto="0 0 0 0.43398202905534067 0.52190881946705492 0.04456705445582132"/>
        <site name="0/1/end1" class="0/1/" size="0.0050000000000000001" pos="0.43398202905534067 0.52190881946705492 0.04456705445582132"/>
        <site name="0/1/attach2" class="0/1/" size="9.9999999999999995e-07 9.9999999999999995e-07 9.9999999999999995e-07" pos="0.17027125064590978 0.20476900300969314 0.017485719665201599"/>
        <body pos="0.17027125064590978 0.20476900300969314 0.017485719665201599" name="0/1/2/">
          <joint name="0/1/2/joint/" class="0/1/" type="hinge" axis="-0.77004357828203596 0.63567786233705337 0.054282067768206925" limited="true" range="-43.136059658458763 43.136059658458763"/>
          <geom name="0/1/2/geom" class="0/1/2/" type="capsule" contype="1" conaffinity="1" condim="3" size="0.056438212679523467" rgba="0.67363835814563622 0.30003328803233698 0.67934222802046307 1" friction="0.59999999999999998 0.10000000000000001 0.10000000000000001" fromto="0 0 0 0.73980977536151582 0.1646884180587922 -0.39864730853241193"/>
          <site name="0/1/2/end2" class="0/1/2/" size="0.0050000000000000001" pos="0.73980977536151582 0.1646884180587922 -0.39864730853241193"/>
          <site name="0/1/2/attach3" class="0/1/2/" size="9.9999999999999995e-07 9.9999999999999995e-07 9.9999999999999995e-07" pos="0.045943889921832196 0.010227529836296656 -0.024756915454243345"/>
          <body pos="0.045943889921832196 0.010227529836296656 -0.024756915454243345" name="0/1/2/3/">
            <joint name="0/1/2/3/joint/" class="0/1/2/" type="hinge" axis="0 0.92423708995427978 0.38181906913202318" limited="true" range="-67.478005520123304 67.478005520123304"/>
            <geom name="0/1/2/3/geom" class="0/1/2/3/" type="capsule" contype="1" conaffinity="1" condim="3" size="0.064577491810513407" rgba="0.91436915907348615 0.96300149616743425 0.93766491831306209 1" friction="0.59999999999999998 0.10000000000000001 0.10000000000000001" fromto="0 0 0 0.03200810462720538 0.59747079085814248 -0.45675614530025616"/>
            <site name="0/1/2/3/end3" class="0/1/2/3/" size="0.0050000000000000001" pos="0.03200810462720538 0.59747079085814248 -0.45675614530025616"/>
            <site name="0/1/2/3/attach4" class="0/1/2/3/" size="9.9999999999999995e-07 9.9999999999999995e-07 9.9999999999999995e-07" pos="0.025843857226248854 0.48240750258819581 -0.36879224008529587"/>
            <body pos="0.025843857226248854 0.48240750258819581 -0.36879224008529587" name="0/1/2/3/4/">
              <joint name="0/1/2/3/4/joint/" class="0/1/2/3/" type="hinge" axis="-0.99909553263087958 0.033781284191004401 -0.025825210849578062" limited="true" range="-30.111000874979325 30.111000874979325"/>
              <geom name="0/1/2/3/4/geom" class="0/1/2/3/4/" type="capsule" contype="1" conaffinity="1" condim="3" size="0.0369133549647492" rgba="0.34492906444134308 0.97801646544652587 0.77945021885511989 1" friction="0.59999999999999998 0.10000000000000001 0.10000000000000001" fromto="0 0 0 -0.55459044823219794 0.52121296623485014 0.25926003786701912"/>
              <site name="0/1/2/3/4/end4" class="0/1/2/3/4/" size="0.0050000000000000001" pos="-0.55459044823219794 0.52121296623485014 0.25926003786701912"/>
              <site name="0/1/2/3/4/attach5" class="0/1/2/3/4/" size="9.9999999999999995e-07 9.9999999999999995e-07 9.9999999999999995e-07" pos="-0.080325212738777588 0.075490918620175734 0.037550444229094815"/>
              <body pos="-0.080325212738777588 0.075490918620175734 0.037550444229094815" name="0/1/2/3/4/5/">
                <joint name="0/1/2/3/4/5/joint/" class="0/1/2/3/4/" type="hinge" axis="-0.72402726387549943 -0.61758709772231524 -0.30719814109444921" limited="true" range="-40.98630334371304 40.98630334371304"/>
                <geom name="0/1/2/3/4/5/geom" class="0/1/2/3/4/5/" type="capsule" contype="1" conaffinity="1" condim="3" size="0.064348731137366305" rgba="0.2918712656721949 0.64506340240641402 0.91532139980792659 1" friction="0.59999999999999998 0.10000000000000001 0.10000000000000001" fromto="0 0 0 -0.54887570212744841 -0.34632671069586612 -0.7249046744869021"/>
                <site name="0/1/2/3/4/5/end5" class="0/1/2/3/4/5/" size="0.0050000000000000001" pos="-0.54887570212744841 -0.34632671069586612 -0.7249046744869021"/>
              </body>
            </body>
          </body>
          <site name="0/1/2/attach6" class="0/1/2/" size="9.9999999999999995e-07 9.9999999999999995e-07 9.9999999999999995e-07" pos="0.21480239183746105 0.047816975775522408 -0.11574650433685359"/>
          <body pos="0.21480239183746105 0.047816975775522408 -0.11574650433685359" name="0/1/2/6/">
            <joint name="0/1/2/6/joint/" class="0/1/2/" type="hinge" axis="-0.50367071387694395 0.32985185896316932 -0.7984444646443678" limited="true" range="-64.140410893389799 64.140410893389799"/>
            <geom name="0/1/2/6/geom" class="0/1/2/6/" type="capsule" contype="1" conaffinity="1" condim="3" size="0.045244953001183384" rgba="0.5155481644862806 0.42265588196080439 0.097367352847503197 1" friction="0.59999999999999998 0.10000000000000001 0.10000000000000001" fromto="0 0 0 0.034942209615196562 -0.69601314982166529 0.295185180415241"/>
            <site name="0/1/2/6/end6" class="0/1/2/6/" size="0.0050000000000000001" pos="0.034942209615196562 -0.69601314982166529 0.295185180415241"/>
          </body>
          <site name="0/1/2/attach7" class="0/1/2/" size="9.9999999999999995e-07 9.9999999999999995e-07 9.9999999999999995e-07" pos="0.2484837909052047 0.055314763065184826 -0.13389576315058158"/>
          <body pos="0.2484837909052047 0.055314763065184826 -0.13389576315058158" name="0/1/2/7/">
            <joint name="0/1/2/7/joint/" class="0/1/2/" type="hinge" axis="-0.50367071387694395 0.32985185896316932 -0.7984444646443678" limited="true" range="-57.841047662962907 57.841047662962907"/>
            <geom name="0/1/2/7/geom" class="0/1/2/7/" type="capsule" contype="1" conaffinity="1" condim="3" size="0.050759151286467089" rgba="0.47508367838327692 0.68576046212106645 0.34556485151990468 1" friction="0.59999999999999998 0.10000000000000001 0.10000000000000001" fromto="0 0 0 0.066275599740056146 0.1229498099834947 -0.018576335932099619"/>
            <site name="0/1/2/7/end7" class="0/1/2/7/" size="0.0050000000000000001" pos="0.066275599740056146 0.1229498099834947 -0.018576335932099619"/>
            <site name="0/1/2/7/attach8" class="0/1/2/7/" size="9.9999999999999995e-07 9.9999999999999995e-07 9.9999999999999995e-07" pos="0.024799385944997115 0.046006068622596236 -0.0069510004591573074"/>
            <body pos="0.024799385944997115 0.046006068622596236 -0.0069510004591573074" name="0/1/2/7/8/">
              <joint name="0/1/2/7/8/joint/" class="0/1/2/7/" type="hinge" axis="1.3877787807814457e-17 0.14939323404288046 0.988777862627501" limited="true" range="-63.117637424361504 63.117637424361504"/>
              <geom name="0/1/2/7/8/geom" class="0/1/2/7/8/" type="capsule" contype="1" conaffinity="1" condim="3" size="0.047513378482845384" rgba="0.08367908709782268 0.81617018659552032 0.17464523312211544 1" friction="0.59999999999999998 0.10000000000000001 0.10000000000000001" fromto="0 0 0 -0.0441595428928514 0.33214443921726211 0.49586407785588515"/>
              <site name="0/1/2/7/8/end8" class="0/1/2/7/8/" size="0.0050000000000000001" pos="-0.0441595428928514 0.33214443921726211 0.49586407785588515"/>
            </body>
            <site name="0/1/2/7/attach9" class="0/1/2/7/" size="9.9999999999999995e-07 9.9999999999999995e-07 9.9999999999999995e-07" pos="0.06136181055990457 0.11383409547667526 -0.017199053812163655"/>
            <body pos="0.06136181055990457 0.11383409547667526 -0.017199053812163655" name="0/1/2/7/9/">
              <geom name="0/1/2/7/9/geom" class="0/1/2/7/9/" type="capsule" contype="1" conaffinity="1" condim="3" size="0.052329886045442801" rgba="0.63386303720914983 0.41970990508176753 0.066406776909763487 1" friction="0.59999999999999998 0.10000000000000001 0.10000000000000001" fromto="0 0 0 -0.13384849399124055 0.60591744068274633 -0.1998020562289371"/>
              <site name="0/1/2/7/9/end9" class="0/1/2/7/9/" size="0.0050000000000000001" pos="-0.13384849399124055 0.60591744068274633 -0.1998020562289371"/>
            </body>
          </body>
        </body>
        <site name="0/1/attach10" class="0/1/" size="9.9999999999999995e-07 9.9999999999999995e-07 9.9999999999999995e-07" pos="0.35207190708196429 0.42340332338791659 0.036155432263961097"/>
        <body pos="0.35207190708196429 0.42340332338791659 0.036155432263961097" name="0/1/10/">
          <joint name="0/1/10/joint/" class="0/1/" type="hinge" axis="-6.9388939039072284e-18 -0.085082772325630496 0.99637388657741566" limited="true" range="-65.825213929640256 65.825213929640256"/>
          <geom name="0/1/10/geom" class="0/1/10/" type="capsule" contype="1" conaffinity="1" condim="3" size="0.040113923499311047" rgba="0.79743244507838396 0.96461062977042866 0.90332170249976929 1" friction="0.59999999999999998 0.10000000000000001 0.10000000000000001" fromto="0 0 0 -0.10741261753354181 0.44560827825393479 0.34633592182643813"/>
          <site name="0/1/10/end10" class="0/1/10/" size="0.0050000000000000001" pos="-0.10741261753354181 0.44560827825393479 0.34633592182643813"/>
        </body>
      </body>
      <camera name="0/iso" class="0/" mode="trackcom" pos="-2.2999999999999998 -2.2999999999999998 1" xyaxes="0.45000000000000001 -0.45000000000000001 0 0.29999999999999999 0.14999999999999999 0.93999999999999995"/>
    </body>
  </worldbody>
  <actuator>
    <motor name="0/1/motor" class="0/1/" ctrllimited="true" ctrlrange="-1 1" gear="55" joint="0/1/joint/"/>
    <motor name="0/1/2/motor" class="0/1/2/" ctrllimited="true" ctrlrange="-1 1" gear="57" joint="0/1/2/joint/"/>
    <motor name="0/1/2/3/motor" class="0/1/2/3/" ctrllimited="true" ctrlrange="-1 1" gear="59" joint="0/1/2/3/joint/"/>
    <motor name="0/1/2/3/4/motor" class="0/1/2/3/4/" ctrllimited="true" ctrlrange="-1 1" gear="94" joint="0/1/2/3/4/joint/"/>
    <motor name="0/1/2/3/4/5/motor" class="0/1/2/3/4/5/" ctrllimited="true" ctrlrange="-1 1" gear="55" joint="0/1/2/3/4/5/joint/"/>
    <motor name="0/1/2/6/motor" class="0/1/2/6/" ctrllimited="true" ctrlrange="-1 1" gear="89" joint="0/1/2/6/joint/"/>
    <motor name="0/1/2/7/motor" class="0/1/2/7/" ctrllimited="true" ctrlrange="-1 1" gear="50" joint="0/1/2/7/joint/"/>
    <motor name="0/1/2/7/8/motor" class="0/1/2/7/8/" ctrllimited="true" ctrlrange="-1 1" gear="82" joint="0/1/2/7/8/joint/"/>
    <motor name="0/1/10/motor" class="0/1/10/" ctrllimited="true" ctrlrange="-1 1" gear="91" joint="0/1/10/joint/"/>
  </actuator>
  <sensor>
    <subtreelinvel name="velocity" body="0/"/>
  </sensor>
</mujoco>
