<mujoco model="morphology">
  <option timestep="0.01"/>
  <default>
    <default class="/"/>
    <default class="0/"/>
    <default class="0/1/"/>
    <default class="0/1/2/"/>
    <default class="0/1/2/3/"/>
    <default class="0/1/2/3/4/"/>
    <default class="0/1/2/3/5/"/>
    <default class="0/1/2/3/5/6/"/>
    <default class="0/1/2/3/5/6/7/"/>
    <default class="0/1/2/3/5/6/7/8/"/>
    <default class="0/1/2/3/5/6/9/"/>
    <default class="0/10/"/>
  </default>
  <asset>
    <texture name="texplane" type="2d" builtin="checker" rgb1="0.10000000000000001 0.20000000000000001 0.29999999999999999" rgb2="0.20000000000000001 0.29999999999999999 0.40000000000000002" width="300" height="300"/>
    <material name="MatPlane" class="/" texture="texplane" texrepeat="20 20" specular="1" shininess="1" reflectance="0.5"/>
  </asset>
  <worldbody>
    <light name="//unnamed_light_0" class="/" directional="true" pos="0 0 1.5" dir="0 0 -1.3" cutoff="100" exponent="1" diffuse="1 1 1" specular="0.10000000000000001 0.10000000000000001 0.10000000000000001"/>
    <geom name="ground" class="/" type="plane" size="15 15 0.5" material="MatPlane" rgba="1 1 1 1"/>
    <site name="body" class="/" size="9.9999999999999995e-07 9.9999999999999995e-07 9.9999999999999995e-07" pos="0 0 1.5048138856887818"/>
    <body pos="0 0 1.5048138856887818" name="0/">
      <freejoint name="0/"/>
      <geom name="0/geom" class="0/" type="capsule" contype="1" conaffinity="1" condim="3" size="0.067750675422723713" rgba="0.039378560020377207 0.55946103078563791 0.7912644987516404 1" friction="0.59999999999999998 0.10000000000000001 0.10000000000000001" fromto="0 0 0 0.35115400609273695 -0.3555559341392906 -0.21199685865948326"/>
      <site name="0/end0" class="0/" size="0.0050000000000000001" pos="0.35115400609273695 -0.3555559341392906 -0.21199685865948326"/>
      <site name="0/attach1" class="0/" size="9.9999999999999995e-07 9.9999999999999995e-07 9.9999999999999995e-07" pos="0.25002914523210107 -0.25316341192921049 -0.15094628693634451"/>
      <body pos="0.25002914523210107 -0.25316341192921049 -0.15094628693634451" name="0/1/">
        <geom name="0/1/geom" class="0/1/" type="capsule" contype="1" conaffinity="1" condim="3" size="0.069454286171078669" rgba="0.93179610750514996 0.66532930035195059 0.12148172544548019 1" friction="0.59999999999999998 0.10000000000000001 0.10000000000000001" fromto="0 0 0 -0.72426017625788552 0.081821161795234243 -0.57425831797824989"/>
        <site name="0/1/end1" class="0/1/" size="0.0050000000000000001" pos="-0.72426017625788552 0.081821161795234243 -0.57425831797824989"/>
        <site name="0/1/attach2" class="0/1/" size="9.9999999999999995e-07 9.9999999999999995e-07 9.9999999999999995e-07" pos="-0.17352936580382425 0.019603969376059568 -0.13758961902504796"/>
        <body pos="-0.17352936580382425 0.019603969376059568 -0.13758961902504796" name="0/1/2/">
          <joint name="0/1/2/joint/" class="0/1/" type="hinge" axis="5.5511151231257827e-17 0.99000149670920545 0.14105685560628828" limited="true" range="-51.805881172172853 51.805881172172853"/>
          <geom name="0/1/2/geom" class="0/1/2/" type="capsule" contype="1" conaffinity="1" condim="3" size="0.0645410341432123" rgba="0.34092861968111998 0.34004274589141992 0.77933561427344367 1" friction="0.59999999999999998 0.10000000000000001 0.10000000000000001" fromto="0 0 0 0.20082222456102206 -0.057786065844968149 -0.33371991737012591"/>
          <site name="0/1/2/end2" class="0/1/2/" size="0.0050000000000000001" pos="0.20082222456102206 -0.057786065844968149 -0.33371991737012591"/>
          <site name="0/1/2/attach3" class="0/1/2/" size="9.9999999999999995e-07 9.9999999999999995e-07 9.9999999999999995e-07" pos="0.17739547889163268 -0.051045081520430365 -0.29479010446655457"/>
          <body pos="0.17739547889163268 -0.051045081520430365 -0.29479010446655457" name="0/1/2/3/">
            <joint name="0/1/2/3/joint/" class="0/1/2/" type="hinge" axis="0.86015850509262182 0.08701995949493152 0.50254837853317835" limited="true" range="-67.147383694166564 67.147383694166564"/>
            <geom name="0/1/2/3/geom" class="0/1/2/3/" type="capsule" contype="1" conaffinity="1" condim="3" size="0.044123852970732597" rgba="0.45685248061081785 0.31485437752567047 0.8307853990667784 1" friction="0.59999999999999998 0.10000000000000001 0.10000000000000001" fromto="0 0 0 0.12221763820379439 -0.27289048636497282 0.5457558943702856"/>
            <site name="0/1/2/3/end3" class="0/1/2/3/" size="0.0050000000000000001" pos="0.12221763820379439 -0.27289048636497282 0.5457558943702856"/>
            <site name="0/1/2/3/attach4" class="0/1/2/3/" size="9.9999999999999995e-07 9.9999999999999995e-07 9.9999999999999995e-07" pos="0.12064885701427916 -0.26938767393872404 0.53875059142270676"/>
            <body pos="0.12064885701427916 -0.26938767393872404 0.53875059142270676" name="0/1/2/3/4/">
              <joint name="0/1/2/3/4/joint/" class="0/1/2/3/" type="hinge" axis="0 0.89441897085125466 0.44723003541956174" limited="true" range="-37.656801273434148 37.656801273434148"/>
              <geom name="0/1/2/3/4/geom" class="0/1/2/3/4/" type="capsule" contype="1" conaffinity="1" condim="3" size="0.05514735527843579" rgba="0.26651623098615651 0.3781388334353194 0.1341705122242256 1" friction="0.59999999999999998 0.10000000000000001 0.10000000000000001" fromto="0 0 0 0.27910502815935745 0.58299049162415129 -0.17517823648685171"/>
              <site name="0/1/2/3/4/end4" class="0/1/2/3/4/" size="0.0050000000000000001" pos="0.27910502815935745 0.58299049162415129 -0.17517823648685171"/>
            </body>
            <site name="0/1/2/3/attach5" class="0/1/2/3/" size="9.9999999999999995e-07 9.9999999999999995e-07 9.9999999999999995e-07" pos="0.043352489843140281 -0.096798483527394855 0.1935880713720681"/>
            <body pos="0.043352489843140281 -0.096798483527394855 0.1935880713720681" name="0/1/2/3/5/">
              <joint name="0/1/2/3/5/joint/" class="0/1/2/3/" type="hinge" axis="0.98052445766891561 0.08783464444403577 -0.17566121697309439" limited="true" range="-55.90716460104322 55.90716460104322"/>
              <geom name="0/1/2/3/5/geom" class="0/1/2/3/5/" type="capsule" contype="1" conaffinity="1" condim="3" size="0.043046454575953977" rgba="0.15706439755210944 0.60234569616079503 0.58373300827107566 1" friction="0.59999999999999998 0.10000000000000001 0.10000000000000001" fromto="0 0 0 -0.094392025560534387 0.36839054532852478 -0.037723312480327675"/>
              <site name="0/1/2/3/5/end5" class="0/1/2/3/5/" size="0.0050000000000000001" pos="-0.094392025560534387 0.36839054532852478 -0.037723312480327675"/>
              <site name="0/1/2/3/5/attach6" class="0/1/2/3/5/" size="9.9999999999999995e-07 9.9999999999999995e-07 9.9999999999999995e-07" pos="-0.042140914584793979 0.16446637745451459 -0.016841410909966083"/>
              <body pos="-0.042140914584793979 0.16446637745451459 -0.016841410909966083" name="0/1/2/3/5/6/">
                <joint name="0/1/2/3/5/6/joint/" class="0/1/2/3/5/" type="hinge" axis="1.3877787807814457e-17 0.10186763704542173 0.99479796165994516" limited="true" range="-58.273484694492055 58.273484694492055"/>
                <geom name="0/1/2/3/5/6/geom" class="0/1/2/3/5/6/" type="capsule" contype="1" conaffinity="1" condim="3" size="0.049697818038163304" rgba="0.20163439574473596 0.89433637515479347 0.61529968997065876 1" friction="0.59999999999999998 0.10000000000000001 0.10000000000000001" fromto="0 0 0 -0.55637964036044707 0.33618555403325034 -0.46018023177206835"/>
                <site name="0/1/2/3/5/6/end6" class="0/1/2/3/5/6/" size="0.0050000000000000001" pos="-0.55637964036044707 0.33618555403325034 -0.46018023177206835"/>
                <site name="0/1/2/3/5/6/attach7" class="0/1/2/3/5/6/" size="9.9999999999999995e-07 9.9999999999999995e-07 9.9999999999999995e-07" pos="-0.49375413179024968 0.29834486079428441 -0.40838282770097967"/>
                <body pos="-0.49375413179024968 0.29834486079428441 -0.40838282770097967" name="0/1/2/3/5/6/7/">
                  <geom name="0/1/2/3/5/6/7/geom" class="0/1/2/3/5/6/7/" type="capsule" contype="1" conaffinity="1" condim="3" size="0.055102846467219718" rgba="0.79159022553718361 0.99237568368028173 0.60665828982257064 1" friction="0.59999999999999998 0.10000000000000001 0.10000000000000001" fromto="0 0 0 -0.28493705300787486 -0.68075206708755542 -0.33412636432559434"/>
                  <site name="0/1/2/3/5/6/7/end7" class="0/1/2/3/5/6/7/" size="0.0050000000000000001" pos="-0.28493705300787486 -0.68075206708755542 -0.33412636432559434"/>
                  <site name="0/1/2/3/5/6/7/attach8" class="0/1/2/3/5/6/7/" size="9.9999999999999995e-07 9.9999999999999995e-07 9.9999999999999995e-07" pos="-0.0064842641133138566 -0.015491759152004941 -0.0076036569152296406"/>
                  <body pos="-0.0064842641133138566 -0.015491759152004941 -0.0076036569152296406" name="0/1/2/3/5/6/7/8/">
                    <joint name="0/1/2/3/5/6/7/8/joint/" class="0/1/2/3/5/6/7/" type="hinge" axis="0.9361003105455783 -0.31575065004897701 -0.15497656464807869" limited="true" range="-61.682763891647795 61.682763891647795"/>
                    <geom name="0/1/2/3/5/6/7/8/geom" class="0/1/2/3/5/6/7/8/" type="capsule" contype="1" conaffinity="1" condim="3" size="0.044935037178093787" rgba="0.90839941140076996 0.62618413328550648 0.24478918426719132 1" friction="0.59999999999999998 0.10000000000000001 0.10000000000000001" fromto="0 0 0 -0.370085253138623 -0.10339566976079118 -0.24419260607635673"/>
                    <site name="0/1/2/3/5/6/7/8/end8" class="0/1/2/3/5/6/7/8/" size="0.0050000000000000001" pos="-0.370085253138623 -0.10339566976079118 -0.24419260607635673"/>
                  </body>
                </body>
                <site name="0/1/2/3/5/6/attach9" class="0/1/2/3/5/6/" size="9.9999999999999995e-07 9.9999999999999995e-07 9.9999999999999995e-07" pos="-0.45393516279182128 0.27428473856354085 -0.37544865640249259"/>
                <body pos="-0.45393516279182128 0.27428473856354085 -0.37544865640249259" name="0/1/2/3/5/6/9/">
                  <joint name="0/1/2/3/5/6/9/joint/" class="0/1/2/3/5/6/" type="hinge" axis="-0.71554395108074553 -0.41208663158140557 0.56407575922356967" limited="true" range="-69.720510534845644 69.720510534845644"/>
                  <geom name="0/1/2/3/5/6/9/geom" class="0/1/2/3/5/6/9/" type="capsule" contype="1" conaffinity="1" condim="3" size="0.05235680004135633" rgba="0.54820434994567757 0.68453855739250868 0.66054635078203428 1" friction="0.59999999999999998 0.10000000000000001 0.10000000000000001" fromto="0 0 0 0.18199096222090994 0.57475817078003377 -0.62278587395509244"/>
                  <site name="0/1/2/3/5/6/9/end9" class="0/1/2/3/5/6/9/" size="0.0050000000000000001" pos="0.18199096222090994 0.57475817078003377 -0.62278587395509244"/>
                </body>
              </body>
            </body>
          </body>
        </body>
      </body>
      <site name="0/attach10" class="0/" size="9.9999999999999995e-07 9.9999999999999995e-07 9.9999999999999995e-07" pos="0.12424220986803711 -0.12579966118197566 -0.075006856672397496"/>
      <body pos="0.12424220986803711 -0.12579966118197566 -0.075006856672397496" name="0/10/">
        <joint name="0/10/joint/" class="0/" type="hinge" axis="0 0 1" limited="true" range="-67.897848706556516 67.897848706556516"/>
        <geom name="0/10/geom" class="0/10/" type="capsule" contype="1" conaffinity="1" condim="3" size="0.058139338631043466" rgba="0.44705993672785183 0.19999866728701032 0.78107551304779599 1" friction="0.59999999999999998 0.10000000000000001 0.10000000000000001" fromto="0 0 0 -0.45363098348322889 0.64395032360236582 -0.70381581761879142"/>
        <site name="0/10/end10" class="0/10/" size="0.0050000000000000001" pos="-0.45363098348322889 0.64395032360236582 -0.70381581761879142"/>
      </body>
      <camera name="0/iso" class="0/" mode="trackcom" pos="-2.2999999999999998 -2.2999999999999998 1" xyaxes="0.45000000000000001 -0.45000000000000001 0 0.29999999999999999 0.14999999999999999 0.93999999999999995"/>
    </body>
  </worldbody>
  <actuator>
    <motor name="0/1/2/motor" class="0/1/2/" ctrllimited="true" ctrlrange="-1 1" gear="73" joint="0/1/2/joint/"/>
    <motor name="0/1/2/3/motor" class="0/1/2/3/" ctrllimited="true" ctrlrange="-1 1" gear="59" joint="0/1/2/3/joint/"/>
    <motor name="0/1/2/3/4/motor" class="0/1/2/3/4/" ctrllimited="true" ctrlrange="-1 1" gear="76" joint="0/1/2/3/4/joint/"/>
    <motor name="0/1/2/3/5/motor" class="0/1/2/3/5/" ctrllimited="true" ctrlrange="-1 1" gear="88" joint="0/1/2/3/5/joint/"/>
    <motor name="0/1/2/3/5/6/motor" class="0/1/2/3/5/6/" ctrllimited="true" ctrlrange="-1 1" gear="68" joint="0/1/2/3/5/6/joint/"/>
    <motor name="0/1/2/3/5/6/7/8/motor" class="0/1/2/3/5/6/7/8/" ctrllimited="true" ctrlrange="-1 1" gear="98" joint="0/1/2/3/5/6/7/8/joint/"/>
    <motor name="0/1/2/3/5/6/9/motor" class="0/1/2/3/5/6/9/" ctrllimited="true" ctrlrange="-1 1" gear="69" joint="0/1/2/3/5/6/9/joint/"/>
    <motor name="0/10/motor" class="0/10/" ctrllimited="true" ctrlrange="-1 1" gear="67" joint="0/10/joint/"/>
  </actuator>
  <sensor>
    <subtreelinvel name="velocity" body="0/"/>
  </sensor>
</mujoco>
