<mujoco model="morphology">
  <option timestep="0.01"/>
  <default>
    <default class="/"/>
    <default class="0/"/>
    <default class="0/1/"/>
    <default class="0/1/2/"/>
    <default class="0/1/2/3/"/>
    <default class="0/1/2/3/4/"/>
    <default class="0/1/2/3/4/5/"/>
    <default class="0/1/2/3/4/5/6/"/>
    <default class="0/1/2/3/4/5/6/7/"/>
    <default class="0/1/2/3/4/5/6/7/8/"/>
    <default class="0/1/2/3/4/5/6/7/8/9/"/>
  </default>
  <asset>
    <texture name="texplane" type="2d" builtin="checker" rgb1="0.10000000000000001 0.20000000000000001 0.29999999999999999" rgb2="0.20000000000000001 0.29999999999999999 0.40000000000000002" width="300" height="300"/>
    <material name="MatPlane" class="/" texture="texplane" texrepeat="20 20" specular="1" shininess="1" reflectance="0.5"/>
  </asset>
  <worldbody>
    <light name="//unnamed_light_0" class="/" directional="true" pos="0 0 1.5" dir="0 0 -1.3" cutoff="100" exponent="1" diffuse="1 1 1" specular="0.10000000000000001 0.10000000000000001 0.10000000000000001"/>
    <geom name="ground" class="/" type="plane" size="15 15 0.5" material="MatPlane" rgba="1 1 1 1"/>
    <site name="body" class="/" size="9.9999999999999995e-07 9.9999999999999995e-07 9.9999999999999995e-07" pos="0 0 1.2006227731704713"/>
    <body pos="0 0 1.2006227731704713" name="0/">
      <freejoint name="0/"/>
      <geom name="0/geom" class="0/" type="capsule" contype="1" conaffinity="1" condim="3" size="0.038940530010809368" rgba="0.1086821345204475 0.44800776809167353 0.017469038524819624 1" friction="0.59999999999999998 0.10000000000000001 0.10000000000000001" fromto="0 0 0 -0.35953545124974301 -0.26066402631519042 -0.011150129195560909"/>
      <site name="0/end0" class="0/" size="0.0050000000000000001" pos="-0.35953545124974301 -0.26066402631519042 -0.011150129195560909"/>
      <site name="0/attach1" class="0/" size="9.9999999999999995e-07 9.9999999999999995e-07 9.9999999999999995e-07" pos="-0.35404465428446041 -0.25668318592886757 -0.010979845304677039"/>
      <body pos="-0.35404465428446041 -0.25668318592886757 -0.010979845304677039" name="0/1/">
        <geom name="0/1/geom" class="0/1/" type="capsule" contype="1" conaffinity="1" condim="3" size="0.040386864735102945" rgba="0.82363997649118958 0.42053726563186755 0.2005989204442451 1" friction="0.59999999999999998 0.10000000000000001 0.10000000000000001" fromto="0 0 0 -0.052921609416916371 -0.50437031093216522 -0.53550979489500872"/>
        <site name="0/1/end1" class="0/1/" size="0.0050000000000000001" pos="-0.052921609416916371 -0.50437031093216522 -0.53550979489500872"/>
        <site name="0/1/attach2" class="0/1/" size="9.9999999999999995e-07 9.9999999999999995e-07 9.9999999999999995e-07" pos="-0.022098545172379483 -0.21061056575083623 -0.22361352050937991"/>
        <body pos="-0.022098545172379483 -0.21061056575083623 -0.22361352050937991" name="0/1/2/">
          <geom name="0/1/2/geom" class="0/1/2/" type="capsule" contype="1" conaffinity="1" condim="3" size="0.065019214515735113" rgba="0.13396903898127044 0.52017416672401395 0.41690419356597885 1" friction="0.59999999999999998 0.10000000000000001 0.10000000000000001" fromto="0 0 0 -0.71957589130582655 -0.098166388974254781 0.10383452693976958"/>
          <site name="0/1/2/end2" class="0/1/2/" size="0.0050000000000000001" pos="-0.71957589130582655 -0.098166388974254781 0.10383452693976958"/>
          <site name="0/1/2/attach3" class="0/1/2/" size="9.9999999999999995e-07 9.9999999999999995e-07 9.9999999999999995e-07" pos="-0.54248035368803305 -0.074006561440504937 0.078279708339166379"/>
          <body pos="-0.54248035368803305 -0.074006561440504937 0.078279708339166379" name="0/1/2/3/">
            <joint name="0/1/2/3/joint/" class="0/1/2/" type="hinge" axis="0.19477548235660644 -0.67383755976356208 0.71274501367925358" limited="true" range="-39.304901029200281 39.304901029200281"/>
            <geom name="0/1/2/3/geom" class="0/1/2/3/" type="capsule" contype="1" conaffinity="1" condim="3" size="0.065924088626361566" rgba="0.91012678736875641 0.06705919320056275 0.70325421730724658 1" friction="0.59999999999999998 0.10000000000000001 0.10000000000000001" fromto="0 0 0 0.52641179382782299 0.23260334707493391 0.45341986943469159"/>
            <site name="0/1/2/3/end3" class="0/1/2/3/" size="0.0050000000000000001" pos="0.52641179382782299 0.23260334707493391 0.45341986943469159"/>
            <site name="0/1/2/3/attach4" class="0/1/2/3/" size="9.9999999999999995e-07 9.9999999999999995e-07 9.9999999999999995e-07" pos="0.27716041278295178 0.12246769629000942 0.23872952629479832"/>
            <body pos="0.27716041278295178 0.12246769629000942 0.23872952629479832" name="0/1/2/3/4/">
              <joint name="0/1/2/3/4/joint/" class="0/1/2/3/" type="hinge" axis="-0.69554189312107972 0.32794659290048422 0.63927498552540651" limited="true" range="-47.839129866391318 47.839129866391318"/>
              <geom name="0/1/2/3/4/geom" class="0/1/2/3/4/" type="capsule" contype="1" conaffinity="1" condim="3" size="0.042481214520691334" rgba="0.18500733239257094 0.83818178624212336 0.7758031788061297 1" friction="0.59999999999999998 0.10000000000000001 0.10000000000000001" fromto="0 0 0 0.16864851012531146 -0.67477815935355423 0.26469034181615125"/>
              <site name="0/1/2/3/4/end4" class="0/1/2/3/4/" size="0.0050000000000000001" pos="0.16864851012531146 -0.67477815935355423 0.26469034181615125"/>
              <site name="0/1/2/3/4/attach5" class="0/1/2/3/4/" size="9.9999999999999995e-07 9.9999999999999995e-07 9.9999999999999995e-07" pos="0.018555451283167802 -0.074242062699084246 0.029122396272847347"/>
              <body pos="0.018555451283167802 -0.074242062699084246 0.029122396272847347" name="0/1/2/3/4/5/">
                <geom name="0/1/2/3/4/5/geom" class="0/1/2/3/4/5/" type="capsule" contype="1" conaffinity="1" condim="3" size="0.04252038011680552" rgba="0.60623224708339496 0.2403239708005519 0.062996036193933902 1" friction="0.59999999999999998 0.10000000000000001 0.10000000000000001" fromto="0 0 0 -0.69832292784792327 0.041761816360582071 -0.023288239955856938"/>
                <site name="0/1/2/3/4/5/end5" class="0/1/2/3/4/5/" size="0.0050000000000000001" pos="-0.69832292784792327 0.041761816360582071 -0.023288239955856938"/>
                <site name="0/1/2/3/4/5/attach6" class="0/1/2/3/4/5/" size="9.9999999999999995e-07 9.9999999999999995e-07 9.9999999999999995e-07" pos="-0.11778738700956155 0.0070440408437475134 -0.0039280694118200617"/>
                <body pos="-0.11778738700956155 0.0070440408437475134 -0.0039280694118200617" name="0/1/2/3/4/5/6/">
                  <joint name="0/1/2/3/4/5/6/joint/" class="0/1/2/3/4/5/" type="hinge" axis="-3.4694469519536142e-18 0.48703634984431893 0.8733817000202847" limited="true" range="-60.601881447400771 60.601881447400771"/>
                  <geom name="0/1/2/3/4/5/6/geom" class="0/1/2/3/4/5/6/" type="capsule" contype="1" conaffinity="1" condim="3" size="0.036149590727103026" rgba="0.15492161813384175 0.63073858594731091 0.0059380148349840178 1" friction="0.59999999999999998 0.10000000000000001 0.10000000000000001" fromto="0 0 0 -0.024468894413686826 -0.59554082304504474 -0.71672400690042237"/>
                  <site name="0/1/2/3/4/5/6/end6" class="0/1/2/3/4/5/6/" size="0.0050000000000000001" pos="-0.024468894413686826 -0.59554082304504474 -0.71672400690042237"/>
                  <site name="0/1/2/3/4/5/6/attach7" class="0/1/2/3/4/5/6/" size="9.9999999999999995e-07 9.9999999999999995e-07 9.9999999999999995e-07" pos="-0.0030827912080989496 -0.075031097944512723 -0.090298745409198786"/>
                  <body pos="-0.0030827912080989496 -0.075031097944512723 -0.090298745409198786" name="0/1/2/3/4/5/6/7/">
                    <joint name="0/1/2/3/4/5/6/7/joint/" class="0/1/2/3/4/5/6/" type="hinge" axis="-5.5511151231257827e-17 -0.76913310195113427 0.63908862568741298" limited="true" range="-66.167370212590257 66.167370212590257"/>
                    <geom name="0/1/2/3/4/5/6/7/geom" class="0/1/2/3/4/5/6/7/" type="capsule" contype="1" conaffinity="1" condim="3" size="0.035302943245964606" rgba="0.17084768185522115 0.48007707855584014 0.76569240451426768 1" friction="0.59999999999999998 0.10000000000000001 0.10000000000000001" fromto="0 0 0 -0.63534115332758834 0.093876534992322735 -0.27739520921448463"/>
                    <site name="0/1/2/3/4/5/6/7/end7" class="0/1/2/3/4/5/6/7/" size="0.0050000000000000001" pos="-0.63534115332758834 0.093876534992322735 -0.27739520921448463"/>
                    <site name="0/1/2/3/4/5/6/7/attach8" class="0/1/2/3/4/5/6/7/" size="9.9999999999999995e-07 9.9999999999999995e-07 9.9999999999999995e-07" pos="-0.41952248636909056 0.0619876694047359 -0.18316699188621785"/>
                    <body pos="-0.41952248636909056 0.0619876694047359 -0.18316699188621785" name="0/1/2/3/4/5/6/7/8/">
                      <joint name="0/1/2/3/4/5/6/7/8/joint/" class="0/1/2/3/4/5/6/7/" type="hinge" axis="0 0.94722745256815244 0.32056224528357719" limited="true" range="-55.599043005442468 55.599043005442468"/>
                      <geom name="0/1/2/3/4/5/6/7/8/geom" class="0/1/2/3/4/5/6/7/8/" type="capsule" contype="1" conaffinity="1" condim="3" size="0.037377210023024472" rgba="0.96013162381673756 0.75074358907755112 0.96856941851099687 1" friction="0.59999999999999998 0.10000000000000001 0.10000000000000001" fromto="0 0 0 -0.11312666792829007 0.33677816021655027 -0.51815923086694626"/>
                      <site name="0/1/2/3/4/5/6/7/8/end8" class="0/1/2/3/4/5/6/7/8/" size="0.0050000000000000001" pos="-0.11312666792829007 0.33677816021655027 -0.51815923086694626"/>
                      <site name="0/1/2/3/4/5/6/7/8/attach9" class="0/1/2/3/4/5/6/7/8/" size="9.9999999999999995e-07 9.9999999999999995e-07 9.9999999999999995e-07" pos="-0.10825693833904207 0.32228097222495639 -0.495854186577175"/>
                      <body pos="-0.10825693833904207 0.32228097222495639 -0.495854186577175" name="0/1/2/3/4/5/6/7/8/9/">
                        <joint name="0/1/2/3/4/5/6/7/8/9/joint/" class="0/1/2/3/4/5/6/7/8/" type="hinge" axis="-0.98365480951236584 -0.098127851638775521 0.1509772845694019" limited="true" range="-68.885540299807701 68.885540299807701"/>
                        <geom name="0/1/2/3/4/5/6/7/8/9/geom" class="0/1/2/3/4/5/6/7/8/9/" type="capsule" contype="1" conaffinity="1" condim="3" size="0.053497149989515734" rgba="0.98633894292191893 0.77573133650337089 0.18598269949270996 1" friction="0.59999999999999998 0.10000000000000001 0.10000000000000001" fromto="0 0 0 0.13262881239044577 -0.21496745652930183 -0.43891299436665565"/>
                        <site name="0/1/2/3/4/5/6/7/8/9/end9" class="0/1/2/3/4/5/6/7/8/9/" size="0.0050000000000000001" pos="0.13262881239044577 -0.21496745652930183 -0.43891299436665565"/>
                      </body>
                    </body>
                  </body>
                </body>
              </body>
            </body>
          </body>
        </body>
      </body>
      <camera name="0/iso" class="0/" mode="trackcom" pos="-2.2999999999999998 -2.2999999999999998 1" xyaxes="0.45000000000000001 -0.45000000000000001 0 0.29999999999999999 0.14999999999999999 0.93999999999999995"/>
    </body>
  </worldbody>
  <actuator>
    <motor name="0/1/2/3/motor" class="0/1/2/3/" ctrllimited="true" ctrlrange="-1 1" gear="60" joint="0/1/2/3/joint/"/>
    <motor name="0/1/2/3/4/motor" class="0/1/2/3/4/" ctrllimited="true" ctrlrange="-1 1" gear="78" joint="0/1/2/3/4/joint/"/>
    <motor name="0/1/2/3/4/5/6/motor" class="0/1/2/3/4/5/6/" ctrllimited="true" ctrlrange="-1 1" gear="58" joint="0/1/2/3/4/5/6/joint/"/>
    <motor name="0/1/2/3/4/5/6/7/motor" class="0/1/2/3/4/5/6/7/" ctrllimited="true" ctrlrange="-1 1" gear="52" joint="0/1/2/3/4/5/6/7/joint/"/>
    <motor name="0/1/2/3/4/5/6/7/8/motor" class="0/1/2/3/4/5/6/7/8/" ctrllimited="true" ctrlrange="-1 1" gear="79" joint="0/1/2/3/4/5/6/7/8/joint/"/>
    <motor name="0/1/2/3/4/5/6/7/8/9/motor" class="0/1/2/3/4/5/6/7/8/9/" ctrllimited="true" ctrlrange="-1 1" gear="61" joint="0/1/2/3/4/5/6/7/8/9/joint/"/>
  </actuator>
  <sensor>
    <subtreelinvel name="velocity" body="0/"/>
  </sensor>
</mujoco>
