<mujoco model="morphology">
  <option timestep="0.01"/>
  <default>
    <default class="/"/>
    <default class="0/"/>
    <default class="0/1/"/>
    <default class="0/1/2/"/>
    <default class="0/1/2/3/"/>
  </default>
  <asset>
    <texture name="texplane" type="2d" builtin="checker" rgb1="0.10000000000000001 0.20000000000000001 0.29999999999999999" rgb2="0.20000000000000001 0.29999999999999999 0.40000000000000002" width="300" height="300"/>
    <material name="MatPlane" class="/" texture="texplane" texrepeat="20 20" specular="1" shininess="1" reflectance="0.5"/>
  </asset>
  <worldbody>
    <light name="//unnamed_light_0" class="/" directional="true" pos="0 0 1.5" dir="0 0 -1.3" cutoff="100" exponent="1" diffuse="1 1 1" specular="0.10000000000000001 0.10000000000000001 0.10000000000000001"/>
    <geom name="ground" class="/" type="plane" size="15 15 0.5" material="MatPlane" rgba="1 1 1 1"/>
    <site name="body" class="/" size="9.9999999999999995e-07 9.9999999999999995e-07 9.9999999999999995e-07" pos="0 0 1.4410753011703492"/>
    <body pos="0 0 1.4410753011703492" name="0/">
      <freejoint name="0/"/>
      <geom name="0/geom" class="0/" type="capsule" contype="1" conaffinity="1" condim="3" size="0.054595993629460562" rgba="0.38818155562486079 0.45291219749374456 0.13076569958014861 1" friction="0.59999999999999998 0.10000000000000001 0.10000000000000001" fromto="0 0 0 0.37988380172606684 -0.080791315576699496 -0.69878355391093327"/>
      <site name="0/end0" class="0/" size="0.0050000000000000001" pos="0.37988380172606684 -0.080791315576699496 -0.69878355391093327"/>
      <site name="0/attach1" class="0/" size="9.9999999999999995e-07 9.9999999999999995e-07 9.9999999999999995e-07" pos="0.3174515824798041 -0.067513620912277597 -0.58394157369165278"/>
      <body pos="0.3174515824798041 -0.067513620912277597 -0.58394157369165278" name="0/1/">
        <joint name="0/1/joint/" class="0/" type="hinge" axis="0 0 1" limited="true" range="-49.914592448607436 49.914592448607436"/>
        <geom name="0/1/geom" class="0/1/" type="capsule" contype="1" conaffinity="1" condim="3" size="0.054621175102137355" rgba="0.21260407189656105 0.059674658650592183 0.98939144996074602 1" friction="0.59999999999999998 0.10000000000000001 0.10000000000000001" fromto="0 0 0 -0.37323277320589432 0.37986152697820397 0.18641881445680486"/>
        <site name="0/1/end1" class="0/1/" size="0.0050000000000000001" pos="-0.37323277320589432 0.37986152697820397 0.18641881445680486"/>
        <site name="0/1/attach2" class="0/1/" size="9.9999999999999995e-07 9.9999999999999995e-07 9.9999999999999995e-07" pos="-0.025259826088390558 0.025708450055769046 0.012616541662018421"/>
        <body pos="-0.025259826088390558 0.025708450055769046 0.012616541662018421" name="0/1/2/">
          <joint name="0/1/2/joint/" class="0/1/" type="hinge" axis="-2.7755575615628914e-17 -0.44056147315425725 0.89772244506425825" limited="true" range="-45.92360462736255 45.92360462736255"/>
          <geom name="0/1/2/geom" class="0/1/2/" type="capsule" contype="1" conaffinity="1" condim="3" size="0.059102175632771439" rgba="0.30392772605564655 0.1080046486393339 0.18907534101147072 1" friction="0.59999999999999998 0.10000000000000001 0.10000000000000001" fromto="0 0 0 -0.21260981812243496 -0.05912294417273678 -0.19680231806892778"/>
          <site name="0/1/2/end2" class="0/1/2/" size="0.0050000000000000001" pos="-0.21260981812243496 -0.05912294417273678 -0.19680231806892778"/>
          <site name="0/1/2/attach3" class="0/1/2/" size="9.9999999999999995e-07 9.9999999999999995e-07 9.9999999999999995e-07" pos="-0.20123397914796548 -0.055959529150114026 -0.18627227058605378"/>
          <body pos="-0.20123397914796548 -0.055959529150114026 -0.18627227058605378" name="0/1/2/3/">
            <joint name="0/1/2/3/joint/" class="0/1/2/" type="hinge" axis="0.6949669835985498 -0.20687911820223129 -0.68863772925958655" limited="true" range="-46.183877347051045 46.183877347051045"/>
            <geom name="0/1/2/3/geom" class="0/1/2/3/" type="capsule" contype="1" conaffinity="1" condim="3" size="0.043159683734529074" rgba="0.16930525738762514 0.17815133815356654 0.6411530838806635 1" friction="0.59999999999999998 0.10000000000000001 0.10000000000000001" fromto="0 0 0 0.50754138480189903 -0.2899188480399788 -0.58347800738357236"/>
            <site name="0/1/2/3/end3" class="0/1/2/3/" size="0.0050000000000000001" pos="0.50754138480189903 -0.2899188480399788 -0.58347800738357236"/>
          </body>
        </body>
      </body>
      <camera name="0/iso" class="0/" mode="trackcom" pos="-2.2999999999999998 -2.2999999999999998 1" xyaxes="0.45000000000000001 -0.45000000000000001 0 0.29999999999999999 0.14999999999999999 0.93999999999999995"/>
    </body>
  </worldbody>
  <actuator>
    <motor name="0/1/motor" class="0/1/" ctrllimited="true" ctrlrange="-1 1" gear="50" joint="0/1/joint/"/>
    <motor name="0/1/2/motor" class="0/1/2/" ctrllimited="true" ctrlrange="-1 1" gear="68" joint="0/1/2/joint/"/>
    <motor name="0/1/2/3/motor" class="0/1/2/3/" ctrllimited="true" ctrlrange="-1 1" gear="92" joint="0/1/2/3/joint/"/>
  </actuator>
  <sensor>
    <subtreelinvel name="velocity" body="0/"/>
  </sensor>
</mujoco>
