<mujoco model="morphology">
  <option timestep="0.01"/>
  <default>
    <default class="/"/>
    <default class="0/"/>
    <default class="0/1/"/>
    <default class="0/1/2/"/>
    <default class="0/1/2/3/"/>
    <default class="0/1/2/3/4/"/>
    <default class="0/1/2/3/4/5/"/>
    <default class="0/1/2/3/4/6/"/>
    <default class="0/1/2/3/4/6/7/"/>
    <default class="0/1/2/3/8/"/>
    <default class="0/1/2/3/8/9/"/>
    <default class="0/1/2/3/10/"/>
  </default>
  <asset>
    <texture name="texplane" type="2d" builtin="checker" rgb1="0.10000000000000001 0.20000000000000001 0.29999999999999999" rgb2="0.20000000000000001 0.29999999999999999 0.40000000000000002" width="300" height="300"/>
    <material name="MatPlane" class="/" texture="texplane" texrepeat="20 20" specular="1" shininess="1" reflectance="0.5"/>
  </asset>
  <worldbody>
    <light name="//unnamed_light_0" class="/" directional="true" pos="0 0 1.5" dir="0 0 -1.3" cutoff="100" exponent="1" diffuse="1 1 1" specular="0.10000000000000001 0.10000000000000001 0.10000000000000001"/>
    <geom name="ground" class="/" type="plane" size="15 15 0.5" material="MatPlane" rgba="1 1 1 1"/>
    <site name="body" class="/" size="9.9999999999999995e-07 9.9999999999999995e-07 9.9999999999999995e-07" pos="0 0 0.64906880855560301"/>
    <body pos="0 0 0.64906880855560301" name="0/">
      <freejoint name="0/"/>
      <geom name="0/geom" class="0/" type="capsule" contype="1" conaffinity="1" condim="3" size="0.04353381015723555" rgba="0.42503061692901922 0.6614471519441858 0.85035949658639498 1" friction="0.59999999999999998 0.10000000000000001 0.10000000000000001" fromto="0 0 0 0.11749952604805358 -0.66464146303834526 0.67153993454337679"/>
      <site name="0/end0" class="0/" size="0.0050000000000000001" pos="0.11749952604805358 -0.66464146303834526 0.67153993454337679"/>
      <site name="0/attach1" class="0/" size="9.9999999999999995e-07 9.9999999999999995e-07 9.9999999999999995e-07" pos="0.11332940405267732 -0.64105297653737203 0.64770661754201631"/>
      <body pos="0.11332940405267732 -0.64105297653737203 0.64770661754201631" name="0/1/">
        <geom name="0/1/geom" class="0/1/" type="capsule" contype="1" conaffinity="1" condim="3" size="0.052210280440735654" rgba="0.061347893849859059 0.51456053378522848 0.24090498683330852 1" friction="0.59999999999999998 0.10000000000000001 0.10000000000000001" fromto="0 0 0 0.20288729687383567 0.62417572491706141 0.19652056738279344"/>
        <site name="0/1/end1" class="0/1/" size="0.0050000000000000001" pos="0.20288729687383567 0.62417572491706141 0.19652056738279344"/>
        <site name="0/1/attach2" class="0/1/" size="9.9999999999999995e-07 9.9999999999999995e-07 9.9999999999999995e-07" pos="0.14735775788725064 0.45334102611965382 0.14273357984687771"/>
        <body pos="0.14735775788725064 0.45334102611965382 0.14273357984687771" name="0/1/2/">
          <joint name="0/1/2/joint/" class="0/1/" type="hinge" axis="2.7755575615628914e-17 -0.30031479760854007 0.95384014506485393" limited="true" range="-35.013465774508759 35.013465774508759"/>
          <geom name="0/1/2/geom" class="0/1/2/" type="capsule" contype="1" conaffinity="1" condim="3" size="0.052699470052900772" rgba="0.25323495684970787 0.56608703312154662 0.11252545274975101 1" friction="0.59999999999999998 0.10000000000000001 0.10000000000000001" fromto="0 0 0 0.69652851433841168 0.49137260228914026 -0.42824395575534918"/>
          <site name="0/1/2/end2" class="0/1/2/" size="0.0050000000000000001" pos="0.69652851433841168 0.49137260228914026 -0.42824395575534918"/>
          <site name="0/1/2/attach3" class="0/1/2/" size="9.9999999999999995e-07 9.9999999999999995e-07 9.9999999999999995e-07" pos="0.69399405321285357 0.48958464281148834 -0.42668570273946499"/>
          <body pos="0.69399405321285357 0.48958464281148834 -0.42668570273946499" name="0/1/2/3/">
            <joint name="0/1/2/3/joint/" class="0/1/2/" type="hinge" axis="0 0.65701998940238215 0.75387315479840078" limited="true" range="-36.421717875796084 36.421717875796084"/>
            <geom name="0/1/2/3/geom" class="0/1/2/3/" type="capsule" contype="1" conaffinity="1" condim="3" size="0.058136188378610273" rgba="0.43210828782000399 0.71075076910117874 0.42200533825455633 1" friction="0.59999999999999998 0.10000000000000001 0.10000000000000001" fromto="0 0 0 -0.54550044891232852 0.62323641745530622 -0.26097306439067891"/>
            <site name="0/1/2/3/end3" class="0/1/2/3/" size="0.0050000000000000001" pos="-0.54550044891232852 0.62323641745530622 -0.26097306439067891"/>
            <site name="0/1/2/3/attach4" class="0/1/2/3/" size="9.9999999999999995e-07 9.9999999999999995e-07 9.9999999999999995e-07" pos="-0.052289979807099214 0.059741508460288077 -0.025016067895809558"/>
            <body pos="-0.052289979807099214 0.059741508460288077 -0.025016067895809558" name="0/1/2/3/4/">
              <joint name="0/1/2/3/4/joint/" class="0/1/2/3/" type="hinge" axis="0 0.38624311599782724 0.92239701611848735" limited="true" range="-47.974241820826222 47.974241820826222"/>
              <geom name="0/1/2/3/4/geom" class="0/1/2/3/4/" type="capsule" contype="1" conaffinity="1" condim="3" size="0.061688310551178724" rgba="0.10577553878162504 0.51197180052503699 0.23789610363448155 1" friction="0.59999999999999998 0.10000000000000001 0.10000000000000001" fromto="0 0 0 -0.131878554910557 -0.13235939071999303 0.70276543950590109"/>
              <site name="0/1/2/3/4/end4" class="0/1/2/3/4/" size="0.0050000000000000001" pos="-0.131878554910557 -0.13235939071999303 0.70276543950590109"/>
              <site name="0/1/2/3/4/attach5" class="0/1/2/3/4/" size="9.9999999999999995e-07 9.9999999999999995e-07 9.9999999999999995e-07" pos="-0.10247542711632876 -0.10284905765071095 0.54607960046881554"/>
              <body pos="-0.10247542711632876 -0.10284905765071095 0.54607960046881554" name="0/1/2/3/4/5/">
                <joint name="0/1/2/3/4/5/joint/" class="0/1/2/3/4/" type="hinge" axis="0.98341746940689378 -0.033566619236143375 0.17822279017677883" limited="true" range="-64.010133863230934 64.010133863230934"/>
                <geom name="0/1/2/3/4/5/geom" class="0/1/2/3/4/5/" type="capsule" contype="1" conaffinity="1" condim="3" size="0.041797088924894275" rgba="0.76428675282517922 0.68625831401048942 0.59904685848753081 1" friction="0.59999999999999998 0.10000000000000001 0.10000000000000001" fromto="0 0 0 0.19149675959025592 -0.39809810202148976 -0.20507818736346639"/>
                <site name="0/1/2/3/4/5/end5" class="0/1/2/3/4/5/" size="0.0050000000000000001" pos="0.19149675959025592 -0.39809810202148976 -0.20507818736346639"/>
              </body>
              <site name="0/1/2/3/4/attach6" class="0/1/2/3/4/" size="9.9999999999999995e-07 9.9999999999999995e-07 9.9999999999999995e-07" pos="-0.064209170482306011 -0.064443280330438751 0.34216318145820768"/>
              <body pos="-0.064209170482306011 -0.064443280330438751 0.34216318145820768" name="0/1/2/3/4/6/">
                <joint name="0/1/2/3/4/6/joint/" class="0/1/2/3/4/" type="hinge" axis="0.98341746940689378 -0.033566619236143375 0.17822279017677883" limited="true" range="-56.349977757106686 56.349977757106686"/>
                <geom name="0/1/2/3/4/6/geom" class="0/1/2/3/4/6/" type="capsule" contype="1" conaffinity="1" condim="3" size="0.066744560987104767" rgba="0.76347377090547075 0.32704354800325064 0.24831995658214856 1" friction="0.59999999999999998 0.10000000000000001 0.10000000000000001" fromto="0 0 0 0.66442338285563474 0.37356227437051204 -0.40888148541910319"/>
                <site name="0/1/2/3/4/6/end6" class="0/1/2/3/4/6/" size="0.0050000000000000001" pos="0.66442338285563474 0.37356227437051204 -0.40888148541910319"/>
                <site name="0/1/2/3/4/6/attach7" class="0/1/2/3/4/6/" size="9.9999999999999995e-07 9.9999999999999995e-07 9.9999999999999995e-07" pos="0.4177919082263275 0.23489735532762573 -0.25710620733644413"/>
                <body pos="0.4177919082263275 0.23489735532762573 -0.25710620733644413" name="0/1/2/3/4/6/7/">
                  <joint name="0/1/2/3/4/6/7/joint/" class="0/1/2/3/4/6/" type="hinge" axis="-0.64028572572043141 0.51810938647508875 -0.5670951005652114" limited="true" range="-69.634578316270762 69.634578316270762"/>
                  <geom name="0/1/2/3/4/6/7/geom" class="0/1/2/3/4/6/7/" type="capsule" contype="1" conaffinity="1" condim="3" size="0.048749419910886452" rgba="0.19218810282955778 0.19792748503047841 0.72079480146233421 1" friction="0.59999999999999998 0.10000000000000001 0.10000000000000001" fromto="0 0 0 0.44896637801157824 -0.23714185870602322 0.025332695794505367"/>
                  <site name="0/1/2/3/4/6/7/end7" class="0/1/2/3/4/6/7/" size="0.0050000000000000001" pos="0.44896637801157824 -0.23714185870602322 0.025332695794505367"/>
                </body>
              </body>
            </body>
            <site name="0/1/2/3/attach8" class="0/1/2/3/" size="9.9999999999999995e-07 9.9999999999999995e-07 9.9999999999999995e-07" pos="-0.53721839416222938 0.61377413719153673 -0.25701084362276871"/>
            <body pos="-0.53721839416222938 0.61377413719153673 -0.25701084362276871" name="0/1/2/3/8/">
              <joint name="0/1/2/3/8/joint/" class="0/1/2/3/" type="hinge" axis="0 0.38624311599782724 0.92239701611848735" limited="true" range="-48.1372088508638 48.1372088508638"/>
              <geom name="0/1/2/3/8/geom" class="0/1/2/3/8/" type="capsule" contype="1" conaffinity="1" condim="3" size="0.067121555891221374" rgba="0.50625743752202923 0.35397650673866765 0.89687474570462988 1" friction="0.59999999999999998 0.10000000000000001 0.10000000000000001" fromto="0 0 0 -0.74668683699757277 -0.68239877641274826 -0.13359737917838643"/>
              <site name="0/1/2/3/8/end8" class="0/1/2/3/8/" size="0.0050000000000000001" pos="-0.74668683699757277 -0.68239877641274826 -0.13359737917838643"/>
              <site name="0/1/2/3/8/attach9" class="0/1/2/3/8/" size="9.9999999999999995e-07 9.9999999999999995e-07 9.9999999999999995e-07" pos="-0.027859291932822196 -0.025460669432887315 -0.0049845908667099058"/>
              <body pos="-0.027859291932822196 -0.025460669432887315 -0.0049845908667099058" name="0/1/2/3/8/9/">
                <joint name="0/1/2/3/8/9/joint/" class="0/1/2/3/8/" type="hinge" axis="0.68150368145815321 -0.71818077786883927 -0.14060264029772873" limited="true" range="-31.084543222653444 31.084543222653444"/>
                <geom name="0/1/2/3/8/9/geom" class="0/1/2/3/8/9/" type="capsule" contype="1" conaffinity="1" condim="3" size="0.067862349611785874" rgba="0.50615900033679884 0.54600436833034682 0.28551519251840218 1" friction="0.59999999999999998 0.10000000000000001 0.10000000000000001" fromto="0 0 0 0.52822782808559698 0.26385137302484152 -0.65082787301651535"/>
                <site name="0/1/2/3/8/9/end9" class="0/1/2/3/8/9/" size="0.0050000000000000001" pos="0.52822782808559698 0.26385137302484152 -0.65082787301651535"/>
              </body>
            </body>
            <site name="0/1/2/3/attach10" class="0/1/2/3/" size="9.9999999999999995e-07 9.9999999999999995e-07 9.9999999999999995e-07" pos="-0.24094950233471968 0.27528575810001643 -0.11527273737918953"/>
            <body pos="-0.24094950233471968 0.27528575810001643 -0.11527273737918953" name="0/1/2/3/10/">
              <joint name="0/1/2/3/10/joint/" class="0/1/2/3/" type="hinge" axis="0 0.38624311599782724 0.92239701611848735" limited="true" range="-66.319837666114751 66.319837666114751"/>
              <geom name="0/1/2/3/10/geom" class="0/1/2/3/10/" type="capsule" contype="1" conaffinity="1" condim="3" size="0.038943952715266267" rgba="0.072396381652317765 0.43721621056915627 0.040539200883128013 1" friction="0.59999999999999998 0.10000000000000001 0.10000000000000001" fromto="0 0 0 0.044442849806585416 -0.1772830740368283 -0.3186577304917288"/>
              <site name="0/1/2/3/10/end10" class="0/1/2/3/10/" size="0.0050000000000000001" pos="0.044442849806585416 -0.1772830740368283 -0.3186577304917288"/>
            </body>
          </body>
        </body>
      </body>
      <camera name="0/iso" class="0/" mode="trackcom" pos="-2.2999999999999998 -2.2999999999999998 1" xyaxes="0.45000000000000001 -0.45000000000000001 0 0.29999999999999999 0.14999999999999999 0.93999999999999995"/>
    </body>
  </worldbody>
  <actuator>
    <motor name="0/1/2/motor" class="0/1/2/" ctrllimited="true" ctrlrange="-1 1" gear="81" joint="0/1/2/joint/"/>
    <motor name="0/1/2/3/motor" class="0/1/2/3/" ctrllimited="true" ctrlrange="-1 1" gear="50" joint="0/1/2/3/joint/"/>
    <motor name="0/1/2/3/4/motor" class="0/1/2/3/4/" ctrllimited="true" ctrlrange="-1 1" gear="93" joint="0/1/2/3/4/joint/"/>
    <motor name="0/1/2/3/4/5/motor" class="0/1/2/3/4/5/" ctrllimited="true" ctrlrange="-1 1" gear="61" joint="0/1/2/3/4/5/joint/"/>
    <motor name="0/1/2/3/4/6/motor" class="0/1/2/3/4/6/" ctrllimited="true" ctrlrange="-1 1" gear="74" joint="0/1/2/3/4/6/joint/"/>
    <motor name="0/1/2/3/4/6/7/motor" class="0/1/2/3/4/6/7/" ctrllimited="true" ctrlrange="-1 1" gear="78" joint="0/1/2/3/4/6/7/joint/"/>
    <motor name="0/1/2/3/8/motor" class="0/1/2/3/8/" ctrllimited="true" ctrlrange="-1 1" gear="93" joint="0/1/2/3/8/joint/"/>
    <motor name="0/1/2/3/8/9/motor" class="0/1/2/3/8/9/" ctrllimited="true" ctrlrange="-1 1" gear="99" joint="0/1/2/3/8/9/joint/"/>
    <motor name="0/1/2/3/10/motor" class="0/1/2/3/10/" ctrllimited="true" ctrlrange="-1 1" gear="65" joint="0/1/2/3/10/joint/"/>
  </actuator>
  <sensor>
    <subtreelinvel name="velocity" body="0/"/>
  </sensor>
</mujoco>
