<mujoco model="morphology">
  <option timestep="0.01"/>
  <default>
    <default class="/"/>
    <default class="0/"/>
    <default class="0/1/"/>
    <default class="0/1/2/"/>
    <default class="0/1/2/3/"/>
    <default class="0/1/2/3/4/"/>
    <default class="0/1/2/3/4/5/"/>
    <default class="0/1/6/"/>
  </default>
  <asset>
    <texture name="texplane" type="2d" builtin="checker" rgb1="0.10000000000000001 0.20000000000000001 0.29999999999999999" rgb2="0.20000000000000001 0.29999999999999999 0.40000000000000002" width="300" height="300"/>
    <material name="MatPlane" class="/" texture="texplane" texrepeat="20 20" specular="1" shininess="1" reflectance="0.5"/>
  </asset>
  <worldbody>
    <light name="//unnamed_light_0" class="/" directional="true" pos="0 0 1.5" dir="0 0 -1.3" cutoff="100" exponent="1" diffuse="1 1 1" specular="0.10000000000000001 0.10000000000000001 0.10000000000000001"/>
    <geom name="ground" class="/" type="plane" size="15 15 0.5" material="MatPlane" rgba="1 1 1 1"/>
    <site name="body" class="/" size="9.9999999999999995e-07 9.9999999999999995e-07 9.9999999999999995e-07" pos="0 0 0.81836608648300169"/>
    <body pos="0 0 0.81836608648300169" name="0/">
      <freejoint name="0/"/>
      <geom name="0/geom" class="0/" type="capsule" contype="1" conaffinity="1" condim="3" size="0.058792793387202516" rgba="0.38898844939692689 0.52647775783648543 0.92686428590515235 1" friction="0.59999999999999998 0.10000000000000001 0.10000000000000001" fromto="0 0 0 0.011953510098899556 0.22832030845068441 -0.04162833202167282"/>
      <site name="0/end0" class="0/" size="0.0050000000000000001" pos="0.011953510098899556 0.22832030845068441 -0.04162833202167282"/>
      <site name="0/attach1" class="0/" size="9.9999999999999995e-07 9.9999999999999995e-07 9.9999999999999995e-07" pos="0.0072949880865528574 0.13933931676011646 -0.025404938269063475"/>
      <body pos="0.0072949880865528574 0.13933931676011646 -0.025404938269063475" name="0/1/">
        <joint name="0/1/joint/" class="0/" type="hinge" axis="0 0 1" limited="true" range="-51.278291191068611 51.278291191068611"/>
        <geom name="0/1/geom" class="0/1/" type="capsule" contype="1" conaffinity="1" condim="3" size="0.062382780362101098" rgba="0.21629390654676384 0.61046954297445655 0.16146321173280798 1" friction="0.59999999999999998 0.10000000000000001 0.10000000000000001" fromto="0 0 0 0.58369149160743095 0.45391318411958625 -0.69296112563154444"/>
        <site name="0/1/end1" class="0/1/" size="0.0050000000000000001" pos="0.58369149160743095 0.45391318411958625 -0.69296112563154444"/>
        <site name="0/1/attach2" class="0/1/" size="9.9999999999999995e-07 9.9999999999999995e-07 9.9999999999999995e-07" pos="0.14572792688547614 0.11332669442476864 -0.17300884063327904"/>
        <body pos="0.14572792688547614 0.11332669442476864 -0.17300884063327904" name="0/1/2/">
          <joint name="0/1/2/joint/" class="0/1/" type="hinge" axis="5.5511151231257827e-17 0.83651415418674202 0.54794531647349609" limited="true" range="-40.263520702968961 40.263520702968961"/>
          <geom name="0/1/2/geom" class="0/1/2/" type="capsule" contype="1" conaffinity="1" condim="3" size="0.065743769474183256" rgba="0.7038342382147843 0.56944320370942458 0.98837107661597701 1" friction="0.59999999999999998 0.10000000000000001 0.10000000000000001" fromto="0 0 0 0.51565287637297375 -0.46604540586725257 0.036591947361030663"/>
          <site name="0/1/2/end2" class="0/1/2/" size="0.0050000000000000001" pos="0.51565287637297375 -0.46604540586725257 0.036591947361030663"/>
          <site name="0/1/2/attach3" class="0/1/2/" size="9.9999999999999995e-07 9.9999999999999995e-07 9.9999999999999995e-07" pos="0.011950479501257211 -0.010800804813979709 0.00084803428214135531"/>
          <body pos="0.011950479501257211 -0.010800804813979709 0.00084803428214135531" name="0/1/2/3/">
            <joint name="0/1/2/3/joint/" class="0/1/2/" type="hinge" axis="3.4694469519536142e-18 0.07827494028175612 0.99693180996690423" limited="true" range="-41.87961404359389 41.87961404359389"/>
            <geom name="0/1/2/3/geom" class="0/1/2/3/" type="capsule" contype="1" conaffinity="1" condim="3" size="0.038379186156690781" rgba="0.81054746389258026 0.6253899915047858 0.71343260477237003 1" friction="0.59999999999999998 0.10000000000000001 0.10000000000000001" fromto="0 0 0 -0.4504099302823053 -0.72041342460300228 -0.03145454291786498"/>
            <site name="0/1/2/3/end3" class="0/1/2/3/" size="0.0050000000000000001" pos="-0.4504099302823053 -0.72041342460300228 -0.03145454291786498"/>
            <site name="0/1/2/3/attach4" class="0/1/2/3/" size="9.9999999999999995e-07 9.9999999999999995e-07 9.9999999999999995e-07" pos="-0.31994156454343603 -0.51173427291248652 -0.022343236675161145"/>
            <body pos="-0.31994156454343603 -0.51173427291248652 -0.022343236675161145" name="0/1/2/3/4/">
              <joint name="0/1/2/3/4/joint/" class="0/1/2/3/" type="hinge" axis="0 -0.043620236552158922 0.99904818450519861" limited="true" range="-35.820502200533141 35.820502200533141"/>
              <geom name="0/1/2/3/4/geom" class="0/1/2/3/4/" type="capsule" contype="1" conaffinity="1" condim="3" size="0.052803919565307798" rgba="0.25842542430711601 0.26212906491860266 0.015433360695269127 1" friction="0.59999999999999998 0.10000000000000001 0.10000000000000001" fromto="0 0 0 0.27835079541173324 0.20586665018906447 0.73070200870698665"/>
              <site name="0/1/2/3/4/end4" class="0/1/2/3/4/" size="0.0050000000000000001" pos="0.27835079541173324 0.20586665018906447 0.73070200870698665"/>
              <site name="0/1/2/3/4/attach5" class="0/1/2/3/4/" size="9.9999999999999995e-07 9.9999999999999995e-07 9.9999999999999995e-07" pos="0.10966142279015456 0.081104958695671206 0.28787351511571924"/>
              <body pos="0.10966142279015456 0.081104958695671206 0.28787351511571924" name="0/1/2/3/4/5/">
                <joint name="0/1/2/3/4/5/joint/" class="0/1/2/3/4/" type="hinge" axis="-0.93887778235147956 0.093354231090432949 0.33135101832389469" limited="true" range="-57.599091629817288 57.599091629817288"/>
                <geom name="0/1/2/3/4/5/geom" class="0/1/2/3/4/5/" type="capsule" contype="1" conaffinity="1" condim="3" size="0.062368098770871384" rgba="0.55856135674075125 0.8847421631082556 0.61692231974835943 1" friction="0.59999999999999998 0.10000000000000001 0.10000000000000001" fromto="0 0 0 0.64472883815016191 -0.5396003950893431 -0.4947831638222695"/>
                <site name="0/1/2/3/4/5/end5" class="0/1/2/3/4/5/" size="0.0050000000000000001" pos="0.64472883815016191 -0.5396003950893431 -0.4947831638222695"/>
              </body>
            </body>
          </body>
        </body>
        <site name="0/1/attach6" class="0/1/" size="9.9999999999999995e-07 9.9999999999999995e-07 9.9999999999999995e-07" pos="0.21743178597010618 0.16908787556025906 -0.2581359799146396"/>
        <body pos="0.21743178597010618 0.16908787556025906 -0.2581359799146396" name="0/1/6/">
          <joint name="0/1/6/joint/" class="0/1/" type="hinge" axis="5.5511151231257827e-17 0.83651415418674202 0.54794531647349609" limited="true" range="-41.016533357773199 41.016533357773199"/>
          <geom name="0/1/6/geom" class="0/1/6/" type="capsule" contype="1" conaffinity="1" condim="3" size="0.043318209888277136" rgba="0.097143724072792925 0.82071278644262335 0.27106501734592003 1" friction="0.59999999999999998 0.10000000000000001 0.10000000000000001" fromto="0 0 0 -0.089032044305898506 0.51342083841404418 0.35237887376314725"/>
          <site name="0/1/6/end6" class="0/1/6/" size="0.0050000000000000001" pos="-0.089032044305898506 0.51342083841404418 0.35237887376314725"/>
        </body>
      </body>
      <camera name="0/iso" class="0/" mode="trackcom" pos="-2.2999999999999998 -2.2999999999999998 1" xyaxes="0.45000000000000001 -0.45000000000000001 0 0.29999999999999999 0.14999999999999999 0.93999999999999995"/>
    </body>
  </worldbody>
  <actuator>
    <motor name="0/1/motor" class="0/1/" ctrllimited="true" ctrlrange="-1 1" gear="86" joint="0/1/joint/"/>
    <motor name="0/1/2/motor" class="0/1/2/" ctrllimited="true" ctrlrange="-1 1" gear="54" joint="0/1/2/joint/"/>
    <motor name="0/1/2/3/motor" class="0/1/2/3/" ctrllimited="true" ctrlrange="-1 1" gear="87" joint="0/1/2/3/joint/"/>
    <motor name="0/1/2/3/4/motor" class="0/1/2/3/4/" ctrllimited="true" ctrlrange="-1 1" gear="91" joint="0/1/2/3/4/joint/"/>
    <motor name="0/1/2/3/4/5/motor" class="0/1/2/3/4/5/" ctrllimited="true" ctrlrange="-1 1" gear="90" joint="0/1/2/3/4/5/joint/"/>
    <motor name="0/1/6/motor" class="0/1/6/" ctrllimited="true" ctrlrange="-1 1" gear="61" joint="0/1/6/joint/"/>
  </actuator>
  <sensor>
    <subtreelinvel name="velocity" body="0/"/>
  </sensor>
</mujoco>
