<mujoco model="morphology">
  <option timestep="0.01"/>
  <default>
    <default class="/"/>
    <default class="0/"/>
    <default class="0/1/"/>
    <default class="0/1/2/"/>
    <default class="0/1/2/3/"/>
    <default class="0/1/4/"/>
    <default class="0/1/4/5/"/>
  </default>
  <asset>
    <texture name="texplane" type="2d" builtin="checker" rgb1="0.10000000000000001 0.20000000000000001 0.29999999999999999" rgb2="0.20000000000000001 0.29999999999999999 0.40000000000000002" width="300" height="300"/>
    <material name="MatPlane" class="/" texture="texplane" texrepeat="20 20" specular="1" shininess="1" reflectance="0.5"/>
  </asset>
  <worldbody>
    <light name="//unnamed_light_0" class="/" directional="true" pos="0 0 1.5" dir="0 0 -1.3" cutoff="100" exponent="1" diffuse="1 1 1" specular="0.10000000000000001 0.10000000000000001 0.10000000000000001"/>
    <geom name="ground" class="/" type="plane" size="15 15 0.5" material="MatPlane" rgba="1 1 1 1"/>
    <site name="body" class="/" size="9.9999999999999995e-07 9.9999999999999995e-07 9.9999999999999995e-07" pos="0 0 1.4767758607864381"/>
    <body pos="0 0 1.4767758607864381" name="0/">
      <freejoint name="0/"/>
      <geom name="0/geom" class="0/" type="capsule" contype="1" conaffinity="1" condim="3" size="0.045754174084655437" rgba="0.2167628434225578 0.25774275525373502 0.70994039981947543 1" friction="0.59999999999999998 0.10000000000000001 0.10000000000000001" fromto="0 0 0 -0.40382255820167612 -0.38490548438161509 -0.56335470511242425"/>
      <site name="0/end0" class="0/" size="0.0050000000000000001" pos="-0.40382255820167612 -0.38490548438161509 -0.56335470511242425"/>
      <site name="0/attach1" class="0/" size="9.9999999999999995e-07 9.9999999999999995e-07 9.9999999999999995e-07" pos="-0.38095537727209799 -0.36310951688703652 -0.53145372853820005"/>
      <body pos="-0.38095537727209799 -0.36310951688703652 -0.53145372853820005" name="0/1/">
        <joint name="0/1/joint/" class="0/" type="hinge" axis="0 1 0" limited="true" range="-35.187781550302006 35.187781550302006"/>
        <geom name="0/1/geom" class="0/1/" type="capsule" contype="1" conaffinity="1" condim="3" size="0.052602176204182574" rgba="0.35348968677809778 0.29878206004848795 0.72074020444463605 1" friction="0.59999999999999998 0.10000000000000001 0.10000000000000001" fromto="0 0 0 -0.70667011177143269 0.54979232846126469 -0.12011783679546939"/>
        <site name="0/1/end1" class="0/1/" size="0.0050000000000000001" pos="-0.70667011177143269 0.54979232846126469 -0.12011783679546939"/>
        <site name="0/1/attach2" class="0/1/" size="9.9999999999999995e-07 9.9999999999999995e-07 9.9999999999999995e-07" pos="-0.29422974587515399 0.22891198367193558 -0.050012360798464571"/>
        <body pos="-0.29422974587515399 0.22891198367193558 -0.050012360798464571" name="0/1/2/">
          <joint name="0/1/2/joint/" class="0/1/" type="hinge" axis="-0.6229553469255239 -0.76423054513454947 0.16696798980717675" limited="true" range="-53.693098651969677 53.693098651969677"/>
          <geom name="0/1/2/geom" class="0/1/2/" type="capsule" contype="1" conaffinity="1" condim="3" size="0.063867502377875862" rgba="0.14328532857821197 0.15566066468628703 0.021362971932857966 1" friction="0.59999999999999998 0.10000000000000001 0.10000000000000001" fromto="0 0 0 -0.70417331247271209 -0.73369850956503868 0.26207834867203017"/>
          <site name="0/1/2/end2" class="0/1/2/" size="0.0050000000000000001" pos="-0.70417331247271209 -0.73369850956503868 0.26207834867203017"/>
          <site name="0/1/2/attach3" class="0/1/2/" size="9.9999999999999995e-07 9.9999999999999995e-07 9.9999999999999995e-07" pos="-0.37163525003122355 -0.38721749918675819 0.1383147456902159"/>
          <body pos="-0.37163525003122355 -0.38721749918675819 0.1383147456902159" name="0/1/2/3/">
            <joint name="0/1/2/3/joint/" class="0/1/2/" type="hinge" axis="2.7755575615628914e-17 0.33638553467418791 0.94172436097934775" limited="true" range="-62.739944578509885 62.739944578509885"/>
            <geom name="0/1/2/3/geom" class="0/1/2/3/" type="capsule" contype="1" conaffinity="1" condim="3" size="0.043270476114878526" rgba="0.54752163949102894 0.35467587794984545 0.39325494924132764 1" friction="0.59999999999999998 0.10000000000000001 0.10000000000000001" fromto="0 0 0 -0.072363833220525087 0.61756364987531964 0.18939987528073121"/>
            <site name="0/1/2/3/end3" class="0/1/2/3/" size="0.0050000000000000001" pos="-0.072363833220525087 0.61756364987531964 0.18939987528073121"/>
          </body>
        </body>
        <site name="0/1/attach4" class="0/1/" size="9.9999999999999995e-07 9.9999999999999995e-07 9.9999999999999995e-07" pos="-0.66866335164992985 0.52022290873288601 -0.1136575525222952"/>
        <body pos="-0.66866335164992985 0.52022290873288601 -0.1136575525222952" name="0/1/4/">
          <joint name="0/1/4/joint/" class="0/1/" type="hinge" axis="0 0.21344379787135104 0.97695534450160715" limited="true" range="-67.388938364994601 67.388938364994601"/>
          <geom name="0/1/4/geom" class="0/1/4/" type="capsule" contype="1" conaffinity="1" condim="3" size="0.052792261831133905" rgba="0.89351463438385026 0.71777587859423175 0.22075225728205161 1" friction="0.59999999999999998 0.10000000000000001 0.10000000000000001" fromto="0 0 0 0.51732085534937 -0.35024229637389154 -0.7316645980750428"/>
          <site name="0/1/4/end4" class="0/1/4/" size="0.0050000000000000001" pos="0.51732085534937 -0.35024229637389154 -0.7316645980750428"/>
          <site name="0/1/4/attach5" class="0/1/4/" size="9.9999999999999995e-07 9.9999999999999995e-07 9.9999999999999995e-07" pos="0.27709959859727434 -0.1876050399542647 -0.39191144980518583"/>
          <body pos="0.27709959859727434 -0.1876050399542647 -0.39191144980518583" name="0/1/4/5/">
            <joint name="0/1/4/5/joint/" class="0/1/4/" type="hinge" axis="0.84313407354540604 0.23216540750200271 0.484999131531345" limited="true" range="-51.448627429940522 51.448627429940522"/>
            <geom name="0/1/4/5/geom" class="0/1/4/5/" type="capsule" contype="1" conaffinity="1" condim="3" size="0.069005569012750956" rgba="0.62819548696228167 0.3362215837062591 0.85600562259846602 1" friction="0.59999999999999998 0.10000000000000001 0.10000000000000001" fromto="0 0 0 -0.4950441778973243 -0.10557124590454414 0.016611760884073679"/>
            <site name="0/1/4/5/end5" class="0/1/4/5/" size="0.0050000000000000001" pos="-0.4950441778973243 -0.10557124590454414 0.016611760884073679"/>
          </body>
        </body>
      </body>
      <camera name="0/iso" class="0/" mode="trackcom" pos="-2.2999999999999998 -2.2999999999999998 1" xyaxes="0.45000000000000001 -0.45000000000000001 0 0.29999999999999999 0.14999999999999999 0.93999999999999995"/>
    </body>
  </worldbody>
  <actuator>
    <motor name="0/1/motor" class="0/1/" ctrllimited="true" ctrlrange="-1 1" gear="83" joint="0/1/joint/"/>
    <motor name="0/1/2/motor" class="0/1/2/" ctrllimited="true" ctrlrange="-1 1" gear="81" joint="0/1/2/joint/"/>
    <motor name="0/1/2/3/motor" class="0/1/2/3/" ctrllimited="true" ctrlrange="-1 1" gear="67" joint="0/1/2/3/joint/"/>
    <motor name="0/1/4/motor" class="0/1/4/" ctrllimited="true" ctrlrange="-1 1" gear="50" joint="0/1/4/joint/"/>
    <motor name="0/1/4/5/motor" class="0/1/4/5/" ctrllimited="true" ctrlrange="-1 1" gear="53" joint="0/1/4/5/joint/"/>
  </actuator>
  <sensor>
    <subtreelinvel name="velocity" body="0/"/>
  </sensor>
</mujoco>
