<mujoco model="morphology">
  <option timestep="0.01"/>
  <default>
    <default class="/"/>
    <default class="0/"/>
    <default class="0/1/"/>
    <default class="0/1/2/"/>
    <default class="0/1/2/3/"/>
    <default class="0/1/2/3/4/"/>
    <default class="0/1/2/3/4/5/"/>
    <default class="0/1/2/3/4/5/6/"/>
    <default class="0/1/2/3/4/5/6/7/"/>
    <default class="0/8/"/>
    <default class="0/8/9/"/>
    <default class="0/8/10/"/>
  </default>
  <asset>
    <texture name="texplane" type="2d" builtin="checker" rgb1="0.10000000000000001 0.20000000000000001 0.29999999999999999" rgb2="0.20000000000000001 0.29999999999999999 0.40000000000000002" width="300" height="300"/>
    <material name="MatPlane" class="/" texture="texplane" texrepeat="20 20" specular="1" shininess="1" reflectance="0.5"/>
  </asset>
  <worldbody>
    <light name="//unnamed_light_0" class="/" directional="true" pos="0 0 1.5" dir="0 0 -1.3" cutoff="100" exponent="1" diffuse="1 1 1" specular="0.10000000000000001 0.10000000000000001 0.10000000000000001"/>
    <geom name="ground" class="/" type="plane" size="15 15 0.5" material="MatPlane" rgba="1 1 1 1"/>
    <site name="body" class="/" size="9.9999999999999995e-07 9.9999999999999995e-07 9.9999999999999995e-07" pos="0 0 0.62170670032501218"/>
    <body pos="0 0 0.62170670032501218" name="0/">
      <freejoint name="0/"/>
      <geom name="0/geom" class="0/" type="capsule" contype="1" conaffinity="1" condim="3" size="0.058471505277263761" rgba="0.97481407537471143 0.34232326891471543 0.24837723187280902 1" friction="0.59999999999999998 0.10000000000000001 0.10000000000000001" fromto="0 0 0 -0.685027784967845 -0.25597003796284928 -0.032791562378923889"/>
      <site name="0/end0" class="0/" size="0.0050000000000000001" pos="-0.685027784967845 -0.25597003796284928 -0.032791562378923889"/>
      <site name="0/attach1" class="0/" size="9.9999999999999995e-07 9.9999999999999995e-07 9.9999999999999995e-07" pos="-0.11722276850154091 -0.043801897035254084 -0.0056113311166332697"/>
      <body pos="-0.11722276850154091 -0.043801897035254084 -0.0056113311166332697" name="0/1/">
        <joint name="0/1/joint/" class="0/" type="hinge" axis="0 1 0" limited="true" range="-60.232407802731977 60.232407802731977"/>
        <geom name="0/1/geom" class="0/1/" type="capsule" contype="1" conaffinity="1" condim="3" size="0.048347156724001507" rgba="0.75014242665416031 0.17683915945683248 0.91123941949489218 1" friction="0.59999999999999998 0.10000000000000001 0.10000000000000001" fromto="0 0 0 0.1091767868539848 0.6930898624979942 0.40014318997750653"/>
        <site name="0/1/end1" class="0/1/" size="0.0050000000000000001" pos="0.1091767868539848 0.6930898624979942 0.40014318997750653"/>
        <site name="0/1/attach2" class="0/1/" size="9.9999999999999995e-07 9.9999999999999995e-07 9.9999999999999995e-07" pos="0.10007251058913641 0.63529294644672085 0.3667751613696929"/>
        <body pos="0.10007251058913641 0.63529294644672085 0.3667751613696929" name="0/1/2/">
          <geom name="0/1/2/geom" class="0/1/2/" type="capsule" contype="1" conaffinity="1" condim="3" size="0.068238398960305383" rgba="0.98109993919499583 0.7221136926570243 0.89688069232577816 1" friction="0.59999999999999998 0.10000000000000001 0.10000000000000001" fromto="0 0 0 -0.39052293104783736 -0.19189937514383204 -0.65209282477990582"/>
          <site name="0/1/2/end2" class="0/1/2/" size="0.0050000000000000001" pos="-0.39052293104783736 -0.19189937514383204 -0.65209282477990582"/>
          <site name="0/1/2/attach3" class="0/1/2/" size="9.9999999999999995e-07 9.9999999999999995e-07 9.9999999999999995e-07" pos="-0.28505503880031713 -0.14007342329580363 -0.47598317714734834"/>
          <body pos="-0.28505503880031713 -0.14007342329580363 -0.47598317714734834" name="0/1/2/3/">
            <joint name="0/1/2/3/joint/" class="0/1/2/" type="hinge" axis="0 -0.95932273240981725 0.28231169845006743" limited="true" range="-68.525430089877943 68.525430089877943"/>
            <geom name="0/1/2/3/geom" class="0/1/2/3/" type="capsule" contype="1" conaffinity="1" condim="3" size="0.040970409813568531" rgba="0.35600913941739176 0.31864571141603137 0.46768506449374414 1" friction="0.59999999999999998 0.10000000000000001 0.10000000000000001" fromto="0 0 0 0.67643886083217231 -0.29783991360405704 -0.40688735636698892"/>
            <site name="0/1/2/3/end3" class="0/1/2/3/" size="0.0050000000000000001" pos="0.67643886083217231 -0.29783991360405704 -0.40688735636698892"/>
            <site name="0/1/2/3/attach4" class="0/1/2/3/" size="9.9999999999999995e-07 9.9999999999999995e-07 9.9999999999999995e-07" pos="0.59896989738219641 -0.26372988427701444 -0.36028870042952033"/>
            <body pos="0.59896989738219641 -0.26372988427701444 -0.36028870042952033" name="0/1/2/3/4/">
              <geom name="0/1/2/3/4/geom" class="0/1/2/3/4/" type="capsule" contype="1" conaffinity="1" condim="3" size="0.043074197596328037" rgba="0.62665030016550105 0.60949745499330243 0.46540291488872743 1" friction="0.59999999999999998 0.10000000000000001 0.10000000000000001" fromto="0 0 0 0.29274676085594398 0.34305435766767389 0.64790965212916363"/>
              <site name="0/1/2/3/4/end4" class="0/1/2/3/4/" size="0.0050000000000000001" pos="0.29274676085594398 0.34305435766767389 0.64790965212916363"/>
              <site name="0/1/2/3/4/attach5" class="0/1/2/3/4/" size="9.9999999999999995e-07 9.9999999999999995e-07 9.9999999999999995e-07" pos="0.20963344109345147 0.24565827908636265 0.46396253709647112"/>
              <body pos="0.20963344109345147 0.24565827908636265 0.46396253709647112" name="0/1/2/3/4/5/">
                <joint name="0/1/2/3/4/5/joint/" class="0/1/2/3/4/" type="hinge" axis="5.5511151231257827e-17 -0.88376345526109823 0.46793392177204396" limited="true" range="-37.961268167107619 37.961268167107619"/>
                <geom name="0/1/2/3/4/5/geom" class="0/1/2/3/4/5/" type="capsule" contype="1" conaffinity="1" condim="3" size="0.046612643992043484" rgba="0.56030444649114708 0.098413186101717565 0.3004050043636709 1" friction="0.59999999999999998 0.10000000000000001 0.10000000000000001" fromto="0 0 0 -0.61608197075287929 0.37163525792338192 0.14156652020025162"/>
                <site name="0/1/2/3/4/5/end5" class="0/1/2/3/4/5/" size="0.0050000000000000001" pos="-0.61608197075287929 0.37163525792338192 0.14156652020025162"/>
                <site name="0/1/2/3/4/5/attach6" class="0/1/2/3/4/5/" size="9.9999999999999995e-07 9.9999999999999995e-07 9.9999999999999995e-07" pos="-0.10749948113498976 0.064846236856128517 0.024701790005339112"/>
                <body pos="-0.10749948113498976 0.064846236856128517 0.024701790005339112" name="0/1/2/3/4/5/6/">
                  <geom name="0/1/2/3/4/5/6/geom" class="0/1/2/3/4/5/6/" type="capsule" contype="1" conaffinity="1" condim="3" size="0.059044837772720807" rgba="0.88901215789485877 0.061718194623675671 0.95690979052918645 1" friction="0.59999999999999998 0.10000000000000001 0.10000000000000001" fromto="0 0 0 -0.13474166091329731 -0.26553706890280188 0.34131023107089464"/>
                  <site name="0/1/2/3/4/5/6/end6" class="0/1/2/3/4/5/6/" size="0.0050000000000000001" pos="-0.13474166091329731 -0.26553706890280188 0.34131023107089464"/>
                  <site name="0/1/2/3/4/5/6/attach7" class="0/1/2/3/4/5/6/" size="9.9999999999999995e-07 9.9999999999999995e-07 9.9999999999999995e-07" pos="-0.036934298420382893 -0.072786881785884161 0.093557210463762405"/>
                  <body pos="-0.036934298420382893 -0.072786881785884161 0.093557210463762405" name="0/1/2/3/4/5/6/7/">
                    <geom name="0/1/2/3/4/5/6/7/geom" class="0/1/2/3/4/5/6/7/" type="capsule" contype="1" conaffinity="1" condim="3" size="0.055269430547492046" rgba="0.83824467027029059 0.91747371411747747 0.5268065788152041 1" friction="0.59999999999999998 0.10000000000000001 0.10000000000000001" fromto="0 0 0 -0.66407007757777103 0.64593867924914261 0.60767862368776338"/>
                    <site name="0/1/2/3/4/5/6/7/end7" class="0/1/2/3/4/5/6/7/" size="0.0050000000000000001" pos="-0.66407007757777103 0.64593867924914261 0.60767862368776338"/>
                  </body>
                </body>
              </body>
            </body>
          </body>
        </body>
      </body>
      <site name="0/attach8" class="0/" size="9.9999999999999995e-07 9.9999999999999995e-07 9.9999999999999995e-07" pos="-0.65175450542743785 -0.24353702018751 -0.031198805346956422"/>
      <body pos="-0.65175450542743785 -0.24353702018751 -0.031198805346956422" name="0/8/">
        <joint name="0/8/joint/" class="0/" type="hinge" axis="0 0 1" limited="true" range="-53.727762060384784 53.727762060384784"/>
        <geom name="0/8/geom" class="0/8/" type="capsule" contype="1" conaffinity="1" condim="3" size="0.047458337238407179" rgba="0.76492267023645499 0.88366796325861396 0.94768487233195153 1" friction="0.59999999999999998 0.10000000000000001 0.10000000000000001" fromto="0 0 0 -0.039017243345760066 -0.57452755111690124 0.71334039000990379"/>
        <site name="0/8/end8" class="0/8/" size="0.0050000000000000001" pos="-0.039017243345760066 -0.57452755111690124 0.71334039000990379"/>
        <site name="0/8/attach9" class="0/8/" size="9.9999999999999995e-07 9.9999999999999995e-07 9.9999999999999995e-07" pos="-0.033244501135992206 -0.48952412287323194 0.60779910041006002"/>
        <body pos="-0.033244501135992206 -0.48952412287323194 0.60779910041006002" name="0/8/9/">
          <joint name="0/8/9/joint/" class="0/8/" type="hinge" axis="0.99909392623757276 -0.02669590898393176 0.033145965044228232" limited="true" range="-67.176534319763846 67.176534319763846"/>
          <geom name="0/8/9/geom" class="0/8/9/" type="capsule" contype="1" conaffinity="1" condim="3" size="0.040628673571855692" rgba="0.93071352162003818 0.64782862458619461 0.75367344554479221 1" friction="0.59999999999999998 0.10000000000000001 0.10000000000000001" fromto="0 0 0 -0.17379202534330607 0.085594646153318243 0.19998480470183311"/>
          <site name="0/8/9/end9" class="0/8/9/" size="0.0050000000000000001" pos="-0.17379202534330607 0.085594646153318243 0.19998480470183311"/>
        </body>
        <site name="0/8/attach10" class="0/8/" size="9.9999999999999995e-07 9.9999999999999995e-07 9.9999999999999995e-07" pos="-0.0072253080418426844 -0.10639240959590311 0.13209810879860229"/>
        <body pos="-0.0072253080418426844 -0.10639240959590311 0.13209810879860229" name="0/8/10/">
          <joint name="0/8/10/joint/" class="0/8/" type="hinge" axis="-5.5511151231257827e-17 0.77881138377619985 0.62725818328707417" limited="true" range="-51.726199896263161 51.726199896263161"/>
          <geom name="0/8/10/geom" class="0/8/10/" type="capsule" contype="1" conaffinity="1" condim="3" size="0.0351421617073297" rgba="0.79637769779597234 0.080964831827896044 0.82405661708263311 1" friction="0.59999999999999998 0.10000000000000001 0.10000000000000001" fromto="0 0 0 0.43269367445415208 0.17908387755431243 0.43788062273377659"/>
          <site name="0/8/10/end10" class="0/8/10/" size="0.0050000000000000001" pos="0.43269367445415208 0.17908387755431243 0.43788062273377659"/>
        </body>
      </body>
      <camera name="0/iso" class="0/" mode="trackcom" pos="-2.2999999999999998 -2.2999999999999998 1" xyaxes="0.45000000000000001 -0.45000000000000001 0 0.29999999999999999 0.14999999999999999 0.93999999999999995"/>
    </body>
  </worldbody>
  <actuator>
    <motor name="0/1/motor" class="0/1/" ctrllimited="true" ctrlrange="-1 1" gear="83" joint="0/1/joint/"/>
    <motor name="0/1/2/3/motor" class="0/1/2/3/" ctrllimited="true" ctrlrange="-1 1" gear="62" joint="0/1/2/3/joint/"/>
    <motor name="0/1/2/3/4/5/motor" class="0/1/2/3/4/5/" ctrllimited="true" ctrlrange="-1 1" gear="67" joint="0/1/2/3/4/5/joint/"/>
    <motor name="0/8/motor" class="0/8/" ctrllimited="true" ctrlrange="-1 1" gear="94" joint="0/8/joint/"/>
    <motor name="0/8/9/motor" class="0/8/9/" ctrllimited="true" ctrlrange="-1 1" gear="69" joint="0/8/9/joint/"/>
    <motor name="0/8/10/motor" class="0/8/10/" ctrllimited="true" ctrlrange="-1 1" gear="83" joint="0/8/10/joint/"/>
  </actuator>
  <sensor>
    <subtreelinvel name="velocity" body="0/"/>
  </sensor>
</mujoco>
