<mujoco model="morphology">
  <option timestep="0.01"/>
  <default>
    <default class="/"/>
    <default class="0/"/>
    <default class="0/1/"/>
    <default class="0/1/2/"/>
    <default class="0/1/2/3/"/>
    <default class="0/1/2/3/4/"/>
    <default class="0/1/2/3/4/5/"/>
    <default class="0/1/2/3/4/5/6/"/>
    <default class="0/1/2/3/4/5/7/"/>
  </default>
  <asset>
    <texture name="texplane" type="2d" builtin="checker" rgb1="0.10000000000000001 0.20000000000000001 0.29999999999999999" rgb2="0.20000000000000001 0.29999999999999999 0.40000000000000002" width="300" height="300"/>
    <material name="MatPlane" class="/" texture="texplane" texrepeat="20 20" specular="1" shininess="1" reflectance="0.5"/>
  </asset>
  <worldbody>
    <light name="//unnamed_light_0" class="/" directional="true" pos="0 0 1.5" dir="0 0 -1.3" cutoff="100" exponent="1" diffuse="1 1 1" specular="0.10000000000000001 0.10000000000000001 0.10000000000000001"/>
    <geom name="ground" class="/" type="plane" size="15 15 0.5" material="MatPlane" rgba="1 1 1 1"/>
    <site name="body" class="/" size="9.9999999999999995e-07 9.9999999999999995e-07 9.9999999999999995e-07" pos="0 0 0.50926620364189146"/>
    <body pos="0 0 0.50926620364189146" name="0/">
      <freejoint name="0/"/>
      <geom name="0/geom" class="0/" type="capsule" contype="1" conaffinity="1" condim="3" size="0.039697990379565742" rgba="0.77191309984216805 0.31339932554767991 0.69538231415305096 1" friction="0.59999999999999998 0.10000000000000001 0.10000000000000001" fromto="0 0 0 -0.61678214636162665 -0.055614258357240542 0.062218150887570434"/>
      <site name="0/end0" class="0/" size="0.0050000000000000001" pos="-0.61678214636162665 -0.055614258357240542 0.062218150887570434"/>
      <site name="0/attach1" class="0/" size="9.9999999999999995e-07 9.9999999999999995e-07 9.9999999999999995e-07" pos="-0.076657900007399082 -0.0069121200755953753 0.0077328969677864529"/>
      <body pos="-0.076657900007399082 -0.0069121200755953753 0.0077328969677864529" name="0/1/">
        <joint name="0/1/joint/" class="0/" type="hinge" axis="0 0 1" limited="true" range="-51.834454337904951 51.834454337904951"/>
        <geom name="0/1/geom" class="0/1/" type="capsule" contype="1" conaffinity="1" condim="3" size="0.046199711530168316" rgba="0.46847478030595613 0.54351536301901071 0.17514898165833404 1" friction="0.59999999999999998 0.10000000000000001 0.10000000000000001" fromto="0 0 0 -0.69264621485595868 0.70895976951741724 -0.41699910496113934"/>
        <site name="0/1/end1" class="0/1/" size="0.0050000000000000001" pos="-0.69264621485595868 0.70895976951741724 -0.41699910496113934"/>
        <site name="0/1/attach2" class="0/1/" size="9.9999999999999995e-07 9.9999999999999995e-07 9.9999999999999995e-07" pos="-0.18919993059344806 0.19365606323877296 -0.11390548309368098"/>
        <body pos="-0.18919993059344806 0.19365606323877296 -0.11390548309368098" name="0/1/2/">
          <geom name="0/1/2/geom" class="0/1/2/" type="capsule" contype="1" conaffinity="1" condim="3" size="0.039992045156183702" rgba="0.40025022722586778 0.87621585579143457 0.44360763793030944 1" friction="0.59999999999999998 0.10000000000000001 0.10000000000000001" fromto="0 0 0 -0.66644710569887111 0.38414803359410232 0.28701319249144452"/>
          <site name="0/1/2/end2" class="0/1/2/" size="0.0050000000000000001" pos="-0.66644710569887111 0.38414803359410232 0.28701319249144452"/>
          <site name="0/1/2/attach3" class="0/1/2/" size="9.9999999999999995e-07 9.9999999999999995e-07 9.9999999999999995e-07" pos="-0.46301092460900339 0.26688500062524484 0.19940103647248941"/>
          <body pos="-0.46301092460900339 0.26688500062524484 0.19940103647248941" name="0/1/2/3/">
            <geom name="0/1/2/3/geom" class="0/1/2/3/" type="capsule" contype="1" conaffinity="1" condim="3" size="0.0633653360712223" rgba="0.10761285621000127 0.77954358431080628 0.83106646544172413 1" friction="0.59999999999999998 0.10000000000000001 0.10000000000000001" fromto="0 0 0 -0.13224240715178315 -0.5464380387104506 -0.021047904030660591"/>
            <site name="0/1/2/3/end3" class="0/1/2/3/" size="0.0050000000000000001" pos="-0.13224240715178315 -0.5464380387104506 -0.021047904030660591"/>
            <site name="0/1/2/3/attach4" class="0/1/2/3/" size="9.9999999999999995e-07 9.9999999999999995e-07 9.9999999999999995e-07" pos="-0.0027105686376064776 -0.011200324026344449 -0.00043141825516967145"/>
            <body pos="-0.0027105686376064776 -0.011200324026344449 -0.00043141825516967145" name="0/1/2/3/4/">
              <joint name="0/1/2/3/4/joint/" class="0/1/2/3/" type="hinge" axis="0.97198248587781899 -0.2348791093802956 -0.0090471610737610057" limited="true" range="-66.717070539056664 66.717070539056664"/>
              <geom name="0/1/2/3/4/geom" class="0/1/2/3/4/" type="capsule" contype="1" conaffinity="1" condim="3" size="0.052046953672847035" rgba="0.1919693121078947 0.012893229343125312 0.81444246233969908 1" friction="0.59999999999999998 0.10000000000000001 0.10000000000000001" fromto="0 0 0 -0.11978150261055842 0.080623465296349339 0.34755831763176537"/>
              <site name="0/1/2/3/4/end4" class="0/1/2/3/4/" size="0.0050000000000000001" pos="-0.11978150261055842 0.080623465296349339 0.34755831763176537"/>
              <site name="0/1/2/3/4/attach5" class="0/1/2/3/4/" size="9.9999999999999995e-07 9.9999999999999995e-07 9.9999999999999995e-07" pos="-0.095962802138715039 0.064591389149004932 0.27844591476699193"/>
              <body pos="-0.095962802138715039 0.064591389149004932 0.27844591476699193" name="0/1/2/3/4/5/">
                <joint name="0/1/2/3/4/5/joint/" class="0/1/2/3/4/" type="hinge" axis="-0.9480015509428148 -0.071918785468041785 -0.31003346223725553" limited="true" range="-53.398172135570917 53.398172135570917"/>
                <geom name="0/1/2/3/4/5/geom" class="0/1/2/3/4/5/" type="capsule" contype="1" conaffinity="1" condim="3" size="0.060173865892227105" rgba="0.95811108327752792 0.13304740852634978 0.026541840247183757 1" friction="0.59999999999999998 0.10000000000000001 0.10000000000000001" fromto="0 0 0 0.65292398047190647 -0.43960609009905643 -0.062064873039676338"/>
                <site name="0/1/2/3/4/5/end5" class="0/1/2/3/4/5/" size="0.0050000000000000001" pos="0.65292398047190647 -0.43960609009905643 -0.062064873039676338"/>
                <site name="0/1/2/3/4/5/attach6" class="0/1/2/3/4/5/" size="9.9999999999999995e-07 9.9999999999999995e-07 9.9999999999999995e-07" pos="0.11395095829960913 -0.07672184931073639 -0.01083181499093216"/>
                <body pos="0.11395095829960913 -0.07672184931073639 -0.01083181499093216" name="0/1/2/3/4/5/6/">
                  <joint name="0/1/2/3/4/5/6/joint/" class="0/1/2/3/4/5/" type="hinge" axis="0.56229046224813073 0.81881945950611534 0.11560332520691922" limited="true" range="-40.697028226731803 40.697028226731803"/>
                  <geom name="0/1/2/3/4/5/6/geom" class="0/1/2/3/4/5/6/" type="capsule" contype="1" conaffinity="1" condim="3" size="0.043108894366503211" rgba="0.41262340507314854 0.94554387597428635 0.38983813038975679 1" friction="0.59999999999999998 0.10000000000000001 0.10000000000000001" fromto="0 0 0 -0.13484457865030663 -0.34600480806667283 0.49592791637488109"/>
                  <site name="0/1/2/3/4/5/6/end6" class="0/1/2/3/4/5/6/" size="0.0050000000000000001" pos="-0.13484457865030663 -0.34600480806667283 0.49592791637488109"/>
                </body>
                <site name="0/1/2/3/4/5/attach7" class="0/1/2/3/4/5/" size="9.9999999999999995e-07 9.9999999999999995e-07 9.9999999999999995e-07" pos="0.080638359693358502 -0.054292865750125339 -0.0076652255181051537"/>
                <body pos="0.080638359693358502 -0.054292865750125339 -0.0076652255181051537" name="0/1/2/3/4/5/7/">
                  <joint name="0/1/2/3/4/5/7/joint/" class="0/1/2/3/4/5/" type="hinge" axis="0.56229046224813073 0.81881945950611534 0.11560332520691922" limited="true" range="-31.788621561884419 31.788621561884419"/>
                  <geom name="0/1/2/3/4/5/7/geom" class="0/1/2/3/4/5/7/" type="capsule" contype="1" conaffinity="1" condim="3" size="0.035674905934497479" rgba="0.50879832408006442 0.30354253837202927 0.70293119666389392 1" friction="0.59999999999999998 0.10000000000000001 0.10000000000000001" fromto="0 0 0 0.055510459926269018 0.26167797201255283 0.42846861408171666"/>
                  <site name="0/1/2/3/4/5/7/end7" class="0/1/2/3/4/5/7/" size="0.0050000000000000001" pos="0.055510459926269018 0.26167797201255283 0.42846861408171666"/>
                </body>
              </body>
            </body>
          </body>
        </body>
      </body>
      <camera name="0/iso" class="0/" mode="trackcom" pos="-2.2999999999999998 -2.2999999999999998 1" xyaxes="0.45000000000000001 -0.45000000000000001 0 0.29999999999999999 0.14999999999999999 0.93999999999999995"/>
    </body>
  </worldbody>
  <actuator>
    <motor name="0/1/motor" class="0/1/" ctrllimited="true" ctrlrange="-1 1" gear="52" joint="0/1/joint/"/>
    <motor name="0/1/2/3/4/motor" class="0/1/2/3/4/" ctrllimited="true" ctrlrange="-1 1" gear="65" joint="0/1/2/3/4/joint/"/>
    <motor name="0/1/2/3/4/5/motor" class="0/1/2/3/4/5/" ctrllimited="true" ctrlrange="-1 1" gear="94" joint="0/1/2/3/4/5/joint/"/>
    <motor name="0/1/2/3/4/5/6/motor" class="0/1/2/3/4/5/6/" ctrllimited="true" ctrlrange="-1 1" gear="95" joint="0/1/2/3/4/5/6/joint/"/>
    <motor name="0/1/2/3/4/5/7/motor" class="0/1/2/3/4/5/7/" ctrllimited="true" ctrlrange="-1 1" gear="66" joint="0/1/2/3/4/5/7/joint/"/>
  </actuator>
  <sensor>
    <subtreelinvel name="velocity" body="0/"/>
  </sensor>
</mujoco>
