<mujoco model="morphology">
  <option timestep="0.01"/>
  <default>
    <default class="/"/>
    <default class="0/"/>
    <default class="0/1/"/>
    <default class="0/2/"/>
    <default class="0/2/3/"/>
    <default class="0/2/4/"/>
    <default class="0/2/4/5/"/>
    <default class="0/2/4/5/6/"/>
    <default class="0/2/4/5/7/"/>
    <default class="0/2/4/5/7/8/"/>
    <default class="0/2/4/5/7/8/9/"/>
    <default class="0/2/4/10/"/>
  </default>
  <asset>
    <texture name="texplane" type="2d" builtin="checker" rgb1="0.10000000000000001 0.20000000000000001 0.29999999999999999" rgb2="0.20000000000000001 0.29999999999999999 0.40000000000000002" width="300" height="300"/>
    <material name="MatPlane" class="/" texture="texplane" texrepeat="20 20" specular="1" shininess="1" reflectance="0.5"/>
  </asset>
  <worldbody>
    <light name="//unnamed_light_0" class="/" directional="true" pos="0 0 1.5" dir="0 0 -1.3" cutoff="100" exponent="1" diffuse="1 1 1" specular="0.10000000000000001 0.10000000000000001 0.10000000000000001"/>
    <geom name="ground" class="/" type="plane" size="15 15 0.5" material="MatPlane" rgba="1 1 1 1"/>
    <site name="body" class="/" size="9.9999999999999995e-07 9.9999999999999995e-07 9.9999999999999995e-07" pos="0 0 1.0573714137077332"/>
    <body pos="0 0 1.0573714137077332" name="0/">
      <freejoint name="0/"/>
      <geom name="0/geom" class="0/" type="capsule" contype="1" conaffinity="1" condim="3" size="0.048256421092265925" rgba="0.77320503247821526 0.14563068999918494 0.98426402251969769 1" friction="0.59999999999999998 0.10000000000000001 0.10000000000000001" fromto="0 0 0 0.50148189398864762 0.062568471009341264 -0.53066984077522195"/>
      <site name="0/end0" class="0/" size="0.0050000000000000001" pos="0.50148189398864762 0.062568471009341264 -0.53066984077522195"/>
      <site name="0/attach1" class="0/" size="9.9999999999999995e-07 9.9999999999999995e-07 9.9999999999999995e-07" pos="0.36696053372214832 0.045784623115997083 -0.38831888117087487"/>
      <body pos="0.36696053372214832 0.045784623115997083 -0.38831888117087487" name="0/1/">
        <joint name="0/1/joint/" class="0/" type="hinge" axis="0 0 1" limited="true" range="-45.30890669896749 45.30890669896749"/>
        <geom name="0/1/geom" class="0/1/" type="capsule" contype="1" conaffinity="1" condim="3" size="0.06941828917359999" rgba="0.43699211655024595 0.52362504660200038 0.55122341599919489 1" friction="0.59999999999999998 0.10000000000000001 0.10000000000000001" fromto="0 0 0 0.47436471406161584 -0.12542798980905423 0.21310827968692792"/>
        <site name="0/1/end1" class="0/1/" size="0.0050000000000000001" pos="0.47436471406161584 -0.12542798980905423 0.21310827968692792"/>
      </body>
      <site name="0/attach2" class="0/" size="9.9999999999999995e-07 9.9999999999999995e-07 9.9999999999999995e-07" pos="0.29412505078250195 0.036697146863337402 -0.31124412613446767"/>
      <body pos="0.29412505078250195 0.036697146863337402 -0.31124412613446767" name="0/2/">
        <joint name="0/2/joint/" class="0/" type="hinge" axis="0 1 0" limited="true" range="-67.596058956622358 67.596058956622358"/>
        <geom name="0/2/geom" class="0/2/" type="capsule" contype="1" conaffinity="1" condim="3" size="0.038864954119602092" rgba="0.66748048044383723 0.58538042851355365 0.64655387472538917 1" friction="0.59999999999999998 0.10000000000000001 0.10000000000000001" fromto="0 0 0 0.40923468593835088 0.62635192637694237 0.5084211249192585"/>
        <site name="0/2/end2" class="0/2/" size="0.0050000000000000001" pos="0.40923468593835088 0.62635192637694237 0.5084211249192585"/>
        <site name="0/2/attach3" class="0/2/" size="9.9999999999999995e-07 9.9999999999999995e-07 9.9999999999999995e-07" pos="0.047605256673224308 0.07286196709981399 0.059143369273241118"/>
        <body pos="0.047605256673224308 0.07286196709981399 0.059143369273241118" name="0/2/3/">
          <joint name="0/2/3/joint/" class="0/2/" type="hinge" axis="-0.89181598681669882 0.35124706719211418 0.28511356236962171" limited="true" range="-54.823813326706997 54.823813326706997"/>
          <geom name="0/2/3/geom" class="0/2/3/" type="capsule" contype="1" conaffinity="1" condim="3" size="0.036932854321422799" rgba="0.36052718631969183 0.16230396817376602 0.27785560865827619 1" friction="0.59999999999999998 0.10000000000000001 0.10000000000000001" fromto="0 0 0 0.29663755496144706 -0.053640966350110064 -0.70527065997027338"/>
          <site name="0/2/3/end3" class="0/2/3/" size="0.0050000000000000001" pos="0.29663755496144706 -0.053640966350110064 -0.70527065997027338"/>
        </body>
        <site name="0/2/attach4" class="0/2/" size="9.9999999999999995e-07 9.9999999999999995e-07 9.9999999999999995e-07" pos="0.073427914797316682 0.11238469627198149 0.091224679443108428"/>
        <body pos="0.073427914797316682 0.11238469627198149 0.091224679443108428" name="0/2/4/">
          <geom name="0/2/4/geom" class="0/2/4/" type="capsule" contype="1" conaffinity="1" condim="3" size="0.052959222556168611" rgba="0.52995042280288485 0.090861573534403939 0.97664286205781448 1" friction="0.59999999999999998 0.10000000000000001 0.10000000000000001" fromto="0 0 0 -0.34480077224665612 0.33094224771098046 -0.40682416466349386"/>
          <site name="0/2/4/end4" class="0/2/4/" size="0.0050000000000000001" pos="-0.34480077224665612 0.33094224771098046 -0.40682416466349386"/>
          <site name="0/2/4/attach5" class="0/2/4/" size="9.9999999999999995e-07 9.9999999999999995e-07 9.9999999999999995e-07" pos="-0.22960524365400725 0.22037675532445505 -0.27090705407434118"/>
          <body pos="-0.22960524365400725 0.22037675532445505 -0.27090705407434118" name="0/2/4/5/">
            <joint name="0/2/4/5/joint/" class="0/2/4/" type="hinge" axis="1.1102230246251565e-16 0.77574280330529355 0.63104920816053989" limited="true" range="-61.54815028615657 61.54815028615657"/>
            <geom name="0/2/4/5/geom" class="0/2/4/5/" type="capsule" contype="1" conaffinity="1" condim="3" size="0.054950926967127264" rgba="0.48344942625507914 0.34850900880737057 0.24078366145894092 1" friction="0.59999999999999998 0.10000000000000001 0.10000000000000001" fromto="0 0 0 0.42564151712336207 0.38580759955868049 0.11517717694609675"/>
            <site name="0/2/4/5/end5" class="0/2/4/5/" size="0.0050000000000000001" pos="0.42564151712336207 0.38580759955868049 0.11517717694609675"/>
            <site name="0/2/4/5/attach6" class="0/2/4/5/" size="9.9999999999999995e-07 9.9999999999999995e-07 9.9999999999999995e-07" pos="0.047918029669063618 0.0434335920216284 0.012966459238755333"/>
            <body pos="0.047918029669063618 0.0434335920216284 0.012966459238755333" name="0/2/4/5/6/">
              <geom name="0/2/4/5/6/geom" class="0/2/4/5/6/" type="capsule" contype="1" conaffinity="1" condim="3" size="0.042273375602094682" rgba="0.65677402375969229 0.41125919345675865 0.058894919917054533 1" friction="0.59999999999999998 0.10000000000000001 0.10000000000000001" fromto="0 0 0 -0.011045892448398265 -0.032857968322449915 0.72501301399477791"/>
              <site name="0/2/4/5/6/end6" class="0/2/4/5/6/" size="0.0050000000000000001" pos="-0.011045892448398265 -0.032857968322449915 0.72501301399477791"/>
            </body>
            <site name="0/2/4/5/attach7" class="0/2/4/5/" size="9.9999999999999995e-07 9.9999999999999995e-07 9.9999999999999995e-07" pos="0.2688426591355787 0.24368285706962406 0.072747928188930375"/>
            <body pos="0.2688426591355787 0.24368285706962406 0.072747928188930375" name="0/2/4/5/7/">
              <joint name="0/2/4/5/7/joint/" class="0/2/4/5/" type="hinge" axis="-0.68719902016348833 0.69611129926106796 0.20781377655826797" limited="true" range="-34.271640078063193 34.271640078063193"/>
              <geom name="0/2/4/5/7/geom" class="0/2/4/5/7/" type="capsule" contype="1" conaffinity="1" condim="3" size="0.06498545250602529" rgba="0.7888874080539322 0.65851023410424669 0.59608909322103476 1" friction="0.59999999999999998 0.10000000000000001 0.10000000000000001" fromto="0 0 0 0.22755370341814518 -0.46381645532785354 0.095308352593329815"/>
              <site name="0/2/4/5/7/end7" class="0/2/4/5/7/" size="0.0050000000000000001" pos="0.22755370341814518 -0.46381645532785354 0.095308352593329815"/>
              <site name="0/2/4/5/7/attach8" class="0/2/4/5/7/" size="9.9999999999999995e-07 9.9999999999999995e-07 9.9999999999999995e-07" pos="0.1796047863538919 -0.36608349640217691 0.075225478856792025"/>
              <body pos="0.1796047863538919 -0.36608349640217691 0.075225478856792025" name="0/2/4/5/7/8/">
                <joint name="0/2/4/5/7/8/joint/" class="0/2/4/5/7/" type="hinge" axis="0.90132239766554123 0.42428378440970094 -0.087184894066701976" limited="true" range="-40.148635176540502 40.148635176540502"/>
                <geom name="0/2/4/5/7/8/geom" class="0/2/4/5/7/8/" type="capsule" contype="1" conaffinity="1" condim="3" size="0.043817410149746855" rgba="0.16305794433204646 0.11435728210557372 0.2047942918287331 1" friction="0.59999999999999998 0.10000000000000001 0.10000000000000001" fromto="0 0 0 -0.49828818689611415 -0.47434836650129708 0.16720323162811246"/>
                <site name="0/2/4/5/7/8/end8" class="0/2/4/5/7/8/" size="0.0050000000000000001" pos="-0.49828818689611415 -0.47434836650129708 0.16720323162811246"/>
                <site name="0/2/4/5/7/8/attach9" class="0/2/4/5/7/8/" size="9.9999999999999995e-07 9.9999999999999995e-07 9.9999999999999995e-07" pos="-0.0019688072729984341 -0.0018742176484657165 0.0006606436739928196"/>
                <body pos="-0.0019688072729984341 -0.0018742176484657165 0.0006606436739928196" name="0/2/4/5/7/8/9/">
                  <geom name="0/2/4/5/7/8/9/geom" class="0/2/4/5/7/8/9/" type="capsule" contype="1" conaffinity="1" condim="3" size="0.059768317976203578" rgba="0.40193980108854366 0.94478193914696795 0.60205607281874207 1" friction="0.59999999999999998 0.10000000000000001 0.10000000000000001" fromto="0 0 0 -0.18677778406259871 -0.095082166350990982 0.35690231967733821"/>
                  <site name="0/2/4/5/7/8/9/end9" class="0/2/4/5/7/8/9/" size="0.0050000000000000001" pos="-0.18677778406259871 -0.095082166350990982 0.35690231967733821"/>
                </body>
              </body>
            </body>
          </body>
          <site name="0/2/4/attach10" class="0/2/4/" size="9.9999999999999995e-07 9.9999999999999995e-07 9.9999999999999995e-07" pos="-0.2884859143957238 0.27689084430118827 -0.34037928736791778"/>
          <body pos="-0.2884859143957238 0.27689084430118827 -0.34037928736791778" name="0/2/4/10/">
            <geom name="0/2/4/10/geom" class="0/2/4/10/" type="capsule" contype="1" conaffinity="1" condim="3" size="0.056102580482000369" rgba="0.92694581329622705 0.16658233391918553 0.63821559835346875 1" friction="0.59999999999999998 0.10000000000000001 0.10000000000000001" fromto="0 0 0 0.54087536801797675 0.2443157721255611 0.68902895080565085"/>
            <site name="0/2/4/10/end10" class="0/2/4/10/" size="0.0050000000000000001" pos="0.54087536801797675 0.2443157721255611 0.68902895080565085"/>
          </body>
        </body>
      </body>
      <camera name="0/iso" class="0/" mode="trackcom" pos="-2.2999999999999998 -2.2999999999999998 1" xyaxes="0.45000000000000001 -0.45000000000000001 0 0.29999999999999999 0.14999999999999999 0.93999999999999995"/>
    </body>
  </worldbody>
  <actuator>
    <motor name="0/1/motor" class="0/1/" ctrllimited="true" ctrlrange="-1 1" gear="79" joint="0/1/joint/"/>
    <motor name="0/2/motor" class="0/2/" ctrllimited="true" ctrlrange="-1 1" gear="75" joint="0/2/joint/"/>
    <motor name="0/2/3/motor" class="0/2/3/" ctrllimited="true" ctrlrange="-1 1" gear="92" joint="0/2/3/joint/"/>
    <motor name="0/2/4/5/motor" class="0/2/4/5/" ctrllimited="true" ctrlrange="-1 1" gear="93" joint="0/2/4/5/joint/"/>
    <motor name="0/2/4/5/7/motor" class="0/2/4/5/7/" ctrllimited="true" ctrlrange="-1 1" gear="99" joint="0/2/4/5/7/joint/"/>
    <motor name="0/2/4/5/7/8/motor" class="0/2/4/5/7/8/" ctrllimited="true" ctrlrange="-1 1" gear="96" joint="0/2/4/5/7/8/joint/"/>
  </actuator>
  <sensor>
    <subtreelinvel name="velocity" body="0/"/>
  </sensor>
</mujoco>
