<mujoco model="morphology">
  <option timestep="0.01"/>
  <default>
    <default class="/"/>
    <default class="0/"/>
    <default class="0/1/"/>
    <default class="0/1/2/"/>
    <default class="0/1/2/3/"/>
    <default class="0/1/2/3/4/"/>
    <default class="0/1/5/"/>
    <default class="0/1/5/6/"/>
    <default class="0/1/5/6/7/"/>
    <default class="0/1/5/6/7/8/"/>
    <default class="0/1/5/6/9/"/>
    <default class="0/1/5/10/"/>
  </default>
  <asset>
    <texture name="texplane" type="2d" builtin="checker" rgb1="0.10000000000000001 0.20000000000000001 0.29999999999999999" rgb2="0.20000000000000001 0.29999999999999999 0.40000000000000002" width="300" height="300"/>
    <material name="MatPlane" class="/" texture="texplane" texrepeat="20 20" specular="1" shininess="1" reflectance="0.5"/>
  </asset>
  <worldbody>
    <light name="//unnamed_light_0" class="/" directional="true" pos="0 0 1.5" dir="0 0 -1.3" cutoff="100" exponent="1" diffuse="1 1 1" specular="0.10000000000000001 0.10000000000000001 0.10000000000000001"/>
    <geom name="ground" class="/" type="plane" size="15 15 0.5" material="MatPlane" rgba="1 1 1 1"/>
    <site name="body" class="/" size="9.9999999999999995e-07 9.9999999999999995e-07 9.9999999999999995e-07" pos="0 0 1.0702491164207459"/>
    <body pos="0 0 1.0702491164207459" name="0/">
      <freejoint name="0/"/>
      <geom name="0/geom" class="0/" type="capsule" contype="1" conaffinity="1" condim="3" size="0.057495024534855443" rgba="0.81971961714110719 0.4108792754384536 0.31586489348421709 1" friction="0.59999999999999998 0.10000000000000001 0.10000000000000001" fromto="0 0 0 -0.62406235629044171 0.73357337864944938 -0.20332841053258743"/>
      <site name="0/end0" class="0/" size="0.0050000000000000001" pos="-0.62406235629044171 0.73357337864944938 -0.20332841053258743"/>
      <site name="0/attach1" class="0/" size="9.9999999999999995e-07 9.9999999999999995e-07 9.9999999999999995e-07" pos="-0.085021235063088382 0.099940837695955811 -0.027701130203805609"/>
      <body pos="-0.085021235063088382 0.099940837695955811 -0.027701130203805609" name="0/1/">
        <geom name="0/1/geom" class="0/1/" type="capsule" contype="1" conaffinity="1" condim="3" size="0.062125331048954943" rgba="0.58598782359907109 0.96817444020907228 0.77696625273524389 1" friction="0.59999999999999998 0.10000000000000001 0.10000000000000001" fromto="0 0 0 0.57542313407480616 0.65511889153511604 0.016161041694773393"/>
        <site name="0/1/end1" class="0/1/" size="0.0050000000000000001" pos="0.57542313407480616 0.65511889153511604 0.016161041694773393"/>
        <site name="0/1/attach2" class="0/1/" size="9.9999999999999995e-07 9.9999999999999995e-07 9.9999999999999995e-07" pos="0.41962299654757196 0.47774052880736501 0.011785318214907654"/>
        <body pos="0.41962299654757196 0.47774052880736501 0.011785318214907654" name="0/1/2/">
          <joint name="0/1/2/joint/" class="0/1/" type="hinge" axis="-0.7514278375089245 0.65961460626158774 0.016271945889540337" limited="true" range="-31.827290794650871 31.827290794650871"/>
          <geom name="0/1/2/geom" class="0/1/2/" type="capsule" contype="1" conaffinity="1" condim="3" size="0.035599115312029965" rgba="0.88521741361401118 0.97048441627375115 0.44692757570699904 1" friction="0.59999999999999998 0.10000000000000001 0.10000000000000001" fromto="0 0 0 0.61272824945267912 -0.60024607998253865 0.57983471168626854"/>
          <site name="0/1/2/end2" class="0/1/2/" size="0.0050000000000000001" pos="0.61272824945267912 -0.60024607998253865 0.57983471168626854"/>
          <site name="0/1/2/attach3" class="0/1/2/" size="9.9999999999999995e-07 9.9999999999999995e-07 9.9999999999999995e-07" pos="0.35721330843925414 -0.34993635155516867 0.33803676571855079"/>
          <body pos="0.35721330843925414 -0.34993635155516867 0.33803676571855079" name="0/1/2/3/">
            <geom name="0/1/2/3/geom" class="0/1/2/3/" type="capsule" contype="1" conaffinity="1" condim="3" size="0.053333928071508149" rgba="0.38403722637339333 0.15834603427167959 0.38639673331951663 1" friction="0.59999999999999998 0.10000000000000001 0.10000000000000001" fromto="0 0 0 0.06151348386103539 -0.0075558213095029414 -0.54426821649851775"/>
            <site name="0/1/2/3/end3" class="0/1/2/3/" size="0.0050000000000000001" pos="0.06151348386103539 -0.0075558213095029414 -0.54426821649851775"/>
            <site name="0/1/2/3/attach4" class="0/1/2/3/" size="9.9999999999999995e-07 9.9999999999999995e-07 9.9999999999999995e-07" pos="0.034331963443508709 -0.004217062092752891 -0.30376748867782755"/>
            <body pos="0.034331963443508709 -0.004217062092752891 -0.30376748867782755" name="0/1/2/3/4/">
              <joint name="0/1/2/3/4/joint/" class="0/1/2/3/" type="hinge" axis="0.99367493011751151 0.0015587867203162298 0.11228403020874739" limited="true" range="-56.357585905514632 56.357585905514632"/>
              <geom name="0/1/2/3/4/geom" class="0/1/2/3/4/" type="capsule" contype="1" conaffinity="1" condim="3" size="0.038427498048079628" rgba="0.60473452105182046 0.85656251144991402 0.98215276611951174 1" friction="0.59999999999999998 0.10000000000000001 0.10000000000000001" fromto="0 0 0 0.63192944565489184 0.44190384504991731 0.16107583566292583"/>
              <site name="0/1/2/3/4/end4" class="0/1/2/3/4/" size="0.0050000000000000001" pos="0.63192944565489184 0.44190384504991731 0.16107583566292583"/>
            </body>
          </body>
        </body>
        <site name="0/1/attach5" class="0/1/" size="9.9999999999999995e-07 9.9999999999999995e-07 9.9999999999999995e-07" pos="0.35363167451952149 0.40260944842863788 0.0099319194833754308"/>
        <body pos="0.35363167451952149 0.40260944842863788 0.0099319194833754308" name="0/1/5/">
          <joint name="0/1/5/joint/" class="0/1/" type="hinge" axis="0 -0.024661365625445724 0.99969586227286555" limited="true" range="-50.620955671201074 50.620955671201074"/>
          <geom name="0/1/5/geom" class="0/1/5/" type="capsule" contype="1" conaffinity="1" condim="3" size="0.063315975672848593" rgba="0.33610445208307349 0.31021504796980304 0.26724022984474438 1" friction="0.59999999999999998 0.10000000000000001 0.10000000000000001" fromto="0 0 0 0.20701236753891328 -0.36218543239900358 -0.42090548910674525"/>
          <site name="0/1/5/end5" class="0/1/5/" size="0.0050000000000000001" pos="0.20701236753891328 -0.36218543239900358 -0.42090548910674525"/>
          <site name="0/1/5/attach6" class="0/1/5/" size="9.9999999999999995e-07 9.9999999999999995e-07 9.9999999999999995e-07" pos="0.029233859550914468 -0.051147079703580491 -0.059439404993243058"/>
          <body pos="0.029233859550914468 -0.051147079703580491 -0.059439404993243058" name="0/1/5/6/">
            <geom name="0/1/5/6/geom" class="0/1/5/6/" type="capsule" contype="1" conaffinity="1" condim="3" size="0.052523087222776869" rgba="0.23287982710263933 0.61972255695540079 0.26863280529557487 1" friction="0.59999999999999998 0.10000000000000001 0.10000000000000001" fromto="0 0 0 -0.61575545242229346 -0.57775270173632598 -0.70458988605646677"/>
            <site name="0/1/5/6/end6" class="0/1/5/6/" size="0.0050000000000000001" pos="-0.61575545242229346 -0.57775270173632598 -0.70458988605646677"/>
            <site name="0/1/5/6/attach7" class="0/1/5/6/" size="9.9999999999999995e-07 9.9999999999999995e-07 9.9999999999999995e-07" pos="-0.37427291102605864 -0.35117380557716366 -0.42826889586844885"/>
            <body pos="-0.37427291102605864 -0.35117380557716366 -0.42826889586844885" name="0/1/5/6/7/">
              <joint name="0/1/5/6/7/joint/" class="0/1/5/6/" type="hinge" axis="0.82854900444159374 -0.355027614304669 -0.43296875212881064" limited="true" range="-38.939390776613934 38.939390776613934"/>
              <geom name="0/1/5/6/7/geom" class="0/1/5/6/7/" type="capsule" contype="1" conaffinity="1" condim="3" size="0.047757610905785494" rgba="0.23253288493091895 0.46259000608854961 0.61877345368951375 1" friction="0.59999999999999998 0.10000000000000001 0.10000000000000001" fromto="0 0 0 0.50115704153189755 -0.41756852371864994 -0.34567743388265598"/>
              <site name="0/1/5/6/7/end7" class="0/1/5/6/7/" size="0.0050000000000000001" pos="0.50115704153189755 -0.41756852371864994 -0.34567743388265598"/>
              <site name="0/1/5/6/7/attach8" class="0/1/5/6/7/" size="9.9999999999999995e-07 9.9999999999999995e-07 9.9999999999999995e-07" pos="0.12382850076053754 -0.10317501296363676 -0.085411786799596837"/>
              <body pos="0.12382850076053754 -0.10317501296363676 -0.085411786799596837" name="0/1/5/6/7/8/">
                <geom name="0/1/5/6/7/8/geom" class="0/1/5/6/7/8/" type="capsule" contype="1" conaffinity="1" condim="3" size="0.047662790868257469" rgba="0.26141247201523188 0.43088357844213387 0.28635120893351029 1" friction="0.59999999999999998 0.10000000000000001 0.10000000000000001" fromto="0 0 0 0.07809379216175838 0.7177520691036221 -0.016121699810607959"/>
                <site name="0/1/5/6/7/8/end8" class="0/1/5/6/7/8/" size="0.0050000000000000001" pos="0.07809379216175838 0.7177520691036221 -0.016121699810607959"/>
              </body>
            </body>
            <site name="0/1/5/6/attach9" class="0/1/5/6/" size="9.9999999999999995e-07 9.9999999999999995e-07 9.9999999999999995e-07" pos="-0.29972432625372514 -0.28122615656585326 -0.34296526007638412"/>
            <body pos="-0.29972432625372514 -0.28122615656585326 -0.34296526007638412" name="0/1/5/6/9/">
              <joint name="0/1/5/6/9/joint/" class="0/1/5/6/" type="hinge" axis="5.5511151231257827e-17 -0.77327371226453812 0.63407236646980658" limited="true" range="-51.840752256647328 51.840752256647328"/>
              <geom name="0/1/5/6/9/geom" class="0/1/5/6/9/" type="capsule" contype="1" conaffinity="1" condim="3" size="0.049092789362662079" rgba="0.10804432353104132 0.63777706085357877 0.14934975376377901 1" friction="0.59999999999999998 0.10000000000000001 0.10000000000000001" fromto="0 0 0 0.65884291740218726 -0.4083170967240648 -0.55007524713561873"/>
              <site name="0/1/5/6/9/end9" class="0/1/5/6/9/" size="0.0050000000000000001" pos="0.65884291740218726 -0.4083170967240648 -0.55007524713561873"/>
            </body>
          </body>
          <site name="0/1/5/attach10" class="0/1/5/" size="9.9999999999999995e-07 9.9999999999999995e-07 9.9999999999999995e-07" pos="0.0086736839365836541 -0.015175334712663099 -0.017635667004285628"/>
          <body pos="0.0086736839365836541 -0.015175334712663099 -0.017635667004285628" name="0/1/5/10/">
            <joint name="0/1/5/10/joint/" class="0/1/5/" type="hinge" axis="0.93700366943092217 0.22784478418338977 0.26478458752996031" limited="true" range="-49.593118657562883 49.593118657562883"/>
            <geom name="0/1/5/10/geom" class="0/1/5/10/" type="capsule" contype="1" conaffinity="1" condim="3" size="0.059741592285250861" rgba="0.25946992303717475 0.97939667750270187 0.97920127162937132 1" friction="0.59999999999999998 0.10000000000000001 0.10000000000000001" fromto="0 0 0 0.422005299991004 -0.20651901837216236 0.1506879140706191"/>
            <site name="0/1/5/10/end10" class="0/1/5/10/" size="0.0050000000000000001" pos="0.422005299991004 -0.20651901837216236 0.1506879140706191"/>
          </body>
        </body>
      </body>
      <camera name="0/iso" class="0/" mode="trackcom" pos="-2.2999999999999998 -2.2999999999999998 1" xyaxes="0.45000000000000001 -0.45000000000000001 0 0.29999999999999999 0.14999999999999999 0.93999999999999995"/>
    </body>
  </worldbody>
  <actuator>
    <motor name="0/1/2/motor" class="0/1/2/" ctrllimited="true" ctrlrange="-1 1" gear="80" joint="0/1/2/joint/"/>
    <motor name="0/1/2/3/4/motor" class="0/1/2/3/4/" ctrllimited="true" ctrlrange="-1 1" gear="66" joint="0/1/2/3/4/joint/"/>
    <motor name="0/1/5/motor" class="0/1/5/" ctrllimited="true" ctrlrange="-1 1" gear="75" joint="0/1/5/joint/"/>
    <motor name="0/1/5/6/7/motor" class="0/1/5/6/7/" ctrllimited="true" ctrlrange="-1 1" gear="81" joint="0/1/5/6/7/joint/"/>
    <motor name="0/1/5/6/9/motor" class="0/1/5/6/9/" ctrllimited="true" ctrlrange="-1 1" gear="50" joint="0/1/5/6/9/joint/"/>
    <motor name="0/1/5/10/motor" class="0/1/5/10/" ctrllimited="true" ctrlrange="-1 1" gear="72" joint="0/1/5/10/joint/"/>
  </actuator>
  <sensor>
    <subtreelinvel name="velocity" body="0/"/>
  </sensor>
</mujoco>
