<mujoco model="morphology">
  <option timestep="0.01"/>
  <default>
    <default class="/"/>
    <default class="0/"/>
    <default class="0/1/"/>
    <default class="0/2/"/>
    <default class="0/2/3/"/>
    <default class="0/2/3/4/"/>
  </default>
  <asset>
    <texture name="texplane" type="2d" builtin="checker" rgb1="0.10000000000000001 0.20000000000000001 0.29999999999999999" rgb2="0.20000000000000001 0.29999999999999999 0.40000000000000002" width="300" height="300"/>
    <material name="MatPlane" class="/" texture="texplane" texrepeat="20 20" specular="1" shininess="1" reflectance="0.5"/>
  </asset>
  <worldbody>
    <light name="//unnamed_light_0" class="/" directional="true" pos="0 0 1.5" dir="0 0 -1.3" cutoff="100" exponent="1" diffuse="1 1 1" specular="0.10000000000000001 0.10000000000000001 0.10000000000000001"/>
    <geom name="ground" class="/" type="plane" size="15 15 0.5" material="MatPlane" rgba="1 1 1 1"/>
    <site name="body" class="/" size="9.9999999999999995e-07 9.9999999999999995e-07 9.9999999999999995e-07" pos="0 0 0.67143598794937132"/>
    <body pos="0 0 0.67143598794937132" name="0/">
      <freejoint name="0/"/>
      <geom name="0/geom" class="0/" type="capsule" contype="1" conaffinity="1" condim="3" size="0.065627554232162502" rgba="0.81700907606781015 0.6670478441766905 0.53742578992812085 1" friction="0.59999999999999998 0.10000000000000001 0.10000000000000001" fromto="0 0 0 0.15196485099214474 -0.64185483531322052 0.68798380500761702"/>
      <site name="0/end0" class="0/" size="0.0050000000000000001" pos="0.15196485099214474 -0.64185483531322052 0.68798380500761702"/>
      <site name="0/attach1" class="0/" size="9.9999999999999995e-07 9.9999999999999995e-07 9.9999999999999995e-07" pos="0.12103061208293052 -0.51119770841194878 0.54793658191077088"/>
      <body pos="0.12103061208293052 -0.51119770841194878 0.54793658191077088" name="0/1/">
        <joint name="0/1/joint/" class="0/" type="hinge" axis="0 0 1" limited="true" range="-35.18987896570809 35.18987896570809"/>
        <geom name="0/1/geom" class="0/1/" type="capsule" contype="1" conaffinity="1" condim="3" size="0.039631476902550124" rgba="0.29097434904067676 0.1025719873115839 0.1344957547504636 1" friction="0.59999999999999998 0.10000000000000001 0.10000000000000001" fromto="0 0 0 -0.029349892404634259 0.41621455173906874 0.20742815790676028"/>
        <site name="0/1/end1" class="0/1/" size="0.0050000000000000001" pos="-0.029349892404634259 0.41621455173906874 0.20742815790676028"/>
      </body>
      <site name="0/attach2" class="0/" size="9.9999999999999995e-07 9.9999999999999995e-07 9.9999999999999995e-07" pos="0.13416669808323572 -0.56668067214559559 0.60740700793622349"/>
      <body pos="0.13416669808323572 -0.56668067214559559 0.60740700793622349" name="0/2/">
        <joint name="0/2/joint/" class="0/" type="hinge" axis="0 0 1" limited="true" range="-46.529839866026798 46.529839866026798"/>
        <geom name="0/2/geom" class="0/2/" type="capsule" contype="1" conaffinity="1" condim="3" size="0.055997692711318547" rgba="0.87374982970827042 0.62879317414752167 0.062067097553066164 1" friction="0.59999999999999998 0.10000000000000001 0.10000000000000001" fromto="0 0 0 0.060215651486844379 -0.50819740499042876 -0.52215089553364435"/>
        <site name="0/2/end2" class="0/2/" size="0.0050000000000000001" pos="0.060215651486844379 -0.50819740499042876 -0.52215089553364435"/>
        <site name="0/2/attach3" class="0/2/" size="9.9999999999999995e-07 9.9999999999999995e-07 9.9999999999999995e-07" pos="0.04476924123699582 -0.37783552379238861 -0.38820969012294532"/>
        <body pos="0.04476924123699582 -0.37783552379238861 -0.38820969012294532" name="0/2/3/">
          <joint name="0/2/3/joint/" class="0/2/" type="hinge" axis="0 -0.71661706335613395 0.69746683398340226" limited="true" range="-53.481673571631973 53.481673571631973"/>
          <geom name="0/2/3/geom" class="0/2/3/" type="capsule" contype="1" conaffinity="1" condim="3" size="0.052872692810603708" rgba="0.11864326581634244 0.13266243509395792 0.089461889264742411 1" friction="0.59999999999999998 0.10000000000000001 0.10000000000000001" fromto="0 0 0 -0.12719462623095323 0.38053105919758479 -0.698314386670984"/>
          <site name="0/2/3/end3" class="0/2/3/" size="0.0050000000000000001" pos="-0.12719462623095323 0.38053105919758479 -0.698314386670984"/>
          <site name="0/2/3/attach4" class="0/2/3/" size="9.9999999999999995e-07 9.9999999999999995e-07 9.9999999999999995e-07" pos="-0.032171785156853372 0.096249062124570559 -0.17662711928667588"/>
          <body pos="-0.032171785156853372 0.096249062124570559 -0.17662711928667588" name="0/2/3/4/">
            <joint name="0/2/3/4/joint/" class="0/2/3/" type="hinge" axis="-5.5511151231257827e-17 0.87808986760092611 0.47849575172261227" limited="true" range="-63.472108809012006 63.472108809012006"/>
            <geom name="0/2/3/4/geom" class="0/2/3/4/" type="capsule" contype="1" conaffinity="1" condim="3" size="0.039443919896049486" rgba="0.1727889395946357 0.77355950363374359 0.63364389493752937 1" friction="0.59999999999999998 0.10000000000000001 0.10000000000000001" fromto="0 0 0 -0.48310720676109115 -0.71969192634368084 -0.61400619872371698"/>
            <site name="0/2/3/4/end4" class="0/2/3/4/" size="0.0050000000000000001" pos="-0.48310720676109115 -0.71969192634368084 -0.61400619872371698"/>
          </body>
        </body>
      </body>
      <camera name="0/iso" class="0/" mode="trackcom" pos="-2.2999999999999998 -2.2999999999999998 1" xyaxes="0.45000000000000001 -0.45000000000000001 0 0.29999999999999999 0.14999999999999999 0.93999999999999995"/>
    </body>
  </worldbody>
  <actuator>
    <motor name="0/1/motor" class="0/1/" ctrllimited="true" ctrlrange="-1 1" gear="74" joint="0/1/joint/"/>
    <motor name="0/2/motor" class="0/2/" ctrllimited="true" ctrlrange="-1 1" gear="65" joint="0/2/joint/"/>
    <motor name="0/2/3/motor" class="0/2/3/" ctrllimited="true" ctrlrange="-1 1" gear="62" joint="0/2/3/joint/"/>
    <motor name="0/2/3/4/motor" class="0/2/3/4/" ctrllimited="true" ctrlrange="-1 1" gear="62" joint="0/2/3/4/joint/"/>
  </actuator>
  <sensor>
    <subtreelinvel name="velocity" body="0/"/>
  </sensor>
</mujoco>
