<mujoco model="morphology">
  <option timestep="0.01"/>
  <default>
    <default class="/"/>
    <default class="0/"/>
    <default class="0/1/"/>
    <default class="0/2/"/>
    <default class="0/2/3/"/>
    <default class="0/4/"/>
    <default class="0/4/5/"/>
  </default>
  <asset>
    <texture name="texplane" type="2d" builtin="checker" rgb1="0.10000000000000001 0.20000000000000001 0.29999999999999999" rgb2="0.20000000000000001 0.29999999999999999 0.40000000000000002" width="300" height="300"/>
    <material name="MatPlane" class="/" texture="texplane" texrepeat="20 20" specular="1" shininess="1" reflectance="0.5"/>
  </asset>
  <worldbody>
    <light name="//unnamed_light_0" class="/" directional="true" pos="0 0 1.5" dir="0 0 -1.3" cutoff="100" exponent="1" diffuse="1 1 1" specular="0.10000000000000001 0.10000000000000001 0.10000000000000001"/>
    <geom name="ground" class="/" type="plane" size="15 15 0.5" material="MatPlane" rgba="1 1 1 1"/>
    <site name="body" class="/" size="9.9999999999999995e-07 9.9999999999999995e-07 9.9999999999999995e-07" pos="0 0 0.326260170340538"/>
    <body pos="0 0 0.326260170340538" name="0/">
      <freejoint name="0/"/>
      <geom name="0/geom" class="0/" type="capsule" contype="1" conaffinity="1" condim="3" size="0.063108370277140211" rgba="0.19077325673836709 0.28444646380870853 0.91722198996599547 1" friction="0.59999999999999998 0.10000000000000001 0.10000000000000001" fromto="0 0 0 -0.6030728729356124 -0.13709230465460709 0.65169534988977773"/>
      <site name="0/end0" class="0/" size="0.0050000000000000001" pos="-0.6030728729356124 -0.13709230465460709 0.65169534988977773"/>
      <site name="0/attach1" class="0/" size="9.9999999999999995e-07 9.9999999999999995e-07 9.9999999999999995e-07" pos="-0.11388818057513629 -0.025889397199983899 0.12307036349842226"/>
      <body pos="-0.11388818057513629 -0.025889397199983899 0.12307036349842226" name="0/1/">
        <joint name="0/1/joint/" class="0/" type="hinge" axis="0 1 0" limited="true" range="-35.682459871554613 35.682459871554613"/>
        <geom name="0/1/geom" class="0/1/" type="capsule" contype="1" conaffinity="1" condim="3" size="0.045276352336998574" rgba="0.25737596410323305 0.63003456094789956 0.078122239919486192 1" friction="0.59999999999999998 0.10000000000000001 0.10000000000000001" fromto="0 0 0 0.17889900814093906 -0.50289893221146342 -0.3493305319710549"/>
        <site name="0/1/end1" class="0/1/" size="0.0050000000000000001" pos="0.17889900814093906 -0.50289893221146342 -0.3493305319710549"/>
      </body>
      <site name="0/attach2" class="0/" size="9.9999999999999995e-07 9.9999999999999995e-07 9.9999999999999995e-07" pos="-0.38334667904214792 -0.087143498024970831 0.41425383123496867"/>
      <body pos="-0.38334667904214792 -0.087143498024970831 0.41425383123496867" name="0/2/">
        <joint name="0/2/joint/" class="0/" type="hinge" axis="0 0 1" limited="true" range="-37.127736514777311 37.127736514777311"/>
        <geom name="0/2/geom" class="0/2/" type="capsule" contype="1" conaffinity="1" condim="3" size="0.04599434546093175" rgba="0.12702087542613361 0.09944051632355233 0.48043182079228153 1" friction="0.59999999999999998 0.10000000000000001 0.10000000000000001" fromto="0 0 0 0.54118731176134083 0.56203512840236636 0.22140713136750767"/>
        <site name="0/2/end2" class="0/2/" size="0.0050000000000000001" pos="0.54118731176134083 0.56203512840236636 0.22140713136750767"/>
        <site name="0/2/attach3" class="0/2/" size="9.9999999999999995e-07 9.9999999999999995e-07 9.9999999999999995e-07" pos="0.36835115074697006 0.38254090923426826 0.1506974939182838"/>
        <body pos="0.36835115074697006 0.38254090923426826 0.1506974939182838" name="0/2/3/">
          <joint name="0/2/3/joint/" class="0/2/" type="hinge" axis="-0.74481188074778359 0.62083804139375709 0.24457184763441742" limited="true" range="-37.832044795301663 37.832044795301663"/>
          <geom name="0/2/3/geom" class="0/2/3/" type="capsule" contype="1" conaffinity="1" condim="3" size="0.043469981709609209" rgba="0.81804028932815298 0.44138302591499479 0.71535473916304637 1" friction="0.59999999999999998 0.10000000000000001 0.10000000000000001" fromto="0 0 0 0.45724068726580214 -0.69730826645974342 0.48705448692933162"/>
          <site name="0/2/3/end3" class="0/2/3/" size="0.0050000000000000001" pos="0.45724068726580214 -0.69730826645974342 0.48705448692933162"/>
        </body>
      </body>
      <site name="0/attach4" class="0/" size="9.9999999999999995e-07 9.9999999999999995e-07 9.9999999999999995e-07" pos="-0.53190799939150535 -0.12091489565074208 0.57479284068150793"/>
      <body pos="-0.53190799939150535 -0.12091489565074208 0.57479284068150793" name="0/4/">
        <joint name="0/4/joint/" class="0/" type="hinge" axis="0 1 0" limited="true" range="-30.379174622688097 30.379174622688097"/>
        <geom name="0/4/geom" class="0/4/" type="capsule" contype="1" conaffinity="1" condim="3" size="0.052822313894117484" rgba="0.64254767182867001 0.54171636405809587 0.7167727729016069 1" friction="0.59999999999999998 0.10000000000000001 0.10000000000000001" fromto="0 0 0 0.30157309680771638 -0.72470941099975583 -0.068778324051201656"/>
        <site name="0/4/end4" class="0/4/" size="0.0050000000000000001" pos="0.30157309680771638 -0.72470941099975583 -0.068778324051201656"/>
        <site name="0/4/attach5" class="0/4/" size="9.9999999999999995e-07 9.9999999999999995e-07 9.9999999999999995e-07" pos="0.26473296464445445 -0.63617899909032205 -0.06037637250169231"/>
        <body pos="0.26473296464445445 -0.63617899909032205 -0.06037637250169231" name="0/4/5/">
          <joint name="0/4/5/joint/" class="0/4/" type="hinge" axis="-6.9388939039072284e-18 -0.094480159921013149 0.99552674468408919" limited="true" range="-40.214460826890331 40.214460826890331"/>
          <geom name="0/4/5/geom" class="0/4/5/" type="capsule" contype="1" conaffinity="1" condim="3" size="0.065279450745976908" rgba="0.62078723319369822 0.38317957849759765 0.75045147632369569 1" friction="0.59999999999999998 0.10000000000000001 0.10000000000000001" fromto="0 0 0 0.46432530479672596 0.44955241222017328 0.29081576375419216"/>
          <site name="0/4/5/end5" class="0/4/5/" size="0.0050000000000000001" pos="0.46432530479672596 0.44955241222017328 0.29081576375419216"/>
        </body>
      </body>
      <camera name="0/iso" class="0/" mode="trackcom" pos="-2.2999999999999998 -2.2999999999999998 1" xyaxes="0.45000000000000001 -0.45000000000000001 0 0.29999999999999999 0.14999999999999999 0.93999999999999995"/>
    </body>
  </worldbody>
  <actuator>
    <motor name="0/1/motor" class="0/1/" ctrllimited="true" ctrlrange="-1 1" gear="52" joint="0/1/joint/"/>
    <motor name="0/2/motor" class="0/2/" ctrllimited="true" ctrlrange="-1 1" gear="72" joint="0/2/joint/"/>
    <motor name="0/2/3/motor" class="0/2/3/" ctrllimited="true" ctrlrange="-1 1" gear="85" joint="0/2/3/joint/"/>
    <motor name="0/4/motor" class="0/4/" ctrllimited="true" ctrlrange="-1 1" gear="77" joint="0/4/joint/"/>
    <motor name="0/4/5/motor" class="0/4/5/" ctrllimited="true" ctrlrange="-1 1" gear="78" joint="0/4/5/joint/"/>
  </actuator>
  <sensor>
    <subtreelinvel name="velocity" body="0/"/>
  </sensor>
</mujoco>
