<mujoco model="morphology">
  <option timestep="0.01"/>
  <default>
    <default class="/"/>
    <default class="0/"/>
    <default class="0/1/"/>
    <default class="0/1/2/"/>
    <default class="0/1/2/3/"/>
    <default class="0/1/2/3/4/"/>
    <default class="0/1/2/3/5/"/>
    <default class="0/1/2/6/"/>
    <default class="0/7/"/>
    <default class="0/7/8/"/>
    <default class="0/7/8/9/"/>
    <default class="0/7/10/"/>
  </default>
  <asset>
    <texture name="texplane" type="2d" builtin="checker" rgb1="0.10000000000000001 0.20000000000000001 0.29999999999999999" rgb2="0.20000000000000001 0.29999999999999999 0.40000000000000002" width="300" height="300"/>
    <material name="MatPlane" class="/" texture="texplane" texrepeat="20 20" specular="1" shininess="1" reflectance="0.5"/>
  </asset>
  <worldbody>
    <light name="//unnamed_light_0" class="/" directional="true" pos="0 0 1.5" dir="0 0 -1.3" cutoff="100" exponent="1" diffuse="1 1 1" specular="0.10000000000000001 0.10000000000000001 0.10000000000000001"/>
    <geom name="ground" class="/" type="plane" size="15 15 0.5" material="MatPlane" rgba="1 1 1 1"/>
    <site name="body" class="/" size="9.9999999999999995e-07 9.9999999999999995e-07 9.9999999999999995e-07" pos="0 0 0.20521709918975831"/>
    <body pos="0 0 0.20521709918975831" name="0/">
      <freejoint name="0/"/>
      <geom name="0/geom" class="0/" type="capsule" contype="1" conaffinity="1" condim="3" size="0.03681931337282851" rgba="0.85923939258421678 0.97589452948175515 0.69292172776403183 1" friction="0.59999999999999998 0.10000000000000001 0.10000000000000001" fromto="0 0 0 -0.38850892889174132 0.60177959244967072 -0.05807632907898852"/>
      <site name="0/end0" class="0/" size="0.0050000000000000001" pos="-0.38850892889174132 0.60177959244967072 -0.05807632907898852"/>
      <site name="0/attach1" class="0/" size="9.9999999999999995e-07 9.9999999999999995e-07 9.9999999999999995e-07" pos="-0.27971425644922404 0.43326245223898352 -0.041813137350458059"/>
      <body pos="-0.27971425644922404 0.43326245223898352 -0.041813137350458059" name="0/1/">
        <geom name="0/1/geom" class="0/1/" type="capsule" contype="1" conaffinity="1" condim="3" size="0.06792661800124826" rgba="0.81346469129430599 0.73968356343569996 0.71376137789149152 1" friction="0.59999999999999998 0.10000000000000001 0.10000000000000001" fromto="0 0 0 -0.52342623539144784 -0.60969744407298776 0.3766990335571645"/>
        <site name="0/1/end1" class="0/1/" size="0.0050000000000000001" pos="-0.52342623539144784 -0.60969744407298776 0.3766990335571645"/>
        <site name="0/1/attach2" class="0/1/" size="9.9999999999999995e-07 9.9999999999999995e-07 9.9999999999999995e-07" pos="-0.040007333051073103 -0.046601349065306295 0.028792449970086238"/>
        <body pos="-0.040007333051073103 -0.046601349065306295 0.028792449970086238" name="0/1/2/">
          <joint name="0/1/2/joint/" class="0/1/" type="hinge" axis="0.80755370355721112 -0.50175099391716582 0.31000476766360952" limited="true" range="-34.871120107134416 34.871120107134416"/>
          <geom name="0/1/2/geom" class="0/1/2/" type="capsule" contype="1" conaffinity="1" condim="3" size="0.060870865166387761" rgba="0.023542326546109993 0.32599305827302327 0.02748845772285291 1" friction="0.59999999999999998 0.10000000000000001 0.10000000000000001" fromto="0 0 0 0.47678412314241703 0.0046357159093385336 0.51920237803253189"/>
          <site name="0/1/2/end2" class="0/1/2/" size="0.0050000000000000001" pos="0.47678412314241703 0.0046357159093385336 0.51920237803253189"/>
          <site name="0/1/2/attach3" class="0/1/2/" size="9.9999999999999995e-07 9.9999999999999995e-07 9.9999999999999995e-07" pos="0.0056764099246802997 5.519106555464613e-05 0.0061814254890805928"/>
          <body pos="0.0056764099246802997 5.519106555464613e-05 0.0061814254890805928" name="0/1/2/3/">
            <joint name="0/1/2/3/joint/" class="0/1/2/" type="hinge" axis="0 -0.99996014302632286 0.0089281777970611764" limited="true" range="-61.320929063815299 61.320929063815299"/>
            <geom name="0/1/2/3/geom" class="0/1/2/3/" type="capsule" contype="1" conaffinity="1" condim="3" size="0.036882463440881065" rgba="0.066123213500567157 0.065709663585472811 0.56534308985759141 1" friction="0.59999999999999998 0.10000000000000001 0.10000000000000001" fromto="0 0 0 0.20994772339606427 0.29672885493106982 0.094177056037363593"/>
            <site name="0/1/2/3/end3" class="0/1/2/3/" size="0.0050000000000000001" pos="0.20994772339606427 0.29672885493106982 0.094177056037363593"/>
            <site name="0/1/2/3/attach4" class="0/1/2/3/" size="9.9999999999999995e-07 9.9999999999999995e-07 9.9999999999999995e-07" pos="0.1341449745797767 0.18959331426863571 0.060173926079196409"/>
            <body pos="0.1341449745797767 0.18959331426863571 0.060173926079196409" name="0/1/2/3/4/">
              <geom name="0/1/2/3/4/geom" class="0/1/2/3/4/" type="capsule" contype="1" conaffinity="1" condim="3" size="0.048271634960262932" rgba="0.41706597729978778 0.098219763319862152 0.94230304801746867 1" friction="0.59999999999999998 0.10000000000000001 0.10000000000000001" fromto="0 0 0 -0.016711556756946688 0.3595681065619496 -0.15855176074728816"/>
              <site name="0/1/2/3/4/end4" class="0/1/2/3/4/" size="0.0050000000000000001" pos="-0.016711556756946688 0.3595681065619496 -0.15855176074728816"/>
            </body>
            <site name="0/1/2/3/attach5" class="0/1/2/3/" size="9.9999999999999995e-07 9.9999999999999995e-07 9.9999999999999995e-07" pos="0.20049175729270627 0.28336429946588287 0.089935357031543123"/>
            <body pos="0.20049175729270627 0.28336429946588287 0.089935357031543123" name="0/1/2/3/5/">
              <joint name="0/1/2/3/5/joint/" class="0/1/2/3/" type="hinge" axis="2.7755575615628914e-17 -0.30251323997558693 0.95314518287586869" limited="true" range="-68.004100232386762 68.004100232386762"/>
              <geom name="0/1/2/3/5/geom" class="0/1/2/3/5/" type="capsule" contype="1" conaffinity="1" condim="3" size="0.03890877162663145" rgba="0.37372594249523683 0.14456741262554729 0.1178502841731478 1" friction="0.59999999999999998 0.10000000000000001 0.10000000000000001" fromto="0 0 0 -0.72053446267107646 -0.52380386788224764 0.46462589357406348"/>
              <site name="0/1/2/3/5/end5" class="0/1/2/3/5/" size="0.0050000000000000001" pos="-0.72053446267107646 -0.52380386788224764 0.46462589357406348"/>
            </body>
          </body>
          <site name="0/1/2/attach6" class="0/1/2/" size="9.9999999999999995e-07 9.9999999999999995e-07 9.9999999999999995e-07" pos="0.44184914940916037 0.004296047271758488 0.48115932970436237"/>
          <body pos="0.44184914940916037 0.004296047271758488 0.48115932970436237" name="0/1/2/6/">
            <joint name="0/1/2/6/joint/" class="0/1/2/" type="hinge" axis="0 -0.99996014302632286 0.0089281777970611764" limited="true" range="-69.139814815668501 69.139814815668501"/>
            <geom name="0/1/2/6/geom" class="0/1/2/6/" type="capsule" contype="1" conaffinity="1" condim="3" size="0.069152246526282393" rgba="0.067412911856682078 0.37457863814916281 0.50255179238327174 1" friction="0.59999999999999998 0.10000000000000001 0.10000000000000001" fromto="0 0 0 0.71682837224018559 -0.53395069840472575 -0.44220618625740443"/>
            <site name="0/1/2/6/end6" class="0/1/2/6/" size="0.0050000000000000001" pos="0.71682837224018559 -0.53395069840472575 -0.44220618625740443"/>
          </body>
        </body>
      </body>
      <site name="0/attach7" class="0/" size="9.9999999999999995e-07 9.9999999999999995e-07 9.9999999999999995e-07" pos="-0.067986841009363683 0.10530798762145294 -0.010163025500505067"/>
      <body pos="-0.067986841009363683 0.10530798762145294 -0.010163025500505067" name="0/7/">
        <geom name="0/7/geom" class="0/7/" type="capsule" contype="1" conaffinity="1" condim="3" size="0.037395047948003871" rgba="0.36377084818756789 0.85115806677334804 0.19484738683559399 1" friction="0.59999999999999998 0.10000000000000001 0.10000000000000001" fromto="0 0 0 -0.41766540321105894 -0.0088097244132043784 0.68269747960794147"/>
        <site name="0/7/end7" class="0/7/" size="0.0050000000000000001" pos="-0.41766540321105894 -0.0088097244132043784 0.68269747960794147"/>
        <site name="0/7/attach8" class="0/7/" size="9.9999999999999995e-07 9.9999999999999995e-07 9.9999999999999995e-07" pos="-0.2120510746846567 -0.0044727466415302583 0.34660935074436966"/>
        <body pos="-0.2120510746846567 -0.0044727466415302583 0.34660935074436966" name="0/7/8/">
          <joint name="0/7/8/joint/" class="0/7/" type="hinge" axis="1.1102230246251565e-16 0.99991675008166703 0.012903213015266299" limited="true" range="-34.702551862840593 34.702551862840593"/>
          <geom name="0/7/8/geom" class="0/7/8/" type="capsule" contype="1" conaffinity="1" condim="3" size="0.052659020686182001" rgba="0.15257368324456022 0.31417430447910355 0.36849620953835305 1" friction="0.59999999999999998 0.10000000000000001 0.10000000000000001" fromto="0 0 0 0.44301331827429236 0.4847906033055378 0.19803398867671551"/>
          <site name="0/7/8/end8" class="0/7/8/" size="0.0050000000000000001" pos="0.44301331827429236 0.4847906033055378 0.19803398867671551"/>
          <site name="0/7/8/attach9" class="0/7/8/" size="9.9999999999999995e-07 9.9999999999999995e-07 9.9999999999999995e-07" pos="0.36429602366079211 0.39865006718145035 0.16284610789047735"/>
          <body pos="0.36429602366079211 0.39865006718145035 0.16284610789047735" name="0/7/8/9/">
            <joint name="0/7/8/9/joint/" class="0/7/8/" type="hinge" axis="-0.76345776285829903 0.59789670147198648 0.24423713620233939" limited="true" range="-68.288133282480445 68.288133282480445"/>
            <geom name="0/7/8/9/geom" class="0/7/8/9/" type="capsule" contype="1" conaffinity="1" condim="3" size="0.057044474827288694" rgba="0.83170401478123723 0.67748156143531713 0.52676934321103064 1" friction="0.59999999999999998 0.10000000000000001 0.10000000000000001" fromto="0 0 0 -0.30252403161275526 -0.083614192078556471 0.73463776746416176"/>
            <site name="0/7/8/9/end9" class="0/7/8/9/" size="0.0050000000000000001" pos="-0.30252403161275526 -0.083614192078556471 0.73463776746416176"/>
          </body>
        </body>
        <site name="0/7/attach10" class="0/7/" size="9.9999999999999995e-07 9.9999999999999995e-07 9.9999999999999995e-07" pos="-0.14844284713122893 -0.0031310722992220459 0.24263814245372389"/>
        <body pos="-0.14844284713122893 -0.0031310722992220459 0.24263814245372389" name="0/7/10/">
          <joint name="0/7/10/joint/" class="0/7/" type="hinge" axis="1.1102230246251565e-16 0.99991675008166703 0.012903213015266299" limited="true" range="-62.39062343712181 62.39062343712181"/>
          <geom name="0/7/10/geom" class="0/7/10/" type="capsule" contype="1" conaffinity="1" condim="3" size="0.043433660235503262" rgba="0.36186741495498875 0.81319967521220271 0.71652762688407379 1" friction="0.59999999999999998 0.10000000000000001 0.10000000000000001" fromto="0 0 0 -0.16346525287621261 0.73645763902505257 0.38040099782129522"/>
          <site name="0/7/10/end10" class="0/7/10/" size="0.0050000000000000001" pos="-0.16346525287621261 0.73645763902505257 0.38040099782129522"/>
        </body>
      </body>
      <camera name="0/iso" class="0/" mode="trackcom" pos="-2.2999999999999998 -2.2999999999999998 1" xyaxes="0.45000000000000001 -0.45000000000000001 0 0.29999999999999999 0.14999999999999999 0.93999999999999995"/>
    </body>
  </worldbody>
  <actuator>
    <motor name="0/1/2/motor" class="0/1/2/" ctrllimited="true" ctrlrange="-1 1" gear="84" joint="0/1/2/joint/"/>
    <motor name="0/1/2/3/motor" class="0/1/2/3/" ctrllimited="true" ctrlrange="-1 1" gear="82" joint="0/1/2/3/joint/"/>
    <motor name="0/1/2/3/5/motor" class="0/1/2/3/5/" ctrllimited="true" ctrlrange="-1 1" gear="95" joint="0/1/2/3/5/joint/"/>
    <motor name="0/1/2/6/motor" class="0/1/2/6/" ctrllimited="true" ctrlrange="-1 1" gear="77" joint="0/1/2/6/joint/"/>
    <motor name="0/7/8/motor" class="0/7/8/" ctrllimited="true" ctrlrange="-1 1" gear="70" joint="0/7/8/joint/"/>
    <motor name="0/7/8/9/motor" class="0/7/8/9/" ctrllimited="true" ctrlrange="-1 1" gear="71" joint="0/7/8/9/joint/"/>
    <motor name="0/7/10/motor" class="0/7/10/" ctrllimited="true" ctrlrange="-1 1" gear="81" joint="0/7/10/joint/"/>
  </actuator>
  <sensor>
    <subtreelinvel name="velocity" body="0/"/>
  </sensor>
</mujoco>
