<mujoco model="morphology">
  <option timestep="0.01"/>
  <default>
    <default class="/"/>
    <default class="0/"/>
    <default class="0/1/"/>
    <default class="0/1/2/"/>
    <default class="0/1/3/"/>
    <default class="0/1/4/"/>
    <default class="0/1/4/5/"/>
    <default class="0/1/4/5/6/"/>
    <default class="0/1/4/5/7/"/>
    <default class="0/1/4/5/7/8/"/>
    <default class="0/9/"/>
    <default class="0/9/10/"/>
  </default>
  <asset>
    <texture name="texplane" type="2d" builtin="checker" rgb1="0.10000000000000001 0.20000000000000001 0.29999999999999999" rgb2="0.20000000000000001 0.29999999999999999 0.40000000000000002" width="300" height="300"/>
    <material name="MatPlane" class="/" texture="texplane" texrepeat="20 20" specular="1" shininess="1" reflectance="0.5"/>
  </asset>
  <worldbody>
    <light name="//unnamed_light_0" class="/" directional="true" pos="0 0 1.5" dir="0 0 -1.3" cutoff="100" exponent="1" diffuse="1 1 1" specular="0.10000000000000001 0.10000000000000001 0.10000000000000001"/>
    <geom name="ground" class="/" type="plane" size="15 15 0.5" material="MatPlane" rgba="1 1 1 1"/>
    <site name="body" class="/" size="9.9999999999999995e-07 9.9999999999999995e-07 9.9999999999999995e-07" pos="0 0 0.93179324865341184"/>
    <body pos="0 0 0.93179324865341184" name="0/">
      <freejoint name="0/"/>
      <geom name="0/geom" class="0/" type="capsule" contype="1" conaffinity="1" condim="3" size="0.064928922683095233" rgba="0.38612640250710895 0.59122339172720217 0.88157180291880721 1" friction="0.59999999999999998 0.10000000000000001 0.10000000000000001" fromto="0 0 0 -0.25791835479945874 0.14176463191886213 -0.20336806842478317"/>
      <site name="0/end0" class="0/" size="0.0050000000000000001" pos="-0.25791835479945874 0.14176463191886213 -0.20336806842478317"/>
      <site name="0/attach1" class="0/" size="9.9999999999999995e-07 9.9999999999999995e-07 9.9999999999999995e-07" pos="-0.049520442615288464 0.027218874458446396 -0.039046762569658985"/>
      <body pos="-0.049520442615288464 0.027218874458446396 -0.039046762569658985" name="0/1/">
        <joint name="0/1/joint/" class="0/" type="hinge" axis="0 1 0" limited="true" range="-36.923249655214157 36.923249655214157"/>
        <geom name="0/1/geom" class="0/1/" type="capsule" contype="1" conaffinity="1" condim="3" size="0.060880998989674764" rgba="0.53383751289224624 0.22424572820076505 0.69057763367636871 1" friction="0.59999999999999998 0.10000000000000001 0.10000000000000001" fromto="0 0 0 0.42361097328443398 0.67003836205439082 0.43259294919305824"/>
        <site name="0/1/end1" class="0/1/" size="0.0050000000000000001" pos="0.42361097328443398 0.67003836205439082 0.43259294919305824"/>
        <site name="0/1/attach2" class="0/1/" size="9.9999999999999995e-07 9.9999999999999995e-07 9.9999999999999995e-07" pos="0.20796563208055216 0.32894556626439408 0.21237520221677028"/>
        <body pos="0.20796563208055216 0.32894556626439408 0.21237520221677028" name="0/1/2/">
          <joint name="0/1/2/joint/" class="0/1/" type="hinge" axis="-0.8831561591526057 0.3940824769001931 0.25442916489865275" limited="true" range="-67.636437379097899 67.636437379097899"/>
          <geom name="0/1/2/geom" class="0/1/2/" type="capsule" contype="1" conaffinity="1" condim="3" size="0.040219988788765371" rgba="0.87047462476395743 0.60924746273397534 0.99120958221212918 1" friction="0.59999999999999998 0.10000000000000001 0.10000000000000001" fromto="0 0 0 -0.22899766356222639 0.29427861282549572 0.36292972423472425"/>
          <site name="0/1/2/end2" class="0/1/2/" size="0.0050000000000000001" pos="-0.22899766356222639 0.29427861282549572 0.36292972423472425"/>
        </body>
        <site name="0/1/attach3" class="0/1/" size="9.9999999999999995e-07 9.9999999999999995e-07 9.9999999999999995e-07" pos="0.2946043961533687 0.46598473481961511 0.30085099918234076"/>
        <body pos="0.2946043961533687 0.46598473481961511 0.30085099918234076" name="0/1/3/">
          <joint name="0/1/3/joint/" class="0/1/" type="hinge" axis="-2.7755575615628914e-17 -0.54240141359029237 0.84011945968133139" limited="true" range="-62.157678088509428 62.157678088509428"/>
          <geom name="0/1/3/geom" class="0/1/3/" type="capsule" contype="1" conaffinity="1" condim="3" size="0.03539999523745356" rgba="0.4595801880099365 0.64879606912867915 0.845481284792576 1" friction="0.59999999999999998 0.10000000000000001 0.10000000000000001" fromto="0 0 0 0.55574523869546355 -0.4395472583936651 0.36013526850960487"/>
          <site name="0/1/3/end3" class="0/1/3/" size="0.0050000000000000001" pos="0.55574523869546355 -0.4395472583936651 0.36013526850960487"/>
        </body>
        <site name="0/1/attach4" class="0/1/" size="9.9999999999999995e-07 9.9999999999999995e-07 9.9999999999999995e-07" pos="0.27081704974052023 0.42835956542301529 0.27655928110330597"/>
        <body pos="0.27081704974052023 0.42835956542301529 0.27655928110330597" name="0/1/4/">
          <joint name="0/1/4/joint/" class="0/1/" type="hinge" axis="-0.8831561591526057 0.3940824769001931 0.25442916489865275" limited="true" range="-47.188983320807125 47.188983320807125"/>
          <geom name="0/1/4/geom" class="0/1/4/" type="capsule" contype="1" conaffinity="1" condim="3" size="0.047862345383242751" rgba="0.25352452591795405 0.34106277802766261 0.57986922596886958 1" friction="0.59999999999999998 0.10000000000000001 0.10000000000000001" fromto="0 0 0 -0.40770523524421287 -0.0031101716263395307 -0.34996990572048986"/>
          <site name="0/1/4/end4" class="0/1/4/" size="0.0050000000000000001" pos="-0.40770523524421287 -0.0031101716263395307 -0.34996990572048986"/>
          <site name="0/1/4/attach5" class="0/1/4/" size="9.9999999999999995e-07 9.9999999999999995e-07 9.9999999999999995e-07" pos="-0.20390397275209352 -0.0015554775748013205 -0.17502903556619567"/>
          <body pos="-0.20390397275209352 -0.0015554775748013205 -0.17502903556619567" name="0/1/4/5/">
            <joint name="0/1/4/5/joint/" class="0/1/4/" type="hinge" axis="0.65135133345929019 -0.006742954828172408 -0.75874631660456149" limited="true" range="-69.143426282794053 69.143426282794053"/>
            <geom name="0/1/4/5/geom" class="0/1/4/5/" type="capsule" contype="1" conaffinity="1" condim="3" size="0.058245505139039956" rgba="0.54429438754268145 0.79520278045002424 0.19253089459944817 1" friction="0.59999999999999998 0.10000000000000001 0.10000000000000001" fromto="0 0 0 -0.0069585276689325681 0.36427108741293956 0.69926625561098676"/>
            <site name="0/1/4/5/end5" class="0/1/4/5/" size="0.0050000000000000001" pos="-0.0069585276689325681 0.36427108741293956 0.69926625561098676"/>
            <site name="0/1/4/5/attach6" class="0/1/4/5/" size="9.9999999999999995e-07 9.9999999999999995e-07 9.9999999999999995e-07" pos="-0.0030216439954241642 0.15817966046210832 0.30364665960921572"/>
            <body pos="-0.0030216439954241642 0.15817966046210832 0.30364665960921572" name="0/1/4/5/6/">
              <joint name="0/1/4/5/6/joint/" class="0/1/4/5/" type="hinge" axis="-0.99996105768796262 -0.0040772517541310949 -0.0078268209193953497" limited="true" range="-40.844211259715209 40.844211259715209"/>
              <geom name="0/1/4/5/6/geom" class="0/1/4/5/6/" type="capsule" contype="1" conaffinity="1" condim="3" size="0.069624025599259384" rgba="0.6519603425626922 0.13271678087136818 0.63018382320261723 1" friction="0.59999999999999998 0.10000000000000001 0.10000000000000001" fromto="0 0 0 -0.70325197150122376 0.65884338224187178 -0.41543928319876378"/>
              <site name="0/1/4/5/6/end6" class="0/1/4/5/6/" size="0.0050000000000000001" pos="-0.70325197150122376 0.65884338224187178 -0.41543928319876378"/>
            </body>
            <site name="0/1/4/5/attach7" class="0/1/4/5/" size="9.9999999999999995e-07 9.9999999999999995e-07 9.9999999999999995e-07" pos="-0.0038262165844653831 0.20029812946255529 0.38449859962778499"/>
            <body pos="-0.0038262165844653831 0.20029812946255529 0.38449859962778499" name="0/1/4/5/7/">
              <joint name="0/1/4/5/7/joint/" class="0/1/4/5/" type="hinge" axis="1.6653345369377348e-16 -0.88687775366476573 0.46200416670690181" limited="true" range="-58.981332531887247 58.981332531887247"/>
              <geom name="0/1/4/5/7/geom" class="0/1/4/5/7/" type="capsule" contype="1" conaffinity="1" condim="3" size="0.049958476376630395" rgba="0.3095794835750999 0.20321631949837204 0.71128483697583811 1" friction="0.59999999999999998 0.10000000000000001 0.10000000000000001" fromto="0 0 0 0.60458297961445995 -0.67837433484250287 0.14455927122076917"/>
              <site name="0/1/4/5/7/end7" class="0/1/4/5/7/" size="0.0050000000000000001" pos="0.60458297961445995 -0.67837433484250287 0.14455927122076917"/>
              <site name="0/1/4/5/7/attach8" class="0/1/4/5/7/" size="9.9999999999999995e-07 9.9999999999999995e-07 9.9999999999999995e-07" pos="0.48315029100149015 -0.54212038436164167 0.11552401624309222"/>
              <body pos="0.48315029100149015 -0.54212038436164167 0.11552401624309222" name="0/1/4/5/7/8/">
                <joint name="0/1/4/5/7/8/joint/" class="0/1/4/5/7/" type="hinge" axis="-1.3877787807814457e-17 0.20841702001572315 0.97804005325332422" limited="true" range="-34.050550675417917 34.050550675417917"/>
                <geom name="0/1/4/5/7/8/geom" class="0/1/4/5/7/8/" type="capsule" contype="1" conaffinity="1" condim="3" size="0.060440778044779507" rgba="0.83047752961267673 0.099464030619831001 0.31826629833279874 1" friction="0.59999999999999998 0.10000000000000001 0.10000000000000001" fromto="0 0 0 0.59703980078220975 0.32583773789629777 0.37227234635831086"/>
                <site name="0/1/4/5/7/8/end8" class="0/1/4/5/7/8/" size="0.0050000000000000001" pos="0.59703980078220975 0.32583773789629777 0.37227234635831086"/>
              </body>
            </body>
          </body>
        </body>
      </body>
      <site name="0/attach9" class="0/" size="9.9999999999999995e-07 9.9999999999999995e-07 9.9999999999999995e-07" pos="-0.16437434206272389 0.090348234880552561 -0.12960881543263045"/>
      <body pos="-0.16437434206272389 0.090348234880552561 -0.12960881543263045" name="0/9/">
        <joint name="0/9/joint/" class="0/" type="hinge" axis="0 1 0" limited="true" range="-66.514768494995167 66.514768494995167"/>
        <geom name="0/9/geom" class="0/9/" type="capsule" contype="1" conaffinity="1" condim="3" size="0.066559310687333437" rgba="0.18366670492242088 0.6758769628920912 0.60777692037212783 1" friction="0.59999999999999998 0.10000000000000001 0.10000000000000001" fromto="0 0 0 0.029561609256497534 0.35190988958376157 -0.70218444493864329"/>
        <site name="0/9/end9" class="0/9/" size="0.0050000000000000001" pos="0.029561609256497534 0.35190988958376157 -0.70218444493864329"/>
        <site name="0/9/attach10" class="0/9/" size="9.9999999999999995e-07 9.9999999999999995e-07 9.9999999999999995e-07" pos="0.0011904367164796269 0.014171300683190061 -0.028276746970806357"/>
        <body pos="0.0011904367164796269 0.014171300683190061 -0.028276746970806357" name="0/9/10/">
          <joint name="0/9/10/joint/" class="0/9/" type="hinge" axis="1.1102230246251565e-16 0.89401038680470779 0.44804623453980313" limited="true" range="-57.726230941464358 57.726230941464358"/>
          <geom name="0/9/10/geom" class="0/9/10/" type="capsule" contype="1" conaffinity="1" condim="3" size="0.048583511663382026" rgba="0.85201808016027558 0.74065710866592482 0.64890003782593586 1" friction="0.59999999999999998 0.10000000000000001 0.10000000000000001" fromto="0 0 0 -0.033357291551844304 0.57692729025447886 0.43994813570357882"/>
          <site name="0/9/10/end10" class="0/9/10/" size="0.0050000000000000001" pos="-0.033357291551844304 0.57692729025447886 0.43994813570357882"/>
        </body>
      </body>
      <camera name="0/iso" class="0/" mode="trackcom" pos="-2.2999999999999998 -2.2999999999999998 1" xyaxes="0.45000000000000001 -0.45000000000000001 0 0.29999999999999999 0.14999999999999999 0.93999999999999995"/>
    </body>
  </worldbody>
  <actuator>
    <motor name="0/1/motor" class="0/1/" ctrllimited="true" ctrlrange="-1 1" gear="78" joint="0/1/joint/"/>
    <motor name="0/1/2/motor" class="0/1/2/" ctrllimited="true" ctrlrange="-1 1" gear="99" joint="0/1/2/joint/"/>
    <motor name="0/1/3/motor" class="0/1/3/" ctrllimited="true" ctrlrange="-1 1" gear="50" joint="0/1/3/joint/"/>
    <motor name="0/1/4/motor" class="0/1/4/" ctrllimited="true" ctrlrange="-1 1" gear="95" joint="0/1/4/joint/"/>
    <motor name="0/1/4/5/motor" class="0/1/4/5/" ctrllimited="true" ctrlrange="-1 1" gear="60" joint="0/1/4/5/joint/"/>
    <motor name="0/1/4/5/6/motor" class="0/1/4/5/6/" ctrllimited="true" ctrlrange="-1 1" gear="98" joint="0/1/4/5/6/joint/"/>
    <motor name="0/1/4/5/7/motor" class="0/1/4/5/7/" ctrllimited="true" ctrlrange="-1 1" gear="92" joint="0/1/4/5/7/joint/"/>
    <motor name="0/1/4/5/7/8/motor" class="0/1/4/5/7/8/" ctrllimited="true" ctrlrange="-1 1" gear="63" joint="0/1/4/5/7/8/joint/"/>
    <motor name="0/9/motor" class="0/9/" ctrllimited="true" ctrlrange="-1 1" gear="75" joint="0/9/joint/"/>
    <motor name="0/9/10/motor" class="0/9/10/" ctrllimited="true" ctrlrange="-1 1" gear="74" joint="0/9/10/joint/"/>
  </actuator>
  <sensor>
    <subtreelinvel name="velocity" body="0/"/>
  </sensor>
</mujoco>
