<mujoco model="morphology">
  <option timestep="0.01"/>
  <default>
    <default class="/"/>
    <default class="0/"/>
    <default class="0/1/"/>
    <default class="0/1/2/"/>
    <default class="0/1/2/3/"/>
    <default class="0/1/2/3/4/"/>
  </default>
  <asset>
    <texture name="texplane" type="2d" builtin="checker" rgb1="0.10000000000000001 0.20000000000000001 0.29999999999999999" rgb2="0.20000000000000001 0.29999999999999999 0.40000000000000002" width="300" height="300"/>
    <material name="MatPlane" class="/" texture="texplane" texrepeat="20 20" specular="1" shininess="1" reflectance="0.5"/>
  </asset>
  <worldbody>
    <light name="//unnamed_light_0" class="/" directional="true" pos="0 0 1.5" dir="0 0 -1.3" cutoff="100" exponent="1" diffuse="1 1 1" specular="0.10000000000000001 0.10000000000000001 0.10000000000000001"/>
    <geom name="ground" class="/" type="plane" size="15 15 0.5" material="MatPlane" rgba="1 1 1 1"/>
    <site name="body" class="/" size="9.9999999999999995e-07 9.9999999999999995e-07 9.9999999999999995e-07" pos="0 0 0.53333807587623594"/>
    <body pos="0 0 0.53333807587623594" name="0/">
      <freejoint name="0/"/>
      <geom name="0/geom" class="0/" type="capsule" contype="1" conaffinity="1" condim="3" size="0.06340897440408623" rgba="0.93846790890076759 0.7429702923360596 0.84305062747102677 1" friction="0.59999999999999998 0.10000000000000001 0.10000000000000001" fromto="0 0 0 0.078108543246076856 -0.21683349515738159 -0.43333808380673461"/>
      <site name="0/end0" class="0/" size="0.0050000000000000001" pos="0.078108543246076856 -0.21683349515738159 -0.43333808380673461"/>
      <site name="0/attach1" class="0/" size="9.9999999999999995e-07 9.9999999999999995e-07 9.9999999999999995e-07" pos="0.056081414592003671 -0.15568500747791264 -0.31113386227044426"/>
      <body pos="0.056081414592003671 -0.15568500747791264 -0.31113386227044426" name="0/1/">
        <joint name="0/1/joint/" class="0/" type="hinge" axis="0 1 0" limited="true" range="-62.147443829586059 62.147443829586059"/>
        <geom name="0/1/geom" class="0/1/" type="capsule" contype="1" conaffinity="1" condim="3" size="0.041399952614250342" rgba="0.53504154396141801 0.19776533506753546 0.64566665441282378 1" friction="0.59999999999999998 0.10000000000000001 0.10000000000000001" fromto="0 0 0 0.47952923744660758 -0.3324701734921458 0.73629733443824374"/>
        <site name="0/1/end1" class="0/1/" size="0.0050000000000000001" pos="0.47952923744660758 -0.3324701734921458 0.73629733443824374"/>
        <site name="0/1/attach2" class="0/1/" size="9.9999999999999995e-07 9.9999999999999995e-07 9.9999999999999995e-07" pos="0.45815569713944304 -0.31765133847824201 0.70347914625128083"/>
        <body pos="0.45815569713944304 -0.31765133847824201 0.70347914625128083" name="0/1/2/">
          <joint name="0/1/2/joint/" class="0/1/" type="hinge" axis="-5.5511151231257827e-17 0.91139437244539268 0.41153407863124603" limited="true" range="-50.207800430868502 50.207800430868502"/>
          <geom name="0/1/2/geom" class="0/1/2/" type="capsule" contype="1" conaffinity="1" condim="3" size="0.068113222291277378" rgba="0.19223813513259069 0.87313838846854219 0.99821633514637342 1" friction="0.59999999999999998 0.10000000000000001 0.10000000000000001" fromto="0 0 0 -0.37973176235402389 0.71708548698597285 0.21201059648758425"/>
          <site name="0/1/2/end2" class="0/1/2/" size="0.0050000000000000001" pos="-0.37973176235402389 0.71708548698597285 0.21201059648758425"/>
          <site name="0/1/2/attach3" class="0/1/2/" size="9.9999999999999995e-07 9.9999999999999995e-07 9.9999999999999995e-07" pos="-0.0068049691426298378 0.01285050421201756 0.0037993281311651346"/>
          <body pos="-0.0068049691426298378 0.01285050421201756 0.0037993281311651346" name="0/1/2/3/">
            <joint name="0/1/2/3/joint/" class="0/1/2/" type="hinge" axis="2.7755575615628914e-17 -0.28352377674975632 0.95896520688581499" limited="true" range="-51.649826477663026 51.649826477663026"/>
            <geom name="0/1/2/3/geom" class="0/1/2/3/" type="capsule" contype="1" conaffinity="1" condim="3" size="0.060678049539633766" rgba="0.85642225111792336 0.36609107472939018 0.75670179767151824 1" friction="0.59999999999999998 0.10000000000000001 0.10000000000000001" fromto="0 0 0 0.73241222973348963 -0.075020500830744741 -0.6259884269798266"/>
            <site name="0/1/2/3/end3" class="0/1/2/3/" size="0.0050000000000000001" pos="0.73241222973348963 -0.075020500830744741 -0.6259884269798266"/>
            <site name="0/1/2/3/attach4" class="0/1/2/3/" size="9.9999999999999995e-07 9.9999999999999995e-07 9.9999999999999995e-07" pos="0.041231514720510225 -0.0042233168136316607 -0.035240333235942382"/>
            <body pos="0.041231514720510225 -0.0042233168136316607 -0.035240333235942382" name="0/1/2/3/4/">
              <joint name="0/1/2/3/4/joint/" class="0/1/2/3/" type="hinge" axis="0.65239207468934057 0.090181710417546856 0.7524970697542307" limited="true" range="-64.290512374267678 64.290512374267678"/>
              <geom name="0/1/2/3/4/geom" class="0/1/2/3/4/" type="capsule" contype="1" conaffinity="1" condim="3" size="0.040152678327575089" rgba="0.84451574055605749 0.60875872206920745 0.73512071718630456 1" friction="0.59999999999999998 0.10000000000000001 0.10000000000000001" fromto="0 0 0 -0.73825674451578382 -0.74083425492700639 -0.65889998677885431"/>
              <site name="0/1/2/3/4/end4" class="0/1/2/3/4/" size="0.0050000000000000001" pos="-0.73825674451578382 -0.74083425492700639 -0.65889998677885431"/>
            </body>
          </body>
        </body>
      </body>
      <camera name="0/iso" class="0/" mode="trackcom" pos="-2.2999999999999998 -2.2999999999999998 1" xyaxes="0.45000000000000001 -0.45000000000000001 0 0.29999999999999999 0.14999999999999999 0.93999999999999995"/>
    </body>
  </worldbody>
  <actuator>
    <motor name="0/1/motor" class="0/1/" ctrllimited="true" ctrlrange="-1 1" gear="59" joint="0/1/joint/"/>
    <motor name="0/1/2/motor" class="0/1/2/" ctrllimited="true" ctrlrange="-1 1" gear="75" joint="0/1/2/joint/"/>
    <motor name="0/1/2/3/motor" class="0/1/2/3/" ctrllimited="true" ctrlrange="-1 1" gear="72" joint="0/1/2/3/joint/"/>
    <motor name="0/1/2/3/4/motor" class="0/1/2/3/4/" ctrllimited="true" ctrlrange="-1 1" gear="84" joint="0/1/2/3/4/joint/"/>
  </actuator>
  <sensor>
    <subtreelinvel name="velocity" body="0/"/>
  </sensor>
</mujoco>
