<mujoco model="morphology">
  <option timestep="0.01"/>
  <default>
    <default class="/"/>
    <default class="0/"/>
    <default class="0/1/"/>
    <default class="0/1/2/"/>
    <default class="0/1/2/3/"/>
    <default class="0/1/2/3/4/"/>
  </default>
  <asset>
    <texture name="texplane" type="2d" builtin="checker" rgb1="0.10000000000000001 0.20000000000000001 0.29999999999999999" rgb2="0.20000000000000001 0.29999999999999999 0.40000000000000002" width="300" height="300"/>
    <material name="MatPlane" class="/" texture="texplane" texrepeat="20 20" specular="1" shininess="1" reflectance="0.5"/>
  </asset>
  <worldbody>
    <light name="//unnamed_light_0" class="/" directional="true" pos="0 0 1.5" dir="0 0 -1.3" cutoff="100" exponent="1" diffuse="1 1 1" specular="0.10000000000000001 0.10000000000000001 0.10000000000000001"/>
    <geom name="ground" class="/" type="plane" size="15 15 0.5" material="MatPlane" rgba="1 1 1 1"/>
    <site name="body" class="/" size="9.9999999999999995e-07 9.9999999999999995e-07 9.9999999999999995e-07" pos="0 0 0.51351369023323057"/>
    <body pos="0 0 0.51351369023323057" name="0/">
      <freejoint name="0/"/>
      <geom name="0/geom" class="0/" type="capsule" contype="1" conaffinity="1" condim="3" size="0.044642901294738635" rgba="0.771652967660861 0.53522101531491217 0.70886555666993745 1" friction="0.59999999999999998 0.10000000000000001 0.10000000000000001" fromto="0 0 0 -0.10220781173872295 -0.028818043599643905 0.16934384507682299"/>
      <site name="0/end0" class="0/" size="0.0050000000000000001" pos="-0.10220781173872295 -0.028818043599643905 0.16934384507682299"/>
      <site name="0/attach1" class="0/" size="9.9999999999999995e-07 9.9999999999999995e-07 9.9999999999999995e-07" pos="-0.091558221939487219 -0.025815334335725436 0.15169898550675717"/>
      <body pos="-0.091558221939487219 -0.025815334335725436 0.15169898550675717" name="0/1/">
        <joint name="0/1/joint/" class="0/" type="hinge" axis="0 0 1" limited="true" range="-33.653783211344916 33.653783211344916"/>
        <geom name="0/1/geom" class="0/1/" type="capsule" contype="1" conaffinity="1" condim="3" size="0.056273758147466116" rgba="0.022018222260874687 0.94704664935804062 0.45770339987801478 1" friction="0.59999999999999998 0.10000000000000001 0.10000000000000001" fromto="0 0 0 -0.30680721328788552 -0.50098492399818362 0.57628436133218264"/>
        <site name="0/1/end1" class="0/1/" size="0.0050000000000000001" pos="-0.30680721328788552 -0.50098492399818362 0.57628436133218264"/>
        <site name="0/1/attach2" class="0/1/" size="9.9999999999999995e-07 9.9999999999999995e-07 9.9999999999999995e-07" pos="-0.0023609452725599522 -0.0038551831140536683 0.0044346279344507546"/>
        <body pos="-0.0023609452725599522 -0.0038551831140536683 0.0044346279344507546" name="0/1/2/">
          <joint name="0/1/2/joint/" class="0/1/" type="hinge" axis="0 0.75469105365552425 0.65608034076042432" limited="true" range="-58.989681228046692 58.989681228046692"/>
          <geom name="0/1/2/geom" class="0/1/2/" type="capsule" contype="1" conaffinity="1" condim="3" size="0.049142573064880089" rgba="0.80697676116316097 0.98142242317656347 0.89963704861755822 1" friction="0.59999999999999998 0.10000000000000001 0.10000000000000001" fromto="0 0 0 -0.58119810078937684 -0.52772238527697957 -0.094814749648943986"/>
          <site name="0/1/2/end2" class="0/1/2/" size="0.0050000000000000001" pos="-0.58119810078937684 -0.52772238527697957 -0.094814749648943986"/>
          <site name="0/1/2/attach3" class="0/1/2/" size="9.9999999999999995e-07 9.9999999999999995e-07 9.9999999999999995e-07" pos="-0.57606219295156469 -0.52305902947617455 -0.093976894509361072"/>
          <body pos="-0.57606219295156469 -0.52305902947617455 -0.093976894509361072" name="0/1/2/3/">
            <joint name="0/1/2/3/joint/" class="0/1/2/" type="hinge" axis="0.6780627727311197 -0.72342053288138963 -0.12997541629782117" limited="true" range="-61.003111519133341 61.003111519133341"/>
            <geom name="0/1/2/3/geom" class="0/1/2/3/" type="capsule" contype="1" conaffinity="1" condim="3" size="0.057763169901724115" rgba="0.71232039897741606 0.7101443839608883 0.74291557728186541 1" friction="0.59999999999999998 0.10000000000000001 0.10000000000000001" fromto="0 0 0 -0.25830343605720762 0.6993989566145391 -0.47567041405700555"/>
            <site name="0/1/2/3/end3" class="0/1/2/3/" size="0.0050000000000000001" pos="-0.25830343605720762 0.6993989566145391 -0.47567041405700555"/>
            <site name="0/1/2/3/attach4" class="0/1/2/3/" size="9.9999999999999995e-07 9.9999999999999995e-07 9.9999999999999995e-07" pos="-0.0011241063754331014 0.0030437025465179625 -0.002070062068117281"/>
            <body pos="-0.0011241063754331014 0.0030437025465179625 -0.002070062068117281" name="0/1/2/3/4/">
              <joint name="0/1/2/3/4/joint/" class="0/1/2/3/" type="hinge" axis="0 0.56237398712800912 0.82688300176128049" limited="true" range="-35.640678560869439 35.640678560869439"/>
              <geom name="0/1/2/3/4/geom" class="0/1/2/3/4/" type="capsule" contype="1" conaffinity="1" condim="3" size="0.045559830455620419" rgba="0.94191159299330351 0.10341821461118939 0.91190007264045225 1" friction="0.59999999999999998 0.10000000000000001 0.10000000000000001" fromto="0 0 0 -0.2938118103595721 0.15733526889710991 0.69057247883659145"/>
              <site name="0/1/2/3/4/end4" class="0/1/2/3/4/" size="0.0050000000000000001" pos="-0.2938118103595721 0.15733526889710991 0.69057247883659145"/>
            </body>
          </body>
        </body>
      </body>
      <camera name="0/iso" class="0/" mode="trackcom" pos="-2.2999999999999998 -2.2999999999999998 1" xyaxes="0.45000000000000001 -0.45000000000000001 0 0.29999999999999999 0.14999999999999999 0.93999999999999995"/>
    </body>
  </worldbody>
  <actuator>
    <motor name="0/1/motor" class="0/1/" ctrllimited="true" ctrlrange="-1 1" gear="96" joint="0/1/joint/"/>
    <motor name="0/1/2/motor" class="0/1/2/" ctrllimited="true" ctrlrange="-1 1" gear="71" joint="0/1/2/joint/"/>
    <motor name="0/1/2/3/motor" class="0/1/2/3/" ctrllimited="true" ctrlrange="-1 1" gear="81" joint="0/1/2/3/joint/"/>
    <motor name="0/1/2/3/4/motor" class="0/1/2/3/4/" ctrllimited="true" ctrlrange="-1 1" gear="82" joint="0/1/2/3/4/joint/"/>
  </actuator>
  <sensor>
    <subtreelinvel name="velocity" body="0/"/>
  </sensor>
</mujoco>
