<mujoco model="morphology">
  <option timestep="0.01"/>
  <default>
    <default class="/"/>
    <default class="0/"/>
    <default class="0/1/"/>
    <default class="0/2/"/>
    <default class="0/2/3/"/>
    <default class="0/2/3/4/"/>
    <default class="0/2/3/5/"/>
    <default class="0/2/3/5/6/"/>
    <default class="0/2/3/5/6/7/"/>
    <default class="0/2/3/5/6/8/"/>
    <default class="0/9/"/>
    <default class="0/9/10/"/>
  </default>
  <asset>
    <texture name="texplane" type="2d" builtin="checker" rgb1="0.10000000000000001 0.20000000000000001 0.29999999999999999" rgb2="0.20000000000000001 0.29999999999999999 0.40000000000000002" width="300" height="300"/>
    <material name="MatPlane" class="/" texture="texplane" texrepeat="20 20" specular="1" shininess="1" reflectance="0.5"/>
  </asset>
  <worldbody>
    <light name="//unnamed_light_0" class="/" directional="true" pos="0 0 1.5" dir="0 0 -1.3" cutoff="100" exponent="1" diffuse="1 1 1" specular="0.10000000000000001 0.10000000000000001 0.10000000000000001"/>
    <geom name="ground" class="/" type="plane" size="15 15 0.5" material="MatPlane" rgba="1 1 1 1"/>
    <site name="body" class="/" size="9.9999999999999995e-07 9.9999999999999995e-07 9.9999999999999995e-07" pos="0 0 0.70940146446228025"/>
    <body pos="0 0 0.70940146446228025" name="0/">
      <freejoint name="0/"/>
      <geom name="0/geom" class="0/" type="capsule" contype="1" conaffinity="1" condim="3" size="0.04167987004461178" rgba="0.39750936916674762 0.6246337051903279 0.14114790712717229 1" friction="0.59999999999999998 0.10000000000000001 0.10000000000000001" fromto="0 0 0 0.077711080378780384 -0.17623995390633895 0.31492832595764741"/>
      <site name="0/end0" class="0/" size="0.0050000000000000001" pos="0.077711080378780384 -0.17623995390633895 0.31492832595764741"/>
      <site name="0/attach1" class="0/" size="9.9999999999999995e-07 9.9999999999999995e-07 9.9999999999999995e-07" pos="0.073050428159662423 -0.16567012102964776 0.29604078258438093"/>
      <body pos="0.073050428159662423 -0.16567012102964776 0.29604078258438093" name="0/1/">
        <geom name="0/1/geom" class="0/1/" type="capsule" contype="1" conaffinity="1" condim="3" size="0.053882339813977567" rgba="0.21052398648436166 0.46869647088970201 0.52710428763191997 1" friction="0.59999999999999998 0.10000000000000001 0.10000000000000001" fromto="0 0 0 0.25481016993697292 -0.021409138139385164 -0.049448284001664455"/>
        <site name="0/1/end1" class="0/1/" size="0.0050000000000000001" pos="0.25481016993697292 -0.021409138139385164 -0.049448284001664455"/>
      </body>
      <site name="0/attach2" class="0/" size="9.9999999999999995e-07 9.9999999999999995e-07 9.9999999999999995e-07" pos="0.025027656271947325 -0.056759897896827012 0.10142592091050127"/>
      <body pos="0.025027656271947325 -0.056759897896827012 0.10142592091050127" name="0/2/">
        <geom name="0/2/geom" class="0/2/" type="capsule" contype="1" conaffinity="1" condim="3" size="0.04331342351721798" rgba="0.30042659796296622 0.24998585549515207 0.26283802349937258 1" friction="0.59999999999999998 0.10000000000000001 0.10000000000000001" fromto="0 0 0 0.65522673932053821 0.30739552578591711 0.33829126342989024"/>
        <site name="0/2/end2" class="0/2/" size="0.0050000000000000001" pos="0.65522673932053821 0.30739552578591711 0.33829126342989024"/>
        <site name="0/2/attach3" class="0/2/" size="9.9999999999999995e-07 9.9999999999999995e-07 9.9999999999999995e-07" pos="0.37705853991332711 0.17689465519816935 0.19467399939535843"/>
        <body pos="0.37705853991332711 0.17689465519816935 0.19467399939535843" name="0/2/3/">
          <joint name="0/2/3/joint/" class="0/2/" type="hinge" axis="0 -0.74009466603706864 0.67250270282243441" limited="true" range="-30.876621381341934 30.876621381341934"/>
          <geom name="0/2/3/geom" class="0/2/3/" type="capsule" contype="1" conaffinity="1" condim="3" size="0.057915490896964045" rgba="0.046500056555530578 0.24044340561725353 0.1597147340475833 1" friction="0.59999999999999998 0.10000000000000001 0.10000000000000001" fromto="0 0 0 0.45684772291023679 -0.19087642491050616 -0.30119364448079355"/>
          <site name="0/2/3/end3" class="0/2/3/" size="0.0050000000000000001" pos="0.45684772291023679 -0.19087642491050616 -0.30119364448079355"/>
          <site name="0/2/3/attach4" class="0/2/3/" size="9.9999999999999995e-07 9.9999999999999995e-07 9.9999999999999995e-07" pos="0.17584552942700213 -0.07347035852494839 -0.11593262528787932"/>
          <body pos="0.17584552942700213 -0.07347035852494839 -0.11593262528787932" name="0/2/3/4/">
            <joint name="0/2/3/4/joint/" class="0/2/3/" type="hinge" axis="0 -0.84466635269055179 0.53529314644635639" limited="true" range="-45.543354379969188 45.543354379969188"/>
            <geom name="0/2/3/4/geom" class="0/2/3/4/" type="capsule" contype="1" conaffinity="1" condim="3" size="0.057931947897884209" rgba="0.68694014701766459 0.26020911170940064 0.13455617514585838 1" friction="0.59999999999999998 0.10000000000000001 0.10000000000000001" fromto="0 0 0 -0.33194685541331637 -0.039386961651521224 -0.54521226814025059"/>
            <site name="0/2/3/4/end4" class="0/2/3/4/" size="0.0050000000000000001" pos="-0.33194685541331637 -0.039386961651521224 -0.54521226814025059"/>
          </body>
          <site name="0/2/3/attach5" class="0/2/3/" size="9.9999999999999995e-07 9.9999999999999995e-07 9.9999999999999995e-07" pos="0.43544887201707955 -0.18193572990242052 -0.28708566590282553"/>
          <body pos="0.43544887201707955 -0.18193572990242052 -0.28708566590282553" name="0/2/3/5/">
            <joint name="0/2/3/5/joint/" class="0/2/3/" type="hinge" axis="0 -0.84466635269055179 0.53529314644635639" limited="true" range="-37.080728984621373 37.080728984621373"/>
            <geom name="0/2/3/5/geom" class="0/2/3/5/" type="capsule" contype="1" conaffinity="1" condim="3" size="0.046467225713169663" rgba="0.57319235924630829 0.92994118738520914 0.56541017063694321 1" friction="0.59999999999999998 0.10000000000000001 0.10000000000000001" fromto="0 0 0 -0.15631089713038615 -0.037210325737668137 -0.61841571887166502"/>
            <site name="0/2/3/5/end5" class="0/2/3/5/" size="0.0050000000000000001" pos="-0.15631089713038615 -0.037210325737668137 -0.61841571887166502"/>
            <site name="0/2/3/5/attach6" class="0/2/3/5/" size="9.9999999999999995e-07 9.9999999999999995e-07 9.9999999999999995e-07" pos="-0.057314869766369049 -0.0136439941985595 -0.2267558886763931"/>
            <body pos="-0.057314869766369049 -0.0136439941985595 -0.2267558886763931" name="0/2/3/5/6/">
              <joint name="0/2/3/5/6/joint/" class="0/2/3/5/" type="hinge" axis="-2.7755575615628914e-16 -0.99819466170182947 0.060061779443925933" limited="true" range="-42.83623931044626 42.83623931044626"/>
              <geom name="0/2/3/5/6/geom" class="0/2/3/5/6/" type="capsule" contype="1" conaffinity="1" condim="3" size="0.059101906980855164" rgba="0.17156876323941761 0.17130463310391464 0.15992768351884701 1" friction="0.59999999999999998 0.10000000000000001 0.10000000000000001" fromto="0 0 0 0.59109184189699504 -0.62545623772219594 0.52264521475410697"/>
              <site name="0/2/3/5/6/end6" class="0/2/3/5/6/" size="0.0050000000000000001" pos="0.59109184189699504 -0.62545623772219594 0.52264521475410697"/>
              <site name="0/2/3/5/6/attach7" class="0/2/3/5/6/" size="9.9999999999999995e-07 9.9999999999999995e-07 9.9999999999999995e-07" pos="0.049946186722070039 -0.052849915734753158 0.044162571084941454"/>
              <body pos="0.049946186722070039 -0.052849915734753158 0.044162571084941454" name="0/2/3/5/6/7/">
                <joint name="0/2/3/5/6/7/joint/" class="0/2/3/5/6/" type="hinge" axis="0.80953507130746893 0.45049328065344613 -0.37644225640768125" limited="true" range="-41.012542858522686 41.012542858522686"/>
                <geom name="0/2/3/5/6/7/geom" class="0/2/3/5/6/7/" type="capsule" contype="1" conaffinity="1" condim="3" size="0.069547666740198494" rgba="0.39895721107404059 0.35515882961006395 0.31888605909377432 1" friction="0.59999999999999998 0.10000000000000001 0.10000000000000001" fromto="0 0 0 0.58100926409225639 0.27351853802203618 0.68393530309711981"/>
                <site name="0/2/3/5/6/7/end7" class="0/2/3/5/6/7/" size="0.0050000000000000001" pos="0.58100926409225639 0.27351853802203618 0.68393530309711981"/>
              </body>
              <site name="0/2/3/5/6/attach8" class="0/2/3/5/6/" size="9.9999999999999995e-07 9.9999999999999995e-07 9.9999999999999995e-07" pos="0.34059649583409057 -0.36039780583349118 0.301156463500515"/>
              <body pos="0.34059649583409057 -0.36039780583349118 0.301156463500515" name="0/2/3/5/6/8/">
                <joint name="0/2/3/5/6/8/joint/" class="0/2/3/5/6/" type="hinge" axis="0.80953507130746893 0.45049328065344613 -0.37644225640768125" limited="true" range="-64.314333852178649 64.314333852178649"/>
                <geom name="0/2/3/5/6/8/geom" class="0/2/3/5/6/8/" type="capsule" contype="1" conaffinity="1" condim="3" size="0.054168308488104278" rgba="0.11656296633498897 0.58379696704000095 0.040782347595282986 1" friction="0.59999999999999998 0.10000000000000001 0.10000000000000001" fromto="0 0 0 -0.0056994247599702064 -0.23444272026962043 -0.52185085287105082"/>
                <site name="0/2/3/5/6/8/end8" class="0/2/3/5/6/8/" size="0.0050000000000000001" pos="-0.0056994247599702064 -0.23444272026962043 -0.52185085287105082"/>
              </body>
            </body>
          </body>
        </body>
      </body>
      <site name="0/attach9" class="0/" size="9.9999999999999995e-07 9.9999999999999995e-07 9.9999999999999995e-07" pos="0.021244016527893685 -0.048179030267140981 0.086092517683913211"/>
      <body pos="0.021244016527893685 -0.048179030267140981 0.086092517683913211" name="0/9/">
        <geom name="0/9/geom" class="0/9/" type="capsule" contype="1" conaffinity="1" condim="3" size="0.069129993743449247" rgba="0.74964695963383166 0.7222889867936213 0.79723168216773377 1" friction="0.59999999999999998 0.10000000000000001 0.10000000000000001" fromto="0 0 0 -0.21385327939468302 -0.13955943017618977 -0.19969780501925616"/>
        <site name="0/9/end9" class="0/9/" size="0.0050000000000000001" pos="-0.21385327939468302 -0.13955943017618977 -0.19969780501925616"/>
        <site name="0/9/attach10" class="0/9/" size="9.9999999999999995e-07 9.9999999999999995e-07 9.9999999999999995e-07" pos="-0.021970933990309787 -0.014338106185724215 -0.020516623848401541"/>
        <body pos="-0.021970933990309787 -0.014338106185724215 -0.020516623848401541" name="0/9/10/">
          <joint name="0/9/10/joint/" class="0/9/" type="hinge" axis="0.75154206621179631 -0.37788827760774713 -0.54072633777240231" limited="true" range="-33.381975730295068 33.381975730295068"/>
          <geom name="0/9/10/geom" class="0/9/10/" type="capsule" contype="1" conaffinity="1" condim="3" size="0.037990552885488797" rgba="0.3147336527450989 0.76305185318629021 0.046095529322947804 1" friction="0.59999999999999998 0.10000000000000001 0.10000000000000001" fromto="0 0 0 -0.52230266416974724 0.41611286033562633 -0.31383646566220008"/>
          <site name="0/9/10/end10" class="0/9/10/" size="0.0050000000000000001" pos="-0.52230266416974724 0.41611286033562633 -0.31383646566220008"/>
        </body>
      </body>
      <camera name="0/iso" class="0/" mode="trackcom" pos="-2.2999999999999998 -2.2999999999999998 1" xyaxes="0.45000000000000001 -0.45000000000000001 0 0.29999999999999999 0.14999999999999999 0.93999999999999995"/>
    </body>
  </worldbody>
  <actuator>
    <motor name="0/2/3/motor" class="0/2/3/" ctrllimited="true" ctrlrange="-1 1" gear="58" joint="0/2/3/joint/"/>
    <motor name="0/2/3/4/motor" class="0/2/3/4/" ctrllimited="true" ctrlrange="-1 1" gear="88" joint="0/2/3/4/joint/"/>
    <motor name="0/2/3/5/motor" class="0/2/3/5/" ctrllimited="true" ctrlrange="-1 1" gear="69" joint="0/2/3/5/joint/"/>
    <motor name="0/2/3/5/6/motor" class="0/2/3/5/6/" ctrllimited="true" ctrlrange="-1 1" gear="77" joint="0/2/3/5/6/joint/"/>
    <motor name="0/2/3/5/6/7/motor" class="0/2/3/5/6/7/" ctrllimited="true" ctrlrange="-1 1" gear="67" joint="0/2/3/5/6/7/joint/"/>
    <motor name="0/2/3/5/6/8/motor" class="0/2/3/5/6/8/" ctrllimited="true" ctrlrange="-1 1" gear="71" joint="0/2/3/5/6/8/joint/"/>
    <motor name="0/9/10/motor" class="0/9/10/" ctrllimited="true" ctrlrange="-1 1" gear="89" joint="0/9/10/joint/"/>
  </actuator>
  <sensor>
    <subtreelinvel name="velocity" body="0/"/>
  </sensor>
</mujoco>
