<mujoco model="morphology">
  <option timestep="0.01"/>
  <default>
    <default class="/"/>
    <default class="0/"/>
    <default class="0/1/"/>
    <default class="0/2/"/>
    <default class="0/2/3/"/>
    <default class="0/2/3/4/"/>
    <default class="0/2/3/4/5/"/>
    <default class="0/2/3/4/6/"/>
    <default class="0/2/3/7/"/>
    <default class="0/2/3/7/8/"/>
    <default class="0/2/3/7/8/9/"/>
    <default class="0/2/3/7/8/9/10/"/>
  </default>
  <asset>
    <texture name="texplane" type="2d" builtin="checker" rgb1="0.10000000000000001 0.20000000000000001 0.29999999999999999" rgb2="0.20000000000000001 0.29999999999999999 0.40000000000000002" width="300" height="300"/>
    <material name="MatPlane" class="/" texture="texplane" texrepeat="20 20" specular="1" shininess="1" reflectance="0.5"/>
  </asset>
  <worldbody>
    <light name="//unnamed_light_0" class="/" directional="true" pos="0 0 1.5" dir="0 0 -1.3" cutoff="100" exponent="1" diffuse="1 1 1" specular="0.10000000000000001 0.10000000000000001 0.10000000000000001"/>
    <geom name="ground" class="/" type="plane" size="15 15 0.5" material="MatPlane" rgba="1 1 1 1"/>
    <site name="body" class="/" size="9.9999999999999995e-07 9.9999999999999995e-07 9.9999999999999995e-07" pos="0 0 0.52694455385208128"/>
    <body pos="0 0 0.52694455385208128" name="0/">
      <freejoint name="0/"/>
      <geom name="0/geom" class="0/" type="capsule" contype="1" conaffinity="1" condim="3" size="0.057316353614960763" rgba="0.061540580960788294 0.85119428617438953 0.41198770707624977 1" friction="0.59999999999999998 0.10000000000000001 0.10000000000000001" fromto="0 0 0 0.72935303382419403 -0.14827335383772011 0.70364622586378989"/>
      <site name="0/end0" class="0/" size="0.0050000000000000001" pos="0.72935303382419403 -0.14827335383772011 0.70364622586378989"/>
      <site name="0/attach1" class="0/" size="9.9999999999999995e-07 9.9999999999999995e-07 9.9999999999999995e-07" pos="0.70784790050881652 -0.14390148165302591 0.6828990633892309"/>
      <body pos="0.70784790050881652 -0.14390148165302591 0.6828990633892309" name="0/1/">
        <joint name="0/1/joint/" class="0/" type="hinge" axis="0 1 0" limited="true" range="-58.447082983860774 58.447082983860774"/>
        <geom name="0/1/geom" class="0/1/" type="capsule" contype="1" conaffinity="1" condim="3" size="0.047112157862767901" rgba="0.52931158770059883 0.64124769159921435 0.33956867361391796 1" friction="0.59999999999999998 0.10000000000000001 0.10000000000000001" fromto="0 0 0 0.60254255935391932 -0.39553305100206509 0.095142293846997905"/>
        <site name="0/1/end1" class="0/1/" size="0.0050000000000000001" pos="0.60254255935391932 -0.39553305100206509 0.095142293846997905"/>
      </body>
      <site name="0/attach2" class="0/" size="9.9999999999999995e-07 9.9999999999999995e-07 9.9999999999999995e-07" pos="0.29623994575756185 -0.060223908397103766 0.285798660066515"/>
      <body pos="0.29623994575756185 -0.060223908397103766 0.285798660066515" name="0/2/">
        <joint name="0/2/joint/" class="0/" type="hinge" axis="0 1 0" limited="true" range="-33.429426819929134 33.429426819929134"/>
        <geom name="0/2/geom" class="0/2/" type="capsule" contype="1" conaffinity="1" condim="3" size="0.038022859199951728" rgba="0.80359791660232149 0.15236315178239268 0.46319287874761828 1" friction="0.59999999999999998 0.10000000000000001 0.10000000000000001" fromto="0 0 0 0.71723802731761865 -0.55107506808122331 -0.014713430143122208"/>
        <site name="0/2/end2" class="0/2/" size="0.0050000000000000001" pos="0.71723802731761865 -0.55107506808122331 -0.014713430143122208"/>
        <site name="0/2/attach3" class="0/2/" size="9.9999999999999995e-07 9.9999999999999995e-07 9.9999999999999995e-07" pos="0.28364150749566946 -0.21793011120507447 -0.00581862554309227"/>
        <body pos="0.28364150749566946 -0.21793011120507447 -0.00581862554309227" name="0/2/3/">
          <joint name="0/2/3/joint/" class="0/2/" type="hinge" axis="1.7347234759768071e-18 -0.026689991008635658 0.99964375873606037" limited="true" range="-34.713965579742705 34.713965579742705"/>
          <geom name="0/2/3/geom" class="0/2/3/" type="capsule" contype="1" conaffinity="1" condim="3" size="0.06928184498599077" rgba="0.5394990425261994 0.15917825987288614 0.53896039759960102 1" friction="0.59999999999999998 0.10000000000000001 0.10000000000000001" fromto="0 0 0 -0.32343082319039324 0.38305585440882406 -0.65581381603770073"/>
          <site name="0/2/3/end3" class="0/2/3/" size="0.0050000000000000001" pos="-0.32343082319039324 0.38305585440882406 -0.65581381603770073"/>
          <site name="0/2/3/attach4" class="0/2/3/" size="9.9999999999999995e-07 9.9999999999999995e-07 9.9999999999999995e-07" pos="-0.20018203426481077 0.23708593824239202 -0.40590486243209345"/>
          <body pos="-0.20018203426481077 0.23708593824239202 -0.40590486243209345" name="0/2/3/4/">
            <joint name="0/2/3/4/joint/" class="0/2/3/" type="hinge" axis="-0.92004810029588802 -0.19761097506482878 0.33832143839233003" limited="true" range="-64.369253031758106 64.369253031758106"/>
            <geom name="0/2/3/4/geom" class="0/2/3/4/" type="capsule" contype="1" conaffinity="1" condim="3" size="0.03794821088386529" rgba="0.97750158126065612 0.38696931938462464 0.71049365290694011 1" friction="0.59999999999999998 0.10000000000000001 0.10000000000000001" fromto="0 0 0 -0.58575743504134259 -0.48616619797257998 0.28058337701190017"/>
            <site name="0/2/3/4/end4" class="0/2/3/4/" size="0.0050000000000000001" pos="-0.58575743504134259 -0.48616619797257998 0.28058337701190017"/>
            <site name="0/2/3/4/attach5" class="0/2/3/4/" size="9.9999999999999995e-07 9.9999999999999995e-07 9.9999999999999995e-07" pos="-0.46701374728854267 -0.3876114656644063 0.22370402232445064"/>
            <body pos="-0.46701374728854267 -0.3876114656644063 0.22370402232445064" name="0/2/3/4/5/">
              <geom name="0/2/3/4/5/geom" class="0/2/3/4/5/" type="capsule" contype="1" conaffinity="1" condim="3" size="0.042288033470780341" rgba="0.56633650326536678 0.42339806542772662 0.85688935969369739 1" friction="0.59999999999999998 0.10000000000000001 0.10000000000000001" fromto="0 0 0 0.44562590259001333 -0.59165685549427627 -0.52472374829826074"/>
              <site name="0/2/3/4/5/end5" class="0/2/3/4/5/" size="0.0050000000000000001" pos="0.44562590259001333 -0.59165685549427627 -0.52472374829826074"/>
            </body>
            <site name="0/2/3/4/attach6" class="0/2/3/4/" size="9.9999999999999995e-07 9.9999999999999995e-07 9.9999999999999995e-07" pos="-0.58208265443676233 -0.48311620832151214 0.27882312218604688"/>
            <body pos="-0.58208265443676233 -0.48311620832151214 0.27882312218604688" name="0/2/3/4/6/">
              <joint name="0/2/3/4/6/joint/" class="0/2/3/4/" type="hinge" axis="0.69188807845359535 -0.62533283811888485 0.36090127246100423" limited="true" range="-40.485117279070224 40.485117279070224"/>
              <geom name="0/2/3/4/6/geom" class="0/2/3/4/6/" type="capsule" contype="1" conaffinity="1" condim="3" size="0.064062844971919095" rgba="0.76108665374967943 0.14817851380583802 0.13139339604951217 1" friction="0.59999999999999998 0.10000000000000001 0.10000000000000001" fromto="0 0 0 0.0039792372487609251 -0.12335700491204693 0.68909645534081165"/>
              <site name="0/2/3/4/6/end6" class="0/2/3/4/6/" size="0.0050000000000000001" pos="0.0039792372487609251 -0.12335700491204693 0.68909645534081165"/>
            </body>
          </body>
          <site name="0/2/3/attach7" class="0/2/3/" size="9.9999999999999995e-07 9.9999999999999995e-07 9.9999999999999995e-07" pos="-0.10773886986394854 0.12760071672105786 -0.21845981989005436"/>
          <body pos="-0.10773886986394854 0.12760071672105786 -0.21845981989005436" name="0/2/3/7/">
            <geom name="0/2/3/7/geom" class="0/2/3/7/" type="capsule" contype="1" conaffinity="1" condim="3" size="0.052818851286384777" rgba="0.31071178031899949 0.75905568967895731 0.062541063548223752 1" friction="0.59999999999999998 0.10000000000000001 0.10000000000000001" fromto="0 0 0 -0.47760696678174086 0.74077723458735045 0.32868148471467817"/>
            <site name="0/2/3/7/end7" class="0/2/3/7/" size="0.0050000000000000001" pos="-0.47760696678174086 0.74077723458735045 0.32868148471467817"/>
            <site name="0/2/3/7/attach8" class="0/2/3/7/" size="9.9999999999999995e-07 9.9999999999999995e-07 9.9999999999999995e-07" pos="-0.34137449227430194 0.52947814821382555 0.23492847208761986"/>
            <body pos="-0.34137449227430194 0.52947814821382555 0.23492847208761986" name="0/2/3/7/8/">
              <geom name="0/2/3/7/8/geom" class="0/2/3/7/8/" type="capsule" contype="1" conaffinity="1" condim="3" size="0.05319246228258917" rgba="0.69534844919501693 0.32384933693501128 0.75160279529307583 1" friction="0.59999999999999998 0.10000000000000001 0.10000000000000001" fromto="0 0 0 0.48108293665443314 0.29560156373216895 0.38239524974801209"/>
              <site name="0/2/3/7/8/end8" class="0/2/3/7/8/" size="0.0050000000000000001" pos="0.48108293665443314 0.29560156373216895 0.38239524974801209"/>
              <site name="0/2/3/7/8/attach9" class="0/2/3/7/8/" size="9.9999999999999995e-07 9.9999999999999995e-07 9.9999999999999995e-07" pos="0.29131858323374821 0.1790007963013511 0.23155849834666892"/>
              <body pos="0.29131858323374821 0.1790007963013511 0.23155849834666892" name="0/2/3/7/8/9/">
                <joint name="0/2/3/7/8/9/joint/" class="0/2/3/7/8/" type="hinge" axis="-0.70875128700640444 0.43145527480172058 0.55813793905497666" limited="true" range="-34.372840411943145 34.372840411943145"/>
                <geom name="0/2/3/7/8/9/geom" class="0/2/3/7/8/9/" type="capsule" contype="1" conaffinity="1" condim="3" size="0.036184706083949685" rgba="0.27538572259033367 0.41440872349309965 0.13402581113748202 1" friction="0.59999999999999998 0.10000000000000001 0.10000000000000001" fromto="0 0 0 -0.23911067922956453 0.28480765424742049 0.26092007171341081"/>
                <site name="0/2/3/7/8/9/end9" class="0/2/3/7/8/9/" size="0.0050000000000000001" pos="-0.23911067922956453 0.28480765424742049 0.26092007171341081"/>
                <site name="0/2/3/7/8/9/attach10" class="0/2/3/7/8/9/" size="9.9999999999999995e-07 9.9999999999999995e-07 9.9999999999999995e-07" pos="-0.21758618540059904 0.25916956641276906 0.23743231913145027"/>
                <body pos="-0.21758618540059904 0.25916956641276906 0.23743231913145027" name="0/2/3/7/8/9/10/">
                  <joint name="0/2/3/7/8/9/10/joint/" class="0/2/3/7/8/9/" type="hinge" axis="0 -0.67550849526395296 0.73735220405599289" limited="true" range="-44.305450943117719 44.305450943117719"/>
                  <geom name="0/2/3/7/8/9/10/geom" class="0/2/3/7/8/9/10/" type="capsule" contype="1" conaffinity="1" condim="3" size="0.038656955932453177" rgba="0.66632769290662008 0.084402527525654247 0.74061056602100805 1" friction="0.59999999999999998 0.10000000000000001 0.10000000000000001" fromto="0 0 0 0.1943269254946508 0.12023254018850404 0.67651875508482062"/>
                  <site name="0/2/3/7/8/9/10/end10" class="0/2/3/7/8/9/10/" size="0.0050000000000000001" pos="0.1943269254946508 0.12023254018850404 0.67651875508482062"/>
                </body>
              </body>
            </body>
          </body>
        </body>
      </body>
      <camera name="0/iso" class="0/" mode="trackcom" pos="-2.2999999999999998 -2.2999999999999998 1" xyaxes="0.45000000000000001 -0.45000000000000001 0 0.29999999999999999 0.14999999999999999 0.93999999999999995"/>
    </body>
  </worldbody>
  <actuator>
    <motor name="0/1/motor" class="0/1/" ctrllimited="true" ctrlrange="-1 1" gear="71" joint="0/1/joint/"/>
    <motor name="0/2/motor" class="0/2/" ctrllimited="true" ctrlrange="-1 1" gear="86" joint="0/2/joint/"/>
    <motor name="0/2/3/motor" class="0/2/3/" ctrllimited="true" ctrlrange="-1 1" gear="69" joint="0/2/3/joint/"/>
    <motor name="0/2/3/4/motor" class="0/2/3/4/" ctrllimited="true" ctrlrange="-1 1" gear="72" joint="0/2/3/4/joint/"/>
    <motor name="0/2/3/4/6/motor" class="0/2/3/4/6/" ctrllimited="true" ctrlrange="-1 1" gear="63" joint="0/2/3/4/6/joint/"/>
    <motor name="0/2/3/7/8/9/motor" class="0/2/3/7/8/9/" ctrllimited="true" ctrlrange="-1 1" gear="72" joint="0/2/3/7/8/9/joint/"/>
    <motor name="0/2/3/7/8/9/10/motor" class="0/2/3/7/8/9/10/" ctrllimited="true" ctrlrange="-1 1" gear="81" joint="0/2/3/7/8/9/10/joint/"/>
  </actuator>
  <sensor>
    <subtreelinvel name="velocity" body="0/"/>
  </sensor>
</mujoco>
