<mujoco model="morphology">
  <option timestep="0.01"/>
  <default>
    <default class="/"/>
    <default class="0/"/>
    <default class="0/1/"/>
    <default class="0/2/"/>
    <default class="0/2/3/"/>
    <default class="0/2/3/4/"/>
    <default class="0/2/3/4/5/"/>
    <default class="0/2/3/4/6/"/>
    <default class="0/2/3/4/6/7/"/>
    <default class="0/2/3/4/6/7/8/"/>
    <default class="0/2/3/4/6/7/8/9/"/>
    <default class="0/2/3/4/6/7/8/10/"/>
  </default>
  <asset>
    <texture name="texplane" type="2d" builtin="checker" rgb1="0.10000000000000001 0.20000000000000001 0.29999999999999999" rgb2="0.20000000000000001 0.29999999999999999 0.40000000000000002" width="300" height="300"/>
    <material name="MatPlane" class="/" texture="texplane" texrepeat="20 20" specular="1" shininess="1" reflectance="0.5"/>
  </asset>
  <worldbody>
    <light name="//unnamed_light_0" class="/" directional="true" pos="0 0 1.5" dir="0 0 -1.3" cutoff="100" exponent="1" diffuse="1 1 1" specular="0.10000000000000001 0.10000000000000001 0.10000000000000001"/>
    <geom name="ground" class="/" type="plane" size="15 15 0.5" material="MatPlane" rgba="1 1 1 1"/>
    <site name="body" class="/" size="9.9999999999999995e-07 9.9999999999999995e-07 9.9999999999999995e-07" pos="0 0 1.5231292009353639"/>
    <body pos="0 0 1.5231292009353639" name="0/">
      <joint name="0/rootx/" class="/" type="slide" axis="1 0 0" limited="false" stiffness="0" armature="0" damping="0"/>
      <joint name="0/rootz/" class="/" type="slide" axis="0 0 1" limited="false" stiffness="0" armature="0" damping="0"/>
      <joint name="0/rooty/" class="/" type="hinge" axis="0 1 0" limited="false" stiffness="0" armature="0" damping="0"/>
      <geom name="0/geom" class="0/" type="capsule" contype="1" conaffinity="1" condim="3" size="0.053388073887987955" rgba="0.13125980987532559 0.22051038426088421 0.6971791217304425 1" friction="0.59999999999999998 0.10000000000000001 0.10000000000000001" fromto="0 0 0 0.42234342362970256 0 -0.15221517515415606"/>
      <site name="0/end0" class="0/" size="0.0050000000000000001" pos="0.42234342362970256 0 -0.15221517515415606"/>
      <site name="0/attach1" class="0/" size="9.9999999999999995e-07 9.9999999999999995e-07 9.9999999999999995e-07" pos="0.30100622481092565 0 -0.10848450021624548"/>
      <body pos="0.30100622481092565 0 -0.10848450021624548" name="0/1/">
        <geom name="0/1/geom" class="0/1/" type="capsule" contype="1" conaffinity="1" condim="3" size="0.055199681095028708" rgba="0.63374417073695577 0.74666784421853982 0.86836213373605642 1" friction="0.59999999999999998 0.10000000000000001 0.10000000000000001" fromto="0 0 0 0.38752615292426285 0 0.50229871100100221"/>
        <site name="0/1/end1" class="0/1/" size="0.0050000000000000001" pos="0.38752615292426285 0 0.50229871100100221"/>
      </body>
      <site name="0/attach2" class="0/" size="9.9999999999999995e-07 9.9999999999999995e-07 9.9999999999999995e-07" pos="0.33575856981233049 0 -0.12100945972892031"/>
      <body pos="0.33575856981233049 0 -0.12100945972892031" name="0/2/">
        <joint name="0/2/joint/" class="0/" type="hinge" axis="0 1 0" limited="true" stiffness="100" range="-47.518916070954646 47.518916070954646" armature="0.20000000000000001" damping="3.5"/>
        <geom name="0/2/geom" class="0/2/" type="capsule" contype="1" conaffinity="1" condim="3" size="0.043432651321561447" rgba="0.34082666574497877 0.94607201523221784 0.53830020003681545 1" friction="0.59999999999999998 0.10000000000000001 0.10000000000000001" fromto="0 0 0 0.10070962114899396 0 -0.68812007788345153"/>
        <site name="0/2/end2" class="0/2/" size="0.0050000000000000001" pos="0.10070962114899396 0 -0.68812007788345153"/>
        <site name="0/2/attach3" class="0/2/" size="9.9999999999999995e-07 9.9999999999999995e-07 9.9999999999999995e-07" pos="0.023756631819794295 0 -0.16232228015136999"/>
        <body pos="0.023756631819794295 0 -0.16232228015136999" name="0/2/3/">
          <geom name="0/2/3/geom" class="0/2/3/" type="capsule" contype="1" conaffinity="1" condim="3" size="0.06477456965069639" rgba="0.25035915472044679 0.33539462515682972 0.78061995759814862 1" friction="0.59999999999999998 0.10000000000000001 0.10000000000000001" fromto="0 0 0 -0.21998053658187455 0 -0.15023287498945392"/>
          <site name="0/2/3/end3" class="0/2/3/" size="0.0050000000000000001" pos="-0.21998053658187455 0 -0.15023287498945392"/>
          <site name="0/2/3/attach4" class="0/2/3/" size="9.9999999999999995e-07 9.9999999999999995e-07 9.9999999999999995e-07" pos="-0.21186247227879429 0 -0.14468874750185193"/>
          <body pos="-0.21186247227879429 0 -0.14468874750185193" name="0/2/3/4/">
            <joint name="0/2/3/4/joint/" class="0/2/3/" type="hinge" axis="0 1 0" limited="true" stiffness="100" range="-38.923181565654296 38.923181565654296" armature="0.20000000000000001" damping="3.5"/>
            <geom name="0/2/3/4/geom" class="0/2/3/4/" type="capsule" contype="1" conaffinity="1" condim="3" size="0.045606877187079453" rgba="0.14578665375430266 0.90063945146399593 0.46606819543300171 1" friction="0.59999999999999998 0.10000000000000001 0.10000000000000001" fromto="0 0 0 -0.60658010211595781 0 0.21892596490328931"/>
            <site name="0/2/3/4/end4" class="0/2/3/4/" size="0.0050000000000000001" pos="-0.60658010211595781 0 0.21892596490328931"/>
            <site name="0/2/3/4/attach5" class="0/2/3/4/" size="9.9999999999999995e-07 9.9999999999999995e-07 9.9999999999999995e-07" pos="-0.1089421980260657 0 0.039319251881728023"/>
            <body pos="-0.1089421980260657 0 0.039319251881728023" name="0/2/3/4/5/">
              <joint name="0/2/3/4/5/joint/" class="0/2/3/4/" type="hinge" axis="0 1 0" limited="true" stiffness="100" range="-46.677128057072196 46.677128057072196" armature="0.20000000000000001" damping="3.5"/>
              <geom name="0/2/3/4/5/geom" class="0/2/3/4/5/" type="capsule" contype="1" conaffinity="1" condim="3" size="0.053303454859959368" rgba="0.90895095884938049 0.25739024697538426 0.96397715108885584 1" friction="0.59999999999999998 0.10000000000000001 0.10000000000000001" fromto="0 0 0 -0.15288578681815546 0 -0.15261597360211199"/>
              <site name="0/2/3/4/5/end5" class="0/2/3/4/5/" size="0.0050000000000000001" pos="-0.15288578681815546 0 -0.15261597360211199"/>
            </body>
            <site name="0/2/3/4/attach6" class="0/2/3/4/" size="9.9999999999999995e-07 9.9999999999999995e-07 9.9999999999999995e-07" pos="-0.27993268034251823 0 0.10103287585294762"/>
            <body pos="-0.27993268034251823 0 0.10103287585294762" name="0/2/3/4/6/">
              <joint name="0/2/3/4/6/joint/" class="0/2/3/4/" type="hinge" axis="0 1 0" limited="true" stiffness="100" range="-48.669153142684053 48.669153142684053" armature="0.20000000000000001" damping="3.5"/>
              <geom name="0/2/3/4/6/geom" class="0/2/3/4/6/" type="capsule" contype="1" conaffinity="1" condim="3" size="0.046193139612576255" rgba="0.46341574605099489 0.7396799369733944 0.14023322293155593 1" friction="0.59999999999999998 0.10000000000000001 0.10000000000000001" fromto="0 0 0 -0.60204567575119317 0 -0.65134974116664712"/>
              <site name="0/2/3/4/6/end6" class="0/2/3/4/6/" size="0.0050000000000000001" pos="-0.60204567575119317 0 -0.65134974116664712"/>
              <site name="0/2/3/4/6/attach7" class="0/2/3/4/6/" size="9.9999999999999995e-07 9.9999999999999995e-07 9.9999999999999995e-07" pos="-0.52339228115473291 0 -0.566255087595122"/>
              <body pos="-0.52339228115473291 0 -0.566255087595122" name="0/2/3/4/6/7/">
                <joint name="0/2/3/4/6/7/joint/" class="0/2/3/4/6/" type="hinge" axis="0 1 0" limited="true" stiffness="100" range="-34.317519863893857 34.317519863893857" armature="0.20000000000000001" damping="3.5"/>
                <geom name="0/2/3/4/6/7/geom" class="0/2/3/4/6/7/" type="capsule" contype="1" conaffinity="1" condim="3" size="0.063488800216378732" rgba="0.44184468130084997 0.55019219464774405 0.60729044299680368 1" friction="0.59999999999999998 0.10000000000000001 0.10000000000000001" fromto="0 0 0 -0.5940836120464893 0 0.025555306288421953"/>
                <site name="0/2/3/4/6/7/end7" class="0/2/3/4/6/7/" size="0.0050000000000000001" pos="-0.5940836120464893 0 0.025555306288421953"/>
                <site name="0/2/3/4/6/7/attach8" class="0/2/3/4/6/7/" size="9.9999999999999995e-07 9.9999999999999995e-07 9.9999999999999995e-07" pos="-0.23675593513649662 0 0.010184375255147532"/>
                <body pos="-0.23675593513649662 0 0.010184375255147532" name="0/2/3/4/6/7/8/">
                  <joint name="0/2/3/4/6/7/8/joint/" class="0/2/3/4/6/7/" type="hinge" axis="0 1 0" limited="true" stiffness="100" range="-30.694344608274928 30.694344608274928" armature="0.20000000000000001" damping="3.5"/>
                  <geom name="0/2/3/4/6/7/8/geom" class="0/2/3/4/6/7/8/" type="capsule" contype="1" conaffinity="1" condim="3" size="0.044912639263291122" rgba="0.032583665849522325 0.73314953422935403 0.9380446074677854 1" friction="0.59999999999999998 0.10000000000000001 0.10000000000000001" fromto="0 0 0 -0.055307232469451684 0 0.079130621227915698"/>
                  <site name="0/2/3/4/6/7/8/end8" class="0/2/3/4/6/7/8/" size="0.0050000000000000001" pos="-0.055307232469451684 0 0.079130621227915698"/>
                  <site name="0/2/3/4/6/7/8/attach9" class="0/2/3/4/6/7/8/" size="9.9999999999999995e-07 9.9999999999999995e-07 9.9999999999999995e-07" pos="-0.012742353586666009 0 0.018231075940665982"/>
                  <body pos="-0.012742353586666009 0 0.018231075940665982" name="0/2/3/4/6/7/8/9/">
                    <joint name="0/2/3/4/6/7/8/9/joint/" class="0/2/3/4/6/7/8/" type="hinge" axis="0 1 0" limited="true" stiffness="100" range="-56.358372914241748 56.358372914241748" armature="0.20000000000000001" damping="3.5"/>
                    <geom name="0/2/3/4/6/7/8/9/geom" class="0/2/3/4/6/7/8/9/" type="capsule" contype="1" conaffinity="1" condim="3" size="0.069774579361156427" rgba="0.61783583710011647 0.75669629832796814 0.68874005732030097 1" friction="0.59999999999999998 0.10000000000000001 0.10000000000000001" fromto="0 0 0 -0.22319996208375426 0 -0.55830196945638533"/>
                    <site name="0/2/3/4/6/7/8/9/end9" class="0/2/3/4/6/7/8/9/" size="0.0050000000000000001" pos="-0.22319996208375426 0 -0.55830196945638533"/>
                  </body>
                  <site name="0/2/3/4/6/7/8/attach10" class="0/2/3/4/6/7/8/" size="9.9999999999999995e-07 9.9999999999999995e-07 9.9999999999999995e-07" pos="-0.044428559649266022 0 0.063565999749666785"/>
                  <body pos="-0.044428559649266022 0 0.063565999749666785" name="0/2/3/4/6/7/8/10/">
                    <joint name="0/2/3/4/6/7/8/10/joint/" class="0/2/3/4/6/7/8/" type="hinge" axis="0 1 0" limited="true" stiffness="100" range="-68.751664305920428 68.751664305920428" armature="0.20000000000000001" damping="3.5"/>
                    <geom name="0/2/3/4/6/7/8/10/geom" class="0/2/3/4/6/7/8/10/" type="capsule" contype="1" conaffinity="1" condim="3" size="0.042955106263371366" rgba="0.43050763492561217 0.23638075531047253 0.36848374136443096 1" friction="0.59999999999999998 0.10000000000000001 0.10000000000000001" fromto="0 0 0 0.36837198830101103 0 0.37603759556306171"/>
                    <site name="0/2/3/4/6/7/8/10/end10" class="0/2/3/4/6/7/8/10/" size="0.0050000000000000001" pos="0.36837198830101103 0 0.37603759556306171"/>
                  </body>
                </body>
              </body>
            </body>
          </body>
        </body>
      </body>
      <camera name="0/side" class="0/" mode="trackcom" pos="0.40000000000000002 -4 0.20000000000000001" quat="0.70699999999999996 0.70699999999999996 0 0"/>
    </body>
  </worldbody>
  <actuator>
    <motor name="0/2/motor" class="0/2/" ctrllimited="true" ctrlrange="-1 1" gear="71" joint="0/2/joint/"/>
    <motor name="0/2/3/4/motor" class="0/2/3/4/" ctrllimited="true" ctrlrange="-1 1" gear="73" joint="0/2/3/4/joint/"/>
    <motor name="0/2/3/4/5/motor" class="0/2/3/4/5/" ctrllimited="true" ctrlrange="-1 1" gear="85" joint="0/2/3/4/5/joint/"/>
    <motor name="0/2/3/4/6/motor" class="0/2/3/4/6/" ctrllimited="true" ctrlrange="-1 1" gear="86" joint="0/2/3/4/6/joint/"/>
    <motor name="0/2/3/4/6/7/motor" class="0/2/3/4/6/7/" ctrllimited="true" ctrlrange="-1 1" gear="70" joint="0/2/3/4/6/7/joint/"/>
    <motor name="0/2/3/4/6/7/8/motor" class="0/2/3/4/6/7/8/" ctrllimited="true" ctrlrange="-1 1" gear="60" joint="0/2/3/4/6/7/8/joint/"/>
    <motor name="0/2/3/4/6/7/8/9/motor" class="0/2/3/4/6/7/8/9/" ctrllimited="true" ctrlrange="-1 1" gear="78" joint="0/2/3/4/6/7/8/9/joint/"/>
    <motor name="0/2/3/4/6/7/8/10/motor" class="0/2/3/4/6/7/8/10/" ctrllimited="true" ctrlrange="-1 1" gear="85" joint="0/2/3/4/6/7/8/10/joint/"/>
  </actuator>
  <sensor>
    <subtreelinvel name="velocity" body="0/"/>
  </sensor>
</mujoco>
