<mujoco model="morphology">
  <option timestep="0.01"/>
  <default>
    <default class="/"/>
    <default class="0/"/>
    <default class="0/1/"/>
    <default class="0/1/2/"/>
    <default class="0/1/2/3/"/>
    <default class="0/1/2/3/4/"/>
    <default class="0/1/2/3/4/5/"/>
    <default class="0/1/2/3/6/"/>
    <default class="0/1/2/3/6/7/"/>
    <default class="0/1/2/3/6/7/8/"/>
    <default class="0/1/2/3/6/7/8/9/"/>
    <default class="0/1/2/3/6/10/"/>
  </default>
  <asset>
    <texture name="texplane" type="2d" builtin="checker" rgb1="0.10000000000000001 0.20000000000000001 0.29999999999999999" rgb2="0.20000000000000001 0.29999999999999999 0.40000000000000002" width="300" height="300"/>
    <material name="MatPlane" class="/" texture="texplane" texrepeat="20 20" specular="1" shininess="1" reflectance="0.5"/>
  </asset>
  <worldbody>
    <light name="//unnamed_light_0" class="/" directional="true" pos="0 0 1.5" dir="0 0 -1.3" cutoff="100" exponent="1" diffuse="1 1 1" specular="0.10000000000000001 0.10000000000000001 0.10000000000000001"/>
    <geom name="ground" class="/" type="plane" size="15 15 0.5" material="MatPlane" rgba="1 1 1 1"/>
    <site name="body" class="/" size="9.9999999999999995e-07 9.9999999999999995e-07 9.9999999999999995e-07" pos="0 0 0.8513797879219055"/>
    <body pos="0 0 0.8513797879219055" name="0/">
      <joint name="0/rootx/" class="/" type="slide" axis="1 0 0" limited="false" stiffness="0" armature="0" damping="0"/>
      <joint name="0/rootz/" class="/" type="slide" axis="0 0 1" limited="false" stiffness="0" armature="0" damping="0"/>
      <joint name="0/rooty/" class="/" type="hinge" axis="0 1 0" limited="false" stiffness="0" armature="0" damping="0"/>
      <geom name="0/geom" class="0/" type="capsule" contype="1" conaffinity="1" condim="3" size="0.04630320543343304" rgba="0.78373327146094085 0.025252371327965095 0.023068315204024858 1" friction="0.59999999999999998 0.10000000000000001 0.10000000000000001" fromto="0 0 0 0.27112770767920646 0 -0.13892931198730607"/>
      <site name="0/end0" class="0/" size="0.0050000000000000001" pos="0.27112770767920646 0 -0.13892931198730607"/>
      <site name="0/attach1" class="0/" size="9.9999999999999995e-07 9.9999999999999995e-07 9.9999999999999995e-07" pos="0.15239285165506447 0 -0.078088050142303592"/>
      <body pos="0.15239285165506447 0 -0.078088050142303592" name="0/1/">
        <geom name="0/1/geom" class="0/1/" type="capsule" contype="1" conaffinity="1" condim="3" size="0.064270475748419015" rgba="0.73627158887991273 0.67810606028458031 0.18478044341206301 1" friction="0.59999999999999998 0.10000000000000001 0.10000000000000001" fromto="0 0 0 0.0093883740944327165 0 -0.13607134001184129"/>
        <site name="0/1/end1" class="0/1/" size="0.0050000000000000001" pos="0.0093883740944327165 0 -0.13607134001184129"/>
        <site name="0/1/attach2" class="0/1/" size="9.9999999999999995e-07 9.9999999999999995e-07 9.9999999999999995e-07" pos="0.0048792233860195612 0 -0.070717512710374381"/>
        <body pos="0.0048792233860195612 0 -0.070717512710374381" name="0/1/2/">
          <joint name="0/1/2/joint/" class="0/1/" type="hinge" axis="0 1 0" limited="true" stiffness="100" range="-50.783595629985555 50.783595629985555" armature="0.20000000000000001" damping="3.5"/>
          <geom name="0/1/2/geom" class="0/1/2/" type="capsule" contype="1" conaffinity="1" condim="3" size="0.042419002555140826" rgba="0.8854415656887521 0.86395802840929636 0.47303907389774136 1" friction="0.59999999999999998 0.10000000000000001 0.10000000000000001" fromto="0 0 0 -0.61927926431191183 0 -0.25733733573121914"/>
          <site name="0/1/2/end2" class="0/1/2/" size="0.0050000000000000001" pos="-0.61927926431191183 0 -0.25733733573121914"/>
          <site name="0/1/2/attach3" class="0/1/2/" size="9.9999999999999995e-07 9.9999999999999995e-07 9.9999999999999995e-07" pos="-0.37889422207613965 0 -0.15744694720460894"/>
          <body pos="-0.37889422207613965 0 -0.15744694720460894" name="0/1/2/3/">
            <joint name="0/1/2/3/joint/" class="0/1/2/" type="hinge" axis="0 1 0" limited="true" stiffness="100" range="-66.782874266015483 66.782874266015483" armature="0.20000000000000001" damping="3.5"/>
            <geom name="0/1/2/3/geom" class="0/1/2/3/" type="capsule" contype="1" conaffinity="1" condim="3" size="0.067293011067331737" rgba="0.43766304273775758 0.98975292379769031 0.55040187709265564 1" friction="0.59999999999999998 0.10000000000000001 0.10000000000000001" fromto="0 0 0 -0.2879570073726056 0 0.54938436535249591"/>
            <site name="0/1/2/3/end3" class="0/1/2/3/" size="0.0050000000000000001" pos="-0.2879570073726056 0 0.54938436535249591"/>
            <site name="0/1/2/3/attach4" class="0/1/2/3/" size="9.9999999999999995e-07 9.9999999999999995e-07 9.9999999999999995e-07" pos="-0.0025308791290663255 0 0.0048285868671597296"/>
            <body pos="-0.0025308791290663255 0 0.0048285868671597296" name="0/1/2/3/4/">
              <joint name="0/1/2/3/4/joint/" class="0/1/2/3/" type="hinge" axis="0 1 0" limited="true" stiffness="100" range="-63.504301135200208 63.504301135200208" armature="0.20000000000000001" damping="3.5"/>
              <geom name="0/1/2/3/4/geom" class="0/1/2/3/4/" type="capsule" contype="1" conaffinity="1" condim="3" size="0.040007638757613109" rgba="0.18426413952167309 0.48955908429601824 0.61591408590016583 1" friction="0.59999999999999998 0.10000000000000001 0.10000000000000001" fromto="0 0 0 0.24718418413468168 0 -0.44995584871160843"/>
              <site name="0/1/2/3/4/end4" class="0/1/2/3/4/" size="0.0050000000000000001" pos="0.24718418413468168 0 -0.44995584871160843"/>
              <site name="0/1/2/3/4/attach5" class="0/1/2/3/4/" size="9.9999999999999995e-07 9.9999999999999995e-07 9.9999999999999995e-07" pos="0.16740452061325573 0 -0.30473083629677444"/>
              <body pos="0.16740452061325573 0 -0.30473083629677444" name="0/1/2/3/4/5/">
                <joint name="0/1/2/3/4/5/joint/" class="0/1/2/3/4/" type="hinge" axis="0 1 0" limited="true" stiffness="100" range="-53.402850718179238 53.402850718179238" armature="0.20000000000000001" damping="3.5"/>
                <geom name="0/1/2/3/4/5/geom" class="0/1/2/3/4/5/" type="capsule" contype="1" conaffinity="1" condim="3" size="0.065590965055349032" rgba="0.50846886644426037 0.71053821958858243 0.14402229392601074 1" friction="0.59999999999999998 0.10000000000000001 0.10000000000000001" fromto="0 0 0 0.18200249031622362 0 0.1867794502214335"/>
                <site name="0/1/2/3/4/5/end5" class="0/1/2/3/4/5/" size="0.0050000000000000001" pos="0.18200249031622362 0 0.1867794502214335"/>
              </body>
            </body>
            <site name="0/1/2/3/attach6" class="0/1/2/3/" size="9.9999999999999995e-07 9.9999999999999995e-07 9.9999999999999995e-07" pos="-0.16294515206068702 0 0.31087807089303288"/>
            <body pos="-0.16294515206068702 0 0.31087807089303288" name="0/1/2/3/6/">
              <joint name="0/1/2/3/6/joint/" class="0/1/2/3/" type="hinge" axis="0 1 0" limited="true" stiffness="100" range="-32.666934022644355 32.666934022644355" armature="0.20000000000000001" damping="3.5"/>
              <geom name="0/1/2/3/6/geom" class="0/1/2/3/6/" type="capsule" contype="1" conaffinity="1" condim="3" size="0.057653482006376468" rgba="0.53583789705495299 0.96303621151213381 0.51695413075258845 1" friction="0.59999999999999998 0.10000000000000001 0.10000000000000001" fromto="0 0 0 0.30682028136349593 0 0.73603877724382638"/>
              <site name="0/1/2/3/6/end6" class="0/1/2/3/6/" size="0.0050000000000000001" pos="0.30682028136349593 0 0.73603877724382638"/>
              <site name="0/1/2/3/6/attach7" class="0/1/2/3/6/" size="9.9999999999999995e-07 9.9999999999999995e-07 9.9999999999999995e-07" pos="0.11106029743435655 0 0.26642530005073217"/>
              <body pos="0.11106029743435655 0 0.26642530005073217" name="0/1/2/3/6/7/">
                <joint name="0/1/2/3/6/7/joint/" class="0/1/2/3/6/" type="hinge" axis="0 1 0" limited="true" stiffness="100" range="-36.038262408905112 36.038262408905112" armature="0.20000000000000001" damping="3.5"/>
                <geom name="0/1/2/3/6/7/geom" class="0/1/2/3/6/7/" type="capsule" contype="1" conaffinity="1" condim="3" size="0.061186381184185207" rgba="0.95959076191474602 0.4174548194839085 0.8025894837390446 1" friction="0.59999999999999998 0.10000000000000001 0.10000000000000001" fromto="0 0 0 0.16069011226895435 0 -0.063629021483591286"/>
                <site name="0/1/2/3/6/7/end7" class="0/1/2/3/6/7/" size="0.0050000000000000001" pos="0.16069011226895435 0 -0.063629021483591286"/>
                <site name="0/1/2/3/6/7/attach8" class="0/1/2/3/6/7/" size="9.9999999999999995e-07 9.9999999999999995e-07 9.9999999999999995e-07" pos="0.078671635431538003 0 -0.031151880537889969"/>
                <body pos="0.078671635431538003 0 -0.031151880537889969" name="0/1/2/3/6/7/8/">
                  <joint name="0/1/2/3/6/7/8/joint/" class="0/1/2/3/6/7/" type="hinge" axis="0 1 0" limited="true" stiffness="100" range="-59.050940346037606 59.050940346037606" armature="0.20000000000000001" damping="3.5"/>
                  <geom name="0/1/2/3/6/7/8/geom" class="0/1/2/3/6/7/8/" type="capsule" contype="1" conaffinity="1" condim="3" size="0.042807848856201459" rgba="0.28730904396770562 0.5654812703083808 0.78020675875014189 1" friction="0.59999999999999998 0.10000000000000001 0.10000000000000001" fromto="0 0 0 0.41128168469409987 0 0.7281066669952585"/>
                  <site name="0/1/2/3/6/7/8/end8" class="0/1/2/3/6/7/8/" size="0.0050000000000000001" pos="0.41128168469409987 0 0.7281066669952585"/>
                  <site name="0/1/2/3/6/7/8/attach9" class="0/1/2/3/6/7/8/" size="9.9999999999999995e-07 9.9999999999999995e-07 9.9999999999999995e-07" pos="0.25830215725106126 0 0.45728154156350975"/>
                  <body pos="0.25830215725106126 0 0.45728154156350975" name="0/1/2/3/6/7/8/9/">
                    <joint name="0/1/2/3/6/7/8/9/joint/" class="0/1/2/3/6/7/8/" type="hinge" axis="0 1 0" limited="true" stiffness="100" range="-50.675162217328321 50.675162217328321" armature="0.20000000000000001" damping="3.5"/>
                    <geom name="0/1/2/3/6/7/8/9/geom" class="0/1/2/3/6/7/8/9/" type="capsule" contype="1" conaffinity="1" condim="3" size="0.062358063508320002" rgba="0.98262475859491616 0.27925529115918146 0.25173483704207322 1" friction="0.59999999999999998 0.10000000000000001 0.10000000000000001" fromto="0 0 0 0.54048111184103065 0 -0.47222001829394994"/>
                    <site name="0/1/2/3/6/7/8/9/end9" class="0/1/2/3/6/7/8/9/" size="0.0050000000000000001" pos="0.54048111184103065 0 -0.47222001829394994"/>
                  </body>
                </body>
              </body>
              <site name="0/1/2/3/6/attach10" class="0/1/2/3/6/" size="9.9999999999999995e-07 9.9999999999999995e-07 9.9999999999999995e-07" pos="0.15506049778676187 0 0.37197847118383481"/>
              <body pos="0.15506049778676187 0 0.37197847118383481" name="0/1/2/3/6/10/">
                <joint name="0/1/2/3/6/10/joint/" class="0/1/2/3/6/" type="hinge" axis="0 1 0" limited="true" stiffness="100" range="-67.526408236091868 67.526408236091868" armature="0.20000000000000001" damping="3.5"/>
                <geom name="0/1/2/3/6/10/geom" class="0/1/2/3/6/10/" type="capsule" contype="1" conaffinity="1" condim="3" size="0.051067001363479497" rgba="0.63650995276683431 0.67139262136466737 0.48189984022117249 1" friction="0.59999999999999998 0.10000000000000001 0.10000000000000001" fromto="0 0 0 -0.45743967222739695 0 0.42922551598219516"/>
                <site name="0/1/2/3/6/10/end10" class="0/1/2/3/6/10/" size="0.0050000000000000001" pos="-0.45743967222739695 0 0.42922551598219516"/>
              </body>
            </body>
          </body>
        </body>
      </body>
      <camera name="0/side" class="0/" mode="trackcom" pos="0.40000000000000002 -4 0.20000000000000001" quat="0.70699999999999996 0.70699999999999996 0 0"/>
    </body>
  </worldbody>
  <actuator>
    <motor name="0/1/2/motor" class="0/1/2/" ctrllimited="true" ctrlrange="-1 1" gear="55" joint="0/1/2/joint/"/>
    <motor name="0/1/2/3/motor" class="0/1/2/3/" ctrllimited="true" ctrlrange="-1 1" gear="87" joint="0/1/2/3/joint/"/>
    <motor name="0/1/2/3/4/motor" class="0/1/2/3/4/" ctrllimited="true" ctrlrange="-1 1" gear="66" joint="0/1/2/3/4/joint/"/>
    <motor name="0/1/2/3/4/5/motor" class="0/1/2/3/4/5/" ctrllimited="true" ctrlrange="-1 1" gear="58" joint="0/1/2/3/4/5/joint/"/>
    <motor name="0/1/2/3/6/motor" class="0/1/2/3/6/" ctrllimited="true" ctrlrange="-1 1" gear="88" joint="0/1/2/3/6/joint/"/>
    <motor name="0/1/2/3/6/7/motor" class="0/1/2/3/6/7/" ctrllimited="true" ctrlrange="-1 1" gear="71" joint="0/1/2/3/6/7/joint/"/>
    <motor name="0/1/2/3/6/7/8/motor" class="0/1/2/3/6/7/8/" ctrllimited="true" ctrlrange="-1 1" gear="70" joint="0/1/2/3/6/7/8/joint/"/>
    <motor name="0/1/2/3/6/7/8/9/motor" class="0/1/2/3/6/7/8/9/" ctrllimited="true" ctrlrange="-1 1" gear="67" joint="0/1/2/3/6/7/8/9/joint/"/>
    <motor name="0/1/2/3/6/10/motor" class="0/1/2/3/6/10/" ctrllimited="true" ctrlrange="-1 1" gear="88" joint="0/1/2/3/6/10/joint/"/>
  </actuator>
  <sensor>
    <subtreelinvel name="velocity" body="0/"/>
  </sensor>
</mujoco>
