<mujoco model="morphology">
  <option timestep="0.01"/>
  <default>
    <default class="/"/>
    <default class="0/"/>
    <default class="0/1/"/>
    <default class="0/2/"/>
    <default class="0/2/3/"/>
    <default class="0/2/3/4/"/>
    <default class="0/2/3/5/"/>
    <default class="0/2/3/5/6/"/>
    <default class="0/2/3/5/6/7/"/>
    <default class="0/2/3/5/6/7/8/"/>
    <default class="0/2/3/5/6/7/8/9/"/>
    <default class="0/2/3/5/6/7/8/9/10/"/>
  </default>
  <asset>
    <texture name="texplane" type="2d" builtin="checker" rgb1="0.10000000000000001 0.20000000000000001 0.29999999999999999" rgb2="0.20000000000000001 0.29999999999999999 0.40000000000000002" width="300" height="300"/>
    <material name="MatPlane" class="/" texture="texplane" texrepeat="20 20" specular="1" shininess="1" reflectance="0.5"/>
  </asset>
  <worldbody>
    <light name="//unnamed_light_0" class="/" directional="true" pos="0 0 1.5" dir="0 0 -1.3" cutoff="100" exponent="1" diffuse="1 1 1" specular="0.10000000000000001 0.10000000000000001 0.10000000000000001"/>
    <geom name="ground" class="/" type="plane" size="15 15 0.5" material="MatPlane" rgba="1 1 1 1"/>
    <site name="body" class="/" size="9.9999999999999995e-07 9.9999999999999995e-07 9.9999999999999995e-07" pos="0 0 2.1474524497985841"/>
    <body pos="0 0 2.1474524497985841" name="0/">
      <joint name="0/rootx/" class="/" type="slide" axis="1 0 0" limited="false" stiffness="0" armature="0" damping="0"/>
      <joint name="0/rootz/" class="/" type="slide" axis="0 0 1" limited="false" stiffness="0" armature="0" damping="0"/>
      <joint name="0/rooty/" class="/" type="hinge" axis="0 1 0" limited="false" stiffness="0" armature="0" damping="0"/>
      <geom name="0/geom" class="0/" type="capsule" contype="1" conaffinity="1" condim="3" size="0.062130601298975185" rgba="0.16041478311118129 0.50110829796523682 0.34171136798177093 1" friction="0.59999999999999998 0.10000000000000001 0.10000000000000001" fromto="0 0 0 -0.4846328472397316 0 -0.67605544920971328"/>
      <site name="0/end0" class="0/" size="0.0050000000000000001" pos="-0.4846328472397316 0 -0.67605544920971328"/>
      <site name="0/attach1" class="0/" size="9.9999999999999995e-07 9.9999999999999995e-07 9.9999999999999995e-07" pos="-0.13114539435884567 0 -0.18294583002376749"/>
      <body pos="-0.13114539435884567 0 -0.18294583002376749" name="0/1/">
        <joint name="0/1/joint/" class="0/" type="hinge" axis="0 1 0" limited="true" range="-46.088218807823857 46.088218807823857"/>
        <geom name="0/1/geom" class="0/1/" type="capsule" contype="1" conaffinity="1" condim="3" size="0.054380961132449744" rgba="0.68154486403999248 0.24797498014920094 0.087776905432252472 1" friction="0.59999999999999998 0.10000000000000001 0.10000000000000001" fromto="0 0 0 0.31092979364290096 0 -0.059648130211418127"/>
        <site name="0/1/end1" class="0/1/" size="0.0050000000000000001" pos="0.31092979364290096 0 -0.059648130211418127"/>
      </body>
      <site name="0/attach2" class="0/" size="9.9999999999999995e-07 9.9999999999999995e-07 9.9999999999999995e-07" pos="-0.43363802973726434 0 -0.60491845457479521"/>
      <body pos="-0.43363802973726434 0 -0.60491845457479521" name="0/2/">
        <geom name="0/2/geom" class="0/2/" type="capsule" contype="1" conaffinity="1" condim="3" size="0.047481356472906598" rgba="0.60339522030365977 0.46570736426384607 0.19123976577706636 1" friction="0.59999999999999998 0.10000000000000001 0.10000000000000001" fromto="0 0 0 0.61797253526959151 0 -0.011016511591066314"/>
        <site name="0/2/end2" class="0/2/" size="0.0050000000000000001" pos="0.61797253526959151 0 -0.011016511591066314"/>
        <site name="0/2/attach3" class="0/2/" size="9.9999999999999995e-07 9.9999999999999995e-07 9.9999999999999995e-07" pos="0.50686784591271261 0 -0.0090358635391461547"/>
        <body pos="0.50686784591271261 0 -0.0090358635391461547" name="0/2/3/">
          <joint name="0/2/3/joint/" class="0/2/" type="hinge" axis="0 1 0" limited="true" range="-30.783974611981545 30.783974611981545"/>
          <geom name="0/2/3/geom" class="0/2/3/" type="capsule" contype="1" conaffinity="1" condim="3" size="0.068818612289871239" rgba="0.51949433323437133 0.2222311058614147 0.5971361327557575 1" friction="0.59999999999999998 0.10000000000000001 0.10000000000000001" fromto="0 0 0 0.51962679485069674 0 -0.67237030162587363"/>
          <site name="0/2/3/end3" class="0/2/3/" size="0.0050000000000000001" pos="0.51962679485069674 0 -0.67237030162587363"/>
          <site name="0/2/3/attach4" class="0/2/3/" size="9.9999999999999995e-07 9.9999999999999995e-07 9.9999999999999995e-07" pos="0.14581051651482807 0 -0.1886712962857672"/>
          <body pos="0.14581051651482807 0 -0.1886712962857672" name="0/2/3/4/">
            <geom name="0/2/3/4/geom" class="0/2/3/4/" type="capsule" contype="1" conaffinity="1" condim="3" size="0.044948060919531796" rgba="0.37804078249630746 0.18281745910119229 0.96185137058828685 1" friction="0.59999999999999998 0.10000000000000001 0.10000000000000001" fromto="0 0 0 -0.20349556288273496 0 -0.1544968653088219"/>
            <site name="0/2/3/4/end4" class="0/2/3/4/" size="0.0050000000000000001" pos="-0.20349556288273496 0 -0.1544968653088219"/>
          </body>
          <site name="0/2/3/attach5" class="0/2/3/" size="9.9999999999999995e-07 9.9999999999999995e-07 9.9999999999999995e-07" pos="0.48835210096071446 0 -0.63190245898872432"/>
          <body pos="0.48835210096071446 0 -0.63190245898872432" name="0/2/3/5/">
            <geom name="0/2/3/5/geom" class="0/2/3/5/" type="capsule" contype="1" conaffinity="1" condim="3" size="0.058605313409821273" rgba="0.99007868436847501 0.90601731437544553 0.54081983317545124 1" friction="0.59999999999999998 0.10000000000000001 0.10000000000000001" fromto="0 0 0 -0.081247564810570383 0 -0.50555536292877257"/>
            <site name="0/2/3/5/end5" class="0/2/3/5/" size="0.0050000000000000001" pos="-0.081247564810570383 0 -0.50555536292877257"/>
            <site name="0/2/3/5/attach6" class="0/2/3/5/" size="9.9999999999999995e-07 9.9999999999999995e-07 9.9999999999999995e-07" pos="-0.032019712218281558 0 -0.19923966052558101"/>
            <body pos="-0.032019712218281558 0 -0.19923966052558101" name="0/2/3/5/6/">
              <joint name="0/2/3/5/6/joint/" class="0/2/3/5/" type="hinge" axis="0 1 0" limited="true" range="-37.722431790806198 37.722431790806198"/>
              <geom name="0/2/3/5/6/geom" class="0/2/3/5/6/" type="capsule" contype="1" conaffinity="1" condim="3" size="0.042613842907857337" rgba="0.91375239866931057 0.34784015598901075 0.30955602166339757 1" friction="0.59999999999999998 0.10000000000000001 0.10000000000000001" fromto="0 0 0 -0.39683771467805601 0 0.15328673266228598"/>
              <site name="0/2/3/5/6/end6" class="0/2/3/5/6/" size="0.0050000000000000001" pos="-0.39683771467805601 0 0.15328673266228598"/>
              <site name="0/2/3/5/6/attach7" class="0/2/3/5/6/" size="9.9999999999999995e-07 9.9999999999999995e-07 9.9999999999999995e-07" pos="-0.0068772739436767337 0 0.002656488568141567"/>
              <body pos="-0.0068772739436767337 0 0.002656488568141567" name="0/2/3/5/6/7/">
                <joint name="0/2/3/5/6/7/joint/" class="0/2/3/5/6/" type="hinge" axis="0 1 0" limited="true" range="-50.546496023570214 50.546496023570214"/>
                <geom name="0/2/3/5/6/7/geom" class="0/2/3/5/6/7/" type="capsule" contype="1" conaffinity="1" condim="3" size="0.055242573862808238" rgba="0.79745139264489484 0.67554148483265697 0.9677993408442801 1" friction="0.59999999999999998 0.10000000000000001 0.10000000000000001" fromto="0 0 0 0.7230407293382255 0 0.15162912630328007"/>
                <site name="0/2/3/5/6/7/end7" class="0/2/3/5/6/7/" size="0.0050000000000000001" pos="0.7230407293382255 0 0.15162912630328007"/>
                <site name="0/2/3/5/6/7/attach8" class="0/2/3/5/6/7/" size="9.9999999999999995e-07 9.9999999999999995e-07 9.9999999999999995e-07" pos="0.36086010439148819 0 0.075676099736002853"/>
                <body pos="0.36086010439148819 0 0.075676099736002853" name="0/2/3/5/6/7/8/">
                  <geom name="0/2/3/5/6/7/8/geom" class="0/2/3/5/6/7/8/" type="capsule" contype="1" conaffinity="1" condim="3" size="0.054427826431407457" rgba="0.28423817019496023 0.51710948423768976 0.019185543525430337 1" friction="0.59999999999999998 0.10000000000000001 0.10000000000000001" fromto="0 0 0 -0.17721305177194502 0 -0.68068848199126952"/>
                  <site name="0/2/3/5/6/7/8/end8" class="0/2/3/5/6/7/8/" size="0.0050000000000000001" pos="-0.17721305177194502 0 -0.68068848199126952"/>
                  <site name="0/2/3/5/6/7/8/attach9" class="0/2/3/5/6/7/8/" size="9.9999999999999995e-07 9.9999999999999995e-07 9.9999999999999995e-07" pos="-0.15014227446806944 0 -0.57670761757383293"/>
                  <body pos="-0.15014227446806944 0 -0.57670761757383293" name="0/2/3/5/6/7/8/9/">
                    <joint name="0/2/3/5/6/7/8/9/joint/" class="0/2/3/5/6/7/8/" type="hinge" axis="0 1 0" limited="true" range="-32.014693311049086 32.014693311049086"/>
                    <geom name="0/2/3/5/6/7/8/9/geom" class="0/2/3/5/6/7/8/9/" type="capsule" contype="1" conaffinity="1" condim="3" size="0.04633118770014677" rgba="0.06301120179437103 0.24292313228338025 0.69986239669213446 1" friction="0.59999999999999998 0.10000000000000001 0.10000000000000001" fromto="0 0 0 0.10101169971313739 0 -0.058183122929173825"/>
                    <site name="0/2/3/5/6/7/8/9/end9" class="0/2/3/5/6/7/8/9/" size="0.0050000000000000001" pos="0.10101169971313739 0 -0.058183122929173825"/>
                    <site name="0/2/3/5/6/7/8/9/attach10" class="0/2/3/5/6/7/8/9/" size="9.9999999999999995e-07 9.9999999999999995e-07 9.9999999999999995e-07" pos="0.047200749467721126 0 -0.027187811079594944"/>
                    <body pos="0.047200749467721126 0 -0.027187811079594944" name="0/2/3/5/6/7/8/9/10/">
                      <joint name="0/2/3/5/6/7/8/9/10/joint/" class="0/2/3/5/6/7/8/9/" type="hinge" axis="0 1 0" limited="true" range="-46.153689025039284 46.153689025039284"/>
                      <geom name="0/2/3/5/6/7/8/9/10/geom" class="0/2/3/5/6/7/8/9/10/" type="capsule" contype="1" conaffinity="1" condim="3" size="0.059850270276390755" rgba="0.79607431735727263 0.85545650513752391 0.2734119385069641 1" friction="0.59999999999999998 0.10000000000000001 0.10000000000000001" fromto="0 0 0 0.16025836170739349 0 0.12010867197656527"/>
                      <site name="0/2/3/5/6/7/8/9/10/end10" class="0/2/3/5/6/7/8/9/10/" size="0.0050000000000000001" pos="0.16025836170739349 0 0.12010867197656527"/>
                    </body>
                  </body>
                </body>
              </body>
            </body>
          </body>
        </body>
      </body>
      <camera name="0/side" class="0/" mode="trackcom" pos="0.40000000000000002 -4 0.20000000000000001" quat="0.70699999999999996 0.70699999999999996 0 0"/>
    </body>
  </worldbody>
  <actuator>
    <motor name="0/1/motor" class="0/1/" ctrllimited="true" ctrlrange="-1 1" gear="88" joint="0/1/joint/"/>
    <motor name="0/2/3/motor" class="0/2/3/" ctrllimited="true" ctrlrange="-1 1" gear="80" joint="0/2/3/joint/"/>
    <motor name="0/2/3/5/6/motor" class="0/2/3/5/6/" ctrllimited="true" ctrlrange="-1 1" gear="69" joint="0/2/3/5/6/joint/"/>
    <motor name="0/2/3/5/6/7/motor" class="0/2/3/5/6/7/" ctrllimited="true" ctrlrange="-1 1" gear="67" joint="0/2/3/5/6/7/joint/"/>
    <motor name="0/2/3/5/6/7/8/9/motor" class="0/2/3/5/6/7/8/9/" ctrllimited="true" ctrlrange="-1 1" gear="64" joint="0/2/3/5/6/7/8/9/joint/"/>
    <motor name="0/2/3/5/6/7/8/9/10/motor" class="0/2/3/5/6/7/8/9/10/" ctrllimited="true" ctrlrange="-1 1" gear="81" joint="0/2/3/5/6/7/8/9/10/joint/"/>
  </actuator>
  <sensor>
    <subtreelinvel name="velocity" body="0/"/>
  </sensor>
</mujoco>
