<mujoco model="morphology">
  <option timestep="0.01"/>
  <default>
    <default class="/"/>
    <default class="0/"/>
    <default class="0/1/"/>
    <default class="0/1/2/"/>
    <default class="0/1/2/3/"/>
    <default class="0/1/2/4/"/>
    <default class="0/1/2/4/5/"/>
    <default class="0/1/2/4/5/6/"/>
    <default class="0/1/2/4/5/7/"/>
    <default class="0/8/"/>
  </default>
  <asset>
    <texture name="texplane" type="2d" builtin="checker" rgb1="0.10000000000000001 0.20000000000000001 0.29999999999999999" rgb2="0.20000000000000001 0.29999999999999999 0.40000000000000002" width="300" height="300"/>
    <material name="MatPlane" class="/" texture="texplane" texrepeat="20 20" specular="1" shininess="1" reflectance="0.5"/>
  </asset>
  <worldbody>
    <light name="//unnamed_light_0" class="/" directional="true" pos="0 0 1.5" dir="0 0 -1.3" cutoff="100" exponent="1" diffuse="1 1 1" specular="0.10000000000000001 0.10000000000000001 0.10000000000000001"/>
    <geom name="ground" class="/" type="plane" size="15 15 0.5" material="MatPlane" rgba="1 1 1 1"/>
    <site name="body" class="/" size="9.9999999999999995e-07 9.9999999999999995e-07 9.9999999999999995e-07" pos="0 0 0.65496239662170408"/>
    <body pos="0 0 0.65496239662170408" name="0/">
      <joint name="0/rootx/" class="/" type="slide" axis="1 0 0" limited="false" stiffness="0" armature="0" damping="0"/>
      <joint name="0/rootz/" class="/" type="slide" axis="0 0 1" limited="false" stiffness="0" armature="0" damping="0"/>
      <joint name="0/rooty/" class="/" type="hinge" axis="0 1 0" limited="false" stiffness="0" armature="0" damping="0"/>
      <geom name="0/geom" class="0/" type="capsule" contype="1" conaffinity="1" condim="3" size="0.060495653293117929" rgba="0.2480556527389276 0.025493911460182983 0.57957901314523463 1" friction="0.59999999999999998 0.10000000000000001 0.10000000000000001" fromto="0 0 0 -0.51440033987103762 0 0.036800422338487904"/>
      <site name="0/end0" class="0/" size="0.0050000000000000001" pos="-0.51440033987103762 0 0.036800422338487904"/>
      <site name="0/attach1" class="0/" size="9.9999999999999995e-07 9.9999999999999995e-07 9.9999999999999995e-07" pos="-0.26749301587582835 0 0.019136565810384632"/>
      <body pos="-0.26749301587582835 0 0.019136565810384632" name="0/1/">
        <joint name="0/1/joint/" class="0/" type="hinge" axis="0 1 0" limited="true" stiffness="100" range="-33.230586923560097 33.230586923560097" armature="0.20000000000000001" damping="3.5"/>
        <geom name="0/1/geom" class="0/1/" type="capsule" contype="1" conaffinity="1" condim="3" size="0.04569035752592996" rgba="0.48994404256619772 0.092408584765199975 0.094072478647784008 1" friction="0.59999999999999998 0.10000000000000001 0.10000000000000001" fromto="0 0 0 0.14276740487743422 0 0.36622097760985906"/>
        <site name="0/1/end1" class="0/1/" size="0.0050000000000000001" pos="0.14276740487743422 0 0.36622097760985906"/>
        <site name="0/1/attach2" class="0/1/" size="9.9999999999999995e-07 9.9999999999999995e-07 9.9999999999999995e-07" pos="0.043669510277427687 0 0.11201920185684593"/>
        <body pos="0.043669510277427687 0 0.11201920185684593" name="0/1/2/">
          <joint name="0/1/2/joint/" class="0/1/" type="hinge" axis="0 1 0" limited="true" stiffness="100" range="-36.188017459950437 36.188017459950437" armature="0.20000000000000001" damping="3.5"/>
          <geom name="0/1/2/geom" class="0/1/2/" type="capsule" contype="1" conaffinity="1" condim="3" size="0.04826613879705445" rgba="0.2411152959042705 0.71520724391001578 0.66188419051731084 1" friction="0.59999999999999998 0.10000000000000001 0.10000000000000001" fromto="0 0 0 -0.27674005781381966 0 0.3879686574005512"/>
          <site name="0/1/2/end2" class="0/1/2/" size="0.0050000000000000001" pos="-0.27674005781381966 0 0.3879686574005512"/>
          <site name="0/1/2/attach3" class="0/1/2/" size="9.9999999999999995e-07 9.9999999999999995e-07 9.9999999999999995e-07" pos="-0.19521589784185978 0 0.27367794307502441"/>
          <body pos="-0.19521589784185978 0 0.27367794307502441" name="0/1/2/3/">
            <joint name="0/1/2/3/joint/" class="0/1/2/" type="hinge" axis="0 1 0" limited="true" stiffness="100" range="-41.187322896922765 41.187322896922765" armature="0.20000000000000001" damping="3.5"/>
            <geom name="0/1/2/3/geom" class="0/1/2/3/" type="capsule" contype="1" conaffinity="1" condim="3" size="0.042003973167425969" rgba="0.86761322238091609 0.22285141912524498 0.0041271830791850261 1" friction="0.59999999999999998 0.10000000000000001 0.10000000000000001" fromto="0 0 0 0.55610824535401093 0 0.65960613893393161"/>
            <site name="0/1/2/3/end3" class="0/1/2/3/" size="0.0050000000000000001" pos="0.55610824535401093 0 0.65960613893393161"/>
          </body>
          <site name="0/1/2/attach4" class="0/1/2/" size="9.9999999999999995e-07 9.9999999999999995e-07 9.9999999999999995e-07" pos="-0.037694754107262196 0 0.052845197972304983"/>
          <body pos="-0.037694754107262196 0 0.052845197972304983" name="0/1/2/4/">
            <joint name="0/1/2/4/joint/" class="0/1/2/" type="hinge" axis="0 1 0" limited="true" stiffness="100" range="-54.786157803888436 54.786157803888436" armature="0.20000000000000001" damping="3.5"/>
            <geom name="0/1/2/4/geom" class="0/1/2/4/" type="capsule" contype="1" conaffinity="1" condim="3" size="0.056045672542252595" rgba="0.49817748638462733 0.015013978278532014 0.3740137574885315 1" friction="0.59999999999999998 0.10000000000000001 0.10000000000000001" fromto="0 0 0 -0.74027749788315744 0 -0.18932364830688164"/>
            <site name="0/1/2/4/end4" class="0/1/2/4/" size="0.0050000000000000001" pos="-0.74027749788315744 0 -0.18932364830688164"/>
            <site name="0/1/2/4/attach5" class="0/1/2/4/" size="9.9999999999999995e-07 9.9999999999999995e-07 9.9999999999999995e-07" pos="-0.37117033157872747 0 -0.09492564817747709"/>
            <body pos="-0.37117033157872747 0 -0.09492564817747709" name="0/1/2/4/5/">
              <joint name="0/1/2/4/5/joint/" class="0/1/2/4/" type="hinge" axis="0 1 0" limited="true" stiffness="100" range="-60.228963553771351 60.228963553771351" armature="0.20000000000000001" damping="3.5"/>
              <geom name="0/1/2/4/5/geom" class="0/1/2/4/5/" type="capsule" contype="1" conaffinity="1" condim="3" size="0.044011173662368328" rgba="0.66796090941268349 0.64926986466821146 0.027518041654235881 1" friction="0.59999999999999998 0.10000000000000001 0.10000000000000001" fromto="0 0 0 -0.51691072660057247 0 0.72769278552053018"/>
              <site name="0/1/2/4/5/end5" class="0/1/2/4/5/" size="0.0050000000000000001" pos="-0.51691072660057247 0 0.72769278552053018"/>
              <site name="0/1/2/4/5/attach6" class="0/1/2/4/5/" size="9.9999999999999995e-07 9.9999999999999995e-07 9.9999999999999995e-07" pos="-0.028362798073810237 0 0.039928371522140592"/>
              <body pos="-0.028362798073810237 0 0.039928371522140592" name="0/1/2/4/5/6/">
                <joint name="0/1/2/4/5/6/joint/" class="0/1/2/4/5/" type="hinge" axis="0 1 0" limited="true" stiffness="100" range="-30.745650218079735 30.745650218079735" armature="0.20000000000000001" damping="3.5"/>
                <geom name="0/1/2/4/5/6/geom" class="0/1/2/4/5/6/" type="capsule" contype="1" conaffinity="1" condim="3" size="0.048926678095879785" rgba="0.83171304693678394 0.081637959231734003 0.23838821481606198 1" friction="0.59999999999999998 0.10000000000000001 0.10000000000000001" fromto="0 0 0 -0.49031165466203425 0 -0.017767433225745366"/>
                <site name="0/1/2/4/5/6/end6" class="0/1/2/4/5/6/" size="0.0050000000000000001" pos="-0.49031165466203425 0 -0.017767433225745366"/>
              </body>
              <site name="0/1/2/4/5/attach7" class="0/1/2/4/5/" size="9.9999999999999995e-07 9.9999999999999995e-07 9.9999999999999995e-07" pos="-0.31479491150443223 0 0.44315966806655038"/>
              <body pos="-0.31479491150443223 0 0.44315966806655038" name="0/1/2/4/5/7/">
                <joint name="0/1/2/4/5/7/joint/" class="0/1/2/4/5/" type="hinge" axis="0 1 0" limited="true" stiffness="100" range="-65.565453758022002 65.565453758022002" armature="0.20000000000000001" damping="3.5"/>
                <geom name="0/1/2/4/5/7/geom" class="0/1/2/4/5/7/" type="capsule" contype="1" conaffinity="1" condim="3" size="0.057164026298212794" rgba="0.9893958167535265 0.30478038005180397 0.015061827665131311 1" friction="0.59999999999999998 0.10000000000000001 0.10000000000000001" fromto="0 0 0 0.42768860916641227 0 0.18541428539840676"/>
                <site name="0/1/2/4/5/7/end7" class="0/1/2/4/5/7/" size="0.0050000000000000001" pos="0.42768860916641227 0 0.18541428539840676"/>
              </body>
            </body>
          </body>
        </body>
      </body>
      <site name="0/attach8" class="0/" size="9.9999999999999995e-07 9.9999999999999995e-07 9.9999999999999995e-07" pos="-0.41854595045273191 0 0.02994295794708433"/>
      <body pos="-0.41854595045273191 0 0.02994295794708433" name="0/8/">
        <joint name="0/8/joint/" class="0/" type="hinge" axis="0 1 0" limited="true" stiffness="100" range="-50.166069499770607 50.166069499770607" armature="0.20000000000000001" damping="3.5"/>
        <geom name="0/8/geom" class="0/8/" type="capsule" contype="1" conaffinity="1" condim="3" size="0.055029295354865698" rgba="0.72428599068487931 0.5176595809507295 0.17156022304144358 1" friction="0.59999999999999998 0.10000000000000001 0.10000000000000001" fromto="0 0 0 -0.30896362723951526 0 -0.58490536890241995"/>
        <site name="0/8/end8" class="0/8/" size="0.0050000000000000001" pos="-0.30896362723951526 0 -0.58490536890241995"/>
      </body>
      <camera name="0/side" class="0/" mode="trackcom" pos="0.40000000000000002 -4 0.20000000000000001" quat="0.70699999999999996 0.70699999999999996 0 0"/>
    </body>
  </worldbody>
  <actuator>
    <motor name="0/1/motor" class="0/1/" ctrllimited="true" ctrlrange="-1 1" gear="59" joint="0/1/joint/"/>
    <motor name="0/1/2/motor" class="0/1/2/" ctrllimited="true" ctrlrange="-1 1" gear="58" joint="0/1/2/joint/"/>
    <motor name="0/1/2/3/motor" class="0/1/2/3/" ctrllimited="true" ctrlrange="-1 1" gear="78" joint="0/1/2/3/joint/"/>
    <motor name="0/1/2/4/motor" class="0/1/2/4/" ctrllimited="true" ctrlrange="-1 1" gear="61" joint="0/1/2/4/joint/"/>
    <motor name="0/1/2/4/5/motor" class="0/1/2/4/5/" ctrllimited="true" ctrlrange="-1 1" gear="82" joint="0/1/2/4/5/joint/"/>
    <motor name="0/1/2/4/5/6/motor" class="0/1/2/4/5/6/" ctrllimited="true" ctrlrange="-1 1" gear="61" joint="0/1/2/4/5/6/joint/"/>
    <motor name="0/1/2/4/5/7/motor" class="0/1/2/4/5/7/" ctrllimited="true" ctrlrange="-1 1" gear="85" joint="0/1/2/4/5/7/joint/"/>
    <motor name="0/8/motor" class="0/8/" ctrllimited="true" ctrlrange="-1 1" gear="56" joint="0/8/joint/"/>
  </actuator>
  <sensor>
    <subtreelinvel name="velocity" body="0/"/>
  </sensor>
</mujoco>
