<mujoco model="morphology">
  <option timestep="0.01"/>
  <default>
    <default class="/"/>
    <default class="0/"/>
    <default class="0/1/"/>
    <default class="0/1/2/"/>
    <default class="0/1/2/3/"/>
    <default class="0/1/2/3/4/"/>
    <default class="0/1/2/3/4/5/"/>
    <default class="0/1/2/3/4/6/"/>
    <default class="0/1/2/3/4/6/7/"/>
    <default class="0/1/2/3/4/6/7/8/"/>
  </default>
  <asset>
    <texture name="texplane" type="2d" builtin="checker" rgb1="0.10000000000000001 0.20000000000000001 0.29999999999999999" rgb2="0.20000000000000001 0.29999999999999999 0.40000000000000002" width="300" height="300"/>
    <material name="MatPlane" class="/" texture="texplane" texrepeat="20 20" specular="1" shininess="1" reflectance="0.5"/>
  </asset>
  <worldbody>
    <light name="//unnamed_light_0" class="/" directional="true" pos="0 0 1.5" dir="0 0 -1.3" cutoff="100" exponent="1" diffuse="1 1 1" specular="0.10000000000000001 0.10000000000000001 0.10000000000000001"/>
    <geom name="ground" class="/" type="plane" size="15 15 0.5" material="MatPlane" rgba="1 1 1 1"/>
    <site name="body" class="/" size="9.9999999999999995e-07 9.9999999999999995e-07 9.9999999999999995e-07" pos="0 0 1.9986126184463502"/>
    <body pos="0 0 1.9986126184463502" name="0/">
      <joint name="0/rootx/" class="/" type="slide" axis="1 0 0" limited="false" stiffness="0" armature="0" damping="0"/>
      <joint name="0/rootz/" class="/" type="slide" axis="0 0 1" limited="false" stiffness="0" armature="0" damping="0"/>
      <joint name="0/rooty/" class="/" type="hinge" axis="0 1 0" limited="false" stiffness="0" armature="0" damping="0"/>
      <geom name="0/geom" class="0/" type="capsule" contype="1" conaffinity="1" condim="3" size="0.046301542937367164" rgba="0.18856140461397042 0.67513851205056419 0.28521870623243206 1" friction="0.59999999999999998 0.10000000000000001 0.10000000000000001" fromto="0 0 0 0.52294390513921241 0 -0.13276722416813347"/>
      <site name="0/end0" class="0/" size="0.0050000000000000001" pos="0.52294390513921241 0 -0.13276722416813347"/>
      <site name="0/attach1" class="0/" size="9.9999999999999995e-07 9.9999999999999995e-07 9.9999999999999995e-07" pos="0.44231459559737657 0 -0.11229671192148438"/>
      <body pos="0.44231459559737657 0 -0.11229671192148438" name="0/1/">
        <joint name="0/1/joint/" class="0/" type="hinge" axis="0 1 0" limited="true" stiffness="100" range="-33.992448565357549 33.992448565357549" armature="0.20000000000000001" damping="3.5"/>
        <geom name="0/1/geom" class="0/1/" type="capsule" contype="1" conaffinity="1" condim="3" size="0.051954363774270165" rgba="0.19309636318884382 0.9910473650917776 0.046831427286483707 1" friction="0.59999999999999998 0.10000000000000001 0.10000000000000001" fromto="0 0 0 -0.039237666101437529 0 -0.6186251000720776"/>
        <site name="0/1/end1" class="0/1/" size="0.0050000000000000001" pos="-0.039237666101437529 0 -0.6186251000720776"/>
        <site name="0/1/attach2" class="0/1/" size="9.9999999999999995e-07 9.9999999999999995e-07 9.9999999999999995e-07" pos="-0.034960230352853915 0 -0.55118660586657042"/>
        <body pos="-0.034960230352853915 0 -0.55118660586657042" name="0/1/2/">
          <geom name="0/1/2/geom" class="0/1/2/" type="capsule" contype="1" conaffinity="1" condim="3" size="0.069649279575995246" rgba="0.18648879058141643 0.17541003931893784 0.27836101012634296 1" friction="0.59999999999999998 0.10000000000000001 0.10000000000000001" fromto="0 0 0 0.61878217566754845 0 -0.21969743925356644"/>
          <site name="0/1/2/end2" class="0/1/2/" size="0.0050000000000000001" pos="0.61878217566754845 0 -0.21969743925356644"/>
          <site name="0/1/2/attach3" class="0/1/2/" size="9.9999999999999995e-07 9.9999999999999995e-07 9.9999999999999995e-07" pos="0.12518333863235179 0 -0.044446107234859852"/>
          <body pos="0.12518333863235179 0 -0.044446107234859852" name="0/1/2/3/">
            <joint name="0/1/2/3/joint/" class="0/1/2/" type="hinge" axis="0 1 0" limited="true" stiffness="100" range="-54.255000376070157 54.255000376070157" armature="0.20000000000000001" damping="3.5"/>
            <geom name="0/1/2/3/geom" class="0/1/2/3/" type="capsule" contype="1" conaffinity="1" condim="3" size="0.049210199514648834" rgba="0.87177559969425156 0.13330828274543649 0.13686337450795638 1" friction="0.59999999999999998 0.10000000000000001 0.10000000000000001" fromto="0 0 0 -0.64710043149857266 0 -0.71947854156679436"/>
            <site name="0/1/2/3/end3" class="0/1/2/3/" size="0.0050000000000000001" pos="-0.64710043149857266 0 -0.71947854156679436"/>
            <site name="0/1/2/3/attach4" class="0/1/2/3/" size="9.9999999999999995e-07 9.9999999999999995e-07 9.9999999999999995e-07" pos="-0.2638494089771885 0 -0.29336093552672432"/>
            <body pos="-0.2638494089771885 0 -0.29336093552672432" name="0/1/2/3/4/">
              <joint name="0/1/2/3/4/joint/" class="0/1/2/3/" type="hinge" axis="0 1 0" limited="true" stiffness="100" range="-58.302392995937367 58.302392995937367" armature="0.20000000000000001" damping="3.5"/>
              <geom name="0/1/2/3/4/geom" class="0/1/2/3/4/" type="capsule" contype="1" conaffinity="1" condim="3" size="0.055984806586061309" rgba="0.77148190460806809 0.44850054647732729 0.70323401073853298 1" friction="0.59999999999999998 0.10000000000000001 0.10000000000000001" fromto="0 0 0 0.12013119294528529 0 -0.43436342571304809"/>
              <site name="0/1/2/3/4/end4" class="0/1/2/3/4/" size="0.0050000000000000001" pos="0.12013119294528529 0 -0.43436342571304809"/>
              <site name="0/1/2/3/4/attach5" class="0/1/2/3/4/" size="9.9999999999999995e-07 9.9999999999999995e-07 9.9999999999999995e-07" pos="0.061386134510842683 0 -0.22195643798822406"/>
              <body pos="0.061386134510842683 0 -0.22195643798822406" name="0/1/2/3/4/5/">
                <geom name="0/1/2/3/4/5/geom" class="0/1/2/3/4/5/" type="capsule" contype="1" conaffinity="1" condim="3" size="0.058328980330184681" rgba="0.88803748693221518 0.28276733841771495 0.35926298776476362 1" friction="0.59999999999999998 0.10000000000000001 0.10000000000000001" fromto="0 0 0 -0.57600845241391085 0 -0.6753657971635505"/>
                <site name="0/1/2/3/4/5/end5" class="0/1/2/3/4/5/" size="0.0050000000000000001" pos="-0.57600845241391085 0 -0.6753657971635505"/>
              </body>
              <site name="0/1/2/3/4/attach6" class="0/1/2/3/4/" size="9.9999999999999995e-07 9.9999999999999995e-07 9.9999999999999995e-07" pos="0.094619989392603659 0 -0.34212149006314019"/>
              <body pos="0.094619989392603659 0 -0.34212149006314019" name="0/1/2/3/4/6/">
                <geom name="0/1/2/3/4/6/geom" class="0/1/2/3/4/6/" type="capsule" contype="1" conaffinity="1" condim="3" size="0.052253870874924856" rgba="0.99601056382081876 0.2716728174195846 0.7426729011364045 1" friction="0.59999999999999998 0.10000000000000001 0.10000000000000001" fromto="0 0 0 0.30412728907771691 0 0.27618881420975105"/>
                <site name="0/1/2/3/4/6/end6" class="0/1/2/3/4/6/" size="0.0050000000000000001" pos="0.30412728907771691 0 0.27618881420975105"/>
                <site name="0/1/2/3/4/6/attach7" class="0/1/2/3/4/6/" size="9.9999999999999995e-07 9.9999999999999995e-07 9.9999999999999995e-07" pos="0.25173903347644544 0 0.22861317495386341"/>
                <body pos="0.25173903347644544 0 0.22861317495386341" name="0/1/2/3/4/6/7/">
                  <joint name="0/1/2/3/4/6/7/joint/" class="0/1/2/3/4/6/" type="hinge" axis="0 1 0" limited="true" stiffness="100" range="-55.668870753723319 55.668870753723319" armature="0.20000000000000001" damping="3.5"/>
                  <geom name="0/1/2/3/4/6/7/geom" class="0/1/2/3/4/6/7/" type="capsule" contype="1" conaffinity="1" condim="3" size="0.063752733696774158" rgba="0.35150072897438545 0.34849817734143151 0.98699783561362908 1" friction="0.59999999999999998 0.10000000000000001 0.10000000000000001" fromto="0 0 0 0.08101668041221155 0 -0.45189104501055005"/>
                  <site name="0/1/2/3/4/6/7/end7" class="0/1/2/3/4/6/7/" size="0.0050000000000000001" pos="0.08101668041221155 0 -0.45189104501055005"/>
                  <site name="0/1/2/3/4/6/7/attach8" class="0/1/2/3/4/6/7/" size="9.9999999999999995e-07 9.9999999999999995e-07 9.9999999999999995e-07" pos="0.051527447137830612 0 -0.28740738099077262"/>
                  <body pos="0.051527447137830612 0 -0.28740738099077262" name="0/1/2/3/4/6/7/8/">
                    <joint name="0/1/2/3/4/6/7/8/joint/" class="0/1/2/3/4/6/7/" type="hinge" axis="0 1 0" limited="true" stiffness="100" range="-40.206185565413961 40.206185565413961" armature="0.20000000000000001" damping="3.5"/>
                    <geom name="0/1/2/3/4/6/7/8/geom" class="0/1/2/3/4/6/7/8/" type="capsule" contype="1" conaffinity="1" condim="3" size="0.06604299196233783" rgba="0.059406160419659293 0.77644654671571478 0.11073111633428101 1" friction="0.59999999999999998 0.10000000000000001 0.10000000000000001" fromto="0 0 0 0.12679122255713315 0 0.071754394774985686"/>
                    <site name="0/1/2/3/4/6/7/8/end8" class="0/1/2/3/4/6/7/8/" size="0.0050000000000000001" pos="0.12679122255713315 0 0.071754394774985686"/>
                  </body>
                </body>
              </body>
            </body>
          </body>
        </body>
      </body>
      <camera name="0/side" class="0/" mode="trackcom" pos="0.40000000000000002 -4 0.20000000000000001" quat="0.70699999999999996 0.70699999999999996 0 0"/>
    </body>
  </worldbody>
  <actuator>
    <motor name="0/1/motor" class="0/1/" ctrllimited="true" ctrlrange="-1 1" gear="56" joint="0/1/joint/"/>
    <motor name="0/1/2/3/motor" class="0/1/2/3/" ctrllimited="true" ctrlrange="-1 1" gear="86" joint="0/1/2/3/joint/"/>
    <motor name="0/1/2/3/4/motor" class="0/1/2/3/4/" ctrllimited="true" ctrlrange="-1 1" gear="80" joint="0/1/2/3/4/joint/"/>
    <motor name="0/1/2/3/4/6/7/motor" class="0/1/2/3/4/6/7/" ctrllimited="true" ctrlrange="-1 1" gear="60" joint="0/1/2/3/4/6/7/joint/"/>
    <motor name="0/1/2/3/4/6/7/8/motor" class="0/1/2/3/4/6/7/8/" ctrllimited="true" ctrlrange="-1 1" gear="63" joint="0/1/2/3/4/6/7/8/joint/"/>
  </actuator>
  <sensor>
    <subtreelinvel name="velocity" body="0/"/>
  </sensor>
</mujoco>
