<mujoco model="morphology">
  <option timestep="0.01"/>
  <default>
    <default class="/"/>
    <default class="0/"/>
    <default class="0/1/"/>
    <default class="0/1/2/"/>
    <default class="0/1/2/3/"/>
    <default class="0/1/2/3/4/"/>
    <default class="0/1/2/3/4/5/"/>
    <default class="0/1/2/3/4/5/6/"/>
    <default class="0/1/2/3/4/7/"/>
    <default class="0/1/2/8/"/>
    <default class="0/1/2/8/9/"/>
    <default class="0/10/"/>
  </default>
  <asset>
    <texture name="texplane" type="2d" builtin="checker" rgb1="0.10000000000000001 0.20000000000000001 0.29999999999999999" rgb2="0.20000000000000001 0.29999999999999999 0.40000000000000002" width="300" height="300"/>
    <material name="MatPlane" class="/" texture="texplane" texrepeat="20 20" specular="1" shininess="1" reflectance="0.5"/>
  </asset>
  <worldbody>
    <light name="//unnamed_light_0" class="/" directional="true" pos="0 0 1.5" dir="0 0 -1.3" cutoff="100" exponent="1" diffuse="1 1 1" specular="0.10000000000000001 0.10000000000000001 0.10000000000000001"/>
    <geom name="ground" class="/" type="plane" size="15 15 0.5" material="MatPlane" rgba="1 1 1 1"/>
    <site name="body" class="/" size="9.9999999999999995e-07 9.9999999999999995e-07 9.9999999999999995e-07" pos="0 0 1.6102374553680421"/>
    <body pos="0 0 1.6102374553680421" name="0/">
      <joint name="0/rootx/" class="/" type="slide" axis="1 0 0" limited="false" stiffness="0" armature="0" damping="0"/>
      <joint name="0/rootz/" class="/" type="slide" axis="0 0 1" limited="false" stiffness="0" armature="0" damping="0"/>
      <joint name="0/rooty/" class="/" type="hinge" axis="0 1 0" limited="false" stiffness="0" armature="0" damping="0"/>
      <geom name="0/geom" class="0/" type="capsule" contype="1" conaffinity="1" condim="3" size="0.052295217234225297" rgba="0.2634299442811856 0.67567318638327134 0.95085648575965209 1" friction="0.59999999999999998 0.10000000000000001 0.10000000000000001" fromto="0 0 0 0.30190797972354577 0 0.72943325160549244"/>
      <site name="0/end0" class="0/" size="0.0050000000000000001" pos="0.30190797972354577 0 0.72943325160549244"/>
      <site name="0/attach1" class="0/" size="9.9999999999999995e-07 9.9999999999999995e-07 9.9999999999999995e-07" pos="0.011298395805376123 0 0.027297806430250555"/>
      <body pos="0.011298395805376123 0 0.027297806430250555" name="0/1/">
        <joint name="0/1/joint/" class="0/" type="hinge" axis="0 1 0" limited="true" stiffness="100" range="-59.231311289796871 59.231311289796871" armature="0.20000000000000001" damping="3.5"/>
        <geom name="0/1/geom" class="0/1/" type="capsule" contype="1" conaffinity="1" condim="3" size="0.060876996112196893" rgba="0.37863171569743514 0.62047128059270895 0.33024723588311322 1" friction="0.59999999999999998 0.10000000000000001 0.10000000000000001" fromto="0 0 0 -0.12857878575418713 0 -0.074370490147103396"/>
        <site name="0/1/end1" class="0/1/" size="0.0050000000000000001" pos="-0.12857878575418713 0 -0.074370490147103396"/>
        <site name="0/1/attach2" class="0/1/" size="9.9999999999999995e-07 9.9999999999999995e-07 9.9999999999999995e-07" pos="-0.071569261057668657 0 -0.041395950296967923"/>
        <body pos="-0.071569261057668657 0 -0.041395950296967923" name="0/1/2/">
          <joint name="0/1/2/joint/" class="0/1/" type="hinge" axis="0 1 0" limited="true" stiffness="100" range="-51.686783396913953 51.686783396913953" armature="0.20000000000000001" damping="3.5"/>
          <geom name="0/1/2/geom" class="0/1/2/" type="capsule" contype="1" conaffinity="1" condim="3" size="0.041229180895039394" rgba="0.69285334243317487 0.13567102246489537 0.1252809109107762 1" friction="0.59999999999999998 0.10000000000000001 0.10000000000000001" fromto="0 0 0 0.00011640722251726743 0 -0.30758273033590616"/>
          <site name="0/1/2/end2" class="0/1/2/" size="0.0050000000000000001" pos="0.00011640722251726743 0 -0.30758273033590616"/>
          <site name="0/1/2/attach3" class="0/1/2/" size="9.9999999999999995e-07 9.9999999999999995e-07 9.9999999999999995e-07" pos="5.8819099535920983e-05 0 -0.1554176694532364"/>
          <body pos="5.8819099535920983e-05 0 -0.1554176694532364" name="0/1/2/3/">
            <joint name="0/1/2/3/joint/" class="0/1/2/" type="hinge" axis="0 1 0" limited="true" stiffness="100" range="-36.092046248376654 36.092046248376654" armature="0.20000000000000001" damping="3.5"/>
            <geom name="0/1/2/3/geom" class="0/1/2/3/" type="capsule" contype="1" conaffinity="1" condim="3" size="0.041982225025139042" rgba="0.88329647826145263 0.5654829612381439 0.88299124814853114 1" friction="0.59999999999999998 0.10000000000000001 0.10000000000000001" fromto="0 0 0 0.54643437102666592 0 0.52994543209765421"/>
            <site name="0/1/2/3/end3" class="0/1/2/3/" size="0.0050000000000000001" pos="0.54643437102666592 0 0.52994543209765421"/>
            <site name="0/1/2/3/attach4" class="0/1/2/3/" size="9.9999999999999995e-07 9.9999999999999995e-07 9.9999999999999995e-07" pos="0.51286664597686105 0 0.49739063046130916"/>
            <body pos="0.51286664597686105 0 0.49739063046130916" name="0/1/2/3/4/">
              <joint name="0/1/2/3/4/joint/" class="0/1/2/3/" type="hinge" axis="0 1 0" limited="true" stiffness="100" range="-55.361204381015199 55.361204381015199" armature="0.20000000000000001" damping="3.5"/>
              <geom name="0/1/2/3/4/geom" class="0/1/2/3/4/" type="capsule" contype="1" conaffinity="1" condim="3" size="0.060968156019638751" rgba="0.083891089304794497 0.62592527553727162 0.29666262345935046 1" friction="0.59999999999999998 0.10000000000000001 0.10000000000000001" fromto="0 0 0 -0.00047803283117431317 0 -0.39122728410053043"/>
              <site name="0/1/2/3/4/end4" class="0/1/2/3/4/" size="0.0050000000000000001" pos="-0.00047803283117431317 0 -0.39122728410053043"/>
              <site name="0/1/2/3/4/attach5" class="0/1/2/3/4/" size="9.9999999999999995e-07 9.9999999999999995e-07 9.9999999999999995e-07" pos="-0.00016615608966642843 0 -0.13598395645184713"/>
              <body pos="-0.00016615608966642843 0 -0.13598395645184713" name="0/1/2/3/4/5/">
                <geom name="0/1/2/3/4/5/geom" class="0/1/2/3/4/5/" type="capsule" contype="1" conaffinity="1" condim="3" size="0.042021399146666513" rgba="0.6843051384277814 0.15929621946584416 0.88587358682908901 1" friction="0.59999999999999998 0.10000000000000001 0.10000000000000001" fromto="0 0 0 0.42068779392125411 0 0.036226742702749282"/>
                <site name="0/1/2/3/4/5/end5" class="0/1/2/3/4/5/" size="0.0050000000000000001" pos="0.42068779392125411 0 0.036226742702749282"/>
                <site name="0/1/2/3/4/5/attach6" class="0/1/2/3/4/5/" size="9.9999999999999995e-07 9.9999999999999995e-07 9.9999999999999995e-07" pos="0.31007213582445259 0 0.026701282152975868"/>
                <body pos="0.31007213582445259 0 0.026701282152975868" name="0/1/2/3/4/5/6/">
                  <geom name="0/1/2/3/4/5/6/geom" class="0/1/2/3/4/5/6/" type="capsule" contype="1" conaffinity="1" condim="3" size="0.055910879358247546" rgba="0.89075849211095848 0.65429364131776513 0.47835116133851086 1" friction="0.59999999999999998 0.10000000000000001 0.10000000000000001" fromto="0 0 0 0.030345609047957023 0 0.63554586918158207"/>
                  <site name="0/1/2/3/4/5/6/end6" class="0/1/2/3/4/5/6/" size="0.0050000000000000001" pos="0.030345609047957023 0 0.63554586918158207"/>
                </body>
              </body>
              <site name="0/1/2/3/4/attach7" class="0/1/2/3/4/" size="9.9999999999999995e-07 9.9999999999999995e-07 9.9999999999999995e-07" pos="-0.00037097885271180763 0 -0.30361314022853675"/>
              <body pos="-0.00037097885271180763 0 -0.30361314022853675" name="0/1/2/3/4/7/">
                <joint name="0/1/2/3/4/7/joint/" class="0/1/2/3/4/" type="hinge" axis="0 1 0" limited="true" stiffness="100" range="-54.647498690493236 54.647498690493236" armature="0.20000000000000001" damping="3.5"/>
                <geom name="0/1/2/3/4/7/geom" class="0/1/2/3/4/7/" type="capsule" contype="1" conaffinity="1" condim="3" size="0.045083569929031925" rgba="0.19756393005431128 0.73015657879535656 0.073763919318221127 1" friction="0.59999999999999998 0.10000000000000001 0.10000000000000001" fromto="0 0 0 0.71503860975912126 0 -0.3488812501923847"/>
                <site name="0/1/2/3/4/7/end7" class="0/1/2/3/4/7/" size="0.0050000000000000001" pos="0.71503860975912126 0 -0.3488812501923847"/>
              </body>
            </body>
          </body>
          <site name="0/1/2/attach8" class="0/1/2/" size="9.9999999999999995e-07 9.9999999999999995e-07 9.9999999999999995e-07" pos="0.00010995970692576717 0 -0.29054646397173961"/>
          <body pos="0.00010995970692576717 0 -0.29054646397173961" name="0/1/2/8/">
            <joint name="0/1/2/8/joint/" class="0/1/2/" type="hinge" axis="0 1 0" limited="true" stiffness="100" range="-33.402595960001456 33.402595960001456" armature="0.20000000000000001" damping="3.5"/>
            <geom name="0/1/2/8/geom" class="0/1/2/8/" type="capsule" contype="1" conaffinity="1" condim="3" size="0.049491163319624901" rgba="0.98945483924677635 0.27046069042011922 0.26486789008912792 1" friction="0.59999999999999998 0.10000000000000001 0.10000000000000001" fromto="0 0 0 0.49043747763606338 0 -0.56993467824646959"/>
            <site name="0/1/2/8/end8" class="0/1/2/8/" size="0.0050000000000000001" pos="0.49043747763606338 0 -0.56993467824646959"/>
            <site name="0/1/2/8/attach9" class="0/1/2/8/" size="9.9999999999999995e-07 9.9999999999999995e-07 9.9999999999999995e-07" pos="0.45881731393235359 0 -0.53318906102031705"/>
            <body pos="0.45881731393235359 0 -0.53318906102031705" name="0/1/2/8/9/">
              <joint name="0/1/2/8/9/joint/" class="0/1/2/8/" type="hinge" axis="0 1 0" limited="true" stiffness="100" range="-46.43652076422633 46.43652076422633" armature="0.20000000000000001" damping="3.5"/>
              <geom name="0/1/2/8/9/geom" class="0/1/2/8/9/" type="capsule" contype="1" conaffinity="1" condim="3" size="0.054224616568449437" rgba="0.61701924626746962 0.12199254529080406 0.49601953567093526 1" friction="0.59999999999999998 0.10000000000000001 0.10000000000000001" fromto="0 0 0 -0.17929042763588066 0 -0.67240384236790673"/>
              <site name="0/1/2/8/9/end9" class="0/1/2/8/9/" size="0.0050000000000000001" pos="-0.17929042763588066 0 -0.67240384236790673"/>
            </body>
          </body>
        </body>
      </body>
      <site name="0/attach10" class="0/" size="9.9999999999999995e-07 9.9999999999999995e-07 9.9999999999999995e-07" pos="0.17493250574074634 0 0.42265059237855396"/>
      <body pos="0.17493250574074634 0 0.42265059237855396" name="0/10/">
        <geom name="0/10/geom" class="0/10/" type="capsule" contype="1" conaffinity="1" condim="3" size="0.060289328040293848" rgba="0.25913095289417487 0.28242398149026771 0.1188151428804719 1" friction="0.59999999999999998 0.10000000000000001 0.10000000000000001" fromto="0 0 0 -0.29582820999064935 0 0.44981654723496556"/>
        <site name="0/10/end10" class="0/10/" size="0.0050000000000000001" pos="-0.29582820999064935 0 0.44981654723496556"/>
      </body>
      <camera name="0/side" class="0/" mode="trackcom" pos="0.40000000000000002 -4 0.20000000000000001" quat="0.70699999999999996 0.70699999999999996 0 0"/>
    </body>
  </worldbody>
  <actuator>
    <motor name="0/1/motor" class="0/1/" ctrllimited="true" ctrlrange="-1 1" gear="51" joint="0/1/joint/"/>
    <motor name="0/1/2/motor" class="0/1/2/" ctrllimited="true" ctrlrange="-1 1" gear="67" joint="0/1/2/joint/"/>
    <motor name="0/1/2/3/motor" class="0/1/2/3/" ctrllimited="true" ctrlrange="-1 1" gear="79" joint="0/1/2/3/joint/"/>
    <motor name="0/1/2/3/4/motor" class="0/1/2/3/4/" ctrllimited="true" ctrlrange="-1 1" gear="57" joint="0/1/2/3/4/joint/"/>
    <motor name="0/1/2/3/4/7/motor" class="0/1/2/3/4/7/" ctrllimited="true" ctrlrange="-1 1" gear="56" joint="0/1/2/3/4/7/joint/"/>
    <motor name="0/1/2/8/motor" class="0/1/2/8/" ctrllimited="true" ctrlrange="-1 1" gear="85" joint="0/1/2/8/joint/"/>
    <motor name="0/1/2/8/9/motor" class="0/1/2/8/9/" ctrllimited="true" ctrlrange="-1 1" gear="57" joint="0/1/2/8/9/joint/"/>
  </actuator>
  <sensor>
    <subtreelinvel name="velocity" body="0/"/>
  </sensor>
</mujoco>
