<mujoco model="morphology">
  <option timestep="0.01"/>
  <default>
    <default class="/"/>
    <default class="0/"/>
    <default class="0/1/"/>
    <default class="0/1/2/"/>
    <default class="0/1/2/3/"/>
    <default class="0/1/2/3/4/"/>
    <default class="0/1/2/3/4/5/"/>
    <default class="0/1/2/3/4/5/6/"/>
    <default class="0/1/2/3/4/5/6/7/"/>
    <default class="0/1/2/8/"/>
  </default>
  <asset>
    <texture name="texplane" type="2d" builtin="checker" rgb1="0.10000000000000001 0.20000000000000001 0.29999999999999999" rgb2="0.20000000000000001 0.29999999999999999 0.40000000000000002" width="300" height="300"/>
    <material name="MatPlane" class="/" texture="texplane" texrepeat="20 20" specular="1" shininess="1" reflectance="0.5"/>
  </asset>
  <worldbody>
    <light name="//unnamed_light_0" class="/" directional="true" pos="0 0 1.5" dir="0 0 -1.3" cutoff="100" exponent="1" diffuse="1 1 1" specular="0.10000000000000001 0.10000000000000001 0.10000000000000001"/>
    <geom name="ground" class="/" type="plane" size="15 15 0.5" material="MatPlane" rgba="1 1 1 1"/>
    <site name="body" class="/" size="9.9999999999999995e-07 9.9999999999999995e-07 9.9999999999999995e-07" pos="0 0 0.73735705614089964"/>
    <body pos="0 0 0.73735705614089964" name="0/">
      <joint name="0/rootx/" class="/" type="slide" axis="1 0 0" limited="false" stiffness="0" armature="0" damping="0"/>
      <joint name="0/rootz/" class="/" type="slide" axis="0 0 1" limited="false" stiffness="0" armature="0" damping="0"/>
      <joint name="0/rooty/" class="/" type="hinge" axis="0 1 0" limited="false" stiffness="0" armature="0" damping="0"/>
      <geom name="0/geom" class="0/" type="capsule" contype="1" conaffinity="1" condim="3" size="0.055554045840999045" rgba="0.0040576181855573878 0.90247922886734544 0.41203304608872937 1" friction="0.59999999999999998 0.10000000000000001 0.10000000000000001" fromto="0 0 0 0.55778422971038566 0 -0.6373570312442306"/>
      <site name="0/end0" class="0/" size="0.0050000000000000001" pos="0.55778422971038566 0 -0.6373570312442306"/>
      <site name="0/attach1" class="0/" size="9.9999999999999995e-07 9.9999999999999995e-07 9.9999999999999995e-07" pos="0.29323328401659066 0 -0.33506557806385151"/>
      <body pos="0.29323328401659066 0 -0.33506557806385151" name="0/1/">
        <joint name="0/1/joint/" class="0/" type="hinge" axis="0 1 0" limited="true" range="-35.894087429080265 35.894087429080265"/>
        <geom name="0/1/geom" class="0/1/" type="capsule" contype="1" conaffinity="1" condim="3" size="0.045720540593500683" rgba="0.28538777916866465 0.058974576682132573 0.53001623238853535 1" friction="0.59999999999999998 0.10000000000000001 0.10000000000000001" fromto="0 0 0 0.21714184010675908 0 0.11082605125507594"/>
        <site name="0/1/end1" class="0/1/" size="0.0050000000000000001" pos="0.21714184010675908 0 0.11082605125507594"/>
        <site name="0/1/attach2" class="0/1/" size="9.9999999999999995e-07 9.9999999999999995e-07 9.9999999999999995e-07" pos="0.13001014525689145 0 0.066355295758920019"/>
        <body pos="0.13001014525689145 0 0.066355295758920019" name="0/1/2/">
          <joint name="0/1/2/joint/" class="0/1/" type="hinge" axis="0 1 0" limited="true" range="-39.693086694032019 39.693086694032019"/>
          <geom name="0/1/2/geom" class="0/1/2/" type="capsule" contype="1" conaffinity="1" condim="3" size="0.061945782357280266" rgba="0.2188551690230639 0.098272591656029862 0.65773936584318837 1" friction="0.59999999999999998 0.10000000000000001 0.10000000000000001" fromto="0 0 0 -0.066172551536488822 0 0.35778616773107652"/>
          <site name="0/1/2/end2" class="0/1/2/" size="0.0050000000000000001" pos="-0.066172551536488822 0 0.35778616773107652"/>
          <site name="0/1/2/attach3" class="0/1/2/" size="9.9999999999999995e-07 9.9999999999999995e-07 9.9999999999999995e-07" pos="-0.045831994868769356 0 0.24780748849506201"/>
          <body pos="-0.045831994868769356 0 0.24780748849506201" name="0/1/2/3/">
            <joint name="0/1/2/3/joint/" class="0/1/2/" type="hinge" axis="0 1 0" limited="true" range="-61.802591334500399 61.802591334500399"/>
            <geom name="0/1/2/3/geom" class="0/1/2/3/" type="capsule" contype="1" conaffinity="1" condim="3" size="0.051009037573850308" rgba="0.9237770256582144 0.25501440493191241 0.28746890973844075 1" friction="0.59999999999999998 0.10000000000000001 0.10000000000000001" fromto="0 0 0 0.32363327797470309 0 0.44638098461076225"/>
            <site name="0/1/2/3/end3" class="0/1/2/3/" size="0.0050000000000000001" pos="0.32363327797470309 0 0.44638098461076225"/>
            <site name="0/1/2/3/attach4" class="0/1/2/3/" size="9.9999999999999995e-07 9.9999999999999995e-07 9.9999999999999995e-07" pos="0.12244228634819809 0 0.16888222583332038"/>
            <body pos="0.12244228634819809 0 0.16888222583332038" name="0/1/2/3/4/">
              <joint name="0/1/2/3/4/joint/" class="0/1/2/3/" type="hinge" axis="0 1 0" limited="true" range="-36.063675809151704 36.063675809151704"/>
              <geom name="0/1/2/3/4/geom" class="0/1/2/3/4/" type="capsule" contype="1" conaffinity="1" condim="3" size="0.060124548398940783" rgba="0.56060524420236468 0.10293908333359347 0.088720758368114438 1" friction="0.59999999999999998 0.10000000000000001 0.10000000000000001" fromto="0 0 0 0.53914758435007504 0 -0.36082226989496335"/>
              <site name="0/1/2/3/4/end4" class="0/1/2/3/4/" size="0.0050000000000000001" pos="0.53914758435007504 0 -0.36082226989496335"/>
              <site name="0/1/2/3/4/attach5" class="0/1/2/3/4/" size="9.9999999999999995e-07 9.9999999999999995e-07 9.9999999999999995e-07" pos="0.28699670800073773 0 -0.19207134862347597"/>
              <body pos="0.28699670800073773 0 -0.19207134862347597" name="0/1/2/3/4/5/">
                <geom name="0/1/2/3/4/5/geom" class="0/1/2/3/4/5/" type="capsule" contype="1" conaffinity="1" condim="3" size="0.048273941875551493" rgba="0.023796090418712779 0.60121662859248015 0.19167742331438831 1" friction="0.59999999999999998 0.10000000000000001 0.10000000000000001" fromto="0 0 0 0.085225474241775734 0 0.43670925007418404"/>
                <site name="0/1/2/3/4/5/end5" class="0/1/2/3/4/5/" size="0.0050000000000000001" pos="0.085225474241775734 0 0.43670925007418404"/>
                <site name="0/1/2/3/4/5/attach6" class="0/1/2/3/4/5/" size="9.9999999999999995e-07 9.9999999999999995e-07 9.9999999999999995e-07" pos="0.010732543507358763 0 0.054995305901034561"/>
                <body pos="0.010732543507358763 0 0.054995305901034561" name="0/1/2/3/4/5/6/">
                  <joint name="0/1/2/3/4/5/6/joint/" class="0/1/2/3/4/5/" type="hinge" axis="0 1 0" limited="true" range="-38.296384708800218 38.296384708800218"/>
                  <geom name="0/1/2/3/4/5/6/geom" class="0/1/2/3/4/5/6/" type="capsule" contype="1" conaffinity="1" condim="3" size="0.045797936444625091" rgba="0.31979516369169392 0.20505990051490852 0.087210255329537301 1" friction="0.59999999999999998 0.10000000000000001 0.10000000000000001" fromto="0 0 0 0.74583675641101843 0 -0.29705530782716305"/>
                  <site name="0/1/2/3/4/5/6/end6" class="0/1/2/3/4/5/6/" size="0.0050000000000000001" pos="0.74583675641101843 0 -0.29705530782716305"/>
                  <site name="0/1/2/3/4/5/6/attach7" class="0/1/2/3/4/5/6/" size="9.9999999999999995e-07 9.9999999999999995e-07 9.9999999999999995e-07" pos="0.22133551082794842 0 -0.088154529442157792"/>
                  <body pos="0.22133551082794842 0 -0.088154529442157792" name="0/1/2/3/4/5/6/7/">
                    <joint name="0/1/2/3/4/5/6/7/joint/" class="0/1/2/3/4/5/6/" type="hinge" axis="0 1 0" limited="true" range="-39.286729082169693 39.286729082169693"/>
                    <geom name="0/1/2/3/4/5/6/7/geom" class="0/1/2/3/4/5/6/7/" type="capsule" contype="1" conaffinity="1" condim="3" size="0.053827795241964529" rgba="0.6573658052691147 0.83478375517325187 0.16735445772531665 1" friction="0.59999999999999998 0.10000000000000001 0.10000000000000001" fromto="0 0 0 0.077020887396840987 0 0.34790470061934364"/>
                    <site name="0/1/2/3/4/5/6/7/end7" class="0/1/2/3/4/5/6/7/" size="0.0050000000000000001" pos="0.077020887396840987 0 0.34790470061934364"/>
                  </body>
                </body>
              </body>
            </body>
          </body>
          <site name="0/1/2/attach8" class="0/1/2/" size="9.9999999999999995e-07 9.9999999999999995e-07 9.9999999999999995e-07" pos="-0.027810557399544814 0 0.15036797770993493"/>
          <body pos="-0.027810557399544814 0 0.15036797770993493" name="0/1/2/8/">
            <joint name="0/1/2/8/joint/" class="0/1/2/" type="hinge" axis="0 1 0" limited="true" range="-69.700903047856073 69.700903047856073"/>
            <geom name="0/1/2/8/geom" class="0/1/2/8/" type="capsule" contype="1" conaffinity="1" condim="3" size="0.060371307674580758" rgba="0.41674571334303778 0.44733387765446775 0.25823776091978623 1" friction="0.59999999999999998 0.10000000000000001 0.10000000000000001" fromto="0 0 0 0.083764130228362044 0 0.090365028178273521"/>
            <site name="0/1/2/8/end8" class="0/1/2/8/" size="0.0050000000000000001" pos="0.083764130228362044 0 0.090365028178273521"/>
          </body>
        </body>
      </body>
      <camera name="0/side" class="0/" mode="trackcom" pos="0.40000000000000002 -4 0.20000000000000001" quat="0.70699999999999996 0.70699999999999996 0 0"/>
    </body>
  </worldbody>
  <actuator>
    <motor name="0/1/motor" class="0/1/" ctrllimited="true" ctrlrange="-1 1" gear="80" joint="0/1/joint/"/>
    <motor name="0/1/2/motor" class="0/1/2/" ctrllimited="true" ctrlrange="-1 1" gear="83" joint="0/1/2/joint/"/>
    <motor name="0/1/2/3/motor" class="0/1/2/3/" ctrllimited="true" ctrlrange="-1 1" gear="77" joint="0/1/2/3/joint/"/>
    <motor name="0/1/2/3/4/motor" class="0/1/2/3/4/" ctrllimited="true" ctrlrange="-1 1" gear="74" joint="0/1/2/3/4/joint/"/>
    <motor name="0/1/2/3/4/5/6/motor" class="0/1/2/3/4/5/6/" ctrllimited="true" ctrlrange="-1 1" gear="74" joint="0/1/2/3/4/5/6/joint/"/>
    <motor name="0/1/2/3/4/5/6/7/motor" class="0/1/2/3/4/5/6/7/" ctrllimited="true" ctrlrange="-1 1" gear="60" joint="0/1/2/3/4/5/6/7/joint/"/>
    <motor name="0/1/2/8/motor" class="0/1/2/8/" ctrllimited="true" ctrlrange="-1 1" gear="50" joint="0/1/2/8/joint/"/>
  </actuator>
  <sensor>
    <subtreelinvel name="velocity" body="0/"/>
  </sensor>
</mujoco>
