<mujoco model="morphology">
  <option timestep="0.01"/>
  <default>
    <default class="/"/>
    <default class="0/"/>
    <default class="0/1/"/>
    <default class="0/1/2/"/>
    <default class="0/1/2/3/"/>
    <default class="0/1/2/3/4/"/>
    <default class="0/5/"/>
    <default class="0/5/6/"/>
    <default class="0/5/7/"/>
    <default class="0/5/7/8/"/>
    <default class="0/5/7/9/"/>
  </default>
  <asset>
    <texture name="texplane" type="2d" builtin="checker" rgb1="0.10000000000000001 0.20000000000000001 0.29999999999999999" rgb2="0.20000000000000001 0.29999999999999999 0.40000000000000002" width="300" height="300"/>
    <material name="MatPlane" class="/" texture="texplane" texrepeat="20 20" specular="1" shininess="1" reflectance="0.5"/>
  </asset>
  <worldbody>
    <light name="//unnamed_light_0" class="/" directional="true" pos="0 0 1.5" dir="0 0 -1.3" cutoff="100" exponent="1" diffuse="1 1 1" specular="0.10000000000000001 0.10000000000000001 0.10000000000000001"/>
    <geom name="ground" class="/" type="plane" size="15 15 0.5" material="MatPlane" rgba="1 1 1 1"/>
    <site name="body" class="/" size="9.9999999999999995e-07 9.9999999999999995e-07 9.9999999999999995e-07" pos="0 0 0.41095951795578001"/>
    <body pos="0 0 0.41095951795578001" name="0/">
      <joint name="0/rootx/" class="/" type="slide" axis="1 0 0" limited="false" stiffness="0" armature="0" damping="0"/>
      <joint name="0/rootz/" class="/" type="slide" axis="0 0 1" limited="false" stiffness="0" armature="0" damping="0"/>
      <joint name="0/rooty/" class="/" type="hinge" axis="0 1 0" limited="false" stiffness="0" armature="0" damping="0"/>
      <geom name="0/geom" class="0/" type="capsule" contype="1" conaffinity="1" condim="3" size="0.062956500481664665" rgba="0.14113276358911919 0.93089905258874517 0.76350924336121073 1" friction="0.59999999999999998 0.10000000000000001 0.10000000000000001" fromto="0 0 0 -0.74456022781224074 0 0.66722961272208714"/>
      <site name="0/end0" class="0/" size="0.0050000000000000001" pos="-0.74456022781224074 0 0.66722961272208714"/>
      <site name="0/attach1" class="0/" size="9.9999999999999995e-07 9.9999999999999995e-07 9.9999999999999995e-07" pos="-0.13861695404890692 0 0.12422008739109147"/>
      <body pos="-0.13861695404890692 0 0.12422008739109147" name="0/1/">
        <joint name="0/1/joint/" class="0/" type="hinge" axis="0 1 0" limited="true" range="-69.483749315230654 69.483749315230654"/>
        <geom name="0/1/geom" class="0/1/" type="capsule" contype="1" conaffinity="1" condim="3" size="0.05043938425670335" rgba="0.13326937277816187 0.4118402598487183 0.095656662221314637 1" friction="0.59999999999999998 0.10000000000000001 0.10000000000000001" fromto="0 0 0 0.31608144088195989 0 0.043691357026150235"/>
        <site name="0/1/end1" class="0/1/" size="0.0050000000000000001" pos="0.31608144088195989 0 0.043691357026150235"/>
        <site name="0/1/attach2" class="0/1/" size="9.9999999999999995e-07 9.9999999999999995e-07 9.9999999999999995e-07" pos="0.29413654741688255 0 0.040657954708670958"/>
        <body pos="0.29413654741688255 0 0.040657954708670958" name="0/1/2/">
          <joint name="0/1/2/joint/" class="0/1/" type="hinge" axis="0 1 0" limited="true" range="-46.087578845522337 46.087578845522337"/>
          <geom name="0/1/2/geom" class="0/1/2/" type="capsule" contype="1" conaffinity="1" condim="3" size="0.067539475685437778" rgba="0.33038472623242643 0.54258951318476056 0.027749723382355151 1" friction="0.59999999999999998 0.10000000000000001 0.10000000000000001" fromto="0 0 0 0.42060808590088183 0 -0.47583756441670844"/>
          <site name="0/1/2/end2" class="0/1/2/" size="0.0050000000000000001" pos="0.42060808590088183 0 -0.47583756441670844"/>
          <site name="0/1/2/attach3" class="0/1/2/" size="9.9999999999999995e-07 9.9999999999999995e-07 9.9999999999999995e-07" pos="0.14672000902209775 0 -0.16598561483842864"/>
          <body pos="0.14672000902209775 0 -0.16598561483842864" name="0/1/2/3/">
            <geom name="0/1/2/3/geom" class="0/1/2/3/" type="capsule" contype="1" conaffinity="1" condim="3" size="0.051471744362881544" rgba="0.11895930715346126 0.037078763212451848 0.77756299366759907 1" friction="0.59999999999999998 0.10000000000000001 0.10000000000000001" fromto="0 0 0 0.7488762877547126 0 0.58058487383785207"/>
            <site name="0/1/2/3/end3" class="0/1/2/3/" size="0.0050000000000000001" pos="0.7488762877547126 0 0.58058487383785207"/>
            <site name="0/1/2/3/attach4" class="0/1/2/3/" size="9.9999999999999995e-07 9.9999999999999995e-07 9.9999999999999995e-07" pos="0.68835283822233773 0 0.53366257186947286"/>
            <body pos="0.68835283822233773 0 0.53366257186947286" name="0/1/2/3/4/">
              <joint name="0/1/2/3/4/joint/" class="0/1/2/3/" type="hinge" axis="0 1 0" limited="true" range="-58.316595413610948 58.316595413610948"/>
              <geom name="0/1/2/3/4/geom" class="0/1/2/3/4/" type="capsule" contype="1" conaffinity="1" condim="3" size="0.06802640457381734" rgba="0.41581900036230846 0.57206715845312039 0.14804160619001394 1" friction="0.59999999999999998 0.10000000000000001 0.10000000000000001" fromto="0 0 0 -0.69509185748097968 0 0.2158043833467953"/>
              <site name="0/1/2/3/4/end4" class="0/1/2/3/4/" size="0.0050000000000000001" pos="-0.69509185748097968 0 0.2158043833467953"/>
            </body>
          </body>
        </body>
      </body>
      <site name="0/attach5" class="0/" size="9.9999999999999995e-07 9.9999999999999995e-07 9.9999999999999995e-07" pos="-0.7300437467174532 0 0.65422082485354538"/>
      <body pos="-0.7300437467174532 0 0.65422082485354538" name="0/5/">
        <joint name="0/5/joint/" class="0/" type="hinge" axis="0 1 0" limited="true" range="-45.287361015347216 45.287361015347216"/>
        <geom name="0/5/geom" class="0/5/" type="capsule" contype="1" conaffinity="1" condim="3" size="0.04065705984360786" rgba="0.066923739370816082 0.15423892872766465 0.61068678557843459 1" friction="0.59999999999999998 0.10000000000000001 0.10000000000000001" fromto="0 0 0 0.23340034871429105 0 0.73174038397981533"/>
        <site name="0/5/end5" class="0/5/" size="0.0050000000000000001" pos="0.23340034871429105 0 0.73174038397981533"/>
        <site name="0/5/attach6" class="0/5/" size="9.9999999999999995e-07 9.9999999999999995e-07 9.9999999999999995e-07" pos="0.13739510875244282 0 0.43075149711335931"/>
        <body pos="0.13739510875244282 0 0.43075149711335931" name="0/5/6/">
          <joint name="0/5/6/joint/" class="0/5/" type="hinge" axis="0 1 0" limited="true" range="-34.045308597937812 34.045308597937812"/>
          <geom name="0/5/6/geom" class="0/5/6/" type="capsule" contype="1" conaffinity="1" condim="3" size="0.046752838327639122" rgba="0.56820923546314139 0.59248051290726622 0.080254539839291206 1" friction="0.59999999999999998 0.10000000000000001 0.10000000000000001" fromto="0 0 0 0.55736000341652114 0 -0.24630869909613184"/>
          <site name="0/5/6/end6" class="0/5/6/" size="0.0050000000000000001" pos="0.55736000341652114 0 -0.24630869909613184"/>
        </body>
        <site name="0/5/attach7" class="0/5/" size="9.9999999999999995e-07 9.9999999999999995e-07 9.9999999999999995e-07" pos="0.12109053771947906 0 0.37963455091337034"/>
        <body pos="0.12109053771947906 0 0.37963455091337034" name="0/5/7/">
          <joint name="0/5/7/joint/" class="0/5/" type="hinge" axis="0 1 0" limited="true" range="-35.403142510036936 35.403142510036936"/>
          <geom name="0/5/7/geom" class="0/5/7/" type="capsule" contype="1" conaffinity="1" condim="3" size="0.044941510514618879" rgba="0.24830036521526155 0.46287274864493766 0.37863077082575791 1" friction="0.59999999999999998 0.10000000000000001 0.10000000000000001" fromto="0 0 0 -0.55057936925341533 0 0.30423180972152997"/>
          <site name="0/5/7/end7" class="0/5/7/" size="0.0050000000000000001" pos="-0.55057936925341533 0 0.30423180972152997"/>
          <site name="0/5/7/attach8" class="0/5/7/" size="9.9999999999999995e-07 9.9999999999999995e-07 9.9999999999999995e-07" pos="-0.43587138116708196 0 0.24084799849674271"/>
          <body pos="-0.43587138116708196 0 0.24084799849674271" name="0/5/7/8/">
            <joint name="0/5/7/8/joint/" class="0/5/7/" type="hinge" axis="0 1 0" limited="true" range="-39.06052761185169 39.06052761185169"/>
            <geom name="0/5/7/8/geom" class="0/5/7/8/" type="capsule" contype="1" conaffinity="1" condim="3" size="0.068438861889555294" rgba="0.48609404842897019 0.33447265958086114 0.09291461776012333 1" friction="0.59999999999999998 0.10000000000000001 0.10000000000000001" fromto="0 0 0 -0.091235284509122883 0 -0.74386201670365049"/>
            <site name="0/5/7/8/end8" class="0/5/7/8/" size="0.0050000000000000001" pos="-0.091235284509122883 0 -0.74386201670365049"/>
          </body>
          <site name="0/5/7/attach9" class="0/5/7/" size="9.9999999999999995e-07 9.9999999999999995e-07 9.9999999999999995e-07" pos="-0.21871885980306752 0 0.12085675245759139"/>
          <body pos="-0.21871885980306752 0 0.12085675245759139" name="0/5/7/9/">
            <joint name="0/5/7/9/joint/" class="0/5/7/" type="hinge" axis="0 1 0" limited="true" range="-60.192491868866256 60.192491868866256"/>
            <geom name="0/5/7/9/geom" class="0/5/7/9/" type="capsule" contype="1" conaffinity="1" condim="3" size="0.061325738251511677" rgba="0.72216500143359108 0.52905607885697092 0.96733401266308006 1" friction="0.59999999999999998 0.10000000000000001 0.10000000000000001" fromto="0 0 0 -0.030817839511678269 0 0.58221652868647378"/>
            <site name="0/5/7/9/end9" class="0/5/7/9/" size="0.0050000000000000001" pos="-0.030817839511678269 0 0.58221652868647378"/>
          </body>
        </body>
      </body>
      <camera name="0/side" class="0/" mode="trackcom" pos="0.40000000000000002 -4 0.20000000000000001" quat="0.70699999999999996 0.70699999999999996 0 0"/>
    </body>
  </worldbody>
  <actuator>
    <motor name="0/1/motor" class="0/1/" ctrllimited="true" ctrlrange="-1 1" gear="50" joint="0/1/joint/"/>
    <motor name="0/1/2/motor" class="0/1/2/" ctrllimited="true" ctrlrange="-1 1" gear="50" joint="0/1/2/joint/"/>
    <motor name="0/1/2/3/4/motor" class="0/1/2/3/4/" ctrllimited="true" ctrlrange="-1 1" gear="78" joint="0/1/2/3/4/joint/"/>
    <motor name="0/5/motor" class="0/5/" ctrllimited="true" ctrlrange="-1 1" gear="67" joint="0/5/joint/"/>
    <motor name="0/5/6/motor" class="0/5/6/" ctrllimited="true" ctrlrange="-1 1" gear="77" joint="0/5/6/joint/"/>
    <motor name="0/5/7/motor" class="0/5/7/" ctrllimited="true" ctrlrange="-1 1" gear="73" joint="0/5/7/joint/"/>
    <motor name="0/5/7/8/motor" class="0/5/7/8/" ctrllimited="true" ctrlrange="-1 1" gear="86" joint="0/5/7/8/joint/"/>
    <motor name="0/5/7/9/motor" class="0/5/7/9/" ctrllimited="true" ctrlrange="-1 1" gear="56" joint="0/5/7/9/joint/"/>
  </actuator>
  <sensor>
    <subtreelinvel name="velocity" body="0/"/>
  </sensor>
</mujoco>
