<mujoco model="morphology">
  <option timestep="0.01"/>
  <default>
    <default class="/"/>
    <default class="0/"/>
    <default class="0/1/"/>
    <default class="0/1/2/"/>
    <default class="0/1/2/3/"/>
    <default class="0/1/2/3/4/"/>
    <default class="0/1/2/5/"/>
  </default>
  <asset>
    <texture name="texplane" type="2d" builtin="checker" rgb1="0.10000000000000001 0.20000000000000001 0.29999999999999999" rgb2="0.20000000000000001 0.29999999999999999 0.40000000000000002" width="300" height="300"/>
    <material name="MatPlane" class="/" texture="texplane" texrepeat="20 20" specular="1" shininess="1" reflectance="0.5"/>
  </asset>
  <worldbody>
    <light name="//unnamed_light_0" class="/" directional="true" pos="0 0 1.5" dir="0 0 -1.3" cutoff="100" exponent="1" diffuse="1 1 1" specular="0.10000000000000001 0.10000000000000001 0.10000000000000001"/>
    <geom name="ground" class="/" type="plane" size="15 15 0.5" material="MatPlane" rgba="1 1 1 1"/>
    <site name="body" class="/" size="9.9999999999999995e-07 9.9999999999999995e-07 9.9999999999999995e-07" pos="0 0 1.0528294205665589"/>
    <body pos="0 0 1.0528294205665589" name="0/">
      <joint name="0/rootx/" class="/" type="slide" axis="1 0 0" limited="false" stiffness="0" armature="0" damping="0"/>
      <joint name="0/rootz/" class="/" type="slide" axis="0 0 1" limited="false" stiffness="0" armature="0" damping="0"/>
      <joint name="0/rooty/" class="/" type="hinge" axis="0 1 0" limited="false" stiffness="0" armature="0" damping="0"/>
      <geom name="0/geom" class="0/" type="capsule" contype="1" conaffinity="1" condim="3" size="0.064933431837231728" rgba="0.40451412237440276 0.7933401636620111 0.46355108110684984 1" friction="0.59999999999999998 0.10000000000000001 0.10000000000000001" fromto="0 0 0 0.66131539441467702 0 -0.59153030300634146"/>
      <site name="0/end0" class="0/" size="0.0050000000000000001" pos="0.66131539441467702 0 -0.59153030300634146"/>
      <site name="0/attach1" class="0/" size="9.9999999999999995e-07 9.9999999999999995e-07 9.9999999999999995e-07" pos="0.53620750576916698 0 -0.47962438352526954"/>
      <body pos="0.53620750576916698 0 -0.47962438352526954" name="0/1/">
        <joint name="0/1/joint/" class="0/" type="hinge" axis="0 1 0" limited="true" range="-48.51632752695977 48.51632752695977"/>
        <geom name="0/1/geom" class="0/1/" type="capsule" contype="1" conaffinity="1" condim="3" size="0.04268731164035483" rgba="0.6361895902623228 0.47471312761309803 0.62476002800192576 1" friction="0.59999999999999998 0.10000000000000001 0.10000000000000001" fromto="0 0 0 0.24972810969869752 0 0.72474199520464211"/>
        <site name="0/1/end1" class="0/1/" size="0.0050000000000000001" pos="0.24972810969869752 0 0.72474199520464211"/>
        <site name="0/1/attach2" class="0/1/" size="9.9999999999999995e-07 9.9999999999999995e-07 9.9999999999999995e-07" pos="0.088442652092786539 0 0.2566715625896176"/>
        <body pos="0.088442652092786539 0 0.2566715625896176" name="0/1/2/">
          <joint name="0/1/2/joint/" class="0/1/" type="hinge" axis="0 1 0" limited="true" range="-65.575108095705588 65.575108095705588"/>
          <geom name="0/1/2/geom" class="0/1/2/" type="capsule" contype="1" conaffinity="1" condim="3" size="0.059399738438364894" rgba="0.65363084016938355 0.28218649044519606 0.87795565734381709 1" friction="0.59999999999999998 0.10000000000000001 0.10000000000000001" fromto="0 0 0 0.42120202079192004 0 -0.029341869036348389"/>
          <site name="0/1/2/end2" class="0/1/2/" size="0.0050000000000000001" pos="0.42120202079192004 0 -0.029341869036348389"/>
          <site name="0/1/2/attach3" class="0/1/2/" size="9.9999999999999995e-07 9.9999999999999995e-07 9.9999999999999995e-07" pos="0.2035939474933795 0 -0.01418280694074611"/>
          <body pos="0.2035939474933795 0 -0.01418280694074611" name="0/1/2/3/">
            <joint name="0/1/2/3/joint/" class="0/1/2/" type="hinge" axis="0 1 0" limited="true" range="-52.122163631646409 52.122163631646409"/>
            <geom name="0/1/2/3/geom" class="0/1/2/3/" type="capsule" contype="1" conaffinity="1" condim="3" size="0.056247348096820984" rgba="0.91073349809683513 0.36706953799518116 0.49360315157093326 1" friction="0.59999999999999998 0.10000000000000001 0.10000000000000001" fromto="0 0 0 -0.10028887614830295 0 -0.71569381870699411"/>
            <site name="0/1/2/3/end3" class="0/1/2/3/" size="0.0050000000000000001" pos="-0.10028887614830295 0 -0.71569381870699411"/>
            <site name="0/1/2/3/attach4" class="0/1/2/3/" size="9.9999999999999995e-07 9.9999999999999995e-07 9.9999999999999995e-07" pos="-0.015930932176793318 0 -0.11368827853161928"/>
            <body pos="-0.015930932176793318 0 -0.11368827853161928" name="0/1/2/3/4/">
              <joint name="0/1/2/3/4/joint/" class="0/1/2/3/" type="hinge" axis="0 1 0" limited="true" range="-60.801156700657458 60.801156700657458"/>
              <geom name="0/1/2/3/4/geom" class="0/1/2/3/4/" type="capsule" contype="1" conaffinity="1" condim="3" size="0.051475669159917595" rgba="0.33428960440387645 0.86198441785107294 0.5377508419583481 1" friction="0.59999999999999998 0.10000000000000001 0.10000000000000001" fromto="0 0 0 -0.10107952046332014 0 -0.037627643464793414"/>
              <site name="0/1/2/3/4/end4" class="0/1/2/3/4/" size="0.0050000000000000001" pos="-0.10107952046332014 0 -0.037627643464793414"/>
            </body>
          </body>
          <site name="0/1/2/attach5" class="0/1/2/" size="9.9999999999999995e-07 9.9999999999999995e-07 9.9999999999999995e-07" pos="0.30168351221123879 0 -0.021015944057164854"/>
          <body pos="0.30168351221123879 0 -0.021015944057164854" name="0/1/2/5/">
            <geom name="0/1/2/5/geom" class="0/1/2/5/" type="capsule" contype="1" conaffinity="1" condim="3" size="0.064212678252453415" rgba="0.65305296741800745 0.97895022974972801 0.80826019498800672 1" friction="0.59999999999999998 0.10000000000000001 0.10000000000000001" fromto="0 0 0 0.4941169366692042 0 -0.68227659875708901"/>
            <site name="0/1/2/5/end5" class="0/1/2/5/" size="0.0050000000000000001" pos="0.4941169366692042 0 -0.68227659875708901"/>
          </body>
        </body>
      </body>
      <camera name="0/side" class="0/" mode="trackcom" pos="0.40000000000000002 -4 0.20000000000000001" quat="0.70699999999999996 0.70699999999999996 0 0"/>
    </body>
  </worldbody>
  <actuator>
    <motor name="0/1/motor" class="0/1/" ctrllimited="true" ctrlrange="-1 1" gear="76" joint="0/1/joint/"/>
    <motor name="0/1/2/motor" class="0/1/2/" ctrllimited="true" ctrlrange="-1 1" gear="51" joint="0/1/2/joint/"/>
    <motor name="0/1/2/3/motor" class="0/1/2/3/" ctrllimited="true" ctrlrange="-1 1" gear="67" joint="0/1/2/3/joint/"/>
    <motor name="0/1/2/3/4/motor" class="0/1/2/3/4/" ctrllimited="true" ctrlrange="-1 1" gear="57" joint="0/1/2/3/4/joint/"/>
  </actuator>
  <sensor>
    <subtreelinvel name="velocity" body="0/"/>
  </sensor>
</mujoco>
