<mujoco model="morphology">
  <option timestep="0.01"/>
  <default>
    <default class="/"/>
    <default class="0/"/>
    <default class="0/1/"/>
    <default class="0/1/2/"/>
    <default class="0/1/2/3/"/>
    <default class="0/4/"/>
    <default class="0/4/5/"/>
  </default>
  <asset>
    <texture name="texplane" type="2d" builtin="checker" rgb1="0.10000000000000001 0.20000000000000001 0.29999999999999999" rgb2="0.20000000000000001 0.29999999999999999 0.40000000000000002" width="300" height="300"/>
    <material name="MatPlane" class="/" texture="texplane" texrepeat="20 20" specular="1" shininess="1" reflectance="0.5"/>
  </asset>
  <worldbody>
    <light name="//unnamed_light_0" class="/" directional="true" pos="0 0 1.5" dir="0 0 -1.3" cutoff="100" exponent="1" diffuse="1 1 1" specular="0.10000000000000001 0.10000000000000001 0.10000000000000001"/>
    <geom name="ground" class="/" type="plane" size="15 15 0.5" material="MatPlane" rgba="1 1 1 1"/>
    <site name="body" class="/" size="9.9999999999999995e-07 9.9999999999999995e-07 9.9999999999999995e-07" pos="0 0 1.4242336511611939"/>
    <body pos="0 0 1.4242336511611939" name="0/">
      <joint name="0/rootx/" class="/" type="slide" axis="1 0 0" limited="false" stiffness="0" armature="0" damping="0"/>
      <joint name="0/rootz/" class="/" type="slide" axis="0 0 1" limited="false" stiffness="0" armature="0" damping="0"/>
      <joint name="0/rooty/" class="/" type="hinge" axis="0 1 0" limited="false" stiffness="0" armature="0" damping="0"/>
      <geom name="0/geom" class="0/" type="capsule" contype="1" conaffinity="1" condim="3" size="0.050672379727607089" rgba="0.058918991794279285 0.92084089827150728 0.69351280088633893 1" friction="0.59999999999999998 0.10000000000000001 0.10000000000000001" fromto="0 0 0 0.35335944028682031 0 -0.59129672343940443"/>
      <site name="0/end0" class="0/" size="0.0050000000000000001" pos="0.35335944028682031 0 -0.59129672343940443"/>
      <site name="0/attach1" class="0/" size="9.9999999999999995e-07 9.9999999999999995e-07 9.9999999999999995e-07" pos="0.25343414434371558 0 -0.42408596480816146"/>
      <body pos="0.25343414434371558 0 -0.42408596480816146" name="0/1/">
        <joint name="0/1/joint/" class="0/" type="hinge" axis="0 1 0" limited="true" range="-65.072945163803354 65.072945163803354"/>
        <geom name="0/1/geom" class="0/1/" type="capsule" contype="1" conaffinity="1" condim="3" size="0.050531108349885195" rgba="0.61166137033804291 0.35940432947505063 0.75309664630843098 1" friction="0.59999999999999998 0.10000000000000001 0.10000000000000001" fromto="0 0 0 0.41360378550304366 0 0.36139658908386862"/>
        <site name="0/1/end1" class="0/1/" size="0.0050000000000000001" pos="0.41360378550304366 0 0.36139658908386862"/>
        <site name="0/1/attach2" class="0/1/" size="9.9999999999999995e-07 9.9999999999999995e-07 9.9999999999999995e-07" pos="0.058062082983117921 0 0.050733188333086314"/>
        <body pos="0.058062082983117921 0 0.050733188333086314" name="0/1/2/">
          <geom name="0/1/2/geom" class="0/1/2/" type="capsule" contype="1" conaffinity="1" condim="3" size="0.049905461061261397" rgba="0.3970989589673829 0.34666348335602426 0.67480148796394201 1" friction="0.59999999999999998 0.10000000000000001 0.10000000000000001" fromto="0 0 0 0.49749825363829769 0 -0.32612866003833213"/>
          <site name="0/1/2/end2" class="0/1/2/" size="0.0050000000000000001" pos="0.49749825363829769 0 -0.32612866003833213"/>
          <site name="0/1/2/attach3" class="0/1/2/" size="9.9999999999999995e-07 9.9999999999999995e-07 9.9999999999999995e-07" pos="0.37348979889220579 0 -0.2448364929121121"/>
          <body pos="0.37348979889220579 0 -0.2448364929121121" name="0/1/2/3/">
            <joint name="0/1/2/3/joint/" class="0/1/2/" type="hinge" axis="0 1 0" limited="true" range="-36.886214614608264 36.886214614608264"/>
            <geom name="0/1/2/3/geom" class="0/1/2/3/" type="capsule" contype="1" conaffinity="1" condim="3" size="0.050223008176781582" rgba="0.1468863482166104 0.57040746132776365 0.041561304170497526 1" friction="0.59999999999999998 0.10000000000000001 0.10000000000000001" fromto="0 0 0 -0.69495724233120071 0 -0.706044437527792"/>
            <site name="0/1/2/3/end3" class="0/1/2/3/" size="0.0050000000000000001" pos="-0.69495724233120071 0 -0.706044437527792"/>
          </body>
        </body>
      </body>
      <site name="0/attach4" class="0/" size="9.9999999999999995e-07 9.9999999999999995e-07 9.9999999999999995e-07" pos="0.15073679787330954 0 -0.252236574214316"/>
      <body pos="0.15073679787330954 0 -0.252236574214316" name="0/4/">
        <joint name="0/4/joint/" class="0/" type="hinge" axis="0 1 0" limited="true" range="-44.508371605768048 44.508371605768048"/>
        <geom name="0/4/geom" class="0/4/" type="capsule" contype="1" conaffinity="1" condim="3" size="0.045735345398609836" rgba="0.67485110786673952 0.48916489345184722 0.31825720437791227 1" friction="0.59999999999999998 0.10000000000000001 0.10000000000000001" fromto="0 0 0 0.17008191918056426 0 0.54639769943560523"/>
        <site name="0/4/end4" class="0/4/" size="0.0050000000000000001" pos="0.17008191918056426 0 0.54639769943560523"/>
        <site name="0/4/attach5" class="0/4/" size="9.9999999999999995e-07 9.9999999999999995e-07 9.9999999999999995e-07" pos="0.16316732419369812 0 0.52418417543755069"/>
        <body pos="0.16316732419369812 0 0.52418417543755069" name="0/4/5/">
          <joint name="0/4/5/joint/" class="0/4/" type="hinge" axis="0 1 0" limited="true" range="-69.960277748799399 69.960277748799399"/>
          <geom name="0/4/5/geom" class="0/4/5/" type="capsule" contype="1" conaffinity="1" condim="3" size="0.04411158379478005" rgba="0.1841853431259437 0.82301076309577414 0.38513751017669395 1" friction="0.59999999999999998 0.10000000000000001 0.10000000000000001" fromto="0 0 0 -0.70083593652173681 0 0.70631539143920419"/>
          <site name="0/4/5/end5" class="0/4/5/" size="0.0050000000000000001" pos="-0.70083593652173681 0 0.70631539143920419"/>
        </body>
      </body>
      <camera name="0/side" class="0/" mode="trackcom" pos="0.40000000000000002 -4 0.20000000000000001" quat="0.70699999999999996 0.70699999999999996 0 0"/>
    </body>
  </worldbody>
  <actuator>
    <motor name="0/1/motor" class="0/1/" ctrllimited="true" ctrlrange="-1 1" gear="64" joint="0/1/joint/"/>
    <motor name="0/1/2/3/motor" class="0/1/2/3/" ctrllimited="true" ctrlrange="-1 1" gear="87" joint="0/1/2/3/joint/"/>
    <motor name="0/4/motor" class="0/4/" ctrllimited="true" ctrlrange="-1 1" gear="61" joint="0/4/joint/"/>
    <motor name="0/4/5/motor" class="0/4/5/" ctrllimited="true" ctrlrange="-1 1" gear="82" joint="0/4/5/joint/"/>
  </actuator>
  <sensor>
    <subtreelinvel name="velocity" body="0/"/>
  </sensor>
</mujoco>
