<mujoco model="morphology">
  <option timestep="0.01"/>
  <default>
    <default class="/"/>
    <default class="0/"/>
    <default class="0/1/"/>
    <default class="0/1/2/"/>
    <default class="0/1/2/3/"/>
    <default class="0/1/2/4/"/>
    <default class="0/1/2/4/5/"/>
    <default class="0/1/2/4/5/6/"/>
    <default class="0/1/2/4/7/"/>
    <default class="0/8/"/>
    <default class="0/8/9/"/>
    <default class="0/8/9/10/"/>
  </default>
  <asset>
    <texture name="texplane" type="2d" builtin="checker" rgb1="0.10000000000000001 0.20000000000000001 0.29999999999999999" rgb2="0.20000000000000001 0.29999999999999999 0.40000000000000002" width="300" height="300"/>
    <material name="MatPlane" class="/" texture="texplane" texrepeat="20 20" specular="1" shininess="1" reflectance="0.5"/>
  </asset>
  <worldbody>
    <light name="//unnamed_light_0" class="/" directional="true" pos="0 0 1.5" dir="0 0 -1.3" cutoff="100" exponent="1" diffuse="1 1 1" specular="0.10000000000000001 0.10000000000000001 0.10000000000000001"/>
    <geom name="ground" class="/" type="plane" size="15 15 0.5" material="MatPlane" rgba="1 1 1 1"/>
    <site name="body" class="/" size="9.9999999999999995e-07 9.9999999999999995e-07 9.9999999999999995e-07" pos="0 0 1.2290807723999024"/>
    <body pos="0 0 1.2290807723999024" name="0/">
      <joint name="0/rootx/" class="/" type="slide" axis="1 0 0" limited="false" stiffness="0" armature="0" damping="0"/>
      <joint name="0/rootz/" class="/" type="slide" axis="0 0 1" limited="false" stiffness="0" armature="0" damping="0"/>
      <joint name="0/rooty/" class="/" type="hinge" axis="0 1 0" limited="false" stiffness="0" armature="0" damping="0"/>
      <geom name="0/geom" class="0/" type="capsule" contype="1" conaffinity="1" condim="3" size="0.048319554319540423" rgba="0.35576779238556178 0.72595017126344241 0.084409259810621529 1" friction="0.59999999999999998 0.10000000000000001 0.10000000000000001" fromto="0 0 0 -0.67901038469300068 0 -0.013148302453991567"/>
      <site name="0/end0" class="0/" size="0.0050000000000000001" pos="-0.67901038469300068 0 -0.013148302453991567"/>
      <site name="0/attach1" class="0/" size="9.9999999999999995e-07 9.9999999999999995e-07 9.9999999999999995e-07" pos="-0.083013045064329785 0 -0.0016074579251481233"/>
      <body pos="-0.083013045064329785 0 -0.0016074579251481233" name="0/1/">
        <geom name="0/1/geom" class="0/1/" type="capsule" contype="1" conaffinity="1" condim="3" size="0.050321376603639834" rgba="0.50986025282590974 0.9011389572687305 0.10339937053028847 1" friction="0.59999999999999998 0.10000000000000001 0.10000000000000001" fromto="0 0 0 0.12706588623334947 0 0.31361958927818678"/>
        <site name="0/1/end1" class="0/1/" size="0.0050000000000000001" pos="0.12706588623334947 0 0.31361958927818678"/>
        <site name="0/1/attach2" class="0/1/" size="9.9999999999999995e-07 9.9999999999999995e-07 9.9999999999999995e-07" pos="0.088313423870626309 0 0.2179721130752007"/>
        <body pos="0.088313423870626309 0 0.2179721130752007" name="0/1/2/">
          <joint name="0/1/2/joint/" class="0/1/" type="hinge" axis="0 1 0" limited="true" range="-53.446397081931188 53.446397081931188"/>
          <geom name="0/1/2/geom" class="0/1/2/" type="capsule" contype="1" conaffinity="1" condim="3" size="0.057435612012338919" rgba="0.74162066372640223 0.6874353247544629 0.1993417120017914 1" friction="0.59999999999999998 0.10000000000000001 0.10000000000000001" fromto="0 0 0 -0.35144873465990556 0 -0.13883899029156277"/>
          <site name="0/1/2/end2" class="0/1/2/" size="0.0050000000000000001" pos="-0.35144873465990556 0 -0.13883899029156277"/>
          <site name="0/1/2/attach3" class="0/1/2/" size="9.9999999999999995e-07 9.9999999999999995e-07 9.9999999999999995e-07" pos="-0.07970033426210979 0 -0.031485428295991415"/>
          <body pos="-0.07970033426210979 0 -0.031485428295991415" name="0/1/2/3/">
            <joint name="0/1/2/3/joint/" class="0/1/2/" type="hinge" axis="0 1 0" limited="true" range="-39.154495988855018 39.154495988855018"/>
            <geom name="0/1/2/3/geom" class="0/1/2/3/" type="capsule" contype="1" conaffinity="1" condim="3" size="0.044028028088819365" rgba="0.01482074405790812 0.6141069538759647 0.72888427348315243 1" friction="0.59999999999999998 0.10000000000000001 0.10000000000000001" fromto="0 0 0 -0.51469566091637708 0 0.59634295035730478"/>
            <site name="0/1/2/3/end3" class="0/1/2/3/" size="0.0050000000000000001" pos="-0.51469566091637708 0 0.59634295035730478"/>
          </body>
          <site name="0/1/2/attach4" class="0/1/2/" size="9.9999999999999995e-07 9.9999999999999995e-07 9.9999999999999995e-07" pos="-0.2142719543974243 0 -0.084647628124558089"/>
          <body pos="-0.2142719543974243 0 -0.084647628124558089" name="0/1/2/4/">
            <joint name="0/1/2/4/joint/" class="0/1/2/" type="hinge" axis="0 1 0" limited="true" range="-61.657352606252488 61.657352606252488"/>
            <geom name="0/1/2/4/geom" class="0/1/2/4/" type="capsule" contype="1" conaffinity="1" condim="3" size="0.068294231781972317" rgba="0.061303316188581869 0.98516712038563803 0.5906870361150911 1" friction="0.59999999999999998 0.10000000000000001 0.10000000000000001" fromto="0 0 0 -0.43467459664422015 0 0.50751606612288169"/>
            <site name="0/1/2/4/end4" class="0/1/2/4/" size="0.0050000000000000001" pos="-0.43467459664422015 0 0.50751606612288169"/>
            <site name="0/1/2/4/attach5" class="0/1/2/4/" size="9.9999999999999995e-07 9.9999999999999995e-07 9.9999999999999995e-07" pos="-0.43363315717004181 0 0.50630010533492542"/>
            <body pos="-0.43363315717004181 0 0.50630010533492542" name="0/1/2/4/5/">
              <joint name="0/1/2/4/5/joint/" class="0/1/2/4/" type="hinge" axis="0 1 0" limited="true" range="-33.993774893783929 33.993774893783929"/>
              <geom name="0/1/2/4/5/geom" class="0/1/2/4/5/" type="capsule" contype="1" conaffinity="1" condim="3" size="0.042666226415282969" rgba="0.29684240615926771 0.96625486527423798 0.32562907885267978 1" friction="0.59999999999999998 0.10000000000000001 0.10000000000000001" fromto="0 0 0 -0.2365970259354796 0 0.17454384920347932"/>
              <site name="0/1/2/4/5/end5" class="0/1/2/4/5/" size="0.0050000000000000001" pos="-0.2365970259354796 0 0.17454384920347932"/>
              <site name="0/1/2/4/5/attach6" class="0/1/2/4/5/" size="9.9999999999999995e-07 9.9999999999999995e-07 9.9999999999999995e-07" pos="-0.20737046482984894 0 0.15298264633464609"/>
              <body pos="-0.20737046482984894 0 0.15298264633464609" name="0/1/2/4/5/6/">
                <joint name="0/1/2/4/5/6/joint/" class="0/1/2/4/5/" type="hinge" axis="0 1 0" limited="true" range="-62.115795025787804 62.115795025787804"/>
                <geom name="0/1/2/4/5/6/geom" class="0/1/2/4/5/6/" type="capsule" contype="1" conaffinity="1" condim="3" size="0.048385690586880123" rgba="0.37816165489381837 0.23618716301444187 0.41188367350100319 1" friction="0.59999999999999998 0.10000000000000001 0.10000000000000001" fromto="0 0 0 -0.41476974845829645 0 -0.41768330315242408"/>
                <site name="0/1/2/4/5/6/end6" class="0/1/2/4/5/6/" size="0.0050000000000000001" pos="-0.41476974845829645 0 -0.41768330315242408"/>
              </body>
            </body>
            <site name="0/1/2/4/attach7" class="0/1/2/4/" size="9.9999999999999995e-07 9.9999999999999995e-07 9.9999999999999995e-07" pos="-0.12253175890061482 0 0.14306526475771295"/>
            <body pos="-0.12253175890061482 0 0.14306526475771295" name="0/1/2/4/7/">
              <joint name="0/1/2/4/7/joint/" class="0/1/2/4/" type="hinge" axis="0 1 0" limited="true" range="-50.421079630648954 50.421079630648954"/>
              <geom name="0/1/2/4/7/geom" class="0/1/2/4/7/" type="capsule" contype="1" conaffinity="1" condim="3" size="0.048786231812676509" rgba="0.85251948844571779 0.67624721697981549 0.49949763007549985 1" friction="0.59999999999999998 0.10000000000000001 0.10000000000000001" fromto="0 0 0 -0.49944742098326628 0 0.024640235209572703"/>
              <site name="0/1/2/4/7/end7" class="0/1/2/4/7/" size="0.0050000000000000001" pos="-0.49944742098326628 0 0.024640235209572703"/>
            </body>
          </body>
        </body>
      </body>
      <site name="0/attach8" class="0/" size="9.9999999999999995e-07 9.9999999999999995e-07 9.9999999999999995e-07" pos="-0.077170679787712124 0 -0.0014943268340258597"/>
      <body pos="-0.077170679787712124 0 -0.0014943268340258597" name="0/8/">
        <joint name="0/8/joint/" class="0/" type="hinge" axis="0 1 0" limited="true" range="-56.6897997790566 56.6897997790566"/>
        <geom name="0/8/geom" class="0/8/" type="capsule" contype="1" conaffinity="1" condim="3" size="0.041928676575135854" rgba="0.54257307204724348 0.76284368596431185 0.56073323200399083 1" friction="0.59999999999999998 0.10000000000000001 0.10000000000000001" fromto="0 0 0 -0.25243889989434004 0 -0.50458373792166777"/>
        <site name="0/8/end8" class="0/8/" size="0.0050000000000000001" pos="-0.25243889989434004 0 -0.50458373792166777"/>
        <site name="0/8/attach9" class="0/8/" size="9.9999999999999995e-07 9.9999999999999995e-07 9.9999999999999995e-07" pos="-0.079927979093250043 0 -0.15976285141583788"/>
        <body pos="-0.079927979093250043 0 -0.15976285141583788" name="0/8/9/">
          <joint name="0/8/9/joint/" class="0/8/" type="hinge" axis="0 1 0" limited="true" range="-47.719675357142876 47.719675357142876"/>
          <geom name="0/8/9/geom" class="0/8/9/" type="capsule" contype="1" conaffinity="1" condim="3" size="0.045993809345709236" rgba="0.74630732336633632 0.093714522318671944 0.61443481047823223 1" friction="0.59999999999999998 0.10000000000000001 0.10000000000000001" fromto="0 0 0 0.37007290386480607 0 -0.40854715582505957"/>
          <site name="0/8/9/end9" class="0/8/9/" size="0.0050000000000000001" pos="0.37007290386480607 0 -0.40854715582505957"/>
          <site name="0/8/9/attach10" class="0/8/9/" size="9.9999999999999995e-07 9.9999999999999995e-07 9.9999999999999995e-07" pos="0.21352423349084565 0 -0.23572306262195097"/>
          <body pos="0.21352423349084565 0 -0.23572306262195097" name="0/8/9/10/">
            <joint name="0/8/9/10/joint/" class="0/8/9/" type="hinge" axis="0 1 0" limited="true" range="-59.325801768277934 59.325801768277934"/>
            <geom name="0/8/9/10/geom" class="0/8/9/10/" type="capsule" contype="1" conaffinity="1" condim="3" size="0.0616212170751433" rgba="0.55995496418054558 0.16456659051565659 0.86143225971108317 1" friction="0.59999999999999998 0.10000000000000001 0.10000000000000001" fromto="0 0 0 -0.093909495631177453 0 -0.73210052905661815"/>
            <site name="0/8/9/10/end10" class="0/8/9/10/" size="0.0050000000000000001" pos="-0.093909495631177453 0 -0.73210052905661815"/>
          </body>
        </body>
      </body>
      <camera name="0/side" class="0/" mode="trackcom" pos="0.40000000000000002 -4 0.20000000000000001" quat="0.70699999999999996 0.70699999999999996 0 0"/>
    </body>
  </worldbody>
  <actuator>
    <motor name="0/1/2/motor" class="0/1/2/" ctrllimited="true" ctrlrange="-1 1" gear="71" joint="0/1/2/joint/"/>
    <motor name="0/1/2/3/motor" class="0/1/2/3/" ctrllimited="true" ctrlrange="-1 1" gear="52" joint="0/1/2/3/joint/"/>
    <motor name="0/1/2/4/motor" class="0/1/2/4/" ctrllimited="true" ctrlrange="-1 1" gear="64" joint="0/1/2/4/joint/"/>
    <motor name="0/1/2/4/5/motor" class="0/1/2/4/5/" ctrllimited="true" ctrlrange="-1 1" gear="68" joint="0/1/2/4/5/joint/"/>
    <motor name="0/1/2/4/5/6/motor" class="0/1/2/4/5/6/" ctrllimited="true" ctrlrange="-1 1" gear="63" joint="0/1/2/4/5/6/joint/"/>
    <motor name="0/1/2/4/7/motor" class="0/1/2/4/7/" ctrllimited="true" ctrlrange="-1 1" gear="89" joint="0/1/2/4/7/joint/"/>
    <motor name="0/8/motor" class="0/8/" ctrllimited="true" ctrlrange="-1 1" gear="73" joint="0/8/joint/"/>
    <motor name="0/8/9/motor" class="0/8/9/" ctrllimited="true" ctrlrange="-1 1" gear="85" joint="0/8/9/joint/"/>
    <motor name="0/8/9/10/motor" class="0/8/9/10/" ctrllimited="true" ctrlrange="-1 1" gear="65" joint="0/8/9/10/joint/"/>
  </actuator>
  <sensor>
    <subtreelinvel name="velocity" body="0/"/>
  </sensor>
</mujoco>
