<mujoco model="morphology">
  <option timestep="0.01"/>
  <default>
    <default class="/"/>
    <default class="0/"/>
    <default class="0/1/"/>
    <default class="0/2/"/>
    <default class="0/2/3/"/>
    <default class="0/2/3/4/"/>
    <default class="0/2/3/4/5/"/>
    <default class="0/2/3/4/6/"/>
    <default class="0/2/3/4/6/7/"/>
    <default class="0/2/3/4/6/7/8/"/>
    <default class="0/2/3/4/6/7/8/9/"/>
    <default class="0/2/3/10/"/>
  </default>
  <asset>
    <texture name="texplane" type="2d" builtin="checker" rgb1="0.10000000000000001 0.20000000000000001 0.29999999999999999" rgb2="0.20000000000000001 0.29999999999999999 0.40000000000000002" width="300" height="300"/>
    <material name="MatPlane" class="/" texture="texplane" texrepeat="20 20" specular="1" shininess="1" reflectance="0.5"/>
  </asset>
  <worldbody>
    <light name="//unnamed_light_0" class="/" directional="true" pos="0 0 1.5" dir="0 0 -1.3" cutoff="100" exponent="1" diffuse="1 1 1" specular="0.10000000000000001 0.10000000000000001 0.10000000000000001"/>
    <geom name="ground" class="/" type="plane" size="15 15 0.5" material="MatPlane" rgba="1 1 1 1"/>
    <site name="body" class="/" size="9.9999999999999995e-07 9.9999999999999995e-07 9.9999999999999995e-07" pos="0 0 0.315834304690361"/>
    <body pos="0 0 0.315834304690361" name="0/">
      <joint name="0/rootx/" class="/" type="slide" axis="1 0 0" limited="false" stiffness="0" armature="0" damping="0"/>
      <joint name="0/rootz/" class="/" type="slide" axis="0 0 1" limited="false" stiffness="0" armature="0" damping="0"/>
      <joint name="0/rooty/" class="/" type="hinge" axis="0 1 0" limited="false" stiffness="0" armature="0" damping="0"/>
      <geom name="0/geom" class="0/" type="capsule" contype="1" conaffinity="1" condim="3" size="0.059822727300490652" rgba="0.67000278879034969 0.38203712526940792 0.4218874257668479 1" friction="0.59999999999999998 0.10000000000000001 0.10000000000000001" fromto="0 0 0 0.68894182879811505 0 0.32775413016631161"/>
      <site name="0/end0" class="0/" size="0.0050000000000000001" pos="0.68894182879811505 0 0.32775413016631161"/>
      <site name="0/attach1" class="0/" size="9.9999999999999995e-07 9.9999999999999995e-07 9.9999999999999995e-07" pos="0.31126313238570913 0 0.14807894214507694"/>
      <body pos="0.31126313238570913 0 0.14807894214507694" name="0/1/">
        <joint name="0/1/joint/" class="0/" type="hinge" axis="0 1 0" limited="true" stiffness="100" range="-50.461310395516364 50.461310395516364" armature="0.20000000000000001" damping="3.5"/>
        <geom name="0/1/geom" class="0/1/" type="capsule" contype="1" conaffinity="1" condim="3" size="0.06275920658978168" rgba="0.46166992133096318 0.5762352147647728 0.013654116732092159 1" friction="0.59999999999999998 0.10000000000000001 0.10000000000000001" fromto="0 0 0 0.30368207092489641 0 -0.36391325190331908"/>
        <site name="0/1/end1" class="0/1/" size="0.0050000000000000001" pos="0.30368207092489641 0 -0.36391325190331908"/>
      </body>
      <site name="0/attach2" class="0/" size="9.9999999999999995e-07 9.9999999999999995e-07 9.9999999999999995e-07" pos="0.65225989859041855 0 0.31030323137414667"/>
      <body pos="0.65225989859041855 0 0.31030323137414667" name="0/2/">
        <joint name="0/2/joint/" class="0/" type="hinge" axis="0 1 0" limited="true" stiffness="100" range="-43.375113592037394 43.375113592037394" armature="0.20000000000000001" damping="3.5"/>
        <geom name="0/2/geom" class="0/2/" type="capsule" contype="1" conaffinity="1" condim="3" size="0.067763498680507087" rgba="0.80284504684997193 0.60804625021965131 0.23802178746595859 1" friction="0.59999999999999998 0.10000000000000001 0.10000000000000001" fromto="0 0 0 -0.23475543268671628 0 0.58576347468205547"/>
        <site name="0/2/end2" class="0/2/" size="0.0050000000000000001" pos="-0.23475543268671628 0 0.58576347468205547"/>
        <site name="0/2/attach3" class="0/2/" size="9.9999999999999995e-07 9.9999999999999995e-07 9.9999999999999995e-07" pos="-0.18701638772986837 0 0.46664466012731809"/>
        <body pos="-0.18701638772986837 0 0.46664466012731809" name="0/2/3/">
          <joint name="0/2/3/joint/" class="0/2/" type="hinge" axis="0 1 0" limited="true" stiffness="100" range="-49.167964306653815 49.167964306653815" armature="0.20000000000000001" damping="3.5"/>
          <geom name="0/2/3/geom" class="0/2/3/" type="capsule" contype="1" conaffinity="1" condim="3" size="0.050951290384039088" rgba="0.44035235523751626 0.10753135827378346 0.42277759445645113 1" friction="0.59999999999999998 0.10000000000000001 0.10000000000000001" fromto="0 0 0 0.62379077504345615 0 0.14885418545432605"/>
          <site name="0/2/3/end3" class="0/2/3/" size="0.0050000000000000001" pos="0.62379077504345615 0 0.14885418545432605"/>
          <site name="0/2/3/attach4" class="0/2/3/" size="9.9999999999999995e-07 9.9999999999999995e-07 9.9999999999999995e-07" pos="0.3319398924445297 0 0.079210280572335964"/>
          <body pos="0.3319398924445297 0 0.079210280572335964" name="0/2/3/4/">
            <joint name="0/2/3/4/joint/" class="0/2/3/" type="hinge" axis="0 1 0" limited="true" stiffness="100" range="-31.479446884618042 31.479446884618042" armature="0.20000000000000001" damping="3.5"/>
            <geom name="0/2/3/4/geom" class="0/2/3/4/" type="capsule" contype="1" conaffinity="1" condim="3" size="0.040536500825623732" rgba="0.66040382270007836 0.12874577640867346 0.56380229209285626 1" friction="0.59999999999999998 0.10000000000000001 0.10000000000000001" fromto="0 0 0 0.087206611853815064 0 -0.61045580415269662"/>
            <site name="0/2/3/4/end4" class="0/2/3/4/" size="0.0050000000000000001" pos="0.087206611853815064 0 -0.61045580415269662"/>
            <site name="0/2/3/4/attach5" class="0/2/3/4/" size="9.9999999999999995e-07 9.9999999999999995e-07 9.9999999999999995e-07" pos="0.060659922233086486 0 -0.42462607845277589"/>
            <body pos="0.060659922233086486 0 -0.42462607845277589" name="0/2/3/4/5/">
              <joint name="0/2/3/4/5/joint/" class="0/2/3/4/" type="hinge" axis="0 1 0" limited="true" stiffness="100" range="-56.934284406200526 56.934284406200526" armature="0.20000000000000001" damping="3.5"/>
              <geom name="0/2/3/4/5/geom" class="0/2/3/4/5/" type="capsule" contype="1" conaffinity="1" condim="3" size="0.054288935118983805" rgba="0.092228960846166608 0.80139664946274802 0.18363959310593336 1" friction="0.59999999999999998 0.10000000000000001 0.10000000000000001" fromto="0 0 0 0.44362627596883564 0 0.43641101313755515"/>
              <site name="0/2/3/4/5/end5" class="0/2/3/4/5/" size="0.0050000000000000001" pos="0.44362627596883564 0 0.43641101313755515"/>
            </body>
            <site name="0/2/3/4/attach6" class="0/2/3/4/" size="9.9999999999999995e-07 9.9999999999999995e-07 9.9999999999999995e-07" pos="0.07951124494220016 0 -0.55658739559492942"/>
            <body pos="0.07951124494220016 0 -0.55658739559492942" name="0/2/3/4/6/">
              <joint name="0/2/3/4/6/joint/" class="0/2/3/4/" type="hinge" axis="0 1 0" limited="true" stiffness="100" range="-67.327367145351474 67.327367145351474" armature="0.20000000000000001" damping="3.5"/>
              <geom name="0/2/3/4/6/geom" class="0/2/3/4/6/" type="capsule" contype="1" conaffinity="1" condim="3" size="0.045011320037858661" rgba="0.69376458807854025 0.7144596283010014 0.046690965748919955 1" friction="0.59999999999999998 0.10000000000000001 0.10000000000000001" fromto="0 0 0 0.70406513203998378 0 0.3833938127369072"/>
              <site name="0/2/3/4/6/end6" class="0/2/3/4/6/" size="0.0050000000000000001" pos="0.70406513203998378 0 0.3833938127369072"/>
              <site name="0/2/3/4/6/attach7" class="0/2/3/4/6/" size="9.9999999999999995e-07 9.9999999999999995e-07 9.9999999999999995e-07" pos="0.70332790253970856 0 0.3829923594961343"/>
              <body pos="0.70332790253970856 0 0.3829923594961343" name="0/2/3/4/6/7/">
                <joint name="0/2/3/4/6/7/joint/" class="0/2/3/4/6/" type="hinge" axis="0 1 0" limited="true" stiffness="100" range="-31.755997115817884 31.755997115817884" armature="0.20000000000000001" damping="3.5"/>
                <geom name="0/2/3/4/6/7/geom" class="0/2/3/4/6/7/" type="capsule" contype="1" conaffinity="1" condim="3" size="0.055695894287755246" rgba="0.092393152792179856 0.57350696510612953 0.87809477967842464 1" friction="0.59999999999999998 0.10000000000000001 0.10000000000000001" fromto="0 0 0 -0.011525267891488777 0 -0.24795518510238423"/>
                <site name="0/2/3/4/6/7/end7" class="0/2/3/4/6/7/" size="0.0050000000000000001" pos="-0.011525267891488777 0 -0.24795518510238423"/>
                <site name="0/2/3/4/6/7/attach8" class="0/2/3/4/6/7/" size="9.9999999999999995e-07 9.9999999999999995e-07 9.9999999999999995e-07" pos="-0.0019638203376889248 0 -0.042249728155913921"/>
                <body pos="-0.0019638203376889248 0 -0.042249728155913921" name="0/2/3/4/6/7/8/">
                  <joint name="0/2/3/4/6/7/8/joint/" class="0/2/3/4/6/7/" type="hinge" axis="0 1 0" limited="true" stiffness="100" range="-54.210100617681618 54.210100617681618" armature="0.20000000000000001" damping="3.5"/>
                  <geom name="0/2/3/4/6/7/8/geom" class="0/2/3/4/6/7/8/" type="capsule" contype="1" conaffinity="1" condim="3" size="0.06392470326176862" rgba="0.058238445334843791 0.1681059270910632 0.27902883949363355 1" friction="0.59999999999999998 0.10000000000000001 0.10000000000000001" fromto="0 0 0 0.69420640212644358 0 -0.23415913158539814"/>
                  <site name="0/2/3/4/6/7/8/end8" class="0/2/3/4/6/7/8/" size="0.0050000000000000001" pos="0.69420640212644358 0 -0.23415913158539814"/>
                  <site name="0/2/3/4/6/7/8/attach9" class="0/2/3/4/6/7/8/" size="9.9999999999999995e-07 9.9999999999999995e-07 9.9999999999999995e-07" pos="0.60242900868640248 0 -0.20320217889630851"/>
                  <body pos="0.60242900868640248 0 -0.20320217889630851" name="0/2/3/4/6/7/8/9/">
                    <joint name="0/2/3/4/6/7/8/9/joint/" class="0/2/3/4/6/7/8/" type="hinge" axis="0 1 0" limited="true" stiffness="100" range="-67.418045638223447 67.418045638223447" armature="0.20000000000000001" damping="3.5"/>
                    <geom name="0/2/3/4/6/7/8/9/geom" class="0/2/3/4/6/7/8/9/" type="capsule" contype="1" conaffinity="1" condim="3" size="0.054299128220029559" rgba="0.28730426326782288 0.73389619369678194 0.93611596651821527 1" friction="0.59999999999999998 0.10000000000000001 0.10000000000000001" fromto="0 0 0 -0.24207807763438016 0 0.50733451603783353"/>
                    <site name="0/2/3/4/6/7/8/9/end9" class="0/2/3/4/6/7/8/9/" size="0.0050000000000000001" pos="-0.24207807763438016 0 0.50733451603783353"/>
                  </body>
                </body>
              </body>
            </body>
          </body>
          <site name="0/2/3/attach10" class="0/2/3/" size="9.9999999999999995e-07 9.9999999999999995e-07 9.9999999999999995e-07" pos="0.59942045015150269 0 0.14303873417453389"/>
          <body pos="0.59942045015150269 0 0.14303873417453389" name="0/2/3/10/">
            <joint name="0/2/3/10/joint/" class="0/2/3/" type="hinge" axis="0 1 0" limited="true" stiffness="100" range="-56.500738139837033 56.500738139837033" armature="0.20000000000000001" damping="3.5"/>
            <geom name="0/2/3/10/geom" class="0/2/3/10/" type="capsule" contype="1" conaffinity="1" condim="3" size="0.05759857175622167" rgba="0.91477463944369575 0.40931225959608164 0.69037586982597066 1" friction="0.59999999999999998 0.10000000000000001 0.10000000000000001" fromto="0 0 0 -0.10687945298681423 0 -0.2870039275444024"/>
            <site name="0/2/3/10/end10" class="0/2/3/10/" size="0.0050000000000000001" pos="-0.10687945298681423 0 -0.2870039275444024"/>
          </body>
        </body>
      </body>
      <camera name="0/side" class="0/" mode="trackcom" pos="0.40000000000000002 -4 0.20000000000000001" quat="0.70699999999999996 0.70699999999999996 0 0"/>
    </body>
  </worldbody>
  <actuator>
    <motor name="0/1/motor" class="0/1/" ctrllimited="true" ctrlrange="-1 1" gear="60" joint="0/1/joint/"/>
    <motor name="0/2/motor" class="0/2/" ctrllimited="true" ctrlrange="-1 1" gear="72" joint="0/2/joint/"/>
    <motor name="0/2/3/motor" class="0/2/3/" ctrllimited="true" ctrlrange="-1 1" gear="85" joint="0/2/3/joint/"/>
    <motor name="0/2/3/4/motor" class="0/2/3/4/" ctrllimited="true" ctrlrange="-1 1" gear="61" joint="0/2/3/4/joint/"/>
    <motor name="0/2/3/4/5/motor" class="0/2/3/4/5/" ctrllimited="true" ctrlrange="-1 1" gear="72" joint="0/2/3/4/5/joint/"/>
    <motor name="0/2/3/4/6/motor" class="0/2/3/4/6/" ctrllimited="true" ctrlrange="-1 1" gear="72" joint="0/2/3/4/6/joint/"/>
    <motor name="0/2/3/4/6/7/motor" class="0/2/3/4/6/7/" ctrllimited="true" ctrlrange="-1 1" gear="61" joint="0/2/3/4/6/7/joint/"/>
    <motor name="0/2/3/4/6/7/8/motor" class="0/2/3/4/6/7/8/" ctrllimited="true" ctrlrange="-1 1" gear="78" joint="0/2/3/4/6/7/8/joint/"/>
    <motor name="0/2/3/4/6/7/8/9/motor" class="0/2/3/4/6/7/8/9/" ctrllimited="true" ctrlrange="-1 1" gear="61" joint="0/2/3/4/6/7/8/9/joint/"/>
    <motor name="0/2/3/10/motor" class="0/2/3/10/" ctrllimited="true" ctrlrange="-1 1" gear="68" joint="0/2/3/10/joint/"/>
  </actuator>
  <sensor>
    <subtreelinvel name="velocity" body="0/"/>
  </sensor>
</mujoco>
