<mujoco model="morphology">
  <option timestep="0.01"/>
  <default>
    <default class="/"/>
    <default class="0/"/>
    <default class="0/1/"/>
    <default class="0/2/"/>
    <default class="0/2/3/"/>
    <default class="0/2/3/4/"/>
    <default class="0/2/3/5/"/>
    <default class="0/2/3/5/6/"/>
    <default class="0/2/3/5/6/7/"/>
    <default class="0/2/3/5/6/8/"/>
    <default class="0/2/3/5/6/8/9/"/>
    <default class="0/2/3/5/6/8/9/10/"/>
  </default>
  <asset>
    <texture name="texplane" type="2d" builtin="checker" rgb1="0.10000000000000001 0.20000000000000001 0.29999999999999999" rgb2="0.20000000000000001 0.29999999999999999 0.40000000000000002" width="300" height="300"/>
    <material name="MatPlane" class="/" texture="texplane" texrepeat="20 20" specular="1" shininess="1" reflectance="0.5"/>
  </asset>
  <worldbody>
    <light name="//unnamed_light_0" class="/" directional="true" pos="0 0 1.5" dir="0 0 -1.3" cutoff="100" exponent="1" diffuse="1 1 1" specular="0.10000000000000001 0.10000000000000001 0.10000000000000001"/>
    <geom name="ground" class="/" type="plane" size="15 15 0.5" material="MatPlane" rgba="1 1 1 1"/>
    <site name="body" class="/" size="9.9999999999999995e-07 9.9999999999999995e-07 9.9999999999999995e-07" pos="0 0 0.63942966461181638"/>
    <body pos="0 0 0.63942966461181638" name="0/">
      <joint name="0/rootx/" class="/" type="slide" axis="1 0 0" limited="false" stiffness="0" armature="0" damping="0"/>
      <joint name="0/rootz/" class="/" type="slide" axis="0 0 1" limited="false" stiffness="0" armature="0" damping="0"/>
      <joint name="0/rooty/" class="/" type="hinge" axis="0 1 0" limited="false" stiffness="0" armature="0" damping="0"/>
      <geom name="0/geom" class="0/" type="capsule" contype="1" conaffinity="1" condim="3" size="0.049507468743345322" rgba="0.83816880130761595 0.045670209763322589 0.79985307390554761 1" friction="0.59999999999999998 0.10000000000000001 0.10000000000000001" fromto="0 0 0 0.57926437542921483 0 0.12633981153373464"/>
      <site name="0/end0" class="0/" size="0.0050000000000000001" pos="0.57926437542921483 0 0.12633981153373464"/>
      <site name="0/attach1" class="0/" size="9.9999999999999995e-07 9.9999999999999995e-07 9.9999999999999995e-07" pos="0.32430725967164203 0 0.070732673721869546"/>
      <body pos="0.32430725967164203 0 0.070732673721869546" name="0/1/">
        <joint name="0/1/joint/" class="0/" type="hinge" axis="0 1 0" limited="true" range="-57.487548491513564 57.487548491513564"/>
        <geom name="0/1/geom" class="0/1/" type="capsule" contype="1" conaffinity="1" condim="3" size="0.063451022020879419" rgba="0.51478728854579126 0.26396800490229755 0.91423498751599208 1" friction="0.59999999999999998 0.10000000000000001 0.10000000000000001" fromto="0 0 0 -0.2368437402058835 0 -0.61016235146289388"/>
        <site name="0/1/end1" class="0/1/" size="0.0050000000000000001" pos="-0.2368437402058835 0 -0.61016235146289388"/>
      </body>
      <site name="0/attach2" class="0/" size="9.9999999999999995e-07 9.9999999999999995e-07 9.9999999999999995e-07" pos="0.41661913524216071 0 0.09086625254460183"/>
      <body pos="0.41661913524216071 0 0.09086625254460183" name="0/2/">
        <joint name="0/2/joint/" class="0/" type="hinge" axis="0 1 0" limited="true" range="-43.482723951133387 43.482723951133387"/>
        <geom name="0/2/geom" class="0/2/" type="capsule" contype="1" conaffinity="1" condim="3" size="0.062551332717362865" rgba="0.84320806846540475 0.89157082795124054 0.8153498354520603 1" friction="0.59999999999999998 0.10000000000000001 0.10000000000000001" fromto="0 0 0 0.37374852714985485 0 -0.33563235198904406"/>
        <site name="0/2/end2" class="0/2/" size="0.0050000000000000001" pos="0.37374852714985485 0 -0.33563235198904406"/>
        <site name="0/2/attach3" class="0/2/" size="9.9999999999999995e-07 9.9999999999999995e-07 9.9999999999999995e-07" pos="0.33183613229902698 0 -0.29799432898852368"/>
        <body pos="0.33183613229902698 0 -0.29799432898852368" name="0/2/3/">
          <joint name="0/2/3/joint/" class="0/2/" type="hinge" axis="0 1 0" limited="true" range="-38.54949329977854 38.54949329977854"/>
          <geom name="0/2/3/geom" class="0/2/3/" type="capsule" contype="1" conaffinity="1" condim="3" size="0.048879063535247701" rgba="0.23819564598099052 0.83414149344072264 0.31200776274805964 1" friction="0.59999999999999998 0.10000000000000001 0.10000000000000001" fromto="0 0 0 0.16458580975372517 0 0.21735789195952426"/>
          <site name="0/2/3/end3" class="0/2/3/" size="0.0050000000000000001" pos="0.16458580975372517 0 0.21735789195952426"/>
          <site name="0/2/3/attach4" class="0/2/3/" size="9.9999999999999995e-07 9.9999999999999995e-07 9.9999999999999995e-07" pos="0.1598894883940182 0 0.21115576243063097"/>
          <body pos="0.1598894883940182 0 0.21115576243063097" name="0/2/3/4/">
            <joint name="0/2/3/4/joint/" class="0/2/3/" type="hinge" axis="0 1 0" limited="true" range="-55.321392888456558 55.321392888456558"/>
            <geom name="0/2/3/4/geom" class="0/2/3/4/" type="capsule" contype="1" conaffinity="1" condim="3" size="0.066920458151939324" rgba="0.051949149410922768 0.79032441632113137 0.27720047539977322 1" friction="0.59999999999999998 0.10000000000000001 0.10000000000000001" fromto="0 0 0 0.068857330211181123 0 0.070942475910680591"/>
            <site name="0/2/3/4/end4" class="0/2/3/4/" size="0.0050000000000000001" pos="0.068857330211181123 0 0.070942475910680591"/>
          </body>
          <site name="0/2/3/attach5" class="0/2/3/" size="9.9999999999999995e-07 9.9999999999999995e-07 9.9999999999999995e-07" pos="0.089557995451189198 0 0.11827348377432373"/>
          <body pos="0.089557995451189198 0 0.11827348377432373" name="0/2/3/5/">
            <joint name="0/2/3/5/joint/" class="0/2/3/" type="hinge" axis="0 1 0" limited="true" range="-64.62400057989106 64.62400057989106"/>
            <geom name="0/2/3/5/geom" class="0/2/3/5/" type="capsule" contype="1" conaffinity="1" condim="3" size="0.050824019160924952" rgba="0.28504016476794969 0.57141780421196076 0.79465183262139805 1" friction="0.59999999999999998 0.10000000000000001 0.10000000000000001" fromto="0 0 0 0.54973244816123401 0 -0.22557559798198046"/>
            <site name="0/2/3/5/end5" class="0/2/3/5/" size="0.0050000000000000001" pos="0.54973244816123401 0 -0.22557559798198046"/>
            <site name="0/2/3/5/attach6" class="0/2/3/5/" size="9.9999999999999995e-07 9.9999999999999995e-07 9.9999999999999995e-07" pos="0.10865655834642572 0 -0.044585812981645545"/>
            <body pos="0.10865655834642572 0 -0.044585812981645545" name="0/2/3/5/6/">
              <joint name="0/2/3/5/6/joint/" class="0/2/3/5/" type="hinge" axis="0 1 0" limited="true" range="-62.012439413235484 62.012439413235484"/>
              <geom name="0/2/3/5/6/geom" class="0/2/3/5/6/" type="capsule" contype="1" conaffinity="1" condim="3" size="0.067466546686297951" rgba="0.57445642071861502 0.34467597124255556 0.6068743260111088 1" friction="0.59999999999999998 0.10000000000000001 0.10000000000000001" fromto="0 0 0 0.71769015723405705 0 0.56147357891738747"/>
              <site name="0/2/3/5/6/end6" class="0/2/3/5/6/" size="0.0050000000000000001" pos="0.71769015723405705 0 0.56147357891738747"/>
              <site name="0/2/3/5/6/attach7" class="0/2/3/5/6/" size="9.9999999999999995e-07 9.9999999999999995e-07 9.9999999999999995e-07" pos="0.57888878768001495 0 0.45288451588426176"/>
              <body pos="0.57888878768001495 0 0.45288451588426176" name="0/2/3/5/6/7/">
                <joint name="0/2/3/5/6/7/joint/" class="0/2/3/5/6/" type="hinge" axis="0 1 0" limited="true" range="-43.955251206066016 43.955251206066016"/>
                <geom name="0/2/3/5/6/7/geom" class="0/2/3/5/6/7/" type="capsule" contype="1" conaffinity="1" condim="3" size="0.043000014281078559" rgba="0.37818556379409995 0.15019316801281868 0.2654656260229018 1" friction="0.59999999999999998 0.10000000000000001 0.10000000000000001" fromto="0 0 0 -0.56936368294097939 0 0.58972308455490174"/>
                <site name="0/2/3/5/6/7/end7" class="0/2/3/5/6/7/" size="0.0050000000000000001" pos="-0.56936368294097939 0 0.58972308455490174"/>
              </body>
              <site name="0/2/3/5/6/attach8" class="0/2/3/5/6/" size="9.9999999999999995e-07 9.9999999999999995e-07 9.9999999999999995e-07" pos="0.4945357262322152 0 0.38689222822872898"/>
              <body pos="0.4945357262322152 0 0.38689222822872898" name="0/2/3/5/6/8/">
                <joint name="0/2/3/5/6/8/joint/" class="0/2/3/5/6/" type="hinge" axis="0 1 0" limited="true" range="-34.630191183867971 34.630191183867971"/>
                <geom name="0/2/3/5/6/8/geom" class="0/2/3/5/6/8/" type="capsule" contype="1" conaffinity="1" condim="3" size="0.059831514554064581" rgba="0.85561662266650496 0.81420386750263585 0.8095196609111287 1" friction="0.59999999999999998 0.10000000000000001 0.10000000000000001" fromto="0 0 0 -0.39508030726415178 0 0.30800483210581442"/>
                <site name="0/2/3/5/6/8/end8" class="0/2/3/5/6/8/" size="0.0050000000000000001" pos="-0.39508030726415178 0 0.30800483210581442"/>
                <site name="0/2/3/5/6/8/attach9" class="0/2/3/5/6/8/" size="9.9999999999999995e-07 9.9999999999999995e-07 9.9999999999999995e-07" pos="-0.37823046054881576 0 0.29486868202912675"/>
                <body pos="-0.37823046054881576 0 0.29486868202912675" name="0/2/3/5/6/8/9/">
                  <joint name="0/2/3/5/6/8/9/joint/" class="0/2/3/5/6/8/" type="hinge" axis="0 1 0" limited="true" range="-55.016751859559179 55.016751859559179"/>
                  <geom name="0/2/3/5/6/8/9/geom" class="0/2/3/5/6/8/9/" type="capsule" contype="1" conaffinity="1" condim="3" size="0.067223222845685882" rgba="0.52265038236182704 0.27773286637054284 0.0052079532379354365 1" friction="0.59999999999999998 0.10000000000000001 0.10000000000000001" fromto="0 0 0 -0.66809740586865429 0 -0.20199903464464908"/>
                  <site name="0/2/3/5/6/8/9/end9" class="0/2/3/5/6/8/9/" size="0.0050000000000000001" pos="-0.66809740586865429 0 -0.20199903464464908"/>
                  <site name="0/2/3/5/6/8/9/attach10" class="0/2/3/5/6/8/9/" size="9.9999999999999995e-07 9.9999999999999995e-07 9.9999999999999995e-07" pos="-0.4456230365669504 0 -0.13473398102018355"/>
                  <body pos="-0.4456230365669504 0 -0.13473398102018355" name="0/2/3/5/6/8/9/10/">
                    <joint name="0/2/3/5/6/8/9/10/joint/" class="0/2/3/5/6/8/9/" type="hinge" axis="0 1 0" limited="true" range="-38.865086521053279 38.865086521053279"/>
                    <geom name="0/2/3/5/6/8/9/10/geom" class="0/2/3/5/6/8/9/10/" type="capsule" contype="1" conaffinity="1" condim="3" size="0.060680267246479055" rgba="0.19363318828301335 0.63693867104780011 0.18862714100576661 1" friction="0.59999999999999998 0.10000000000000001 0.10000000000000001" fromto="0 0 0 -0.35722244942218551 0 0.44769122086331103"/>
                    <site name="0/2/3/5/6/8/9/10/end10" class="0/2/3/5/6/8/9/10/" size="0.0050000000000000001" pos="-0.35722244942218551 0 0.44769122086331103"/>
                  </body>
                </body>
              </body>
            </body>
          </body>
        </body>
      </body>
      <camera name="0/side" class="0/" mode="trackcom" pos="0.40000000000000002 -4 0.20000000000000001" quat="0.70699999999999996 0.70699999999999996 0 0"/>
    </body>
  </worldbody>
  <actuator>
    <motor name="0/1/motor" class="0/1/" ctrllimited="true" ctrlrange="-1 1" gear="76" joint="0/1/joint/"/>
    <motor name="0/2/motor" class="0/2/" ctrllimited="true" ctrlrange="-1 1" gear="58" joint="0/2/joint/"/>
    <motor name="0/2/3/motor" class="0/2/3/" ctrllimited="true" ctrlrange="-1 1" gear="73" joint="0/2/3/joint/"/>
    <motor name="0/2/3/4/motor" class="0/2/3/4/" ctrllimited="true" ctrlrange="-1 1" gear="71" joint="0/2/3/4/joint/"/>
    <motor name="0/2/3/5/motor" class="0/2/3/5/" ctrllimited="true" ctrlrange="-1 1" gear="77" joint="0/2/3/5/joint/"/>
    <motor name="0/2/3/5/6/motor" class="0/2/3/5/6/" ctrllimited="true" ctrlrange="-1 1" gear="54" joint="0/2/3/5/6/joint/"/>
    <motor name="0/2/3/5/6/7/motor" class="0/2/3/5/6/7/" ctrllimited="true" ctrlrange="-1 1" gear="52" joint="0/2/3/5/6/7/joint/"/>
    <motor name="0/2/3/5/6/8/motor" class="0/2/3/5/6/8/" ctrllimited="true" ctrlrange="-1 1" gear="60" joint="0/2/3/5/6/8/joint/"/>
    <motor name="0/2/3/5/6/8/9/motor" class="0/2/3/5/6/8/9/" ctrllimited="true" ctrlrange="-1 1" gear="80" joint="0/2/3/5/6/8/9/joint/"/>
    <motor name="0/2/3/5/6/8/9/10/motor" class="0/2/3/5/6/8/9/10/" ctrllimited="true" ctrlrange="-1 1" gear="85" joint="0/2/3/5/6/8/9/10/joint/"/>
  </actuator>
  <sensor>
    <subtreelinvel name="velocity" body="0/"/>
  </sensor>
</mujoco>
