<mujoco model="morphology">
  <option timestep="0.01"/>
  <default>
    <default class="/"/>
    <default class="0/"/>
    <default class="0/1/"/>
    <default class="0/1/2/"/>
    <default class="0/1/2/3/"/>
    <default class="0/1/2/3/4/"/>
    <default class="0/1/2/3/5/"/>
    <default class="0/1/2/3/5/6/"/>
    <default class="0/1/2/3/5/6/7/"/>
    <default class="0/1/2/3/5/6/8/"/>
    <default class="0/1/2/3/5/6/8/9/"/>
    <default class="0/1/2/3/10/"/>
  </default>
  <asset>
    <texture name="texplane" type="2d" builtin="checker" rgb1="0.10000000000000001 0.20000000000000001 0.29999999999999999" rgb2="0.20000000000000001 0.29999999999999999 0.40000000000000002" width="300" height="300"/>
    <material name="MatPlane" class="/" texture="texplane" texrepeat="20 20" specular="1" shininess="1" reflectance="0.5"/>
  </asset>
  <worldbody>
    <light name="//unnamed_light_0" class="/" directional="true" pos="0 0 1.5" dir="0 0 -1.3" cutoff="100" exponent="1" diffuse="1 1 1" specular="0.10000000000000001 0.10000000000000001 0.10000000000000001"/>
    <geom name="ground" class="/" type="plane" size="15 15 0.5" material="MatPlane" rgba="1 1 1 1"/>
    <site name="body" class="/" size="9.9999999999999995e-07 9.9999999999999995e-07 9.9999999999999995e-07" pos="0 0 0.10381871708668769"/>
    <body pos="0 0 0.10381871708668769" name="0/">
      <joint name="0/rootx/" class="/" type="slide" axis="1 0 0" limited="false" stiffness="0" armature="0" damping="0"/>
      <joint name="0/rootz/" class="/" type="slide" axis="0 0 1" limited="false" stiffness="0" armature="0" damping="0"/>
      <joint name="0/rooty/" class="/" type="hinge" axis="0 1 0" limited="false" stiffness="0" armature="0" damping="0"/>
      <geom name="0/geom" class="0/" type="capsule" contype="1" conaffinity="1" condim="3" size="0.048607320074202973" rgba="0.62600471413747139 0.77205023131233741 0.84819178884413216 1" friction="0.59999999999999998 0.10000000000000001 0.10000000000000001" fromto="0 0 0 -0.47253581909399595 0 -0.0038187171260941621"/>
      <site name="0/end0" class="0/" size="0.0050000000000000001" pos="-0.47253581909399595 0 -0.0038187171260941621"/>
      <site name="0/attach1" class="0/" size="9.9999999999999995e-07 9.9999999999999995e-07 9.9999999999999995e-07" pos="-0.43098798921221126 0 -0.0034829554692830038"/>
      <body pos="-0.43098798921221126 0 -0.0034829554692830038" name="0/1/">
        <joint name="0/1/joint/" class="0/" type="hinge" axis="0 1 0" limited="true" range="-55.705999735974899 55.705999735974899"/>
        <geom name="0/1/geom" class="0/1/" type="capsule" contype="1" conaffinity="1" condim="3" size="0.063082529030815168" rgba="0.87429581714171145 0.89532965351088889 0.45134733662487347 1" friction="0.59999999999999998 0.10000000000000001 0.10000000000000001" fromto="0 0 0 -0.02599942840614311 0 0.73039289112134376"/>
        <site name="0/1/end1" class="0/1/" size="0.0050000000000000001" pos="-0.02599942840614311 0 0.73039289112134376"/>
        <site name="0/1/attach2" class="0/1/" size="9.9999999999999995e-07 9.9999999999999995e-07 9.9999999999999995e-07" pos="-0.021489251709336462 0 0.60369006729040253"/>
        <body pos="-0.021489251709336462 0 0.60369006729040253" name="0/1/2/">
          <geom name="0/1/2/geom" class="0/1/2/" type="capsule" contype="1" conaffinity="1" condim="3" size="0.044060517229819351" rgba="0.44856449677686283 0.10637607332721166 0.97819265433600922 1" friction="0.59999999999999998 0.10000000000000001 0.10000000000000001" fromto="0 0 0 0.29253589475810671 0 0.17930102197794628"/>
          <site name="0/1/2/end2" class="0/1/2/" size="0.0050000000000000001" pos="0.29253589475810671 0 0.17930102197794628"/>
          <site name="0/1/2/attach3" class="0/1/2/" size="9.9999999999999995e-07 9.9999999999999995e-07 9.9999999999999995e-07" pos="0.18518552256895143 0 0.11350386071284979"/>
          <body pos="0.18518552256895143 0 0.11350386071284979" name="0/1/2/3/">
            <joint name="0/1/2/3/joint/" class="0/1/2/" type="hinge" axis="0 1 0" limited="true" range="-41.23968528833818 41.23968528833818"/>
            <geom name="0/1/2/3/geom" class="0/1/2/3/" type="capsule" contype="1" conaffinity="1" condim="3" size="0.048410276025171631" rgba="0.080124397023007887 0.62487969006987742 0.55062329589369174 1" friction="0.59999999999999998 0.10000000000000001 0.10000000000000001" fromto="0 0 0 -0.73170131449904785 0 0.65085784075618425"/>
            <site name="0/1/2/3/end3" class="0/1/2/3/" size="0.0050000000000000001" pos="-0.73170131449904785 0 0.65085784075618425"/>
            <site name="0/1/2/3/attach4" class="0/1/2/3/" size="9.9999999999999995e-07 9.9999999999999995e-07 9.9999999999999995e-07" pos="-0.11131778380518374 0 0.099018617254786834"/>
            <body pos="-0.11131778380518374 0 0.099018617254786834" name="0/1/2/3/4/">
              <joint name="0/1/2/3/4/joint/" class="0/1/2/3/" type="hinge" axis="0 1 0" limited="true" range="-39.096266843935382 39.096266843935382"/>
              <geom name="0/1/2/3/4/geom" class="0/1/2/3/4/" type="capsule" contype="1" conaffinity="1" condim="3" size="0.040683302739087261" rgba="0.029259528667033297 0.42525018559719996 0.92032830838463675 1" friction="0.59999999999999998 0.10000000000000001 0.10000000000000001" fromto="0 0 0 0.14521502248935214 0 0.53355751707723664"/>
              <site name="0/1/2/3/4/end4" class="0/1/2/3/4/" size="0.0050000000000000001" pos="0.14521502248935214 0 0.53355751707723664"/>
            </body>
            <site name="0/1/2/3/attach5" class="0/1/2/3/" size="9.9999999999999995e-07 9.9999999999999995e-07 9.9999999999999995e-07" pos="-0.64070507324551063 0 0.56991550004198954"/>
            <body pos="-0.64070507324551063 0 0.56991550004198954" name="0/1/2/3/5/">
              <joint name="0/1/2/3/5/joint/" class="0/1/2/3/" type="hinge" axis="0 1 0" limited="true" range="-38.988900820847206 38.988900820847206"/>
              <geom name="0/1/2/3/5/geom" class="0/1/2/3/5/" type="capsule" contype="1" conaffinity="1" condim="3" size="0.061862872638035304" rgba="0.71846903571485965 0.059323341124631779 0.66287291823962946 1" friction="0.59999999999999998 0.10000000000000001 0.10000000000000001" fromto="0 0 0 0.56317261549068354 0 0.747590777000114"/>
              <site name="0/1/2/3/5/end5" class="0/1/2/3/5/" size="0.0050000000000000001" pos="0.56317261549068354 0 0.747590777000114"/>
              <site name="0/1/2/3/5/attach6" class="0/1/2/3/5/" size="9.9999999999999995e-07 9.9999999999999995e-07 9.9999999999999995e-07" pos="0.54463367058972711 0 0.72298101466074194"/>
              <body pos="0.54463367058972711 0 0.72298101466074194" name="0/1/2/3/5/6/">
                <joint name="0/1/2/3/5/6/joint/" class="0/1/2/3/5/" type="hinge" axis="0 1 0" limited="true" range="-66.572888448030099 66.572888448030099"/>
                <geom name="0/1/2/3/5/6/geom" class="0/1/2/3/5/6/" type="capsule" contype="1" conaffinity="1" condim="3" size="0.053978681302575021" rgba="0.4569018486236337 0.84217299375059884 0.011690628598555186 1" friction="0.59999999999999998 0.10000000000000001 0.10000000000000001" fromto="0 0 0 -0.17473654783760573 0 0.19201503948202459"/>
                <site name="0/1/2/3/5/6/end6" class="0/1/2/3/5/6/" size="0.0050000000000000001" pos="-0.17473654783760573 0 0.19201503948202459"/>
                <site name="0/1/2/3/5/6/attach7" class="0/1/2/3/5/6/" size="9.9999999999999995e-07 9.9999999999999995e-07 9.9999999999999995e-07" pos="-0.1290521370928194 0 0.14181321255211599"/>
                <body pos="-0.1290521370928194 0 0.14181321255211599" name="0/1/2/3/5/6/7/">
                  <geom name="0/1/2/3/5/6/7/geom" class="0/1/2/3/5/6/7/" type="capsule" contype="1" conaffinity="1" condim="3" size="0.063353562473353178" rgba="0.067306094642964776 0.80119758386590956 0.67998609557857648 1" friction="0.59999999999999998 0.10000000000000001 0.10000000000000001" fromto="0 0 0 -0.45633726789117446 0 -0.24282336734025423"/>
                  <site name="0/1/2/3/5/6/7/end7" class="0/1/2/3/5/6/7/" size="0.0050000000000000001" pos="-0.45633726789117446 0 -0.24282336734025423"/>
                </body>
                <site name="0/1/2/3/5/6/attach8" class="0/1/2/3/5/6/" size="9.9999999999999995e-07 9.9999999999999995e-07 9.9999999999999995e-07" pos="-0.054942001215052931 0 0.060374836650283134"/>
                <body pos="-0.054942001215052931 0 0.060374836650283134" name="0/1/2/3/5/6/8/">
                  <joint name="0/1/2/3/5/6/8/joint/" class="0/1/2/3/5/6/" type="hinge" axis="0 1 0" limited="true" range="-42.17126088339009 42.17126088339009"/>
                  <geom name="0/1/2/3/5/6/8/geom" class="0/1/2/3/5/6/8/" type="capsule" contype="1" conaffinity="1" condim="3" size="0.050177795329994189" rgba="0.61457830101183986 0.27818079062809331 0.48432755691689522 1" friction="0.59999999999999998 0.10000000000000001 0.10000000000000001" fromto="0 0 0 0.19675364305319709 0 0.42726413535546559"/>
                  <site name="0/1/2/3/5/6/8/end8" class="0/1/2/3/5/6/8/" size="0.0050000000000000001" pos="0.19675364305319709 0 0.42726413535546559"/>
                  <site name="0/1/2/3/5/6/8/attach9" class="0/1/2/3/5/6/8/" size="9.9999999999999995e-07 9.9999999999999995e-07 9.9999999999999995e-07" pos="0.14341643451440958 0 0.31143870038531041"/>
                  <body pos="0.14341643451440958 0 0.31143870038531041" name="0/1/2/3/5/6/8/9/">
                    <joint name="0/1/2/3/5/6/8/9/joint/" class="0/1/2/3/5/6/8/" type="hinge" axis="0 1 0" limited="true" range="-63.810280234750913 63.810280234750913"/>
                    <geom name="0/1/2/3/5/6/8/9/geom" class="0/1/2/3/5/6/8/9/" type="capsule" contype="1" conaffinity="1" condim="3" size="0.051658397395338722" rgba="0.46323985119846711 0.53378921576296912 0.84108061818118163 1" friction="0.59999999999999998 0.10000000000000001 0.10000000000000001" fromto="0 0 0 0.55740843695050302 0 -0.054832798959830065"/>
                    <site name="0/1/2/3/5/6/8/9/end9" class="0/1/2/3/5/6/8/9/" size="0.0050000000000000001" pos="0.55740843695050302 0 -0.054832798959830065"/>
                  </body>
                </body>
              </body>
            </body>
            <site name="0/1/2/3/attach10" class="0/1/2/3/" size="9.9999999999999995e-07 9.9999999999999995e-07 9.9999999999999995e-07" pos="-0.29786980741814717 0 0.26495906982942558"/>
            <body pos="-0.29786980741814717 0 0.26495906982942558" name="0/1/2/3/10/">
              <joint name="0/1/2/3/10/joint/" class="0/1/2/3/" type="hinge" axis="0 1 0" limited="true" range="-64.694707229302935 64.694707229302935"/>
              <geom name="0/1/2/3/10/geom" class="0/1/2/3/10/" type="capsule" contype="1" conaffinity="1" condim="3" size="0.048235762736587848" rgba="0.095081698524305924 0.26537860620381115 0.78266776618660172 1" friction="0.59999999999999998 0.10000000000000001 0.10000000000000001" fromto="0 0 0 -0.23548441967566047 0 -0.54155423265195723"/>
              <site name="0/1/2/3/10/end10" class="0/1/2/3/10/" size="0.0050000000000000001" pos="-0.23548441967566047 0 -0.54155423265195723"/>
            </body>
          </body>
        </body>
      </body>
      <camera name="0/side" class="0/" mode="trackcom" pos="0.40000000000000002 -4 0.20000000000000001" quat="0.70699999999999996 0.70699999999999996 0 0"/>
    </body>
  </worldbody>
  <actuator>
    <motor name="0/1/motor" class="0/1/" ctrllimited="true" ctrlrange="-1 1" gear="63" joint="0/1/joint/"/>
    <motor name="0/1/2/3/motor" class="0/1/2/3/" ctrllimited="true" ctrlrange="-1 1" gear="78" joint="0/1/2/3/joint/"/>
    <motor name="0/1/2/3/4/motor" class="0/1/2/3/4/" ctrllimited="true" ctrlrange="-1 1" gear="70" joint="0/1/2/3/4/joint/"/>
    <motor name="0/1/2/3/5/motor" class="0/1/2/3/5/" ctrllimited="true" ctrlrange="-1 1" gear="65" joint="0/1/2/3/5/joint/"/>
    <motor name="0/1/2/3/5/6/motor" class="0/1/2/3/5/6/" ctrllimited="true" ctrlrange="-1 1" gear="73" joint="0/1/2/3/5/6/joint/"/>
    <motor name="0/1/2/3/5/6/8/motor" class="0/1/2/3/5/6/8/" ctrllimited="true" ctrlrange="-1 1" gear="68" joint="0/1/2/3/5/6/8/joint/"/>
    <motor name="0/1/2/3/5/6/8/9/motor" class="0/1/2/3/5/6/8/9/" ctrllimited="true" ctrlrange="-1 1" gear="73" joint="0/1/2/3/5/6/8/9/joint/"/>
    <motor name="0/1/2/3/10/motor" class="0/1/2/3/10/" ctrllimited="true" ctrlrange="-1 1" gear="67" joint="0/1/2/3/10/joint/"/>
  </actuator>
  <sensor>
    <subtreelinvel name="velocity" body="0/"/>
  </sensor>
</mujoco>
