<mujoco model="morphology">
  <option timestep="0.01"/>
  <default>
    <default class="/"/>
    <default class="0/"/>
    <default class="0/1/"/>
    <default class="0/1/2/"/>
    <default class="0/1/3/"/>
    <default class="0/1/3/4/"/>
    <default class="0/1/3/4/5/"/>
    <default class="0/1/3/4/5/6/"/>
    <default class="0/1/3/4/5/6/7/"/>
    <default class="0/1/3/4/5/6/8/"/>
    <default class="0/1/3/4/5/6/8/9/"/>
    <default class="0/1/3/4/5/6/8/9/10/"/>
  </default>
  <asset>
    <texture name="texplane" type="2d" builtin="checker" rgb1="0.10000000000000001 0.20000000000000001 0.29999999999999999" rgb2="0.20000000000000001 0.29999999999999999 0.40000000000000002" width="300" height="300"/>
    <material name="MatPlane" class="/" texture="texplane" texrepeat="20 20" specular="1" shininess="1" reflectance="0.5"/>
  </asset>
  <worldbody>
    <light name="//unnamed_light_0" class="/" directional="true" pos="0 0 1.5" dir="0 0 -1.3" cutoff="100" exponent="1" diffuse="1 1 1" specular="0.10000000000000001 0.10000000000000001 0.10000000000000001"/>
    <geom name="ground" class="/" type="plane" size="15 15 0.5" material="MatPlane" rgba="1 1 1 1"/>
    <site name="body" class="/" size="9.9999999999999995e-07 9.9999999999999995e-07 9.9999999999999995e-07" pos="0 0 0.96002302169799802"/>
    <body pos="0 0 0.96002302169799802" name="0/">
      <joint name="0/rootx/" class="/" type="slide" axis="1 0 0" limited="false" stiffness="0" armature="0" damping="0"/>
      <joint name="0/rootz/" class="/" type="slide" axis="0 0 1" limited="false" stiffness="0" armature="0" damping="0"/>
      <joint name="0/rooty/" class="/" type="hinge" axis="0 1 0" limited="false" stiffness="0" armature="0" damping="0"/>
      <geom name="0/geom" class="0/" type="capsule" contype="1" conaffinity="1" condim="3" size="0.049599252718048971" rgba="0.62592533188450517 0.50000571621871048 0.64579070086882973 1" friction="0.59999999999999998 0.10000000000000001 0.10000000000000001" fromto="0 0 0 -0.6335569104645814 0 -0.49788682062366701"/>
      <site name="0/end0" class="0/" size="0.0050000000000000001" pos="-0.6335569104645814 0 -0.49788682062366701"/>
      <site name="0/attach1" class="0/" size="9.9999999999999995e-07 9.9999999999999995e-07 9.9999999999999995e-07" pos="-0.18224127551156158 0 -0.14321606749473795"/>
      <body pos="-0.18224127551156158 0 -0.14321606749473795" name="0/1/">
        <joint name="0/1/joint/" class="0/" type="hinge" axis="0 1 0" limited="true" stiffness="100" range="-36.713600430997808 36.713600430997808" armature="0.20000000000000001" damping="3.5"/>
        <geom name="0/1/geom" class="0/1/" type="capsule" contype="1" conaffinity="1" condim="3" size="0.064383754027178733" rgba="0.3024115740023442 0.9174336837785434 0.32421490027018907 1" friction="0.59999999999999998 0.10000000000000001 0.10000000000000001" fromto="0 0 0 -0.54786009284117698 0 0.34126610791151624"/>
        <site name="0/1/end1" class="0/1/" size="0.0050000000000000001" pos="-0.54786009284117698 0 0.34126610791151624"/>
        <site name="0/1/attach2" class="0/1/" size="9.9999999999999995e-07 9.9999999999999995e-07 9.9999999999999995e-07" pos="-0.23282740616396669 0 0.14502991503662005"/>
        <body pos="-0.23282740616396669 0 0.14502991503662005" name="0/1/2/">
          <joint name="0/1/2/joint/" class="0/1/" type="hinge" axis="0 1 0" limited="true" stiffness="100" range="-46.311461135542352 46.311461135542352" armature="0.20000000000000001" damping="3.5"/>
          <geom name="0/1/2/geom" class="0/1/2/" type="capsule" contype="1" conaffinity="1" condim="3" size="0.041445834244133353" rgba="0.72043822180060635 0.37551519247316889 0.70781331345664533 1" friction="0.59999999999999998 0.10000000000000001 0.10000000000000001" fromto="0 0 0 0.40763899050008323 0 0.41877829380087217"/>
          <site name="0/1/2/end2" class="0/1/2/" size="0.0050000000000000001" pos="0.40763899050008323 0 0.41877829380087217"/>
        </body>
        <site name="0/1/attach3" class="0/1/" size="9.9999999999999995e-07 9.9999999999999995e-07 9.9999999999999995e-07" pos="-0.20576667008483474 0 0.12817358218884084"/>
        <body pos="-0.20576667008483474 0 0.12817358218884084" name="0/1/3/">
          <geom name="0/1/3/geom" class="0/1/3/" type="capsule" contype="1" conaffinity="1" condim="3" size="0.04642927086520262" rgba="0.19174116635194605 0.73359606704090297 0.8589482512822102 1" friction="0.59999999999999998 0.10000000000000001 0.10000000000000001" fromto="0 0 0 -0.58240383746490598 0 -0.16674955590985152"/>
          <site name="0/1/3/end3" class="0/1/3/" size="0.0050000000000000001" pos="-0.58240383746490598 0 -0.16674955590985152"/>
          <site name="0/1/3/attach4" class="0/1/3/" size="9.9999999999999995e-07 9.9999999999999995e-07 9.9999999999999995e-07" pos="-0.57270532089490733 0 -0.16397274843194912"/>
          <body pos="-0.57270532089490733 0 -0.16397274843194912" name="0/1/3/4/">
            <joint name="0/1/3/4/joint/" class="0/1/3/" type="hinge" axis="0 1 0" limited="true" stiffness="100" range="-36.483178756812542 36.483178756812542" armature="0.20000000000000001" damping="3.5"/>
            <geom name="0/1/3/4/geom" class="0/1/3/4/" type="capsule" contype="1" conaffinity="1" condim="3" size="0.061090489391656885" rgba="0.99235871081633575 0.30599067621041764 0.23717819162067266 1" friction="0.59999999999999998 0.10000000000000001 0.10000000000000001" fromto="0 0 0 -0.32006628884316651 0 0.70421111063799957"/>
            <site name="0/1/3/4/end4" class="0/1/3/4/" size="0.0050000000000000001" pos="-0.32006628884316651 0 0.70421111063799957"/>
            <site name="0/1/3/4/attach5" class="0/1/3/4/" size="9.9999999999999995e-07 9.9999999999999995e-07 9.9999999999999995e-07" pos="-0.28917688228622418 0 0.63624811654376068"/>
            <body pos="-0.28917688228622418 0 0.63624811654376068" name="0/1/3/4/5/">
              <joint name="0/1/3/4/5/joint/" class="0/1/3/4/" type="hinge" axis="0 1 0" limited="true" stiffness="100" range="-31.023621796539807 31.023621796539807" armature="0.20000000000000001" damping="3.5"/>
              <geom name="0/1/3/4/5/geom" class="0/1/3/4/5/" type="capsule" contype="1" conaffinity="1" condim="3" size="0.049936109782529083" rgba="0.87068756593082008 0.92094496224329125 0.44692816323815043 1" friction="0.59999999999999998 0.10000000000000001 0.10000000000000001" fromto="0 0 0 -0.62912242599426205 0 -0.45558557072806583"/>
              <site name="0/1/3/4/5/end5" class="0/1/3/4/5/" size="0.0050000000000000001" pos="-0.62912242599426205 0 -0.45558557072806583"/>
              <site name="0/1/3/4/5/attach6" class="0/1/3/4/5/" size="9.9999999999999995e-07 9.9999999999999995e-07 9.9999999999999995e-07" pos="-0.60116862552262951 0 -0.4353425343718903"/>
              <body pos="-0.60116862552262951 0 -0.4353425343718903" name="0/1/3/4/5/6/">
                <joint name="0/1/3/4/5/6/joint/" class="0/1/3/4/5/" type="hinge" axis="0 1 0" limited="true" stiffness="100" range="-55.182955318606297 55.182955318606297" armature="0.20000000000000001" damping="3.5"/>
                <geom name="0/1/3/4/5/6/geom" class="0/1/3/4/5/6/" type="capsule" contype="1" conaffinity="1" condim="3" size="0.060143131397363547" rgba="0.72107807060778151 0.77087153978463419 0.23261630191861005 1" friction="0.59999999999999998 0.10000000000000001 0.10000000000000001" fromto="0 0 0 0.30914692574720481 0 -0.50801442842030342"/>
                <site name="0/1/3/4/5/6/end6" class="0/1/3/4/5/6/" size="0.0050000000000000001" pos="0.30914692574720481 0 -0.50801442842030342"/>
                <site name="0/1/3/4/5/6/attach7" class="0/1/3/4/5/6/" size="9.9999999999999995e-07 9.9999999999999995e-07 9.9999999999999995e-07" pos="0.21924375239386448 0 -0.36027849634244224"/>
                <body pos="0.21924375239386448 0 -0.36027849634244224" name="0/1/3/4/5/6/7/">
                  <joint name="0/1/3/4/5/6/7/joint/" class="0/1/3/4/5/6/" type="hinge" axis="0 1 0" limited="true" stiffness="100" range="-55.006386609060129 55.006386609060129" armature="0.20000000000000001" damping="3.5"/>
                  <geom name="0/1/3/4/5/6/7/geom" class="0/1/3/4/5/6/7/" type="capsule" contype="1" conaffinity="1" condim="3" size="0.061567813412689985" rgba="0.02830914178825561 0.69886451842769681 0.090721167274498415 1" friction="0.59999999999999998 0.10000000000000001 0.10000000000000001" fromto="0 0 0 -0.51756573899523406 0 -0.030766495084202816"/>
                  <site name="0/1/3/4/5/6/7/end7" class="0/1/3/4/5/6/7/" size="0.0050000000000000001" pos="-0.51756573899523406 0 -0.030766495084202816"/>
                </body>
                <site name="0/1/3/4/5/6/attach8" class="0/1/3/4/5/6/" size="9.9999999999999995e-07 9.9999999999999995e-07 9.9999999999999995e-07" pos="0.20714819439084439 0 -0.34040212859116292"/>
                <body pos="0.20714819439084439 0 -0.34040212859116292" name="0/1/3/4/5/6/8/">
                  <joint name="0/1/3/4/5/6/8/joint/" class="0/1/3/4/5/6/" type="hinge" axis="0 1 0" limited="true" stiffness="100" range="-69.287993735091021 69.287993735091021" armature="0.20000000000000001" damping="3.5"/>
                  <geom name="0/1/3/4/5/6/8/geom" class="0/1/3/4/5/6/8/" type="capsule" contype="1" conaffinity="1" condim="3" size="0.064433645110030441" rgba="0.46257896259586362 0.49186664101522148 0.97633887818880194 1" friction="0.59999999999999998 0.10000000000000001 0.10000000000000001" fromto="0 0 0 0.2253453535886627 0 0.30201146293589209"/>
                  <site name="0/1/3/4/5/6/8/end8" class="0/1/3/4/5/6/8/" size="0.0050000000000000001" pos="0.2253453535886627 0 0.30201146293589209"/>
                  <site name="0/1/3/4/5/6/8/attach9" class="0/1/3/4/5/6/8/" size="9.9999999999999995e-07 9.9999999999999995e-07 9.9999999999999995e-07" pos="0.080729582015254431 0 0.10819508269575751"/>
                  <body pos="0.080729582015254431 0 0.10819508269575751" name="0/1/3/4/5/6/8/9/">
                    <geom name="0/1/3/4/5/6/8/9/geom" class="0/1/3/4/5/6/8/9/" type="capsule" contype="1" conaffinity="1" condim="3" size="0.064875713180567479" rgba="0.41503335927285201 0.28144227056093341 0.23948578072567739 1" friction="0.59999999999999998 0.10000000000000001 0.10000000000000001" fromto="0 0 0 0.57028910461806848 0 -0.15622430252208774"/>
                    <site name="0/1/3/4/5/6/8/9/end9" class="0/1/3/4/5/6/8/9/" size="0.0050000000000000001" pos="0.57028910461806848 0 -0.15622430252208774"/>
                    <site name="0/1/3/4/5/6/8/9/attach10" class="0/1/3/4/5/6/8/9/" size="9.9999999999999995e-07 9.9999999999999995e-07 9.9999999999999995e-07" pos="0.34030366625155978 0 -0.093222371732778975"/>
                    <body pos="0.34030366625155978 0 -0.093222371732778975" name="0/1/3/4/5/6/8/9/10/">
                      <joint name="0/1/3/4/5/6/8/9/10/joint/" class="0/1/3/4/5/6/8/9/" type="hinge" axis="0 1 0" limited="true" stiffness="100" range="-36.081719034709799 36.081719034709799" armature="0.20000000000000001" damping="3.5"/>
                      <geom name="0/1/3/4/5/6/8/9/10/geom" class="0/1/3/4/5/6/8/9/10/" type="capsule" contype="1" conaffinity="1" condim="3" size="0.040832426622934667" rgba="0.90499734610380722 0.95801893911002833 0.43521723843286153 1" friction="0.59999999999999998 0.10000000000000001 0.10000000000000001" fromto="0 0 0 -0.28762207875719165 0 -0.55648395291891206"/>
                      <site name="0/1/3/4/5/6/8/9/10/end10" class="0/1/3/4/5/6/8/9/10/" size="0.0050000000000000001" pos="-0.28762207875719165 0 -0.55648395291891206"/>
                    </body>
                  </body>
                </body>
              </body>
            </body>
          </body>
        </body>
      </body>
      <camera name="0/side" class="0/" mode="trackcom" pos="0.40000000000000002 -4 0.20000000000000001" quat="0.70699999999999996 0.70699999999999996 0 0"/>
    </body>
  </worldbody>
  <actuator>
    <motor name="0/1/motor" class="0/1/" ctrllimited="true" ctrlrange="-1 1" gear="65" joint="0/1/joint/"/>
    <motor name="0/1/2/motor" class="0/1/2/" ctrllimited="true" ctrlrange="-1 1" gear="51" joint="0/1/2/joint/"/>
    <motor name="0/1/3/4/motor" class="0/1/3/4/" ctrllimited="true" ctrlrange="-1 1" gear="73" joint="0/1/3/4/joint/"/>
    <motor name="0/1/3/4/5/motor" class="0/1/3/4/5/" ctrllimited="true" ctrlrange="-1 1" gear="59" joint="0/1/3/4/5/joint/"/>
    <motor name="0/1/3/4/5/6/motor" class="0/1/3/4/5/6/" ctrllimited="true" ctrlrange="-1 1" gear="80" joint="0/1/3/4/5/6/joint/"/>
    <motor name="0/1/3/4/5/6/7/motor" class="0/1/3/4/5/6/7/" ctrllimited="true" ctrlrange="-1 1" gear="77" joint="0/1/3/4/5/6/7/joint/"/>
    <motor name="0/1/3/4/5/6/8/motor" class="0/1/3/4/5/6/8/" ctrllimited="true" ctrlrange="-1 1" gear="88" joint="0/1/3/4/5/6/8/joint/"/>
    <motor name="0/1/3/4/5/6/8/9/10/motor" class="0/1/3/4/5/6/8/9/10/" ctrllimited="true" ctrlrange="-1 1" gear="80" joint="0/1/3/4/5/6/8/9/10/joint/"/>
  </actuator>
  <sensor>
    <subtreelinvel name="velocity" body="0/"/>
  </sensor>
</mujoco>
