<mujoco model="morphology">
  <option timestep="0.01"/>
  <default>
    <default class="/"/>
    <default class="0/"/>
    <default class="0/1/"/>
    <default class="0/1/2/"/>
    <default class="0/1/3/"/>
    <default class="0/1/3/4/"/>
    <default class="0/1/3/4/5/"/>
    <default class="0/1/3/4/5/6/"/>
    <default class="0/1/3/4/5/6/7/"/>
    <default class="0/1/3/4/5/6/7/8/"/>
    <default class="0/1/3/4/5/6/7/8/9/"/>
    <default class="0/1/3/4/5/6/7/10/"/>
  </default>
  <asset>
    <texture name="texplane" type="2d" builtin="checker" rgb1="0.10000000000000001 0.20000000000000001 0.29999999999999999" rgb2="0.20000000000000001 0.29999999999999999 0.40000000000000002" width="300" height="300"/>
    <material name="MatPlane" class="/" texture="texplane" texrepeat="20 20" specular="1" shininess="1" reflectance="0.5"/>
  </asset>
  <worldbody>
    <light name="//unnamed_light_0" class="/" directional="true" pos="0 0 1.5" dir="0 0 -1.3" cutoff="100" exponent="1" diffuse="1 1 1" specular="0.10000000000000001 0.10000000000000001 0.10000000000000001"/>
    <geom name="ground" class="/" type="plane" size="15 15 0.5" material="MatPlane" rgba="1 1 1 1"/>
    <site name="body" class="/" size="9.9999999999999995e-07 9.9999999999999995e-07 9.9999999999999995e-07" pos="0 0 0.10000000000000001"/>
    <body pos="0 0 0.10000000000000001" name="0/">
      <joint name="0/rootx/" class="/" type="slide" axis="1 0 0" limited="false" stiffness="0" armature="0" damping="0"/>
      <joint name="0/rootz/" class="/" type="slide" axis="0 0 1" limited="false" stiffness="0" armature="0" damping="0"/>
      <joint name="0/rooty/" class="/" type="hinge" axis="0 1 0" limited="false" stiffness="0" armature="0" damping="0"/>
      <geom name="0/geom" class="0/" type="capsule" contype="1" conaffinity="1" condim="3" size="0.046042335833509883" rgba="0.23119961207517226 0.44319345367856966 0.034822775738834633 1" friction="0.59999999999999998 0.10000000000000001 0.10000000000000001" fromto="0 0 0 0.68503488215168673 0 0.41609461137198922"/>
      <site name="0/end0" class="0/" size="0.0050000000000000001" pos="0.68503488215168673 0 0.41609461137198922"/>
      <site name="0/attach1" class="0/" size="9.9999999999999995e-07 9.9999999999999995e-07 9.9999999999999995e-07" pos="0.53691549272524752 0 0.32612593767983195"/>
      <body pos="0.53691549272524752 0 0.32612593767983195" name="0/1/">
        <geom name="0/1/geom" class="0/1/" type="capsule" contype="1" conaffinity="1" condim="3" size="0.063798632418285317" rgba="0.33692036011558846 0.41375571882098217 0.4518429124019796 1" friction="0.59999999999999998 0.10000000000000001 0.10000000000000001" fromto="0 0 0 0.15028251393703163 0 0.72088932286496177"/>
        <site name="0/1/end1" class="0/1/" size="0.0050000000000000001" pos="0.15028251393703163 0 0.72088932286496177"/>
        <site name="0/1/attach2" class="0/1/" size="9.9999999999999995e-07 9.9999999999999995e-07 9.9999999999999995e-07" pos="0.14684341902170309 0 0.70439234833458952"/>
        <body pos="0.14684341902170309 0 0.70439234833458952" name="0/1/2/">
          <joint name="0/1/2/joint/" class="0/1/" type="hinge" axis="0 1 0" limited="true" stiffness="100" range="-45.383813352445763 45.383813352445763" armature="0.20000000000000001" damping="3.5"/>
          <geom name="0/1/2/geom" class="0/1/2/" type="capsule" contype="1" conaffinity="1" condim="3" size="0.043792702093618116" rgba="0.3560061037103629 0.83986020119813309 0.83541512643479976 1" friction="0.59999999999999998 0.10000000000000001 0.10000000000000001" fromto="0 0 0 -0.41945492057060824 0 0.16602802623072943"/>
          <site name="0/1/2/end2" class="0/1/2/" size="0.0050000000000000001" pos="-0.41945492057060824 0 0.16602802623072943"/>
        </body>
        <site name="0/1/attach3" class="0/1/" size="9.9999999999999995e-07 9.9999999999999995e-07 9.9999999999999995e-07" pos="0.13344689414831334 0 0.64013063556627636"/>
        <body pos="0.13344689414831334 0 0.64013063556627636" name="0/1/3/">
          <joint name="0/1/3/joint/" class="0/1/" type="hinge" axis="0 1 0" limited="true" stiffness="100" range="-69.552900449680706 69.552900449680706" armature="0.20000000000000001" damping="3.5"/>
          <geom name="0/1/3/geom" class="0/1/3/" type="capsule" contype="1" conaffinity="1" condim="3" size="0.051056309840512737" rgba="0.27769374710067196 0.39943309759761803 0.9085225268764956 1" friction="0.59999999999999998 0.10000000000000001 0.10000000000000001" fromto="0 0 0 -0.54898822257509527 0 0.080773502011393772"/>
          <site name="0/1/3/end3" class="0/1/3/" size="0.0050000000000000001" pos="-0.54898822257509527 0 0.080773502011393772"/>
          <site name="0/1/3/attach4" class="0/1/3/" size="9.9999999999999995e-07 9.9999999999999995e-07 9.9999999999999995e-07" pos="-0.3142337668633467 0 0.046233709132644359"/>
          <body pos="-0.3142337668633467 0 0.046233709132644359" name="0/1/3/4/">
            <geom name="0/1/3/4/geom" class="0/1/3/4/" type="capsule" contype="1" conaffinity="1" condim="3" size="0.056371970146785744" rgba="0.25274796660676524 0.15061727157735494 0.17178333912917554 1" friction="0.59999999999999998 0.10000000000000001 0.10000000000000001" fromto="0 0 0 0.021366492949948634 0 -0.6417685677515188"/>
            <site name="0/1/3/4/end4" class="0/1/3/4/" size="0.0050000000000000001" pos="0.021366492949948634 0 -0.6417685677515188"/>
            <site name="0/1/3/4/attach5" class="0/1/3/4/" size="9.9999999999999995e-07 9.9999999999999995e-07 9.9999999999999995e-07" pos="0.020411982679490456 0 -0.61309869241863069"/>
            <body pos="0.020411982679490456 0 -0.61309869241863069" name="0/1/3/4/5/">
              <joint name="0/1/3/4/5/joint/" class="0/1/3/4/" type="hinge" axis="0 1 0" limited="true" stiffness="100" range="-67.409271043687653 67.409271043687653" armature="0.20000000000000001" damping="3.5"/>
              <geom name="0/1/3/4/5/geom" class="0/1/3/4/5/" type="capsule" contype="1" conaffinity="1" condim="3" size="0.059263600523592613" rgba="0.51670012875959859 0.94304887805259074 0.27107682748698314 1" friction="0.59999999999999998 0.10000000000000001 0.10000000000000001" fromto="0 0 0 -0.52699637963850032 0 0.19416446290521205"/>
              <site name="0/1/3/4/5/end5" class="0/1/3/4/5/" size="0.0050000000000000001" pos="-0.52699637963850032 0 0.19416446290521205"/>
              <site name="0/1/3/4/5/attach6" class="0/1/3/4/5/" size="9.9999999999999995e-07 9.9999999999999995e-07 9.9999999999999995e-07" pos="-0.51333539849199417 0 0.18913126501324726"/>
              <body pos="-0.51333539849199417 0 0.18913126501324726" name="0/1/3/4/5/6/">
                <geom name="0/1/3/4/5/6/geom" class="0/1/3/4/5/6/" type="capsule" contype="1" conaffinity="1" condim="3" size="0.06459706519899619" rgba="0.9147004990941705 0.21702505310353049 0.78115255824200169 1" friction="0.59999999999999998 0.10000000000000001 0.10000000000000001" fromto="0 0 0 -0.60133155119642812 0 0.15876613972281406"/>
                <site name="0/1/3/4/5/6/end6" class="0/1/3/4/5/6/" size="0.0050000000000000001" pos="-0.60133155119642812 0 0.15876613972281406"/>
                <site name="0/1/3/4/5/6/attach7" class="0/1/3/4/5/6/" size="9.9999999999999995e-07 9.9999999999999995e-07 9.9999999999999995e-07" pos="-0.44959319325089786 0 0.11870352652555476"/>
                <body pos="-0.44959319325089786 0 0.11870352652555476" name="0/1/3/4/5/6/7/">
                  <joint name="0/1/3/4/5/6/7/joint/" class="0/1/3/4/5/6/" type="hinge" axis="0 1 0" limited="true" stiffness="100" range="-36.078518957755939 36.078518957755939" armature="0.20000000000000001" damping="3.5"/>
                  <geom name="0/1/3/4/5/6/7/geom" class="0/1/3/4/5/6/7/" type="capsule" contype="1" conaffinity="1" condim="3" size="0.052890966324259402" rgba="0.68315507698003741 0.13926714585071154 0.50379483107324252 1" friction="0.59999999999999998 0.10000000000000001 0.10000000000000001" fromto="0 0 0 -0.2274098639742792 0 0.58629352460833495"/>
                  <site name="0/1/3/4/5/6/7/end7" class="0/1/3/4/5/6/7/" size="0.0050000000000000001" pos="-0.2274098639742792 0 0.58629352460833495"/>
                  <site name="0/1/3/4/5/6/7/attach8" class="0/1/3/4/5/6/7/" size="9.9999999999999995e-07 9.9999999999999995e-07 9.9999999999999995e-07" pos="-0.19304377590419747 0 0.49769308068085633"/>
                  <body pos="-0.19304377590419747 0 0.49769308068085633" name="0/1/3/4/5/6/7/8/">
                    <joint name="0/1/3/4/5/6/7/8/joint/" class="0/1/3/4/5/6/7/" type="hinge" axis="0 1 0" limited="true" stiffness="100" range="-50.005322663774145 50.005322663774145" armature="0.20000000000000001" damping="3.5"/>
                    <geom name="0/1/3/4/5/6/7/8/geom" class="0/1/3/4/5/6/7/8/" type="capsule" contype="1" conaffinity="1" condim="3" size="0.04801892903349668" rgba="0.88223215894075113 0.88458484041242069 0.7423676542045109 1" friction="0.59999999999999998 0.10000000000000001 0.10000000000000001" fromto="0 0 0 -0.29723247951989085 0 -0.1944742631728088"/>
                    <site name="0/1/3/4/5/6/7/8/end8" class="0/1/3/4/5/6/7/8/" size="0.0050000000000000001" pos="-0.29723247951989085 0 -0.1944742631728088"/>
                    <site name="0/1/3/4/5/6/7/8/attach9" class="0/1/3/4/5/6/7/8/" size="9.9999999999999995e-07 9.9999999999999995e-07 9.9999999999999995e-07" pos="-0.26790976339406652 0 -0.17528889816153484"/>
                    <body pos="-0.26790976339406652 0 -0.17528889816153484" name="0/1/3/4/5/6/7/8/9/">
                      <joint name="0/1/3/4/5/6/7/8/9/joint/" class="0/1/3/4/5/6/7/8/" type="hinge" axis="0 1 0" limited="true" stiffness="100" range="-48.487678521321001 48.487678521321001" armature="0.20000000000000001" damping="3.5"/>
                      <geom name="0/1/3/4/5/6/7/8/9/geom" class="0/1/3/4/5/6/7/8/9/" type="capsule" contype="1" conaffinity="1" condim="3" size="0.065025646839660681" rgba="0.19945274210829655 0.88430478674223156 0.36572582341069126 1" friction="0.59999999999999998 0.10000000000000001 0.10000000000000001" fromto="0 0 0 -0.70926046228301343 0 0.7018588385210931"/>
                      <site name="0/1/3/4/5/6/7/8/9/end9" class="0/1/3/4/5/6/7/8/9/" size="0.0050000000000000001" pos="-0.70926046228301343 0 0.7018588385210931"/>
                    </body>
                  </body>
                  <site name="0/1/3/4/5/6/7/attach10" class="0/1/3/4/5/6/7/" size="9.9999999999999995e-07 9.9999999999999995e-07 9.9999999999999995e-07" pos="-0.22217055303014785 0 0.57278586919589769"/>
                  <body pos="-0.22217055303014785 0 0.57278586919589769" name="0/1/3/4/5/6/7/10/">
                    <joint name="0/1/3/4/5/6/7/10/joint/" class="0/1/3/4/5/6/7/" type="hinge" axis="0 1 0" limited="true" stiffness="100" range="-44.933803347173239 44.933803347173239" armature="0.20000000000000001" damping="3.5"/>
                    <geom name="0/1/3/4/5/6/7/10/geom" class="0/1/3/4/5/6/7/10/" type="capsule" contype="1" conaffinity="1" condim="3" size="0.06304209918220241" rgba="0.84997593379869085 0.5466263065725826 0.078618165852683108 1" friction="0.59999999999999998 0.10000000000000001 0.10000000000000001" fromto="0 0 0 -0.56750563691477085 0 0.70228912588750236"/>
                    <site name="0/1/3/4/5/6/7/10/end10" class="0/1/3/4/5/6/7/10/" size="0.0050000000000000001" pos="-0.56750563691477085 0 0.70228912588750236"/>
                  </body>
                </body>
              </body>
            </body>
          </body>
        </body>
      </body>
      <camera name="0/side" class="0/" mode="trackcom" pos="0.40000000000000002 -4 0.20000000000000001" quat="0.70699999999999996 0.70699999999999996 0 0"/>
    </body>
  </worldbody>
  <actuator>
    <motor name="0/1/2/motor" class="0/1/2/" ctrllimited="true" ctrlrange="-1 1" gear="61" joint="0/1/2/joint/"/>
    <motor name="0/1/3/motor" class="0/1/3/" ctrllimited="true" ctrlrange="-1 1" gear="73" joint="0/1/3/joint/"/>
    <motor name="0/1/3/4/5/motor" class="0/1/3/4/5/" ctrllimited="true" ctrlrange="-1 1" gear="85" joint="0/1/3/4/5/joint/"/>
    <motor name="0/1/3/4/5/6/7/motor" class="0/1/3/4/5/6/7/" ctrllimited="true" ctrlrange="-1 1" gear="76" joint="0/1/3/4/5/6/7/joint/"/>
    <motor name="0/1/3/4/5/6/7/8/motor" class="0/1/3/4/5/6/7/8/" ctrllimited="true" ctrlrange="-1 1" gear="78" joint="0/1/3/4/5/6/7/8/joint/"/>
    <motor name="0/1/3/4/5/6/7/8/9/motor" class="0/1/3/4/5/6/7/8/9/" ctrllimited="true" ctrlrange="-1 1" gear="83" joint="0/1/3/4/5/6/7/8/9/joint/"/>
    <motor name="0/1/3/4/5/6/7/10/motor" class="0/1/3/4/5/6/7/10/" ctrllimited="true" ctrlrange="-1 1" gear="50" joint="0/1/3/4/5/6/7/10/joint/"/>
  </actuator>
  <sensor>
    <subtreelinvel name="velocity" body="0/"/>
  </sensor>
</mujoco>
