<mujoco model="morphology">
  <option timestep="0.01"/>
  <default>
    <default class="/"/>
    <default class="0/"/>
    <default class="0/1/"/>
    <default class="0/1/2/"/>
    <default class="0/1/2/3/"/>
    <default class="0/1/2/3/4/"/>
    <default class="0/1/2/3/4/5/"/>
    <default class="0/1/2/3/4/5/6/"/>
    <default class="0/1/2/3/4/5/6/7/"/>
  </default>
  <asset>
    <texture name="texplane" type="2d" builtin="checker" rgb1="0.10000000000000001 0.20000000000000001 0.29999999999999999" rgb2="0.20000000000000001 0.29999999999999999 0.40000000000000002" width="300" height="300"/>
    <material name="MatPlane" class="/" texture="texplane" texrepeat="20 20" specular="1" shininess="1" reflectance="0.5"/>
  </asset>
  <worldbody>
    <light name="//unnamed_light_0" class="/" directional="true" pos="0 0 1.5" dir="0 0 -1.3" cutoff="100" exponent="1" diffuse="1 1 1" specular="0.10000000000000001 0.10000000000000001 0.10000000000000001"/>
    <geom name="ground" class="/" type="plane" size="15 15 0.5" material="MatPlane" rgba="1 1 1 1"/>
    <site name="body" class="/" size="9.9999999999999995e-07 9.9999999999999995e-07 9.9999999999999995e-07" pos="0 0 0.90764895677566526"/>
    <body pos="0 0 0.90764895677566526" name="0/">
      <joint name="0/rootx/" class="/" type="slide" axis="1 0 0" limited="false" stiffness="0" armature="0" damping="0"/>
      <joint name="0/rootz/" class="/" type="slide" axis="0 0 1" limited="false" stiffness="0" armature="0" damping="0"/>
      <joint name="0/rooty/" class="/" type="hinge" axis="0 1 0" limited="false" stiffness="0" armature="0" damping="0"/>
      <geom name="0/geom" class="0/" type="capsule" contype="1" conaffinity="1" condim="3" size="0.041895437908112183" rgba="0.93795825693144552 0.80186830876119342 0.95070234518416674 1" friction="0.59999999999999998 0.10000000000000001 0.10000000000000001" fromto="0 0 0 -0.14853391416827899 0 0.64592817565703431"/>
      <site name="0/end0" class="0/" size="0.0050000000000000001" pos="-0.14853391416827899 0 0.64592817565703431"/>
      <site name="0/attach1" class="0/" size="9.9999999999999995e-07 9.9999999999999995e-07 9.9999999999999995e-07" pos="-0.091182751499438094 0 0.396525659861719"/>
      <body pos="-0.091182751499438094 0 0.396525659861719" name="0/1/">
        <joint name="0/1/joint/" class="0/" type="hinge" axis="0 1 0" limited="true" range="-49.29009709656259 49.29009709656259"/>
        <geom name="0/1/geom" class="0/1/" type="capsule" contype="1" conaffinity="1" condim="3" size="0.050256881657772534" rgba="0.071082818505926793 0.73725291175017171 0.81227710631160421 1" friction="0.59999999999999998 0.10000000000000001 0.10000000000000001" fromto="0 0 0 -0.54062257406105574 0 -0.21070070561334742"/>
        <site name="0/1/end1" class="0/1/" size="0.0050000000000000001" pos="-0.54062257406105574 0 -0.21070070561334742"/>
        <site name="0/1/attach2" class="0/1/" size="9.9999999999999995e-07 9.9999999999999995e-07 9.9999999999999995e-07" pos="-0.51094369273463791 0 -0.1991337427499269"/>
        <body pos="-0.51094369273463791 0 -0.1991337427499269" name="0/1/2/">
          <joint name="0/1/2/joint/" class="0/1/" type="hinge" axis="0 1 0" limited="true" range="-64.39911783982518 64.39911783982518"/>
          <geom name="0/1/2/geom" class="0/1/2/" type="capsule" contype="1" conaffinity="1" condim="3" size="0.057036737670640464" rgba="0.27004448537616255 0.086658853991611995 0.86793043797494851 1" friction="0.59999999999999998 0.10000000000000001 0.10000000000000001" fromto="0 0 0 0.48234843195330579 0 -0.41227594872977746"/>
          <site name="0/1/2/end2" class="0/1/2/" size="0.0050000000000000001" pos="0.48234843195330579 0 -0.41227594872977746"/>
          <site name="0/1/2/attach3" class="0/1/2/" size="9.9999999999999995e-07 9.9999999999999995e-07 9.9999999999999995e-07" pos="0.083282208600416477 0 -0.071183504057439936"/>
          <body pos="0.083282208600416477 0 -0.071183504057439936" name="0/1/2/3/">
            <joint name="0/1/2/3/joint/" class="0/1/2/" type="hinge" axis="0 1 0" limited="true" range="-53.070224647866752 53.070224647866752"/>
            <geom name="0/1/2/3/geom" class="0/1/2/3/" type="capsule" contype="1" conaffinity="1" condim="3" size="0.051552455480402298" rgba="0.96184326803084841 0.83565286394321803 0.527083592693953 1" friction="0.59999999999999998 0.10000000000000001 0.10000000000000001" fromto="0 0 0 0.37261691173797606 0 0.151583861346541"/>
            <site name="0/1/2/3/end3" class="0/1/2/3/" size="0.0050000000000000001" pos="0.37261691173797606 0 0.151583861346541"/>
            <site name="0/1/2/3/attach4" class="0/1/2/3/" size="9.9999999999999995e-07 9.9999999999999995e-07 9.9999999999999995e-07" pos="0.010263585584022888 0 0.0041753175582672306"/>
            <body pos="0.010263585584022888 0 0.0041753175582672306" name="0/1/2/3/4/">
              <joint name="0/1/2/3/4/joint/" class="0/1/2/3/" type="hinge" axis="0 1 0" limited="true" range="-48.709531080527725 48.709531080527725"/>
              <geom name="0/1/2/3/4/geom" class="0/1/2/3/4/" type="capsule" contype="1" conaffinity="1" condim="3" size="0.057669642633643034" rgba="0.13684975830707291 0.0047399019580648405 0.70583430606692665 1" friction="0.59999999999999998 0.10000000000000001 0.10000000000000001" fromto="0 0 0 -0.23970336741582943 0 -0.56383515092034298"/>
              <site name="0/1/2/3/4/end4" class="0/1/2/3/4/" size="0.0050000000000000001" pos="-0.23970336741582943 0 -0.56383515092034298"/>
              <site name="0/1/2/3/4/attach5" class="0/1/2/3/4/" size="9.9999999999999995e-07 9.9999999999999995e-07 9.9999999999999995e-07" pos="-0.098179525312282329 0 -0.23093988235762555"/>
              <body pos="-0.098179525312282329 0 -0.23093988235762555" name="0/1/2/3/4/5/">
                <joint name="0/1/2/3/4/5/joint/" class="0/1/2/3/4/" type="hinge" axis="0 1 0" limited="true" range="-48.418655870896863 48.418655870896863"/>
                <geom name="0/1/2/3/4/5/geom" class="0/1/2/3/4/5/" type="capsule" contype="1" conaffinity="1" condim="3" size="0.044798681687638772" rgba="0.37874507549514136 0.087666018815514501 0.19137519457336027 1" friction="0.59999999999999998 0.10000000000000001 0.10000000000000001" fromto="0 0 0 0.35254427545665656 0 -0.2497600584257389"/>
                <site name="0/1/2/3/4/5/end5" class="0/1/2/3/4/5/" size="0.0050000000000000001" pos="0.35254427545665656 0 -0.2497600584257389"/>
                <site name="0/1/2/3/4/5/attach6" class="0/1/2/3/4/5/" size="9.9999999999999995e-07 9.9999999999999995e-07 9.9999999999999995e-07" pos="0.21491815471777445 0 -0.15225880723643395"/>
                <body pos="0.21491815471777445 0 -0.15225880723643395" name="0/1/2/3/4/5/6/">
                  <joint name="0/1/2/3/4/5/6/joint/" class="0/1/2/3/4/5/" type="hinge" axis="0 1 0" limited="true" range="-64.323669515450945 64.323669515450945"/>
                  <geom name="0/1/2/3/4/5/6/geom" class="0/1/2/3/4/5/6/" type="capsule" contype="1" conaffinity="1" condim="3" size="0.06513191451211936" rgba="0.40166259850606234 0.58635875231067014 0.27264118066126741 1" friction="0.59999999999999998 0.10000000000000001 0.10000000000000001" fromto="0 0 0 -0.28534226631204251 0 -0.28011315327257225"/>
                  <site name="0/1/2/3/4/5/6/end6" class="0/1/2/3/4/5/6/" size="0.0050000000000000001" pos="-0.28534226631204251 0 -0.28011315327257225"/>
                  <site name="0/1/2/3/4/5/6/attach7" class="0/1/2/3/4/5/6/" size="9.9999999999999995e-07 9.9999999999999995e-07 9.9999999999999995e-07" pos="-0.1418508666727189 0 -0.13925134215724697"/>
                  <body pos="-0.1418508666727189 0 -0.13925134215724697" name="0/1/2/3/4/5/6/7/">
                    <geom name="0/1/2/3/4/5/6/7/geom" class="0/1/2/3/4/5/6/7/" type="capsule" contype="1" conaffinity="1" condim="3" size="0.049537688501414295" rgba="0.37814997503962933 0.88669922081301189 0.41550461512764314 1" friction="0.59999999999999998 0.10000000000000001 0.10000000000000001" fromto="0 0 0 0.54264980854330602 0 -0.4155826849216121"/>
                    <site name="0/1/2/3/4/5/6/7/end7" class="0/1/2/3/4/5/6/7/" size="0.0050000000000000001" pos="0.54264980854330602 0 -0.4155826849216121"/>
                  </body>
                </body>
              </body>
            </body>
          </body>
        </body>
      </body>
      <camera name="0/side" class="0/" mode="trackcom" pos="0.40000000000000002 -4 0.20000000000000001" quat="0.70699999999999996 0.70699999999999996 0 0"/>
    </body>
  </worldbody>
  <actuator>
    <motor name="0/1/motor" class="0/1/" ctrllimited="true" ctrlrange="-1 1" gear="73" joint="0/1/joint/"/>
    <motor name="0/1/2/motor" class="0/1/2/" ctrllimited="true" ctrlrange="-1 1" gear="65" joint="0/1/2/joint/"/>
    <motor name="0/1/2/3/motor" class="0/1/2/3/" ctrllimited="true" ctrlrange="-1 1" gear="68" joint="0/1/2/3/joint/"/>
    <motor name="0/1/2/3/4/motor" class="0/1/2/3/4/" ctrllimited="true" ctrlrange="-1 1" gear="67" joint="0/1/2/3/4/joint/"/>
    <motor name="0/1/2/3/4/5/motor" class="0/1/2/3/4/5/" ctrllimited="true" ctrlrange="-1 1" gear="76" joint="0/1/2/3/4/5/joint/"/>
    <motor name="0/1/2/3/4/5/6/motor" class="0/1/2/3/4/5/6/" ctrllimited="true" ctrlrange="-1 1" gear="70" joint="0/1/2/3/4/5/6/joint/"/>
  </actuator>
  <sensor>
    <subtreelinvel name="velocity" body="0/"/>
  </sensor>
</mujoco>
