<mujoco model="morphology">
  <option timestep="0.01"/>
  <default>
    <default class="/"/>
    <default class="0/"/>
    <default class="0/1/"/>
    <default class="0/2/"/>
    <default class="0/2/3/"/>
    <default class="0/2/4/"/>
    <default class="0/2/4/5/"/>
    <default class="0/2/4/6/"/>
    <default class="0/2/4/6/7/"/>
    <default class="0/2/4/6/7/8/"/>
    <default class="0/2/4/6/7/8/9/"/>
    <default class="0/2/4/6/7/8/10/"/>
  </default>
  <asset>
    <texture name="texplane" type="2d" builtin="checker" rgb1="0.10000000000000001 0.20000000000000001 0.29999999999999999" rgb2="0.20000000000000001 0.29999999999999999 0.40000000000000002" width="300" height="300"/>
    <material name="MatPlane" class="/" texture="texplane" texrepeat="20 20" specular="1" shininess="1" reflectance="0.5"/>
  </asset>
  <worldbody>
    <light name="//unnamed_light_0" class="/" directional="true" pos="0 0 1.5" dir="0 0 -1.3" cutoff="100" exponent="1" diffuse="1 1 1" specular="0.10000000000000001 0.10000000000000001 0.10000000000000001"/>
    <geom name="ground" class="/" type="plane" size="15 15 0.5" material="MatPlane" rgba="1 1 1 1"/>
    <site name="body" class="/" size="9.9999999999999995e-07 9.9999999999999995e-07 9.9999999999999995e-07" pos="0 0 0.82136974334716795"/>
    <body pos="0 0 0.82136974334716795" name="0/">
      <joint name="0/rootx/" class="/" type="slide" axis="1 0 0" limited="false" stiffness="0" armature="0" damping="0"/>
      <joint name="0/rootz/" class="/" type="slide" axis="0 0 1" limited="false" stiffness="0" armature="0" damping="0"/>
      <joint name="0/rooty/" class="/" type="hinge" axis="0 1 0" limited="false" stiffness="0" armature="0" damping="0"/>
      <geom name="0/geom" class="0/" type="capsule" contype="1" conaffinity="1" condim="3" size="0.047597975604602882" rgba="0.22719833095802344 0.20431869463495245 0.67321762428528187 1" friction="0.59999999999999998 0.10000000000000001 0.10000000000000001" fromto="0 0 0 -0.028870326342730568 0 -0.7213697501400671"/>
      <site name="0/end0" class="0/" size="0.0050000000000000001" pos="-0.028870326342730568 0 -0.7213697501400671"/>
      <site name="0/attach1" class="0/" size="9.9999999999999995e-07 9.9999999999999995e-07 9.9999999999999995e-07" pos="-0.023847642845422384 0 -0.59587023563949226"/>
      <body pos="-0.023847642845422384 0 -0.59587023563949226" name="0/1/">
        <joint name="0/1/joint/" class="0/" type="hinge" axis="0 1 0" limited="true" stiffness="100" range="-63.536994842335652 63.536994842335652" armature="0.20000000000000001" damping="3.5"/>
        <geom name="0/1/geom" class="0/1/" type="capsule" contype="1" conaffinity="1" condim="3" size="0.042062539212790885" rgba="0.19108290777918768 0.75528139804661842 0.78494481658986881 1" friction="0.59999999999999998 0.10000000000000001 0.10000000000000001" fromto="0 0 0 0.71690068572851384 0 0.1219481570221842"/>
        <site name="0/1/end1" class="0/1/" size="0.0050000000000000001" pos="0.71690068572851384 0 0.1219481570221842"/>
      </body>
      <site name="0/attach2" class="0/" size="9.9999999999999995e-07 9.9999999999999995e-07 9.9999999999999995e-07" pos="-0.0022367863831380232 0 -0.055889566857191604"/>
      <body pos="-0.0022367863831380232 0 -0.055889566857191604" name="0/2/">
        <joint name="0/2/joint/" class="0/" type="hinge" axis="0 1 0" limited="true" stiffness="100" range="-43.219521341435396 43.219521341435396" armature="0.20000000000000001" damping="3.5"/>
        <geom name="0/2/geom" class="0/2/" type="capsule" contype="1" conaffinity="1" condim="3" size="0.052136060902135087" rgba="0.77089997059461235 0.10165351312807835 0.44293653067887606 1" friction="0.59999999999999998 0.10000000000000001 0.10000000000000001" fromto="0 0 0 -0.64563985466237017 0 0.34582387418721305"/>
        <site name="0/2/end2" class="0/2/" size="0.0050000000000000001" pos="-0.64563985466237017 0 0.34582387418721305"/>
        <site name="0/2/attach3" class="0/2/" size="9.9999999999999995e-07 9.9999999999999995e-07 9.9999999999999995e-07" pos="-0.56554077106799761 0 0.30292042699847527"/>
        <body pos="-0.56554077106799761 0 0.30292042699847527" name="0/2/3/">
          <joint name="0/2/3/joint/" class="0/2/" type="hinge" axis="0 1 0" limited="true" stiffness="100" range="-58.770247123433023 58.770247123433023" armature="0.20000000000000001" damping="3.5"/>
          <geom name="0/2/3/geom" class="0/2/3/" type="capsule" contype="1" conaffinity="1" condim="3" size="0.049971250705687496" rgba="0.4409929182847897 0.38151520011814921 0.21289149846466715 1" friction="0.59999999999999998 0.10000000000000001 0.10000000000000001" fromto="0 0 0 -0.24721093180178944 0 -0.59667634382673351"/>
          <site name="0/2/3/end3" class="0/2/3/" size="0.0050000000000000001" pos="-0.24721093180178944 0 -0.59667634382673351"/>
        </body>
        <site name="0/2/attach4" class="0/2/" size="9.9999999999999995e-07 9.9999999999999995e-07 9.9999999999999995e-07" pos="-0.1984375172219294 0 0.10628902552130365"/>
        <body pos="-0.1984375172219294 0 0.10628902552130365" name="0/2/4/">
          <geom name="0/2/4/geom" class="0/2/4/" type="capsule" contype="1" conaffinity="1" condim="3" size="0.068740904262308514" rgba="0.41717396621468816 0.89766309810497824 0.20782280134588427 1" friction="0.59999999999999998 0.10000000000000001 0.10000000000000001" fromto="0 0 0 0.54210311845630565 0 0.60641866350047402"/>
          <site name="0/2/4/end4" class="0/2/4/" size="0.0050000000000000001" pos="0.54210311845630565 0 0.60641866350047402"/>
          <site name="0/2/4/attach5" class="0/2/4/" size="9.9999999999999995e-07 9.9999999999999995e-07 9.9999999999999995e-07" pos="0.26764111154805953 0 0.2993942658454517"/>
          <body pos="0.26764111154805953 0 0.2993942658454517" name="0/2/4/5/">
            <joint name="0/2/4/5/joint/" class="0/2/4/" type="hinge" axis="0 1 0" limited="true" stiffness="100" range="-51.368030414729695 51.368030414729695" armature="0.20000000000000001" damping="3.5"/>
            <geom name="0/2/4/5/geom" class="0/2/4/5/" type="capsule" contype="1" conaffinity="1" condim="3" size="0.05090496137676663" rgba="0.70699202524528615 0.11248473101093637 0.80805257145308851 1" friction="0.59999999999999998 0.10000000000000001 0.10000000000000001" fromto="0 0 0 0.20233444144711499 0 -0.025239507550414153"/>
            <site name="0/2/4/5/end5" class="0/2/4/5/" size="0.0050000000000000001" pos="0.20233444144711499 0 -0.025239507550414153"/>
          </body>
          <site name="0/2/4/attach6" class="0/2/4/" size="9.9999999999999995e-07 9.9999999999999995e-07 9.9999999999999995e-07" pos="0.35575525779679573 0 0.39796234447189988"/>
          <body pos="0.35575525779679573 0 0.39796234447189988" name="0/2/4/6/">
            <joint name="0/2/4/6/joint/" class="0/2/4/" type="hinge" axis="0 1 0" limited="true" stiffness="100" range="-47.61543207373542 47.61543207373542" armature="0.20000000000000001" damping="3.5"/>
            <geom name="0/2/4/6/geom" class="0/2/4/6/" type="capsule" contype="1" conaffinity="1" condim="3" size="0.052560876962750538" rgba="0.29769082468626962 0.38194269146577886 0.88931613397219689 1" friction="0.59999999999999998 0.10000000000000001 0.10000000000000001" fromto="0 0 0 -0.25204414849373319 0 0.58684300827749758"/>
            <site name="0/2/4/6/end6" class="0/2/4/6/" size="0.0050000000000000001" pos="-0.25204414849373319 0 0.58684300827749758"/>
            <site name="0/2/4/6/attach7" class="0/2/4/6/" size="9.9999999999999995e-07 9.9999999999999995e-07 9.9999999999999995e-07" pos="-0.21142891354172941 0 0.49227716811190497"/>
            <body pos="-0.21142891354172941 0 0.49227716811190497" name="0/2/4/6/7/">
              <joint name="0/2/4/6/7/joint/" class="0/2/4/6/" type="hinge" axis="0 1 0" limited="true" stiffness="100" range="-56.107102067118333 56.107102067118333" armature="0.20000000000000001" damping="3.5"/>
              <geom name="0/2/4/6/7/geom" class="0/2/4/6/7/" type="capsule" contype="1" conaffinity="1" condim="3" size="0.06505227682553387" rgba="0.74967859861341968 0.85745669449731776 0.3548243210830504 1" friction="0.59999999999999998 0.10000000000000001 0.10000000000000001" fromto="0 0 0 0.6629123479926029 0 0.73054823334236874"/>
              <site name="0/2/4/6/7/end7" class="0/2/4/6/7/" size="0.0050000000000000001" pos="0.6629123479926029 0 0.73054823334236874"/>
              <site name="0/2/4/6/7/attach8" class="0/2/4/6/7/" size="9.9999999999999995e-07 9.9999999999999995e-07 9.9999999999999995e-07" pos="0.092346966874513034 0 0.10176898003030491"/>
              <body pos="0.092346966874513034 0 0.10176898003030491" name="0/2/4/6/7/8/">
                <joint name="0/2/4/6/7/8/joint/" class="0/2/4/6/7/" type="hinge" axis="0 1 0" limited="true" stiffness="100" range="-33.096296935480076 33.096296935480076" armature="0.20000000000000001" damping="3.5"/>
                <geom name="0/2/4/6/7/8/geom" class="0/2/4/6/7/8/" type="capsule" contype="1" conaffinity="1" condim="3" size="0.062720361499077282" rgba="0.46670491901587696 0.0012630645594032819 0.28786868915746133 1" friction="0.59999999999999998 0.10000000000000001 0.10000000000000001" fromto="0 0 0 -0.51857180675014591 0 0.36180446024453206"/>
                <site name="0/2/4/6/7/8/end8" class="0/2/4/6/7/8/" size="0.0050000000000000001" pos="-0.51857180675014591 0 0.36180446024453206"/>
                <site name="0/2/4/6/7/8/attach9" class="0/2/4/6/7/8/" size="9.9999999999999995e-07 9.9999999999999995e-07 9.9999999999999995e-07" pos="-0.50211441269094714 0 0.35032223445224397"/>
                <body pos="-0.50211441269094714 0 0.35032223445224397" name="0/2/4/6/7/8/9/">
                  <joint name="0/2/4/6/7/8/9/joint/" class="0/2/4/6/7/8/" type="hinge" axis="0 1 0" limited="true" stiffness="100" range="-54.121500903555393 54.121500903555393" armature="0.20000000000000001" damping="3.5"/>
                  <geom name="0/2/4/6/7/8/9/geom" class="0/2/4/6/7/8/9/" type="capsule" contype="1" conaffinity="1" condim="3" size="0.042959280949565713" rgba="0.8080047855350071 0.1882280521385663 0.38887196142367719 1" friction="0.59999999999999998 0.10000000000000001 0.10000000000000001" fromto="0 0 0 -0.62272581119009751 0 -0.40340977023314123"/>
                  <site name="0/2/4/6/7/8/9/end9" class="0/2/4/6/7/8/9/" size="0.0050000000000000001" pos="-0.62272581119009751 0 -0.40340977023314123"/>
                </body>
                <site name="0/2/4/6/7/8/attach10" class="0/2/4/6/7/8/" size="9.9999999999999995e-07 9.9999999999999995e-07 9.9999999999999995e-07" pos="-0.17251956714889999 0 0.12036587423658759"/>
                <body pos="-0.17251956714889999 0 0.12036587423658759" name="0/2/4/6/7/8/10/">
                  <joint name="0/2/4/6/7/8/10/joint/" class="0/2/4/6/7/8/" type="hinge" axis="0 1 0" limited="true" stiffness="100" range="-66.243248359355604 66.243248359355604" armature="0.20000000000000001" damping="3.5"/>
                  <geom name="0/2/4/6/7/8/10/geom" class="0/2/4/6/7/8/10/" type="capsule" contype="1" conaffinity="1" condim="3" size="0.05893006752672518" rgba="0.54243326024219318 0.27728450045855424 0.79310843248973595 1" friction="0.59999999999999998 0.10000000000000001 0.10000000000000001" fromto="0 0 0 -0.22460616636169084 0 -0.51449086650274711"/>
                  <site name="0/2/4/6/7/8/10/end10" class="0/2/4/6/7/8/10/" size="0.0050000000000000001" pos="-0.22460616636169084 0 -0.51449086650274711"/>
                </body>
              </body>
            </body>
          </body>
        </body>
      </body>
      <camera name="0/side" class="0/" mode="trackcom" pos="0.40000000000000002 -4 0.20000000000000001" quat="0.70699999999999996 0.70699999999999996 0 0"/>
    </body>
  </worldbody>
  <actuator>
    <motor name="0/1/motor" class="0/1/" ctrllimited="true" ctrlrange="-1 1" gear="89" joint="0/1/joint/"/>
    <motor name="0/2/motor" class="0/2/" ctrllimited="true" ctrlrange="-1 1" gear="84" joint="0/2/joint/"/>
    <motor name="0/2/3/motor" class="0/2/3/" ctrllimited="true" ctrlrange="-1 1" gear="53" joint="0/2/3/joint/"/>
    <motor name="0/2/4/5/motor" class="0/2/4/5/" ctrllimited="true" ctrlrange="-1 1" gear="59" joint="0/2/4/5/joint/"/>
    <motor name="0/2/4/6/motor" class="0/2/4/6/" ctrllimited="true" ctrlrange="-1 1" gear="50" joint="0/2/4/6/joint/"/>
    <motor name="0/2/4/6/7/motor" class="0/2/4/6/7/" ctrllimited="true" ctrlrange="-1 1" gear="73" joint="0/2/4/6/7/joint/"/>
    <motor name="0/2/4/6/7/8/motor" class="0/2/4/6/7/8/" ctrllimited="true" ctrlrange="-1 1" gear="69" joint="0/2/4/6/7/8/joint/"/>
    <motor name="0/2/4/6/7/8/9/motor" class="0/2/4/6/7/8/9/" ctrllimited="true" ctrlrange="-1 1" gear="71" joint="0/2/4/6/7/8/9/joint/"/>
    <motor name="0/2/4/6/7/8/10/motor" class="0/2/4/6/7/8/10/" ctrllimited="true" ctrlrange="-1 1" gear="55" joint="0/2/4/6/7/8/10/joint/"/>
  </actuator>
  <sensor>
    <subtreelinvel name="velocity" body="0/"/>
  </sensor>
</mujoco>
