<mujoco model="morphology">
  <option timestep="0.01"/>
  <default>
    <default class="/"/>
    <default class="0/"/>
    <default class="0/1/"/>
    <default class="0/1/2/"/>
    <default class="0/1/2/3/"/>
    <default class="0/1/2/3/4/"/>
    <default class="0/1/2/3/4/5/"/>
    <default class="0/1/2/3/4/5/6/"/>
    <default class="0/1/2/3/4/5/6/7/"/>
    <default class="0/1/2/3/4/5/6/8/"/>
    <default class="0/1/2/3/4/5/9/"/>
    <default class="0/1/2/3/4/5/9/10/"/>
  </default>
  <asset>
    <texture name="texplane" type="2d" builtin="checker" rgb1="0.10000000000000001 0.20000000000000001 0.29999999999999999" rgb2="0.20000000000000001 0.29999999999999999 0.40000000000000002" width="300" height="300"/>
    <material name="MatPlane" class="/" texture="texplane" texrepeat="20 20" specular="1" shininess="1" reflectance="0.5"/>
  </asset>
  <worldbody>
    <light name="//unnamed_light_0" class="/" directional="true" pos="0 0 1.5" dir="0 0 -1.3" cutoff="100" exponent="1" diffuse="1 1 1" specular="0.10000000000000001 0.10000000000000001 0.10000000000000001"/>
    <geom name="ground" class="/" type="plane" size="15 15 0.5" material="MatPlane" rgba="1 1 1 1"/>
    <site name="body" class="/" size="9.9999999999999995e-07 9.9999999999999995e-07 9.9999999999999995e-07" pos="0 0 1.7422913074493409"/>
    <body pos="0 0 1.7422913074493409" name="0/">
      <joint name="0/rootx/" class="/" type="slide" axis="1 0 0" limited="false" stiffness="0" armature="0" damping="0"/>
      <joint name="0/rootz/" class="/" type="slide" axis="0 0 1" limited="false" stiffness="0" armature="0" damping="0"/>
      <joint name="0/rooty/" class="/" type="hinge" axis="0 1 0" limited="false" stiffness="0" armature="0" damping="0"/>
      <geom name="0/geom" class="0/" type="capsule" contype="1" conaffinity="1" condim="3" size="0.04026196404622711" rgba="0.50181329485665604 0.027262452879792343 0.82215975368033856 1" friction="0.59999999999999998 0.10000000000000001 0.10000000000000001" fromto="0 0 0 -0.12205688327772046 0 -0.65213591219737799"/>
      <site name="0/end0" class="0/" size="0.0050000000000000001" pos="-0.12205688327772046 0 -0.65213591219737799"/>
      <site name="0/attach1" class="0/" size="9.9999999999999995e-07 9.9999999999999995e-07 9.9999999999999995e-07" pos="-0.06334905492290141 0 -0.33846672641139769"/>
      <body pos="-0.06334905492290141 0 -0.33846672641139769" name="0/1/">
        <joint name="0/1/joint/" class="0/" type="hinge" axis="0 1 0" limited="true" stiffness="100" range="-56.952559059274101 56.952559059274101" armature="0.20000000000000001" damping="3.5"/>
        <geom name="0/1/geom" class="0/1/" type="capsule" contype="1" conaffinity="1" condim="3" size="0.055823579767003174" rgba="0.90926418962584976 0.013366461751233016 0.77032316958453928 1" friction="0.59999999999999998 0.10000000000000001 0.10000000000000001" fromto="0 0 0 0.18337278498547094 0 0.11121804087953902"/>
        <site name="0/1/end1" class="0/1/" size="0.0050000000000000001" pos="0.18337278498547094 0 0.11121804087953902"/>
        <site name="0/1/attach2" class="0/1/" size="9.9999999999999995e-07 9.9999999999999995e-07 9.9999999999999995e-07" pos="0.16274778212588262 0 0.098708701440973726"/>
        <body pos="0.16274778212588262 0 0.098708701440973726" name="0/1/2/">
          <joint name="0/1/2/joint/" class="0/1/" type="hinge" axis="0 1 0" limited="true" stiffness="100" range="-48.878445470923587 48.878445470923587" armature="0.20000000000000001" damping="3.5"/>
          <geom name="0/1/2/geom" class="0/1/2/" type="capsule" contype="1" conaffinity="1" condim="3" size="0.054491540275578447" rgba="0.43974652071076414 0.78260599047577895 0.58925355063532259 1" friction="0.59999999999999998 0.10000000000000001 0.10000000000000001" fromto="0 0 0 0.20639389832932387 0 0.036687279031861753"/>
          <site name="0/1/2/end2" class="0/1/2/" size="0.0050000000000000001" pos="0.20639389832932387 0 0.036687279031861753"/>
          <site name="0/1/2/attach3" class="0/1/2/" size="9.9999999999999995e-07 9.9999999999999995e-07 9.9999999999999995e-07" pos="0.0079495159535781391 0 0.001413055871893096"/>
          <body pos="0.0079495159535781391 0 0.001413055871893096" name="0/1/2/3/">
            <joint name="0/1/2/3/joint/" class="0/1/2/" type="hinge" axis="0 1 0" limited="true" stiffness="100" range="-35.689173094593826 35.689173094593826" armature="0.20000000000000001" damping="3.5"/>
            <geom name="0/1/2/3/geom" class="0/1/2/3/" type="capsule" contype="1" conaffinity="1" condim="3" size="0.048880879011685564" rgba="0.68204261920133191 0.50420013275801212 0.071172802741793828 1" friction="0.59999999999999998 0.10000000000000001 0.10000000000000001" fromto="0 0 0 0.53795490398964851 0 -0.48184338921116837"/>
            <site name="0/1/2/3/end3" class="0/1/2/3/" size="0.0050000000000000001" pos="0.53795490398964851 0 -0.48184338921116837"/>
            <site name="0/1/2/3/attach4" class="0/1/2/3/" size="9.9999999999999995e-07 9.9999999999999995e-07 9.9999999999999995e-07" pos="0.21031967755309866 0 -0.18838223334039017"/>
            <body pos="0.21031967755309866 0 -0.18838223334039017" name="0/1/2/3/4/">
              <joint name="0/1/2/3/4/joint/" class="0/1/2/3/" type="hinge" axis="0 1 0" limited="true" stiffness="100" range="-45.086074378672436 45.086074378672436" armature="0.20000000000000001" damping="3.5"/>
              <geom name="0/1/2/3/4/geom" class="0/1/2/3/4/" type="capsule" contype="1" conaffinity="1" condim="3" size="0.057060655770049235" rgba="0.8118951377394289 0.07581011156379025 0.11194117734418763 1" friction="0.59999999999999998 0.10000000000000001 0.10000000000000001" fromto="0 0 0 -0.62018602023132718 0 -0.49500977582989786"/>
              <site name="0/1/2/3/4/end4" class="0/1/2/3/4/" size="0.0050000000000000001" pos="-0.62018602023132718 0 -0.49500977582989786"/>
              <site name="0/1/2/3/4/attach5" class="0/1/2/3/4/" size="9.9999999999999995e-07 9.9999999999999995e-07 9.9999999999999995e-07" pos="-0.19378291551245433 0 -0.15467042861060393"/>
              <body pos="-0.19378291551245433 0 -0.15467042861060393" name="0/1/2/3/4/5/">
                <joint name="0/1/2/3/4/5/joint/" class="0/1/2/3/4/" type="hinge" axis="0 1 0" limited="true" stiffness="100" range="-68.257749325924422 68.257749325924422" armature="0.20000000000000001" damping="3.5"/>
                <geom name="0/1/2/3/4/5/geom" class="0/1/2/3/4/5/" type="capsule" contype="1" conaffinity="1" condim="3" size="0.067540890277160592" rgba="0.15345937597367731 0.61527046918633921 0.70179919553832559 1" friction="0.59999999999999998 0.10000000000000001 0.10000000000000001" fromto="0 0 0 0.0082142535965691321 0 -0.42963806253615722"/>
                <site name="0/1/2/3/4/5/end5" class="0/1/2/3/4/5/" size="0.0050000000000000001" pos="0.0082142535965691321 0 -0.42963806253615722"/>
                <site name="0/1/2/3/4/5/attach6" class="0/1/2/3/4/5/" size="9.9999999999999995e-07 9.9999999999999995e-07 9.9999999999999995e-07" pos="0.0041228430100087882 0 -0.21564105151328058"/>
                <body pos="0.0041228430100087882 0 -0.21564105151328058" name="0/1/2/3/4/5/6/">
                  <joint name="0/1/2/3/4/5/6/joint/" class="0/1/2/3/4/5/" type="hinge" axis="0 1 0" limited="true" stiffness="100" range="-63.571179604299068 63.571179604299068" armature="0.20000000000000001" damping="3.5"/>
                  <geom name="0/1/2/3/4/5/6/geom" class="0/1/2/3/4/5/6/" type="capsule" contype="1" conaffinity="1" condim="3" size="0.063274754930300839" rgba="0.13477701582002866 0.94299564911415867 0.81384558911063776 1" friction="0.59999999999999998 0.10000000000000001 0.10000000000000001" fromto="0 0 0 -0.47905491264577288 0 -0.30530558984885131"/>
                  <site name="0/1/2/3/4/5/6/end6" class="0/1/2/3/4/5/6/" size="0.0050000000000000001" pos="-0.47905491264577288 0 -0.30530558984885131"/>
                  <site name="0/1/2/3/4/5/6/attach7" class="0/1/2/3/4/5/6/" size="9.9999999999999995e-07 9.9999999999999995e-07 9.9999999999999995e-07" pos="-0.42166536301886443 0 -0.26873076337805168"/>
                  <body pos="-0.42166536301886443 0 -0.26873076337805168" name="0/1/2/3/4/5/6/7/">
                    <joint name="0/1/2/3/4/5/6/7/joint/" class="0/1/2/3/4/5/6/" type="hinge" axis="0 1 0" limited="true" stiffness="100" range="-44.318432472112264 44.318432472112264" armature="0.20000000000000001" damping="3.5"/>
                    <geom name="0/1/2/3/4/5/6/7/geom" class="0/1/2/3/4/5/6/7/" type="capsule" contype="1" conaffinity="1" condim="3" size="0.06393694675636595" rgba="0.57711045568846808 0.85476507963398796 0.81523447223154044 1" friction="0.59999999999999998 0.10000000000000001 0.10000000000000001" fromto="0 0 0 -0.60314647708540114 0 0.28840559393131526"/>
                    <site name="0/1/2/3/4/5/6/7/end7" class="0/1/2/3/4/5/6/7/" size="0.0050000000000000001" pos="-0.60314647708540114 0 0.28840559393131526"/>
                  </body>
                  <site name="0/1/2/3/4/5/6/attach8" class="0/1/2/3/4/5/6/" size="9.9999999999999995e-07 9.9999999999999995e-07 9.9999999999999995e-07" pos="-0.19697404908664307 0 -0.12553316259545677"/>
                  <body pos="-0.19697404908664307 0 -0.12553316259545677" name="0/1/2/3/4/5/6/8/">
                    <geom name="0/1/2/3/4/5/6/8/geom" class="0/1/2/3/4/5/6/8/" type="capsule" contype="1" conaffinity="1" condim="3" size="0.040116791060291319" rgba="0.37269900963674063 0.31315894049139448 0.94140415694625956 1" friction="0.59999999999999998 0.10000000000000001 0.10000000000000001" fromto="0 0 0 0.076559056642728773 0 -0.71971947138405012"/>
                    <site name="0/1/2/3/4/5/6/8/end8" class="0/1/2/3/4/5/6/8/" size="0.0050000000000000001" pos="0.076559056642728773 0 -0.71971947138405012"/>
                  </body>
                </body>
                <site name="0/1/2/3/4/5/attach9" class="0/1/2/3/4/5/" size="9.9999999999999995e-07 9.9999999999999995e-07 9.9999999999999995e-07" pos="0.002070496558147871 0 -0.10829518705168535"/>
                <body pos="0.002070496558147871 0 -0.10829518705168535" name="0/1/2/3/4/5/9/">
                  <geom name="0/1/2/3/4/5/9/geom" class="0/1/2/3/4/5/9/" type="capsule" contype="1" conaffinity="1" condim="3" size="0.040566741944175783" rgba="0.61918221504062187 0.50023416657897957 0.42869741741975953 1" friction="0.59999999999999998 0.10000000000000001 0.10000000000000001" fromto="0 0 0 0.6784068009189963 0 -0.44706511215654254"/>
                  <site name="0/1/2/3/4/5/9/end9" class="0/1/2/3/4/5/9/" size="0.0050000000000000001" pos="0.6784068009189963 0 -0.44706511215654254"/>
                  <site name="0/1/2/3/4/5/9/attach10" class="0/1/2/3/4/5/9/" size="9.9999999999999995e-07 9.9999999999999995e-07 9.9999999999999995e-07" pos="0.38702183242351379 0 -0.25504455245004004"/>
                  <body pos="0.38702183242351379 0 -0.25504455245004004" name="0/1/2/3/4/5/9/10/">
                    <joint name="0/1/2/3/4/5/9/10/joint/" class="0/1/2/3/4/5/9/" type="hinge" axis="0 1 0" limited="true" stiffness="100" range="-33.092364430032418 33.092364430032418" armature="0.20000000000000001" damping="3.5"/>
                    <geom name="0/1/2/3/4/5/9/10/geom" class="0/1/2/3/4/5/9/10/" type="capsule" contype="1" conaffinity="1" condim="3" size="0.062577864373370443" rgba="0.27537618503462646 0.41154882819707916 0.33433225131000111 1" friction="0.59999999999999998 0.10000000000000001 0.10000000000000001" fromto="0 0 0 -0.44021041292830909 0 -0.45480801759621647"/>
                    <site name="0/1/2/3/4/5/9/10/end10" class="0/1/2/3/4/5/9/10/" size="0.0050000000000000001" pos="-0.44021041292830909 0 -0.45480801759621647"/>
                  </body>
                </body>
              </body>
            </body>
          </body>
        </body>
      </body>
      <camera name="0/side" class="0/" mode="trackcom" pos="0.40000000000000002 -4 0.20000000000000001" quat="0.70699999999999996 0.70699999999999996 0 0"/>
    </body>
  </worldbody>
  <actuator>
    <motor name="0/1/motor" class="0/1/" ctrllimited="true" ctrlrange="-1 1" gear="55" joint="0/1/joint/"/>
    <motor name="0/1/2/motor" class="0/1/2/" ctrllimited="true" ctrlrange="-1 1" gear="61" joint="0/1/2/joint/"/>
    <motor name="0/1/2/3/motor" class="0/1/2/3/" ctrllimited="true" ctrlrange="-1 1" gear="83" joint="0/1/2/3/joint/"/>
    <motor name="0/1/2/3/4/motor" class="0/1/2/3/4/" ctrllimited="true" ctrlrange="-1 1" gear="57" joint="0/1/2/3/4/joint/"/>
    <motor name="0/1/2/3/4/5/motor" class="0/1/2/3/4/5/" ctrllimited="true" ctrlrange="-1 1" gear="85" joint="0/1/2/3/4/5/joint/"/>
    <motor name="0/1/2/3/4/5/6/motor" class="0/1/2/3/4/5/6/" ctrllimited="true" ctrlrange="-1 1" gear="51" joint="0/1/2/3/4/5/6/joint/"/>
    <motor name="0/1/2/3/4/5/6/7/motor" class="0/1/2/3/4/5/6/7/" ctrllimited="true" ctrlrange="-1 1" gear="57" joint="0/1/2/3/4/5/6/7/joint/"/>
    <motor name="0/1/2/3/4/5/9/10/motor" class="0/1/2/3/4/5/9/10/" ctrllimited="true" ctrlrange="-1 1" gear="59" joint="0/1/2/3/4/5/9/10/joint/"/>
  </actuator>
  <sensor>
    <subtreelinvel name="velocity" body="0/"/>
  </sensor>
</mujoco>
