<mujoco model="morphology">
  <option timestep="0.01"/>
  <default>
    <default class="/"/>
    <default class="0/"/>
    <default class="0/1/"/>
    <default class="0/2/"/>
    <default class="0/2/3/"/>
    <default class="0/2/4/"/>
  </default>
  <asset>
    <texture name="texplane" type="2d" builtin="checker" rgb1="0.10000000000000001 0.20000000000000001 0.29999999999999999" rgb2="0.20000000000000001 0.29999999999999999 0.40000000000000002" width="300" height="300"/>
    <material name="MatPlane" class="/" texture="texplane" texrepeat="20 20" specular="1" shininess="1" reflectance="0.5"/>
  </asset>
  <worldbody>
    <light name="//unnamed_light_0" class="/" directional="true" pos="0 0 1.5" dir="0 0 -1.3" cutoff="100" exponent="1" diffuse="1 1 1" specular="0.10000000000000001 0.10000000000000001 0.10000000000000001"/>
    <geom name="ground" class="/" type="plane" size="15 15 0.5" material="MatPlane" rgba="1 1 1 1"/>
    <site name="body" class="/" size="9.9999999999999995e-07 9.9999999999999995e-07 9.9999999999999995e-07" pos="0 0 0.71180949211120603"/>
    <body pos="0 0 0.71180949211120603" name="0/">
      <joint name="0/rootx/" class="/" type="slide" axis="1 0 0" limited="false" stiffness="0" armature="0" damping="0"/>
      <joint name="0/rootz/" class="/" type="slide" axis="0 0 1" limited="false" stiffness="0" armature="0" damping="0"/>
      <joint name="0/rooty/" class="/" type="hinge" axis="0 1 0" limited="false" stiffness="0" armature="0" damping="0"/>
      <geom name="0/geom" class="0/" type="capsule" contype="1" conaffinity="1" condim="3" size="0.059072031557350475" rgba="0.55674305374786459 0.38389772160271929 0.34285758787406817 1" friction="0.59999999999999998 0.10000000000000001 0.10000000000000001" fromto="0 0 0 -0.24656026235875228 0 -0.57514965936099705"/>
      <site name="0/end0" class="0/" size="0.0050000000000000001" pos="-0.24656026235875228 0 -0.57514965936099705"/>
      <site name="0/attach1" class="0/" size="9.9999999999999995e-07 9.9999999999999995e-07 9.9999999999999995e-07" pos="-0.036929880456465905 0 -0.086146112766028751"/>
      <body pos="-0.036929880456465905 0 -0.086146112766028751" name="0/1/">
        <joint name="0/1/joint/" class="0/" type="hinge" axis="0 1 0" limited="true" range="-40.100608550130808 40.100608550130808"/>
        <geom name="0/1/geom" class="0/1/" type="capsule" contype="1" conaffinity="1" condim="3" size="0.067989572606779181" rgba="0.15946462023454222 0.3654611719998786 0.2043328751976734 1" friction="0.59999999999999998 0.10000000000000001 0.10000000000000001" fromto="0 0 0 -0.69297952038996047 0 0.19612297519673616"/>
        <site name="0/1/end1" class="0/1/" size="0.0050000000000000001" pos="-0.69297952038996047 0 0.19612297519673616"/>
      </body>
      <site name="0/attach2" class="0/" size="9.9999999999999995e-07 9.9999999999999995e-07 9.9999999999999995e-07" pos="-0.021665150792213508 0 -0.050538168555383636"/>
      <body pos="-0.021665150792213508 0 -0.050538168555383636" name="0/2/">
        <joint name="0/2/joint/" class="0/" type="hinge" axis="0 1 0" limited="true" range="-54.440178417147251 54.440178417147251"/>
        <geom name="0/2/geom" class="0/2/" type="capsule" contype="1" conaffinity="1" condim="3" size="0.04276712194629171" rgba="0.51418414512952604 0.60635846290571571 0.56130560328656776 1" friction="0.59999999999999998 0.10000000000000001 0.10000000000000001" fromto="0 0 0 0.51564801837879815 0 -0.56127133581429023"/>
        <site name="0/2/end2" class="0/2/" size="0.0050000000000000001" pos="0.51564801837879815 0 -0.56127133581429023"/>
        <site name="0/2/attach3" class="0/2/" size="9.9999999999999995e-07 9.9999999999999995e-07 9.9999999999999995e-07" pos="0.052602538711791429 0 -0.057256686960253884"/>
        <body pos="0.052602538711791429 0 -0.057256686960253884" name="0/2/3/">
          <joint name="0/2/3/joint/" class="0/2/" type="hinge" axis="0 1 0" limited="true" range="-65.078440352506874 65.078440352506874"/>
          <geom name="0/2/3/geom" class="0/2/3/" type="capsule" contype="1" conaffinity="1" condim="3" size="0.045018555940516541" rgba="0.65001772890118825 0.5045710294174458 0.34514770407662099 1" friction="0.59999999999999998 0.10000000000000001 0.10000000000000001" fromto="0 0 0 0.48017227072188184 0 0.70250987504698581"/>
          <site name="0/2/3/end3" class="0/2/3/" size="0.0050000000000000001" pos="0.48017227072188184 0 0.70250987504698581"/>
        </body>
        <site name="0/2/attach4" class="0/2/" size="9.9999999999999995e-07 9.9999999999999995e-07 9.9999999999999995e-07" pos="0.29757366000110297 0 -0.32390227383608966"/>
        <body pos="0.29757366000110297 0 -0.32390227383608966" name="0/2/4/">
          <joint name="0/2/4/joint/" class="0/2/" type="hinge" axis="0 1 0" limited="true" range="-41.690751069750831 41.690751069750831"/>
          <geom name="0/2/4/geom" class="0/2/4/" type="capsule" contype="1" conaffinity="1" condim="3" size="0.054353937201125975" rgba="0.64970224325865455 0.099255236660018897 0.6977240132855913 1" friction="0.59999999999999998 0.10000000000000001 0.10000000000000001" fromto="0 0 0 0.71443755153838229 0 0.61114267632381325"/>
          <site name="0/2/4/end4" class="0/2/4/" size="0.0050000000000000001" pos="0.71443755153838229 0 0.61114267632381325"/>
        </body>
      </body>
      <camera name="0/side" class="0/" mode="trackcom" pos="0.40000000000000002 -4 0.20000000000000001" quat="0.70699999999999996 0.70699999999999996 0 0"/>
    </body>
  </worldbody>
  <actuator>
    <motor name="0/1/motor" class="0/1/" ctrllimited="true" ctrlrange="-1 1" gear="70" joint="0/1/joint/"/>
    <motor name="0/2/motor" class="0/2/" ctrllimited="true" ctrlrange="-1 1" gear="56" joint="0/2/joint/"/>
    <motor name="0/2/3/motor" class="0/2/3/" ctrllimited="true" ctrlrange="-1 1" gear="72" joint="0/2/3/joint/"/>
    <motor name="0/2/4/motor" class="0/2/4/" ctrllimited="true" ctrlrange="-1 1" gear="59" joint="0/2/4/joint/"/>
  </actuator>
  <sensor>
    <subtreelinvel name="velocity" body="0/"/>
  </sensor>
</mujoco>
