<mujoco model="morphology">
  <option timestep="0.01"/>
  <default>
    <default class="/"/>
    <default class="0/"/>
    <default class="0/1/"/>
    <default class="0/1/2/"/>
    <default class="0/1/2/3/"/>
    <default class="0/4/"/>
  </default>
  <asset>
    <texture name="texplane" type="2d" builtin="checker" rgb1="0.10000000000000001 0.20000000000000001 0.29999999999999999" rgb2="0.20000000000000001 0.29999999999999999 0.40000000000000002" width="300" height="300"/>
    <material name="MatPlane" class="/" texture="texplane" texrepeat="20 20" specular="1" shininess="1" reflectance="0.5"/>
  </asset>
  <worldbody>
    <light name="//unnamed_light_0" class="/" directional="true" pos="0 0 1.5" dir="0 0 -1.3" cutoff="100" exponent="1" diffuse="1 1 1" specular="0.10000000000000001 0.10000000000000001 0.10000000000000001"/>
    <geom name="ground" class="/" type="plane" size="15 15 0.5" material="MatPlane" rgba="1 1 1 1"/>
    <site name="body" class="/" size="9.9999999999999995e-07 9.9999999999999995e-07 9.9999999999999995e-07" pos="0 0 0.74147108793258665"/>
    <body pos="0 0 0.74147108793258665" name="0/">
      <joint name="0/rootx/" class="/" type="slide" axis="1 0 0" limited="false" stiffness="0" armature="0" damping="0"/>
      <joint name="0/rootz/" class="/" type="slide" axis="0 0 1" limited="false" stiffness="0" armature="0" damping="0"/>
      <joint name="0/rooty/" class="/" type="hinge" axis="0 1 0" limited="false" stiffness="0" armature="0" damping="0"/>
      <geom name="0/geom" class="0/" type="capsule" contype="1" conaffinity="1" condim="3" size="0.045692145530442381" rgba="0.80118887263546812 0.21770464683878477 0.025468770443005218 1" friction="0.59999999999999998 0.10000000000000001 0.10000000000000001" fromto="0 0 0 -0.36149988285747764 0 -0.22127362780862114"/>
      <site name="0/end0" class="0/" size="0.0050000000000000001" pos="-0.36149988285747764 0 -0.22127362780862114"/>
      <site name="0/attach1" class="0/" size="9.9999999999999995e-07 9.9999999999999995e-07 9.9999999999999995e-07" pos="-0.09768955248388532 0 -0.059795653338101412"/>
      <body pos="-0.09768955248388532 0 -0.059795653338101412" name="0/1/">
        <joint name="0/1/joint/" class="0/" type="hinge" axis="0 1 0" limited="true" range="-60.266415872307455 60.266415872307455"/>
        <geom name="0/1/geom" class="0/1/" type="capsule" contype="1" conaffinity="1" condim="3" size="0.046742332891378295" rgba="0.96766531629379404 0.56658800815810884 0.94144593949100441 1" friction="0.59999999999999998 0.10000000000000001 0.10000000000000001" fromto="0 0 0 0.082400573439687985 0 0.46769058098521965"/>
        <site name="0/1/end1" class="0/1/" size="0.0050000000000000001" pos="0.082400573439687985 0 0.46769058098521965"/>
        <site name="0/1/attach2" class="0/1/" size="9.9999999999999995e-07 9.9999999999999995e-07 9.9999999999999995e-07" pos="0.057672517432945533 0 0.32733865869073059"/>
        <body pos="0.057672517432945533 0 0.32733865869073059" name="0/1/2/">
          <geom name="0/1/2/geom" class="0/1/2/" type="capsule" contype="1" conaffinity="1" condim="3" size="0.042335273462376116" rgba="0.61175988683607796 0.84256271881122857 0.47524990699780922 1" friction="0.59999999999999998 0.10000000000000001 0.10000000000000001" fromto="0 0 0 0.42004792789898659 0 -0.55037569499829242"/>
          <site name="0/1/2/end2" class="0/1/2/" size="0.0050000000000000001" pos="0.42004792789898659 0 -0.55037569499829242"/>
          <site name="0/1/2/attach3" class="0/1/2/" size="9.9999999999999995e-07 9.9999999999999995e-07 9.9999999999999995e-07" pos="0.27309998293152804 0 -0.3578343872847472"/>
          <body pos="0.27309998293152804 0 -0.3578343872847472" name="0/1/2/3/">
            <joint name="0/1/2/3/joint/" class="0/1/2/" type="hinge" axis="0 1 0" limited="true" range="-62.016315352205787 62.016315352205787"/>
            <geom name="0/1/2/3/geom" class="0/1/2/3/" type="capsule" contype="1" conaffinity="1" condim="3" size="0.048052858191204667" rgba="0.84154134356312948 0.86186671171498919 0.17101512317207446 1" friction="0.59999999999999998 0.10000000000000001 0.10000000000000001" fromto="0 0 0 -0.10054118683701163 0 -0.55117970374017156"/>
            <site name="0/1/2/3/end3" class="0/1/2/3/" size="0.0050000000000000001" pos="-0.10054118683701163 0 -0.55117970374017156"/>
          </body>
        </body>
      </body>
      <site name="0/attach4" class="0/" size="9.9999999999999995e-07 9.9999999999999995e-07 9.9999999999999995e-07" pos="-0.29332853977716083 0 -0.17954603366188956"/>
      <body pos="-0.29332853977716083 0 -0.17954603366188956" name="0/4/">
        <joint name="0/4/joint/" class="0/" type="hinge" axis="0 1 0" limited="true" range="-32.36295307064313 32.36295307064313"/>
        <geom name="0/4/geom" class="0/4/" type="capsule" contype="1" conaffinity="1" condim="3" size="0.06938053017771055" rgba="0.019094649759638593 0.22300787008783396 0.26714775044000794 1" friction="0.59999999999999998 0.10000000000000001 0.10000000000000001" fromto="0 0 0 -0.086616190005782023 0 0.69379787293749806"/>
        <site name="0/4/end4" class="0/4/" size="0.0050000000000000001" pos="-0.086616190005782023 0 0.69379787293749806"/>
      </body>
      <camera name="0/side" class="0/" mode="trackcom" pos="0.40000000000000002 -4 0.20000000000000001" quat="0.70699999999999996 0.70699999999999996 0 0"/>
    </body>
  </worldbody>
  <actuator>
    <motor name="0/1/motor" class="0/1/" ctrllimited="true" ctrlrange="-1 1" gear="79" joint="0/1/joint/"/>
    <motor name="0/1/2/3/motor" class="0/1/2/3/" ctrllimited="true" ctrlrange="-1 1" gear="66" joint="0/1/2/3/joint/"/>
    <motor name="0/4/motor" class="0/4/" ctrllimited="true" ctrlrange="-1 1" gear="71" joint="0/4/joint/"/>
  </actuator>
  <sensor>
    <subtreelinvel name="velocity" body="0/"/>
  </sensor>
</mujoco>
