<mujoco model="morphology">
  <option timestep="0.01"/>
  <default>
    <default class="/"/>
    <default class="0/"/>
    <default class="0/1/"/>
    <default class="0/1/2/"/>
    <default class="0/3/"/>
    <default class="0/3/4/"/>
    <default class="0/3/4/5/"/>
    <default class="0/3/4/5/6/"/>
    <default class="0/3/4/7/"/>
    <default class="0/3/4/7/8/"/>
  </default>
  <asset>
    <texture name="texplane" type="2d" builtin="checker" rgb1="0.10000000000000001 0.20000000000000001 0.29999999999999999" rgb2="0.20000000000000001 0.29999999999999999 0.40000000000000002" width="300" height="300"/>
    <material name="MatPlane" class="/" texture="texplane" texrepeat="20 20" specular="1" shininess="1" reflectance="0.5"/>
  </asset>
  <worldbody>
    <light name="//unnamed_light_0" class="/" directional="true" pos="0 0 1.5" dir="0 0 -1.3" cutoff="100" exponent="1" diffuse="1 1 1" specular="0.10000000000000001 0.10000000000000001 0.10000000000000001"/>
    <geom name="ground" class="/" type="plane" size="15 15 0.5" material="MatPlane" rgba="1 1 1 1"/>
    <site name="body" class="/" size="9.9999999999999995e-07 9.9999999999999995e-07 9.9999999999999995e-07" pos="0 0 0.99976656436920164"/>
    <body pos="0 0 0.99976656436920164" name="0/">
      <joint name="0/rootx/" class="/" type="slide" axis="1 0 0" limited="false" stiffness="0" armature="0" damping="0"/>
      <joint name="0/rootz/" class="/" type="slide" axis="0 0 1" limited="false" stiffness="0" armature="0" damping="0"/>
      <joint name="0/rooty/" class="/" type="hinge" axis="0 1 0" limited="false" stiffness="0" armature="0" damping="0"/>
      <geom name="0/geom" class="0/" type="capsule" contype="1" conaffinity="1" condim="3" size="0.060715564997464777" rgba="0.015709204885450023 0.8662960653965619 0.86033261731373067 1" friction="0.59999999999999998 0.10000000000000001 0.10000000000000001" fromto="0 0 0 0.48264377886048959 0 0.57654589218407182"/>
      <site name="0/end0" class="0/" size="0.0050000000000000001" pos="0.48264377886048959 0 0.57654589218407182"/>
      <site name="0/attach1" class="0/" size="9.9999999999999995e-07 9.9999999999999995e-07 9.9999999999999995e-07" pos="0.12875918628696306 0 0.15381029070752897"/>
      <body pos="0.12875918628696306 0 0.15381029070752897" name="0/1/">
        <joint name="0/1/joint/" class="0/" type="hinge" axis="0 1 0" limited="true" stiffness="100" range="-69.458176151576083 69.458176151576083" armature="0.20000000000000001" damping="3.5"/>
        <geom name="0/1/geom" class="0/1/" type="capsule" contype="1" conaffinity="1" condim="3" size="0.049559129496454267" rgba="0.42001984711205365 0.72051066378900475 0.4821327838203735 1" friction="0.59999999999999998 0.10000000000000001 0.10000000000000001" fromto="0 0 0 0.43152554922038977 0 -0.61241471861472729"/>
        <site name="0/1/end1" class="0/1/" size="0.0050000000000000001" pos="0.43152554922038977 0 -0.61241471861472729"/>
        <site name="0/1/attach2" class="0/1/" size="9.9999999999999995e-07 9.9999999999999995e-07 9.9999999999999995e-07" pos="0.020583717068462883 0 -0.029212108806308028"/>
        <body pos="0.020583717068462883 0 -0.029212108806308028" name="0/1/2/">
          <joint name="0/1/2/joint/" class="0/1/" type="hinge" axis="0 1 0" limited="true" stiffness="100" range="-48.745556710765655 48.745556710765655" armature="0.20000000000000001" damping="3.5"/>
          <geom name="0/1/2/geom" class="0/1/2/" type="capsule" contype="1" conaffinity="1" condim="3" size="0.050305466291736871" rgba="0.44568352118090393 0.24919238086655593 0.59604360653709221 1" friction="0.59999999999999998 0.10000000000000001 0.10000000000000001" fromto="0 0 0 0.19020037085915154 0 -0.028735765522757251"/>
          <site name="0/1/2/end2" class="0/1/2/" size="0.0050000000000000001" pos="0.19020037085915154 0 -0.028735765522757251"/>
        </body>
      </body>
      <site name="0/attach3" class="0/" size="9.9999999999999995e-07 9.9999999999999995e-07 9.9999999999999995e-07" pos="0.017718193181553779 0 0.021165405922908324"/>
      <body pos="0.017718193181553779 0 0.021165405922908324" name="0/3/">
        <joint name="0/3/joint/" class="0/" type="hinge" axis="0 1 0" limited="true" stiffness="100" range="-39.166835485908734 39.166835485908734" armature="0.20000000000000001" damping="3.5"/>
        <geom name="0/3/geom" class="0/3/" type="capsule" contype="1" conaffinity="1" condim="3" size="0.04214446011385279" rgba="0.24189755202547569 0.37492060591166887 0.27460199937840968 1" friction="0.59999999999999998 0.10000000000000001 0.10000000000000001" fromto="0 0 0 0.65253382621734457 0 -0.65828496315121021"/>
        <site name="0/3/end3" class="0/3/" size="0.0050000000000000001" pos="0.65253382621734457 0 -0.65828496315121021"/>
        <site name="0/3/attach4" class="0/3/" size="9.9999999999999995e-07 9.9999999999999995e-07 9.9999999999999995e-07" pos="0.54758915965703814 0 -0.55241536193829599"/>
        <body pos="0.54758915965703814 0 -0.55241536193829599" name="0/3/4/">
          <joint name="0/3/4/joint/" class="0/3/" type="hinge" axis="0 1 0" limited="true" stiffness="100" range="-58.34944414219278 58.34944414219278" armature="0.20000000000000001" damping="3.5"/>
          <geom name="0/3/4/geom" class="0/3/4/" type="capsule" contype="1" conaffinity="1" condim="3" size="0.05927391463915576" rgba="0.22141438467981733 0.57718144869097598 0.78322752926592698 1" friction="0.59999999999999998 0.10000000000000001 0.10000000000000001" fromto="0 0 0 -0.033719851511042953 0 -0.13160182344455995"/>
          <site name="0/3/4/end4" class="0/3/4/" size="0.0050000000000000001" pos="-0.033719851511042953 0 -0.13160182344455995"/>
          <site name="0/3/4/attach5" class="0/3/4/" size="9.9999999999999995e-07 9.9999999999999995e-07 9.9999999999999995e-07" pos="-0.0058620631803367965 0 -0.02287845791452827"/>
          <body pos="-0.0058620631803367965 0 -0.02287845791452827" name="0/3/4/5/">
            <joint name="0/3/4/5/joint/" class="0/3/4/" type="hinge" axis="0 1 0" limited="true" stiffness="100" range="-68.298361203568845 68.298361203568845" armature="0.20000000000000001" damping="3.5"/>
            <geom name="0/3/4/5/geom" class="0/3/4/5/" type="capsule" contype="1" conaffinity="1" condim="3" size="0.050920578016211734" rgba="0.99011037214108144 0.013560186899006066 0.23928268675974163 1" friction="0.59999999999999998 0.10000000000000001 0.10000000000000001" fromto="0 0 0 -0.69244141010743376 0 -0.34563816819450488"/>
            <site name="0/3/4/5/end5" class="0/3/4/5/" size="0.0050000000000000001" pos="-0.69244141010743376 0 -0.34563816819450488"/>
            <site name="0/3/4/5/attach6" class="0/3/4/5/" size="9.9999999999999995e-07 9.9999999999999995e-07 9.9999999999999995e-07" pos="-0.52396903436112907 0 -0.26154371270072602"/>
            <body pos="-0.52396903436112907 0 -0.26154371270072602" name="0/3/4/5/6/">
              <geom name="0/3/4/5/6/geom" class="0/3/4/5/6/" type="capsule" contype="1" conaffinity="1" condim="3" size="0.065486728880105205" rgba="0.17312083131668332 0.015592844834136033 0.25694449806059938 1" friction="0.59999999999999998 0.10000000000000001 0.10000000000000001" fromto="0 0 0 -0.41107278367337913 0 0.59949637865733996"/>
              <site name="0/3/4/5/6/end6" class="0/3/4/5/6/" size="0.0050000000000000001" pos="-0.41107278367337913 0 0.59949637865733996"/>
            </body>
          </body>
          <site name="0/3/4/attach7" class="0/3/4/" size="9.9999999999999995e-07 9.9999999999999995e-07 9.9999999999999995e-07" pos="-0.0033675918958804129 0 -0.013143036349666223"/>
          <body pos="-0.0033675918958804129 0 -0.013143036349666223" name="0/3/4/7/">
            <joint name="0/3/4/7/joint/" class="0/3/4/" type="hinge" axis="0 1 0" limited="true" stiffness="100" range="-55.900294978919419 55.900294978919419" armature="0.20000000000000001" damping="3.5"/>
            <geom name="0/3/4/7/geom" class="0/3/4/7/" type="capsule" contype="1" conaffinity="1" condim="3" size="0.05414186062750341" rgba="0.17947230617989773 0.60068607530561535 0.90974084469181493 1" friction="0.59999999999999998 0.10000000000000001 0.10000000000000001" fromto="0 0 0 0.44266966178016709 0 0.27085253495761474"/>
            <site name="0/3/4/7/end7" class="0/3/4/7/" size="0.0050000000000000001" pos="0.44266966178016709 0 0.27085253495761474"/>
            <site name="0/3/4/7/attach8" class="0/3/4/7/" size="9.9999999999999995e-07 9.9999999999999995e-07 9.9999999999999995e-07" pos="0.4102950239563416 0 0.25104373964136278"/>
            <body pos="0.4102950239563416 0 0.25104373964136278" name="0/3/4/7/8/">
              <joint name="0/3/4/7/8/joint/" class="0/3/4/7/" type="hinge" axis="0 1 0" limited="true" stiffness="100" range="-58.661113190043544 58.661113190043544" armature="0.20000000000000001" damping="3.5"/>
              <geom name="0/3/4/7/8/geom" class="0/3/4/7/8/" type="capsule" contype="1" conaffinity="1" condim="3" size="0.049186709540892617" rgba="0.20760719901092273 0.22276610590646095 0.62076900587266348 1" friction="0.59999999999999998 0.10000000000000001 0.10000000000000001" fromto="0 0 0 -0.45278602238571225 0 0.20479130641216914"/>
              <site name="0/3/4/7/8/end8" class="0/3/4/7/8/" size="0.0050000000000000001" pos="-0.45278602238571225 0 0.20479130641216914"/>
            </body>
          </body>
        </body>
      </body>
      <camera name="0/side" class="0/" mode="trackcom" pos="0.40000000000000002 -4 0.20000000000000001" quat="0.70699999999999996 0.70699999999999996 0 0"/>
    </body>
  </worldbody>
  <actuator>
    <motor name="0/1/motor" class="0/1/" ctrllimited="true" ctrlrange="-1 1" gear="85" joint="0/1/joint/"/>
    <motor name="0/1/2/motor" class="0/1/2/" ctrllimited="true" ctrlrange="-1 1" gear="75" joint="0/1/2/joint/"/>
    <motor name="0/3/motor" class="0/3/" ctrllimited="true" ctrlrange="-1 1" gear="79" joint="0/3/joint/"/>
    <motor name="0/3/4/motor" class="0/3/4/" ctrllimited="true" ctrlrange="-1 1" gear="83" joint="0/3/4/joint/"/>
    <motor name="0/3/4/5/motor" class="0/3/4/5/" ctrllimited="true" ctrlrange="-1 1" gear="60" joint="0/3/4/5/joint/"/>
    <motor name="0/3/4/7/motor" class="0/3/4/7/" ctrllimited="true" ctrlrange="-1 1" gear="86" joint="0/3/4/7/joint/"/>
    <motor name="0/3/4/7/8/motor" class="0/3/4/7/8/" ctrllimited="true" ctrlrange="-1 1" gear="63" joint="0/3/4/7/8/joint/"/>
  </actuator>
  <sensor>
    <subtreelinvel name="velocity" body="0/"/>
  </sensor>
</mujoco>
