<mujoco model="morphology">
  <option timestep="0.01"/>
  <default>
    <default class="/"/>
    <default class="0/"/>
    <default class="0/1/"/>
    <default class="0/1/2/"/>
    <default class="0/1/3/"/>
    <default class="0/1/3/4/"/>
    <default class="0/1/3/4/5/"/>
    <default class="0/1/3/4/5/6/"/>
    <default class="0/1/3/4/7/"/>
    <default class="0/1/3/4/7/8/"/>
    <default class="0/1/3/9/"/>
    <default class="0/1/3/9/10/"/>
  </default>
  <asset>
    <texture name="texplane" type="2d" builtin="checker" rgb1="0.10000000000000001 0.20000000000000001 0.29999999999999999" rgb2="0.20000000000000001 0.29999999999999999 0.40000000000000002" width="300" height="300"/>
    <material name="MatPlane" class="/" texture="texplane" texrepeat="20 20" specular="1" shininess="1" reflectance="0.5"/>
  </asset>
  <worldbody>
    <light name="//unnamed_light_0" class="/" directional="true" pos="0 0 1.5" dir="0 0 -1.3" cutoff="100" exponent="1" diffuse="1 1 1" specular="0.10000000000000001 0.10000000000000001 0.10000000000000001"/>
    <geom name="ground" class="/" type="plane" size="15 15 0.5" material="MatPlane" rgba="1 1 1 1"/>
    <site name="body" class="/" size="9.9999999999999995e-07 9.9999999999999995e-07 9.9999999999999995e-07" pos="0 0 0.19265002608299256"/>
    <body pos="0 0 0.19265002608299256" name="0/">
      <joint name="0/rootx/" class="/" type="slide" axis="1 0 0" limited="false" stiffness="0" armature="0" damping="0"/>
      <joint name="0/rootz/" class="/" type="slide" axis="0 0 1" limited="false" stiffness="0" armature="0" damping="0"/>
      <joint name="0/rooty/" class="/" type="hinge" axis="0 1 0" limited="false" stiffness="0" armature="0" damping="0"/>
      <geom name="0/geom" class="0/" type="capsule" contype="1" conaffinity="1" condim="3" size="0.068564920935528018" rgba="0.42640914659120477 0.50135517741739877 0.65511189262558345 1" friction="0.59999999999999998 0.10000000000000001 0.10000000000000001" fromto="0 0 0 -0.56736526476456706 0 0.02365829035489142"/>
      <site name="0/end0" class="0/" size="0.0050000000000000001" pos="-0.56736526476456706 0 0.02365829035489142"/>
      <site name="0/attach1" class="0/" size="9.9999999999999995e-07 9.9999999999999995e-07 9.9999999999999995e-07" pos="-0.4974661815074593 0 0.020743602216688955"/>
      <body pos="-0.4974661815074593 0 0.020743602216688955" name="0/1/">
        <joint name="0/1/joint/" class="0/" type="hinge" axis="0 1 0" limited="true" stiffness="100" range="-44.43278866239595 44.43278866239595" armature="0.20000000000000001" damping="3.5"/>
        <geom name="0/1/geom" class="0/1/" type="capsule" contype="1" conaffinity="1" condim="3" size="0.064201178027326306" rgba="0.85408081839401773 0.59730403284245548 0.95308077085070686 1" friction="0.59999999999999998 0.10000000000000001 0.10000000000000001" fromto="0 0 0 0.063821261294191745 0 0.27888785818344264"/>
        <site name="0/1/end1" class="0/1/" size="0.0050000000000000001" pos="0.063821261294191745 0 0.27888785818344264"/>
        <site name="0/1/attach2" class="0/1/" size="9.9999999999999995e-07 9.9999999999999995e-07 9.9999999999999995e-07" pos="0.024290599773348243 0 0.10614571394246058"/>
        <body pos="0.024290599773348243 0 0.10614571394246058" name="0/1/2/">
          <joint name="0/1/2/joint/" class="0/1/" type="hinge" axis="0 1 0" limited="true" stiffness="100" range="-45.069159515621948 45.069159515621948" armature="0.20000000000000001" damping="3.5"/>
          <geom name="0/1/2/geom" class="0/1/2/" type="capsule" contype="1" conaffinity="1" condim="3" size="0.04255925261471153" rgba="0.52437766070282632 0.011537181596485646 0.60358994920796349 1" friction="0.59999999999999998 0.10000000000000001 0.10000000000000001" fromto="0 0 0 -0.45954864228749992 0 -0.21953934301980516"/>
          <site name="0/1/2/end2" class="0/1/2/" size="0.0050000000000000001" pos="-0.45954864228749992 0 -0.21953934301980516"/>
        </body>
        <site name="0/1/attach3" class="0/1/" size="9.9999999999999995e-07 9.9999999999999995e-07 9.9999999999999995e-07" pos="0.051098285964786827 0 0.22329065957932415"/>
        <body pos="0.051098285964786827 0 0.22329065957932415" name="0/1/3/">
          <joint name="0/1/3/joint/" class="0/1/" type="hinge" axis="0 1 0" limited="true" stiffness="100" range="-48.678892760893888 48.678892760893888" armature="0.20000000000000001" damping="3.5"/>
          <geom name="0/1/3/geom" class="0/1/3/" type="capsule" contype="1" conaffinity="1" condim="3" size="0.055582876166627541" rgba="0.84604800202307939 0.3917541312339341 0.57371863241370369 1" friction="0.59999999999999998 0.10000000000000001 0.10000000000000001" fromto="0 0 0 -0.68543519178276724 0 0.72188978459715725"/>
          <site name="0/1/3/end3" class="0/1/3/" size="0.0050000000000000001" pos="-0.68543519178276724 0 0.72188978459715725"/>
          <site name="0/1/3/attach4" class="0/1/3/" size="9.9999999999999995e-07 9.9999999999999995e-07 9.9999999999999995e-07" pos="-0.41027999123708025 0 0.43210056625240484"/>
          <body pos="-0.41027999123708025 0 0.43210056625240484" name="0/1/3/4/">
            <geom name="0/1/3/4/geom" class="0/1/3/4/" type="capsule" contype="1" conaffinity="1" condim="3" size="0.056799821453450243" rgba="0.44722585160246831 0.4570063149385617 0.97327370020771564 1" friction="0.59999999999999998 0.10000000000000001 0.10000000000000001" fromto="0 0 0 0.59327171733528394 0 0.29084223385043462"/>
            <site name="0/1/3/4/end4" class="0/1/3/4/" size="0.0050000000000000001" pos="0.59327171733528394 0 0.29084223385043462"/>
            <site name="0/1/3/4/attach5" class="0/1/3/4/" size="9.9999999999999995e-07 9.9999999999999995e-07 9.9999999999999995e-07" pos="0.39708932878498393 0 0.19466686856526105"/>
            <body pos="0.39708932878498393 0 0.19466686856526105" name="0/1/3/4/5/">
              <joint name="0/1/3/4/5/joint/" class="0/1/3/4/" type="hinge" axis="0 1 0" limited="true" stiffness="100" range="-33.681675786357047 33.681675786357047" armature="0.20000000000000001" damping="3.5"/>
              <geom name="0/1/3/4/5/geom" class="0/1/3/4/5/" type="capsule" contype="1" conaffinity="1" condim="3" size="0.049953546755947341" rgba="0.92835291373430429 0.03187608585110846 0.43402995913535725 1" friction="0.59999999999999998 0.10000000000000001 0.10000000000000001" fromto="0 0 0 0.42757813343621653 0 -0.36427260604669126"/>
              <site name="0/1/3/4/5/end5" class="0/1/3/4/5/" size="0.0050000000000000001" pos="0.42757813343621653 0 -0.36427260604669126"/>
              <site name="0/1/3/4/5/attach6" class="0/1/3/4/5/" size="9.9999999999999995e-07 9.9999999999999995e-07 9.9999999999999995e-07" pos="0.14761812306968211 0 -0.1257623675892113"/>
              <body pos="0.14761812306968211 0 -0.1257623675892113" name="0/1/3/4/5/6/">
                <joint name="0/1/3/4/5/6/joint/" class="0/1/3/4/5/" type="hinge" axis="0 1 0" limited="true" stiffness="100" range="-46.856039402584315 46.856039402584315" armature="0.20000000000000001" damping="3.5"/>
                <geom name="0/1/3/4/5/6/geom" class="0/1/3/4/5/6/" type="capsule" contype="1" conaffinity="1" condim="3" size="0.067147280811080887" rgba="0.50565181625177757 0.021812084359777884 0.17305242555497036 1" friction="0.59999999999999998 0.10000000000000001 0.10000000000000001" fromto="0 0 0 0.29285588164856602 0 0.061551991283366192"/>
                <site name="0/1/3/4/5/6/end6" class="0/1/3/4/5/6/" size="0.0050000000000000001" pos="0.29285588164856602 0 0.061551991283366192"/>
              </body>
            </body>
            <site name="0/1/3/4/attach7" class="0/1/3/4/" size="9.9999999999999995e-07 9.9999999999999995e-07 9.9999999999999995e-07" pos="0.17296070344906905 0 0.084791295269247863"/>
            <body pos="0.17296070344906905 0 0.084791295269247863" name="0/1/3/4/7/">
              <joint name="0/1/3/4/7/joint/" class="0/1/3/4/" type="hinge" axis="0 1 0" limited="true" stiffness="100" range="-43.383980001235585 43.383980001235585" armature="0.20000000000000001" damping="3.5"/>
              <geom name="0/1/3/4/7/geom" class="0/1/3/4/7/" type="capsule" contype="1" conaffinity="1" condim="3" size="0.063189818076289164" rgba="0.46952877410349625 0.29449967415615164 0.44149495230438818 1" friction="0.59999999999999998 0.10000000000000001 0.10000000000000001" fromto="0 0 0 0.14140657395940359 0 -0.060813667752464107"/>
              <site name="0/1/3/4/7/end7" class="0/1/3/4/7/" size="0.0050000000000000001" pos="0.14140657395940359 0 -0.060813667752464107"/>
              <site name="0/1/3/4/7/attach8" class="0/1/3/4/7/" size="9.9999999999999995e-07 9.9999999999999995e-07 9.9999999999999995e-07" pos="0.13069105069901324 0 -0.056205322799999145"/>
              <body pos="0.13069105069901324 0 -0.056205322799999145" name="0/1/3/4/7/8/">
                <geom name="0/1/3/4/7/8/geom" class="0/1/3/4/7/8/" type="capsule" contype="1" conaffinity="1" condim="3" size="0.042019859905418545" rgba="0.41006609004650585 0.92781746076063143 0.42154211142270326 1" friction="0.59999999999999998 0.10000000000000001 0.10000000000000001" fromto="0 0 0 -0.09802887929450399 0 -0.04871100309331744"/>
                <site name="0/1/3/4/7/8/end8" class="0/1/3/4/7/8/" size="0.0050000000000000001" pos="-0.09802887929450399 0 -0.04871100309331744"/>
              </body>
            </body>
          </body>
          <site name="0/1/3/attach9" class="0/1/3/" size="9.9999999999999995e-07 9.9999999999999995e-07 9.9999999999999995e-07" pos="-0.46805021930297591 0 0.49294328047918629"/>
          <body pos="-0.46805021930297591 0 0.49294328047918629" name="0/1/3/9/">
            <geom name="0/1/3/9/geom" class="0/1/3/9/" type="capsule" contype="1" conaffinity="1" condim="3" size="0.050200209533481442" rgba="0.47425832756571862 0.29534203713258966 0.23061937036360092 1" friction="0.59999999999999998 0.10000000000000001 0.10000000000000001" fromto="0 0 0 0.22739645698606581 0 0.45256585096569024"/>
            <site name="0/1/3/9/end9" class="0/1/3/9/" size="0.0050000000000000001" pos="0.22739645698606581 0 0.45256585096569024"/>
            <site name="0/1/3/9/attach10" class="0/1/3/9/" size="9.9999999999999995e-07 9.9999999999999995e-07 9.9999999999999995e-07" pos="0.15518447137363153 0 0.30884910554332834"/>
            <body pos="0.15518447137363153 0 0.30884910554332834" name="0/1/3/9/10/">
              <geom name="0/1/3/9/10/geom" class="0/1/3/9/10/" type="capsule" contype="1" conaffinity="1" condim="3" size="0.064919809864658576" rgba="0.80728897361484908 0.70860917129121503 0.6578891605706525 1" friction="0.59999999999999998 0.10000000000000001 0.10000000000000001" fromto="0 0 0 -0.12041256478826434 0 0.30904571494201583"/>
              <site name="0/1/3/9/10/end10" class="0/1/3/9/10/" size="0.0050000000000000001" pos="-0.12041256478826434 0 0.30904571494201583"/>
            </body>
          </body>
        </body>
      </body>
      <camera name="0/side" class="0/" mode="trackcom" pos="0.40000000000000002 -4 0.20000000000000001" quat="0.70699999999999996 0.70699999999999996 0 0"/>
    </body>
  </worldbody>
  <actuator>
    <motor name="0/1/motor" class="0/1/" ctrllimited="true" ctrlrange="-1 1" gear="86" joint="0/1/joint/"/>
    <motor name="0/1/2/motor" class="0/1/2/" ctrllimited="true" ctrlrange="-1 1" gear="88" joint="0/1/2/joint/"/>
    <motor name="0/1/3/motor" class="0/1/3/" ctrllimited="true" ctrlrange="-1 1" gear="53" joint="0/1/3/joint/"/>
    <motor name="0/1/3/4/5/motor" class="0/1/3/4/5/" ctrllimited="true" ctrlrange="-1 1" gear="65" joint="0/1/3/4/5/joint/"/>
    <motor name="0/1/3/4/5/6/motor" class="0/1/3/4/5/6/" ctrllimited="true" ctrlrange="-1 1" gear="76" joint="0/1/3/4/5/6/joint/"/>
    <motor name="0/1/3/4/7/motor" class="0/1/3/4/7/" ctrllimited="true" ctrlrange="-1 1" gear="60" joint="0/1/3/4/7/joint/"/>
  </actuator>
  <sensor>
    <subtreelinvel name="velocity" body="0/"/>
  </sensor>
</mujoco>
