<mujoco model="morphology">
  <option timestep="0.01"/>
  <default>
    <default class="/"/>
    <default class="0/"/>
    <default class="0/1/"/>
    <default class="0/1/2/"/>
    <default class="0/1/2/3/"/>
    <default class="0/1/2/3/4/"/>
    <default class="0/1/2/3/4/5/"/>
    <default class="0/1/2/3/4/5/6/"/>
    <default class="0/1/2/3/4/5/7/"/>
    <default class="0/1/2/3/4/5/7/8/"/>
    <default class="0/1/2/3/4/5/7/8/9/"/>
    <default class="0/1/2/3/4/5/7/8/9/10/"/>
  </default>
  <asset>
    <texture name="texplane" type="2d" builtin="checker" rgb1="0.10000000000000001 0.20000000000000001 0.29999999999999999" rgb2="0.20000000000000001 0.29999999999999999 0.40000000000000002" width="300" height="300"/>
    <material name="MatPlane" class="/" texture="texplane" texrepeat="20 20" specular="1" shininess="1" reflectance="0.5"/>
  </asset>
  <worldbody>
    <light name="//unnamed_light_0" class="/" directional="true" pos="0 0 1.5" dir="0 0 -1.3" cutoff="100" exponent="1" diffuse="1 1 1" specular="0.10000000000000001 0.10000000000000001 0.10000000000000001"/>
    <geom name="ground" class="/" type="plane" size="15 15 0.5" material="MatPlane" rgba="1 1 1 1"/>
    <site name="body" class="/" size="9.9999999999999995e-07 9.9999999999999995e-07 9.9999999999999995e-07" pos="0 0 1.8544649839401246"/>
    <body pos="0 0 1.8544649839401246" name="0/">
      <joint name="0/rootx/" class="/" type="slide" axis="1 0 0" limited="false" stiffness="0" armature="0" damping="0"/>
      <joint name="0/rootz/" class="/" type="slide" axis="0 0 1" limited="false" stiffness="0" armature="0" damping="0"/>
      <joint name="0/rooty/" class="/" type="hinge" axis="0 1 0" limited="false" stiffness="0" armature="0" damping="0"/>
      <geom name="0/geom" class="0/" type="capsule" contype="1" conaffinity="1" condim="3" size="0.04784556429285336" rgba="0.81691413145154379 0.84487350370368353 0.27205490387010611 1" friction="0.59999999999999998 0.10000000000000001 0.10000000000000001" fromto="0 0 0 0.50378492473693637 0 -0.48854958177617175"/>
      <site name="0/end0" class="0/" size="0.0050000000000000001" pos="0.50378492473693637 0 -0.48854958177617175"/>
      <site name="0/attach1" class="0/" size="9.9999999999999995e-07 9.9999999999999995e-07 9.9999999999999995e-07" pos="0.037556541815402938 0 -0.036420765878326725"/>
      <body pos="0.037556541815402938 0 -0.036420765878326725" name="0/1/">
        <geom name="0/1/geom" class="0/1/" type="capsule" contype="1" conaffinity="1" condim="3" size="0.053631309290933397" rgba="0.26112028284695277 0.36130512508762902 0.34602850736630164 1" friction="0.59999999999999998 0.10000000000000001 0.10000000000000001" fromto="0 0 0 -0.72490948957239532 0 -0.48255206754688085"/>
        <site name="0/1/end1" class="0/1/" size="0.0050000000000000001" pos="-0.72490948957239532 0 -0.48255206754688085"/>
        <site name="0/1/attach2" class="0/1/" size="9.9999999999999995e-07 9.9999999999999995e-07 9.9999999999999995e-07" pos="-0.1429219519404184 0 -0.095139164818171695"/>
        <body pos="-0.1429219519404184 0 -0.095139164818171695" name="0/1/2/">
          <joint name="0/1/2/joint/" class="0/1/" type="hinge" axis="0 1 0" limited="true" range="-48.412094305520647 48.412094305520647"/>
          <geom name="0/1/2/geom" class="0/1/2/" type="capsule" contype="1" conaffinity="1" condim="3" size="0.043833414145253838" rgba="0.23330617205092985 0.18199669296737431 0.66009352087640716 1" friction="0.59999999999999998 0.10000000000000001 0.10000000000000001" fromto="0 0 0 0.41022373427865633 0 -0.64452806211893843"/>
          <site name="0/1/2/end2" class="0/1/2/" size="0.0050000000000000001" pos="0.41022373427865633 0 -0.64452806211893843"/>
          <site name="0/1/2/attach3" class="0/1/2/" size="9.9999999999999995e-07 9.9999999999999995e-07 9.9999999999999995e-07" pos="0.40274791381113495 0 -0.63278233490704672"/>
          <body pos="0.40274791381113495 0 -0.63278233490704672" name="0/1/2/3/">
            <geom name="0/1/2/3/geom" class="0/1/2/3/" type="capsule" contype="1" conaffinity="1" condim="3" size="0.043082519438887953" rgba="0.57246708756654496 0.49984239835678257 0.10286826250383541 1" friction="0.59999999999999998 0.10000000000000001 0.10000000000000001" fromto="0 0 0 -0.12767029213204695 0 -0.5629309291512079"/>
            <site name="0/1/2/3/end3" class="0/1/2/3/" size="0.0050000000000000001" pos="-0.12767029213204695 0 -0.5629309291512079"/>
            <site name="0/1/2/3/attach4" class="0/1/2/3/" size="9.9999999999999995e-07 9.9999999999999995e-07 9.9999999999999995e-07" pos="-0.021478443599260134 0 -0.094703944121534198"/>
            <body pos="-0.021478443599260134 0 -0.094703944121534198" name="0/1/2/3/4/">
              <joint name="0/1/2/3/4/joint/" class="0/1/2/3/" type="hinge" axis="0 1 0" limited="true" range="-34.78917094441001 34.78917094441001"/>
              <geom name="0/1/2/3/4/geom" class="0/1/2/3/4/" type="capsule" contype="1" conaffinity="1" condim="3" size="0.046423271429815019" rgba="0.87488706965251828 0.28946244584163106 0.4336988841710222 1" friction="0.59999999999999998 0.10000000000000001 0.10000000000000001" fromto="0 0 0 -0.47339221208557281 0 -0.017690971611947548"/>
              <site name="0/1/2/3/4/end4" class="0/1/2/3/4/" size="0.0050000000000000001" pos="-0.47339221208557281 0 -0.017690971611947548"/>
              <site name="0/1/2/3/4/attach5" class="0/1/2/3/4/" size="9.9999999999999995e-07 9.9999999999999995e-07 9.9999999999999995e-07" pos="-0.25745681637322632 0 -0.0096213269113472766"/>
              <body pos="-0.25745681637322632 0 -0.0096213269113472766" name="0/1/2/3/4/5/">
                <joint name="0/1/2/3/4/5/joint/" class="0/1/2/3/4/" type="hinge" axis="0 1 0" limited="true" range="-40.282149688143875 40.282149688143875"/>
                <geom name="0/1/2/3/4/5/geom" class="0/1/2/3/4/5/" type="capsule" contype="1" conaffinity="1" condim="3" size="0.049090770712638225" rgba="0.059218023578830881 0.37690203841174919 0.84769959031787268 1" friction="0.59999999999999998 0.10000000000000001 0.10000000000000001" fromto="0 0 0 -0.12435271123315284 0 -0.63655110674648374"/>
                <site name="0/1/2/3/4/5/end5" class="0/1/2/3/4/5/" size="0.0050000000000000001" pos="-0.12435271123315284 0 -0.63655110674648374"/>
                <site name="0/1/2/3/4/5/attach6" class="0/1/2/3/4/5/" size="9.9999999999999995e-07 9.9999999999999995e-07 9.9999999999999995e-07" pos="-0.12156027526830937 0 -0.62225686107775002"/>
                <body pos="-0.12156027526830937 0 -0.62225686107775002" name="0/1/2/3/4/5/6/">
                  <joint name="0/1/2/3/4/5/6/joint/" class="0/1/2/3/4/5/" type="hinge" axis="0 1 0" limited="true" range="-56.321183538581138 56.321183538581138"/>
                  <geom name="0/1/2/3/4/5/6/geom" class="0/1/2/3/4/5/6/" type="capsule" contype="1" conaffinity="1" condim="3" size="0.065550912684952237" rgba="0.6680953064898254 0.10594095452186825 0.68197733982703734 1" friction="0.59999999999999998 0.10000000000000001 0.10000000000000001" fromto="0 0 0 -0.55590541889853617 0 0.50128633787170651"/>
                  <site name="0/1/2/3/4/5/6/end6" class="0/1/2/3/4/5/6/" size="0.0050000000000000001" pos="-0.55590541889853617 0 0.50128633787170651"/>
                </body>
                <site name="0/1/2/3/4/5/attach7" class="0/1/2/3/4/5/" size="9.9999999999999995e-07 9.9999999999999995e-07 9.9999999999999995e-07" pos="-0.10548777726419005 0 -0.539983090837868"/>
                <body pos="-0.10548777726419005 0 -0.539983090837868" name="0/1/2/3/4/5/7/">
                  <joint name="0/1/2/3/4/5/7/joint/" class="0/1/2/3/4/5/" type="hinge" axis="0 1 0" limited="true" range="-61.993831916315941 61.993831916315941"/>
                  <geom name="0/1/2/3/4/5/7/geom" class="0/1/2/3/4/5/7/" type="capsule" contype="1" conaffinity="1" condim="3" size="0.054843044220437204" rgba="0.11504558239839957 0.97617618154669905 0.12955242800476729 1" friction="0.59999999999999998 0.10000000000000001 0.10000000000000001" fromto="0 0 0 0.66661157729201048 0 0.034212695688440098"/>
                  <site name="0/1/2/3/4/5/7/end7" class="0/1/2/3/4/5/7/" size="0.0050000000000000001" pos="0.66661157729201048 0 0.034212695688440098"/>
                  <site name="0/1/2/3/4/5/7/attach8" class="0/1/2/3/4/5/7/" size="9.9999999999999995e-07 9.9999999999999995e-07 9.9999999999999995e-07" pos="0.097425669945846491 0 0.0050002053844311464"/>
                  <body pos="0.097425669945846491 0 0.0050002053844311464" name="0/1/2/3/4/5/7/8/">
                    <joint name="0/1/2/3/4/5/7/8/joint/" class="0/1/2/3/4/5/7/" type="hinge" axis="0 1 0" limited="true" range="-65.514646037745038 65.514646037745038"/>
                    <geom name="0/1/2/3/4/5/7/8/geom" class="0/1/2/3/4/5/7/8/" type="capsule" contype="1" conaffinity="1" condim="3" size="0.05576517799390654" rgba="0.82595274945842545 0.88775145904058994 0.7040583522625169 1" friction="0.59999999999999998 0.10000000000000001 0.10000000000000001" fromto="0 0 0 0.05273116081403828 0 -0.17641836534666844"/>
                    <site name="0/1/2/3/4/5/7/8/end8" class="0/1/2/3/4/5/7/8/" size="0.0050000000000000001" pos="0.05273116081403828 0 -0.17641836534666844"/>
                    <site name="0/1/2/3/4/5/7/8/attach9" class="0/1/2/3/4/5/7/8/" size="9.9999999999999995e-07 9.9999999999999995e-07 9.9999999999999995e-07" pos="0.052445105501512962 0 -0.17546133330232527"/>
                    <body pos="0.052445105501512962 0 -0.17546133330232527" name="0/1/2/3/4/5/7/8/9/">
                      <joint name="0/1/2/3/4/5/7/8/9/joint/" class="0/1/2/3/4/5/7/8/" type="hinge" axis="0 1 0" limited="true" range="-36.351382527644745 36.351382527644745"/>
                      <geom name="0/1/2/3/4/5/7/8/9/geom" class="0/1/2/3/4/5/7/8/9/" type="capsule" contype="1" conaffinity="1" condim="3" size="0.046495636738576644" rgba="0.64997618537321666 0.61513018793441743 0.012799845102829499 1" friction="0.59999999999999998 0.10000000000000001 0.10000000000000001" fromto="0 0 0 0.12195001451722343 0 -0.17535323423352112"/>
                      <site name="0/1/2/3/4/5/7/8/9/end9" class="0/1/2/3/4/5/7/8/9/" size="0.0050000000000000001" pos="0.12195001451722343 0 -0.17535323423352112"/>
                      <site name="0/1/2/3/4/5/7/8/9/attach10" class="0/1/2/3/4/5/7/8/9/" size="9.9999999999999995e-07 9.9999999999999995e-07 9.9999999999999995e-07" pos="0.0075778997504241238 0 -0.010896343351780333"/>
                      <body pos="0.0075778997504241238 0 -0.010896343351780333" name="0/1/2/3/4/5/7/8/9/10/">
                        <joint name="0/1/2/3/4/5/7/8/9/10/joint/" class="0/1/2/3/4/5/7/8/9/" type="hinge" axis="0 1 0" limited="true" range="-55.548220943282587 55.548220943282587"/>
                        <geom name="0/1/2/3/4/5/7/8/9/10/geom" class="0/1/2/3/4/5/7/8/9/10/" type="capsule" contype="1" conaffinity="1" condim="3" size="0.067092221545184502" rgba="0.095370901174882894 0.34224256896455363 0.91256082593888554 1" friction="0.59999999999999998 0.10000000000000001 0.10000000000000001" fromto="0 0 0 0.28087267869222643 0 0.066281708951023699"/>
                        <site name="0/1/2/3/4/5/7/8/9/10/end10" class="0/1/2/3/4/5/7/8/9/10/" size="0.0050000000000000001" pos="0.28087267869222643 0 0.066281708951023699"/>
                      </body>
                    </body>
                  </body>
                </body>
              </body>
            </body>
          </body>
        </body>
      </body>
      <camera name="0/side" class="0/" mode="trackcom" pos="0.40000000000000002 -4 0.20000000000000001" quat="0.70699999999999996 0.70699999999999996 0 0"/>
    </body>
  </worldbody>
  <actuator>
    <motor name="0/1/2/motor" class="0/1/2/" ctrllimited="true" ctrlrange="-1 1" gear="63" joint="0/1/2/joint/"/>
    <motor name="0/1/2/3/4/motor" class="0/1/2/3/4/" ctrllimited="true" ctrlrange="-1 1" gear="85" joint="0/1/2/3/4/joint/"/>
    <motor name="0/1/2/3/4/5/motor" class="0/1/2/3/4/5/" ctrllimited="true" ctrlrange="-1 1" gear="87" joint="0/1/2/3/4/5/joint/"/>
    <motor name="0/1/2/3/4/5/6/motor" class="0/1/2/3/4/5/6/" ctrllimited="true" ctrlrange="-1 1" gear="64" joint="0/1/2/3/4/5/6/joint/"/>
    <motor name="0/1/2/3/4/5/7/motor" class="0/1/2/3/4/5/7/" ctrllimited="true" ctrlrange="-1 1" gear="73" joint="0/1/2/3/4/5/7/joint/"/>
    <motor name="0/1/2/3/4/5/7/8/motor" class="0/1/2/3/4/5/7/8/" ctrllimited="true" ctrlrange="-1 1" gear="61" joint="0/1/2/3/4/5/7/8/joint/"/>
    <motor name="0/1/2/3/4/5/7/8/9/motor" class="0/1/2/3/4/5/7/8/9/" ctrllimited="true" ctrlrange="-1 1" gear="77" joint="0/1/2/3/4/5/7/8/9/joint/"/>
    <motor name="0/1/2/3/4/5/7/8/9/10/motor" class="0/1/2/3/4/5/7/8/9/10/" ctrllimited="true" ctrlrange="-1 1" gear="79" joint="0/1/2/3/4/5/7/8/9/10/joint/"/>
  </actuator>
  <sensor>
    <subtreelinvel name="velocity" body="0/"/>
  </sensor>
</mujoco>
