<mujoco model="morphology">
  <option timestep="0.01"/>
  <default>
    <default class="/"/>
    <default class="0/"/>
    <default class="0/1/"/>
    <default class="0/1/2/"/>
    <default class="0/1/2/3/"/>
    <default class="0/1/2/4/"/>
    <default class="0/1/2/5/"/>
    <default class="0/1/2/5/6/"/>
    <default class="0/1/2/5/6/7/"/>
    <default class="0/1/2/5/6/8/"/>
    <default class="0/1/9/"/>
    <default class="0/10/"/>
  </default>
  <asset>
    <texture name="texplane" type="2d" builtin="checker" rgb1="0.10000000000000001 0.20000000000000001 0.29999999999999999" rgb2="0.20000000000000001 0.29999999999999999 0.40000000000000002" width="300" height="300"/>
    <material name="MatPlane" class="/" texture="texplane" texrepeat="20 20" specular="1" shininess="1" reflectance="0.5"/>
  </asset>
  <worldbody>
    <light name="//unnamed_light_0" class="/" directional="true" pos="0 0 1.5" dir="0 0 -1.3" cutoff="100" exponent="1" diffuse="1 1 1" specular="0.10000000000000001 0.10000000000000001 0.10000000000000001"/>
    <geom name="ground" class="/" type="plane" size="15 15 0.5" material="MatPlane" rgba="1 1 1 1"/>
    <site name="body" class="/" size="9.9999999999999995e-07 9.9999999999999995e-07 9.9999999999999995e-07" pos="0 0 0.32699600458145139"/>
    <body pos="0 0 0.32699600458145139" name="0/">
      <joint name="0/rootx/" class="/" type="slide" axis="1 0 0" limited="false" stiffness="0" armature="0" damping="0"/>
      <joint name="0/rootz/" class="/" type="slide" axis="0 0 1" limited="false" stiffness="0" armature="0" damping="0"/>
      <joint name="0/rooty/" class="/" type="hinge" axis="0 1 0" limited="false" stiffness="0" armature="0" damping="0"/>
      <geom name="0/geom" class="0/" type="capsule" contype="1" conaffinity="1" condim="3" size="0.048225218248603853" rgba="0.18930152753433371 0.71564286075398886 0.36541481078360816 1" friction="0.59999999999999998 0.10000000000000001 0.10000000000000001" fromto="0 0 0 0.25222162929897163 0 0.68069671476414673"/>
      <site name="0/end0" class="0/" size="0.0050000000000000001" pos="0.25222162929897163 0 0.68069671476414673"/>
      <site name="0/attach1" class="0/" size="9.9999999999999995e-07 9.9999999999999995e-07 9.9999999999999995e-07" pos="0.15573728216847854 0 0.42030438322449015"/>
      <body pos="0.15573728216847854 0 0.42030438322449015" name="0/1/">
        <joint name="0/1/joint/" class="0/" type="hinge" axis="0 1 0" limited="true" range="-62.305777412486798 62.305777412486798"/>
        <geom name="0/1/geom" class="0/1/" type="capsule" contype="1" conaffinity="1" condim="3" size="0.059215855569137076" rgba="0.73559208169404522 0.60911267160530236 0.57724182781012434 1" friction="0.59999999999999998 0.10000000000000001 0.10000000000000001" fromto="0 0 0 0.56711217807873959 0 -0.38832747886084013"/>
        <site name="0/1/end1" class="0/1/" size="0.0050000000000000001" pos="0.56711217807873959 0 -0.38832747886084013"/>
        <site name="0/1/attach2" class="0/1/" size="9.9999999999999995e-07 9.9999999999999995e-07 9.9999999999999995e-07" pos="0.5086328674519689 0 -0.34828403747654874"/>
        <body pos="0.5086328674519689 0 -0.34828403747654874" name="0/1/2/">
          <geom name="0/1/2/geom" class="0/1/2/" type="capsule" contype="1" conaffinity="1" condim="3" size="0.052420760078479817" rgba="0.52591703988000316 0.27734506955394611 0.30898660720154447 1" friction="0.59999999999999998 0.10000000000000001 0.10000000000000001" fromto="0 0 0 0.095138698964153168 0 0.34160616838157232"/>
          <site name="0/1/2/end2" class="0/1/2/" size="0.0050000000000000001" pos="0.095138698964153168 0 0.34160616838157232"/>
          <site name="0/1/2/attach3" class="0/1/2/" size="9.9999999999999995e-07 9.9999999999999995e-07 9.9999999999999995e-07" pos="0.091906830203902556 0 0.33000178114565593"/>
          <body pos="0.091906830203902556 0 0.33000178114565593" name="0/1/2/3/">
            <geom name="0/1/2/3/geom" class="0/1/2/3/" type="capsule" contype="1" conaffinity="1" condim="3" size="0.061661865023595872" rgba="0.29310823368882333 0.91478823075382365 0.8828704206754342 1" friction="0.59999999999999998 0.10000000000000001 0.10000000000000001" fromto="0 0 0 -0.036278329402647858 0 0.15668842662627225"/>
            <site name="0/1/2/3/end3" class="0/1/2/3/" size="0.0050000000000000001" pos="-0.036278329402647858 0 0.15668842662627225"/>
          </body>
          <site name="0/1/2/attach4" class="0/1/2/" size="9.9999999999999995e-07 9.9999999999999995e-07 9.9999999999999995e-07" pos="0.068301300433603496 0 0.24524347915870823"/>
          <body pos="0.068301300433603496 0 0.24524347915870823" name="0/1/2/4/">
            <joint name="0/1/2/4/joint/" class="0/1/2/" type="hinge" axis="0 1 0" limited="true" range="-37.006805637774264 37.006805637774264"/>
            <geom name="0/1/2/4/geom" class="0/1/2/4/" type="capsule" contype="1" conaffinity="1" condim="3" size="0.053559959985295363" rgba="0.77428992506706273 0.23313444718581944 0.29897592075283086 1" friction="0.59999999999999998 0.10000000000000001 0.10000000000000001" fromto="0 0 0 -0.43427228896782755 0 0.49762811471482227"/>
            <site name="0/1/2/4/end4" class="0/1/2/4/" size="0.0050000000000000001" pos="-0.43427228896782755 0 0.49762811471482227"/>
          </body>
          <site name="0/1/2/attach5" class="0/1/2/" size="9.9999999999999995e-07 9.9999999999999995e-07 9.9999999999999995e-07" pos="0.060206158513255767 0 0.21617696422815433"/>
          <body pos="0.060206158513255767 0 0.21617696422815433" name="0/1/2/5/">
            <joint name="0/1/2/5/joint/" class="0/1/2/" type="hinge" axis="0 1 0" limited="true" range="-51.690504881507827 51.690504881507827"/>
            <geom name="0/1/2/5/geom" class="0/1/2/5/" type="capsule" contype="1" conaffinity="1" condim="3" size="0.057042509751551132" rgba="0.39632574403459186 0.45475043065268883 0.46405212779362315 1" friction="0.59999999999999998 0.10000000000000001 0.10000000000000001" fromto="0 0 0 0.25757305984019618 0 -0.26947020058864529"/>
            <site name="0/1/2/5/end5" class="0/1/2/5/" size="0.0050000000000000001" pos="0.25757305984019618 0 -0.26947020058864529"/>
            <site name="0/1/2/5/attach6" class="0/1/2/5/" size="9.9999999999999995e-07 9.9999999999999995e-07 9.9999999999999995e-07" pos="0.17953149217689468 0 -0.18782394105541003"/>
            <body pos="0.17953149217689468 0 -0.18782394105541003" name="0/1/2/5/6/">
              <joint name="0/1/2/5/6/joint/" class="0/1/2/5/" type="hinge" axis="0 1 0" limited="true" range="-66.580125341069362 66.580125341069362"/>
              <geom name="0/1/2/5/6/geom" class="0/1/2/5/6/" type="capsule" contype="1" conaffinity="1" condim="3" size="0.052524246273404677" rgba="0.37175267920155131 0.53883757067596505 0.38317776478322596 1" friction="0.59999999999999998 0.10000000000000001 0.10000000000000001" fromto="0 0 0 0.025034788396099295 0 0.5927871761789838"/>
              <site name="0/1/2/5/6/end6" class="0/1/2/5/6/" size="0.0050000000000000001" pos="0.025034788396099295 0 0.5927871761789838"/>
              <site name="0/1/2/5/6/attach7" class="0/1/2/5/6/" size="9.9999999999999995e-07 9.9999999999999995e-07 9.9999999999999995e-07" pos="0.0028110730755011699 0 0.066562099271378267"/>
              <body pos="0.0028110730755011699 0 0.066562099271378267" name="0/1/2/5/6/7/">
                <joint name="0/1/2/5/6/7/joint/" class="0/1/2/5/6/" type="hinge" axis="0 1 0" limited="true" range="-46.616958832301371 46.616958832301371"/>
                <geom name="0/1/2/5/6/7/geom" class="0/1/2/5/6/7/" type="capsule" contype="1" conaffinity="1" condim="3" size="0.051242832272587996" rgba="0.59346140136751657 0.2890273278123745 0.47433749133132252 1" friction="0.59999999999999998 0.10000000000000001 0.10000000000000001" fromto="0 0 0 0.68290834502873077 0 -0.39393146880974961"/>
                <site name="0/1/2/5/6/7/end7" class="0/1/2/5/6/7/" size="0.0050000000000000001" pos="0.68290834502873077 0 -0.39393146880974961"/>
              </body>
              <site name="0/1/2/5/6/attach8" class="0/1/2/5/6/" size="9.9999999999999995e-07 9.9999999999999995e-07 9.9999999999999995e-07" pos="0.0056485780604808326 0 0.13375006750289584"/>
              <body pos="0.0056485780604808326 0 0.13375006750289584" name="0/1/2/5/6/8/">
                <joint name="0/1/2/5/6/8/joint/" class="0/1/2/5/6/" type="hinge" axis="0 1 0" limited="true" range="-65.654309318922444 65.654309318922444"/>
                <geom name="0/1/2/5/6/8/geom" class="0/1/2/5/6/8/" type="capsule" contype="1" conaffinity="1" condim="3" size="0.045422773357130922" rgba="0.064835074505571466 0.05443098731733953 0.30280142248090081 1" friction="0.59999999999999998 0.10000000000000001 0.10000000000000001" fromto="0 0 0 0.39389465186758166 0 -0.24024638789266239"/>
                <site name="0/1/2/5/6/8/end8" class="0/1/2/5/6/8/" size="0.0050000000000000001" pos="0.39389465186758166 0 -0.24024638789266239"/>
              </body>
            </body>
          </body>
        </body>
        <site name="0/1/attach9" class="0/1/" size="9.9999999999999995e-07 9.9999999999999995e-07 9.9999999999999995e-07" pos="0.14152292630780278 0 -0.096907178682534109"/>
        <body pos="0.14152292630780278 0 -0.096907178682534109" name="0/1/9/">
          <geom name="0/1/9/geom" class="0/1/9/" type="capsule" contype="1" conaffinity="1" condim="3" size="0.043508542722849854" rgba="0.49409494923767516 0.27482444780966786 0.12194706308362169 1" friction="0.59999999999999998 0.10000000000000001 0.10000000000000001" fromto="0 0 0 -0.070489750561125275 0 -0.37113286744602358"/>
          <site name="0/1/9/end9" class="0/1/9/" size="0.0050000000000000001" pos="-0.070489750561125275 0 -0.37113286744602358"/>
        </body>
      </body>
      <site name="0/attach10" class="0/" size="9.9999999999999995e-07 9.9999999999999995e-07 9.9999999999999995e-07" pos="0.13282922573831463 0 0.35848003137574158"/>
      <body pos="0.13282922573831463 0 0.35848003137574158" name="0/10/">
        <geom name="0/10/geom" class="0/10/" type="capsule" contype="1" conaffinity="1" condim="3" size="0.051872577242793282" rgba="0.11428423344915994 0.92380652345838665 0.30938766073766211 1" friction="0.59999999999999998 0.10000000000000001 0.10000000000000001" fromto="0 0 0 -0.47608844106979786 0 -0.057195966600340098"/>
        <site name="0/10/end10" class="0/10/" size="0.0050000000000000001" pos="-0.47608844106979786 0 -0.057195966600340098"/>
      </body>
      <camera name="0/side" class="0/" mode="trackcom" pos="0.40000000000000002 -4 0.20000000000000001" quat="0.70699999999999996 0.70699999999999996 0 0"/>
    </body>
  </worldbody>
  <actuator>
    <motor name="0/1/motor" class="0/1/" ctrllimited="true" ctrlrange="-1 1" gear="73" joint="0/1/joint/"/>
    <motor name="0/1/2/4/motor" class="0/1/2/4/" ctrllimited="true" ctrlrange="-1 1" gear="77" joint="0/1/2/4/joint/"/>
    <motor name="0/1/2/5/motor" class="0/1/2/5/" ctrllimited="true" ctrlrange="-1 1" gear="77" joint="0/1/2/5/joint/"/>
    <motor name="0/1/2/5/6/motor" class="0/1/2/5/6/" ctrllimited="true" ctrlrange="-1 1" gear="69" joint="0/1/2/5/6/joint/"/>
    <motor name="0/1/2/5/6/7/motor" class="0/1/2/5/6/7/" ctrllimited="true" ctrlrange="-1 1" gear="53" joint="0/1/2/5/6/7/joint/"/>
    <motor name="0/1/2/5/6/8/motor" class="0/1/2/5/6/8/" ctrllimited="true" ctrlrange="-1 1" gear="52" joint="0/1/2/5/6/8/joint/"/>
  </actuator>
  <sensor>
    <subtreelinvel name="velocity" body="0/"/>
  </sensor>
</mujoco>
