<mujoco model="morphology">
  <option timestep="0.01"/>
  <default>
    <default class="/"/>
    <default class="0/"/>
    <default class="0/1/"/>
    <default class="0/1/2/"/>
    <default class="0/1/3/"/>
    <default class="0/1/3/4/"/>
    <default class="0/1/3/4/5/"/>
    <default class="0/1/3/4/5/6/"/>
    <default class="0/1/3/7/"/>
  </default>
  <asset>
    <texture name="texplane" type="2d" builtin="checker" rgb1="0.10000000000000001 0.20000000000000001 0.29999999999999999" rgb2="0.20000000000000001 0.29999999999999999 0.40000000000000002" width="300" height="300"/>
    <material name="MatPlane" class="/" texture="texplane" texrepeat="20 20" specular="1" shininess="1" reflectance="0.5"/>
  </asset>
  <worldbody>
    <light name="//unnamed_light_0" class="/" directional="true" pos="0 0 1.5" dir="0 0 -1.3" cutoff="100" exponent="1" diffuse="1 1 1" specular="0.10000000000000001 0.10000000000000001 0.10000000000000001"/>
    <geom name="ground" class="/" type="plane" size="15 15 0.5" material="MatPlane" rgba="1 1 1 1"/>
    <site name="body" class="/" size="9.9999999999999995e-07 9.9999999999999995e-07 9.9999999999999995e-07" pos="0 0 0.10000000000000001"/>
    <body pos="0 0 0.10000000000000001" name="0/">
      <joint name="0/rootx/" class="/" type="slide" axis="1 0 0" limited="false" stiffness="0" armature="0" damping="0"/>
      <joint name="0/rootz/" class="/" type="slide" axis="0 0 1" limited="false" stiffness="0" armature="0" damping="0"/>
      <joint name="0/rooty/" class="/" type="hinge" axis="0 1 0" limited="false" stiffness="0" armature="0" damping="0"/>
      <geom name="0/geom" class="0/" type="capsule" contype="1" conaffinity="1" condim="3" size="0.055362694448792146" rgba="0.34123013434879035 0.23097372009363693 0.88451826832175906 1" friction="0.59999999999999998 0.10000000000000001 0.10000000000000001" fromto="0 0 0 -0.58995297469924779 0 0.50866682665337115"/>
      <site name="0/end0" class="0/" size="0.0050000000000000001" pos="-0.58995297469924779 0 0.50866682665337115"/>
      <site name="0/attach1" class="0/" size="9.9999999999999995e-07 9.9999999999999995e-07 9.9999999999999995e-07" pos="-0.51723217077795147 0 0.44596579428518057"/>
      <body pos="-0.51723217077795147 0 0.44596579428518057" name="0/1/">
        <geom name="0/1/geom" class="0/1/" type="capsule" contype="1" conaffinity="1" condim="3" size="0.041256814170679584" rgba="0.85674612859797716 0.89548587864999407 0.64203471260681355 1" friction="0.59999999999999998 0.10000000000000001 0.10000000000000001" fromto="0 0 0 0.39868896501661233 0 0.17360117520169516"/>
        <site name="0/1/end1" class="0/1/" size="0.0050000000000000001" pos="0.39868896501661233 0 0.17360117520169516"/>
        <site name="0/1/attach2" class="0/1/" size="9.9999999999999995e-07 9.9999999999999995e-07 9.9999999999999995e-07" pos="0.39554679327276066 0 0.17223297905060408"/>
        <body pos="0.39554679327276066 0 0.17223297905060408" name="0/1/2/">
          <joint name="0/1/2/joint/" class="0/1/" type="hinge" axis="0 1 0" limited="true" range="-58.057009747917192 58.057009747917192"/>
          <geom name="0/1/2/geom" class="0/1/2/" type="capsule" contype="1" conaffinity="1" condim="3" size="0.066319335934401896" rgba="0.31162631113043582 0.89888011199477702 0.75632039753958169 1" friction="0.59999999999999998 0.10000000000000001 0.10000000000000001" fromto="0 0 0 0.55282672265874266 0 0.47433331763873987"/>
          <site name="0/1/2/end2" class="0/1/2/" size="0.0050000000000000001" pos="0.55282672265874266 0 0.47433331763873987"/>
        </body>
        <site name="0/1/attach3" class="0/1/" size="9.9999999999999995e-07 9.9999999999999995e-07 9.9999999999999995e-07" pos="0.27061314993545155 0 0.11783311045960213"/>
        <body pos="0.27061314993545155 0 0.11783311045960213" name="0/1/3/">
          <joint name="0/1/3/joint/" class="0/1/" type="hinge" axis="0 1 0" limited="true" range="-30.726109704420281 30.726109704420281"/>
          <geom name="0/1/3/geom" class="0/1/3/" type="capsule" contype="1" conaffinity="1" condim="3" size="0.055619326789559095" rgba="0.62272952238599477 0.80666183125940927 0.62114794668932816 1" friction="0.59999999999999998 0.10000000000000001 0.10000000000000001" fromto="0 0 0 -0.56709246914423139 0 0.71893372526380261"/>
          <site name="0/1/3/end3" class="0/1/3/" size="0.0050000000000000001" pos="-0.56709246914423139 0 0.71893372526380261"/>
          <site name="0/1/3/attach4" class="0/1/3/" size="9.9999999999999995e-07 9.9999999999999995e-07 9.9999999999999995e-07" pos="-0.50491883905180579 0 0.64011285930701489"/>
          <body pos="-0.50491883905180579 0 0.64011285930701489" name="0/1/3/4/">
            <joint name="0/1/3/4/joint/" class="0/1/3/" type="hinge" axis="0 1 0" limited="true" range="-68.791526811892794 68.791526811892794"/>
            <geom name="0/1/3/4/geom" class="0/1/3/4/" type="capsule" contype="1" conaffinity="1" condim="3" size="0.045817448458853348" rgba="0.099039854911446845 0.62980656955682002 0.78562921131522134 1" friction="0.59999999999999998 0.10000000000000001 0.10000000000000001" fromto="0 0 0 0.32670640017584529 0 0.11713816725971871"/>
            <site name="0/1/3/4/end4" class="0/1/3/4/" size="0.0050000000000000001" pos="0.32670640017584529 0 0.11713816725971871"/>
            <site name="0/1/3/4/attach5" class="0/1/3/4/" size="9.9999999999999995e-07 9.9999999999999995e-07 9.9999999999999995e-07" pos="0.30390327644548448 0 0.10896227563306747"/>
            <body pos="0.30390327644548448 0 0.10896227563306747" name="0/1/3/4/5/">
              <geom name="0/1/3/4/5/geom" class="0/1/3/4/5/" type="capsule" contype="1" conaffinity="1" condim="3" size="0.053820972565777919" rgba="0.14225990823934909 0.81904754286834403 0.79921540816311809 1" friction="0.59999999999999998 0.10000000000000001 0.10000000000000001" fromto="0 0 0 0.14233978619985532 0 -0.15639187659514708"/>
              <site name="0/1/3/4/5/end5" class="0/1/3/4/5/" size="0.0050000000000000001" pos="0.14233978619985532 0 -0.15639187659514708"/>
              <site name="0/1/3/4/5/attach6" class="0/1/3/4/5/" size="9.9999999999999995e-07 9.9999999999999995e-07 9.9999999999999995e-07" pos="0.027165864748163952 0 -0.029847737450793162"/>
              <body pos="0.027165864748163952 0 -0.029847737450793162" name="0/1/3/4/5/6/">
                <joint name="0/1/3/4/5/6/joint/" class="0/1/3/4/5/" type="hinge" axis="0 1 0" limited="true" range="-69.529404146753336 69.529404146753336"/>
                <geom name="0/1/3/4/5/6/geom" class="0/1/3/4/5/6/" type="capsule" contype="1" conaffinity="1" condim="3" size="0.068197953234621009" rgba="0.31937449573277732 0.17730330356530366 0.82710528486261192 1" friction="0.59999999999999998 0.10000000000000001 0.10000000000000001" fromto="0 0 0 -0.070735759695260136 0 -0.28751978553859397"/>
                <site name="0/1/3/4/5/6/end6" class="0/1/3/4/5/6/" size="0.0050000000000000001" pos="-0.070735759695260136 0 -0.28751978553859397"/>
              </body>
            </body>
          </body>
          <site name="0/1/3/attach7" class="0/1/3/" size="9.9999999999999995e-07 9.9999999999999995e-07 9.9999999999999995e-07" pos="-0.4761130489116509 0 0.60359420469345548"/>
          <body pos="-0.4761130489116509 0 0.60359420469345548" name="0/1/3/7/">
            <joint name="0/1/3/7/joint/" class="0/1/3/" type="hinge" axis="0 1 0" limited="true" range="-54.428299036402436 54.428299036402436"/>
            <geom name="0/1/3/7/geom" class="0/1/3/7/" type="capsule" contype="1" conaffinity="1" condim="3" size="0.049291850988027811" rgba="0.65630392959547912 0.63454693685856534 0.60763296636105879 1" friction="0.59999999999999998 0.10000000000000001 0.10000000000000001" fromto="0 0 0 -0.44196038115568154 0 -0.26498378321453814"/>
            <site name="0/1/3/7/end7" class="0/1/3/7/" size="0.0050000000000000001" pos="-0.44196038115568154 0 -0.26498378321453814"/>
          </body>
        </body>
      </body>
      <camera name="0/side" class="0/" mode="trackcom" pos="0.40000000000000002 -4 0.20000000000000001" quat="0.70699999999999996 0.70699999999999996 0 0"/>
    </body>
  </worldbody>
  <actuator>
    <motor name="0/1/2/motor" class="0/1/2/" ctrllimited="true" ctrlrange="-1 1" gear="67" joint="0/1/2/joint/"/>
    <motor name="0/1/3/motor" class="0/1/3/" ctrllimited="true" ctrlrange="-1 1" gear="68" joint="0/1/3/joint/"/>
    <motor name="0/1/3/4/motor" class="0/1/3/4/" ctrllimited="true" ctrlrange="-1 1" gear="68" joint="0/1/3/4/joint/"/>
    <motor name="0/1/3/4/5/6/motor" class="0/1/3/4/5/6/" ctrllimited="true" ctrlrange="-1 1" gear="83" joint="0/1/3/4/5/6/joint/"/>
    <motor name="0/1/3/7/motor" class="0/1/3/7/" ctrllimited="true" ctrlrange="-1 1" gear="78" joint="0/1/3/7/joint/"/>
  </actuator>
  <sensor>
    <subtreelinvel name="velocity" body="0/"/>
  </sensor>
</mujoco>
