<mujoco model="morphology">
  <option timestep="0.01"/>
  <default>
    <default class="/"/>
    <default class="0/"/>
    <default class="0/1/"/>
    <default class="0/1/2/"/>
    <default class="0/1/2/3/"/>
    <default class="0/1/2/3/4/"/>
    <default class="0/1/2/3/4/5/"/>
    <default class="0/1/2/3/4/5/6/"/>
    <default class="0/1/2/3/7/"/>
    <default class="0/8/"/>
    <default class="0/9/"/>
    <default class="0/9/10/"/>
  </default>
  <asset>
    <texture name="texplane" type="2d" builtin="checker" rgb1="0.10000000000000001 0.20000000000000001 0.29999999999999999" rgb2="0.20000000000000001 0.29999999999999999 0.40000000000000002" width="300" height="300"/>
    <material name="MatPlane" class="/" texture="texplane" texrepeat="20 20" specular="1" shininess="1" reflectance="0.5"/>
  </asset>
  <worldbody>
    <light name="//unnamed_light_0" class="/" directional="true" pos="0 0 1.5" dir="0 0 -1.3" cutoff="100" exponent="1" diffuse="1 1 1" specular="0.10000000000000001 0.10000000000000001 0.10000000000000001"/>
    <geom name="ground" class="/" type="plane" size="15 15 0.5" material="MatPlane" rgba="1 1 1 1"/>
    <site name="body" class="/" size="9.9999999999999995e-07 9.9999999999999995e-07 9.9999999999999995e-07" pos="0 0 0.39529154300689695"/>
    <body pos="0 0 0.39529154300689695" name="0/">
      <joint name="0/rootx/" class="/" type="slide" axis="1 0 0" limited="false" stiffness="0" armature="0" damping="0"/>
      <joint name="0/rootz/" class="/" type="slide" axis="0 0 1" limited="false" stiffness="0" armature="0" damping="0"/>
      <joint name="0/rooty/" class="/" type="hinge" axis="0 1 0" limited="false" stiffness="0" armature="0" damping="0"/>
      <geom name="0/geom" class="0/" type="capsule" contype="1" conaffinity="1" condim="3" size="0.051460999772626873" rgba="0.8692239346788363 0.131538854394182 0.78323937379415298 1" friction="0.59999999999999998 0.10000000000000001 0.10000000000000001" fromto="0 0 0 -0.44431593564756239 0 0.32166649000425029"/>
      <site name="0/end0" class="0/" size="0.0050000000000000001" pos="-0.44431593564756239 0 0.32166649000425029"/>
      <site name="0/attach1" class="0/" size="9.9999999999999995e-07 9.9999999999999995e-07 9.9999999999999995e-07" pos="-0.10228761980653589 0 0.074052035937230837"/>
      <body pos="-0.10228761980653589 0 0.074052035937230837" name="0/1/">
        <joint name="0/1/joint/" class="0/" type="hinge" axis="0 1 0" limited="true" range="-49.156254005556953 49.156254005556953"/>
        <geom name="0/1/geom" class="0/1/" type="capsule" contype="1" conaffinity="1" condim="3" size="0.054679525063197155" rgba="0.65029518222701876 0.66429263059549537 0.52255477767247294 1" friction="0.59999999999999998 0.10000000000000001 0.10000000000000001" fromto="0 0 0 0.69501381142059748 0 0.22812789488216345"/>
        <site name="0/1/end1" class="0/1/" size="0.0050000000000000001" pos="0.69501381142059748 0 0.22812789488216345"/>
        <site name="0/1/attach2" class="0/1/" size="9.9999999999999995e-07 9.9999999999999995e-07 9.9999999999999995e-07" pos="0.52409194748355636 0 0.17202534789882562"/>
        <body pos="0.52409194748355636 0 0.17202534789882562" name="0/1/2/">
          <joint name="0/1/2/joint/" class="0/1/" type="hinge" axis="0 1 0" limited="true" range="-37.953843706270568 37.953843706270568"/>
          <geom name="0/1/2/geom" class="0/1/2/" type="capsule" contype="1" conaffinity="1" condim="3" size="0.057662278500642941" rgba="0.26846665774619349 0.22838632131548975 0.64257944422761537 1" friction="0.59999999999999998 0.10000000000000001 0.10000000000000001" fromto="0 0 0 0.043033891926759882 0 0.43392088547190633"/>
          <site name="0/1/2/end2" class="0/1/2/" size="0.0050000000000000001" pos="0.043033891926759882 0 0.43392088547190633"/>
          <site name="0/1/2/attach3" class="0/1/2/" size="9.9999999999999995e-07 9.9999999999999995e-07 9.9999999999999995e-07" pos="0.031529672310737049 0 0.31792112484268559"/>
          <body pos="0.031529672310737049 0 0.31792112484268559" name="0/1/2/3/">
            <joint name="0/1/2/3/joint/" class="0/1/2/" type="hinge" axis="0 1 0" limited="true" range="-69.502982493023325 69.502982493023325"/>
            <geom name="0/1/2/3/geom" class="0/1/2/3/" type="capsule" contype="1" conaffinity="1" condim="3" size="0.048187335131496374" rgba="0.9426834903705047 0.71023560027411958 0.40948187495726052 1" friction="0.59999999999999998 0.10000000000000001 0.10000000000000001" fromto="0 0 0 0.13814280765346676 0 -0.04986899562376057"/>
            <site name="0/1/2/3/end3" class="0/1/2/3/" size="0.0050000000000000001" pos="0.13814280765346676 0 -0.04986899562376057"/>
            <site name="0/1/2/3/attach4" class="0/1/2/3/" size="9.9999999999999995e-07 9.9999999999999995e-07 9.9999999999999995e-07" pos="0.12311766427527561 0 -0.044444979548649434"/>
            <body pos="0.12311766427527561 0 -0.044444979548649434" name="0/1/2/3/4/">
              <joint name="0/1/2/3/4/joint/" class="0/1/2/3/" type="hinge" axis="0 1 0" limited="true" range="-69.534079557267901 69.534079557267901"/>
              <geom name="0/1/2/3/4/geom" class="0/1/2/3/4/" type="capsule" contype="1" conaffinity="1" condim="3" size="0.055662877390429633" rgba="0.55455077032462352 0.79801140619887534 0.51167085903421994 1" friction="0.59999999999999998 0.10000000000000001 0.10000000000000001" fromto="0 0 0 0.25307844078254993 0 0.69799003642398239"/>
              <site name="0/1/2/3/4/end4" class="0/1/2/3/4/" size="0.0050000000000000001" pos="0.25307844078254993 0 0.69799003642398239"/>
              <site name="0/1/2/3/4/attach5" class="0/1/2/3/4/" size="9.9999999999999995e-07 9.9999999999999995e-07 9.9999999999999995e-07" pos="0.10567609791174723 0 0.29145455141294152"/>
              <body pos="0.10567609791174723 0 0.29145455141294152" name="0/1/2/3/4/5/">
                <joint name="0/1/2/3/4/5/joint/" class="0/1/2/3/4/" type="hinge" axis="0 1 0" limited="true" range="-42.938428627956334 42.938428627956334"/>
                <geom name="0/1/2/3/4/5/geom" class="0/1/2/3/4/5/" type="capsule" contype="1" conaffinity="1" condim="3" size="0.040423087945256529" rgba="0.70386170644742507 0.044068818368497964 0.5718474263057034 1" friction="0.59999999999999998 0.10000000000000001 0.10000000000000001" fromto="0 0 0 0.4997335762843913 0 -0.24939217255440838"/>
                <site name="0/1/2/3/4/5/end5" class="0/1/2/3/4/5/" size="0.0050000000000000001" pos="0.4997335762843913 0 -0.24939217255440838"/>
                <site name="0/1/2/3/4/5/attach6" class="0/1/2/3/4/5/" size="9.9999999999999995e-07 9.9999999999999995e-07 9.9999999999999995e-07" pos="0.45380052228579798 0 -0.22646926988706975"/>
                <body pos="0.45380052228579798 0 -0.22646926988706975" name="0/1/2/3/4/5/6/">
                  <joint name="0/1/2/3/4/5/6/joint/" class="0/1/2/3/4/5/" type="hinge" axis="0 1 0" limited="true" range="-47.444575860638572 47.444575860638572"/>
                  <geom name="0/1/2/3/4/5/6/geom" class="0/1/2/3/4/5/6/" type="capsule" contype="1" conaffinity="1" condim="3" size="0.062111150702038397" rgba="0.61522977803621626 0.39203436200832031 0.69694802157161528 1" friction="0.59999999999999998 0.10000000000000001 0.10000000000000001" fromto="0 0 0 -0.068874441731287428 0 0.58734427328830296"/>
                  <site name="0/1/2/3/4/5/6/end6" class="0/1/2/3/4/5/6/" size="0.0050000000000000001" pos="-0.068874441731287428 0 0.58734427328830296"/>
                </body>
              </body>
            </body>
            <site name="0/1/2/3/attach7" class="0/1/2/3/" size="9.9999999999999995e-07 9.9999999999999995e-07 9.9999999999999995e-07" pos="0.10633872015343408 0 -0.03838784848843213"/>
            <body pos="0.10633872015343408 0 -0.03838784848843213" name="0/1/2/3/7/">
              <geom name="0/1/2/3/7/geom" class="0/1/2/3/7/" type="capsule" contype="1" conaffinity="1" condim="3" size="0.042345861970123688" rgba="0.70330442704802909 0.16414331085884726 0.93160994503898786 1" friction="0.59999999999999998 0.10000000000000001 0.10000000000000001" fromto="0 0 0 -0.072812123328147793 0 0.44804350258763215"/>
              <site name="0/1/2/3/7/end7" class="0/1/2/3/7/" size="0.0050000000000000001" pos="-0.072812123328147793 0 0.44804350258763215"/>
            </body>
          </body>
        </body>
      </body>
      <site name="0/attach8" class="0/" size="9.9999999999999995e-07 9.9999999999999995e-07 9.9999999999999995e-07" pos="-0.19076629620645782 0 0.13810696396114971"/>
      <body pos="-0.19076629620645782 0 0.13810696396114971" name="0/8/">
        <joint name="0/8/joint/" class="0/" type="hinge" axis="0 1 0" limited="true" range="-53.797660425199922 53.797660425199922"/>
        <geom name="0/8/geom" class="0/8/" type="capsule" contype="1" conaffinity="1" condim="3" size="0.065260971154782188" rgba="0.19434035176541897 0.50064570954109666 0.65297070386781519 1" friction="0.59999999999999998 0.10000000000000001 0.10000000000000001" fromto="0 0 0 0.32260247201976489 0 0.57933223609946705"/>
        <site name="0/8/end8" class="0/8/" size="0.0050000000000000001" pos="0.32260247201976489 0 0.57933223609946705"/>
      </body>
      <site name="0/attach9" class="0/" size="9.9999999999999995e-07 9.9999999999999995e-07 9.9999999999999995e-07" pos="-0.39131630159076591 0 0.28329693156445956"/>
      <body pos="-0.39131630159076591 0 0.28329693156445956" name="0/9/">
        <joint name="0/9/joint/" class="0/" type="hinge" axis="0 1 0" limited="true" range="-30.997659684181912 30.997659684181912"/>
        <geom name="0/9/geom" class="0/9/" type="capsule" contype="1" conaffinity="1" condim="3" size="0.050992421251135941" rgba="0.36920033328833957 0.70922524373388007 0.82637758037222664 1" friction="0.59999999999999998 0.10000000000000001 0.10000000000000001" fromto="0 0 0 -0.24942068503109427 0 -0.26976180750215778"/>
        <site name="0/9/end9" class="0/9/" size="0.0050000000000000001" pos="-0.24942068503109427 0 -0.26976180750215778"/>
        <site name="0/9/attach10" class="0/9/" size="9.9999999999999995e-07 9.9999999999999995e-07 9.9999999999999995e-07" pos="-0.23248245395957207 0 -0.25144220490314556"/>
        <body pos="-0.23248245395957207 0 -0.25144220490314556" name="0/9/10/">
          <joint name="0/9/10/joint/" class="0/9/" type="hinge" axis="0 1 0" limited="true" range="-35.630225526291987 35.630225526291987"/>
          <geom name="0/9/10/geom" class="0/9/10/" type="capsule" contype="1" conaffinity="1" condim="3" size="0.065586019576075447" rgba="0.25095666698281716 0.73400161465879254 0.87321541366313216 1" friction="0.59999999999999998 0.10000000000000001 0.10000000000000001" fromto="0 0 0 0.72497205874421544 0 -0.32714626508572175"/>
          <site name="0/9/10/end10" class="0/9/10/" size="0.0050000000000000001" pos="0.72497205874421544 0 -0.32714626508572175"/>
        </body>
      </body>
      <camera name="0/side" class="0/" mode="trackcom" pos="0.40000000000000002 -4 0.20000000000000001" quat="0.70699999999999996 0.70699999999999996 0 0"/>
    </body>
  </worldbody>
  <actuator>
    <motor name="0/1/motor" class="0/1/" ctrllimited="true" ctrlrange="-1 1" gear="85" joint="0/1/joint/"/>
    <motor name="0/1/2/motor" class="0/1/2/" ctrllimited="true" ctrlrange="-1 1" gear="71" joint="0/1/2/joint/"/>
    <motor name="0/1/2/3/motor" class="0/1/2/3/" ctrllimited="true" ctrlrange="-1 1" gear="63" joint="0/1/2/3/joint/"/>
    <motor name="0/1/2/3/4/motor" class="0/1/2/3/4/" ctrllimited="true" ctrlrange="-1 1" gear="86" joint="0/1/2/3/4/joint/"/>
    <motor name="0/1/2/3/4/5/motor" class="0/1/2/3/4/5/" ctrllimited="true" ctrlrange="-1 1" gear="68" joint="0/1/2/3/4/5/joint/"/>
    <motor name="0/1/2/3/4/5/6/motor" class="0/1/2/3/4/5/6/" ctrllimited="true" ctrlrange="-1 1" gear="67" joint="0/1/2/3/4/5/6/joint/"/>
    <motor name="0/8/motor" class="0/8/" ctrllimited="true" ctrlrange="-1 1" gear="70" joint="0/8/joint/"/>
    <motor name="0/9/motor" class="0/9/" ctrllimited="true" ctrlrange="-1 1" gear="86" joint="0/9/joint/"/>
    <motor name="0/9/10/motor" class="0/9/10/" ctrllimited="true" ctrlrange="-1 1" gear="89" joint="0/9/10/joint/"/>
  </actuator>
  <sensor>
    <subtreelinvel name="velocity" body="0/"/>
  </sensor>
</mujoco>
