<mujoco model="morphology">
  <option timestep="0.01"/>
  <default>
    <default class="/"/>
    <default class="0/"/>
    <default class="0/1/"/>
    <default class="0/1/2/"/>
    <default class="0/3/"/>
    <default class="0/3/4/"/>
    <default class="0/3/4/5/"/>
    <default class="0/3/6/"/>
  </default>
  <asset>
    <texture name="texplane" type="2d" builtin="checker" rgb1="0.10000000000000001 0.20000000000000001 0.29999999999999999" rgb2="0.20000000000000001 0.29999999999999999 0.40000000000000002" width="300" height="300"/>
    <material name="MatPlane" class="/" texture="texplane" texrepeat="20 20" specular="1" shininess="1" reflectance="0.5"/>
  </asset>
  <worldbody>
    <light name="//unnamed_light_0" class="/" directional="true" pos="0 0 1.5" dir="0 0 -1.3" cutoff="100" exponent="1" diffuse="1 1 1" specular="0.10000000000000001 0.10000000000000001 0.10000000000000001"/>
    <geom name="ground" class="/" type="plane" size="15 15 0.5" material="MatPlane" rgba="1 1 1 1"/>
    <site name="body" class="/" size="9.9999999999999995e-07 9.9999999999999995e-07 9.9999999999999995e-07" pos="0 0 1.0902424216270448"/>
    <body pos="0 0 1.0902424216270448" name="0/">
      <joint name="0/rootx/" class="/" type="slide" axis="1 0 0" limited="false" stiffness="0" armature="0" damping="0"/>
      <joint name="0/rootz/" class="/" type="slide" axis="0 0 1" limited="false" stiffness="0" armature="0" damping="0"/>
      <joint name="0/rooty/" class="/" type="hinge" axis="0 1 0" limited="false" stiffness="0" armature="0" damping="0"/>
      <geom name="0/geom" class="0/" type="capsule" contype="1" conaffinity="1" condim="3" size="0.043056627315821903" rgba="0.50919774827375852 0.52399143477694898 0.15332503073214421 1" friction="0.59999999999999998 0.10000000000000001 0.10000000000000001" fromto="0 0 0 -0.65219473666458827 0 0.11759318222897219"/>
      <site name="0/end0" class="0/" size="0.0050000000000000001" pos="-0.65219473666458827 0 0.11759318222897219"/>
      <site name="0/attach1" class="0/" size="9.9999999999999995e-07 9.9999999999999995e-07 9.9999999999999995e-07" pos="-0.59680767168991944 0 0.1076066845488418"/>
      <body pos="-0.59680767168991944 0 0.1076066845488418" name="0/1/">
        <joint name="0/1/joint/" class="0/" type="hinge" axis="0 1 0" limited="true" range="-31.488016825447204 31.488016825447204"/>
        <geom name="0/1/geom" class="0/1/" type="capsule" contype="1" conaffinity="1" condim="3" size="0.067428311145075276" rgba="0.45913276229127986 0.71454164421467758 0.19983886503365733 1" friction="0.59999999999999998 0.10000000000000001 0.10000000000000001" fromto="0 0 0 0.67988341390569529 0 0.72803865111364274"/>
        <site name="0/1/end1" class="0/1/" size="0.0050000000000000001" pos="0.67988341390569529 0 0.72803865111364274"/>
        <site name="0/1/attach2" class="0/1/" size="9.9999999999999995e-07 9.9999999999999995e-07 9.9999999999999995e-07" pos="0.15584182390774814 0 0.16687989285266541"/>
        <body pos="0.15584182390774814 0 0.16687989285266541" name="0/1/2/">
          <joint name="0/1/2/joint/" class="0/1/" type="hinge" axis="0 1 0" limited="true" range="-60.954007684505413 60.954007684505413"/>
          <geom name="0/1/2/geom" class="0/1/2/" type="capsule" contype="1" conaffinity="1" condim="3" size="0.04037277631988441" rgba="0.94402394577496851 0.77986434831425699 0.34961620074273925 1" friction="0.59999999999999998 0.10000000000000001 0.10000000000000001" fromto="0 0 0 -0.73508900688780865 0 0.65330587823132036"/>
          <site name="0/1/2/end2" class="0/1/2/" size="0.0050000000000000001" pos="-0.73508900688780865 0 0.65330587823132036"/>
        </body>
      </body>
      <site name="0/attach3" class="0/" size="9.9999999999999995e-07 9.9999999999999995e-07 9.9999999999999995e-07" pos="-0.033438206941392663 0 0.0060290354110776575"/>
      <body pos="-0.033438206941392663 0 0.0060290354110776575" name="0/3/">
        <joint name="0/3/joint/" class="0/" type="hinge" axis="0 1 0" limited="true" range="-41.033120307263474 41.033120307263474"/>
        <geom name="0/3/geom" class="0/3/" type="capsule" contype="1" conaffinity="1" condim="3" size="0.050750426200544409" rgba="0.31853670963658598 0.26785691925883248 0.61107458340631671 1" friction="0.59999999999999998 0.10000000000000001 0.10000000000000001" fromto="0 0 0 -0.38966549858472999 0 -0.74131933250383142"/>
        <site name="0/3/end3" class="0/3/" size="0.0050000000000000001" pos="-0.38966549858472999 0 -0.74131933250383142"/>
        <site name="0/3/attach4" class="0/3/" size="9.9999999999999995e-07 9.9999999999999995e-07 9.9999999999999995e-07" pos="-0.15326724484284712 0 -0.29158335047436812"/>
        <body pos="-0.15326724484284712 0 -0.29158335047436812" name="0/3/4/">
          <joint name="0/3/4/joint/" class="0/3/" type="hinge" axis="0 1 0" limited="true" range="-55.607505810068062 55.607505810068062"/>
          <geom name="0/3/4/geom" class="0/3/4/" type="capsule" contype="1" conaffinity="1" condim="3" size="0.051212179645373765" rgba="0.79410399972372425 0.99423307978930842 0.1524498807933421 1" friction="0.59999999999999998 0.10000000000000001 0.10000000000000001" fromto="0 0 0 0.43378596424842364 0 -0.60947856978364423"/>
          <site name="0/3/4/end4" class="0/3/4/" size="0.0050000000000000001" pos="0.43378596424842364 0 -0.60947856978364423"/>
          <site name="0/3/4/attach5" class="0/3/4/" size="9.9999999999999995e-07 9.9999999999999995e-07 9.9999999999999995e-07" pos="0.14462188382376451 0 -0.20319684401278934"/>
          <body pos="0.14462188382376451 0 -0.20319684401278934" name="0/3/4/5/">
            <joint name="0/3/4/5/joint/" class="0/3/4/" type="hinge" axis="0 1 0" limited="true" range="-37.357303012486064 37.357303012486064"/>
            <geom name="0/3/4/5/geom" class="0/3/4/5/" type="capsule" contype="1" conaffinity="1" condim="3" size="0.041707325110479844" rgba="0.59650683678459437 0.82196745883307432 0.54874329455574766 1" friction="0.59999999999999998 0.10000000000000001 0.10000000000000001" fromto="0 0 0 -0.49719359145766956 0 -0.50149125229496949"/>
            <site name="0/3/4/5/end5" class="0/3/4/5/" size="0.0050000000000000001" pos="-0.49719359145766956 0 -0.50149125229496949"/>
          </body>
        </body>
        <site name="0/3/attach6" class="0/3/" size="9.9999999999999995e-07 9.9999999999999995e-07 9.9999999999999995e-07" pos="-0.05561997536390894 0 -0.10581425135252738"/>
        <body pos="-0.05561997536390894 0 -0.10581425135252738" name="0/3/6/">
          <joint name="0/3/6/joint/" class="0/3/" type="hinge" axis="0 1 0" limited="true" range="-57.824121912497645 57.824121912497645"/>
          <geom name="0/3/6/geom" class="0/3/6/" type="capsule" contype="1" conaffinity="1" condim="3" size="0.047610283647077332" rgba="0.54870776050857972 0.33775690275867365 0.39660705753957437 1" friction="0.59999999999999998 0.10000000000000001 0.10000000000000001" fromto="0 0 0 0.62721909033922474 0 -0.70645530365088249"/>
          <site name="0/3/6/end6" class="0/3/6/" size="0.0050000000000000001" pos="0.62721909033922474 0 -0.70645530365088249"/>
        </body>
      </body>
      <camera name="0/side" class="0/" mode="trackcom" pos="0.40000000000000002 -4 0.20000000000000001" quat="0.70699999999999996 0.70699999999999996 0 0"/>
    </body>
  </worldbody>
  <actuator>
    <motor name="0/1/motor" class="0/1/" ctrllimited="true" ctrlrange="-1 1" gear="63" joint="0/1/joint/"/>
    <motor name="0/1/2/motor" class="0/1/2/" ctrllimited="true" ctrlrange="-1 1" gear="62" joint="0/1/2/joint/"/>
    <motor name="0/3/motor" class="0/3/" ctrllimited="true" ctrlrange="-1 1" gear="85" joint="0/3/joint/"/>
    <motor name="0/3/4/motor" class="0/3/4/" ctrllimited="true" ctrlrange="-1 1" gear="73" joint="0/3/4/joint/"/>
    <motor name="0/3/4/5/motor" class="0/3/4/5/" ctrllimited="true" ctrlrange="-1 1" gear="69" joint="0/3/4/5/joint/"/>
    <motor name="0/3/6/motor" class="0/3/6/" ctrllimited="true" ctrlrange="-1 1" gear="74" joint="0/3/6/joint/"/>
  </actuator>
  <sensor>
    <subtreelinvel name="velocity" body="0/"/>
  </sensor>
</mujoco>
