<mujoco model="morphology">
  <option timestep="0.01"/>
  <default>
    <default class="/"/>
    <default class="0/"/>
    <default class="0/1/"/>
    <default class="0/1/2/"/>
    <default class="0/1/2/3/"/>
    <default class="0/1/2/3/4/"/>
    <default class="0/1/2/3/4/5/"/>
    <default class="0/1/2/3/4/5/6/"/>
    <default class="0/1/2/3/4/5/6/7/"/>
    <default class="0/1/2/3/4/5/8/"/>
    <default class="0/1/2/3/4/5/8/9/"/>
    <default class="0/1/2/3/4/5/8/9/10/"/>
  </default>
  <asset>
    <texture name="texplane" type="2d" builtin="checker" rgb1="0.10000000000000001 0.20000000000000001 0.29999999999999999" rgb2="0.20000000000000001 0.29999999999999999 0.40000000000000002" width="300" height="300"/>
    <material name="MatPlane" class="/" texture="texplane" texrepeat="20 20" specular="1" shininess="1" reflectance="0.5"/>
  </asset>
  <worldbody>
    <light name="//unnamed_light_0" class="/" directional="true" pos="0 0 1.5" dir="0 0 -1.3" cutoff="100" exponent="1" diffuse="1 1 1" specular="0.10000000000000001 0.10000000000000001 0.10000000000000001"/>
    <geom name="ground" class="/" type="plane" size="15 15 0.5" material="MatPlane" rgba="1 1 1 1"/>
    <site name="body" class="/" size="9.9999999999999995e-07 9.9999999999999995e-07 9.9999999999999995e-07" pos="0 0 1.2471182107925416"/>
    <body pos="0 0 1.2471182107925416" name="0/">
      <joint name="0/rootx/" class="/" type="slide" axis="1 0 0" limited="false" stiffness="0" armature="0" damping="0"/>
      <joint name="0/rootz/" class="/" type="slide" axis="0 0 1" limited="false" stiffness="0" armature="0" damping="0"/>
      <joint name="0/rooty/" class="/" type="hinge" axis="0 1 0" limited="false" stiffness="0" armature="0" damping="0"/>
      <geom name="0/geom" class="0/" type="capsule" contype="1" conaffinity="1" condim="3" size="0.06614778233389218" rgba="0.30268895611549784 0.85254273265039016 0.38757793896572479 1" friction="0.59999999999999998 0.10000000000000001 0.10000000000000001" fromto="0 0 0 0.41709012959092706 0 -0.25958174689826646"/>
      <site name="0/end0" class="0/" size="0.0050000000000000001" pos="0.41709012959092706 0 -0.25958174689826646"/>
      <site name="0/attach1" class="0/" size="9.9999999999999995e-07 9.9999999999999995e-07 9.9999999999999995e-07" pos="0.32327296859901311 0 -0.20119335357138041"/>
      <body pos="0.32327296859901311 0 -0.20119335357138041" name="0/1/">
        <joint name="0/1/joint/" class="0/" type="hinge" axis="0 1 0" limited="true" stiffness="100" range="-57.492528761682479 57.492528761682479" armature="0.20000000000000001" damping="3.5"/>
        <geom name="0/1/geom" class="0/1/" type="capsule" contype="1" conaffinity="1" condim="3" size="0.043233817073442767" rgba="0.58686146396473249 0.17175579357834825 0.79643750731492469 1" friction="0.59999999999999998 0.10000000000000001 0.10000000000000001" fromto="0 0 0 0.59801241375160119 0 0.48068570112876707"/>
        <site name="0/1/end1" class="0/1/" size="0.0050000000000000001" pos="0.59801241375160119 0 0.48068570112876707"/>
        <site name="0/1/attach2" class="0/1/" size="9.9999999999999995e-07 9.9999999999999995e-07 9.9999999999999995e-07" pos="0.29787475593834178 0 0.23943338401375924"/>
        <body pos="0.29787475593834178 0 0.23943338401375924" name="0/1/2/">
          <joint name="0/1/2/joint/" class="0/1/" type="hinge" axis="0 1 0" limited="true" stiffness="100" range="-43.368972648362544 43.368972648362544" armature="0.20000000000000001" damping="3.5"/>
          <geom name="0/1/2/geom" class="0/1/2/" type="capsule" contype="1" conaffinity="1" condim="3" size="0.041398192574464081" rgba="0.94020410150093459 0.43730769049255847 0.82971361641851971 1" friction="0.59999999999999998 0.10000000000000001 0.10000000000000001" fromto="0 0 0 0.23940201159298613 0 -0.30074833658795891"/>
          <site name="0/1/2/end2" class="0/1/2/" size="0.0050000000000000001" pos="0.23940201159298613 0 -0.30074833658795891"/>
          <site name="0/1/2/attach3" class="0/1/2/" size="9.9999999999999995e-07 9.9999999999999995e-07 9.9999999999999995e-07" pos="0.16632676517851577 0 -0.20894769273091687"/>
          <body pos="0.16632676517851577 0 -0.20894769273091687" name="0/1/2/3/">
            <joint name="0/1/2/3/joint/" class="0/1/2/" type="hinge" axis="0 1 0" limited="true" stiffness="100" range="-69.125183779508461 69.125183779508461" armature="0.20000000000000001" damping="3.5"/>
            <geom name="0/1/2/3/geom" class="0/1/2/3/" type="capsule" contype="1" conaffinity="1" condim="3" size="0.060395958857458715" rgba="0.83665350957330786 0.96279189225561845 0.82597950975898404 1" friction="0.59999999999999998 0.10000000000000001 0.10000000000000001" fromto="0 0 0 -0.49311725234228793 0 -0.21333682464425774"/>
            <site name="0/1/2/3/end3" class="0/1/2/3/" size="0.0050000000000000001" pos="-0.49311725234228793 0 -0.21333682464425774"/>
            <site name="0/1/2/3/attach4" class="0/1/2/3/" size="9.9999999999999995e-07 9.9999999999999995e-07 9.9999999999999995e-07" pos="-0.083684215168280299 0 -0.03620421847349093"/>
            <body pos="-0.083684215168280299 0 -0.03620421847349093" name="0/1/2/3/4/">
              <joint name="0/1/2/3/4/joint/" class="0/1/2/3/" type="hinge" axis="0 1 0" limited="true" stiffness="100" range="-31.605974834382927 31.605974834382927" armature="0.20000000000000001" damping="3.5"/>
              <geom name="0/1/2/3/4/geom" class="0/1/2/3/4/" type="capsule" contype="1" conaffinity="1" condim="3" size="0.06741004698647865" rgba="0.5651700755784802 0.41233965757287783 0.78970357112122969 1" friction="0.59999999999999998 0.10000000000000001 0.10000000000000001" fromto="0 0 0 -0.088875349849741658 0 -0.48056176441492343"/>
              <site name="0/1/2/3/4/end4" class="0/1/2/3/4/" size="0.0050000000000000001" pos="-0.088875349849741658 0 -0.48056176441492343"/>
              <site name="0/1/2/3/4/attach5" class="0/1/2/3/4/" size="9.9999999999999995e-07 9.9999999999999995e-07 9.9999999999999995e-07" pos="-0.068827015731114258 0 -0.37215754621588248"/>
              <body pos="-0.068827015731114258 0 -0.37215754621588248" name="0/1/2/3/4/5/">
                <geom name="0/1/2/3/4/5/geom" class="0/1/2/3/4/5/" type="capsule" contype="1" conaffinity="1" condim="3" size="0.042344991311849926" rgba="0.33174340566919203 0.19978033955670949 0.10156901849086608 1" friction="0.59999999999999998 0.10000000000000001 0.10000000000000001" fromto="0 0 0 -0.74724823202757418 0 -0.077940145200911415"/>
                <site name="0/1/2/3/4/5/end5" class="0/1/2/3/4/5/" size="0.0050000000000000001" pos="-0.74724823202757418 0 -0.077940145200911415"/>
                <site name="0/1/2/3/4/5/attach6" class="0/1/2/3/4/5/" size="9.9999999999999995e-07 9.9999999999999995e-07 9.9999999999999995e-07" pos="-0.29570106840709337 0 -0.030842474053338464"/>
                <body pos="-0.29570106840709337 0 -0.030842474053338464" name="0/1/2/3/4/5/6/">
                  <joint name="0/1/2/3/4/5/6/joint/" class="0/1/2/3/4/5/" type="hinge" axis="0 1 0" limited="true" stiffness="100" range="-60.881317654024244 60.881317654024244" armature="0.20000000000000001" damping="3.5"/>
                  <geom name="0/1/2/3/4/5/6/geom" class="0/1/2/3/4/5/6/" type="capsule" contype="1" conaffinity="1" condim="3" size="0.045240721421198657" rgba="0.15843990813032116 0.17436689155596297 0.41425596611952886 1" friction="0.59999999999999998 0.10000000000000001 0.10000000000000001" fromto="0 0 0 -0.15597417026780469 0 -0.53720627646154262"/>
                  <site name="0/1/2/3/4/5/6/end6" class="0/1/2/3/4/5/6/" size="0.0050000000000000001" pos="-0.15597417026780469 0 -0.53720627646154262"/>
                  <site name="0/1/2/3/4/5/6/attach7" class="0/1/2/3/4/5/6/" size="9.9999999999999995e-07 9.9999999999999995e-07 9.9999999999999995e-07" pos="-0.10350181295781319 0 -0.35648097021845726"/>
                  <body pos="-0.10350181295781319 0 -0.35648097021845726" name="0/1/2/3/4/5/6/7/">
                    <joint name="0/1/2/3/4/5/6/7/joint/" class="0/1/2/3/4/5/6/" type="hinge" axis="0 1 0" limited="true" stiffness="100" range="-61.533325678190167 61.533325678190167" armature="0.20000000000000001" damping="3.5"/>
                    <geom name="0/1/2/3/4/5/6/7/geom" class="0/1/2/3/4/5/6/7/" type="capsule" contype="1" conaffinity="1" condim="3" size="0.051366476247471052" rgba="0.34589886141692705 0.30843391765997241 0.029360563215850122 1" friction="0.59999999999999998 0.10000000000000001 0.10000000000000001" fromto="0 0 0 -0.64054477118897601 0 -0.13749176248980088"/>
                    <site name="0/1/2/3/4/5/6/7/end7" class="0/1/2/3/4/5/6/7/" size="0.0050000000000000001" pos="-0.64054477118897601 0 -0.13749176248980088"/>
                  </body>
                </body>
                <site name="0/1/2/3/4/5/attach8" class="0/1/2/3/4/5/" size="9.9999999999999995e-07 9.9999999999999995e-07 9.9999999999999995e-07" pos="-0.35352293009608082 0 -0.036873460949886118"/>
                <body pos="-0.35352293009608082 0 -0.036873460949886118" name="0/1/2/3/4/5/8/">
                  <joint name="0/1/2/3/4/5/8/joint/" class="0/1/2/3/4/5/" type="hinge" axis="0 1 0" limited="true" stiffness="100" range="-38.432763347289878 38.432763347289878" armature="0.20000000000000001" damping="3.5"/>
                  <geom name="0/1/2/3/4/5/8/geom" class="0/1/2/3/4/5/8/" type="capsule" contype="1" conaffinity="1" condim="3" size="0.065409236484712155" rgba="0.36258721763352753 0.72118041019778922 0.54790363649883789 1" friction="0.59999999999999998 0.10000000000000001 0.10000000000000001" fromto="0 0 0 0.018225381008903585 0 0.16225428375072726"/>
                  <site name="0/1/2/3/4/5/8/end8" class="0/1/2/3/4/5/8/" size="0.0050000000000000001" pos="0.018225381008903585 0 0.16225428375072726"/>
                  <site name="0/1/2/3/4/5/8/attach9" class="0/1/2/3/4/5/8/" size="9.9999999999999995e-07 9.9999999999999995e-07 9.9999999999999995e-07" pos="0.0077449501848931412 0 0.068950621351673888"/>
                  <body pos="0.0077449501848931412 0 0.068950621351673888" name="0/1/2/3/4/5/8/9/">
                    <joint name="0/1/2/3/4/5/8/9/joint/" class="0/1/2/3/4/5/8/" type="hinge" axis="0 1 0" limited="true" stiffness="100" range="-63.196498189391754 63.196498189391754" armature="0.20000000000000001" damping="3.5"/>
                    <geom name="0/1/2/3/4/5/8/9/geom" class="0/1/2/3/4/5/8/9/" type="capsule" contype="1" conaffinity="1" condim="3" size="0.046587445014997918" rgba="0.12605267900464256 0.358403745655136 0.63542237463447226 1" friction="0.59999999999999998 0.10000000000000001 0.10000000000000001" fromto="0 0 0 -0.61792393634160225 0 0.4082896574031305"/>
                    <site name="0/1/2/3/4/5/8/9/end9" class="0/1/2/3/4/5/8/9/" size="0.0050000000000000001" pos="-0.61792393634160225 0 0.4082896574031305"/>
                    <site name="0/1/2/3/4/5/8/9/attach10" class="0/1/2/3/4/5/8/9/" size="9.9999999999999995e-07 9.9999999999999995e-07 9.9999999999999995e-07" pos="-0.58363147303616925 0 0.38563111114680865"/>
                    <body pos="-0.58363147303616925 0 0.38563111114680865" name="0/1/2/3/4/5/8/9/10/">
                      <joint name="0/1/2/3/4/5/8/9/10/joint/" class="0/1/2/3/4/5/8/9/" type="hinge" axis="0 1 0" limited="true" stiffness="100" range="-51.274538656741441 51.274538656741441" armature="0.20000000000000001" damping="3.5"/>
                      <geom name="0/1/2/3/4/5/8/9/10/geom" class="0/1/2/3/4/5/8/9/10/" type="capsule" contype="1" conaffinity="1" condim="3" size="0.061460303888865447" rgba="0.99887322340667184 0.55964337096332084 0.12046003800590577 1" friction="0.59999999999999998 0.10000000000000001 0.10000000000000001" fromto="0 0 0 -0.37218421768171839 0 -0.52245732009530332"/>
                      <site name="0/1/2/3/4/5/8/9/10/end10" class="0/1/2/3/4/5/8/9/10/" size="0.0050000000000000001" pos="-0.37218421768171839 0 -0.52245732009530332"/>
                    </body>
                  </body>
                </body>
              </body>
            </body>
          </body>
        </body>
      </body>
      <camera name="0/side" class="0/" mode="trackcom" pos="0.40000000000000002 -4 0.20000000000000001" quat="0.70699999999999996 0.70699999999999996 0 0"/>
    </body>
  </worldbody>
  <actuator>
    <motor name="0/1/motor" class="0/1/" ctrllimited="true" ctrlrange="-1 1" gear="70" joint="0/1/joint/"/>
    <motor name="0/1/2/motor" class="0/1/2/" ctrllimited="true" ctrlrange="-1 1" gear="85" joint="0/1/2/joint/"/>
    <motor name="0/1/2/3/motor" class="0/1/2/3/" ctrllimited="true" ctrlrange="-1 1" gear="80" joint="0/1/2/3/joint/"/>
    <motor name="0/1/2/3/4/motor" class="0/1/2/3/4/" ctrllimited="true" ctrlrange="-1 1" gear="57" joint="0/1/2/3/4/joint/"/>
    <motor name="0/1/2/3/4/5/6/motor" class="0/1/2/3/4/5/6/" ctrllimited="true" ctrlrange="-1 1" gear="60" joint="0/1/2/3/4/5/6/joint/"/>
    <motor name="0/1/2/3/4/5/6/7/motor" class="0/1/2/3/4/5/6/7/" ctrllimited="true" ctrlrange="-1 1" gear="68" joint="0/1/2/3/4/5/6/7/joint/"/>
    <motor name="0/1/2/3/4/5/8/motor" class="0/1/2/3/4/5/8/" ctrllimited="true" ctrlrange="-1 1" gear="67" joint="0/1/2/3/4/5/8/joint/"/>
    <motor name="0/1/2/3/4/5/8/9/motor" class="0/1/2/3/4/5/8/9/" ctrllimited="true" ctrlrange="-1 1" gear="74" joint="0/1/2/3/4/5/8/9/joint/"/>
    <motor name="0/1/2/3/4/5/8/9/10/motor" class="0/1/2/3/4/5/8/9/10/" ctrllimited="true" ctrlrange="-1 1" gear="73" joint="0/1/2/3/4/5/8/9/10/joint/"/>
  </actuator>
  <sensor>
    <subtreelinvel name="velocity" body="0/"/>
  </sensor>
</mujoco>
