<mujoco model="morphology">
  <option timestep="0.01"/>
  <default>
    <default class="/"/>
    <default class="0/"/>
    <default class="0/1/"/>
    <default class="0/1/2/"/>
    <default class="0/1/2/3/"/>
    <default class="0/1/4/"/>
    <default class="0/1/4/5/"/>
    <default class="0/1/4/5/6/"/>
    <default class="0/1/4/5/6/7/"/>
    <default class="0/1/4/5/6/7/8/"/>
    <default class="0/1/4/5/6/9/"/>
  </default>
  <asset>
    <texture name="texplane" type="2d" builtin="checker" rgb1="0.10000000000000001 0.20000000000000001 0.29999999999999999" rgb2="0.20000000000000001 0.29999999999999999 0.40000000000000002" width="300" height="300"/>
    <material name="MatPlane" class="/" texture="texplane" texrepeat="20 20" specular="1" shininess="1" reflectance="0.5"/>
  </asset>
  <worldbody>
    <light name="//unnamed_light_0" class="/" directional="true" pos="0 0 1.5" dir="0 0 -1.3" cutoff="100" exponent="1" diffuse="1 1 1" specular="0.10000000000000001 0.10000000000000001 0.10000000000000001"/>
    <geom name="ground" class="/" type="plane" size="15 15 0.5" material="MatPlane" rgba="1 1 1 1"/>
    <site name="body" class="/" size="9.9999999999999995e-07 9.9999999999999995e-07 9.9999999999999995e-07" pos="0 0 1.7474465131759644"/>
    <body pos="0 0 1.7474465131759644" name="0/">
      <joint name="0/rootx/" class="/" type="slide" axis="1 0 0" limited="false" stiffness="0" armature="0" damping="0"/>
      <joint name="0/rootz/" class="/" type="slide" axis="0 0 1" limited="false" stiffness="0" armature="0" damping="0"/>
      <joint name="0/rooty/" class="/" type="hinge" axis="0 1 0" limited="false" stiffness="0" armature="0" damping="0"/>
      <geom name="0/geom" class="0/" type="capsule" contype="1" conaffinity="1" condim="3" size="0.061839534084908609" rgba="0.73139825261312474 0.798127169891931 0.39476276510470254 1" friction="0.59999999999999998 0.10000000000000001 0.10000000000000001" fromto="0 0 0 0.69471194382463164 0 -0.56266369369550495"/>
      <site name="0/end0" class="0/" size="0.0050000000000000001" pos="0.69471194382463164 0 -0.56266369369550495"/>
      <site name="0/attach1" class="0/" size="9.9999999999999995e-07 9.9999999999999995e-07 9.9999999999999995e-07" pos="0.51667185786448444 0 -0.41846480193513874"/>
      <body pos="0.51667185786448444 0 -0.41846480193513874" name="0/1/">
        <joint name="0/1/joint/" class="0/" type="hinge" axis="0 1 0" limited="true" stiffness="100" range="-55.234938718775382 55.234938718775382" armature="0.20000000000000001" damping="3.5"/>
        <geom name="0/1/geom" class="0/1/" type="capsule" contype="1" conaffinity="1" condim="3" size="0.046336185491430884" rgba="0.43827296640894076 0.92850926861572214 0.98486621218788151 1" friction="0.59999999999999998 0.10000000000000001 0.10000000000000001" fromto="0 0 0 -0.31013649486153277 0 -0.24758467522515337"/>
        <site name="0/1/end1" class="0/1/" size="0.0050000000000000001" pos="-0.31013649486153277 0 -0.24758467522515337"/>
        <site name="0/1/attach2" class="0/1/" size="9.9999999999999995e-07 9.9999999999999995e-07 9.9999999999999995e-07" pos="-0.035368743935831844 0 -0.028235177496231736"/>
        <body pos="-0.035368743935831844 0 -0.028235177496231736" name="0/1/2/">
          <geom name="0/1/2/geom" class="0/1/2/" type="capsule" contype="1" conaffinity="1" condim="3" size="0.057227423416788957" rgba="0.43367104583701421 0.17731879272649143 0.11077177347441469 1" friction="0.59999999999999998 0.10000000000000001 0.10000000000000001" fromto="0 0 0 -0.71629513725809124 0 0.37272833507143233"/>
          <site name="0/1/2/end2" class="0/1/2/" size="0.0050000000000000001" pos="-0.71629513725809124 0 0.37272833507143233"/>
          <site name="0/1/2/attach3" class="0/1/2/" size="9.9999999999999995e-07 9.9999999999999995e-07 9.9999999999999995e-07" pos="-0.65087493871567281 0 0.33868655478503024"/>
          <body pos="-0.65087493871567281 0 0.33868655478503024" name="0/1/2/3/">
            <geom name="0/1/2/3/geom" class="0/1/2/3/" type="capsule" contype="1" conaffinity="1" condim="3" size="0.051776295810961735" rgba="0.68584981953524471 0.38379530425875463 0.48664237643018482 1" friction="0.59999999999999998 0.10000000000000001 0.10000000000000001" fromto="0 0 0 -0.48342919475232671 0 -0.16894027619445073"/>
            <site name="0/1/2/3/end3" class="0/1/2/3/" size="0.0050000000000000001" pos="-0.48342919475232671 0 -0.16894027619445073"/>
          </body>
        </body>
        <site name="0/1/attach4" class="0/1/" size="9.9999999999999995e-07 9.9999999999999995e-07 9.9999999999999995e-07" pos="-0.057578891712267939 0 -0.045965732639013927"/>
        <body pos="-0.057578891712267939 0 -0.045965732639013927" name="0/1/4/">
          <joint name="0/1/4/joint/" class="0/1/" type="hinge" axis="0 1 0" limited="true" stiffness="100" range="-58.724331191718342 58.724331191718342" armature="0.20000000000000001" damping="3.5"/>
          <geom name="0/1/4/geom" class="0/1/4/" type="capsule" contype="1" conaffinity="1" condim="3" size="0.054125293149823936" rgba="0.73109791024551041 0.73535869290661748 0.3733742433681958 1" friction="0.59999999999999998 0.10000000000000001 0.10000000000000001" fromto="0 0 0 0.24041492778834539 0 -0.40455792267205465"/>
          <site name="0/1/4/end4" class="0/1/4/" size="0.0050000000000000001" pos="0.24041492778834539 0 -0.40455792267205465"/>
          <site name="0/1/4/attach5" class="0/1/4/" size="9.9999999999999995e-07 9.9999999999999995e-07 9.9999999999999995e-07" pos="0.22664137988014568 0 -0.38138050194853407"/>
          <body pos="0.22664137988014568 0 -0.38138050194853407" name="0/1/4/5/">
            <joint name="0/1/4/5/joint/" class="0/1/4/" type="hinge" axis="0 1 0" limited="true" stiffness="100" range="-46.587517085578014 46.587517085578014" armature="0.20000000000000001" damping="3.5"/>
            <geom name="0/1/4/5/geom" class="0/1/4/5/" type="capsule" contype="1" conaffinity="1" condim="3" size="0.067138253493695538" rgba="0.10138462778695911 0.066439330808378383 0.4880191113837028 1" friction="0.59999999999999998 0.10000000000000001 0.10000000000000001" fromto="0 0 0 0.42494453100078777 0 -0.077083609888430438"/>
            <site name="0/1/4/5/end5" class="0/1/4/5/" size="0.0050000000000000001" pos="0.42494453100078777 0 -0.077083609888430438"/>
            <site name="0/1/4/5/attach6" class="0/1/4/5/" size="9.9999999999999995e-07 9.9999999999999995e-07 9.9999999999999995e-07" pos="0.090232333991633856 0 -0.016367863392318306"/>
            <body pos="0.090232333991633856 0 -0.016367863392318306" name="0/1/4/5/6/">
              <joint name="0/1/4/5/6/joint/" class="0/1/4/5/" type="hinge" axis="0 1 0" limited="true" stiffness="100" range="-54.364251296290171 54.364251296290171" armature="0.20000000000000001" damping="3.5"/>
              <geom name="0/1/4/5/6/geom" class="0/1/4/5/6/" type="capsule" contype="1" conaffinity="1" condim="3" size="0.065614306214389906" rgba="0.67925081968035528 0.58510958471317509 0.71589870107748632 1" friction="0.59999999999999998 0.10000000000000001 0.10000000000000001" fromto="0 0 0 0.044719703010675182 0 -0.3402097344531374"/>
              <site name="0/1/4/5/6/end6" class="0/1/4/5/6/" size="0.0050000000000000001" pos="0.044719703010675182 0 -0.3402097344531374"/>
              <site name="0/1/4/5/6/attach7" class="0/1/4/5/6/" size="9.9999999999999995e-07 9.9999999999999995e-07 9.9999999999999995e-07" pos="0.035332079293089978 0 -0.26879242268469289"/>
              <body pos="0.035332079293089978 0 -0.26879242268469289" name="0/1/4/5/6/7/">
                <geom name="0/1/4/5/6/7/geom" class="0/1/4/5/6/7/" type="capsule" contype="1" conaffinity="1" condim="3" size="0.06389642303586196" rgba="0.63343196369973609 0.61050853082880374 0.35153510297420754 1" friction="0.59999999999999998 0.10000000000000001 0.10000000000000001" fromto="0 0 0 -0.30448644864302171 0 0.0049158702872027504"/>
                <site name="0/1/4/5/6/7/end7" class="0/1/4/5/6/7/" size="0.0050000000000000001" pos="-0.30448644864302171 0 0.0049158702872027504"/>
                <site name="0/1/4/5/6/7/attach8" class="0/1/4/5/6/7/" size="9.9999999999999995e-07 9.9999999999999995e-07 9.9999999999999995e-07" pos="-0.080757322428185563 0 0.0013038101484253626"/>
                <body pos="-0.080757322428185563 0 0.0013038101484253626" name="0/1/4/5/6/7/8/">
                  <joint name="0/1/4/5/6/7/8/joint/" class="0/1/4/5/6/7/" type="hinge" axis="0 1 0" limited="true" stiffness="100" range="-61.926384720071916 61.926384720071916" armature="0.20000000000000001" damping="3.5"/>
                  <geom name="0/1/4/5/6/7/8/geom" class="0/1/4/5/6/7/8/" type="capsule" contype="1" conaffinity="1" condim="3" size="0.040863275946949468" rgba="0.8940066485025906 0.53744537192424191 0.34742897144207674 1" friction="0.59999999999999998 0.10000000000000001 0.10000000000000001" fromto="0 0 0 0.11266182233826405 0 -0.51777905654869205"/>
                  <site name="0/1/4/5/6/7/8/end8" class="0/1/4/5/6/7/8/" size="0.0050000000000000001" pos="0.11266182233826405 0 -0.51777905654869205"/>
                </body>
              </body>
              <site name="0/1/4/5/6/attach9" class="0/1/4/5/6/" size="9.9999999999999995e-07 9.9999999999999995e-07 9.9999999999999995e-07" pos="0.030148764511323565 0 -0.22935982303011057"/>
              <body pos="0.030148764511323565 0 -0.22935982303011057" name="0/1/4/5/6/9/">
                <joint name="0/1/4/5/6/9/joint/" class="0/1/4/5/6/" type="hinge" axis="0 1 0" limited="true" stiffness="100" range="-50.240922744832616 50.240922744832616" armature="0.20000000000000001" damping="3.5"/>
                <geom name="0/1/4/5/6/9/geom" class="0/1/4/5/6/9/" type="capsule" contype="1" conaffinity="1" condim="3" size="0.064715136005006169" rgba="0.20993897719865384 0.10528684592917315 0.27661600918603779 1" friction="0.59999999999999998 0.10000000000000001 0.10000000000000001" fromto="0 0 0 0.4574741886421867 0 -0.29577352571170729"/>
                <site name="0/1/4/5/6/9/end9" class="0/1/4/5/6/9/" size="0.0050000000000000001" pos="0.4574741886421867 0 -0.29577352571170729"/>
              </body>
            </body>
          </body>
        </body>
      </body>
      <camera name="0/side" class="0/" mode="trackcom" pos="0.40000000000000002 -4 0.20000000000000001" quat="0.70699999999999996 0.70699999999999996 0 0"/>
    </body>
  </worldbody>
  <actuator>
    <motor name="0/1/motor" class="0/1/" ctrllimited="true" ctrlrange="-1 1" gear="60" joint="0/1/joint/"/>
    <motor name="0/1/4/motor" class="0/1/4/" ctrllimited="true" ctrlrange="-1 1" gear="81" joint="0/1/4/joint/"/>
    <motor name="0/1/4/5/motor" class="0/1/4/5/" ctrllimited="true" ctrlrange="-1 1" gear="73" joint="0/1/4/5/joint/"/>
    <motor name="0/1/4/5/6/motor" class="0/1/4/5/6/" ctrllimited="true" ctrlrange="-1 1" gear="57" joint="0/1/4/5/6/joint/"/>
    <motor name="0/1/4/5/6/7/8/motor" class="0/1/4/5/6/7/8/" ctrllimited="true" ctrlrange="-1 1" gear="63" joint="0/1/4/5/6/7/8/joint/"/>
    <motor name="0/1/4/5/6/9/motor" class="0/1/4/5/6/9/" ctrllimited="true" ctrlrange="-1 1" gear="75" joint="0/1/4/5/6/9/joint/"/>
  </actuator>
  <sensor>
    <subtreelinvel name="velocity" body="0/"/>
  </sensor>
</mujoco>
