<mujoco model="morphology">
  <option timestep="0.01"/>
  <default>
    <default class="/"/>
    <default class="0/"/>
    <default class="0/1/"/>
    <default class="0/1/2/"/>
    <default class="0/1/2/3/"/>
    <default class="0/1/2/3/4/"/>
    <default class="0/1/2/3/4/5/"/>
    <default class="0/1/2/3/4/5/6/"/>
    <default class="0/1/2/3/4/5/7/"/>
    <default class="0/1/2/3/4/5/7/8/"/>
    <default class="0/1/2/3/4/5/7/8/9/"/>
    <default class="0/1/2/3/4/5/7/8/10/"/>
  </default>
  <asset>
    <texture name="texplane" type="2d" builtin="checker" rgb1="0.10000000000000001 0.20000000000000001 0.29999999999999999" rgb2="0.20000000000000001 0.29999999999999999 0.40000000000000002" width="300" height="300"/>
    <material name="MatPlane" class="/" texture="texplane" texrepeat="20 20" specular="1" shininess="1" reflectance="0.5"/>
  </asset>
  <worldbody>
    <light name="//unnamed_light_0" class="/" directional="true" pos="0 0 1.5" dir="0 0 -1.3" cutoff="100" exponent="1" diffuse="1 1 1" specular="0.10000000000000001 0.10000000000000001 0.10000000000000001"/>
    <geom name="ground" class="/" type="plane" size="15 15 0.5" material="MatPlane" rgba="1 1 1 1"/>
    <site name="body" class="/" size="9.9999999999999995e-07 9.9999999999999995e-07 9.9999999999999995e-07" pos="0 0 1.2786205768585206"/>
    <body pos="0 0 1.2786205768585206" name="0/">
      <joint name="0/rootx/" class="/" type="slide" axis="1 0 0" limited="false" stiffness="0" armature="0" damping="0"/>
      <joint name="0/rootz/" class="/" type="slide" axis="0 0 1" limited="false" stiffness="0" armature="0" damping="0"/>
      <joint name="0/rooty/" class="/" type="hinge" axis="0 1 0" limited="false" stiffness="0" armature="0" damping="0"/>
      <geom name="0/geom" class="0/" type="capsule" contype="1" conaffinity="1" condim="3" size="0.069450539290684718" rgba="0.68798055275939418 0.26605674078041652 0.66483766271916322 1" friction="0.59999999999999998 0.10000000000000001 0.10000000000000001" fromto="0 0 0 -0.064340028058066379 0 0.10680575620821675"/>
      <site name="0/end0" class="0/" size="0.0050000000000000001" pos="-0.064340028058066379 0 0.10680575620821675"/>
      <site name="0/attach1" class="0/" size="9.9999999999999995e-07 9.9999999999999995e-07 9.9999999999999995e-07" pos="-0.032985998923209491 0 0.054757429637693769"/>
      <body pos="-0.032985998923209491 0 0.054757429637693769" name="0/1/">
        <joint name="0/1/joint/" class="0/" type="hinge" axis="0 1 0" limited="true" stiffness="100" range="-38.324273931565287 38.324273931565287" armature="0.20000000000000001" damping="3.5"/>
        <geom name="0/1/geom" class="0/1/" type="capsule" contype="1" conaffinity="1" condim="3" size="0.054808205448909589" rgba="0.019542853374241775 0.62818995380560783 0.93611642316225385 1" friction="0.59999999999999998 0.10000000000000001 0.10000000000000001" fromto="0 0 0 -0.3353020869925708 0 -0.26467629514075397"/>
        <site name="0/1/end1" class="0/1/" size="0.0050000000000000001" pos="-0.3353020869925708 0 -0.26467629514075397"/>
        <site name="0/1/attach2" class="0/1/" size="9.9999999999999995e-07 9.9999999999999995e-07 9.9999999999999995e-07" pos="-0.1200019636871575 0 -0.094725551645719025"/>
        <body pos="-0.1200019636871575 0 -0.094725551645719025" name="0/1/2/">
          <joint name="0/1/2/joint/" class="0/1/" type="hinge" axis="0 1 0" limited="true" stiffness="100" range="-30.517431671712586 30.517431671712586" armature="0.20000000000000001" damping="3.5"/>
          <geom name="0/1/2/geom" class="0/1/2/" type="capsule" contype="1" conaffinity="1" condim="3" size="0.06836842341376892" rgba="0.12309536824764589 0.97688498098303789 0.56619991088719213 1" friction="0.59999999999999998 0.10000000000000001 0.10000000000000001" fromto="0 0 0 0.12155919690424843 0 -0.43196805200121507"/>
          <site name="0/1/2/end2" class="0/1/2/" size="0.0050000000000000001" pos="0.12155919690424843 0 -0.43196805200121507"/>
          <site name="0/1/2/attach3" class="0/1/2/" size="9.9999999999999995e-07 9.9999999999999995e-07 9.9999999999999995e-07" pos="0.047075362305465406 0 -0.16728518343503979"/>
          <body pos="0.047075362305465406 0 -0.16728518343503979" name="0/1/2/3/">
            <joint name="0/1/2/3/joint/" class="0/1/2/" type="hinge" axis="0 1 0" limited="true" stiffness="100" range="-43.041093536885796 43.041093536885796" armature="0.20000000000000001" damping="3.5"/>
            <geom name="0/1/2/3/geom" class="0/1/2/3/" type="capsule" contype="1" conaffinity="1" condim="3" size="0.065851777023069755" rgba="0.95068099653371874 0.47394575162756236 0.75906847294828372 1" friction="0.59999999999999998 0.10000000000000001 0.10000000000000001" fromto="0 0 0 -0.46350876465105117 0 -0.36624597981973128"/>
            <site name="0/1/2/3/end3" class="0/1/2/3/" size="0.0050000000000000001" pos="-0.46350876465105117 0 -0.36624597981973128"/>
            <site name="0/1/2/3/attach4" class="0/1/2/3/" size="9.9999999999999995e-07 9.9999999999999995e-07 9.9999999999999995e-07" pos="-0.37683901204391196 0 -0.29776302785606679"/>
            <body pos="-0.37683901204391196 0 -0.29776302785606679" name="0/1/2/3/4/">
              <joint name="0/1/2/3/4/joint/" class="0/1/2/3/" type="hinge" axis="0 1 0" limited="true" stiffness="100" range="-46.415866464262805 46.415866464262805" armature="0.20000000000000001" damping="3.5"/>
              <geom name="0/1/2/3/4/geom" class="0/1/2/3/4/" type="capsule" contype="1" conaffinity="1" condim="3" size="0.050979606679438023" rgba="0.0062470322952140611 0.32032179589433885 0.14217345632249778 1" friction="0.59999999999999998 0.10000000000000001 0.10000000000000001" fromto="0 0 0 0.47754818067877824 0 -0.60032339601606854"/>
              <site name="0/1/2/3/4/end4" class="0/1/2/3/4/" size="0.0050000000000000001" pos="0.47754818067877824 0 -0.60032339601606854"/>
              <site name="0/1/2/3/4/attach5" class="0/1/2/3/4/" size="9.9999999999999995e-07 9.9999999999999995e-07 9.9999999999999995e-07" pos="0.27969423554461442 0 -0.35160220501646805"/>
              <body pos="0.27969423554461442 0 -0.35160220501646805" name="0/1/2/3/4/5/">
                <joint name="0/1/2/3/4/5/joint/" class="0/1/2/3/4/" type="hinge" axis="0 1 0" limited="true" stiffness="100" range="-60.71610169305977 60.71610169305977" armature="0.20000000000000001" damping="3.5"/>
                <geom name="0/1/2/3/4/5/geom" class="0/1/2/3/4/5/" type="capsule" contype="1" conaffinity="1" condim="3" size="0.044901519015918226" rgba="0.079785493018118991 0.51619466321622187 0.799645743916376 1" friction="0.59999999999999998 0.10000000000000001 0.10000000000000001" fromto="0 0 0 0.69012216073462485 0 0.71036327238514896"/>
                <site name="0/1/2/3/4/5/end5" class="0/1/2/3/4/5/" size="0.0050000000000000001" pos="0.69012216073462485 0 0.71036327238514896"/>
                <site name="0/1/2/3/4/5/attach6" class="0/1/2/3/4/5/" size="9.9999999999999995e-07 9.9999999999999995e-07 9.9999999999999995e-07" pos="0.35974934146864784 0 0.37030070034563001"/>
                <body pos="0.35974934146864784 0 0.37030070034563001" name="0/1/2/3/4/5/6/">
                  <geom name="0/1/2/3/4/5/6/geom" class="0/1/2/3/4/5/6/" type="capsule" contype="1" conaffinity="1" condim="3" size="0.043639021498791494" rgba="0.61109824885587527 0.90227701209333599 0.21463432928242243 1" friction="0.59999999999999998 0.10000000000000001 0.10000000000000001" fromto="0 0 0 0.23758286630661041 0 -0.69230277074075763"/>
                  <site name="0/1/2/3/4/5/6/end6" class="0/1/2/3/4/5/6/" size="0.0050000000000000001" pos="0.23758286630661041 0 -0.69230277074075763"/>
                </body>
                <site name="0/1/2/3/4/5/attach7" class="0/1/2/3/4/5/" size="9.9999999999999995e-07 9.9999999999999995e-07 9.9999999999999995e-07" pos="0.6686940626282889 0 0.68830669348091045"/>
                <body pos="0.6686940626282889 0 0.68830669348091045" name="0/1/2/3/4/5/7/">
                  <joint name="0/1/2/3/4/5/7/joint/" class="0/1/2/3/4/5/" type="hinge" axis="0 1 0" limited="true" stiffness="100" range="-52.689273010783261 52.689273010783261" armature="0.20000000000000001" damping="3.5"/>
                  <geom name="0/1/2/3/4/5/7/geom" class="0/1/2/3/4/5/7/" type="capsule" contype="1" conaffinity="1" condim="3" size="0.063683094020398054" rgba="0.97427319434806514 0.13166878093893852 0.84145044681507009 1" friction="0.59999999999999998 0.10000000000000001 0.10000000000000001" fromto="0 0 0 -0.41335585120276341 0 0.55584450515173711"/>
                  <site name="0/1/2/3/4/5/7/end7" class="0/1/2/3/4/5/7/" size="0.0050000000000000001" pos="-0.41335585120276341 0 0.55584450515173711"/>
                  <site name="0/1/2/3/4/5/7/attach8" class="0/1/2/3/4/5/7/" size="9.9999999999999995e-07 9.9999999999999995e-07 9.9999999999999995e-07" pos="-0.31684120318091513 0 0.42606011571223013"/>
                  <body pos="-0.31684120318091513 0 0.42606011571223013" name="0/1/2/3/4/5/7/8/">
                    <geom name="0/1/2/3/4/5/7/8/geom" class="0/1/2/3/4/5/7/8/" type="capsule" contype="1" conaffinity="1" condim="3" size="0.051066972551816636" rgba="0.67599956829708507 0.98747259288667832 0.84380291121139783 1" friction="0.59999999999999998 0.10000000000000001 0.10000000000000001" fromto="0 0 0 0.31112000931722505 0 0.34604840265371317"/>
                    <site name="0/1/2/3/4/5/7/8/end8" class="0/1/2/3/4/5/7/8/" size="0.0050000000000000001" pos="0.31112000931722505 0 0.34604840265371317"/>
                    <site name="0/1/2/3/4/5/7/8/attach9" class="0/1/2/3/4/5/7/8/" size="9.9999999999999995e-07 9.9999999999999995e-07 9.9999999999999995e-07" pos="0.22939108248134357 0 0.25514404505798605"/>
                    <body pos="0.22939108248134357 0 0.25514404505798605" name="0/1/2/3/4/5/7/8/9/">
                      <joint name="0/1/2/3/4/5/7/8/9/joint/" class="0/1/2/3/4/5/7/8/" type="hinge" axis="0 1 0" limited="true" stiffness="100" range="-61.602938770843643 61.602938770843643" armature="0.20000000000000001" damping="3.5"/>
                      <geom name="0/1/2/3/4/5/7/8/9/geom" class="0/1/2/3/4/5/7/8/9/" type="capsule" contype="1" conaffinity="1" condim="3" size="0.04565829599560102" rgba="0.68612868671478799 0.67418816920506153 0.64607990741189802 1" friction="0.59999999999999998 0.10000000000000001 0.10000000000000001" fromto="0 0 0 -0.51867519688572838 0 0.65642113888813447"/>
                      <site name="0/1/2/3/4/5/7/8/9/end9" class="0/1/2/3/4/5/7/8/9/" size="0.0050000000000000001" pos="-0.51867519688572838 0 0.65642113888813447"/>
                    </body>
                    <site name="0/1/2/3/4/5/7/8/attach10" class="0/1/2/3/4/5/7/8/" size="9.9999999999999995e-07 9.9999999999999995e-07 9.9999999999999995e-07" pos="0.28829273631282887 0 0.32065838875699471"/>
                    <body pos="0.28829273631282887 0 0.32065838875699471" name="0/1/2/3/4/5/7/8/10/">
                      <joint name="0/1/2/3/4/5/7/8/10/joint/" class="0/1/2/3/4/5/7/8/" type="hinge" axis="0 1 0" limited="true" stiffness="100" range="-64.614330765314179 64.614330765314179" armature="0.20000000000000001" damping="3.5"/>
                      <geom name="0/1/2/3/4/5/7/8/10/geom" class="0/1/2/3/4/5/7/8/10/" type="capsule" contype="1" conaffinity="1" condim="3" size="0.061688457271349459" rgba="0.70164398072179901 0.38942510324855639 0.25291909060344764 1" friction="0.59999999999999998 0.10000000000000001 0.10000000000000001" fromto="0 0 0 0.61146234376721842 0 -0.24256179570023717"/>
                      <site name="0/1/2/3/4/5/7/8/10/end10" class="0/1/2/3/4/5/7/8/10/" size="0.0050000000000000001" pos="0.61146234376721842 0 -0.24256179570023717"/>
                    </body>
                  </body>
                </body>
              </body>
            </body>
          </body>
        </body>
      </body>
      <camera name="0/side" class="0/" mode="trackcom" pos="0.40000000000000002 -4 0.20000000000000001" quat="0.70699999999999996 0.70699999999999996 0 0"/>
    </body>
  </worldbody>
  <actuator>
    <motor name="0/1/motor" class="0/1/" ctrllimited="true" ctrlrange="-1 1" gear="85" joint="0/1/joint/"/>
    <motor name="0/1/2/motor" class="0/1/2/" ctrllimited="true" ctrlrange="-1 1" gear="89" joint="0/1/2/joint/"/>
    <motor name="0/1/2/3/motor" class="0/1/2/3/" ctrllimited="true" ctrlrange="-1 1" gear="61" joint="0/1/2/3/joint/"/>
    <motor name="0/1/2/3/4/motor" class="0/1/2/3/4/" ctrllimited="true" ctrlrange="-1 1" gear="59" joint="0/1/2/3/4/joint/"/>
    <motor name="0/1/2/3/4/5/motor" class="0/1/2/3/4/5/" ctrllimited="true" ctrlrange="-1 1" gear="50" joint="0/1/2/3/4/5/joint/"/>
    <motor name="0/1/2/3/4/5/7/motor" class="0/1/2/3/4/5/7/" ctrllimited="true" ctrlrange="-1 1" gear="66" joint="0/1/2/3/4/5/7/joint/"/>
    <motor name="0/1/2/3/4/5/7/8/9/motor" class="0/1/2/3/4/5/7/8/9/" ctrllimited="true" ctrlrange="-1 1" gear="65" joint="0/1/2/3/4/5/7/8/9/joint/"/>
    <motor name="0/1/2/3/4/5/7/8/10/motor" class="0/1/2/3/4/5/7/8/10/" ctrllimited="true" ctrlrange="-1 1" gear="69" joint="0/1/2/3/4/5/7/8/10/joint/"/>
  </actuator>
  <sensor>
    <subtreelinvel name="velocity" body="0/"/>
  </sensor>
</mujoco>
