<mujoco model="morphology">
  <option timestep="0.01"/>
  <default>
    <default class="/"/>
    <default class="0/"/>
    <default class="0/1/"/>
    <default class="0/1/2/"/>
    <default class="0/1/2/3/"/>
    <default class="0/1/2/4/"/>
    <default class="0/1/2/4/5/"/>
    <default class="0/1/2/4/5/6/"/>
    <default class="0/1/2/4/5/6/7/"/>
    <default class="0/1/2/4/5/8/"/>
    <default class="0/1/2/4/5/8/9/"/>
    <default class="0/1/2/4/10/"/>
  </default>
  <asset>
    <texture name="texplane" type="2d" builtin="checker" rgb1="0.10000000000000001 0.20000000000000001 0.29999999999999999" rgb2="0.20000000000000001 0.29999999999999999 0.40000000000000002" width="300" height="300"/>
    <material name="MatPlane" class="/" texture="texplane" texrepeat="20 20" specular="1" shininess="1" reflectance="0.5"/>
  </asset>
  <worldbody>
    <light name="//unnamed_light_0" class="/" directional="true" pos="0 0 1.5" dir="0 0 -1.3" cutoff="100" exponent="1" diffuse="1 1 1" specular="0.10000000000000001 0.10000000000000001 0.10000000000000001"/>
    <geom name="ground" class="/" type="plane" size="15 15 0.5" material="MatPlane" rgba="1 1 1 1"/>
    <site name="body" class="/" size="9.9999999999999995e-07 9.9999999999999995e-07 9.9999999999999995e-07" pos="0 0 1.3794942855834962"/>
    <body pos="0 0 1.3794942855834962" name="0/">
      <joint name="0/rootx/" class="/" type="slide" axis="1 0 0" limited="false" stiffness="0" armature="0" damping="0"/>
      <joint name="0/rootz/" class="/" type="slide" axis="0 0 1" limited="false" stiffness="0" armature="0" damping="0"/>
      <joint name="0/rooty/" class="/" type="hinge" axis="0 1 0" limited="false" stiffness="0" armature="0" damping="0"/>
      <geom name="0/geom" class="0/" type="capsule" contype="1" conaffinity="1" condim="3" size="0.065763998831318615" rgba="0.91482400612257286 0.64207576289172852 0.16166873833359774 1" friction="0.59999999999999998 0.10000000000000001 0.10000000000000001" fromto="0 0 0 -0.16676456651866289 0 -0.37503972436202782"/>
      <site name="0/end0" class="0/" size="0.0050000000000000001" pos="-0.16676456651866289 0 -0.37503972436202782"/>
      <site name="0/attach1" class="0/" size="9.9999999999999995e-07 9.9999999999999995e-07 9.9999999999999995e-07" pos="-0.087394209859836008 0 -0.19654235345613458"/>
      <body pos="-0.087394209859836008 0 -0.19654235345613458" name="0/1/">
        <joint name="0/1/joint/" class="0/" type="hinge" axis="0 1 0" limited="true" stiffness="100" range="-56.97718030510292 56.97718030510292" armature="0.20000000000000001" damping="3.5"/>
        <geom name="0/1/geom" class="0/1/" type="capsule" contype="1" conaffinity="1" condim="3" size="0.052582855046555646" rgba="0.60986165854179231 0.31878796171599366 0.80848589077390032 1" friction="0.59999999999999998 0.10000000000000001 0.10000000000000001" fromto="0 0 0 -0.037120200165486561 0 0.066059133243237755"/>
        <site name="0/1/end1" class="0/1/" size="0.0050000000000000001" pos="-0.037120200165486561 0 0.066059133243237755"/>
        <site name="0/1/attach2" class="0/1/" size="9.9999999999999995e-07 9.9999999999999995e-07 9.9999999999999995e-07" pos="-0.023334617513844441 0 0.041526301061281849"/>
        <body pos="-0.023334617513844441 0 0.041526301061281849" name="0/1/2/">
          <joint name="0/1/2/joint/" class="0/1/" type="hinge" axis="0 1 0" limited="true" stiffness="100" range="-51.196677723659917 51.196677723659917" armature="0.20000000000000001" damping="3.5"/>
          <geom name="0/1/2/geom" class="0/1/2/" type="capsule" contype="1" conaffinity="1" condim="3" size="0.056841854738989631" rgba="0.26944980186701073 0.5090614876353422 0.14184428808194904 1" friction="0.59999999999999998 0.10000000000000001 0.10000000000000001" fromto="0 0 0 -0.69136679162082881 0 -0.29242820127344876"/>
          <site name="0/1/2/end2" class="0/1/2/" size="0.0050000000000000001" pos="-0.69136679162082881 0 -0.29242820127344876"/>
          <site name="0/1/2/attach3" class="0/1/2/" size="9.9999999999999995e-07 9.9999999999999995e-07 9.9999999999999995e-07" pos="-0.26446641000198123 0 -0.11186165941354688"/>
          <body pos="-0.26446641000198123 0 -0.11186165941354688" name="0/1/2/3/">
            <joint name="0/1/2/3/joint/" class="0/1/2/" type="hinge" axis="0 1 0" limited="true" stiffness="100" range="-37.413364778608226 37.413364778608226" armature="0.20000000000000001" damping="3.5"/>
            <geom name="0/1/2/3/geom" class="0/1/2/3/" type="capsule" contype="1" conaffinity="1" condim="3" size="0.064566737697223181" rgba="0.62969508483776215 0.64768410691944933 0.99166253408825911 1" friction="0.59999999999999998 0.10000000000000001 0.10000000000000001" fromto="0 0 0 0.19182007714641869 0 -0.67142726589390933"/>
            <site name="0/1/2/3/end3" class="0/1/2/3/" size="0.0050000000000000001" pos="0.19182007714641869 0 -0.67142726589390933"/>
          </body>
          <site name="0/1/2/attach4" class="0/1/2/" size="9.9999999999999995e-07 9.9999999999999995e-07 9.9999999999999995e-07" pos="-0.52827116547638187 0 -0.22344345805606772"/>
          <body pos="-0.52827116547638187 0 -0.22344345805606772" name="0/1/2/4/">
            <joint name="0/1/2/4/joint/" class="0/1/2/" type="hinge" axis="0 1 0" limited="true" stiffness="100" range="-53.800114556951556 53.800114556951556" armature="0.20000000000000001" damping="3.5"/>
            <geom name="0/1/2/4/geom" class="0/1/2/4/" type="capsule" contype="1" conaffinity="1" condim="3" size="0.040894237663804289" rgba="0.57372035612536831 0.72266424770958626 0.54883786799868872 1" friction="0.59999999999999998 0.10000000000000001 0.10000000000000001" fromto="0 0 0 0.26493448754883264 0 -0.1547024578287346"/>
            <site name="0/1/2/4/end4" class="0/1/2/4/" size="0.0050000000000000001" pos="0.26493448754883264 0 -0.1547024578287346"/>
            <site name="0/1/2/4/attach5" class="0/1/2/4/" size="9.9999999999999995e-07 9.9999999999999995e-07 9.9999999999999995e-07" pos="0.1950579646905776 0 -0.11389965434809941"/>
            <body pos="0.1950579646905776 0 -0.11389965434809941" name="0/1/2/4/5/">
              <joint name="0/1/2/4/5/joint/" class="0/1/2/4/" type="hinge" axis="0 1 0" limited="true" stiffness="100" range="-30.591784481045305 30.591784481045305" armature="0.20000000000000001" damping="3.5"/>
              <geom name="0/1/2/4/5/geom" class="0/1/2/4/5/" type="capsule" contype="1" conaffinity="1" condim="3" size="0.063817094938012811" rgba="0.020598583169317397 0.80454955152328655 0.32566222913576215 1" friction="0.59999999999999998 0.10000000000000001 0.10000000000000001" fromto="0 0 0 -0.2969462162110153 0 -0.28945311691938685"/>
              <site name="0/1/2/4/5/end5" class="0/1/2/4/5/" size="0.0050000000000000001" pos="-0.2969462162110153 0 -0.28945311691938685"/>
              <site name="0/1/2/4/5/attach6" class="0/1/2/4/5/" size="9.9999999999999995e-07 9.9999999999999995e-07 9.9999999999999995e-07" pos="-0.24211758602437844 0 -0.23600802471903806"/>
              <body pos="-0.24211758602437844 0 -0.23600802471903806" name="0/1/2/4/5/6/">
                <joint name="0/1/2/4/5/6/joint/" class="0/1/2/4/5/" type="hinge" axis="0 1 0" limited="true" stiffness="100" range="-48.348109516753702 48.348109516753702" armature="0.20000000000000001" damping="3.5"/>
                <geom name="0/1/2/4/5/6/geom" class="0/1/2/4/5/6/" type="capsule" contype="1" conaffinity="1" condim="3" size="0.054911759405491381" rgba="0.11015351755065184 0.93485690346713457 0.71317421579949669 1" friction="0.59999999999999998 0.10000000000000001 0.10000000000000001" fromto="0 0 0 -0.1508204727504654 0 0.1823415401247781"/>
                <site name="0/1/2/4/5/6/end6" class="0/1/2/4/5/6/" size="0.0050000000000000001" pos="-0.1508204727504654 0 0.1823415401247781"/>
                <site name="0/1/2/4/5/6/attach7" class="0/1/2/4/5/6/" size="9.9999999999999995e-07 9.9999999999999995e-07 9.9999999999999995e-07" pos="-0.1232717743734157 0 0.14903523893836496"/>
                <body pos="-0.1232717743734157 0 0.14903523893836496" name="0/1/2/4/5/6/7/">
                  <geom name="0/1/2/4/5/6/7/geom" class="0/1/2/4/5/6/7/" type="capsule" contype="1" conaffinity="1" condim="3" size="0.059683980856496364" rgba="0.51758446460500829 0.34360699984589893 0.66592570892009861 1" friction="0.59999999999999998 0.10000000000000001 0.10000000000000001" fromto="0 0 0 -0.17021735863012744 0 -0.42750771510545355"/>
                  <site name="0/1/2/4/5/6/7/end7" class="0/1/2/4/5/6/7/" size="0.0050000000000000001" pos="-0.17021735863012744 0 -0.42750771510545355"/>
                </body>
              </body>
              <site name="0/1/2/4/5/attach8" class="0/1/2/4/5/" size="9.9999999999999995e-07 9.9999999999999995e-07 9.9999999999999995e-07" pos="-0.24171397063413957 0 -0.23561459410311045"/>
              <body pos="-0.24171397063413957 0 -0.23561459410311045" name="0/1/2/4/5/8/">
                <joint name="0/1/2/4/5/8/joint/" class="0/1/2/4/5/" type="hinge" axis="0 1 0" limited="true" stiffness="100" range="-34.930750969522634 34.930750969522634" armature="0.20000000000000001" damping="3.5"/>
                <geom name="0/1/2/4/5/8/geom" class="0/1/2/4/5/8/" type="capsule" contype="1" conaffinity="1" condim="3" size="0.061234537678875697" rgba="0.41100108352971265 0.12806159440543585 0.56358019718709884 1" friction="0.59999999999999998 0.10000000000000001 0.10000000000000001" fromto="0 0 0 0.12250181576403674 0 -0.52544827217391976"/>
                <site name="0/1/2/4/5/8/end8" class="0/1/2/4/5/8/" size="0.0050000000000000001" pos="0.12250181576403674 0 -0.52544827217391976"/>
                <site name="0/1/2/4/5/8/attach9" class="0/1/2/4/5/8/" size="9.9999999999999995e-07 9.9999999999999995e-07 9.9999999999999995e-07" pos="0.080734177943534824 0 -0.34629392259397035"/>
                <body pos="0.080734177943534824 0 -0.34629392259397035" name="0/1/2/4/5/8/9/">
                  <joint name="0/1/2/4/5/8/9/joint/" class="0/1/2/4/5/8/" type="hinge" axis="0 1 0" limited="true" stiffness="100" range="-45.825488059387141 45.825488059387141" armature="0.20000000000000001" damping="3.5"/>
                  <geom name="0/1/2/4/5/8/9/geom" class="0/1/2/4/5/8/9/" type="capsule" contype="1" conaffinity="1" condim="3" size="0.050221820633595836" rgba="0.53256147165994294 0.54037242788655704 0.44029625714512888 1" friction="0.59999999999999998 0.10000000000000001 0.10000000000000001" fromto="0 0 0 0.4989849908657793 0 -0.20522656756197155"/>
                  <site name="0/1/2/4/5/8/9/end9" class="0/1/2/4/5/8/9/" size="0.0050000000000000001" pos="0.4989849908657793 0 -0.20522656756197155"/>
                </body>
              </body>
            </body>
            <site name="0/1/2/4/attach10" class="0/1/2/4/" size="9.9999999999999995e-07 9.9999999999999995e-07 9.9999999999999995e-07" pos="0.011382873045189543 0 -0.0066467693713099379"/>
            <body pos="0.011382873045189543 0 -0.0066467693713099379" name="0/1/2/4/10/">
              <joint name="0/1/2/4/10/joint/" class="0/1/2/4/" type="hinge" axis="0 1 0" limited="true" stiffness="100" range="-35.077557810118229 35.077557810118229" armature="0.20000000000000001" damping="3.5"/>
              <geom name="0/1/2/4/10/geom" class="0/1/2/4/10/" type="capsule" contype="1" conaffinity="1" condim="3" size="0.05829546364380038" rgba="0.61085430291343679 0.33494090624077488 0.71528612557123405 1" friction="0.59999999999999998 0.10000000000000001 0.10000000000000001" fromto="0 0 0 -0.62621056615258486 0 0.69576449961618669"/>
              <site name="0/1/2/4/10/end10" class="0/1/2/4/10/" size="0.0050000000000000001" pos="-0.62621056615258486 0 0.69576449961618669"/>
            </body>
          </body>
        </body>
      </body>
      <camera name="0/side" class="0/" mode="trackcom" pos="0.40000000000000002 -4 0.20000000000000001" quat="0.70699999999999996 0.70699999999999996 0 0"/>
    </body>
  </worldbody>
  <actuator>
    <motor name="0/1/motor" class="0/1/" ctrllimited="true" ctrlrange="-1 1" gear="54" joint="0/1/joint/"/>
    <motor name="0/1/2/motor" class="0/1/2/" ctrllimited="true" ctrlrange="-1 1" gear="89" joint="0/1/2/joint/"/>
    <motor name="0/1/2/3/motor" class="0/1/2/3/" ctrllimited="true" ctrlrange="-1 1" gear="82" joint="0/1/2/3/joint/"/>
    <motor name="0/1/2/4/motor" class="0/1/2/4/" ctrllimited="true" ctrlrange="-1 1" gear="54" joint="0/1/2/4/joint/"/>
    <motor name="0/1/2/4/5/motor" class="0/1/2/4/5/" ctrllimited="true" ctrlrange="-1 1" gear="88" joint="0/1/2/4/5/joint/"/>
    <motor name="0/1/2/4/5/6/motor" class="0/1/2/4/5/6/" ctrllimited="true" ctrlrange="-1 1" gear="68" joint="0/1/2/4/5/6/joint/"/>
    <motor name="0/1/2/4/5/8/motor" class="0/1/2/4/5/8/" ctrllimited="true" ctrlrange="-1 1" gear="57" joint="0/1/2/4/5/8/joint/"/>
    <motor name="0/1/2/4/5/8/9/motor" class="0/1/2/4/5/8/9/" ctrllimited="true" ctrlrange="-1 1" gear="72" joint="0/1/2/4/5/8/9/joint/"/>
    <motor name="0/1/2/4/10/motor" class="0/1/2/4/10/" ctrllimited="true" ctrlrange="-1 1" gear="82" joint="0/1/2/4/10/joint/"/>
  </actuator>
  <sensor>
    <subtreelinvel name="velocity" body="0/"/>
  </sensor>
</mujoco>
