<mujoco model="morphology">
  <option timestep="0.01"/>
  <default>
    <default class="/"/>
    <default class="0/"/>
    <default class="0/1/"/>
    <default class="0/2/"/>
    <default class="0/2/3/"/>
    <default class="0/2/3/4/"/>
    <default class="0/2/3/5/"/>
    <default class="0/2/3/5/6/"/>
    <default class="0/2/3/5/6/7/"/>
    <default class="0/2/8/"/>
    <default class="0/2/9/"/>
    <default class="0/2/9/10/"/>
  </default>
  <asset>
    <texture name="texplane" type="2d" builtin="checker" rgb1="0.10000000000000001 0.20000000000000001 0.29999999999999999" rgb2="0.20000000000000001 0.29999999999999999 0.40000000000000002" width="300" height="300"/>
    <material name="MatPlane" class="/" texture="texplane" texrepeat="20 20" specular="1" shininess="1" reflectance="0.5"/>
  </asset>
  <worldbody>
    <light name="//unnamed_light_0" class="/" directional="true" pos="0 0 1.5" dir="0 0 -1.3" cutoff="100" exponent="1" diffuse="1 1 1" specular="0.10000000000000001 0.10000000000000001 0.10000000000000001"/>
    <geom name="ground" class="/" type="plane" size="15 15 0.5" material="MatPlane" rgba="1 1 1 1"/>
    <site name="body" class="/" size="9.9999999999999995e-07 9.9999999999999995e-07 9.9999999999999995e-07" pos="0 0 0.80670527219772337"/>
    <body pos="0 0 0.80670527219772337" name="0/">
      <joint name="0/rootx/" class="/" type="slide" axis="1 0 0" limited="false" stiffness="0" armature="0" damping="0"/>
      <joint name="0/rootz/" class="/" type="slide" axis="0 0 1" limited="false" stiffness="0" armature="0" damping="0"/>
      <joint name="0/rooty/" class="/" type="hinge" axis="0 1 0" limited="false" stiffness="0" armature="0" damping="0"/>
      <geom name="0/geom" class="0/" type="capsule" contype="1" conaffinity="1" condim="3" size="0.051059157186214385" rgba="0.91006877623466564 0.75459937585810943 0.85668962362040246 1" friction="0.59999999999999998 0.10000000000000001 0.10000000000000001" fromto="0 0 0 0.10850914260324207 0 0.37177350365792972"/>
      <site name="0/end0" class="0/" size="0.0050000000000000001" pos="0.10850914260324207 0 0.37177350365792972"/>
      <site name="0/attach1" class="0/" size="9.9999999999999995e-07 9.9999999999999995e-07 9.9999999999999995e-07" pos="0.1033521343525365 0 0.35410458673755607"/>
      <body pos="0.1033521343525365 0 0.35410458673755607" name="0/1/">
        <geom name="0/1/geom" class="0/1/" type="capsule" contype="1" conaffinity="1" condim="3" size="0.052558314848162618" rgba="0.5019783202462037 0.13946834852514778 0.97946140792163505 1" friction="0.59999999999999998 0.10000000000000001 0.10000000000000001" fromto="0 0 0 0.72336851600292951 0 0.30708708282722741"/>
        <site name="0/1/end1" class="0/1/" size="0.0050000000000000001" pos="0.72336851600292951 0 0.30708708282722741"/>
      </body>
      <site name="0/attach2" class="0/" size="9.9999999999999995e-07 9.9999999999999995e-07 9.9999999999999995e-07" pos="0.099570412501628208 0 0.34114766948024544"/>
      <body pos="0.099570412501628208 0 0.34114766948024544" name="0/2/">
        <joint name="0/2/joint/" class="0/" type="hinge" axis="0 1 0" limited="true" range="-65.164724484775761 65.164724484775761"/>
        <geom name="0/2/geom" class="0/2/" type="capsule" contype="1" conaffinity="1" condim="3" size="0.064152282570693206" rgba="0.74964427233032127 0.6286979103751491 0.027112932324842021 1" friction="0.59999999999999998 0.10000000000000001 0.10000000000000001" fromto="0 0 0 0.66111752034530991 0 -0.37179453471949253"/>
        <site name="0/2/end2" class="0/2/" size="0.0050000000000000001" pos="0.66111752034530991 0 -0.37179453471949253"/>
        <site name="0/2/attach3" class="0/2/" size="9.9999999999999995e-07 9.9999999999999995e-07 9.9999999999999995e-07" pos="0.58943622002761487 0 -0.33148291858536616"/>
        <body pos="0.58943622002761487 0 -0.33148291858536616" name="0/2/3/">
          <joint name="0/2/3/joint/" class="0/2/" type="hinge" axis="0 1 0" limited="true" range="-54.132014779784328 54.132014779784328"/>
          <geom name="0/2/3/geom" class="0/2/3/" type="capsule" contype="1" conaffinity="1" condim="3" size="0.068062744351632468" rgba="0.60338443328204372 0.97264948793338479 0.51487659525975726 1" friction="0.59999999999999998 0.10000000000000001 0.10000000000000001" fromto="0 0 0 0.057916908912086784 0 -0.71637001446077653"/>
          <site name="0/2/3/end3" class="0/2/3/" size="0.0050000000000000001" pos="0.057916908912086784 0 -0.71637001446077653"/>
          <site name="0/2/3/attach4" class="0/2/3/" size="9.9999999999999995e-07 9.9999999999999995e-07 9.9999999999999995e-07" pos="0.047536170581810332 0 -0.58797142055339779"/>
          <body pos="0.047536170581810332 0 -0.58797142055339779" name="0/2/3/4/">
            <joint name="0/2/3/4/joint/" class="0/2/3/" type="hinge" axis="0 1 0" limited="true" range="-69.62798650819569 69.62798650819569"/>
            <geom name="0/2/3/4/geom" class="0/2/3/4/" type="capsule" contype="1" conaffinity="1" condim="3" size="0.069037416460927925" rgba="0.44010417028004423 0.62898945565500908 0.75169501844717179 1" friction="0.59999999999999998 0.10000000000000001 0.10000000000000001" fromto="0 0 0 0.23905224205368136 0 0.27156363500818981"/>
            <site name="0/2/3/4/end4" class="0/2/3/4/" size="0.0050000000000000001" pos="0.23905224205368136 0 0.27156363500818981"/>
          </body>
          <site name="0/2/3/attach5" class="0/2/3/" size="9.9999999999999995e-07 9.9999999999999995e-07 9.9999999999999995e-07" pos="0.020391435681706996 0 -0.25222017798556762"/>
          <body pos="0.020391435681706996 0 -0.25222017798556762" name="0/2/3/5/">
            <joint name="0/2/3/5/joint/" class="0/2/3/" type="hinge" axis="0 1 0" limited="true" range="-35.366997830366572 35.366997830366572"/>
            <geom name="0/2/3/5/geom" class="0/2/3/5/" type="capsule" contype="1" conaffinity="1" condim="3" size="0.062094534271930055" rgba="0.90554078637657454 0.70012177757483329 0.54207657519538344 1" friction="0.59999999999999998 0.10000000000000001 0.10000000000000001" fromto="0 0 0 0.59526814705801057 0 0.055712897662241745"/>
            <site name="0/2/3/5/end5" class="0/2/3/5/" size="0.0050000000000000001" pos="0.59526814705801057 0 0.055712897662241745"/>
            <site name="0/2/3/5/attach6" class="0/2/3/5/" size="9.9999999999999995e-07 9.9999999999999995e-07 9.9999999999999995e-07" pos="0.41782279982983661 0 0.039105265421841034"/>
            <body pos="0.41782279982983661 0 0.039105265421841034" name="0/2/3/5/6/">
              <joint name="0/2/3/5/6/joint/" class="0/2/3/5/" type="hinge" axis="0 1 0" limited="true" range="-39.160796430667418 39.160796430667418"/>
              <geom name="0/2/3/5/6/geom" class="0/2/3/5/6/" type="capsule" contype="1" conaffinity="1" condim="3" size="0.043030658252666193" rgba="0.14919216540020053 0.74920802388280416 0.067069370043554399 1" friction="0.59999999999999998 0.10000000000000001 0.10000000000000001" fromto="0 0 0 -0.32578423971981851 0 0.65096886681217203"/>
              <site name="0/2/3/5/6/end6" class="0/2/3/5/6/" size="0.0050000000000000001" pos="-0.32578423971981851 0 0.65096886681217203"/>
              <site name="0/2/3/5/6/attach7" class="0/2/3/5/6/" size="9.9999999999999995e-07 9.9999999999999995e-07 9.9999999999999995e-07" pos="-0.31997518307685258 0 0.6393614452150701"/>
              <body pos="-0.31997518307685258 0 0.6393614452150701" name="0/2/3/5/6/7/">
                <joint name="0/2/3/5/6/7/joint/" class="0/2/3/5/6/" type="hinge" axis="0 1 0" limited="true" range="-39.717195200593068 39.717195200593068"/>
                <geom name="0/2/3/5/6/7/geom" class="0/2/3/5/6/7/" type="capsule" contype="1" conaffinity="1" condim="3" size="0.048305743784982216" rgba="0.47764204797284093 0.62444519681491772 0.71471219029029798 1" friction="0.59999999999999998 0.10000000000000001 0.10000000000000001" fromto="0 0 0 0.23133196706370218 0 0.086777819905767162"/>
                <site name="0/2/3/5/6/7/end7" class="0/2/3/5/6/7/" size="0.0050000000000000001" pos="0.23133196706370218 0 0.086777819905767162"/>
              </body>
            </body>
          </body>
        </body>
        <site name="0/2/attach8" class="0/2/" size="9.9999999999999995e-07 9.9999999999999995e-07 9.9999999999999995e-07" pos="0.48742739620086356 0 -0.27411592705239285"/>
        <body pos="0.48742739620086356 0 -0.27411592705239285" name="0/2/8/">
          <geom name="0/2/8/geom" class="0/2/8/" type="capsule" contype="1" conaffinity="1" condim="3" size="0.051184233684521227" rgba="0.50899948323904132 0.41206886135107501 0.71968553649358558 1" friction="0.59999999999999998 0.10000000000000001 0.10000000000000001" fromto="0 0 0 -0.48428840076619117 0 -0.65172506162426447"/>
          <site name="0/2/8/end8" class="0/2/8/" size="0.0050000000000000001" pos="-0.48428840076619117 0 -0.65172506162426447"/>
        </body>
        <site name="0/2/attach9" class="0/2/" size="9.9999999999999995e-07 9.9999999999999995e-07 9.9999999999999995e-07" pos="0.16815469263693067 0 -0.09456563135279257"/>
        <body pos="0.16815469263693067 0 -0.09456563135279257" name="0/2/9/">
          <joint name="0/2/9/joint/" class="0/2/" type="hinge" axis="0 1 0" limited="true" range="-35.75574741039879 35.75574741039879"/>
          <geom name="0/2/9/geom" class="0/2/9/" type="capsule" contype="1" conaffinity="1" condim="3" size="0.054887614811661656" rgba="0.60816841875108452 0.32321207175560285 0.046636216220769522 1" friction="0.59999999999999998 0.10000000000000001 0.10000000000000001" fromto="0 0 0 -0.34666783339111529 0 -0.55988004383617285"/>
          <site name="0/2/9/end9" class="0/2/9/" size="0.0050000000000000001" pos="-0.34666783339111529 0 -0.55988004383617285"/>
          <site name="0/2/9/attach10" class="0/2/9/" size="9.9999999999999995e-07 9.9999999999999995e-07 9.9999999999999995e-07" pos="-0.33255281475623089 0 -0.53708382079250927"/>
          <body pos="-0.33255281475623089 0 -0.53708382079250927" name="0/2/9/10/">
            <joint name="0/2/9/10/joint/" class="0/2/9/" type="hinge" axis="0 1 0" limited="true" range="-63.762913190154507 63.762913190154507"/>
            <geom name="0/2/9/10/geom" class="0/2/9/10/" type="capsule" contype="1" conaffinity="1" condim="3" size="0.044834843520651986" rgba="0.35941916063414658 0.37003519973062393 0.017129825403907506 1" friction="0.59999999999999998 0.10000000000000001 0.10000000000000001" fromto="0 0 0 -0.4856697950927974 0 0.70026741112770385"/>
            <site name="0/2/9/10/end10" class="0/2/9/10/" size="0.0050000000000000001" pos="-0.4856697950927974 0 0.70026741112770385"/>
          </body>
        </body>
      </body>
      <camera name="0/side" class="0/" mode="trackcom" pos="0.40000000000000002 -4 0.20000000000000001" quat="0.70699999999999996 0.70699999999999996 0 0"/>
    </body>
  </worldbody>
  <actuator>
    <motor name="0/2/motor" class="0/2/" ctrllimited="true" ctrlrange="-1 1" gear="59" joint="0/2/joint/"/>
    <motor name="0/2/3/motor" class="0/2/3/" ctrllimited="true" ctrlrange="-1 1" gear="81" joint="0/2/3/joint/"/>
    <motor name="0/2/3/4/motor" class="0/2/3/4/" ctrllimited="true" ctrlrange="-1 1" gear="55" joint="0/2/3/4/joint/"/>
    <motor name="0/2/3/5/motor" class="0/2/3/5/" ctrllimited="true" ctrlrange="-1 1" gear="75" joint="0/2/3/5/joint/"/>
    <motor name="0/2/3/5/6/motor" class="0/2/3/5/6/" ctrllimited="true" ctrlrange="-1 1" gear="65" joint="0/2/3/5/6/joint/"/>
    <motor name="0/2/3/5/6/7/motor" class="0/2/3/5/6/7/" ctrllimited="true" ctrlrange="-1 1" gear="84" joint="0/2/3/5/6/7/joint/"/>
    <motor name="0/2/9/motor" class="0/2/9/" ctrllimited="true" ctrlrange="-1 1" gear="75" joint="0/2/9/joint/"/>
    <motor name="0/2/9/10/motor" class="0/2/9/10/" ctrllimited="true" ctrlrange="-1 1" gear="82" joint="0/2/9/10/joint/"/>
  </actuator>
  <sensor>
    <subtreelinvel name="velocity" body="0/"/>
  </sensor>
</mujoco>
