<mujoco model="morphology">
  <option timestep="0.01"/>
  <default>
    <default class="/"/>
    <default class="0/"/>
    <default class="0/1/"/>
    <default class="0/1/2/"/>
    <default class="0/1/2/3/"/>
    <default class="0/1/2/3/4/"/>
    <default class="0/1/2/3/4/5/"/>
    <default class="0/1/2/3/4/5/6/"/>
    <default class="0/1/2/3/4/5/6/7/"/>
    <default class="0/1/2/3/4/5/6/7/8/"/>
    <default class="0/1/2/9/"/>
    <default class="0/1/2/9/10/"/>
  </default>
  <asset>
    <texture name="texplane" type="2d" builtin="checker" rgb1="0.10000000000000001 0.20000000000000001 0.29999999999999999" rgb2="0.20000000000000001 0.29999999999999999 0.40000000000000002" width="300" height="300"/>
    <material name="MatPlane" class="/" texture="texplane" texrepeat="20 20" specular="1" shininess="1" reflectance="0.5"/>
  </asset>
  <worldbody>
    <light name="//unnamed_light_0" class="/" directional="true" pos="0 0 1.5" dir="0 0 -1.3" cutoff="100" exponent="1" diffuse="1 1 1" specular="0.10000000000000001 0.10000000000000001 0.10000000000000001"/>
    <geom name="ground" class="/" type="plane" size="15 15 0.5" material="MatPlane" rgba="1 1 1 1"/>
    <site name="body" class="/" size="9.9999999999999995e-07 9.9999999999999995e-07 9.9999999999999995e-07" pos="0 0 1.2254236698150636"/>
    <body pos="0 0 1.2254236698150636" name="0/">
      <joint name="0/rootx/" class="/" type="slide" axis="1 0 0" limited="false" stiffness="0" armature="0" damping="0"/>
      <joint name="0/rootz/" class="/" type="slide" axis="0 0 1" limited="false" stiffness="0" armature="0" damping="0"/>
      <joint name="0/rooty/" class="/" type="hinge" axis="0 1 0" limited="false" stiffness="0" armature="0" damping="0"/>
      <geom name="0/geom" class="0/" type="capsule" contype="1" conaffinity="1" condim="3" size="0.059098935944711405" rgba="0.44873837889740853 0.61514706872164504 0.026430439503999814 1" friction="0.59999999999999998 0.10000000000000001 0.10000000000000001" fromto="0 0 0 0.21737533470299153 0 -0.23696815021591799"/>
      <site name="0/end0" class="0/" size="0.0050000000000000001" pos="0.21737533470299153 0 -0.23696815021591799"/>
      <site name="0/attach1" class="0/" size="9.9999999999999995e-07 9.9999999999999995e-07 9.9999999999999995e-07" pos="0.1859901043897198 0 -0.20275405696748924"/>
      <body pos="0.1859901043897198 0 -0.20275405696748924" name="0/1/">
        <joint name="0/1/joint/" class="0/" type="hinge" axis="0 1 0" limited="true" range="-59.632796424934853 59.632796424934853"/>
        <geom name="0/1/geom" class="0/1/" type="capsule" contype="1" conaffinity="1" condim="3" size="0.041095881994889887" rgba="0.025674486533716845 0.66095272034039521 0.60043000789036283 1" friction="0.59999999999999998 0.10000000000000001 0.10000000000000001" fromto="0 0 0 -0.2018692448131687 0 -0.62632923840919674"/>
        <site name="0/1/end1" class="0/1/" size="0.0050000000000000001" pos="-0.2018692448131687 0 -0.62632923840919674"/>
        <site name="0/1/attach2" class="0/1/" size="9.9999999999999995e-07 9.9999999999999995e-07 9.9999999999999995e-07" pos="-0.049693976461963996 0 -0.1541829239999023"/>
        <body pos="-0.049693976461963996 0 -0.1541829239999023" name="0/1/2/">
          <joint name="0/1/2/joint/" class="0/1/" type="hinge" axis="0 1 0" limited="true" range="-52.142063850045993 52.142063850045993"/>
          <geom name="0/1/2/geom" class="0/1/2/" type="capsule" contype="1" conaffinity="1" condim="3" size="0.054167861666898499" rgba="0.67173712910097405 0.18197056509653087 0.7217842464647285 1" friction="0.59999999999999998 0.10000000000000001 0.10000000000000001" fromto="0 0 0 -0.67982004813608499 0 -0.33465410092288023"/>
          <site name="0/1/2/end2" class="0/1/2/" size="0.0050000000000000001" pos="-0.67982004813608499 0 -0.33465410092288023"/>
          <site name="0/1/2/attach3" class="0/1/2/" size="9.9999999999999995e-07 9.9999999999999995e-07 9.9999999999999995e-07" pos="-0.012400704452932391 0 -0.0061044781054702272"/>
          <body pos="-0.012400704452932391 0 -0.0061044781054702272" name="0/1/2/3/">
            <joint name="0/1/2/3/joint/" class="0/1/2/" type="hinge" axis="0 1 0" limited="true" range="-38.993480727756406 38.993480727756406"/>
            <geom name="0/1/2/3/geom" class="0/1/2/3/" type="capsule" contype="1" conaffinity="1" condim="3" size="0.054144242045618469" rgba="0.048067546361043267 0.070661346928479252 0.21605049824466427 1" friction="0.59999999999999998 0.10000000000000001 0.10000000000000001" fromto="0 0 0 -0.69011797826741672 0 0.45702906302112911"/>
            <site name="0/1/2/3/end3" class="0/1/2/3/" size="0.0050000000000000001" pos="-0.69011797826741672 0 0.45702906302112911"/>
            <site name="0/1/2/3/attach4" class="0/1/2/3/" size="9.9999999999999995e-07 9.9999999999999995e-07 9.9999999999999995e-07" pos="-0.53630855530180388 0 0.35516912214801144"/>
            <body pos="-0.53630855530180388 0 0.35516912214801144" name="0/1/2/3/4/">
              <joint name="0/1/2/3/4/joint/" class="0/1/2/3/" type="hinge" axis="0 1 0" limited="true" range="-64.964051718785413 64.964051718785413"/>
              <geom name="0/1/2/3/4/geom" class="0/1/2/3/4/" type="capsule" contype="1" conaffinity="1" condim="3" size="0.049323320496127018" rgba="0.09602455569985302 0.32613411396477543 0.39919608362274428 1" friction="0.59999999999999998 0.10000000000000001 0.10000000000000001" fromto="0 0 0 -0.50457690725629734 0 -0.36312608843370364"/>
              <site name="0/1/2/3/4/end4" class="0/1/2/3/4/" size="0.0050000000000000001" pos="-0.50457690725629734 0 -0.36312608843370364"/>
              <site name="0/1/2/3/4/attach5" class="0/1/2/3/4/" size="9.9999999999999995e-07 9.9999999999999995e-07 9.9999999999999995e-07" pos="-0.21860411273181349 0 -0.1573216198170217"/>
              <body pos="-0.21860411273181349 0 -0.1573216198170217" name="0/1/2/3/4/5/">
                <joint name="0/1/2/3/4/5/joint/" class="0/1/2/3/4/" type="hinge" axis="0 1 0" limited="true" range="-34.369595721545579 34.369595721545579"/>
                <geom name="0/1/2/3/4/5/geom" class="0/1/2/3/4/5/" type="capsule" contype="1" conaffinity="1" condim="3" size="0.051393328544879838" rgba="0.037490146237384669 0.80364621172356798 0.12185049107488977 1" friction="0.59999999999999998 0.10000000000000001 0.10000000000000001" fromto="0 0 0 -0.28536585589887892 0 0.63379695203335551"/>
                <site name="0/1/2/3/4/5/end5" class="0/1/2/3/4/5/" size="0.0050000000000000001" pos="-0.28536585589887892 0 0.63379695203335551"/>
                <site name="0/1/2/3/4/5/attach6" class="0/1/2/3/4/5/" size="9.9999999999999995e-07 9.9999999999999995e-07 9.9999999999999995e-07" pos="-0.11732295716652447 0 0.26057403546566082"/>
                <body pos="-0.11732295716652447 0 0.26057403546566082" name="0/1/2/3/4/5/6/">
                  <joint name="0/1/2/3/4/5/6/joint/" class="0/1/2/3/4/5/" type="hinge" axis="0 1 0" limited="true" range="-62.696803327433052 62.696803327433052"/>
                  <geom name="0/1/2/3/4/5/6/geom" class="0/1/2/3/4/5/6/" type="capsule" contype="1" conaffinity="1" condim="3" size="0.061213809284803813" rgba="0.59243723878992816 0.3368354972469203 0.97374320154160665 1" friction="0.59999999999999998 0.10000000000000001 0.10000000000000001" fromto="0 0 0 -0.48523639961911502 0 -0.25939568977513905"/>
                  <site name="0/1/2/3/4/5/6/end6" class="0/1/2/3/4/5/6/" size="0.0050000000000000001" pos="-0.48523639961911502 0 -0.25939568977513905"/>
                  <site name="0/1/2/3/4/5/6/attach7" class="0/1/2/3/4/5/6/" size="9.9999999999999995e-07 9.9999999999999995e-07 9.9999999999999995e-07" pos="-0.30367862648955435 0 -0.16233927803037315"/>
                  <body pos="-0.30367862648955435 0 -0.16233927803037315" name="0/1/2/3/4/5/6/7/">
                    <geom name="0/1/2/3/4/5/6/7/geom" class="0/1/2/3/4/5/6/7/" type="capsule" contype="1" conaffinity="1" condim="3" size="0.064914162063680503" rgba="0.58251228788402698 0.23157571592995652 0.9052050909981646 1" friction="0.59999999999999998 0.10000000000000001 0.10000000000000001" fromto="0 0 0 -0.045019485695720007 0 -0.17939091791675776"/>
                    <site name="0/1/2/3/4/5/6/7/end7" class="0/1/2/3/4/5/6/7/" size="0.0050000000000000001" pos="-0.045019485695720007 0 -0.17939091791675776"/>
                    <site name="0/1/2/3/4/5/6/7/attach8" class="0/1/2/3/4/5/6/7/" size="9.9999999999999995e-07 9.9999999999999995e-07 9.9999999999999995e-07" pos="-0.0003334761376959179 0 -0.0013288155011129579"/>
                    <body pos="-0.0003334761376959179 0 -0.0013288155011129579" name="0/1/2/3/4/5/6/7/8/">
                      <joint name="0/1/2/3/4/5/6/7/8/joint/" class="0/1/2/3/4/5/6/7/" type="hinge" axis="0 1 0" limited="true" range="-42.664170358667114 42.664170358667114"/>
                      <geom name="0/1/2/3/4/5/6/7/8/geom" class="0/1/2/3/4/5/6/7/8/" type="capsule" contype="1" conaffinity="1" condim="3" size="0.069663978272099206" rgba="0.77299302616392251 0.31731267611501102 0.86052717955123792 1" friction="0.59999999999999998 0.10000000000000001 0.10000000000000001" fromto="0 0 0 -0.68713299147332518 0 0.60516997900092662"/>
                      <site name="0/1/2/3/4/5/6/7/8/end8" class="0/1/2/3/4/5/6/7/8/" size="0.0050000000000000001" pos="-0.68713299147332518 0 0.60516997900092662"/>
                    </body>
                  </body>
                </body>
              </body>
            </body>
          </body>
          <site name="0/1/2/attach9" class="0/1/2/" size="9.9999999999999995e-07 9.9999999999999995e-07 9.9999999999999995e-07" pos="-0.5751400457764565 0 -0.2831234169274387"/>
          <body pos="-0.5751400457764565 0 -0.2831234169274387" name="0/1/2/9/">
            <geom name="0/1/2/9/geom" class="0/1/2/9/" type="capsule" contype="1" conaffinity="1" condim="3" size="0.049412903411067459" rgba="0.1709165408336174 0.0051156012447892696 0.17045805709121187 1" friction="0.59999999999999998 0.10000000000000001 0.10000000000000001" fromto="0 0 0 -0.31797198502975232 0 0.14176114103741844"/>
            <site name="0/1/2/9/end9" class="0/1/2/9/" size="0.0050000000000000001" pos="-0.31797198502975232 0 0.14176114103741844"/>
            <site name="0/1/2/9/attach10" class="0/1/2/9/" size="9.9999999999999995e-07 9.9999999999999995e-07 9.9999999999999995e-07" pos="-0.19815649741723501 0 0.088343918648106867"/>
            <body pos="-0.19815649741723501 0 0.088343918648106867" name="0/1/2/9/10/">
              <geom name="0/1/2/9/10/geom" class="0/1/2/9/10/" type="capsule" contype="1" conaffinity="1" condim="3" size="0.055259669513512411" rgba="0.66304133524382358 0.35641432556386243 0.32608351138805602 1" friction="0.59999999999999998 0.10000000000000001 0.10000000000000001" fromto="0 0 0 -0.63622171740261368 0 -0.57370719236597401"/>
              <site name="0/1/2/9/10/end10" class="0/1/2/9/10/" size="0.0050000000000000001" pos="-0.63622171740261368 0 -0.57370719236597401"/>
            </body>
          </body>
        </body>
      </body>
      <camera name="0/side" class="0/" mode="trackcom" pos="0.40000000000000002 -4 0.20000000000000001" quat="0.70699999999999996 0.70699999999999996 0 0"/>
    </body>
  </worldbody>
  <actuator>
    <motor name="0/1/motor" class="0/1/" ctrllimited="true" ctrlrange="-1 1" gear="51" joint="0/1/joint/"/>
    <motor name="0/1/2/motor" class="0/1/2/" ctrllimited="true" ctrlrange="-1 1" gear="50" joint="0/1/2/joint/"/>
    <motor name="0/1/2/3/motor" class="0/1/2/3/" ctrllimited="true" ctrlrange="-1 1" gear="84" joint="0/1/2/3/joint/"/>
    <motor name="0/1/2/3/4/motor" class="0/1/2/3/4/" ctrllimited="true" ctrlrange="-1 1" gear="89" joint="0/1/2/3/4/joint/"/>
    <motor name="0/1/2/3/4/5/motor" class="0/1/2/3/4/5/" ctrllimited="true" ctrlrange="-1 1" gear="69" joint="0/1/2/3/4/5/joint/"/>
    <motor name="0/1/2/3/4/5/6/motor" class="0/1/2/3/4/5/6/" ctrllimited="true" ctrlrange="-1 1" gear="83" joint="0/1/2/3/4/5/6/joint/"/>
    <motor name="0/1/2/3/4/5/6/7/8/motor" class="0/1/2/3/4/5/6/7/8/" ctrllimited="true" ctrlrange="-1 1" gear="77" joint="0/1/2/3/4/5/6/7/8/joint/"/>
  </actuator>
  <sensor>
    <subtreelinvel name="velocity" body="0/"/>
  </sensor>
</mujoco>
