<mujoco model="morphology">
  <option timestep="0.01"/>
  <default>
    <default class="/"/>
    <default class="0/"/>
    <default class="0/1/"/>
    <default class="0/1/2/"/>
    <default class="0/1/3/"/>
    <default class="0/1/3/4/"/>
    <default class="0/1/3/4/5/"/>
    <default class="0/1/3/4/5/6/"/>
    <default class="0/1/3/4/5/7/"/>
    <default class="0/1/3/4/5/7/8/"/>
    <default class="0/1/3/4/5/7/8/9/"/>
    <default class="0/1/3/4/5/7/8/10/"/>
  </default>
  <asset>
    <texture name="texplane" type="2d" builtin="checker" rgb1="0.10000000000000001 0.20000000000000001 0.29999999999999999" rgb2="0.20000000000000001 0.29999999999999999 0.40000000000000002" width="300" height="300"/>
    <material name="MatPlane" class="/" texture="texplane" texrepeat="20 20" specular="1" shininess="1" reflectance="0.5"/>
  </asset>
  <worldbody>
    <light name="//unnamed_light_0" class="/" directional="true" pos="0 0 1.5" dir="0 0 -1.3" cutoff="100" exponent="1" diffuse="1 1 1" specular="0.10000000000000001 0.10000000000000001 0.10000000000000001"/>
    <geom name="ground" class="/" type="plane" size="15 15 0.5" material="MatPlane" rgba="1 1 1 1"/>
    <site name="body" class="/" size="9.9999999999999995e-07 9.9999999999999995e-07 9.9999999999999995e-07" pos="0 0 0.77408537864685056"/>
    <body pos="0 0 0.77408537864685056" name="0/">
      <joint name="0/rootx/" class="/" type="slide" axis="1 0 0" limited="false" stiffness="0" armature="0" damping="0"/>
      <joint name="0/rootz/" class="/" type="slide" axis="0 0 1" limited="false" stiffness="0" armature="0" damping="0"/>
      <joint name="0/rooty/" class="/" type="hinge" axis="0 1 0" limited="false" stiffness="0" armature="0" damping="0"/>
      <geom name="0/geom" class="0/" type="capsule" contype="1" conaffinity="1" condim="3" size="0.068133523125485138" rgba="0.67368878331698201 0.95845228916324254 0.82361010507004162 1" friction="0.59999999999999998 0.10000000000000001 0.10000000000000001" fromto="0 0 0 -0.40518606765632675 0 0.59862969507248076"/>
      <site name="0/end0" class="0/" size="0.0050000000000000001" pos="-0.40518606765632675 0 0.59862969507248076"/>
      <site name="0/attach1" class="0/" size="9.9999999999999995e-07 9.9999999999999995e-07 9.9999999999999995e-07" pos="-0.16261823457615437 0 0.2402553097164184"/>
      <body pos="-0.16261823457615437 0 0.2402553097164184" name="0/1/">
        <joint name="0/1/joint/" class="0/" type="hinge" axis="0 1 0" limited="true" range="-34.207994179081147 34.207994179081147"/>
        <geom name="0/1/geom" class="0/1/" type="capsule" contype="1" conaffinity="1" condim="3" size="0.055274214201340301" rgba="0.36089236012931958 0.75295362614327199 0.29893024089903175 1" friction="0.59999999999999998 0.10000000000000001 0.10000000000000001" fromto="0 0 0 -0.56567874397857332 0 0.015321061938565861"/>
        <site name="0/1/end1" class="0/1/" size="0.0050000000000000001" pos="-0.56567874397857332 0 0.015321061938565861"/>
        <site name="0/1/attach2" class="0/1/" size="9.9999999999999995e-07 9.9999999999999995e-07 9.9999999999999995e-07" pos="-0.55503734378513259 0 0.015032846139029036"/>
        <body pos="-0.55503734378513259 0 0.015032846139029036" name="0/1/2/">
          <joint name="0/1/2/joint/" class="0/1/" type="hinge" axis="0 1 0" limited="true" range="-46.633738197059515 46.633738197059515"/>
          <geom name="0/1/2/geom" class="0/1/2/" type="capsule" contype="1" conaffinity="1" condim="3" size="0.044109706651571511" rgba="0.55599383299835448 0.83296011107246093 0.51749352358233303 1" friction="0.59999999999999998 0.10000000000000001 0.10000000000000001" fromto="0 0 0 -0.58656426139093387 0 0.19216393291291767"/>
          <site name="0/1/2/end2" class="0/1/2/" size="0.0050000000000000001" pos="-0.58656426139093387 0 0.19216393291291767"/>
        </body>
        <site name="0/1/attach3" class="0/1/" size="9.9999999999999995e-07 9.9999999999999995e-07 9.9999999999999995e-07" pos="-0.096282345080800483 0 0.0026077482816451586"/>
        <body pos="-0.096282345080800483 0 0.0026077482816451586" name="0/1/3/">
          <joint name="0/1/3/joint/" class="0/1/" type="hinge" axis="0 1 0" limited="true" range="-41.419231732101544 41.419231732101544"/>
          <geom name="0/1/3/geom" class="0/1/3/" type="capsule" contype="1" conaffinity="1" condim="3" size="0.053701980684382492" rgba="0.87018699014469136 0.62761939975638548 0.45384537230287059 1" friction="0.59999999999999998 0.10000000000000001 0.10000000000000001" fromto="0 0 0 -0.35175166034854072 0 -0.71389011365358357"/>
          <site name="0/1/3/end3" class="0/1/3/" size="0.0050000000000000001" pos="-0.35175166034854072 0 -0.71389011365358357"/>
          <site name="0/1/3/attach4" class="0/1/3/" size="9.9999999999999995e-07 9.9999999999999995e-07 9.9999999999999995e-07" pos="-0.31317669056032665 0 -0.63560110276731008"/>
          <body pos="-0.31317669056032665 0 -0.63560110276731008" name="0/1/3/4/">
            <geom name="0/1/3/4/geom" class="0/1/3/4/" type="capsule" contype="1" conaffinity="1" condim="3" size="0.061928049357544881" rgba="0.35748986429106344 0.60098576724272967 0.86789416492055449 1" friction="0.59999999999999998 0.10000000000000001 0.10000000000000001" fromto="0 0 0 0.66440738364730545 0 -0.28134733452442906"/>
            <site name="0/1/3/4/end4" class="0/1/3/4/" size="0.0050000000000000001" pos="0.66440738364730545 0 -0.28134733452442906"/>
            <site name="0/1/3/4/attach5" class="0/1/3/4/" size="9.9999999999999995e-07 9.9999999999999995e-07 9.9999999999999995e-07" pos="0.30797780474310288 0 -0.13041506851036705"/>
            <body pos="0.30797780474310288 0 -0.13041506851036705" name="0/1/3/4/5/">
              <joint name="0/1/3/4/5/joint/" class="0/1/3/4/" type="hinge" axis="0 1 0" limited="true" range="-31.645944407647018 31.645944407647018"/>
              <geom name="0/1/3/4/5/geom" class="0/1/3/4/5/" type="capsule" contype="1" conaffinity="1" condim="3" size="0.040505816399885548" rgba="0.80576584226427772 0.24361473910812237 0.22570649573779378 1" friction="0.59999999999999998 0.10000000000000001 0.10000000000000001" fromto="0 0 0 0.11701272950382857 0 0.15636463607744211"/>
              <site name="0/1/3/4/5/end5" class="0/1/3/4/5/" size="0.0050000000000000001" pos="0.11701272950382857 0 0.15636463607744211"/>
              <site name="0/1/3/4/5/attach6" class="0/1/3/4/5/" size="9.9999999999999995e-07 9.9999999999999995e-07 9.9999999999999995e-07" pos="0.080119281252668886 0 0.10706375544764896"/>
              <body pos="0.080119281252668886 0 0.10706375544764896" name="0/1/3/4/5/6/">
                <joint name="0/1/3/4/5/6/joint/" class="0/1/3/4/5/" type="hinge" axis="0 1 0" limited="true" range="-40.647240584044795 40.647240584044795"/>
                <geom name="0/1/3/4/5/6/geom" class="0/1/3/4/5/6/" type="capsule" contype="1" conaffinity="1" condim="3" size="0.055799563593050466" rgba="0.65393408603913183 0.85421922984932075 0.63545992268337648 1" friction="0.59999999999999998 0.10000000000000001 0.10000000000000001" fromto="0 0 0 0.43314333403469196 0 -0.08529218564910912"/>
                <site name="0/1/3/4/5/6/end6" class="0/1/3/4/5/6/" size="0.0050000000000000001" pos="0.43314333403469196 0 -0.08529218564910912"/>
              </body>
              <site name="0/1/3/4/5/attach7" class="0/1/3/4/5/" size="9.9999999999999995e-07 9.9999999999999995e-07 9.9999999999999995e-07" pos="0.09526545395961275 0 0.12730365407517286"/>
              <body pos="0.09526545395961275 0 0.12730365407517286" name="0/1/3/4/5/7/">
                <geom name="0/1/3/4/5/7/geom" class="0/1/3/4/5/7/" type="capsule" contype="1" conaffinity="1" condim="3" size="0.048314282904299767" rgba="0.94142437787209032 0.83873212916854512 0.23662781041021963 1" friction="0.59999999999999998 0.10000000000000001 0.10000000000000001" fromto="0 0 0 -0.055145347385145982 0 0.3376145189399482"/>
                <site name="0/1/3/4/5/7/end7" class="0/1/3/4/5/7/" size="0.0050000000000000001" pos="-0.055145347385145982 0 0.3376145189399482"/>
                <site name="0/1/3/4/5/7/attach8" class="0/1/3/4/5/7/" size="9.9999999999999995e-07 9.9999999999999995e-07 9.9999999999999995e-07" pos="-0.012142186375307605 0 0.074337702206276862"/>
                <body pos="-0.012142186375307605 0 0.074337702206276862" name="0/1/3/4/5/7/8/">
                  <geom name="0/1/3/4/5/7/8/geom" class="0/1/3/4/5/7/8/" type="capsule" contype="1" conaffinity="1" condim="3" size="0.050400837722818705" rgba="0.05373558433499348 0.7243563194274748 0.86146765965876804 1" friction="0.59999999999999998 0.10000000000000001 0.10000000000000001" fromto="0 0 0 0.36859763848868288 0 0.11555790437130198"/>
                  <site name="0/1/3/4/5/7/8/end8" class="0/1/3/4/5/7/8/" size="0.0050000000000000001" pos="0.36859763848868288 0 0.11555790437130198"/>
                  <site name="0/1/3/4/5/7/8/attach9" class="0/1/3/4/5/7/8/" size="9.9999999999999995e-07 9.9999999999999995e-07 9.9999999999999995e-07" pos="0.10996584025189435 0 0.03447505009538588"/>
                  <body pos="0.10996584025189435 0 0.03447505009538588" name="0/1/3/4/5/7/8/9/">
                    <joint name="0/1/3/4/5/7/8/9/joint/" class="0/1/3/4/5/7/8/" type="hinge" axis="0 1 0" limited="true" range="-49.668716895302381 49.668716895302381"/>
                    <geom name="0/1/3/4/5/7/8/9/geom" class="0/1/3/4/5/7/8/9/" type="capsule" contype="1" conaffinity="1" condim="3" size="0.05328852162972933" rgba="0.011334809490293196 0.95620555372785043 0.28808487728999344 1" friction="0.59999999999999998 0.10000000000000001 0.10000000000000001" fromto="0 0 0 0.058613484019736539 0 0.14331031902665203"/>
                    <site name="0/1/3/4/5/7/8/9/end9" class="0/1/3/4/5/7/8/9/" size="0.0050000000000000001" pos="0.058613484019736539 0 0.14331031902665203"/>
                  </body>
                  <site name="0/1/3/4/5/7/8/attach10" class="0/1/3/4/5/7/8/" size="9.9999999999999995e-07 9.9999999999999995e-07 9.9999999999999995e-07" pos="0.33967667024804615 0 0.10649098116479433"/>
                  <body pos="0.33967667024804615 0 0.10649098116479433" name="0/1/3/4/5/7/8/10/">
                    <joint name="0/1/3/4/5/7/8/10/joint/" class="0/1/3/4/5/7/8/" type="hinge" axis="0 1 0" limited="true" range="-46.049024020485291 46.049024020485291"/>
                    <geom name="0/1/3/4/5/7/8/10/geom" class="0/1/3/4/5/7/8/10/" type="capsule" contype="1" conaffinity="1" condim="3" size="0.059567712518968398" rgba="0.67915533204956635 0.096910000748154812 0.9533211868143463 1" friction="0.59999999999999998 0.10000000000000001 0.10000000000000001" fromto="0 0 0 0.37065416227408265 0 -0.31415937899289254"/>
                    <site name="0/1/3/4/5/7/8/10/end10" class="0/1/3/4/5/7/8/10/" size="0.0050000000000000001" pos="0.37065416227408265 0 -0.31415937899289254"/>
                  </body>
                </body>
              </body>
            </body>
          </body>
        </body>
      </body>
      <camera name="0/side" class="0/" mode="trackcom" pos="0.40000000000000002 -4 0.20000000000000001" quat="0.70699999999999996 0.70699999999999996 0 0"/>
    </body>
  </worldbody>
  <actuator>
    <motor name="0/1/motor" class="0/1/" ctrllimited="true" ctrlrange="-1 1" gear="66" joint="0/1/joint/"/>
    <motor name="0/1/2/motor" class="0/1/2/" ctrllimited="true" ctrlrange="-1 1" gear="65" joint="0/1/2/joint/"/>
    <motor name="0/1/3/motor" class="0/1/3/" ctrllimited="true" ctrlrange="-1 1" gear="57" joint="0/1/3/joint/"/>
    <motor name="0/1/3/4/5/motor" class="0/1/3/4/5/" ctrllimited="true" ctrlrange="-1 1" gear="62" joint="0/1/3/4/5/joint/"/>
    <motor name="0/1/3/4/5/6/motor" class="0/1/3/4/5/6/" ctrllimited="true" ctrlrange="-1 1" gear="55" joint="0/1/3/4/5/6/joint/"/>
    <motor name="0/1/3/4/5/7/8/9/motor" class="0/1/3/4/5/7/8/9/" ctrllimited="true" ctrlrange="-1 1" gear="73" joint="0/1/3/4/5/7/8/9/joint/"/>
    <motor name="0/1/3/4/5/7/8/10/motor" class="0/1/3/4/5/7/8/10/" ctrllimited="true" ctrlrange="-1 1" gear="72" joint="0/1/3/4/5/7/8/10/joint/"/>
  </actuator>
  <sensor>
    <subtreelinvel name="velocity" body="0/"/>
  </sensor>
</mujoco>
