<mujoco model="morphology">
  <option timestep="0.01"/>
  <default>
    <default class="/"/>
    <default class="0/"/>
    <default class="0/1/"/>
    <default class="0/1/2/"/>
    <default class="0/1/2/3/"/>
    <default class="0/1/4/"/>
  </default>
  <asset>
    <texture name="texplane" type="2d" builtin="checker" rgb1="0.10000000000000001 0.20000000000000001 0.29999999999999999" rgb2="0.20000000000000001 0.29999999999999999 0.40000000000000002" width="300" height="300"/>
    <material name="MatPlane" class="/" texture="texplane" texrepeat="20 20" specular="1" shininess="1" reflectance="0.5"/>
  </asset>
  <worldbody>
    <light name="//unnamed_light_0" class="/" directional="true" pos="0 0 1.5" dir="0 0 -1.3" cutoff="100" exponent="1" diffuse="1 1 1" specular="0.10000000000000001 0.10000000000000001 0.10000000000000001"/>
    <geom name="ground" class="/" type="plane" size="15 15 0.5" material="MatPlane" rgba="1 1 1 1"/>
    <site name="body" class="/" size="9.9999999999999995e-07 9.9999999999999995e-07 9.9999999999999995e-07" pos="0 0 0.10000000000000001"/>
    <body pos="0 0 0.10000000000000001" name="0/">
      <joint name="0/rootx/" class="/" type="slide" axis="1 0 0" limited="false" stiffness="0" armature="0" damping="0"/>
      <joint name="0/rootz/" class="/" type="slide" axis="0 0 1" limited="false" stiffness="0" armature="0" damping="0"/>
      <joint name="0/rooty/" class="/" type="hinge" axis="0 1 0" limited="false" stiffness="0" armature="0" damping="0"/>
      <geom name="0/geom" class="0/" type="capsule" contype="1" conaffinity="1" condim="3" size="0.048961288148170169" rgba="0.2386821834035644 0.36781776845260827 0.12222439737540358 1" friction="0.59999999999999998 0.10000000000000001 0.10000000000000001" fromto="0 0 0 0.73623177112567273 0 0.29961522042288125"/>
      <site name="0/end0" class="0/" size="0.0050000000000000001" pos="0.73623177112567273 0 0.29961522042288125"/>
      <site name="0/attach1" class="0/" size="9.9999999999999995e-07 9.9999999999999995e-07 9.9999999999999995e-07" pos="0.17274499601320933 0 0.070299913814250048"/>
      <body pos="0.17274499601320933 0 0.070299913814250048" name="0/1/">
        <joint name="0/1/joint/" class="0/" type="hinge" axis="0 1 0" limited="true" range="-33.513489263625388 33.513489263625388"/>
        <geom name="0/1/geom" class="0/1/" type="capsule" contype="1" conaffinity="1" condim="3" size="0.044734156916989481" rgba="0.3551852535629576 0.94726971106328006 0.8019544495745986 1" friction="0.59999999999999998 0.10000000000000001 0.10000000000000001" fromto="0 0 0 0.26555832629105103 0 0.7253737356862533"/>
        <site name="0/1/end1" class="0/1/" size="0.0050000000000000001" pos="0.26555832629105103 0 0.7253737356862533"/>
        <site name="0/1/attach2" class="0/1/" size="9.9999999999999995e-07 9.9999999999999995e-07 9.9999999999999995e-07" pos="0.040781814702636539 0 0.1113957061413853"/>
        <body pos="0.040781814702636539 0 0.1113957061413853" name="0/1/2/">
          <joint name="0/1/2/joint/" class="0/1/" type="hinge" axis="0 1 0" limited="true" range="-65.398875915526787 65.398875915526787"/>
          <geom name="0/1/2/geom" class="0/1/2/" type="capsule" contype="1" conaffinity="1" condim="3" size="0.068668927516748329" rgba="0.17769480553092043 0.20645109644620274 0.31348821498851931 1" friction="0.59999999999999998 0.10000000000000001 0.10000000000000001" fromto="0 0 0 -0.64017455103220078 0 -0.12029786774712148"/>
          <site name="0/1/2/end2" class="0/1/2/" size="0.0050000000000000001" pos="-0.64017455103220078 0 -0.12029786774712148"/>
          <site name="0/1/2/attach3" class="0/1/2/" size="9.9999999999999995e-07 9.9999999999999995e-07 9.9999999999999995e-07" pos="-0.0013781821603698935 0 -0.00025897995318979847"/>
          <body pos="-0.0013781821603698935 0 -0.00025897995318979847" name="0/1/2/3/">
            <geom name="0/1/2/3/geom" class="0/1/2/3/" type="capsule" contype="1" conaffinity="1" condim="3" size="0.058116926143325628" rgba="0.92821940996193675 0.60363650842823013 0.49747137803110442 1" friction="0.59999999999999998 0.10000000000000001 0.10000000000000001" fromto="0 0 0 -0.27830151989812435 0 0.47706663704374952"/>
            <site name="0/1/2/3/end3" class="0/1/2/3/" size="0.0050000000000000001" pos="-0.27830151989812435 0 0.47706663704374952"/>
          </body>
        </body>
        <site name="0/1/attach4" class="0/1/" size="9.9999999999999995e-07 9.9999999999999995e-07 9.9999999999999995e-07" pos="0.21785203751458321 0 0.5950637981714838"/>
        <body pos="0.21785203751458321 0 0.5950637981714838" name="0/1/4/">
          <joint name="0/1/4/joint/" class="0/1/" type="hinge" axis="0 1 0" limited="true" range="-47.099632698921496 47.099632698921496"/>
          <geom name="0/1/4/geom" class="0/1/4/" type="capsule" contype="1" conaffinity="1" condim="3" size="0.044923879247024373" rgba="0.90477432691652238 0.54617515247863302 0.41160352219381557 1" friction="0.59999999999999998 0.10000000000000001 0.10000000000000001" fromto="0 0 0 -0.43289504458892664 0 0.71389299860151656"/>
          <site name="0/1/4/end4" class="0/1/4/" size="0.0050000000000000001" pos="-0.43289504458892664 0 0.71389299860151656"/>
        </body>
      </body>
      <camera name="0/side" class="0/" mode="trackcom" pos="0.40000000000000002 -4 0.20000000000000001" quat="0.70699999999999996 0.70699999999999996 0 0"/>
    </body>
  </worldbody>
  <actuator>
    <motor name="0/1/motor" class="0/1/" ctrllimited="true" ctrlrange="-1 1" gear="54" joint="0/1/joint/"/>
    <motor name="0/1/2/motor" class="0/1/2/" ctrllimited="true" ctrlrange="-1 1" gear="68" joint="0/1/2/joint/"/>
    <motor name="0/1/4/motor" class="0/1/4/" ctrllimited="true" ctrlrange="-1 1" gear="82" joint="0/1/4/joint/"/>
  </actuator>
  <sensor>
    <subtreelinvel name="velocity" body="0/"/>
  </sensor>
</mujoco>
