<mujoco model="morphology">
  <option timestep="0.01"/>
  <default>
    <default class="/"/>
    <default class="0/"/>
    <default class="0/1/"/>
    <default class="0/1/2/"/>
    <default class="0/1/2/3/"/>
    <default class="0/1/2/3/4/"/>
    <default class="0/1/5/"/>
    <default class="0/1/5/6/"/>
  </default>
  <asset>
    <texture name="texplane" type="2d" builtin="checker" rgb1="0.10000000000000001 0.20000000000000001 0.29999999999999999" rgb2="0.20000000000000001 0.29999999999999999 0.40000000000000002" width="300" height="300"/>
    <material name="MatPlane" class="/" texture="texplane" texrepeat="20 20" specular="1" shininess="1" reflectance="0.5"/>
  </asset>
  <worldbody>
    <light name="//unnamed_light_0" class="/" directional="true" pos="0 0 1.5" dir="0 0 -1.3" cutoff="100" exponent="1" diffuse="1 1 1" specular="0.10000000000000001 0.10000000000000001 0.10000000000000001"/>
    <geom name="ground" class="/" type="plane" size="15 15 0.5" material="MatPlane" rgba="1 1 1 1"/>
    <site name="body" class="/" size="9.9999999999999995e-07 9.9999999999999995e-07 9.9999999999999995e-07" pos="0 0 0.76808903217315672"/>
    <body pos="0 0 0.76808903217315672" name="0/">
      <joint name="0/rootx/" class="/" type="slide" axis="1 0 0" limited="false" stiffness="0" armature="0" damping="0"/>
      <joint name="0/rootz/" class="/" type="slide" axis="0 0 1" limited="false" stiffness="0" armature="0" damping="0"/>
      <joint name="0/rooty/" class="/" type="hinge" axis="0 1 0" limited="false" stiffness="0" armature="0" damping="0"/>
      <geom name="0/geom" class="0/" type="capsule" contype="1" conaffinity="1" condim="3" size="0.047113097955315784" rgba="0.28888121484060081 0.75975959189308262 0.42656155539018881 1" friction="0.59999999999999998 0.10000000000000001 0.10000000000000001" fromto="0 0 0 -0.063064015368448079 0 -0.061869452233397904"/>
      <site name="0/end0" class="0/" size="0.0050000000000000001" pos="-0.063064015368448079 0 -0.061869452233397904"/>
      <site name="0/attach1" class="0/" size="9.9999999999999995e-07 9.9999999999999995e-07 9.9999999999999995e-07" pos="-0.025996086398187842 0 -0.02550366665159506"/>
      <body pos="-0.025996086398187842 0 -0.02550366665159506" name="0/1/">
        <joint name="0/1/joint/" class="0/" type="hinge" axis="0 1 0" limited="true" stiffness="100" range="-60.421997700076005 60.421997700076005" armature="0.20000000000000001" damping="3.5"/>
        <geom name="0/1/geom" class="0/1/" type="capsule" contype="1" conaffinity="1" condim="3" size="0.044544922786876578" rgba="0.97997860196145625 0.90323282047515641 0.53755157674513387 1" friction="0.59999999999999998 0.10000000000000001 0.10000000000000001" fromto="0 0 0 -0.44142927039255508 0 0.6465876217839619"/>
        <site name="0/1/end1" class="0/1/" size="0.0050000000000000001" pos="-0.44142927039255508 0 0.6465876217839619"/>
        <site name="0/1/attach2" class="0/1/" size="9.9999999999999995e-07 9.9999999999999995e-07 9.9999999999999995e-07" pos="-0.23704815248363542 0 0.34721848196965599"/>
        <body pos="-0.23704815248363542 0 0.34721848196965599" name="0/1/2/">
          <joint name="0/1/2/joint/" class="0/1/" type="hinge" axis="0 1 0" limited="true" stiffness="100" range="-38.283591594499313 38.283591594499313" armature="0.20000000000000001" damping="3.5"/>
          <geom name="0/1/2/geom" class="0/1/2/" type="capsule" contype="1" conaffinity="1" condim="3" size="0.052597569112982225" rgba="0.25079020358928117 0.83872049555049866 0.41404993267778933 1" friction="0.59999999999999998 0.10000000000000001 0.10000000000000001" fromto="0 0 0 -0.70208185180509075 0 0.026340721308208859"/>
          <site name="0/1/2/end2" class="0/1/2/" size="0.0050000000000000001" pos="-0.70208185180509075 0 0.026340721308208859"/>
          <site name="0/1/2/attach3" class="0/1/2/" size="9.9999999999999995e-07 9.9999999999999995e-07 9.9999999999999995e-07" pos="-0.49359762185714828 0 0.018518805695241489"/>
          <body pos="-0.49359762185714828 0 0.018518805695241489" name="0/1/2/3/">
            <joint name="0/1/2/3/joint/" class="0/1/2/" type="hinge" axis="0 1 0" limited="true" stiffness="100" range="-49.708133455582747 49.708133455582747" armature="0.20000000000000001" damping="3.5"/>
            <geom name="0/1/2/3/geom" class="0/1/2/3/" type="capsule" contype="1" conaffinity="1" condim="3" size="0.050158827376319021" rgba="0.99182842667130688 0.19675214880153413 0.65248755653564494 1" friction="0.59999999999999998 0.10000000000000001 0.10000000000000001" fromto="0 0 0 0.16906287542659526 0 0.2763078356365325"/>
            <site name="0/1/2/3/end3" class="0/1/2/3/" size="0.0050000000000000001" pos="0.16906287542659526 0 0.2763078356365325"/>
            <site name="0/1/2/3/attach4" class="0/1/2/3/" size="9.9999999999999995e-07 9.9999999999999995e-07 9.9999999999999995e-07" pos="0.12793300875812763 0 0.20908725624849436"/>
            <body pos="0.12793300875812763 0 0.20908725624849436" name="0/1/2/3/4/">
              <geom name="0/1/2/3/4/geom" class="0/1/2/3/4/" type="capsule" contype="1" conaffinity="1" condim="3" size="0.049233431211322648" rgba="0.6239897952307274 0.79267984865397201 0.78161208012592687 1" friction="0.59999999999999998 0.10000000000000001 0.10000000000000001" fromto="0 0 0 -0.45150102676674736 0 0.48569969871422636"/>
              <site name="0/1/2/3/4/end4" class="0/1/2/3/4/" size="0.0050000000000000001" pos="-0.45150102676674736 0 0.48569969871422636"/>
            </body>
          </body>
        </body>
        <site name="0/1/attach5" class="0/1/" size="9.9999999999999995e-07 9.9999999999999995e-07 9.9999999999999995e-07" pos="-0.092838482934160887 0 0.13598602973710378"/>
        <body pos="-0.092838482934160887 0 0.13598602973710378" name="0/1/5/">
          <joint name="0/1/5/joint/" class="0/1/" type="hinge" axis="0 1 0" limited="true" stiffness="100" range="-53.396173534853325 53.396173534853325" armature="0.20000000000000001" damping="3.5"/>
          <geom name="0/1/5/geom" class="0/1/5/" type="capsule" contype="1" conaffinity="1" condim="3" size="0.067764653141626885" rgba="0.37831788270924771 0.34971858848977333 0.19224374006240008 1" friction="0.59999999999999998 0.10000000000000001 0.10000000000000001" fromto="0 0 0 -0.45704294043201826 0 -0.32156291431051953"/>
          <site name="0/1/5/end5" class="0/1/5/" size="0.0050000000000000001" pos="-0.45704294043201826 0 -0.32156291431051953"/>
          <site name="0/1/5/attach6" class="0/1/5/" size="9.9999999999999995e-07 9.9999999999999995e-07 9.9999999999999995e-07" pos="-0.10535508515913999 0 -0.074124956812991541"/>
          <body pos="-0.10535508515913999 0 -0.074124956812991541" name="0/1/5/6/">
            <geom name="0/1/5/6/geom" class="0/1/5/6/" type="capsule" contype="1" conaffinity="1" condim="3" size="0.058402244742916005" rgba="0.43366197125644268 0.50635238381157377 0.58362995282124652 1" friction="0.59999999999999998 0.10000000000000001 0.10000000000000001" fromto="0 0 0 0.27491987092588066 0 -0.70444641294099686"/>
            <site name="0/1/5/6/end6" class="0/1/5/6/" size="0.0050000000000000001" pos="0.27491987092588066 0 -0.70444641294099686"/>
          </body>
        </body>
      </body>
      <camera name="0/side" class="0/" mode="trackcom" pos="0.40000000000000002 -4 0.20000000000000001" quat="0.70699999999999996 0.70699999999999996 0 0"/>
    </body>
  </worldbody>
  <actuator>
    <motor name="0/1/motor" class="0/1/" ctrllimited="true" ctrlrange="-1 1" gear="83" joint="0/1/joint/"/>
    <motor name="0/1/2/motor" class="0/1/2/" ctrllimited="true" ctrlrange="-1 1" gear="55" joint="0/1/2/joint/"/>
    <motor name="0/1/2/3/motor" class="0/1/2/3/" ctrllimited="true" ctrlrange="-1 1" gear="81" joint="0/1/2/3/joint/"/>
    <motor name="0/1/5/motor" class="0/1/5/" ctrllimited="true" ctrlrange="-1 1" gear="64" joint="0/1/5/joint/"/>
  </actuator>
  <sensor>
    <subtreelinvel name="velocity" body="0/"/>
  </sensor>
</mujoco>
