<mujoco model="morphology">
  <option timestep="0.01"/>
  <default>
    <default class="/"/>
    <default class="0/"/>
    <default class="0/1/"/>
    <default class="0/1/2/"/>
    <default class="0/1/2/3/"/>
    <default class="0/1/2/3/4/"/>
    <default class="0/1/2/3/5/"/>
    <default class="0/6/"/>
  </default>
  <asset>
    <texture name="texplane" type="2d" builtin="checker" rgb1="0.10000000000000001 0.20000000000000001 0.29999999999999999" rgb2="0.20000000000000001 0.29999999999999999 0.40000000000000002" width="300" height="300"/>
    <material name="MatPlane" class="/" texture="texplane" texrepeat="20 20" specular="1" shininess="1" reflectance="0.5"/>
  </asset>
  <worldbody>
    <light name="//unnamed_light_0" class="/" directional="true" pos="0 0 1.5" dir="0 0 -1.3" cutoff="100" exponent="1" diffuse="1 1 1" specular="0.10000000000000001 0.10000000000000001 0.10000000000000001"/>
    <geom name="ground" class="/" type="plane" size="15 15 0.5" material="MatPlane" rgba="1 1 1 1"/>
    <site name="body" class="/" size="9.9999999999999995e-07 9.9999999999999995e-07 9.9999999999999995e-07" pos="0 0 1.3943629026412965"/>
    <body pos="0 0 1.3943629026412965" name="0/">
      <joint name="0/rootx/" class="/" type="slide" axis="1 0 0" limited="false" stiffness="0" armature="0" damping="0"/>
      <joint name="0/rootz/" class="/" type="slide" axis="0 0 1" limited="false" stiffness="0" armature="0" damping="0"/>
      <joint name="0/rooty/" class="/" type="hinge" axis="0 1 0" limited="false" stiffness="0" armature="0" damping="0"/>
      <geom name="0/geom" class="0/" type="capsule" contype="1" conaffinity="1" condim="3" size="0.041538621048823846" rgba="0.69019840540069544 0.89886280818461672 0.16216317925493495 1" friction="0.59999999999999998 0.10000000000000001 0.10000000000000001" fromto="0 0 0 -0.18243630396952026 0 -0.20931002850003899"/>
      <site name="0/end0" class="0/" size="0.0050000000000000001" pos="-0.18243630396952026 0 -0.20931002850003899"/>
      <site name="0/attach1" class="0/" size="9.9999999999999995e-07 9.9999999999999995e-07 9.9999999999999995e-07" pos="-0.1698546485440208 0 -0.19487503613070808"/>
      <body pos="-0.1698546485440208 0 -0.19487503613070808" name="0/1/">
        <joint name="0/1/joint/" class="0/" type="hinge" axis="0 1 0" limited="true" range="-54.920230684266834 54.920230684266834"/>
        <geom name="0/1/geom" class="0/1/" type="capsule" contype="1" conaffinity="1" condim="3" size="0.04589383743651182" rgba="0.22798713973876272 0.75872111246176466 0.47739360415567988 1" friction="0.59999999999999998 0.10000000000000001 0.10000000000000001" fromto="0 0 0 -0.12082674338088017 0 -0.2868135128301269"/>
        <site name="0/1/end1" class="0/1/" size="0.0050000000000000001" pos="-0.12082674338088017 0 -0.2868135128301269"/>
        <site name="0/1/attach2" class="0/1/" size="9.9999999999999995e-07 9.9999999999999995e-07 9.9999999999999995e-07" pos="-0.11726611313950686 0 -0.278361436420203"/>
        <body pos="-0.11726611313950686 0 -0.278361436420203" name="0/1/2/">
          <joint name="0/1/2/joint/" class="0/1/" type="hinge" axis="0 1 0" limited="true" range="-35.955133941912173 35.955133941912173"/>
          <geom name="0/1/2/geom" class="0/1/2/" type="capsule" contype="1" conaffinity="1" condim="3" size="0.057608208358288018" rgba="0.45660419839455624 0.55318109515012248 0.99393495384888408 1" friction="0.59999999999999998 0.10000000000000001 0.10000000000000001" fromto="0 0 0 -0.25539169778994508 0 0.21999863694531763"/>
          <site name="0/1/2/end2" class="0/1/2/" size="0.0050000000000000001" pos="-0.25539169778994508 0 0.21999863694531763"/>
          <site name="0/1/2/attach3" class="0/1/2/" size="9.9999999999999995e-07 9.9999999999999995e-07 9.9999999999999995e-07" pos="-0.0030144359019153195 0 0.0025966849953198002"/>
          <body pos="-0.0030144359019153195 0 0.0025966849953198002" name="0/1/2/3/">
            <joint name="0/1/2/3/joint/" class="0/1/2/" type="hinge" axis="0 1 0" limited="true" range="-41.841651489394039 41.841651489394039"/>
            <geom name="0/1/2/3/geom" class="0/1/2/3/" type="capsule" contype="1" conaffinity="1" condim="3" size="0.0620592156871018" rgba="0.57431814533940972 0.89879369231139306 0.061608338343649094 1" friction="0.59999999999999998 0.10000000000000001 0.10000000000000001" fromto="0 0 0 0.36786924520583897 0 -0.16262208865215189"/>
            <site name="0/1/2/3/end3" class="0/1/2/3/" size="0.0050000000000000001" pos="0.36786924520583897 0 -0.16262208865215189"/>
            <site name="0/1/2/3/attach4" class="0/1/2/3/" size="9.9999999999999995e-07 9.9999999999999995e-07 9.9999999999999995e-07" pos="0.087928473847771693 0 -0.038870093804987065"/>
            <body pos="0.087928473847771693 0 -0.038870093804987065" name="0/1/2/3/4/">
              <joint name="0/1/2/3/4/joint/" class="0/1/2/3/" type="hinge" axis="0 1 0" limited="true" range="-60.879906497324868 60.879906497324868"/>
              <geom name="0/1/2/3/4/geom" class="0/1/2/3/4/" type="capsule" contype="1" conaffinity="1" condim="3" size="0.043513341311890275" rgba="0.94884952896688801 0.836766747734486 0.68627749750055811 1" friction="0.59999999999999998 0.10000000000000001 0.10000000000000001" fromto="0 0 0 0.32505934984097218 0 0.24052907534019474"/>
              <site name="0/1/2/3/4/end4" class="0/1/2/3/4/" size="0.0050000000000000001" pos="0.32505934984097218 0 0.24052907534019474"/>
            </body>
            <site name="0/1/2/3/attach5" class="0/1/2/3/" size="9.9999999999999995e-07 9.9999999999999995e-07 9.9999999999999995e-07" pos="0.20986806994367149 0 -0.09277531166417291"/>
            <body pos="0.20986806994367149 0 -0.09277531166417291" name="0/1/2/3/5/">
              <joint name="0/1/2/3/5/joint/" class="0/1/2/3/" type="hinge" axis="0 1 0" limited="true" range="-67.355568009037952 67.355568009037952"/>
              <geom name="0/1/2/3/5/geom" class="0/1/2/3/5/" type="capsule" contype="1" conaffinity="1" condim="3" size="0.050058803220117548" rgba="0.89504763686420175 0.52631336526871475 0.78433503134960714 1" friction="0.59999999999999998 0.10000000000000001 0.10000000000000001" fromto="0 0 0 0.086682427272449569 0 -0.73094785850239563"/>
              <site name="0/1/2/3/5/end5" class="0/1/2/3/5/" size="0.0050000000000000001" pos="0.086682427272449569 0 -0.73094785850239563"/>
            </body>
          </body>
        </body>
      </body>
      <site name="0/attach6" class="0/" size="9.9999999999999995e-07 9.9999999999999995e-07 9.9999999999999995e-07" pos="-0.10869621885410878 0 -0.12470768246873189"/>
      <body pos="-0.10869621885410878 0 -0.12470768246873189" name="0/6/">
        <joint name="0/6/joint/" class="0/" type="hinge" axis="0 1 0" limited="true" range="-34.654909576688802 34.654909576688802"/>
        <geom name="0/6/geom" class="0/6/" type="capsule" contype="1" conaffinity="1" condim="3" size="0.041083748521710782" rgba="0.66019677031357094 0.091247268456081221 0.7923141112969162 1" friction="0.59999999999999998 0.10000000000000001 0.10000000000000001" fromto="0 0 0 -0.70753597122005907 0 0.047574592519988856"/>
        <site name="0/6/end6" class="0/6/" size="0.0050000000000000001" pos="-0.70753597122005907 0 0.047574592519988856"/>
      </body>
      <camera name="0/side" class="0/" mode="trackcom" pos="0.40000000000000002 -4 0.20000000000000001" quat="0.70699999999999996 0.70699999999999996 0 0"/>
    </body>
  </worldbody>
  <actuator>
    <motor name="0/1/motor" class="0/1/" ctrllimited="true" ctrlrange="-1 1" gear="70" joint="0/1/joint/"/>
    <motor name="0/1/2/motor" class="0/1/2/" ctrllimited="true" ctrlrange="-1 1" gear="65" joint="0/1/2/joint/"/>
    <motor name="0/1/2/3/motor" class="0/1/2/3/" ctrllimited="true" ctrlrange="-1 1" gear="69" joint="0/1/2/3/joint/"/>
    <motor name="0/1/2/3/4/motor" class="0/1/2/3/4/" ctrllimited="true" ctrlrange="-1 1" gear="53" joint="0/1/2/3/4/joint/"/>
    <motor name="0/1/2/3/5/motor" class="0/1/2/3/5/" ctrllimited="true" ctrlrange="-1 1" gear="78" joint="0/1/2/3/5/joint/"/>
    <motor name="0/6/motor" class="0/6/" ctrllimited="true" ctrlrange="-1 1" gear="55" joint="0/6/joint/"/>
  </actuator>
  <sensor>
    <subtreelinvel name="velocity" body="0/"/>
  </sensor>
</mujoco>
