<mujoco model="morphology">
  <option timestep="0.01"/>
  <default>
    <default class="/"/>
    <default class="0/"/>
    <default class="0/1/"/>
    <default class="0/1/2/"/>
    <default class="0/1/3/"/>
    <default class="0/1/3/4/"/>
    <default class="0/1/3/4/5/"/>
    <default class="0/1/3/4/6/"/>
    <default class="0/1/3/4/6/7/"/>
    <default class="0/1/3/4/6/7/8/"/>
    <default class="0/1/9/"/>
    <default class="0/1/9/10/"/>
  </default>
  <asset>
    <texture name="texplane" type="2d" builtin="checker" rgb1="0.10000000000000001 0.20000000000000001 0.29999999999999999" rgb2="0.20000000000000001 0.29999999999999999 0.40000000000000002" width="300" height="300"/>
    <material name="MatPlane" class="/" texture="texplane" texrepeat="20 20" specular="1" shininess="1" reflectance="0.5"/>
  </asset>
  <worldbody>
    <light name="//unnamed_light_0" class="/" directional="true" pos="0 0 1.5" dir="0 0 -1.3" cutoff="100" exponent="1" diffuse="1 1 1" specular="0.10000000000000001 0.10000000000000001 0.10000000000000001"/>
    <geom name="ground" class="/" type="plane" size="15 15 0.5" material="MatPlane" rgba="1 1 1 1"/>
    <site name="body" class="/" size="9.9999999999999995e-07 9.9999999999999995e-07 9.9999999999999995e-07" pos="0 0 0.47787011265754697"/>
    <body pos="0 0 0.47787011265754697" name="0/">
      <joint name="0/rootx/" class="/" type="slide" axis="1 0 0" limited="false" stiffness="0" armature="0" damping="0"/>
      <joint name="0/rootz/" class="/" type="slide" axis="0 0 1" limited="false" stiffness="0" armature="0" damping="0"/>
      <joint name="0/rooty/" class="/" type="hinge" axis="0 1 0" limited="false" stiffness="0" armature="0" damping="0"/>
      <geom name="0/geom" class="0/" type="capsule" contype="1" conaffinity="1" condim="3" size="0.057877986063215703" rgba="0.63747679248440148 0.16388396810774908 0.93201144365907829 1" friction="0.59999999999999998 0.10000000000000001 0.10000000000000001" fromto="0 0 0 -0.34608638767359462 0 -0.19942516084445328"/>
      <site name="0/end0" class="0/" size="0.0050000000000000001" pos="-0.34608638767359462 0 -0.19942516084445328"/>
      <site name="0/attach1" class="0/" size="9.9999999999999995e-07 9.9999999999999995e-07 9.9999999999999995e-07" pos="-0.24906224881926892 0 -0.14351699691207925"/>
      <body pos="-0.24906224881926892 0 -0.14351699691207925" name="0/1/">
        <joint name="0/1/joint/" class="0/" type="hinge" axis="0 1 0" limited="true" stiffness="100" range="-47.944491509825411 47.944491509825411" armature="0.20000000000000001" damping="3.5"/>
        <geom name="0/1/geom" class="0/1/" type="capsule" contype="1" conaffinity="1" condim="3" size="0.053712012691193516" rgba="0.26683387440528017 0.29859302738081583 0.9110972689752439 1" friction="0.59999999999999998 0.10000000000000001 0.10000000000000001" fromto="0 0 0 -0.64065314093938919 0 0.2181707942934481"/>
        <site name="0/1/end1" class="0/1/" size="0.0050000000000000001" pos="-0.64065314093938919 0 0.2181707942934481"/>
        <site name="0/1/attach2" class="0/1/" size="9.9999999999999995e-07 9.9999999999999995e-07 9.9999999999999995e-07" pos="-0.17539219314719784 0 0.059728816806681712"/>
        <body pos="-0.17539219314719784 0 0.059728816806681712" name="0/1/2/">
          <joint name="0/1/2/joint/" class="0/1/" type="hinge" axis="0 1 0" limited="true" stiffness="100" range="-50.025733653486171 50.025733653486171" armature="0.20000000000000001" damping="3.5"/>
          <geom name="0/1/2/geom" class="0/1/2/" type="capsule" contype="1" conaffinity="1" condim="3" size="0.064804068093999606" rgba="0.43784819573862455 0.63097653884749272 0.54126066118758809 1" friction="0.59999999999999998 0.10000000000000001 0.10000000000000001" fromto="0 0 0 0.014376304534645223 0 0.065395656636222488"/>
          <site name="0/1/2/end2" class="0/1/2/" size="0.0050000000000000001" pos="0.014376304534645223 0 0.065395656636222488"/>
        </body>
        <site name="0/1/attach3" class="0/1/" size="9.9999999999999995e-07 9.9999999999999995e-07 9.9999999999999995e-07" pos="-0.12421610382453489 0 0.042301089784245821"/>
        <body pos="-0.12421610382453489 0 0.042301089784245821" name="0/1/3/">
          <joint name="0/1/3/joint/" class="0/1/" type="hinge" axis="0 1 0" limited="true" stiffness="100" range="-68.646777345631435 68.646777345631435" armature="0.20000000000000001" damping="3.5"/>
          <geom name="0/1/3/geom" class="0/1/3/" type="capsule" contype="1" conaffinity="1" condim="3" size="0.043683153565644374" rgba="0.9380334733131126 0.54560499152363606 0.62010567252851445 1" friction="0.59999999999999998 0.10000000000000001 0.10000000000000001" fromto="0 0 0 0.74689568913777227 0 0.68713219612998944"/>
          <site name="0/1/3/end3" class="0/1/3/" size="0.0050000000000000001" pos="0.74689568913777227 0 0.68713219612998944"/>
          <site name="0/1/3/attach4" class="0/1/3/" size="9.9999999999999995e-07 9.9999999999999995e-07 9.9999999999999995e-07" pos="0.65785966447632127 0 0.60522046461238854"/>
          <body pos="0.65785966447632127 0 0.60522046461238854" name="0/1/3/4/">
            <joint name="0/1/3/4/joint/" class="0/1/3/" type="hinge" axis="0 1 0" limited="true" stiffness="100" range="-67.646370727750849 67.646370727750849" armature="0.20000000000000001" damping="3.5"/>
            <geom name="0/1/3/4/geom" class="0/1/3/4/" type="capsule" contype="1" conaffinity="1" condim="3" size="0.04507442204795524" rgba="0.18854358586987485 0.65961053719168894 0.81744905981050009 1" friction="0.59999999999999998 0.10000000000000001 0.10000000000000001" fromto="0 0 0 0.21997874213253976 0 -0.27483556727542358"/>
            <site name="0/1/3/4/end4" class="0/1/3/4/" size="0.0050000000000000001" pos="0.21997874213253976 0 -0.27483556727542358"/>
            <site name="0/1/3/4/attach5" class="0/1/3/4/" size="9.9999999999999995e-07 9.9999999999999995e-07 9.9999999999999995e-07" pos="0.11317716030886397 0 -0.14140052240760151"/>
            <body pos="0.11317716030886397 0 -0.14140052240760151" name="0/1/3/4/5/">
              <joint name="0/1/3/4/5/joint/" class="0/1/3/4/" type="hinge" axis="0 1 0" limited="true" stiffness="100" range="-59.549984406597204 59.549984406597204" armature="0.20000000000000001" damping="3.5"/>
              <geom name="0/1/3/4/5/geom" class="0/1/3/4/5/" type="capsule" contype="1" conaffinity="1" condim="3" size="0.067225811449989875" rgba="0.61085713231445682 0.51969607986511634 0.56819397713084951 1" friction="0.59999999999999998 0.10000000000000001 0.10000000000000001" fromto="0 0 0 -0.21786260381268918 0 -0.74047414360866548"/>
              <site name="0/1/3/4/5/end5" class="0/1/3/4/5/" size="0.0050000000000000001" pos="-0.21786260381268918 0 -0.74047414360866548"/>
            </body>
            <site name="0/1/3/4/attach6" class="0/1/3/4/" size="9.9999999999999995e-07 9.9999999999999995e-07 9.9999999999999995e-07" pos="0.21143085821122864 0 -0.26415606932146879"/>
            <body pos="0.21143085821122864 0 -0.26415606932146879" name="0/1/3/4/6/">
              <joint name="0/1/3/4/6/joint/" class="0/1/3/4/" type="hinge" axis="0 1 0" limited="true" stiffness="100" range="-39.56266827275433 39.56266827275433" armature="0.20000000000000001" damping="3.5"/>
              <geom name="0/1/3/4/6/geom" class="0/1/3/4/6/" type="capsule" contype="1" conaffinity="1" condim="3" size="0.05493211848208706" rgba="0.89691668862037888 0.72002827817875004 0.37593967845517351 1" friction="0.59999999999999998 0.10000000000000001 0.10000000000000001" fromto="0 0 0 0.19177201078796646 0 0.25250070618573428"/>
              <site name="0/1/3/4/6/end6" class="0/1/3/4/6/" size="0.0050000000000000001" pos="0.19177201078796646 0 0.25250070618573428"/>
              <site name="0/1/3/4/6/attach7" class="0/1/3/4/6/" size="9.9999999999999995e-07 9.9999999999999995e-07 9.9999999999999995e-07" pos="0.11020431983437136 0 0.14510286703758854"/>
              <body pos="0.11020431983437136 0 0.14510286703758854" name="0/1/3/4/6/7/">
                <joint name="0/1/3/4/6/7/joint/" class="0/1/3/4/6/" type="hinge" axis="0 1 0" limited="true" stiffness="100" range="-62.624079069995098 62.624079069995098" armature="0.20000000000000001" damping="3.5"/>
                <geom name="0/1/3/4/6/7/geom" class="0/1/3/4/6/7/" type="capsule" contype="1" conaffinity="1" condim="3" size="0.051690674458081134" rgba="0.7887712027350029 0.96524367369849551 0.43620803914109041 1" friction="0.59999999999999998 0.10000000000000001 0.10000000000000001" fromto="0 0 0 0.5538762761540017 0 -0.67518905479720703"/>
                <site name="0/1/3/4/6/7/end7" class="0/1/3/4/6/7/" size="0.0050000000000000001" pos="0.5538762761540017 0 -0.67518905479720703"/>
                <site name="0/1/3/4/6/7/attach8" class="0/1/3/4/6/7/" size="9.9999999999999995e-07 9.9999999999999995e-07 9.9999999999999995e-07" pos="0.47444300581676069 0 -0.57835790851510738"/>
                <body pos="0.47444300581676069 0 -0.57835790851510738" name="0/1/3/4/6/7/8/">
                  <joint name="0/1/3/4/6/7/8/joint/" class="0/1/3/4/6/7/" type="hinge" axis="0 1 0" limited="true" stiffness="100" range="-63.769793869754196 63.769793869754196" armature="0.20000000000000001" damping="3.5"/>
                  <geom name="0/1/3/4/6/7/8/geom" class="0/1/3/4/6/7/8/" type="capsule" contype="1" conaffinity="1" condim="3" size="0.062724700551124474" rgba="0.73746277349093281 0.83779064105116152 0.14515094676431073 1" friction="0.59999999999999998 0.10000000000000001 0.10000000000000001" fromto="0 0 0 0.26591235892566134 0 0.14337866022071422"/>
                  <site name="0/1/3/4/6/7/8/end8" class="0/1/3/4/6/7/8/" size="0.0050000000000000001" pos="0.26591235892566134 0 0.14337866022071422"/>
                </body>
              </body>
            </body>
          </body>
        </body>
        <site name="0/1/attach9" class="0/1/" size="9.9999999999999995e-07 9.9999999999999995e-07 9.9999999999999995e-07" pos="-0.33956323159044527 0 0.11563633300901326"/>
        <body pos="-0.33956323159044527 0 0.11563633300901326" name="0/1/9/">
          <joint name="0/1/9/joint/" class="0/1/" type="hinge" axis="0 1 0" limited="true" stiffness="100" range="-63.194408155924016 63.194408155924016" armature="0.20000000000000001" damping="3.5"/>
          <geom name="0/1/9/geom" class="0/1/9/" type="capsule" contype="1" conaffinity="1" condim="3" size="0.064709508559258722" rgba="0.58839223264770435 0.88377297684708467 0.66981872690735922 1" friction="0.59999999999999998 0.10000000000000001 0.10000000000000001" fromto="0 0 0 -0.0052618411013518607 0 0.37872666785110143"/>
          <site name="0/1/9/end9" class="0/1/9/" size="0.0050000000000000001" pos="-0.0052618411013518607 0 0.37872666785110143"/>
          <site name="0/1/9/attach10" class="0/1/9/" size="9.9999999999999995e-07 9.9999999999999995e-07 9.9999999999999995e-07" pos="-0.003618715925691544 0 0.26046096756604176"/>
          <body pos="-0.003618715925691544 0 0.26046096756604176" name="0/1/9/10/">
            <joint name="0/1/9/10/joint/" class="0/1/9/" type="hinge" axis="0 1 0" limited="true" stiffness="100" range="-47.857377434355541 47.857377434355541" armature="0.20000000000000001" damping="3.5"/>
            <geom name="0/1/9/10/geom" class="0/1/9/10/" type="capsule" contype="1" conaffinity="1" condim="3" size="0.060759674084156903" rgba="0.92813842186597584 0.070032807945487829 0.31465537279297695 1" friction="0.59999999999999998 0.10000000000000001 0.10000000000000001" fromto="0 0 0 -0.63733380924778249 0 0.50042541765507265"/>
            <site name="0/1/9/10/end10" class="0/1/9/10/" size="0.0050000000000000001" pos="-0.63733380924778249 0 0.50042541765507265"/>
          </body>
        </body>
      </body>
      <camera name="0/side" class="0/" mode="trackcom" pos="0.40000000000000002 -4 0.20000000000000001" quat="0.70699999999999996 0.70699999999999996 0 0"/>
    </body>
  </worldbody>
  <actuator>
    <motor name="0/1/motor" class="0/1/" ctrllimited="true" ctrlrange="-1 1" gear="89" joint="0/1/joint/"/>
    <motor name="0/1/2/motor" class="0/1/2/" ctrllimited="true" ctrlrange="-1 1" gear="75" joint="0/1/2/joint/"/>
    <motor name="0/1/3/motor" class="0/1/3/" ctrllimited="true" ctrlrange="-1 1" gear="86" joint="0/1/3/joint/"/>
    <motor name="0/1/3/4/motor" class="0/1/3/4/" ctrllimited="true" ctrlrange="-1 1" gear="72" joint="0/1/3/4/joint/"/>
    <motor name="0/1/3/4/5/motor" class="0/1/3/4/5/" ctrllimited="true" ctrlrange="-1 1" gear="50" joint="0/1/3/4/5/joint/"/>
    <motor name="0/1/3/4/6/motor" class="0/1/3/4/6/" ctrllimited="true" ctrlrange="-1 1" gear="86" joint="0/1/3/4/6/joint/"/>
    <motor name="0/1/3/4/6/7/motor" class="0/1/3/4/6/7/" ctrllimited="true" ctrlrange="-1 1" gear="86" joint="0/1/3/4/6/7/joint/"/>
    <motor name="0/1/3/4/6/7/8/motor" class="0/1/3/4/6/7/8/" ctrllimited="true" ctrlrange="-1 1" gear="85" joint="0/1/3/4/6/7/8/joint/"/>
    <motor name="0/1/9/motor" class="0/1/9/" ctrllimited="true" ctrlrange="-1 1" gear="83" joint="0/1/9/joint/"/>
    <motor name="0/1/9/10/motor" class="0/1/9/10/" ctrllimited="true" ctrlrange="-1 1" gear="80" joint="0/1/9/10/joint/"/>
  </actuator>
  <sensor>
    <subtreelinvel name="velocity" body="0/"/>
  </sensor>
</mujoco>
