<mujoco model="morphology">
  <option timestep="0.01"/>
  <default>
    <default class="/"/>
    <default class="0/"/>
    <default class="0/1/"/>
    <default class="0/1/2/"/>
    <default class="0/1/2/3/"/>
    <default class="0/1/2/3/4/"/>
    <default class="0/1/2/5/"/>
    <default class="0/1/2/5/6/"/>
    <default class="0/1/2/5/6/7/"/>
    <default class="0/1/2/5/6/7/8/"/>
    <default class="0/1/2/5/6/7/8/9/"/>
    <default class="0/1/2/5/6/7/8/9/10/"/>
  </default>
  <asset>
    <texture name="texplane" type="2d" builtin="checker" rgb1="0.10000000000000001 0.20000000000000001 0.29999999999999999" rgb2="0.20000000000000001 0.29999999999999999 0.40000000000000002" width="300" height="300"/>
    <material name="MatPlane" class="/" texture="texplane" texrepeat="20 20" specular="1" shininess="1" reflectance="0.5"/>
  </asset>
  <worldbody>
    <light name="//unnamed_light_0" class="/" directional="true" pos="0 0 1.5" dir="0 0 -1.3" cutoff="100" exponent="1" diffuse="1 1 1" specular="0.10000000000000001 0.10000000000000001 0.10000000000000001"/>
    <geom name="ground" class="/" type="plane" size="15 15 0.5" material="MatPlane" rgba="1 1 1 1"/>
    <site name="body" class="/" size="9.9999999999999995e-07 9.9999999999999995e-07 9.9999999999999995e-07" pos="0 0 2.1706288814544679"/>
    <body pos="0 0 2.1706288814544679" name="0/">
      <joint name="0/rootx/" class="/" type="slide" axis="1 0 0" limited="false" stiffness="0" armature="0" damping="0"/>
      <joint name="0/rootz/" class="/" type="slide" axis="0 0 1" limited="false" stiffness="0" armature="0" damping="0"/>
      <joint name="0/rooty/" class="/" type="hinge" axis="0 1 0" limited="false" stiffness="0" armature="0" damping="0"/>
      <geom name="0/geom" class="0/" type="capsule" contype="1" conaffinity="1" condim="3" size="0.042302939764190535" rgba="0.2312411419009579 0.80379815796272114 0.0055044817277949409 1" friction="0.59999999999999998 0.10000000000000001 0.10000000000000001" fromto="0 0 0 0.5333587453363664 0 -0.15270529305018299"/>
      <site name="0/end0" class="0/" size="0.0050000000000000001" pos="0.5333587453363664 0 -0.15270529305018299"/>
      <site name="0/attach1" class="0/" size="9.9999999999999995e-07 9.9999999999999995e-07 9.9999999999999995e-07" pos="0.33110781970767528 0 -0.094799076759827919"/>
      <body pos="0.33110781970767528 0 -0.094799076759827919" name="0/1/">
        <joint name="0/1/joint/" class="0/" type="hinge" axis="0 1 0" limited="true" range="-51.10454451608696 51.10454451608696"/>
        <geom name="0/1/geom" class="0/1/" type="capsule" contype="1" conaffinity="1" condim="3" size="0.065882488798187866" rgba="0.78354116724616019 0.07225179514251312 0.9204158899743774 1" friction="0.59999999999999998 0.10000000000000001 0.10000000000000001" fromto="0 0 0 -0.74921872616977325 0 -0.65853067485841876"/>
        <site name="0/1/end1" class="0/1/" size="0.0050000000000000001" pos="-0.74921872616977325 0 -0.65853067485841876"/>
        <site name="0/1/attach2" class="0/1/" size="9.9999999999999995e-07 9.9999999999999995e-07 9.9999999999999995e-07" pos="-0.60357958114642996 0 -0.53052020060301075"/>
        <body pos="-0.60357958114642996 0 -0.53052020060301075" name="0/1/2/">
          <joint name="0/1/2/joint/" class="0/1/" type="hinge" axis="0 1 0" limited="true" range="-63.788765269946936 63.788765269946936"/>
          <geom name="0/1/2/geom" class="0/1/2/" type="capsule" contype="1" conaffinity="1" condim="3" size="0.067356758846727718" rgba="0.45707242081565225 0.98392458418851481 0.7320796523043005 1" friction="0.59999999999999998 0.10000000000000001 0.10000000000000001" fromto="0 0 0 0.43341178101673461 0 -0.47190508183494434"/>
          <site name="0/1/2/end2" class="0/1/2/" size="0.0050000000000000001" pos="0.43341178101673461 0 -0.47190508183494434"/>
          <site name="0/1/2/attach3" class="0/1/2/" size="9.9999999999999995e-07 9.9999999999999995e-07 9.9999999999999995e-07" pos="0.07889415055760457 0 -0.085901104228976385"/>
          <body pos="0.07889415055760457 0 -0.085901104228976385" name="0/1/2/3/">
            <joint name="0/1/2/3/joint/" class="0/1/2/" type="hinge" axis="0 1 0" limited="true" range="-48.135554633565462 48.135554633565462"/>
            <geom name="0/1/2/3/geom" class="0/1/2/3/" type="capsule" contype="1" conaffinity="1" condim="3" size="0.043219157477671688" rgba="0.88676191962701023 0.58538895768818555 0.59252588427906483 1" friction="0.59999999999999998 0.10000000000000001 0.10000000000000001" fromto="0 0 0 0.54991188114901157 0 0.23121503354915074"/>
            <site name="0/1/2/3/end3" class="0/1/2/3/" size="0.0050000000000000001" pos="0.54991188114901157 0 0.23121503354915074"/>
            <site name="0/1/2/3/attach4" class="0/1/2/3/" size="9.9999999999999995e-07 9.9999999999999995e-07 9.9999999999999995e-07" pos="0.43615760111360352 0 0.18338609844814807"/>
            <body pos="0.43615760111360352 0 0.18338609844814807" name="0/1/2/3/4/">
              <joint name="0/1/2/3/4/joint/" class="0/1/2/3/" type="hinge" axis="0 1 0" limited="true" range="-58.95764488459217 58.95764488459217"/>
              <geom name="0/1/2/3/4/geom" class="0/1/2/3/4/" type="capsule" contype="1" conaffinity="1" condim="3" size="0.063988599359958834" rgba="0.59488425835738179 0.95556534725153985 0.71590361091970411 1" friction="0.59999999999999998 0.10000000000000001 0.10000000000000001" fromto="0 0 0 0.62383353961263133 0 -0.67441937271347741"/>
              <site name="0/1/2/3/4/end4" class="0/1/2/3/4/" size="0.0050000000000000001" pos="0.62383353961263133 0 -0.67441937271347741"/>
            </body>
          </body>
          <site name="0/1/2/attach5" class="0/1/2/" size="9.9999999999999995e-07 9.9999999999999995e-07 9.9999999999999995e-07" pos="0.31927180849728232 0 -0.34762781150769706"/>
          <body pos="0.31927180849728232 0 -0.34762781150769706" name="0/1/2/5/">
            <geom name="0/1/2/5/geom" class="0/1/2/5/" type="capsule" contype="1" conaffinity="1" condim="3" size="0.054160388987187079" rgba="0.44159891832526876 0.70177025446949259 0.90273150038461891 1" friction="0.59999999999999998 0.10000000000000001 0.10000000000000001" fromto="0 0 0 0.40461911384091342 0 -0.00070392377413885932"/>
            <site name="0/1/2/5/end5" class="0/1/2/5/" size="0.0050000000000000001" pos="0.40461911384091342 0 -0.00070392377413885932"/>
            <site name="0/1/2/5/attach6" class="0/1/2/5/" size="9.9999999999999995e-07 9.9999999999999995e-07 9.9999999999999995e-07" pos="0.24983636239627549 0 -0.00043464519870471625"/>
            <body pos="0.24983636239627549 0 -0.00043464519870471625" name="0/1/2/5/6/">
              <geom name="0/1/2/5/6/geom" class="0/1/2/5/6/" type="capsule" contype="1" conaffinity="1" condim="3" size="0.050423712814383445" rgba="0.98276274505617078 0.96126405373855828 0.26688371786283438 1" friction="0.59999999999999998 0.10000000000000001 0.10000000000000001" fromto="0 0 0 -0.025929626290547625 0 -0.29838272687252976"/>
              <site name="0/1/2/5/6/end6" class="0/1/2/5/6/" size="0.0050000000000000001" pos="-0.025929626290547625 0 -0.29838272687252976"/>
              <site name="0/1/2/5/6/attach7" class="0/1/2/5/6/" size="9.9999999999999995e-07 9.9999999999999995e-07 9.9999999999999995e-07" pos="-0.010417451922435504 0 -0.11987784462643464"/>
              <body pos="-0.010417451922435504 0 -0.11987784462643464" name="0/1/2/5/6/7/">
                <geom name="0/1/2/5/6/7/geom" class="0/1/2/5/6/7/" type="capsule" contype="1" conaffinity="1" condim="3" size="0.057580969779699107" rgba="0.98446408520944539 0.68770280346451795 0.81425114170245438 1" friction="0.59999999999999998 0.10000000000000001 0.10000000000000001" fromto="0 0 0 0.30344279290443232 0 -0.038881672741565065"/>
                <site name="0/1/2/5/6/7/end7" class="0/1/2/5/6/7/" size="0.0050000000000000001" pos="0.30344279290443232 0 -0.038881672741565065"/>
                <site name="0/1/2/5/6/7/attach8" class="0/1/2/5/6/7/" size="9.9999999999999995e-07 9.9999999999999995e-07 9.9999999999999995e-07" pos="0.180548235719103 0 -0.023134566315134164"/>
                <body pos="0.180548235719103 0 -0.023134566315134164" name="0/1/2/5/6/7/8/">
                  <joint name="0/1/2/5/6/7/8/joint/" class="0/1/2/5/6/7/" type="hinge" axis="0 1 0" limited="true" range="-58.868831380600156 58.868831380600156"/>
                  <geom name="0/1/2/5/6/7/8/geom" class="0/1/2/5/6/7/8/" type="capsule" contype="1" conaffinity="1" condim="3" size="0.044850716465588289" rgba="0.97607628655577516 0.54317218978015025 0.98758007726618735 1" friction="0.59999999999999998 0.10000000000000001 0.10000000000000001" fromto="0 0 0 -0.11859882642282238 0 -0.66413043830471286"/>
                  <site name="0/1/2/5/6/7/8/end8" class="0/1/2/5/6/7/8/" size="0.0050000000000000001" pos="-0.11859882642282238 0 -0.66413043830471286"/>
                  <site name="0/1/2/5/6/7/8/attach9" class="0/1/2/5/6/7/8/" size="9.9999999999999995e-07 9.9999999999999995e-07 9.9999999999999995e-07" pos="-0.083524146821182324 0 -0.46771903154940953"/>
                  <body pos="-0.083524146821182324 0 -0.46771903154940953" name="0/1/2/5/6/7/8/9/">
                    <joint name="0/1/2/5/6/7/8/9/joint/" class="0/1/2/5/6/7/8/" type="hinge" axis="0 1 0" limited="true" range="-50.004700447327586 50.004700447327586"/>
                    <geom name="0/1/2/5/6/7/8/9/geom" class="0/1/2/5/6/7/8/9/" type="capsule" contype="1" conaffinity="1" condim="3" size="0.057225024655774566" rgba="0.8562368687657238 0.97462161175072448 0.44720557573943531 1" friction="0.59999999999999998 0.10000000000000001 0.10000000000000001" fromto="0 0 0 -0.36871140455088836 0 0.34317619379288544"/>
                    <site name="0/1/2/5/6/7/8/9/end9" class="0/1/2/5/6/7/8/9/" size="0.0050000000000000001" pos="-0.36871140455088836 0 0.34317619379288544"/>
                    <site name="0/1/2/5/6/7/8/9/attach10" class="0/1/2/5/6/7/8/9/" size="9.9999999999999995e-07 9.9999999999999995e-07 9.9999999999999995e-07" pos="-0.14413481219284299 0 0.13415271573072651"/>
                    <body pos="-0.14413481219284299 0 0.13415271573072651" name="0/1/2/5/6/7/8/9/10/">
                      <geom name="0/1/2/5/6/7/8/9/10/geom" class="0/1/2/5/6/7/8/9/10/" type="capsule" contype="1" conaffinity="1" condim="3" size="0.048668192982430497" rgba="0.99989124856801004 0.76694177636802807 0.035029783746836629 1" friction="0.59999999999999998 0.10000000000000001 0.10000000000000001" fromto="0 0 0 -0.058289505495782379 0 -0.62066845827165418"/>
                      <site name="0/1/2/5/6/7/8/9/10/end10" class="0/1/2/5/6/7/8/9/10/" size="0.0050000000000000001" pos="-0.058289505495782379 0 -0.62066845827165418"/>
                    </body>
                  </body>
                </body>
              </body>
            </body>
          </body>
        </body>
      </body>
      <camera name="0/side" class="0/" mode="trackcom" pos="0.40000000000000002 -4 0.20000000000000001" quat="0.70699999999999996 0.70699999999999996 0 0"/>
    </body>
  </worldbody>
  <actuator>
    <motor name="0/1/motor" class="0/1/" ctrllimited="true" ctrlrange="-1 1" gear="52" joint="0/1/joint/"/>
    <motor name="0/1/2/motor" class="0/1/2/" ctrllimited="true" ctrlrange="-1 1" gear="65" joint="0/1/2/joint/"/>
    <motor name="0/1/2/3/motor" class="0/1/2/3/" ctrllimited="true" ctrlrange="-1 1" gear="61" joint="0/1/2/3/joint/"/>
    <motor name="0/1/2/3/4/motor" class="0/1/2/3/4/" ctrllimited="true" ctrlrange="-1 1" gear="53" joint="0/1/2/3/4/joint/"/>
    <motor name="0/1/2/5/6/7/8/motor" class="0/1/2/5/6/7/8/" ctrllimited="true" ctrlrange="-1 1" gear="85" joint="0/1/2/5/6/7/8/joint/"/>
    <motor name="0/1/2/5/6/7/8/9/motor" class="0/1/2/5/6/7/8/9/" ctrllimited="true" ctrlrange="-1 1" gear="66" joint="0/1/2/5/6/7/8/9/joint/"/>
  </actuator>
  <sensor>
    <subtreelinvel name="velocity" body="0/"/>
  </sensor>
</mujoco>
