<mujoco model="morphology">
  <option timestep="0.01"/>
  <default>
    <default class="/"/>
    <default class="0/"/>
    <default class="0/1/"/>
    <default class="0/2/"/>
    <default class="0/2/3/"/>
    <default class="0/2/4/"/>
    <default class="0/2/4/5/"/>
    <default class="0/2/4/6/"/>
    <default class="0/2/4/7/"/>
    <default class="0/2/4/7/8/"/>
    <default class="0/2/4/7/9/"/>
    <default class="0/2/4/7/9/10/"/>
  </default>
  <asset>
    <texture name="texplane" type="2d" builtin="checker" rgb1="0.10000000000000001 0.20000000000000001 0.29999999999999999" rgb2="0.20000000000000001 0.29999999999999999 0.40000000000000002" width="300" height="300"/>
    <material name="MatPlane" class="/" texture="texplane" texrepeat="20 20" specular="1" shininess="1" reflectance="0.5"/>
  </asset>
  <worldbody>
    <light name="//unnamed_light_0" class="/" directional="true" pos="0 0 1.5" dir="0 0 -1.3" cutoff="100" exponent="1" diffuse="1 1 1" specular="0.10000000000000001 0.10000000000000001 0.10000000000000001"/>
    <geom name="ground" class="/" type="plane" size="15 15 0.5" material="MatPlane" rgba="1 1 1 1"/>
    <site name="body" class="/" size="9.9999999999999995e-07 9.9999999999999995e-07 9.9999999999999995e-07" pos="0 0 1.4308166265487672"/>
    <body pos="0 0 1.4308166265487672" name="0/">
      <joint name="0/rootx/" class="/" type="slide" axis="1 0 0" limited="false" stiffness="0" armature="0" damping="0"/>
      <joint name="0/rootz/" class="/" type="slide" axis="0 0 1" limited="false" stiffness="0" armature="0" damping="0"/>
      <joint name="0/rooty/" class="/" type="hinge" axis="0 1 0" limited="false" stiffness="0" armature="0" damping="0"/>
      <geom name="0/geom" class="0/" type="capsule" contype="1" conaffinity="1" condim="3" size="0.051953347605531455" rgba="0.054278991652007114 0.73455962098082705 0.41776271063471315 1" friction="0.59999999999999998 0.10000000000000001 0.10000000000000001" fromto="0 0 0 0.00026744023786084981 0 -0.42062630452320676"/>
      <site name="0/end0" class="0/" size="0.0050000000000000001" pos="0.00026744023786084981 0 -0.42062630452320676"/>
      <site name="0/attach1" class="0/" size="9.9999999999999995e-07 9.9999999999999995e-07 9.9999999999999995e-07" pos="2.2270079152713689e-05 0 -0.035026072255885263"/>
      <body pos="2.2270079152713689e-05 0 -0.035026072255885263" name="0/1/">
        <joint name="0/1/joint/" class="0/" type="hinge" axis="0 1 0" limited="true" range="-58.404084346691334 58.404084346691334"/>
        <geom name="0/1/geom" class="0/1/" type="capsule" contype="1" conaffinity="1" condim="3" size="0.045452699818541317" rgba="0.84765530728723093 0.96874663947951212 0.70381845366015283 1" friction="0.59999999999999998 0.10000000000000001 0.10000000000000001" fromto="0 0 0 0.46282816290142814 0 -0.14736295805279664"/>
        <site name="0/1/end1" class="0/1/" size="0.0050000000000000001" pos="0.46282816290142814 0 -0.14736295805279664"/>
      </body>
      <site name="0/attach2" class="0/" size="9.9999999999999995e-07 9.9999999999999995e-07 9.9999999999999995e-07" pos="0.00015082853098638679 0 -0.237221025949271"/>
      <body pos="0.00015082853098638679 0 -0.237221025949271" name="0/2/">
        <geom name="0/2/geom" class="0/2/" type="capsule" contype="1" conaffinity="1" condim="3" size="0.049677888131568461" rgba="0.42593546131800297 0.13424662481805272 0.12217200943103523 1" friction="0.59999999999999998 0.10000000000000001 0.10000000000000001" fromto="0 0 0 -0.66716089747766438 0 -0.34010424501444264"/>
        <site name="0/2/end2" class="0/2/" size="0.0050000000000000001" pos="-0.66716089747766438 0 -0.34010424501444264"/>
        <site name="0/2/attach3" class="0/2/" size="9.9999999999999995e-07 9.9999999999999995e-07 9.9999999999999995e-07" pos="-0.63828966727301062 0 -0.3253863141697011"/>
        <body pos="-0.63828966727301062 0 -0.3253863141697011" name="0/2/3/">
          <geom name="0/2/3/geom" class="0/2/3/" type="capsule" contype="1" conaffinity="1" condim="3" size="0.057368292030582801" rgba="0.2299237827776639 0.40137647509359553 0.49000119540792064 1" friction="0.59999999999999998 0.10000000000000001 0.10000000000000001" fromto="0 0 0 0.17823792094214852 0 0.71024171643507006"/>
          <site name="0/2/3/end3" class="0/2/3/" size="0.0050000000000000001" pos="0.17823792094214852 0 0.71024171643507006"/>
        </body>
        <site name="0/2/attach4" class="0/2/" size="9.9999999999999995e-07 9.9999999999999995e-07 9.9999999999999995e-07" pos="-0.10352041055153348 0 -0.052772473937432972"/>
        <body pos="-0.10352041055153348 0 -0.052772473937432972" name="0/2/4/">
          <joint name="0/2/4/joint/" class="0/2/" type="hinge" axis="0 1 0" limited="true" range="-54.242667783525889 54.242667783525889"/>
          <geom name="0/2/4/geom" class="0/2/4/" type="capsule" contype="1" conaffinity="1" condim="3" size="0.063901087044023863" rgba="0.51701219769455931 0.10353484890556264 0.40756030071394056 1" friction="0.59999999999999998 0.10000000000000001 0.10000000000000001" fromto="0 0 0 -0.024187553518157934 0 -0.58475446428240729"/>
          <site name="0/2/4/end4" class="0/2/4/" size="0.0050000000000000001" pos="-0.024187553518157934 0 -0.58475446428240729"/>
          <site name="0/2/4/attach5" class="0/2/4/" size="9.9999999999999995e-07 9.9999999999999995e-07 9.9999999999999995e-07" pos="-0.010474777638283122 0 -0.25323656573011127"/>
          <body pos="-0.010474777638283122 0 -0.25323656573011127" name="0/2/4/5/">
            <joint name="0/2/4/5/joint/" class="0/2/4/" type="hinge" axis="0 1 0" limited="true" range="-54.14652990352841 54.14652990352841"/>
            <geom name="0/2/4/5/geom" class="0/2/4/5/" type="capsule" contype="1" conaffinity="1" condim="3" size="0.063216110718751287" rgba="0.021606457669084533 0.82352884231021006 0.91069125270816365 1" friction="0.59999999999999998 0.10000000000000001 0.10000000000000001" fromto="0 0 0 0.065591078003058856 0 -0.00031509864919188058"/>
            <site name="0/2/4/5/end5" class="0/2/4/5/" size="0.0050000000000000001" pos="0.065591078003058856 0 -0.00031509864919188058"/>
          </body>
          <site name="0/2/4/attach6" class="0/2/4/" size="9.9999999999999995e-07 9.9999999999999995e-07 9.9999999999999995e-07" pos="-0.019934435409689113 0 -0.48193175428073465"/>
          <body pos="-0.019934435409689113 0 -0.48193175428073465" name="0/2/4/6/">
            <joint name="0/2/4/6/joint/" class="0/2/4/" type="hinge" axis="0 1 0" limited="true" range="-54.638616621485163 54.638616621485163"/>
            <geom name="0/2/4/6/geom" class="0/2/4/6/" type="capsule" contype="1" conaffinity="1" condim="3" size="0.045880601472102274" rgba="0.403498792628463 0.73197277573172681 0.73178479902886528 1" friction="0.59999999999999998 0.10000000000000001 0.10000000000000001" fromto="0 0 0 -0.63969588228767993 0 -0.057945273121359775"/>
            <site name="0/2/4/6/end6" class="0/2/4/6/" size="0.0050000000000000001" pos="-0.63969588228767993 0 -0.057945273121359775"/>
          </body>
          <site name="0/2/4/attach7" class="0/2/4/" size="9.9999999999999995e-07 9.9999999999999995e-07 9.9999999999999995e-07" pos="-0.013290243808801458 0 -0.32130283010078226"/>
          <body pos="-0.013290243808801458 0 -0.32130283010078226" name="0/2/4/7/">
            <geom name="0/2/4/7/geom" class="0/2/4/7/" type="capsule" contype="1" conaffinity="1" condim="3" size="0.049998200905795091" rgba="0.7698312074957171 0.45511487160879871 0.78587866350754298 1" friction="0.59999999999999998 0.10000000000000001 0.10000000000000001" fromto="0 0 0 0.48595254598726756 0 -0.019350060962482263"/>
            <site name="0/2/4/7/end7" class="0/2/4/7/" size="0.0050000000000000001" pos="0.48595254598726756 0 -0.019350060962482263"/>
            <site name="0/2/4/7/attach8" class="0/2/4/7/" size="9.9999999999999995e-07 9.9999999999999995e-07 9.9999999999999995e-07" pos="0.056198328468311846 0 -0.0022377515887732971"/>
            <body pos="0.056198328468311846 0 -0.0022377515887732971" name="0/2/4/7/8/">
              <joint name="0/2/4/7/8/joint/" class="0/2/4/7/" type="hinge" axis="0 1 0" limited="true" range="-51.558428728280695 51.558428728280695"/>
              <geom name="0/2/4/7/8/geom" class="0/2/4/7/8/" type="capsule" contype="1" conaffinity="1" condim="3" size="0.044009997111023755" rgba="0.0063703483147991014 0.78175014694958478 0.44073341902521157 1" friction="0.59999999999999998 0.10000000000000001 0.10000000000000001" fromto="0 0 0 0.59133008352181116 0 -0.7172825978629811"/>
              <site name="0/2/4/7/8/end8" class="0/2/4/7/8/" size="0.0050000000000000001" pos="0.59133008352181116 0 -0.7172825978629811"/>
            </body>
            <site name="0/2/4/7/attach9" class="0/2/4/7/" size="9.9999999999999995e-07 9.9999999999999995e-07 9.9999999999999995e-07" pos="0.3559515164683788 0 -0.014173572296772375"/>
            <body pos="0.3559515164683788 0 -0.014173572296772375" name="0/2/4/7/9/">
              <joint name="0/2/4/7/9/joint/" class="0/2/4/7/" type="hinge" axis="0 1 0" limited="true" range="-51.254618658062547 51.254618658062547"/>
              <geom name="0/2/4/7/9/geom" class="0/2/4/7/9/" type="capsule" contype="1" conaffinity="1" condim="3" size="0.047020900847868641" rgba="0.37107306655959627 0.69207417505799951 0.44585890940624917 1" friction="0.59999999999999998 0.10000000000000001 0.10000000000000001" fromto="0 0 0 0.34139529354128317 0 -0.66903504368944788"/>
              <site name="0/2/4/7/9/end9" class="0/2/4/7/9/" size="0.0050000000000000001" pos="0.34139529354128317 0 -0.66903504368944788"/>
              <site name="0/2/4/7/9/attach10" class="0/2/4/7/9/" size="9.9999999999999995e-07 9.9999999999999995e-07 9.9999999999999995e-07" pos="0.14356358825681634 0 -0.28134269381777022"/>
              <body pos="0.14356358825681634 0 -0.28134269381777022" name="0/2/4/7/9/10/">
                <joint name="0/2/4/7/9/10/joint/" class="0/2/4/7/9/" type="hinge" axis="0 1 0" limited="true" range="-37.892542285162129 37.892542285162129"/>
                <geom name="0/2/4/7/9/10/geom" class="0/2/4/7/9/10/" type="capsule" contype="1" conaffinity="1" condim="3" size="0.04014355206229988" rgba="0.64256657657239535 0.33516227049827729 0.93806705001031387 1" friction="0.59999999999999998 0.10000000000000001 0.10000000000000001" fromto="0 0 0 0.11608726044306983 0 0.19806580687940056"/>
                <site name="0/2/4/7/9/10/end10" class="0/2/4/7/9/10/" size="0.0050000000000000001" pos="0.11608726044306983 0 0.19806580687940056"/>
              </body>
            </body>
          </body>
        </body>
      </body>
      <camera name="0/side" class="0/" mode="trackcom" pos="0.40000000000000002 -4 0.20000000000000001" quat="0.70699999999999996 0.70699999999999996 0 0"/>
    </body>
  </worldbody>
  <actuator>
    <motor name="0/1/motor" class="0/1/" ctrllimited="true" ctrlrange="-1 1" gear="62" joint="0/1/joint/"/>
    <motor name="0/2/4/motor" class="0/2/4/" ctrllimited="true" ctrlrange="-1 1" gear="74" joint="0/2/4/joint/"/>
    <motor name="0/2/4/5/motor" class="0/2/4/5/" ctrllimited="true" ctrlrange="-1 1" gear="77" joint="0/2/4/5/joint/"/>
    <motor name="0/2/4/6/motor" class="0/2/4/6/" ctrllimited="true" ctrlrange="-1 1" gear="79" joint="0/2/4/6/joint/"/>
    <motor name="0/2/4/7/8/motor" class="0/2/4/7/8/" ctrllimited="true" ctrlrange="-1 1" gear="52" joint="0/2/4/7/8/joint/"/>
    <motor name="0/2/4/7/9/motor" class="0/2/4/7/9/" ctrllimited="true" ctrlrange="-1 1" gear="87" joint="0/2/4/7/9/joint/"/>
    <motor name="0/2/4/7/9/10/motor" class="0/2/4/7/9/10/" ctrllimited="true" ctrlrange="-1 1" gear="66" joint="0/2/4/7/9/10/joint/"/>
  </actuator>
  <sensor>
    <subtreelinvel name="velocity" body="0/"/>
  </sensor>
</mujoco>
