<mujoco model="morphology">
  <option timestep="0.01"/>
  <default>
    <default class="/"/>
    <default class="0/"/>
    <default class="0/1/"/>
    <default class="0/2/"/>
    <default class="0/2/3/"/>
    <default class="0/2/3/4/"/>
    <default class="0/2/3/4/5/"/>
    <default class="0/2/3/4/5/6/"/>
    <default class="0/2/3/4/5/6/7/"/>
    <default class="0/2/3/4/5/6/7/8/"/>
    <default class="0/2/3/4/5/6/7/9/"/>
    <default class="0/2/3/4/5/6/7/9/10/"/>
  </default>
  <asset>
    <texture name="texplane" type="2d" builtin="checker" rgb1="0.10000000000000001 0.20000000000000001 0.29999999999999999" rgb2="0.20000000000000001 0.29999999999999999 0.40000000000000002" width="300" height="300"/>
    <material name="MatPlane" class="/" texture="texplane" texrepeat="20 20" specular="1" shininess="1" reflectance="0.5"/>
  </asset>
  <worldbody>
    <light name="//unnamed_light_0" class="/" directional="true" pos="0 0 1.5" dir="0 0 -1.3" cutoff="100" exponent="1" diffuse="1 1 1" specular="0.10000000000000001 0.10000000000000001 0.10000000000000001"/>
    <geom name="ground" class="/" type="plane" size="15 15 0.5" material="MatPlane" rgba="1 1 1 1"/>
    <site name="body" class="/" size="9.9999999999999995e-07 9.9999999999999995e-07 9.9999999999999995e-07" pos="0 0 0.56546873450279234"/>
    <body pos="0 0 0.56546873450279234" name="0/">
      <joint name="0/rootx/" class="/" type="slide" axis="1 0 0" limited="false" stiffness="0" armature="0" damping="0"/>
      <joint name="0/rootz/" class="/" type="slide" axis="0 0 1" limited="false" stiffness="0" armature="0" damping="0"/>
      <joint name="0/rooty/" class="/" type="hinge" axis="0 1 0" limited="false" stiffness="0" armature="0" damping="0"/>
      <geom name="0/geom" class="0/" type="capsule" contype="1" conaffinity="1" condim="3" size="0.054901762958965164" rgba="0.74776139616139159 0.54357964836530814 0.14886407272141711 1" friction="0.59999999999999998 0.10000000000000001 0.10000000000000001" fromto="0 0 0 0.024612115647364319 0 -0.11372423137645837"/>
      <site name="0/end0" class="0/" size="0.0050000000000000001" pos="0.024612115647364319 0 -0.11372423137645837"/>
      <site name="0/attach1" class="0/" size="9.9999999999999995e-07 9.9999999999999995e-07 9.9999999999999995e-07" pos="0.010739970072903381 0 -0.049625755828833037"/>
      <body pos="0.010739970072903381 0 -0.049625755828833037" name="0/1/">
        <joint name="0/1/joint/" class="0/" type="hinge" axis="0 1 0" limited="true" range="-44.358924499206509 44.358924499206509"/>
        <geom name="0/1/geom" class="0/1/" type="capsule" contype="1" conaffinity="1" condim="3" size="0.052491373580407882" rgba="0.25571056371010681 0.90015737585719002 0.13972779999026597 1" friction="0.59999999999999998 0.10000000000000001 0.10000000000000001" fromto="0 0 0 0.28017787073409517 0 0.1478626328908651"/>
        <site name="0/1/end1" class="0/1/" size="0.0050000000000000001" pos="0.28017787073409517 0 0.1478626328908651"/>
      </body>
      <site name="0/attach2" class="0/" size="9.9999999999999995e-07 9.9999999999999995e-07 9.9999999999999995e-07" pos="0.019885999746331064 0 -0.091886454163729314"/>
      <body pos="0.019885999746331064 0 -0.091886454163729314" name="0/2/">
        <joint name="0/2/joint/" class="0/" type="hinge" axis="0 1 0" limited="true" range="-63.275676252452925 63.275676252452925"/>
        <geom name="0/2/geom" class="0/2/" type="capsule" contype="1" conaffinity="1" condim="3" size="0.061159066010090718" rgba="0.15478771125491686 0.97431942126505866 0.87125956837272023 1" friction="0.59999999999999998 0.10000000000000001 0.10000000000000001" fromto="0 0 0 0.17246981578715515 0 -0.336832717195721"/>
        <site name="0/2/end2" class="0/2/" size="0.0050000000000000001" pos="0.17246981578715515 0 -0.336832717195721"/>
        <site name="0/2/attach3" class="0/2/" size="9.9999999999999995e-07 9.9999999999999995e-07 9.9999999999999995e-07" pos="0.1305200044008934 0 -0.25490493817773652"/>
        <body pos="0.1305200044008934 0 -0.25490493817773652" name="0/2/3/">
          <geom name="0/2/3/geom" class="0/2/3/" type="capsule" contype="1" conaffinity="1" condim="3" size="0.059406847095029788" rgba="0.58632887774624809 0.40440702744869095 0.16158837155290107 1" friction="0.59999999999999998 0.10000000000000001 0.10000000000000001" fromto="0 0 0 0.49725639602334581 0 0.63838242272172629"/>
          <site name="0/2/3/end3" class="0/2/3/" size="0.0050000000000000001" pos="0.49725639602334581 0 0.63838242272172629"/>
          <site name="0/2/3/attach4" class="0/2/3/" size="9.9999999999999995e-07 9.9999999999999995e-07 9.9999999999999995e-07" pos="0.34965551987471344 0 0.44889103424456417"/>
          <body pos="0.34965551987471344 0 0.44889103424456417" name="0/2/3/4/">
            <joint name="0/2/3/4/joint/" class="0/2/3/" type="hinge" axis="0 1 0" limited="true" range="-48.212469715033642 48.212469715033642"/>
            <geom name="0/2/3/4/geom" class="0/2/3/4/" type="capsule" contype="1" conaffinity="1" condim="3" size="0.050471561737960531" rgba="0.61851511924443847 0.76639442262492963 0.41269580881241563 1" friction="0.59999999999999998 0.10000000000000001 0.10000000000000001" fromto="0 0 0 0.62242985979844656 0 -0.56756838511065943"/>
            <site name="0/2/3/4/end4" class="0/2/3/4/" size="0.0050000000000000001" pos="0.62242985979844656 0 -0.56756838511065943"/>
            <site name="0/2/3/4/attach5" class="0/2/3/4/" size="9.9999999999999995e-07 9.9999999999999995e-07 9.9999999999999995e-07" pos="0.097372084762731084 0 -0.088789629921574423"/>
            <body pos="0.097372084762731084 0 -0.088789629921574423" name="0/2/3/4/5/">
              <joint name="0/2/3/4/5/joint/" class="0/2/3/4/" type="hinge" axis="0 1 0" limited="true" range="-60.834125113018452 60.834125113018452"/>
              <geom name="0/2/3/4/5/geom" class="0/2/3/4/5/" type="capsule" contype="1" conaffinity="1" condim="3" size="0.04594320902917063" rgba="0.7166000040711854 0.93008182352746005 0.81045068877705806 1" friction="0.59999999999999998 0.10000000000000001 0.10000000000000001" fromto="0 0 0 0.32222293100120947 0 0.66996652750542918"/>
              <site name="0/2/3/4/5/end5" class="0/2/3/4/5/" size="0.0050000000000000001" pos="0.32222293100120947 0 0.66996652750542918"/>
              <site name="0/2/3/4/5/attach6" class="0/2/3/4/5/" size="9.9999999999999995e-07 9.9999999999999995e-07 9.9999999999999995e-07" pos="0.21628619038105565 0 0.44970265606711307"/>
              <body pos="0.21628619038105565 0 0.44970265606711307" name="0/2/3/4/5/6/">
                <joint name="0/2/3/4/5/6/joint/" class="0/2/3/4/5/" type="hinge" axis="0 1 0" limited="true" range="-54.732952438092163 54.732952438092163"/>
                <geom name="0/2/3/4/5/6/geom" class="0/2/3/4/5/6/" type="capsule" contype="1" conaffinity="1" condim="3" size="0.068865628119952477" rgba="0.2022889582923223 0.925922714495654 0.44611270551875359 1" friction="0.59999999999999998 0.10000000000000001 0.10000000000000001" fromto="0 0 0 0.60448915319416274 0 0.12415399125374149"/>
                <site name="0/2/3/4/5/6/end6" class="0/2/3/4/5/6/" size="0.0050000000000000001" pos="0.60448915319416274 0 0.12415399125374149"/>
                <site name="0/2/3/4/5/6/attach7" class="0/2/3/4/5/6/" size="9.9999999999999995e-07 9.9999999999999995e-07 9.9999999999999995e-07" pos="0.52467555586415582 0 0.10776134531050406"/>
                <body pos="0.52467555586415582 0 0.10776134531050406" name="0/2/3/4/5/6/7/">
                  <geom name="0/2/3/4/5/6/7/geom" class="0/2/3/4/5/6/7/" type="capsule" contype="1" conaffinity="1" condim="3" size="0.060216261351489379" rgba="0.72345958815418177 0.039462573448341476 0.33746756483731111 1" friction="0.59999999999999998 0.10000000000000001 0.10000000000000001" fromto="0 0 0 0.012476499359297177 0 -0.58603371061305309"/>
                  <site name="0/2/3/4/5/6/7/end7" class="0/2/3/4/5/6/7/" size="0.0050000000000000001" pos="0.012476499359297177 0 -0.58603371061305309"/>
                  <site name="0/2/3/4/5/6/7/attach8" class="0/2/3/4/5/6/7/" size="9.9999999999999995e-07 9.9999999999999995e-07 9.9999999999999995e-07" pos="0.0066980206656119439 0 -0.31461276047006476"/>
                  <body pos="0.0066980206656119439 0 -0.31461276047006476" name="0/2/3/4/5/6/7/8/">
                    <joint name="0/2/3/4/5/6/7/8/joint/" class="0/2/3/4/5/6/7/" type="hinge" axis="0 1 0" limited="true" range="-41.751263411827587 41.751263411827587"/>
                    <geom name="0/2/3/4/5/6/7/8/geom" class="0/2/3/4/5/6/7/8/" type="capsule" contype="1" conaffinity="1" condim="3" size="0.05817114908106074" rgba="0.43035321112863001 0.63543963091171951 0.77989054183248707 1" friction="0.59999999999999998 0.10000000000000001 0.10000000000000001" fromto="0 0 0 0.55649090354339892 0 -0.18373620441273908"/>
                    <site name="0/2/3/4/5/6/7/8/end8" class="0/2/3/4/5/6/7/8/" size="0.0050000000000000001" pos="0.55649090354339892 0 -0.18373620441273908"/>
                  </body>
                  <site name="0/2/3/4/5/6/7/attach9" class="0/2/3/4/5/6/7/" size="9.9999999999999995e-07 9.9999999999999995e-07 9.9999999999999995e-07" pos="0.0058003153740999449 0 -0.27244664096237425"/>
                  <body pos="0.0058003153740999449 0 -0.27244664096237425" name="0/2/3/4/5/6/7/9/">
                    <joint name="0/2/3/4/5/6/7/9/joint/" class="0/2/3/4/5/6/7/" type="hinge" axis="0 1 0" limited="true" range="-37.287583925620609 37.287583925620609"/>
                    <geom name="0/2/3/4/5/6/7/9/geom" class="0/2/3/4/5/6/7/9/" type="capsule" contype="1" conaffinity="1" condim="3" size="0.042515888778779223" rgba="0.56091566900747181 0.91255881938323735 0.18510493902090497 1" friction="0.59999999999999998 0.10000000000000001 0.10000000000000001" fromto="0 0 0 0.54412108703126916 0 0.32639029058814395"/>
                    <site name="0/2/3/4/5/6/7/9/end9" class="0/2/3/4/5/6/7/9/" size="0.0050000000000000001" pos="0.54412108703126916 0 0.32639029058814395"/>
                    <site name="0/2/3/4/5/6/7/9/attach10" class="0/2/3/4/5/6/7/9/" size="9.9999999999999995e-07 9.9999999999999995e-07 9.9999999999999995e-07" pos="0.36622094512599035 0 0.21967713354264395"/>
                    <body pos="0.36622094512599035 0 0.21967713354264395" name="0/2/3/4/5/6/7/9/10/">
                      <joint name="0/2/3/4/5/6/7/9/10/joint/" class="0/2/3/4/5/6/7/9/" type="hinge" axis="0 1 0" limited="true" range="-54.077773725420002 54.077773725420002"/>
                      <geom name="0/2/3/4/5/6/7/9/10/geom" class="0/2/3/4/5/6/7/9/10/" type="capsule" contype="1" conaffinity="1" condim="3" size="0.049491948843572844" rgba="0.44000786488875521 0.91339329586813978 0.57407237672912126 1" friction="0.59999999999999998 0.10000000000000001 0.10000000000000001" fromto="0 0 0 0.17988998387305344 0 -0.31226290936139478"/>
                      <site name="0/2/3/4/5/6/7/9/10/end10" class="0/2/3/4/5/6/7/9/10/" size="0.0050000000000000001" pos="0.17988998387305344 0 -0.31226290936139478"/>
                    </body>
                  </body>
                </body>
              </body>
            </body>
          </body>
        </body>
      </body>
      <camera name="0/side" class="0/" mode="trackcom" pos="0.40000000000000002 -4 0.20000000000000001" quat="0.70699999999999996 0.70699999999999996 0 0"/>
    </body>
  </worldbody>
  <actuator>
    <motor name="0/1/motor" class="0/1/" ctrllimited="true" ctrlrange="-1 1" gear="61" joint="0/1/joint/"/>
    <motor name="0/2/motor" class="0/2/" ctrllimited="true" ctrlrange="-1 1" gear="55" joint="0/2/joint/"/>
    <motor name="0/2/3/4/motor" class="0/2/3/4/" ctrllimited="true" ctrlrange="-1 1" gear="82" joint="0/2/3/4/joint/"/>
    <motor name="0/2/3/4/5/motor" class="0/2/3/4/5/" ctrllimited="true" ctrlrange="-1 1" gear="56" joint="0/2/3/4/5/joint/"/>
    <motor name="0/2/3/4/5/6/motor" class="0/2/3/4/5/6/" ctrllimited="true" ctrlrange="-1 1" gear="54" joint="0/2/3/4/5/6/joint/"/>
    <motor name="0/2/3/4/5/6/7/8/motor" class="0/2/3/4/5/6/7/8/" ctrllimited="true" ctrlrange="-1 1" gear="53" joint="0/2/3/4/5/6/7/8/joint/"/>
    <motor name="0/2/3/4/5/6/7/9/motor" class="0/2/3/4/5/6/7/9/" ctrllimited="true" ctrlrange="-1 1" gear="57" joint="0/2/3/4/5/6/7/9/joint/"/>
    <motor name="0/2/3/4/5/6/7/9/10/motor" class="0/2/3/4/5/6/7/9/10/" ctrllimited="true" ctrlrange="-1 1" gear="51" joint="0/2/3/4/5/6/7/9/10/joint/"/>
  </actuator>
  <sensor>
    <subtreelinvel name="velocity" body="0/"/>
  </sensor>
</mujoco>
