<mujoco model="morphology">
  <option timestep="0.01"/>
  <default>
    <default class="/"/>
    <default class="0/"/>
    <default class="0/1/"/>
    <default class="0/1/2/"/>
    <default class="0/1/2/3/"/>
    <default class="0/1/2/3/4/"/>
    <default class="0/1/2/3/4/5/"/>
    <default class="0/1/2/3/4/5/6/"/>
    <default class="0/1/2/3/4/5/6/7/"/>
    <default class="0/1/2/3/4/5/6/7/8/"/>
    <default class="0/1/2/3/4/5/9/"/>
    <default class="0/1/2/3/10/"/>
  </default>
  <asset>
    <texture name="texplane" type="2d" builtin="checker" rgb1="0.10000000000000001 0.20000000000000001 0.29999999999999999" rgb2="0.20000000000000001 0.29999999999999999 0.40000000000000002" width="300" height="300"/>
    <material name="MatPlane" class="/" texture="texplane" texrepeat="20 20" specular="1" shininess="1" reflectance="0.5"/>
  </asset>
  <worldbody>
    <light name="//unnamed_light_0" class="/" directional="true" pos="0 0 1.5" dir="0 0 -1.3" cutoff="100" exponent="1" diffuse="1 1 1" specular="0.10000000000000001 0.10000000000000001 0.10000000000000001"/>
    <geom name="ground" class="/" type="plane" size="15 15 0.5" material="MatPlane" rgba="1 1 1 1"/>
    <site name="body" class="/" size="9.9999999999999995e-07 9.9999999999999995e-07 9.9999999999999995e-07" pos="0 0 1.0353750348091126"/>
    <body pos="0 0 1.0353750348091126" name="0/">
      <joint name="0/rootx/" class="/" type="slide" axis="1 0 0" limited="false" stiffness="0" armature="0" damping="0"/>
      <joint name="0/rootz/" class="/" type="slide" axis="0 0 1" limited="false" stiffness="0" armature="0" damping="0"/>
      <joint name="0/rooty/" class="/" type="hinge" axis="0 1 0" limited="false" stiffness="0" armature="0" damping="0"/>
      <geom name="0/geom" class="0/" type="capsule" contype="1" conaffinity="1" condim="3" size="0.059551217849871066" rgba="0.16135953483667587 0.8676126143087215 0.19401822741045771 1" friction="0.59999999999999998 0.10000000000000001 0.10000000000000001" fromto="0 0 0 -0.016797788177875028 0 -0.46560423397363654"/>
      <site name="0/end0" class="0/" size="0.0050000000000000001" pos="-0.016797788177875028 0 -0.46560423397363654"/>
      <site name="0/attach1" class="0/" size="9.9999999999999995e-07 9.9999999999999995e-07 9.9999999999999995e-07" pos="-0.0066739293346863285 0 -0.18498922135258802"/>
      <body pos="-0.0066739293346863285 0 -0.18498922135258802" name="0/1/">
        <joint name="0/1/joint/" class="0/" type="hinge" axis="0 1 0" limited="true" stiffness="100" range="-36.51882860403073 36.51882860403073" armature="0.20000000000000001" damping="3.5"/>
        <geom name="0/1/geom" class="0/1/" type="capsule" contype="1" conaffinity="1" condim="3" size="0.05822778957581165" rgba="0.81886501709298454 0.67660470909233994 0.90335501916845773 1" friction="0.59999999999999998 0.10000000000000001 0.10000000000000001" fromto="0 0 0 0.50903650205028028 0 -0.030106630259475908"/>
        <site name="0/1/end1" class="0/1/" size="0.0050000000000000001" pos="0.50903650205028028 0 -0.030106630259475908"/>
        <site name="0/1/attach2" class="0/1/" size="9.9999999999999995e-07 9.9999999999999995e-07 9.9999999999999995e-07" pos="0.16858073451380268 0 -0.0099705970444858242"/>
        <body pos="0.16858073451380268 0 -0.0099705970444858242" name="0/1/2/">
          <joint name="0/1/2/joint/" class="0/1/" type="hinge" axis="0 1 0" limited="true" stiffness="100" range="-40.67650155668791 40.67650155668791" armature="0.20000000000000001" damping="3.5"/>
          <geom name="0/1/2/geom" class="0/1/2/" type="capsule" contype="1" conaffinity="1" condim="3" size="0.069035868500266259" rgba="0.88941016214360724 0.43144659262990415 0.29044910144240399 1" friction="0.59999999999999998 0.10000000000000001 0.10000000000000001" fromto="0 0 0 0.32627797367507561 0 -0.58505001512952637"/>
          <site name="0/1/2/end2" class="0/1/2/" size="0.0050000000000000001" pos="0.32627797367507561 0 -0.58505001512952637"/>
          <site name="0/1/2/attach3" class="0/1/2/" size="9.9999999999999995e-07 9.9999999999999995e-07 9.9999999999999995e-07" pos="0.10683016467434633 0 -0.19155748932429564"/>
          <body pos="0.10683016467434633 0 -0.19155748932429564" name="0/1/2/3/">
            <joint name="0/1/2/3/joint/" class="0/1/2/" type="hinge" axis="0 1 0" limited="true" stiffness="100" range="-57.326571315074226 57.326571315074226" armature="0.20000000000000001" damping="3.5"/>
            <geom name="0/1/2/3/geom" class="0/1/2/3/" type="capsule" contype="1" conaffinity="1" condim="3" size="0.04965070980744634" rgba="0.70212542910307429 0.27634528058708252 0.95191742086166331 1" friction="0.59999999999999998 0.10000000000000001 0.10000000000000001" fromto="0 0 0 0.60588501403396045 0 0.06827003991473346"/>
            <site name="0/1/2/3/end3" class="0/1/2/3/" size="0.0050000000000000001" pos="0.60588501403396045 0 0.06827003991473346"/>
            <site name="0/1/2/3/attach4" class="0/1/2/3/" size="9.9999999999999995e-07 9.9999999999999995e-07 9.9999999999999995e-07" pos="0.44065980158718082 0 0.049652758438235828"/>
            <body pos="0.44065980158718082 0 0.049652758438235828" name="0/1/2/3/4/">
              <geom name="0/1/2/3/4/geom" class="0/1/2/3/4/" type="capsule" contype="1" conaffinity="1" condim="3" size="0.052219726113005918" rgba="0.51395941892042474 0.87192513630126689 0.78428566832744895 1" friction="0.59999999999999998 0.10000000000000001 0.10000000000000001" fromto="0 0 0 0.27805294015365778 0 -0.59851048332082701"/>
              <site name="0/1/2/3/4/end4" class="0/1/2/3/4/" size="0.0050000000000000001" pos="0.27805294015365778 0 -0.59851048332082701"/>
              <site name="0/1/2/3/4/attach5" class="0/1/2/3/4/" size="9.9999999999999995e-07 9.9999999999999995e-07 9.9999999999999995e-07" pos="0.050902973773859016 0 -0.10956893107846162"/>
              <body pos="0.050902973773859016 0 -0.10956893107846162" name="0/1/2/3/4/5/">
                <joint name="0/1/2/3/4/5/joint/" class="0/1/2/3/4/" type="hinge" axis="0 1 0" limited="true" stiffness="100" range="-63.700650926421915 63.700650926421915" armature="0.20000000000000001" damping="3.5"/>
                <geom name="0/1/2/3/4/5/geom" class="0/1/2/3/4/5/" type="capsule" contype="1" conaffinity="1" condim="3" size="0.063404337100145189" rgba="0.43419444218234149 0.74484616415222926 0.88782763438964096 1" friction="0.59999999999999998 0.10000000000000001 0.10000000000000001" fromto="0 0 0 -0.11574834471685591 0 -0.2712469196599554"/>
                <site name="0/1/2/3/4/5/end5" class="0/1/2/3/4/5/" size="0.0050000000000000001" pos="-0.11574834471685591 0 -0.2712469196599554"/>
                <site name="0/1/2/3/4/5/attach6" class="0/1/2/3/4/5/" size="9.9999999999999995e-07 9.9999999999999995e-07 9.9999999999999995e-07" pos="-0.0020202809059420772 0 -0.0047343655231106771"/>
                <body pos="-0.0020202809059420772 0 -0.0047343655231106771" name="0/1/2/3/4/5/6/">
                  <geom name="0/1/2/3/4/5/6/geom" class="0/1/2/3/4/5/6/" type="capsule" contype="1" conaffinity="1" condim="3" size="0.044930064498799611" rgba="0.73691266222809693 0.95764130442508499 0.021903303083228631 1" friction="0.59999999999999998 0.10000000000000001 0.10000000000000001" fromto="0 0 0 0.37269140278133439 0 -0.073099469978640808"/>
                  <site name="0/1/2/3/4/5/6/end6" class="0/1/2/3/4/5/6/" size="0.0050000000000000001" pos="0.37269140278133439 0 -0.073099469978640808"/>
                  <site name="0/1/2/3/4/5/6/attach7" class="0/1/2/3/4/5/6/" size="9.9999999999999995e-07 9.9999999999999995e-07 9.9999999999999995e-07" pos="0.2049096733209064 0 -0.040190861397581129"/>
                  <body pos="0.2049096733209064 0 -0.040190861397581129" name="0/1/2/3/4/5/6/7/">
                    <joint name="0/1/2/3/4/5/6/7/joint/" class="0/1/2/3/4/5/6/" type="hinge" axis="0 1 0" limited="true" stiffness="100" range="-67.96489756711469 67.96489756711469" armature="0.20000000000000001" damping="3.5"/>
                    <geom name="0/1/2/3/4/5/6/7/geom" class="0/1/2/3/4/5/6/7/" type="capsule" contype="1" conaffinity="1" condim="3" size="0.058621709144397724" rgba="0.7686988209989789 0.55037951668672824 0.33243577856713469 1" friction="0.59999999999999998 0.10000000000000001 0.10000000000000001" fromto="0 0 0 0.09180879561137878 0 0.25580961691636261"/>
                    <site name="0/1/2/3/4/5/6/7/end7" class="0/1/2/3/4/5/6/7/" size="0.0050000000000000001" pos="0.09180879561137878 0 0.25580961691636261"/>
                    <site name="0/1/2/3/4/5/6/7/attach8" class="0/1/2/3/4/5/6/7/" size="9.9999999999999995e-07 9.9999999999999995e-07 9.9999999999999995e-07" pos="0.038298572674686046 0 0.10671246844175629"/>
                    <body pos="0.038298572674686046 0 0.10671246844175629" name="0/1/2/3/4/5/6/7/8/">
                      <joint name="0/1/2/3/4/5/6/7/8/joint/" class="0/1/2/3/4/5/6/7/" type="hinge" axis="0 1 0" limited="true" stiffness="100" range="-37.200741264055836 37.200741264055836" armature="0.20000000000000001" damping="3.5"/>
                      <geom name="0/1/2/3/4/5/6/7/8/geom" class="0/1/2/3/4/5/6/7/8/" type="capsule" contype="1" conaffinity="1" condim="3" size="0.040774732580824695" rgba="0.78536789908445681 0.95950759421228093 0.7348799683947892 1" friction="0.59999999999999998 0.10000000000000001 0.10000000000000001" fromto="0 0 0 -0.12818144243528196 0 0.17921607832773501"/>
                      <site name="0/1/2/3/4/5/6/7/8/end8" class="0/1/2/3/4/5/6/7/8/" size="0.0050000000000000001" pos="-0.12818144243528196 0 0.17921607832773501"/>
                    </body>
                  </body>
                </body>
                <site name="0/1/2/3/4/5/attach9" class="0/1/2/3/4/5/" size="9.9999999999999995e-07 9.9999999999999995e-07 9.9999999999999995e-07" pos="-0.081073699004449773 0 -0.18998968127094903"/>
                <body pos="-0.081073699004449773 0 -0.18998968127094903" name="0/1/2/3/4/5/9/">
                  <geom name="0/1/2/3/4/5/9/geom" class="0/1/2/3/4/5/9/" type="capsule" contype="1" conaffinity="1" condim="3" size="0.054670177676144814" rgba="0.89377470502660183 0.96776665478654134 0.61812602054684906 1" friction="0.59999999999999998 0.10000000000000001 0.10000000000000001" fromto="0 0 0 0.1218041516244831 0 -0.053874197018690451"/>
                  <site name="0/1/2/3/4/5/9/end9" class="0/1/2/3/4/5/9/" size="0.0050000000000000001" pos="0.1218041516244831 0 -0.053874197018690451"/>
                </body>
              </body>
            </body>
            <site name="0/1/2/3/attach10" class="0/1/2/3/" size="9.9999999999999995e-07 9.9999999999999995e-07 9.9999999999999995e-07" pos="0.34610154517829622 0 0.038998103198751195"/>
            <body pos="0.34610154517829622 0 0.038998103198751195" name="0/1/2/3/10/">
              <joint name="0/1/2/3/10/joint/" class="0/1/2/3/" type="hinge" axis="0 1 0" limited="true" stiffness="100" range="-46.789700808898786 46.789700808898786" armature="0.20000000000000001" damping="3.5"/>
              <geom name="0/1/2/3/10/geom" class="0/1/2/3/10/" type="capsule" contype="1" conaffinity="1" condim="3" size="0.069106918468054612" rgba="0.98068733259189822 0.21892939594034611 0.9794512718586158 1" friction="0.59999999999999998 0.10000000000000001 0.10000000000000001" fromto="0 0 0 0.38074936516082691 0 0.49429086904425823"/>
              <site name="0/1/2/3/10/end10" class="0/1/2/3/10/" size="0.0050000000000000001" pos="0.38074936516082691 0 0.49429086904425823"/>
            </body>
          </body>
        </body>
      </body>
      <camera name="0/side" class="0/" mode="trackcom" pos="0.40000000000000002 -4 0.20000000000000001" quat="0.70699999999999996 0.70699999999999996 0 0"/>
    </body>
  </worldbody>
  <actuator>
    <motor name="0/1/motor" class="0/1/" ctrllimited="true" ctrlrange="-1 1" gear="88" joint="0/1/joint/"/>
    <motor name="0/1/2/motor" class="0/1/2/" ctrllimited="true" ctrlrange="-1 1" gear="64" joint="0/1/2/joint/"/>
    <motor name="0/1/2/3/motor" class="0/1/2/3/" ctrllimited="true" ctrlrange="-1 1" gear="54" joint="0/1/2/3/joint/"/>
    <motor name="0/1/2/3/4/5/motor" class="0/1/2/3/4/5/" ctrllimited="true" ctrlrange="-1 1" gear="54" joint="0/1/2/3/4/5/joint/"/>
    <motor name="0/1/2/3/4/5/6/7/motor" class="0/1/2/3/4/5/6/7/" ctrllimited="true" ctrlrange="-1 1" gear="70" joint="0/1/2/3/4/5/6/7/joint/"/>
    <motor name="0/1/2/3/4/5/6/7/8/motor" class="0/1/2/3/4/5/6/7/8/" ctrllimited="true" ctrlrange="-1 1" gear="59" joint="0/1/2/3/4/5/6/7/8/joint/"/>
    <motor name="0/1/2/3/10/motor" class="0/1/2/3/10/" ctrllimited="true" ctrlrange="-1 1" gear="76" joint="0/1/2/3/10/joint/"/>
  </actuator>
  <sensor>
    <subtreelinvel name="velocity" body="0/"/>
  </sensor>
</mujoco>
