<mujoco model="morphology">
  <option timestep="0.01"/>
  <default>
    <default class="/"/>
    <default class="0/"/>
    <default class="0/1/"/>
    <default class="0/1/2/"/>
    <default class="0/1/3/"/>
    <default class="0/1/3/4/"/>
    <default class="0/1/3/5/"/>
    <default class="0/1/3/5/6/"/>
    <default class="0/1/3/5/6/7/"/>
    <default class="0/1/3/5/6/7/8/"/>
    <default class="0/1/3/5/6/7/9/"/>
    <default class="0/1/3/5/6/10/"/>
  </default>
  <asset>
    <texture name="texplane" type="2d" builtin="checker" rgb1="0.10000000000000001 0.20000000000000001 0.29999999999999999" rgb2="0.20000000000000001 0.29999999999999999 0.40000000000000002" width="300" height="300"/>
    <material name="MatPlane" class="/" texture="texplane" texrepeat="20 20" specular="1" shininess="1" reflectance="0.5"/>
  </asset>
  <worldbody>
    <light name="//unnamed_light_0" class="/" directional="true" pos="0 0 1.5" dir="0 0 -1.3" cutoff="100" exponent="1" diffuse="1 1 1" specular="0.10000000000000001 0.10000000000000001 0.10000000000000001"/>
    <geom name="ground" class="/" type="plane" size="15 15 0.5" material="MatPlane" rgba="1 1 1 1"/>
    <site name="body" class="/" size="9.9999999999999995e-07 9.9999999999999995e-07 9.9999999999999995e-07" pos="0 0 0.79269996881484983"/>
    <body pos="0 0 0.79269996881484983" name="0/">
      <joint name="0/rootx/" class="/" type="slide" axis="1 0 0" limited="false" stiffness="0" armature="0" damping="0"/>
      <joint name="0/rootz/" class="/" type="slide" axis="0 0 1" limited="false" stiffness="0" armature="0" damping="0"/>
      <joint name="0/rooty/" class="/" type="hinge" axis="0 1 0" limited="false" stiffness="0" armature="0" damping="0"/>
      <geom name="0/geom" class="0/" type="capsule" contype="1" conaffinity="1" condim="3" size="0.065852721539210166" rgba="0.17300227570386528 0.60816767963989393 0.16522307025105076 1" friction="0.59999999999999998 0.10000000000000001 0.10000000000000001" fromto="0 0 0 -0.4293877890555764 0 -0.69269994887305653"/>
      <site name="0/end0" class="0/" size="0.0050000000000000001" pos="-0.4293877890555764 0 -0.69269994887305653"/>
      <site name="0/attach1" class="0/" size="9.9999999999999995e-07 9.9999999999999995e-07 9.9999999999999995e-07" pos="-0.14761902886857875 0 -0.23814299417983595"/>
      <body pos="-0.14761902886857875 0 -0.23814299417983595" name="0/1/">
        <joint name="0/1/joint/" class="0/" type="hinge" axis="0 1 0" limited="true" range="-41.498053074616074 41.498053074616074"/>
        <geom name="0/1/geom" class="0/1/" type="capsule" contype="1" conaffinity="1" condim="3" size="0.051736418225767723" rgba="0.94114157662543729 0.61083763915570977 0.53831968944455899 1" friction="0.59999999999999998 0.10000000000000001 0.10000000000000001" fromto="0 0 0 -0.72949560567942218 0 -0.068115769890737532"/>
        <site name="0/1/end1" class="0/1/" size="0.0050000000000000001" pos="-0.72949560567942218 0 -0.068115769890737532"/>
        <site name="0/1/attach2" class="0/1/" size="9.9999999999999995e-07 9.9999999999999995e-07 9.9999999999999995e-07" pos="-0.67277313625822133 0 -0.062819377911610491"/>
        <body pos="-0.67277313625822133 0 -0.062819377911610491" name="0/1/2/">
          <joint name="0/1/2/joint/" class="0/1/" type="hinge" axis="0 1 0" limited="true" range="-49.757125480166188 49.757125480166188"/>
          <geom name="0/1/2/geom" class="0/1/2/" type="capsule" contype="1" conaffinity="1" condim="3" size="0.069908446744417721" rgba="0.27206451437775203 0.16352018142326885 0.83176045424583012 1" friction="0.59999999999999998 0.10000000000000001 0.10000000000000001" fromto="0 0 0 0.014382623050227972 0 0.47385529837588969"/>
          <site name="0/1/2/end2" class="0/1/2/" size="0.0050000000000000001" pos="0.014382623050227972 0 0.47385529837588969"/>
        </body>
        <site name="0/1/attach3" class="0/1/" size="9.9999999999999995e-07 9.9999999999999995e-07 9.9999999999999995e-07" pos="-0.39166404797909826 0 -0.036571156781365098"/>
        <body pos="-0.39166404797909826 0 -0.036571156781365098" name="0/1/3/">
          <geom name="0/1/3/geom" class="0/1/3/" type="capsule" contype="1" conaffinity="1" condim="3" size="0.047709617984838651" rgba="0.66927803455902402 0.81276227240535026 0.26179715327679176 1" friction="0.59999999999999998 0.10000000000000001 0.10000000000000001" fromto="0 0 0 0.047120222301614278 0 0.51340794958067648"/>
          <site name="0/1/3/end3" class="0/1/3/" size="0.0050000000000000001" pos="0.047120222301614278 0 0.51340794958067648"/>
          <site name="0/1/3/attach4" class="0/1/3/" size="9.9999999999999995e-07 9.9999999999999995e-07 9.9999999999999995e-07" pos="0.032254533877612582 0 0.35143582296338671"/>
          <body pos="0.032254533877612582 0 0.35143582296338671" name="0/1/3/4/">
            <joint name="0/1/3/4/joint/" class="0/1/3/" type="hinge" axis="0 1 0" limited="true" range="-37.404425718944225 37.404425718944225"/>
            <geom name="0/1/3/4/geom" class="0/1/3/4/" type="capsule" contype="1" conaffinity="1" condim="3" size="0.044015698402650953" rgba="0.30859447602746393 0.031408310848873522 0.084392438354868204 1" friction="0.59999999999999998 0.10000000000000001 0.10000000000000001" fromto="0 0 0 -0.51051107350996638 0 0.4368541068939702"/>
            <site name="0/1/3/4/end4" class="0/1/3/4/" size="0.0050000000000000001" pos="-0.51051107350996638 0 0.4368541068939702"/>
          </body>
          <site name="0/1/3/attach5" class="0/1/3/" size="9.9999999999999995e-07 9.9999999999999995e-07 9.9999999999999995e-07" pos="0.030256776626793578 0 0.32966885320382816"/>
          <body pos="0.030256776626793578 0 0.32966885320382816" name="0/1/3/5/">
            <geom name="0/1/3/5/geom" class="0/1/3/5/" type="capsule" contype="1" conaffinity="1" condim="3" size="0.047104000343540245" rgba="0.63949439937223718 0.20457091598495636 0.30308897109690114 1" friction="0.59999999999999998 0.10000000000000001 0.10000000000000001" fromto="0 0 0 0.61859365038168046 0 0.26181364317791367"/>
            <site name="0/1/3/5/end5" class="0/1/3/5/" size="0.0050000000000000001" pos="0.61859365038168046 0 0.26181364317791367"/>
            <site name="0/1/3/5/attach6" class="0/1/3/5/" size="9.9999999999999995e-07 9.9999999999999995e-07 9.9999999999999995e-07" pos="0.56645285669613232 0 0.23974556804558997"/>
            <body pos="0.56645285669613232 0 0.23974556804558997" name="0/1/3/5/6/">
              <joint name="0/1/3/5/6/joint/" class="0/1/3/5/" type="hinge" axis="0 1 0" limited="true" range="-52.934655130659515 52.934655130659515"/>
              <geom name="0/1/3/5/6/geom" class="0/1/3/5/6/" type="capsule" contype="1" conaffinity="1" condim="3" size="0.066417448139902441" rgba="0.46957180316665859 0.19065002424617672 0.023784798071583402 1" friction="0.59999999999999998 0.10000000000000001 0.10000000000000001" fromto="0 0 0 0.15941426008737569 0 -0.39542843030991021"/>
              <site name="0/1/3/5/6/end6" class="0/1/3/5/6/" size="0.0050000000000000001" pos="0.15941426008737569 0 -0.39542843030991021"/>
              <site name="0/1/3/5/6/attach7" class="0/1/3/5/6/" size="9.9999999999999995e-07 9.9999999999999995e-07 9.9999999999999995e-07" pos="0.0067231340623121185 0 -0.016676791320713875"/>
              <body pos="0.0067231340623121185 0 -0.016676791320713875" name="0/1/3/5/6/7/">
                <joint name="0/1/3/5/6/7/joint/" class="0/1/3/5/6/" type="hinge" axis="0 1 0" limited="true" range="-32.943091913993953 32.943091913993953"/>
                <geom name="0/1/3/5/6/7/geom" class="0/1/3/5/6/7/" type="capsule" contype="1" conaffinity="1" condim="3" size="0.048012710143957485" rgba="0.85866444347014237 0.13339178021362574 0.37485505329540092 1" friction="0.59999999999999998 0.10000000000000001 0.10000000000000001" fromto="0 0 0 -0.12092520287857678 0 0.26525181170224821"/>
                <site name="0/1/3/5/6/7/end7" class="0/1/3/5/6/7/" size="0.0050000000000000001" pos="-0.12092520287857678 0 0.26525181170224821"/>
                <site name="0/1/3/5/6/7/attach8" class="0/1/3/5/6/7/" size="9.9999999999999995e-07 9.9999999999999995e-07 9.9999999999999995e-07" pos="-0.11450690573384262 0 0.25117315063608836"/>
                <body pos="-0.11450690573384262 0 0.25117315063608836" name="0/1/3/5/6/7/8/">
                  <joint name="0/1/3/5/6/7/8/joint/" class="0/1/3/5/6/7/" type="hinge" axis="0 1 0" limited="true" range="-45.557056542766858 45.557056542766858"/>
                  <geom name="0/1/3/5/6/7/8/geom" class="0/1/3/5/6/7/8/" type="capsule" contype="1" conaffinity="1" condim="3" size="0.046620164158691767" rgba="0.733091856180351 0.13185461198835347 0.59348829689186655 1" friction="0.59999999999999998 0.10000000000000001 0.10000000000000001" fromto="0 0 0 -0.4177617233191499 0 0.30799598027856812"/>
                  <site name="0/1/3/5/6/7/8/end8" class="0/1/3/5/6/7/8/" size="0.0050000000000000001" pos="-0.4177617233191499 0 0.30799598027856812"/>
                </body>
                <site name="0/1/3/5/6/7/attach9" class="0/1/3/5/6/7/" size="9.9999999999999995e-07 9.9999999999999995e-07 9.9999999999999995e-07" pos="-0.043104776677082304 0 0.094551175722215691"/>
                <body pos="-0.043104776677082304 0 0.094551175722215691" name="0/1/3/5/6/7/9/">
                  <geom name="0/1/3/5/6/7/9/geom" class="0/1/3/5/6/7/9/" type="capsule" contype="1" conaffinity="1" condim="3" size="0.068507893624874777" rgba="0.57990164860599347 0.33670791627494301 0.4288718225785112 1" friction="0.59999999999999998 0.10000000000000001 0.10000000000000001" fromto="0 0 0 -0.29216753064530138 0 -0.13413519155536935"/>
                  <site name="0/1/3/5/6/7/9/end9" class="0/1/3/5/6/7/9/" size="0.0050000000000000001" pos="-0.29216753064530138 0 -0.13413519155536935"/>
                </body>
              </body>
              <site name="0/1/3/5/6/attach10" class="0/1/3/5/6/" size="9.9999999999999995e-07 9.9999999999999995e-07 9.9999999999999995e-07" pos="0.048039177503240861 0 -0.1191615890766225"/>
              <body pos="0.048039177503240861 0 -0.1191615890766225" name="0/1/3/5/6/10/">
                <joint name="0/1/3/5/6/10/joint/" class="0/1/3/5/6/" type="hinge" axis="0 1 0" limited="true" range="-44.958525030704379 44.958525030704379"/>
                <geom name="0/1/3/5/6/10/geom" class="0/1/3/5/6/10/" type="capsule" contype="1" conaffinity="1" condim="3" size="0.065648441671625979" rgba="0.91412171997053338 0.38425084662483755 0.040393840551264937 1" friction="0.59999999999999998 0.10000000000000001 0.10000000000000001" fromto="0 0 0 0.3949867561143694 0 0.1833801049594741"/>
                <site name="0/1/3/5/6/10/end10" class="0/1/3/5/6/10/" size="0.0050000000000000001" pos="0.3949867561143694 0 0.1833801049594741"/>
              </body>
            </body>
          </body>
        </body>
      </body>
      <camera name="0/side" class="0/" mode="trackcom" pos="0.40000000000000002 -4 0.20000000000000001" quat="0.70699999999999996 0.70699999999999996 0 0"/>
    </body>
  </worldbody>
  <actuator>
    <motor name="0/1/motor" class="0/1/" ctrllimited="true" ctrlrange="-1 1" gear="76" joint="0/1/joint/"/>
    <motor name="0/1/2/motor" class="0/1/2/" ctrllimited="true" ctrlrange="-1 1" gear="87" joint="0/1/2/joint/"/>
    <motor name="0/1/3/4/motor" class="0/1/3/4/" ctrllimited="true" ctrlrange="-1 1" gear="60" joint="0/1/3/4/joint/"/>
    <motor name="0/1/3/5/6/motor" class="0/1/3/5/6/" ctrllimited="true" ctrlrange="-1 1" gear="67" joint="0/1/3/5/6/joint/"/>
    <motor name="0/1/3/5/6/7/motor" class="0/1/3/5/6/7/" ctrllimited="true" ctrlrange="-1 1" gear="73" joint="0/1/3/5/6/7/joint/"/>
    <motor name="0/1/3/5/6/7/8/motor" class="0/1/3/5/6/7/8/" ctrllimited="true" ctrlrange="-1 1" gear="57" joint="0/1/3/5/6/7/8/joint/"/>
    <motor name="0/1/3/5/6/10/motor" class="0/1/3/5/6/10/" ctrllimited="true" ctrlrange="-1 1" gear="86" joint="0/1/3/5/6/10/joint/"/>
  </actuator>
  <sensor>
    <subtreelinvel name="velocity" body="0/"/>
  </sensor>
</mujoco>
