<mujoco model="morphology">
  <option timestep="0.01"/>
  <default>
    <default class="/"/>
    <default class="0/"/>
    <default class="0/1/"/>
    <default class="0/2/"/>
    <default class="0/2/3/"/>
    <default class="0/2/3/4/"/>
    <default class="0/2/3/5/"/>
    <default class="0/2/3/5/6/"/>
    <default class="0/2/3/5/6/7/"/>
    <default class="0/2/3/5/6/8/"/>
    <default class="0/2/3/5/9/"/>
    <default class="0/2/3/5/9/10/"/>
  </default>
  <asset>
    <texture name="texplane" type="2d" builtin="checker" rgb1="0.10000000000000001 0.20000000000000001 0.29999999999999999" rgb2="0.20000000000000001 0.29999999999999999 0.40000000000000002" width="300" height="300"/>
    <material name="MatPlane" class="/" texture="texplane" texrepeat="20 20" specular="1" shininess="1" reflectance="0.5"/>
  </asset>
  <worldbody>
    <light name="//unnamed_light_0" class="/" directional="true" pos="0 0 1.5" dir="0 0 -1.3" cutoff="100" exponent="1" diffuse="1 1 1" specular="0.10000000000000001 0.10000000000000001 0.10000000000000001"/>
    <geom name="ground" class="/" type="plane" size="15 15 0.5" material="MatPlane" rgba="1 1 1 1"/>
    <site name="body" class="/" size="9.9999999999999995e-07 9.9999999999999995e-07 9.9999999999999995e-07" pos="0 0 0.3039423882961273"/>
    <body pos="0 0 0.3039423882961273" name="0/">
      <joint name="0/rootx/" class="/" type="slide" axis="1 0 0" limited="false" stiffness="0" armature="0" damping="0"/>
      <joint name="0/rootz/" class="/" type="slide" axis="0 0 1" limited="false" stiffness="0" armature="0" damping="0"/>
      <joint name="0/rooty/" class="/" type="hinge" axis="0 1 0" limited="false" stiffness="0" armature="0" damping="0"/>
      <geom name="0/geom" class="0/" type="capsule" contype="1" conaffinity="1" condim="3" size="0.059563986115441017" rgba="0.97183191933155577 0.17744371731488262 0.67361703306244947 1" friction="0.59999999999999998 0.10000000000000001 0.10000000000000001" fromto="0 0 0 0.058673310678187929 0 0.1803922688617432"/>
      <site name="0/end0" class="0/" size="0.0050000000000000001" pos="0.058673310678187929 0 0.1803922688617432"/>
      <site name="0/attach1" class="0/" size="9.9999999999999995e-07 9.9999999999999995e-07 9.9999999999999995e-07" pos="0.051631045535995949 0 0.15874068363087529"/>
      <body pos="0.051631045535995949 0 0.15874068363087529" name="0/1/">
        <joint name="0/1/joint/" class="0/" type="hinge" axis="0 1 0" limited="true" range="-65.282971110854135 65.282971110854135"/>
        <geom name="0/1/geom" class="0/1/" type="capsule" contype="1" conaffinity="1" condim="3" size="0.052383691702455951" rgba="0.37358813005083469 0.86829638196184855 0.88920240811129614 1" friction="0.59999999999999998 0.10000000000000001 0.10000000000000001" fromto="0 0 0 -0.4227148017912386 0 0.58946965975191978"/>
        <site name="0/1/end1" class="0/1/" size="0.0050000000000000001" pos="-0.4227148017912386 0 0.58946965975191978"/>
      </body>
      <site name="0/attach2" class="0/" size="9.9999999999999995e-07 9.9999999999999995e-07 9.9999999999999995e-07" pos="0.046964733097863497 0 0.14439401257715859"/>
      <body pos="0.046964733097863497 0 0.14439401257715859" name="0/2/">
        <joint name="0/2/joint/" class="0/" type="hinge" axis="0 1 0" limited="true" range="-60.454729468232131 60.454729468232131"/>
        <geom name="0/2/geom" class="0/2/" type="capsule" contype="1" conaffinity="1" condim="3" size="0.069139640152862142" rgba="0.75395611271517005 0.13880472274830846 0.31552161659341416 1" friction="0.59999999999999998 0.10000000000000001 0.10000000000000001" fromto="0 0 0 0.18647887226864879 0 0.020961410456112328"/>
        <site name="0/2/end2" class="0/2/" size="0.0050000000000000001" pos="0.18647887226864879 0 0.020961410456112328"/>
        <site name="0/2/attach3" class="0/2/" size="9.9999999999999995e-07 9.9999999999999995e-07 9.9999999999999995e-07" pos="0.17068030861070102 0 0.019185551489236015"/>
        <body pos="0.17068030861070102 0 0.019185551489236015" name="0/2/3/">
          <joint name="0/2/3/joint/" class="0/2/" type="hinge" axis="0 1 0" limited="true" range="-58.969702047761302 58.969702047761302"/>
          <geom name="0/2/3/geom" class="0/2/3/" type="capsule" contype="1" conaffinity="1" condim="3" size="0.05918068432218733" rgba="0.25700859774230644 0.89556604354741032 0.76899890433248497 1" friction="0.59999999999999998 0.10000000000000001 0.10000000000000001" fromto="0 0 0 0.44938429571748295 0 0.32228064410483404"/>
          <site name="0/2/3/end3" class="0/2/3/" size="0.0050000000000000001" pos="0.44938429571748295 0 0.32228064410483404"/>
          <site name="0/2/3/attach4" class="0/2/3/" size="9.9999999999999995e-07 9.9999999999999995e-07 9.9999999999999995e-07" pos="0.25863088010549923 0 0.18547983857050851"/>
          <body pos="0.25863088010549923 0 0.18547983857050851" name="0/2/3/4/">
            <geom name="0/2/3/4/geom" class="0/2/3/4/" type="capsule" contype="1" conaffinity="1" condim="3" size="0.062937701010738326" rgba="0.45947224903812256 0.47393412984186933 0.45261253470204443 1" friction="0.59999999999999998 0.10000000000000001 0.10000000000000001" fromto="0 0 0 -0.53172534467063792 0 0.14767234627338421"/>
            <site name="0/2/3/4/end4" class="0/2/3/4/" size="0.0050000000000000001" pos="-0.53172534467063792 0 0.14767234627338421"/>
          </body>
          <site name="0/2/3/attach5" class="0/2/3/" size="9.9999999999999995e-07 9.9999999999999995e-07 9.9999999999999995e-07" pos="0.43521745095529785 0 0.31212074332859385"/>
          <body pos="0.43521745095529785 0 0.31212074332859385" name="0/2/3/5/">
            <joint name="0/2/3/5/joint/" class="0/2/3/" type="hinge" axis="0 1 0" limited="true" range="-51.058865902671911 51.058865902671911"/>
            <geom name="0/2/3/5/geom" class="0/2/3/5/" type="capsule" contype="1" conaffinity="1" condim="3" size="0.063102574524929816" rgba="0.37724948522463198 0.37832074357223511 0.99180535261086367 1" friction="0.59999999999999998 0.10000000000000001 0.10000000000000001" fromto="0 0 0 0.22557702693515769 0 -0.012450356974223808"/>
            <site name="0/2/3/5/end5" class="0/2/3/5/" size="0.0050000000000000001" pos="0.22557702693515769 0 -0.012450356974223808"/>
            <site name="0/2/3/5/attach6" class="0/2/3/5/" size="9.9999999999999995e-07 9.9999999999999995e-07 9.9999999999999995e-07" pos="0.01735745677903075 0 -0.00095801658528691335"/>
            <body pos="0.01735745677903075 0 -0.00095801658528691335" name="0/2/3/5/6/">
              <joint name="0/2/3/5/6/joint/" class="0/2/3/5/" type="hinge" axis="0 1 0" limited="true" range="-38.995124040966097 38.995124040966097"/>
              <geom name="0/2/3/5/6/geom" class="0/2/3/5/6/" type="capsule" contype="1" conaffinity="1" condim="3" size="0.06291341836083697" rgba="0.74696653672459756 0.37742747272946375 0.12106015931066516 1" friction="0.59999999999999998 0.10000000000000001 0.10000000000000001" fromto="0 0 0 0.25064097043714306 0 -0.67868468601997889"/>
              <site name="0/2/3/5/6/end6" class="0/2/3/5/6/" size="0.0050000000000000001" pos="0.25064097043714306 0 -0.67868468601997889"/>
              <site name="0/2/3/5/6/attach7" class="0/2/3/5/6/" size="9.9999999999999995e-07 9.9999999999999995e-07 9.9999999999999995e-07" pos="0.16470855696734621 0 -0.44599721695628047"/>
              <body pos="0.16470855696734621 0 -0.44599721695628047" name="0/2/3/5/6/7/">
                <geom name="0/2/3/5/6/7/geom" class="0/2/3/5/6/7/" type="capsule" contype="1" conaffinity="1" condim="3" size="0.046597908826148435" rgba="0.7198772436440376 0.78854164366471169 0.92806984583774987 1" friction="0.59999999999999998 0.10000000000000001 0.10000000000000001" fromto="0 0 0 0.7387507141614531 0 -0.22110600693264604"/>
                <site name="0/2/3/5/6/7/end7" class="0/2/3/5/6/7/" size="0.0050000000000000001" pos="0.7387507141614531 0 -0.22110600693264604"/>
              </body>
              <site name="0/2/3/5/6/attach8" class="0/2/3/5/6/" size="9.9999999999999995e-07 9.9999999999999995e-07 9.9999999999999995e-07" pos="0.12290068630255255 0 -0.33279002051983342"/>
              <body pos="0.12290068630255255 0 -0.33279002051983342" name="0/2/3/5/6/8/">
                <joint name="0/2/3/5/6/8/joint/" class="0/2/3/5/6/" type="hinge" axis="0 1 0" limited="true" range="-45.462281480903926 45.462281480903926"/>
                <geom name="0/2/3/5/6/8/geom" class="0/2/3/5/6/8/" type="capsule" contype="1" conaffinity="1" condim="3" size="0.054386455780126908" rgba="0.37500222438184716 0.20071902352717441 0.91262990488395279 1" friction="0.59999999999999998 0.10000000000000001 0.10000000000000001" fromto="0 0 0 0.62590388015996479 0 -0.22951299487020083"/>
                <site name="0/2/3/5/6/8/end8" class="0/2/3/5/6/8/" size="0.0050000000000000001" pos="0.62590388015996479 0 -0.22951299487020083"/>
              </body>
            </body>
            <site name="0/2/3/5/attach9" class="0/2/3/5/" size="9.9999999999999995e-07 9.9999999999999995e-07 9.9999999999999995e-07" pos="0.0084847121445184477 0 -0.00046829988167701296"/>
            <body pos="0.0084847121445184477 0 -0.00046829988167701296" name="0/2/3/5/9/">
              <joint name="0/2/3/5/9/joint/" class="0/2/3/5/" type="hinge" axis="0 1 0" limited="true" range="-37.609476120866795 37.609476120866795"/>
              <geom name="0/2/3/5/9/geom" class="0/2/3/5/9/" type="capsule" contype="1" conaffinity="1" condim="3" size="0.062958820122843928" rgba="0.43536412082422937 0.60616481841135794 0.46391060549852992 1" friction="0.59999999999999998 0.10000000000000001 0.10000000000000001" fromto="0 0 0 -0.59791680639606493 0 0.47646700523762719"/>
              <site name="0/2/3/5/9/end9" class="0/2/3/5/9/" size="0.0050000000000000001" pos="-0.59791680639606493 0 0.47646700523762719"/>
              <site name="0/2/3/5/9/attach10" class="0/2/3/5/9/" size="9.9999999999999995e-07 9.9999999999999995e-07 9.9999999999999995e-07" pos="-0.54320714461037078 0 0.43287005591333294"/>
              <body pos="-0.54320714461037078 0 0.43287005591333294" name="0/2/3/5/9/10/">
                <joint name="0/2/3/5/9/10/joint/" class="0/2/3/5/9/" type="hinge" axis="0 1 0" limited="true" range="-44.087851997855054 44.087851997855054"/>
                <geom name="0/2/3/5/9/10/geom" class="0/2/3/5/9/10/" type="capsule" contype="1" conaffinity="1" condim="3" size="0.052062634702999606" rgba="0.25415880902787946 0.10055141391331979 0.76327215705705342 1" friction="0.59999999999999998 0.10000000000000001 0.10000000000000001" fromto="0 0 0 0.28238797190105736 0 0.31330837236158948"/>
                <site name="0/2/3/5/9/10/end10" class="0/2/3/5/9/10/" size="0.0050000000000000001" pos="0.28238797190105736 0 0.31330837236158948"/>
              </body>
            </body>
          </body>
        </body>
      </body>
      <camera name="0/side" class="0/" mode="trackcom" pos="0.40000000000000002 -4 0.20000000000000001" quat="0.70699999999999996 0.70699999999999996 0 0"/>
    </body>
  </worldbody>
  <actuator>
    <motor name="0/1/motor" class="0/1/" ctrllimited="true" ctrlrange="-1 1" gear="68" joint="0/1/joint/"/>
    <motor name="0/2/motor" class="0/2/" ctrllimited="true" ctrlrange="-1 1" gear="55" joint="0/2/joint/"/>
    <motor name="0/2/3/motor" class="0/2/3/" ctrllimited="true" ctrlrange="-1 1" gear="58" joint="0/2/3/joint/"/>
    <motor name="0/2/3/5/motor" class="0/2/3/5/" ctrllimited="true" ctrlrange="-1 1" gear="62" joint="0/2/3/5/joint/"/>
    <motor name="0/2/3/5/6/motor" class="0/2/3/5/6/" ctrllimited="true" ctrlrange="-1 1" gear="85" joint="0/2/3/5/6/joint/"/>
    <motor name="0/2/3/5/6/8/motor" class="0/2/3/5/6/8/" ctrllimited="true" ctrlrange="-1 1" gear="79" joint="0/2/3/5/6/8/joint/"/>
    <motor name="0/2/3/5/9/motor" class="0/2/3/5/9/" ctrllimited="true" ctrlrange="-1 1" gear="83" joint="0/2/3/5/9/joint/"/>
    <motor name="0/2/3/5/9/10/motor" class="0/2/3/5/9/10/" ctrllimited="true" ctrlrange="-1 1" gear="50" joint="0/2/3/5/9/10/joint/"/>
  </actuator>
  <sensor>
    <subtreelinvel name="velocity" body="0/"/>
  </sensor>
</mujoco>
