<mujoco model="morphology">
  <option timestep="0.01"/>
  <default>
    <default class="/"/>
    <default class="0/"/>
    <default class="0/1/"/>
    <default class="0/1/2/"/>
    <default class="0/1/2/3/"/>
    <default class="0/1/2/3/4/"/>
    <default class="0/1/2/3/5/"/>
    <default class="0/1/2/3/5/6/"/>
    <default class="0/1/2/3/5/7/"/>
    <default class="0/1/8/"/>
    <default class="0/9/"/>
    <default class="0/9/10/"/>
  </default>
  <asset>
    <texture name="texplane" type="2d" builtin="checker" rgb1="0.10000000000000001 0.20000000000000001 0.29999999999999999" rgb2="0.20000000000000001 0.29999999999999999 0.40000000000000002" width="300" height="300"/>
    <material name="MatPlane" class="/" texture="texplane" texrepeat="20 20" specular="1" shininess="1" reflectance="0.5"/>
  </asset>
  <worldbody>
    <light name="//unnamed_light_0" class="/" directional="true" pos="0 0 1.5" dir="0 0 -1.3" cutoff="100" exponent="1" diffuse="1 1 1" specular="0.10000000000000001 0.10000000000000001 0.10000000000000001"/>
    <geom name="ground" class="/" type="plane" size="15 15 0.5" material="MatPlane" rgba="1 1 1 1"/>
    <site name="body" class="/" size="9.9999999999999995e-07 9.9999999999999995e-07 9.9999999999999995e-07" pos="0 0 0.68278620243072508"/>
    <body pos="0 0 0.68278620243072508" name="0/">
      <joint name="0/rootx/" class="/" type="slide" axis="1 0 0" limited="false" stiffness="0" armature="0" damping="0"/>
      <joint name="0/rootz/" class="/" type="slide" axis="0 0 1" limited="false" stiffness="0" armature="0" damping="0"/>
      <joint name="0/rooty/" class="/" type="hinge" axis="0 1 0" limited="false" stiffness="0" armature="0" damping="0"/>
      <geom name="0/geom" class="0/" type="capsule" contype="1" conaffinity="1" condim="3" size="0.063507581174739453" rgba="0.31382172410303311 0.59196096705202472 0.34708102832739662 1" friction="0.59999999999999998 0.10000000000000001 0.10000000000000001" fromto="0 0 0 -0.70965696625477048 0 -0.53812435707425643"/>
      <site name="0/end0" class="0/" size="0.0050000000000000001" pos="-0.70965696625477048 0 -0.53812435707425643"/>
      <site name="0/attach1" class="0/" size="9.9999999999999995e-07 9.9999999999999995e-07 9.9999999999999995e-07" pos="-0.0024416728825154004 0 -0.0018514912310711269"/>
      <body pos="-0.0024416728825154004 0 -0.0018514912310711269" name="0/1/">
        <joint name="0/1/joint/" class="0/" type="hinge" axis="0 1 0" limited="true" range="-37.99152996907884 37.99152996907884"/>
        <geom name="0/1/geom" class="0/1/" type="capsule" contype="1" conaffinity="1" condim="3" size="0.069586543019788352" rgba="0.79393915050148534 0.52989986347276408 0.17361670515935201 1" friction="0.59999999999999998 0.10000000000000001 0.10000000000000001" fromto="0 0 0 0.25350652672858942 0 -0.44455246952646815"/>
        <site name="0/1/end1" class="0/1/" size="0.0050000000000000001" pos="0.25350652672858942 0 -0.44455246952646815"/>
        <site name="0/1/attach2" class="0/1/" size="9.9999999999999995e-07 9.9999999999999995e-07 9.9999999999999995e-07" pos="0.027680297788266091 0 -0.048540544094851416"/>
        <body pos="0.027680297788266091 0 -0.048540544094851416" name="0/1/2/">
          <joint name="0/1/2/joint/" class="0/1/" type="hinge" axis="0 1 0" limited="true" range="-47.914518399586015 47.914518399586015"/>
          <geom name="0/1/2/geom" class="0/1/2/" type="capsule" contype="1" conaffinity="1" condim="3" size="0.049577674123155162" rgba="0.040091898239932311 0.86729099026450307 0.013545073563749122 1" friction="0.59999999999999998 0.10000000000000001 0.10000000000000001" fromto="0 0 0 0.51063731208316732 0 0.27837166911591771"/>
          <site name="0/1/2/end2" class="0/1/2/" size="0.0050000000000000001" pos="0.51063731208316732 0 0.27837166911591771"/>
          <site name="0/1/2/attach3" class="0/1/2/" size="9.9999999999999995e-07 9.9999999999999995e-07 9.9999999999999995e-07" pos="0.37573267965194262 0 0.2048290062263852"/>
          <body pos="0.37573267965194262 0 0.2048290062263852" name="0/1/2/3/">
            <geom name="0/1/2/3/geom" class="0/1/2/3/" type="capsule" contype="1" conaffinity="1" condim="3" size="0.053891395611543345" rgba="0.95929449712994219 0.069372621284050195 0.90381818680179504 1" friction="0.59999999999999998 0.10000000000000001 0.10000000000000001" fromto="0 0 0 -0.36389154934683116 0 0.31736719148704529"/>
            <site name="0/1/2/3/end3" class="0/1/2/3/" size="0.0050000000000000001" pos="-0.36389154934683116 0 0.31736719148704529"/>
            <site name="0/1/2/3/attach4" class="0/1/2/3/" size="9.9999999999999995e-07 9.9999999999999995e-07 9.9999999999999995e-07" pos="-0.21579512642841805 0 0.18820523129517214"/>
            <body pos="-0.21579512642841805 0 0.18820523129517214" name="0/1/2/3/4/">
              <joint name="0/1/2/3/4/joint/" class="0/1/2/3/" type="hinge" axis="0 1 0" limited="true" range="-63.25961408843915 63.25961408843915"/>
              <geom name="0/1/2/3/4/geom" class="0/1/2/3/4/" type="capsule" contype="1" conaffinity="1" condim="3" size="0.040459765490075024" rgba="0.80719747843233913 0.040216207106210544 0.69790287775725912 1" friction="0.59999999999999998 0.10000000000000001 0.10000000000000001" fromto="0 0 0 -0.01619142745252411 0 0.73629021318143839"/>
              <site name="0/1/2/3/4/end4" class="0/1/2/3/4/" size="0.0050000000000000001" pos="-0.01619142745252411 0 0.73629021318143839"/>
            </body>
            <site name="0/1/2/3/attach5" class="0/1/2/3/" size="9.9999999999999995e-07 9.9999999999999995e-07 9.9999999999999995e-07" pos="-0.217933971126854 0 0.19007061985994642"/>
            <body pos="-0.217933971126854 0 0.19007061985994642" name="0/1/2/3/5/">
              <joint name="0/1/2/3/5/joint/" class="0/1/2/3/" type="hinge" axis="0 1 0" limited="true" range="-69.186504279573469 69.186504279573469"/>
              <geom name="0/1/2/3/5/geom" class="0/1/2/3/5/" type="capsule" contype="1" conaffinity="1" condim="3" size="0.065194665166528748" rgba="0.68842237902329317 0.59279516826443124 0.7251341408540275 1" friction="0.59999999999999998 0.10000000000000001 0.10000000000000001" fromto="0 0 0 0.70988098558974544 0 0.59159054354217289"/>
              <site name="0/1/2/3/5/end5" class="0/1/2/3/5/" size="0.0050000000000000001" pos="0.70988098558974544 0 0.59159054354217289"/>
              <site name="0/1/2/3/5/attach6" class="0/1/2/3/5/" size="9.9999999999999995e-07 9.9999999999999995e-07 9.9999999999999995e-07" pos="0.65306695704590279 0 0.54424367454673162"/>
              <body pos="0.65306695704590279 0 0.54424367454673162" name="0/1/2/3/5/6/">
                <geom name="0/1/2/3/5/6/geom" class="0/1/2/3/5/6/" type="capsule" contype="1" conaffinity="1" condim="3" size="0.06775674699424955" rgba="0.51430834499222922 0.94543490255033891 0.83658879257724894 1" friction="0.59999999999999998 0.10000000000000001 0.10000000000000001" fromto="0 0 0 0.15473185094853581 0 -0.45737401657261623"/>
                <site name="0/1/2/3/5/6/end6" class="0/1/2/3/5/6/" size="0.0050000000000000001" pos="0.15473185094853581 0 -0.45737401657261623"/>
              </body>
              <site name="0/1/2/3/5/attach7" class="0/1/2/3/5/" size="9.9999999999999995e-07 9.9999999999999995e-07 9.9999999999999995e-07" pos="0.66513654873430794 0 0.55430205961721468"/>
              <body pos="0.66513654873430794 0 0.55430205961721468" name="0/1/2/3/5/7/">
                <joint name="0/1/2/3/5/7/joint/" class="0/1/2/3/5/" type="hinge" axis="0 1 0" limited="true" range="-31.396499213853385 31.396499213853385"/>
                <geom name="0/1/2/3/5/7/geom" class="0/1/2/3/5/7/" type="capsule" contype="1" conaffinity="1" condim="3" size="0.040649974638004197" rgba="0.37823468615007083 0.86419817977078295 0.61864918860811569 1" friction="0.59999999999999998 0.10000000000000001 0.10000000000000001" fromto="0 0 0 0.42289926758935947 0 -0.40939519771057076"/>
                <site name="0/1/2/3/5/7/end7" class="0/1/2/3/5/7/" size="0.0050000000000000001" pos="0.42289926758935947 0 -0.40939519771057076"/>
              </body>
            </body>
          </body>
        </body>
        <site name="0/1/attach8" class="0/1/" size="9.9999999999999995e-07 9.9999999999999995e-07 9.9999999999999995e-07" pos="0.14102277077938599 0 -0.24729943571259913"/>
        <body pos="0.14102277077938599 0 -0.24729943571259913" name="0/1/8/">
          <joint name="0/1/8/joint/" class="0/1/" type="hinge" axis="0 1 0" limited="true" range="-68.085710890027059 68.085710890027059"/>
          <geom name="0/1/8/geom" class="0/1/8/" type="capsule" contype="1" conaffinity="1" condim="3" size="0.044772886027756101" rgba="0.91651111404108143 0.094350577365756694 0.83961336781858475 1" friction="0.59999999999999998 0.10000000000000001 0.10000000000000001" fromto="0 0 0 0.3050699656863447 0 0.33169989540331679"/>
          <site name="0/1/8/end8" class="0/1/8/" size="0.0050000000000000001" pos="0.3050699656863447 0 0.33169989540331679"/>
        </body>
      </body>
      <site name="0/attach9" class="0/" size="9.9999999999999995e-07 9.9999999999999995e-07 9.9999999999999995e-07" pos="-0.27231399216036484 0 -0.20649243074013912"/>
      <body pos="-0.27231399216036484 0 -0.20649243074013912" name="0/9/">
        <joint name="0/9/joint/" class="0/" type="hinge" axis="0 1 0" limited="true" range="-41.857608022685007 41.857608022685007"/>
        <geom name="0/9/geom" class="0/9/" type="capsule" contype="1" conaffinity="1" condim="3" size="0.042798141390461314" rgba="0.70346408623820389 0.46174975016217301 0.38425151924413781 1" friction="0.59999999999999998 0.10000000000000001 0.10000000000000001" fromto="0 0 0 0.38481790367411772 0 -0.11583208130652223"/>
        <site name="0/9/end9" class="0/9/" size="0.0050000000000000001" pos="0.38481790367411772 0 -0.11583208130652223"/>
        <site name="0/9/attach10" class="0/9/" size="9.9999999999999995e-07 9.9999999999999995e-07 9.9999999999999995e-07" pos="0.30088001046610724 0 -0.090566362695357769"/>
        <body pos="0.30088001046610724 0 -0.090566362695357769" name="0/9/10/">
          <joint name="0/9/10/joint/" class="0/9/" type="hinge" axis="0 1 0" limited="true" range="-35.615364161881736 35.615364161881736"/>
          <geom name="0/9/10/geom" class="0/9/10/" type="capsule" contype="1" conaffinity="1" condim="3" size="0.046882817201885946" rgba="0.06972367245074429 0.93940471372594103 0.75297982249078543 1" friction="0.59999999999999998 0.10000000000000001 0.10000000000000001" fromto="0 0 0 -0.39199039171091926 0 -0.28572739412957809"/>
          <site name="0/9/10/end10" class="0/9/10/" size="0.0050000000000000001" pos="-0.39199039171091926 0 -0.28572739412957809"/>
        </body>
      </body>
      <camera name="0/side" class="0/" mode="trackcom" pos="0.40000000000000002 -4 0.20000000000000001" quat="0.70699999999999996 0.70699999999999996 0 0"/>
    </body>
  </worldbody>
  <actuator>
    <motor name="0/1/motor" class="0/1/" ctrllimited="true" ctrlrange="-1 1" gear="53" joint="0/1/joint/"/>
    <motor name="0/1/2/motor" class="0/1/2/" ctrllimited="true" ctrlrange="-1 1" gear="65" joint="0/1/2/joint/"/>
    <motor name="0/1/2/3/4/motor" class="0/1/2/3/4/" ctrllimited="true" ctrlrange="-1 1" gear="88" joint="0/1/2/3/4/joint/"/>
    <motor name="0/1/2/3/5/motor" class="0/1/2/3/5/" ctrllimited="true" ctrlrange="-1 1" gear="72" joint="0/1/2/3/5/joint/"/>
    <motor name="0/1/2/3/5/7/motor" class="0/1/2/3/5/7/" ctrllimited="true" ctrlrange="-1 1" gear="84" joint="0/1/2/3/5/7/joint/"/>
    <motor name="0/1/8/motor" class="0/1/8/" ctrllimited="true" ctrlrange="-1 1" gear="60" joint="0/1/8/joint/"/>
    <motor name="0/9/motor" class="0/9/" ctrllimited="true" ctrlrange="-1 1" gear="83" joint="0/9/joint/"/>
    <motor name="0/9/10/motor" class="0/9/10/" ctrllimited="true" ctrlrange="-1 1" gear="67" joint="0/9/10/joint/"/>
  </actuator>
  <sensor>
    <subtreelinvel name="velocity" body="0/"/>
  </sensor>
</mujoco>
