<mujoco model="morphology">
  <option timestep="0.01"/>
  <default>
    <default class="/"/>
    <default class="0/"/>
    <default class="0/1/"/>
    <default class="0/1/2/"/>
    <default class="0/1/2/3/"/>
    <default class="0/1/2/3/4/"/>
    <default class="0/1/2/3/4/5/"/>
    <default class="0/1/2/3/4/5/6/"/>
    <default class="0/1/2/3/4/5/6/7/"/>
    <default class="0/1/2/3/4/8/"/>
    <default class="0/1/2/3/4/8/9/"/>
    <default class="0/1/2/3/4/8/9/10/"/>
  </default>
  <asset>
    <texture name="texplane" type="2d" builtin="checker" rgb1="0.10000000000000001 0.20000000000000001 0.29999999999999999" rgb2="0.20000000000000001 0.29999999999999999 0.40000000000000002" width="300" height="300"/>
    <material name="MatPlane" class="/" texture="texplane" texrepeat="20 20" specular="1" shininess="1" reflectance="0.5"/>
  </asset>
  <worldbody>
    <light name="//unnamed_light_0" class="/" directional="true" pos="0 0 1.5" dir="0 0 -1.3" cutoff="100" exponent="1" diffuse="1 1 1" specular="0.10000000000000001 0.10000000000000001 0.10000000000000001"/>
    <geom name="ground" class="/" type="plane" size="15 15 0.5" material="MatPlane" rgba="1 1 1 1"/>
    <site name="body" class="/" size="9.9999999999999995e-07 9.9999999999999995e-07 9.9999999999999995e-07" pos="0 0 0.10000000000000001"/>
    <body pos="0 0 0.10000000000000001" name="0/">
      <joint name="0/rootx/" class="/" type="slide" axis="1 0 0" limited="false" stiffness="0" armature="0" damping="0"/>
      <joint name="0/rootz/" class="/" type="slide" axis="0 0 1" limited="false" stiffness="0" armature="0" damping="0"/>
      <joint name="0/rooty/" class="/" type="hinge" axis="0 1 0" limited="false" stiffness="0" armature="0" damping="0"/>
      <geom name="0/geom" class="0/" type="capsule" contype="1" conaffinity="1" condim="3" size="0.06845316394854177" rgba="0.75333942532333076 0.042459500140377582 0.71663470771913473 1" friction="0.59999999999999998 0.10000000000000001 0.10000000000000001" fromto="0 0 0 -0.4810562623365956 0 0.089096311233515024"/>
      <site name="0/end0" class="0/" size="0.0050000000000000001" pos="-0.4810562623365956 0 0.089096311233515024"/>
      <site name="0/attach1" class="0/" size="9.9999999999999995e-07 9.9999999999999995e-07 9.9999999999999995e-07" pos="-0.046690435485968136 0 0.0086475239953854987"/>
      <body pos="-0.046690435485968136 0 0.0086475239953854987" name="0/1/">
        <joint name="0/1/joint/" class="0/" type="hinge" axis="0 1 0" limited="true" range="-68.622305171773391 68.622305171773391"/>
        <geom name="0/1/geom" class="0/1/" type="capsule" contype="1" conaffinity="1" condim="3" size="0.065599581334619975" rgba="0.86097743911584623 0.59394724603045357 0.52447908739214844 1" friction="0.59999999999999998 0.10000000000000001 0.10000000000000001" fromto="0 0 0 0.74782599635522962 0 0.52797074457096738"/>
        <site name="0/1/end1" class="0/1/" size="0.0050000000000000001" pos="0.74782599635522962 0 0.52797074457096738"/>
        <site name="0/1/attach2" class="0/1/" size="9.9999999999999995e-07 9.9999999999999995e-07 9.9999999999999995e-07" pos="0.28559158825690462 0 0.20162979654371121"/>
        <body pos="0.28559158825690462 0 0.20162979654371121" name="0/1/2/">
          <joint name="0/1/2/joint/" class="0/1/" type="hinge" axis="0 1 0" limited="true" range="-69.557892719997042 69.557892719997042"/>
          <geom name="0/1/2/geom" class="0/1/2/" type="capsule" contype="1" conaffinity="1" condim="3" size="0.060172354565072396" rgba="0.65996365151361747 0.75392558218526129 0.25560756986688371 1" friction="0.59999999999999998 0.10000000000000001 0.10000000000000001" fromto="0 0 0 -0.07105359875253181 0 0.21677986254459725"/>
          <site name="0/1/2/end2" class="0/1/2/" size="0.0050000000000000001" pos="-0.07105359875253181 0 0.21677986254459725"/>
          <site name="0/1/2/attach3" class="0/1/2/" size="9.9999999999999995e-07 9.9999999999999995e-07 9.9999999999999995e-07" pos="-0.038283990860042215 0 0.11680194137953989"/>
          <body pos="-0.038283990860042215 0 0.11680194137953989" name="0/1/2/3/">
            <geom name="0/1/2/3/geom" class="0/1/2/3/" type="capsule" contype="1" conaffinity="1" condim="3" size="0.060779414265485457" rgba="0.60126900667426775 0.49276898186375628 0.93234551357904349 1" friction="0.59999999999999998 0.10000000000000001 0.10000000000000001" fromto="0 0 0 0.68058092289528349 0 0.57707025167123649"/>
            <site name="0/1/2/3/end3" class="0/1/2/3/" size="0.0050000000000000001" pos="0.68058092289528349 0 0.57707025167123649"/>
            <site name="0/1/2/3/attach4" class="0/1/2/3/" size="9.9999999999999995e-07 9.9999999999999995e-07 9.9999999999999995e-07" pos="0.31960752839568607 0 0.27099789406776886"/>
            <body pos="0.31960752839568607 0 0.27099789406776886" name="0/1/2/3/4/">
              <joint name="0/1/2/3/4/joint/" class="0/1/2/3/" type="hinge" axis="0 1 0" limited="true" range="-63.521433875115427 63.521433875115427"/>
              <geom name="0/1/2/3/4/geom" class="0/1/2/3/4/" type="capsule" contype="1" conaffinity="1" condim="3" size="0.057855121790027643" rgba="0.030103996992643212 0.8435416829883664 0.98222324390622118 1" friction="0.59999999999999998 0.10000000000000001 0.10000000000000001" fromto="0 0 0 -0.6414425767738412 0 0.26084290825333012"/>
              <site name="0/1/2/3/4/end4" class="0/1/2/3/4/" size="0.0050000000000000001" pos="-0.6414425767738412 0 0.26084290825333012"/>
              <site name="0/1/2/3/4/attach5" class="0/1/2/3/4/" size="9.9999999999999995e-07 9.9999999999999995e-07 9.9999999999999995e-07" pos="-0.46121875921993966 0 0.18755481293587198"/>
              <body pos="-0.46121875921993966 0 0.18755481293587198" name="0/1/2/3/4/5/">
                <joint name="0/1/2/3/4/5/joint/" class="0/1/2/3/4/" type="hinge" axis="0 1 0" limited="true" range="-43.174614205440093 43.174614205440093"/>
                <geom name="0/1/2/3/4/5/geom" class="0/1/2/3/4/5/" type="capsule" contype="1" conaffinity="1" condim="3" size="0.040313534054828785" rgba="0.68514820977241331 0.54397976533100134 0.34693004647943826 1" friction="0.59999999999999998 0.10000000000000001 0.10000000000000001" fromto="0 0 0 0.16403231782914407 0 0.20808155168298337"/>
                <site name="0/1/2/3/4/5/end5" class="0/1/2/3/4/5/" size="0.0050000000000000001" pos="0.16403231782914407 0 0.20808155168298337"/>
                <site name="0/1/2/3/4/5/attach6" class="0/1/2/3/4/5/" size="9.9999999999999995e-07 9.9999999999999995e-07 9.9999999999999995e-07" pos="0.13886274780866451 0 0.17615294606204665"/>
                <body pos="0.13886274780866451 0 0.17615294606204665" name="0/1/2/3/4/5/6/">
                  <joint name="0/1/2/3/4/5/6/joint/" class="0/1/2/3/4/5/" type="hinge" axis="0 1 0" limited="true" range="-44.430327258852252 44.430327258852252"/>
                  <geom name="0/1/2/3/4/5/6/geom" class="0/1/2/3/4/5/6/" type="capsule" contype="1" conaffinity="1" condim="3" size="0.066752421348117513" rgba="0.58713170856127705 0.29358484914169614 0.11521731312360328 1" friction="0.59999999999999998 0.10000000000000001 0.10000000000000001" fromto="0 0 0 -0.39087217229053933 0 0.59636582356865064"/>
                  <site name="0/1/2/3/4/5/6/end6" class="0/1/2/3/4/5/6/" size="0.0050000000000000001" pos="-0.39087217229053933 0 0.59636582356865064"/>
                  <site name="0/1/2/3/4/5/6/attach7" class="0/1/2/3/4/5/6/" size="9.9999999999999995e-07 9.9999999999999995e-07 9.9999999999999995e-07" pos="-0.29354079549863638 0 0.44786431644056496"/>
                  <body pos="-0.29354079549863638 0 0.44786431644056496" name="0/1/2/3/4/5/6/7/">
                    <geom name="0/1/2/3/4/5/6/7/geom" class="0/1/2/3/4/5/6/7/" type="capsule" contype="1" conaffinity="1" condim="3" size="0.051076600102941058" rgba="0.39415562311483254 0.97555338971742456 0.33591928627504863 1" friction="0.59999999999999998 0.10000000000000001 0.10000000000000001" fromto="0 0 0 0.59811380714805829 0 0.7176464573155652"/>
                    <site name="0/1/2/3/4/5/6/7/end7" class="0/1/2/3/4/5/6/7/" size="0.0050000000000000001" pos="0.59811380714805829 0 0.7176464573155652"/>
                  </body>
                </body>
              </body>
              <site name="0/1/2/3/4/attach8" class="0/1/2/3/4/" size="9.9999999999999995e-07 9.9999999999999995e-07 9.9999999999999995e-07" pos="-0.2801815270485104 0 0.11393594220353749"/>
              <body pos="-0.2801815270485104 0 0.11393594220353749" name="0/1/2/3/4/8/">
                <joint name="0/1/2/3/4/8/joint/" class="0/1/2/3/4/" type="hinge" axis="0 1 0" limited="true" range="-46.405040976731371 46.405040976731371"/>
                <geom name="0/1/2/3/4/8/geom" class="0/1/2/3/4/8/" type="capsule" contype="1" conaffinity="1" condim="3" size="0.065625481684469716" rgba="0.028148474159832126 0.8335017126566644 0.031498055776645995 1" friction="0.59999999999999998 0.10000000000000001 0.10000000000000001" fromto="0 0 0 -0.47687981150431324 0 -0.51792678167218087"/>
                <site name="0/1/2/3/4/8/end8" class="0/1/2/3/4/8/" size="0.0050000000000000001" pos="-0.47687981150431324 0 -0.51792678167218087"/>
                <site name="0/1/2/3/4/8/attach9" class="0/1/2/3/4/8/" size="9.9999999999999995e-07 9.9999999999999995e-07 9.9999999999999995e-07" pos="-0.11402915294811394 0 -0.12384410238907201"/>
                <body pos="-0.11402915294811394 0 -0.12384410238907201" name="0/1/2/3/4/8/9/">
                  <joint name="0/1/2/3/4/8/9/joint/" class="0/1/2/3/4/8/" type="hinge" axis="0 1 0" limited="true" range="-50.876458575909425 50.876458575909425"/>
                  <geom name="0/1/2/3/4/8/9/geom" class="0/1/2/3/4/8/9/" type="capsule" contype="1" conaffinity="1" condim="3" size="0.054231301483346823" rgba="0.22013209133321809 0.029917155743389823 0.99806063977541926 1" friction="0.59999999999999998 0.10000000000000001 0.10000000000000001" fromto="0 0 0 -0.69250216106791329 0 0.15765692934489595"/>
                  <site name="0/1/2/3/4/8/9/end9" class="0/1/2/3/4/8/9/" size="0.0050000000000000001" pos="-0.69250216106791329 0 0.15765692934489595"/>
                  <site name="0/1/2/3/4/8/9/attach10" class="0/1/2/3/4/8/9/" size="9.9999999999999995e-07 9.9999999999999995e-07 9.9999999999999995e-07" pos="-0.3131551982838347 0 0.071293765919352298"/>
                  <body pos="-0.3131551982838347 0 0.071293765919352298" name="0/1/2/3/4/8/9/10/">
                    <joint name="0/1/2/3/4/8/9/10/joint/" class="0/1/2/3/4/8/9/" type="hinge" axis="0 1 0" limited="true" range="-68.045865841434178 68.045865841434178"/>
                    <geom name="0/1/2/3/4/8/9/10/geom" class="0/1/2/3/4/8/9/10/" type="capsule" contype="1" conaffinity="1" condim="3" size="0.05844106842506018" rgba="0.19415474005851008 0.51183605332488802 0.023595860184029371 1" friction="0.59999999999999998 0.10000000000000001 0.10000000000000001" fromto="0 0 0 -0.24672965501061428 0 0.60069401033601189"/>
                    <site name="0/1/2/3/4/8/9/10/end10" class="0/1/2/3/4/8/9/10/" size="0.0050000000000000001" pos="-0.24672965501061428 0 0.60069401033601189"/>
                  </body>
                </body>
              </body>
            </body>
          </body>
        </body>
      </body>
      <camera name="0/side" class="0/" mode="trackcom" pos="0.40000000000000002 -4 0.20000000000000001" quat="0.70699999999999996 0.70699999999999996 0 0"/>
    </body>
  </worldbody>
  <actuator>
    <motor name="0/1/motor" class="0/1/" ctrllimited="true" ctrlrange="-1 1" gear="76" joint="0/1/joint/"/>
    <motor name="0/1/2/motor" class="0/1/2/" ctrllimited="true" ctrlrange="-1 1" gear="68" joint="0/1/2/joint/"/>
    <motor name="0/1/2/3/4/motor" class="0/1/2/3/4/" ctrllimited="true" ctrlrange="-1 1" gear="53" joint="0/1/2/3/4/joint/"/>
    <motor name="0/1/2/3/4/5/motor" class="0/1/2/3/4/5/" ctrllimited="true" ctrlrange="-1 1" gear="73" joint="0/1/2/3/4/5/joint/"/>
    <motor name="0/1/2/3/4/5/6/motor" class="0/1/2/3/4/5/6/" ctrllimited="true" ctrlrange="-1 1" gear="86" joint="0/1/2/3/4/5/6/joint/"/>
    <motor name="0/1/2/3/4/8/motor" class="0/1/2/3/4/8/" ctrllimited="true" ctrlrange="-1 1" gear="58" joint="0/1/2/3/4/8/joint/"/>
    <motor name="0/1/2/3/4/8/9/motor" class="0/1/2/3/4/8/9/" ctrllimited="true" ctrlrange="-1 1" gear="57" joint="0/1/2/3/4/8/9/joint/"/>
    <motor name="0/1/2/3/4/8/9/10/motor" class="0/1/2/3/4/8/9/10/" ctrllimited="true" ctrlrange="-1 1" gear="57" joint="0/1/2/3/4/8/9/10/joint/"/>
  </actuator>
  <sensor>
    <subtreelinvel name="velocity" body="0/"/>
  </sensor>
</mujoco>
