<mujoco model="morphology">
  <option timestep="0.01"/>
  <default>
    <default class="/"/>
    <default class="0/"/>
    <default class="0/1/"/>
    <default class="0/2/"/>
    <default class="0/2/3/"/>
    <default class="0/2/3/4/"/>
    <default class="0/2/3/5/"/>
    <default class="0/2/3/5/6/"/>
    <default class="0/2/3/7/"/>
    <default class="0/2/3/7/8/"/>
    <default class="0/2/9/"/>
    <default class="0/2/9/10/"/>
  </default>
  <asset>
    <texture name="texplane" type="2d" builtin="checker" rgb1="0.10000000000000001 0.20000000000000001 0.29999999999999999" rgb2="0.20000000000000001 0.29999999999999999 0.40000000000000002" width="300" height="300"/>
    <material name="MatPlane" class="/" texture="texplane" texrepeat="20 20" specular="1" shininess="1" reflectance="0.5"/>
  </asset>
  <worldbody>
    <light name="//unnamed_light_0" class="/" directional="true" pos="0 0 1.5" dir="0 0 -1.3" cutoff="100" exponent="1" diffuse="1 1 1" specular="0.10000000000000001 0.10000000000000001 0.10000000000000001"/>
    <geom name="ground" class="/" type="plane" size="15 15 0.5" material="MatPlane" rgba="1 1 1 1"/>
    <site name="body" class="/" size="9.9999999999999995e-07 9.9999999999999995e-07 9.9999999999999995e-07" pos="0 0 0.58064798116683958"/>
    <body pos="0 0 0.58064798116683958" name="0/">
      <joint name="0/rootx/" class="/" type="slide" axis="1 0 0" limited="false" stiffness="0" armature="0" damping="0"/>
      <joint name="0/rootz/" class="/" type="slide" axis="0 0 1" limited="false" stiffness="0" armature="0" damping="0"/>
      <joint name="0/rooty/" class="/" type="hinge" axis="0 1 0" limited="false" stiffness="0" armature="0" damping="0"/>
      <geom name="0/geom" class="0/" type="capsule" contype="1" conaffinity="1" condim="3" size="0.059242041949445143" rgba="0.55274517701668746 0.28340828350132152 0.65763786261317725 1" friction="0.59999999999999998 0.10000000000000001 0.10000000000000001" fromto="0 0 0 0.19609180788694558 0 -0.083015228782254535"/>
      <site name="0/end0" class="0/" size="0.0050000000000000001" pos="0.19609180788694558 0 -0.083015228782254535"/>
      <site name="0/attach1" class="0/" size="9.9999999999999995e-07 9.9999999999999995e-07 9.9999999999999995e-07" pos="0.049346220758666973 0 -0.020890662644010904"/>
      <body pos="0.049346220758666973 0 -0.020890662644010904" name="0/1/">
        <joint name="0/1/joint/" class="0/" type="hinge" axis="0 1 0" limited="true" stiffness="100" range="-34.634533815734564 34.634533815734564" armature="0.20000000000000001" damping="3.5"/>
        <geom name="0/1/geom" class="0/1/" type="capsule" contype="1" conaffinity="1" condim="3" size="0.063366941476484293" rgba="0.31043573562454385 0.81284353142096277 0.67637661344990618 1" friction="0.59999999999999998 0.10000000000000001 0.10000000000000001" fromto="0 0 0 -0.62359292101932096 0 -0.45975731764328598"/>
        <site name="0/1/end1" class="0/1/" size="0.0050000000000000001" pos="-0.62359292101932096 0 -0.45975731764328598"/>
      </body>
      <site name="0/attach2" class="0/" size="9.9999999999999995e-07 9.9999999999999995e-07 9.9999999999999995e-07" pos="0.10808755818224311 0 -0.045758736520943227"/>
      <body pos="0.10808755818224311 0 -0.045758736520943227" name="0/2/">
        <joint name="0/2/joint/" class="0/" type="hinge" axis="0 1 0" limited="true" stiffness="100" range="-36.925932102316729 36.925932102316729" armature="0.20000000000000001" damping="3.5"/>
        <geom name="0/2/geom" class="0/2/" type="capsule" contype="1" conaffinity="1" condim="3" size="0.048227109197974606" rgba="0.17322399860147497 0.14642636265458397 0.61814479247256238 1" friction="0.59999999999999998 0.10000000000000001 0.10000000000000001" fromto="0 0 0 -0.12633252537704642 0 0.63040499146709106"/>
        <site name="0/2/end2" class="0/2/" size="0.0050000000000000001" pos="-0.12633252537704642 0 0.63040499146709106"/>
        <site name="0/2/attach3" class="0/2/" size="9.9999999999999995e-07 9.9999999999999995e-07 9.9999999999999995e-07" pos="-0.10944348710669462 0 0.54612792983999114"/>
        <body pos="-0.10944348710669462 0 0.54612792983999114" name="0/2/3/">
          <joint name="0/2/3/joint/" class="0/2/" type="hinge" axis="0 1 0" limited="true" stiffness="100" range="-67.898418073928127 67.898418073928127" armature="0.20000000000000001" damping="3.5"/>
          <geom name="0/2/3/geom" class="0/2/3/" type="capsule" contype="1" conaffinity="1" condim="3" size="0.052422541759170396" rgba="0.17255085704202855 0.69563985521401528 0.77567198002931392 1" friction="0.59999999999999998 0.10000000000000001 0.10000000000000001" fromto="0 0 0 0.58270601199847438 0 0.56227031912521719"/>
          <site name="0/2/3/end3" class="0/2/3/" size="0.0050000000000000001" pos="0.58270601199847438 0 0.56227031912521719"/>
          <site name="0/2/3/attach4" class="0/2/3/" size="9.9999999999999995e-07 9.9999999999999995e-07 9.9999999999999995e-07" pos="0.31778988988125895 0 0.30664489316916627"/>
          <body pos="0.31778988988125895 0 0.30664489316916627" name="0/2/3/4/">
            <joint name="0/2/3/4/joint/" class="0/2/3/" type="hinge" axis="0 1 0" limited="true" stiffness="100" range="-48.747694311843773 48.747694311843773" armature="0.20000000000000001" damping="3.5"/>
            <geom name="0/2/3/4/geom" class="0/2/3/4/" type="capsule" contype="1" conaffinity="1" condim="3" size="0.055694256674208041" rgba="0.020428136850749734 0.2475709818836852 0.61064941001821693 1" friction="0.59999999999999998 0.10000000000000001 0.10000000000000001" fromto="0 0 0 0.28696241879738427 0 -0.023458733581455782"/>
            <site name="0/2/3/4/end4" class="0/2/3/4/" size="0.0050000000000000001" pos="0.28696241879738427 0 -0.023458733581455782"/>
          </body>
          <site name="0/2/3/attach5" class="0/2/3/" size="9.9999999999999995e-07 9.9999999999999995e-07 9.9999999999999995e-07" pos="0.13430247305529772 0 0.12959244083499491"/>
          <body pos="0.13430247305529772 0 0.12959244083499491" name="0/2/3/5/">
            <geom name="0/2/3/5/geom" class="0/2/3/5/" type="capsule" contype="1" conaffinity="1" condim="3" size="0.066355016831023864" rgba="0.83450036991683907 0.032343332121260726 0.044191364130758526 1" friction="0.59999999999999998 0.10000000000000001 0.10000000000000001" fromto="0 0 0 0.35507586321395479 0 -0.402067830640636"/>
            <site name="0/2/3/5/end5" class="0/2/3/5/" size="0.0050000000000000001" pos="0.35507586321395479 0 -0.402067830640636"/>
            <site name="0/2/3/5/attach6" class="0/2/3/5/" size="9.9999999999999995e-07 9.9999999999999995e-07 9.9999999999999995e-07" pos="0.29306577261254385 0 -0.33185111024667502"/>
            <body pos="0.29306577261254385 0 -0.33185111024667502" name="0/2/3/5/6/">
              <joint name="0/2/3/5/6/joint/" class="0/2/3/5/" type="hinge" axis="0 1 0" limited="true" stiffness="100" range="-35.114636102106864 35.114636102106864" armature="0.20000000000000001" damping="3.5"/>
              <geom name="0/2/3/5/6/geom" class="0/2/3/5/6/" type="capsule" contype="1" conaffinity="1" condim="3" size="0.054472617050372693" rgba="0.7197490798749453 0.35198992937906681 0.65628091508011865 1" friction="0.59999999999999998 0.10000000000000001 0.10000000000000001" fromto="0 0 0 0.72415016665109633 0 0.042463150210806377"/>
              <site name="0/2/3/5/6/end6" class="0/2/3/5/6/" size="0.0050000000000000001" pos="0.72415016665109633 0 0.042463150210806377"/>
            </body>
          </body>
          <site name="0/2/3/attach7" class="0/2/3/" size="9.9999999999999995e-07 9.9999999999999995e-07 9.9999999999999995e-07" pos="0.037939436837858768 0 0.03660888821979362"/>
          <body pos="0.037939436837858768 0 0.03660888821979362" name="0/2/3/7/">
            <joint name="0/2/3/7/joint/" class="0/2/3/" type="hinge" axis="0 1 0" limited="true" stiffness="100" range="-34.319084502789416 34.319084502789416" armature="0.20000000000000001" damping="3.5"/>
            <geom name="0/2/3/7/geom" class="0/2/3/7/" type="capsule" contype="1" conaffinity="1" condim="3" size="0.066858065017382645" rgba="0.95429355468525667 0.35013622255029853 0.42622322099056908 1" friction="0.59999999999999998 0.10000000000000001 0.10000000000000001" fromto="0 0 0 0.19678261564171839 0 -0.13690069006624683"/>
            <site name="0/2/3/7/end7" class="0/2/3/7/" size="0.0050000000000000001" pos="0.19678261564171839 0 -0.13690069006624683"/>
            <site name="0/2/3/7/attach8" class="0/2/3/7/" size="9.9999999999999995e-07 9.9999999999999995e-07 9.9999999999999995e-07" pos="0.18907743924441417 0 -0.13154023704841697"/>
            <body pos="0.18907743924441417 0 -0.13154023704841697" name="0/2/3/7/8/">
              <joint name="0/2/3/7/8/joint/" class="0/2/3/7/" type="hinge" axis="0 1 0" limited="true" stiffness="100" range="-61.181683108875959 61.181683108875959" armature="0.20000000000000001" damping="3.5"/>
              <geom name="0/2/3/7/8/geom" class="0/2/3/7/8/" type="capsule" contype="1" conaffinity="1" condim="3" size="0.068992794073076805" rgba="0.40009827882405813 0.98355880550432884 0.7032219593492991 1" friction="0.59999999999999998 0.10000000000000001 0.10000000000000001" fromto="0 0 0 0.077361228434665419 0 -0.5744287988810004"/>
              <site name="0/2/3/7/8/end8" class="0/2/3/7/8/" size="0.0050000000000000001" pos="0.077361228434665419 0 -0.5744287988810004"/>
            </body>
          </body>
        </body>
        <site name="0/2/attach9" class="0/2/" size="9.9999999999999995e-07 9.9999999999999995e-07 9.9999999999999995e-07" pos="-0.11352458907603613 0 0.56649281247398076"/>
        <body pos="-0.11352458907603613 0 0.56649281247398076" name="0/2/9/">
          <joint name="0/2/9/joint/" class="0/2/" type="hinge" axis="0 1 0" limited="true" stiffness="100" range="-54.744903006205583 54.744903006205583" armature="0.20000000000000001" damping="3.5"/>
          <geom name="0/2/9/geom" class="0/2/9/" type="capsule" contype="1" conaffinity="1" condim="3" size="0.0617758894818798" rgba="0.33729258698869258 0.32588023523159126 0.96226067749095068 1" friction="0.59999999999999998 0.10000000000000001 0.10000000000000001" fromto="0 0 0 -0.52672459690420936 0 -0.0052769722394196972"/>
          <site name="0/2/9/end9" class="0/2/9/" size="0.0050000000000000001" pos="-0.52672459690420936 0 -0.0052769722394196972"/>
          <site name="0/2/9/attach10" class="0/2/9/" size="9.9999999999999995e-07 9.9999999999999995e-07 9.9999999999999995e-07" pos="-0.33167343727448201 0 -0.0033228589121093405"/>
          <body pos="-0.33167343727448201 0 -0.0033228589121093405" name="0/2/9/10/">
            <joint name="0/2/9/10/joint/" class="0/2/9/" type="hinge" axis="0 1 0" limited="true" stiffness="100" range="-57.65983068937674 57.65983068937674" armature="0.20000000000000001" damping="3.5"/>
            <geom name="0/2/9/10/geom" class="0/2/9/10/" type="capsule" contype="1" conaffinity="1" condim="3" size="0.066045444461126687" rgba="0.53938312880921224 0.68045920528922732 0.40686299964948491 1" friction="0.59999999999999998 0.10000000000000001 0.10000000000000001" fromto="0 0 0 -0.0036343106218763577 0 0.68694768912730497"/>
            <site name="0/2/9/10/end10" class="0/2/9/10/" size="0.0050000000000000001" pos="-0.0036343106218763577 0 0.68694768912730497"/>
          </body>
        </body>
      </body>
      <camera name="0/side" class="0/" mode="trackcom" pos="0.40000000000000002 -4 0.20000000000000001" quat="0.70699999999999996 0.70699999999999996 0 0"/>
    </body>
  </worldbody>
  <actuator>
    <motor name="0/1/motor" class="0/1/" ctrllimited="true" ctrlrange="-1 1" gear="80" joint="0/1/joint/"/>
    <motor name="0/2/motor" class="0/2/" ctrllimited="true" ctrlrange="-1 1" gear="74" joint="0/2/joint/"/>
    <motor name="0/2/3/motor" class="0/2/3/" ctrllimited="true" ctrlrange="-1 1" gear="56" joint="0/2/3/joint/"/>
    <motor name="0/2/3/4/motor" class="0/2/3/4/" ctrllimited="true" ctrlrange="-1 1" gear="83" joint="0/2/3/4/joint/"/>
    <motor name="0/2/3/5/6/motor" class="0/2/3/5/6/" ctrllimited="true" ctrlrange="-1 1" gear="70" joint="0/2/3/5/6/joint/"/>
    <motor name="0/2/3/7/motor" class="0/2/3/7/" ctrllimited="true" ctrlrange="-1 1" gear="78" joint="0/2/3/7/joint/"/>
    <motor name="0/2/3/7/8/motor" class="0/2/3/7/8/" ctrllimited="true" ctrlrange="-1 1" gear="84" joint="0/2/3/7/8/joint/"/>
    <motor name="0/2/9/motor" class="0/2/9/" ctrllimited="true" ctrlrange="-1 1" gear="84" joint="0/2/9/joint/"/>
    <motor name="0/2/9/10/motor" class="0/2/9/10/" ctrllimited="true" ctrlrange="-1 1" gear="57" joint="0/2/9/10/joint/"/>
  </actuator>
  <sensor>
    <subtreelinvel name="velocity" body="0/"/>
  </sensor>
</mujoco>
