<mujoco model="morphology">
  <option timestep="0.01"/>
  <default>
    <default class="/"/>
    <default class="0/"/>
    <default class="0/1/"/>
    <default class="0/1/2/"/>
    <default class="0/1/2/3/"/>
    <default class="0/1/2/3/4/"/>
    <default class="0/1/2/3/4/5/"/>
    <default class="0/1/6/"/>
    <default class="0/1/6/7/"/>
    <default class="0/1/6/7/8/"/>
    <default class="0/1/6/7/8/9/"/>
    <default class="0/1/6/7/8/9/10/"/>
  </default>
  <asset>
    <texture name="texplane" type="2d" builtin="checker" rgb1="0.10000000000000001 0.20000000000000001 0.29999999999999999" rgb2="0.20000000000000001 0.29999999999999999 0.40000000000000002" width="300" height="300"/>
    <material name="MatPlane" class="/" texture="texplane" texrepeat="20 20" specular="1" shininess="1" reflectance="0.5"/>
  </asset>
  <worldbody>
    <light name="//unnamed_light_0" class="/" directional="true" pos="0 0 1.5" dir="0 0 -1.3" cutoff="100" exponent="1" diffuse="1 1 1" specular="0.10000000000000001 0.10000000000000001 0.10000000000000001"/>
    <geom name="ground" class="/" type="plane" size="15 15 0.5" material="MatPlane" rgba="1 1 1 1"/>
    <site name="body" class="/" size="9.9999999999999995e-07 9.9999999999999995e-07 9.9999999999999995e-07" pos="0 0 1.131094789505005"/>
    <body pos="0 0 1.131094789505005" name="0/">
      <joint name="0/rootx/" class="/" type="slide" axis="1 0 0" limited="false" stiffness="0" armature="0" damping="0"/>
      <joint name="0/rootz/" class="/" type="slide" axis="0 0 1" limited="false" stiffness="0" armature="0" damping="0"/>
      <joint name="0/rooty/" class="/" type="hinge" axis="0 1 0" limited="false" stiffness="0" armature="0" damping="0"/>
      <geom name="0/geom" class="0/" type="capsule" contype="1" conaffinity="1" condim="3" size="0.068151066052536985" rgba="0.39136573120228269 0.93878637870793358 0.57535908073916442 1" friction="0.59999999999999998 0.10000000000000001 0.10000000000000001" fromto="0 0 0 -0.37125340907812954 0 -0.29781697183159411"/>
      <site name="0/end0" class="0/" size="0.0050000000000000001" pos="-0.37125340907812954 0 -0.29781697183159411"/>
      <site name="0/attach1" class="0/" size="9.9999999999999995e-07 9.9999999999999995e-07 9.9999999999999995e-07" pos="-0.13411224430918664 0 -0.10758393460919149"/>
      <body pos="-0.13411224430918664 0 -0.10758393460919149" name="0/1/">
        <geom name="0/1/geom" class="0/1/" type="capsule" contype="1" conaffinity="1" condim="3" size="0.052608053348221696" rgba="0.57108715937702814 0.24883505893896507 0.30830730069262213 1" friction="0.59999999999999998 0.10000000000000001 0.10000000000000001" fromto="0 0 0 0.70733513978626239 0 -0.28080681552347347"/>
        <site name="0/1/end1" class="0/1/" size="0.0050000000000000001" pos="0.70733513978626239 0 -0.28080681552347347"/>
        <site name="0/1/attach2" class="0/1/" size="9.9999999999999995e-07 9.9999999999999995e-07 9.9999999999999995e-07" pos="0.70409411491933793 0 -0.27952015263805757"/>
        <body pos="0.70409411491933793 0 -0.27952015263805757" name="0/1/2/">
          <joint name="0/1/2/joint/" class="0/1/" type="hinge" axis="0 1 0" limited="true" range="-62.28082055834227 62.28082055834227"/>
          <geom name="0/1/2/geom" class="0/1/2/" type="capsule" contype="1" conaffinity="1" condim="3" size="0.054714777278031534" rgba="0.52889422234298467 0.032843237341793063 0.18322050487620167 1" friction="0.59999999999999998 0.10000000000000001 0.10000000000000001" fromto="0 0 0 0.23589763909007611 0 0.14389278544116013"/>
          <site name="0/1/2/end2" class="0/1/2/" size="0.0050000000000000001" pos="0.23589763909007611 0 0.14389278544116013"/>
          <site name="0/1/2/attach3" class="0/1/2/" size="9.9999999999999995e-07 9.9999999999999995e-07 9.9999999999999995e-07" pos="0.122734347313171 0 0.074865467803394814"/>
          <body pos="0.122734347313171 0 0.074865467803394814" name="0/1/2/3/">
            <joint name="0/1/2/3/joint/" class="0/1/2/" type="hinge" axis="0 1 0" limited="true" range="-44.388219395312845 44.388219395312845"/>
            <geom name="0/1/2/3/geom" class="0/1/2/3/" type="capsule" contype="1" conaffinity="1" condim="3" size="0.0546737885659399" rgba="0.5970945841053189 0.1450557702013725 0.48820225065133493 1" friction="0.59999999999999998 0.10000000000000001 0.10000000000000001" fromto="0 0 0 0.18617497010007722 0 -0.10235235999549042"/>
            <site name="0/1/2/3/end3" class="0/1/2/3/" size="0.0050000000000000001" pos="0.18617497010007722 0 -0.10235235999549042"/>
            <site name="0/1/2/3/attach4" class="0/1/2/3/" size="9.9999999999999995e-07 9.9999999999999995e-07 9.9999999999999995e-07" pos="0.083259822113186749 0 -0.045773281346619905"/>
            <body pos="0.083259822113186749 0 -0.045773281346619905" name="0/1/2/3/4/">
              <geom name="0/1/2/3/4/geom" class="0/1/2/3/4/" type="capsule" contype="1" conaffinity="1" condim="3" size="0.067576333774343703" rgba="0.49306253005969236 0.66372277690465253 0.46784829783833803 1" friction="0.59999999999999998 0.10000000000000001 0.10000000000000001" fromto="0 0 0 0.61722829907859089 0 0.41239501530743006"/>
              <site name="0/1/2/3/4/end4" class="0/1/2/3/4/" size="0.0050000000000000001" pos="0.61722829907859089 0 0.41239501530743006"/>
              <site name="0/1/2/3/4/attach5" class="0/1/2/3/4/" size="9.9999999999999995e-07 9.9999999999999995e-07 9.9999999999999995e-07" pos="0.47351933547420361 0 0.31637728518404168"/>
              <body pos="0.47351933547420361 0 0.31637728518404168" name="0/1/2/3/4/5/">
                <joint name="0/1/2/3/4/5/joint/" class="0/1/2/3/4/" type="hinge" axis="0 1 0" limited="true" range="-59.408219038481803 59.408219038481803"/>
                <geom name="0/1/2/3/4/5/geom" class="0/1/2/3/4/5/" type="capsule" contype="1" conaffinity="1" condim="3" size="0.065548058464457742" rgba="0.72266898594215556 0.79128998300388254 0.70513904532048211 1" friction="0.59999999999999998 0.10000000000000001 0.10000000000000001" fromto="0 0 0 -0.5613167934786345 0 0.20346855063021962"/>
                <site name="0/1/2/3/4/5/end5" class="0/1/2/3/4/5/" size="0.0050000000000000001" pos="-0.5613167934786345 0 0.20346855063021962"/>
              </body>
            </body>
          </body>
        </body>
        <site name="0/1/attach6" class="0/1/" size="9.9999999999999995e-07 9.9999999999999995e-07 9.9999999999999995e-07" pos="0.17384648744696157 0 -0.069015768882448078"/>
        <body pos="0.17384648744696157 0 -0.069015768882448078" name="0/1/6/">
          <joint name="0/1/6/joint/" class="0/1/" type="hinge" axis="0 1 0" limited="true" range="-36.213951394098927 36.213951394098927"/>
          <geom name="0/1/6/geom" class="0/1/6/" type="capsule" contype="1" conaffinity="1" condim="3" size="0.064060709522422571" rgba="0.57531050906482739 0.43576233795967623 0.29471855198055574 1" friction="0.59999999999999998 0.10000000000000001 0.10000000000000001" fromto="0 0 0 -0.37775954416306973 0 -0.37641636861622096"/>
          <site name="0/1/6/end6" class="0/1/6/" size="0.0050000000000000001" pos="-0.37775954416306973 0 -0.37641636861622096"/>
          <site name="0/1/6/attach7" class="0/1/6/" size="9.9999999999999995e-07 9.9999999999999995e-07 9.9999999999999995e-07" pos="-0.32451154234727364 0 -0.32335769732843578"/>
          <body pos="-0.32451154234727364 0 -0.32335769732843578" name="0/1/6/7/">
            <geom name="0/1/6/7/geom" class="0/1/6/7/" type="capsule" contype="1" conaffinity="1" condim="3" size="0.059132640207783527" rgba="0.16398117072865492 0.69893422241575198 0.65921342233973479 1" friction="0.59999999999999998 0.10000000000000001 0.10000000000000001" fromto="0 0 0 -0.40959060443518652 0 0.39457016868165118"/>
            <site name="0/1/6/7/end7" class="0/1/6/7/" size="0.0050000000000000001" pos="-0.40959060443518652 0 0.39457016868165118"/>
            <site name="0/1/6/7/attach8" class="0/1/6/7/" size="9.9999999999999995e-07 9.9999999999999995e-07 9.9999999999999995e-07" pos="-0.40040117648650214 0 0.38571773384418651"/>
            <body pos="-0.40040117648650214 0 0.38571773384418651" name="0/1/6/7/8/">
              <joint name="0/1/6/7/8/joint/" class="0/1/6/7/" type="hinge" axis="0 1 0" limited="true" range="-32.354189556130152 32.354189556130152"/>
              <geom name="0/1/6/7/8/geom" class="0/1/6/7/8/" type="capsule" contype="1" conaffinity="1" condim="3" size="0.049135896626221517" rgba="0.64253977840837262 0.27011728590668149 0.32537615039767043 1" friction="0.59999999999999998 0.10000000000000001 0.10000000000000001" fromto="0 0 0 -0.13693631825207242 0 -0.39260324073193836"/>
              <site name="0/1/6/7/8/end8" class="0/1/6/7/8/" size="0.0050000000000000001" pos="-0.13693631825207242 0 -0.39260324073193836"/>
              <site name="0/1/6/7/8/attach9" class="0/1/6/7/8/" size="9.9999999999999995e-07 9.9999999999999995e-07 9.9999999999999995e-07" pos="-0.13009124836779673 0 -0.37297808464547"/>
              <body pos="-0.13009124836779673 0 -0.37297808464547" name="0/1/6/7/8/9/">
                <joint name="0/1/6/7/8/9/joint/" class="0/1/6/7/8/" type="hinge" axis="0 1 0" limited="true" range="-59.782639961797557 59.782639961797557"/>
                <geom name="0/1/6/7/8/9/geom" class="0/1/6/7/8/9/" type="capsule" contype="1" conaffinity="1" condim="3" size="0.057578463565234966" rgba="0.80652787778529877 0.81129373260302573 0.60875495243448441 1" friction="0.59999999999999998 0.10000000000000001 0.10000000000000001" fromto="0 0 0 0.0683250245844087 0 -0.54387700249761461"/>
                <site name="0/1/6/7/8/9/end9" class="0/1/6/7/8/9/" size="0.0050000000000000001" pos="0.0683250245844087 0 -0.54387700249761461"/>
                <site name="0/1/6/7/8/9/attach10" class="0/1/6/7/8/9/" size="9.9999999999999995e-07 9.9999999999999995e-07 9.9999999999999995e-07" pos="0.065009575208953244 0 -0.5174855495969628"/>
                <body pos="0.065009575208953244 0 -0.5174855495969628" name="0/1/6/7/8/9/10/">
                  <joint name="0/1/6/7/8/9/10/joint/" class="0/1/6/7/8/9/" type="hinge" axis="0 1 0" limited="true" range="-47.140632013374052 47.140632013374052"/>
                  <geom name="0/1/6/7/8/9/10/geom" class="0/1/6/7/8/9/10/" type="capsule" contype="1" conaffinity="1" condim="3" size="0.068681851123614579" rgba="0.84526283063729657 0.28144806360503871 0.86112836542746363 1" friction="0.59999999999999998 0.10000000000000001 0.10000000000000001" fromto="0 0 0 -0.28725830977885186 0 0.08540399552177691"/>
                  <site name="0/1/6/7/8/9/10/end10" class="0/1/6/7/8/9/10/" size="0.0050000000000000001" pos="-0.28725830977885186 0 0.08540399552177691"/>
                </body>
              </body>
            </body>
          </body>
        </body>
      </body>
      <camera name="0/side" class="0/" mode="trackcom" pos="0.40000000000000002 -4 0.20000000000000001" quat="0.70699999999999996 0.70699999999999996 0 0"/>
    </body>
  </worldbody>
  <actuator>
    <motor name="0/1/2/motor" class="0/1/2/" ctrllimited="true" ctrlrange="-1 1" gear="80" joint="0/1/2/joint/"/>
    <motor name="0/1/2/3/motor" class="0/1/2/3/" ctrllimited="true" ctrlrange="-1 1" gear="87" joint="0/1/2/3/joint/"/>
    <motor name="0/1/2/3/4/5/motor" class="0/1/2/3/4/5/" ctrllimited="true" ctrlrange="-1 1" gear="66" joint="0/1/2/3/4/5/joint/"/>
    <motor name="0/1/6/motor" class="0/1/6/" ctrllimited="true" ctrlrange="-1 1" gear="70" joint="0/1/6/joint/"/>
    <motor name="0/1/6/7/8/motor" class="0/1/6/7/8/" ctrllimited="true" ctrlrange="-1 1" gear="60" joint="0/1/6/7/8/joint/"/>
    <motor name="0/1/6/7/8/9/motor" class="0/1/6/7/8/9/" ctrllimited="true" ctrlrange="-1 1" gear="78" joint="0/1/6/7/8/9/joint/"/>
    <motor name="0/1/6/7/8/9/10/motor" class="0/1/6/7/8/9/10/" ctrllimited="true" ctrlrange="-1 1" gear="60" joint="0/1/6/7/8/9/10/joint/"/>
  </actuator>
  <sensor>
    <subtreelinvel name="velocity" body="0/"/>
  </sensor>
</mujoco>
