<mujoco model="morphology">
  <option timestep="0.01"/>
  <default>
    <default class="/"/>
    <default class="0/"/>
    <default class="0/1/"/>
    <default class="0/1/2/"/>
    <default class="0/3/"/>
    <default class="0/3/4/"/>
    <default class="0/3/4/5/"/>
    <default class="0/3/4/5/6/"/>
    <default class="0/3/4/5/6/7/"/>
  </default>
  <asset>
    <texture name="texplane" type="2d" builtin="checker" rgb1="0.10000000000000001 0.20000000000000001 0.29999999999999999" rgb2="0.20000000000000001 0.29999999999999999 0.40000000000000002" width="300" height="300"/>
    <material name="MatPlane" class="/" texture="texplane" texrepeat="20 20" specular="1" shininess="1" reflectance="0.5"/>
  </asset>
  <worldbody>
    <light name="//unnamed_light_0" class="/" directional="true" pos="0 0 1.5" dir="0 0 -1.3" cutoff="100" exponent="1" diffuse="1 1 1" specular="0.10000000000000001 0.10000000000000001 0.10000000000000001"/>
    <geom name="ground" class="/" type="plane" size="15 15 0.5" material="MatPlane" rgba="1 1 1 1"/>
    <site name="body" class="/" size="9.9999999999999995e-07 9.9999999999999995e-07 9.9999999999999995e-07" pos="0 0 0.17978496700525284"/>
    <body pos="0 0 0.17978496700525284" name="0/">
      <joint name="0/rootx/" class="/" type="slide" axis="1 0 0" limited="false" stiffness="0" armature="0" damping="0"/>
      <joint name="0/rootz/" class="/" type="slide" axis="0 0 1" limited="false" stiffness="0" armature="0" damping="0"/>
      <joint name="0/rooty/" class="/" type="hinge" axis="0 1 0" limited="false" stiffness="0" armature="0" damping="0"/>
      <geom name="0/geom" class="0/" type="capsule" contype="1" conaffinity="1" condim="3" size="0.060027669958981851" rgba="0.88109591707776613 0.050200068633106665 0.55277339552650828 1" friction="0.59999999999999998 0.10000000000000001 0.10000000000000001" fromto="0 0 0 0.15232480187164033 0 0.1036447597580421"/>
      <site name="0/end0" class="0/" size="0.0050000000000000001" pos="0.15232480187164033 0 0.1036447597580421"/>
      <site name="0/attach1" class="0/" size="9.9999999999999995e-07 9.9999999999999995e-07 9.9999999999999995e-07" pos="0.13775599653257789 0 0.093731861065410135"/>
      <body pos="0.13775599653257789 0 0.093731861065410135" name="0/1/">
        <joint name="0/1/joint/" class="0/" type="hinge" axis="0 1 0" limited="true" range="-34.656028028236705 34.656028028236705"/>
        <geom name="0/1/geom" class="0/1/" type="capsule" contype="1" conaffinity="1" condim="3" size="0.066634664695346693" rgba="0.19807407056532078 0.60284311776614619 0.37834973532279925 1" friction="0.59999999999999998 0.10000000000000001 0.10000000000000001" fromto="0 0 0 0.17600074494142537 0 0.70493243263506433"/>
        <site name="0/1/end1" class="0/1/" size="0.0050000000000000001" pos="0.17600074494142537 0 0.70493243263506433"/>
        <site name="0/1/attach2" class="0/1/" size="9.9999999999999995e-07 9.9999999999999995e-07 9.9999999999999995e-07" pos="0.12489722775138447 0 0.50024848825191615"/>
        <body pos="0.12489722775138447 0 0.50024848825191615" name="0/1/2/">
          <joint name="0/1/2/joint/" class="0/1/" type="hinge" axis="0 1 0" limited="true" range="-30.145143384815817 30.145143384815817"/>
          <geom name="0/1/2/geom" class="0/1/2/" type="capsule" contype="1" conaffinity="1" condim="3" size="0.045920355430867685" rgba="0.24288881141239393 0.19938526722380134 0.93484648038832963 1" friction="0.59999999999999998 0.10000000000000001 0.10000000000000001" fromto="0 0 0 -0.43131544751275791 0 0.45549909699951363"/>
          <site name="0/1/2/end2" class="0/1/2/" size="0.0050000000000000001" pos="-0.43131544751275791 0 0.45549909699951363"/>
        </body>
      </body>
      <site name="0/attach3" class="0/" size="9.9999999999999995e-07 9.9999999999999995e-07 9.9999999999999995e-07" pos="0.04937567635199841 0 0.033596171145563743"/>
      <body pos="0.04937567635199841 0 0.033596171145563743" name="0/3/">
        <geom name="0/3/geom" class="0/3/" type="capsule" contype="1" conaffinity="1" condim="3" size="0.043039403826401722" rgba="0.86414958540584774 0.89042233591604236 0.4681249441427332 1" friction="0.59999999999999998 0.10000000000000001 0.10000000000000001" fromto="0 0 0 -0.20034343821938205 0 0.0658694084871847"/>
        <site name="0/3/end3" class="0/3/" size="0.0050000000000000001" pos="-0.20034343821938205 0 0.0658694084871847"/>
        <site name="0/3/attach4" class="0/3/" size="9.9999999999999995e-07 9.9999999999999995e-07 9.9999999999999995e-07" pos="-0.13606499565071647 0 0.04473578400661081"/>
        <body pos="-0.13606499565071647 0 0.04473578400661081" name="0/3/4/">
          <geom name="0/3/4/geom" class="0/3/4/" type="capsule" contype="1" conaffinity="1" condim="3" size="0.061859329033862653" rgba="0.9589226094138199 0.60195138883164256 0.98936413528737333 1" friction="0.59999999999999998 0.10000000000000001 0.10000000000000001" fromto="0 0 0 -0.13906345620383986 0 -0.15811692217923401"/>
          <site name="0/3/4/end4" class="0/3/4/" size="0.0050000000000000001" pos="-0.13906345620383986 0 -0.15811692217923401"/>
          <site name="0/3/4/attach5" class="0/3/4/" size="9.9999999999999995e-07 9.9999999999999995e-07 9.9999999999999995e-07" pos="-0.11845623487807352 0 -0.13468624887624675"/>
          <body pos="-0.11845623487807352 0 -0.13468624887624675" name="0/3/4/5/">
            <geom name="0/3/4/5/geom" class="0/3/4/5/" type="capsule" contype="1" conaffinity="1" condim="3" size="0.053177412939174717" rgba="0.60239063448387653 0.47181615242237562 0.78404829108344565 1" friction="0.59999999999999998 0.10000000000000001 0.10000000000000001" fromto="0 0 0 -0.58265234516968289 0 0.24552158019387438"/>
            <site name="0/3/4/5/end5" class="0/3/4/5/" size="0.0050000000000000001" pos="-0.58265234516968289 0 0.24552158019387438"/>
            <site name="0/3/4/5/attach6" class="0/3/4/5/" size="9.9999999999999995e-07 9.9999999999999995e-07 9.9999999999999995e-07" pos="-0.38088474979420672 0 0.16049952671860968"/>
            <body pos="-0.38088474979420672 0 0.16049952671860968" name="0/3/4/5/6/">
              <joint name="0/3/4/5/6/joint/" class="0/3/4/5/" type="hinge" axis="0 1 0" limited="true" range="-63.712055849765392 63.712055849765392"/>
              <geom name="0/3/4/5/6/geom" class="0/3/4/5/6/" type="capsule" contype="1" conaffinity="1" condim="3" size="0.054671986770164563" rgba="0.22878267205117131 0.67960975474352103 0.78785467238547791 1" friction="0.59999999999999998 0.10000000000000001 0.10000000000000001" fromto="0 0 0 0.048059414149043689 0 0.57897689541502695"/>
              <site name="0/3/4/5/6/end6" class="0/3/4/5/6/" size="0.0050000000000000001" pos="0.048059414149043689 0 0.57897689541502695"/>
              <site name="0/3/4/5/6/attach7" class="0/3/4/5/6/" size="9.9999999999999995e-07 9.9999999999999995e-07 9.9999999999999995e-07" pos="0.029769342077077883 0 0.35863444362601432"/>
              <body pos="0.029769342077077883 0 0.35863444362601432" name="0/3/4/5/6/7/">
                <joint name="0/3/4/5/6/7/joint/" class="0/3/4/5/6/" type="hinge" axis="0 1 0" limited="true" range="-46.685072218397238 46.685072218397238"/>
                <geom name="0/3/4/5/6/7/geom" class="0/3/4/5/6/7/" type="capsule" contype="1" conaffinity="1" condim="3" size="0.060847101288948699" rgba="0.91837221529717572 0.68717445679941846 0.54766318746548259 1" friction="0.59999999999999998 0.10000000000000001 0.10000000000000001" fromto="0 0 0 -0.5759884650086553 0 0.49007924685831794"/>
                <site name="0/3/4/5/6/7/end7" class="0/3/4/5/6/7/" size="0.0050000000000000001" pos="-0.5759884650086553 0 0.49007924685831794"/>
              </body>
            </body>
          </body>
        </body>
      </body>
      <camera name="0/side" class="0/" mode="trackcom" pos="0.40000000000000002 -4 0.20000000000000001" quat="0.70699999999999996 0.70699999999999996 0 0"/>
    </body>
  </worldbody>
  <actuator>
    <motor name="0/1/motor" class="0/1/" ctrllimited="true" ctrlrange="-1 1" gear="60" joint="0/1/joint/"/>
    <motor name="0/1/2/motor" class="0/1/2/" ctrllimited="true" ctrlrange="-1 1" gear="67" joint="0/1/2/joint/"/>
    <motor name="0/3/4/5/6/motor" class="0/3/4/5/6/" ctrllimited="true" ctrlrange="-1 1" gear="74" joint="0/3/4/5/6/joint/"/>
    <motor name="0/3/4/5/6/7/motor" class="0/3/4/5/6/7/" ctrllimited="true" ctrlrange="-1 1" gear="87" joint="0/3/4/5/6/7/joint/"/>
  </actuator>
  <sensor>
    <subtreelinvel name="velocity" body="0/"/>
  </sensor>
</mujoco>
