<mujoco model="morphology">
  <option timestep="0.01"/>
  <default>
    <default class="/"/>
    <default class="0/"/>
    <default class="0/1/"/>
    <default class="0/1/2/"/>
    <default class="0/1/2/3/"/>
    <default class="0/1/2/4/"/>
    <default class="0/1/2/4/5/"/>
    <default class="0/1/2/4/6/"/>
    <default class="0/1/2/4/6/7/"/>
    <default class="0/1/2/4/6/7/8/"/>
    <default class="0/1/2/4/6/7/8/9/"/>
    <default class="0/1/2/4/6/7/10/"/>
  </default>
  <asset>
    <texture name="texplane" type="2d" builtin="checker" rgb1="0.10000000000000001 0.20000000000000001 0.29999999999999999" rgb2="0.20000000000000001 0.29999999999999999 0.40000000000000002" width="300" height="300"/>
    <material name="MatPlane" class="/" texture="texplane" texrepeat="20 20" specular="1" shininess="1" reflectance="0.5"/>
  </asset>
  <worldbody>
    <light name="//unnamed_light_0" class="/" directional="true" pos="0 0 1.5" dir="0 0 -1.3" cutoff="100" exponent="1" diffuse="1 1 1" specular="0.10000000000000001 0.10000000000000001 0.10000000000000001"/>
    <geom name="ground" class="/" type="plane" size="15 15 0.5" material="MatPlane" rgba="1 1 1 1"/>
    <site name="body" class="/" size="9.9999999999999995e-07 9.9999999999999995e-07 9.9999999999999995e-07" pos="0 0 0.6772585868835449"/>
    <body pos="0 0 0.6772585868835449" name="0/">
      <joint name="0/rootx/" class="/" type="slide" axis="1 0 0" limited="false" stiffness="0" armature="0" damping="0"/>
      <joint name="0/rootz/" class="/" type="slide" axis="0 0 1" limited="false" stiffness="0" armature="0" damping="0"/>
      <joint name="0/rooty/" class="/" type="hinge" axis="0 1 0" limited="false" stiffness="0" armature="0" damping="0"/>
      <geom name="0/geom" class="0/" type="capsule" contype="1" conaffinity="1" condim="3" size="0.054000066251820696" rgba="0.29962466764085438 0.13343454836120006 0.7421916297217398 1" friction="0.59999999999999998 0.10000000000000001 0.10000000000000001" fromto="0 0 0 -0.36900259194714141 0 -0.57725859259694179"/>
      <site name="0/end0" class="0/" size="0.0050000000000000001" pos="-0.36900259194714141 0 -0.57725859259694179"/>
      <site name="0/attach1" class="0/" size="9.9999999999999995e-07 9.9999999999999995e-07 9.9999999999999995e-07" pos="-0.10209971278339701 0 -0.15972228323626095"/>
      <body pos="-0.10209971278339701 0 -0.15972228323626095" name="0/1/">
        <joint name="0/1/joint/" class="0/" type="hinge" axis="0 1 0" limited="true" stiffness="100" range="-47.684209056404413 47.684209056404413" armature="0.20000000000000001" damping="3.5"/>
        <geom name="0/1/geom" class="0/1/" type="capsule" contype="1" conaffinity="1" condim="3" size="0.069537511969008564" rgba="0.28915148401251423 0.10095317394214254 0.99464592419451514 1" friction="0.59999999999999998 0.10000000000000001 0.10000000000000001" fromto="0 0 0 -0.68822850068052799 0 0.26258387956724727"/>
        <site name="0/1/end1" class="0/1/" size="0.0050000000000000001" pos="-0.68822850068052799 0 0.26258387956724727"/>
        <site name="0/1/attach2" class="0/1/" size="9.9999999999999995e-07 9.9999999999999995e-07 9.9999999999999995e-07" pos="-0.37563136706172984 0 0.14331685123863164"/>
        <body pos="-0.37563136706172984 0 0.14331685123863164" name="0/1/2/">
          <joint name="0/1/2/joint/" class="0/1/" type="hinge" axis="0 1 0" limited="true" stiffness="100" range="-48.51196327187791 48.51196327187791" armature="0.20000000000000001" damping="3.5"/>
          <geom name="0/1/2/geom" class="0/1/2/" type="capsule" contype="1" conaffinity="1" condim="3" size="0.064855422542972579" rgba="0.85827830886953449 0.98534121432123223 0.071983260125563109 1" friction="0.59999999999999998 0.10000000000000001 0.10000000000000001" fromto="0 0 0 0.26819069396587492 0 0.65473706352223959"/>
          <site name="0/1/2/end2" class="0/1/2/" size="0.0050000000000000001" pos="0.26819069396587492 0 0.65473706352223959"/>
          <site name="0/1/2/attach3" class="0/1/2/" size="9.9999999999999995e-07 9.9999999999999995e-07 9.9999999999999995e-07" pos="0.26046864187984892 0 0.63588512786255635"/>
          <body pos="0.26046864187984892 0 0.63588512786255635" name="0/1/2/3/">
            <joint name="0/1/2/3/joint/" class="0/1/2/" type="hinge" axis="0 1 0" limited="true" stiffness="100" range="-40.300518360111568 40.300518360111568" armature="0.20000000000000001" damping="3.5"/>
            <geom name="0/1/2/3/geom" class="0/1/2/3/" type="capsule" contype="1" conaffinity="1" condim="3" size="0.065986301447818349" rgba="0.99208324487129185 0.0070108510564010906 0.86295262867620304 1" friction="0.59999999999999998 0.10000000000000001 0.10000000000000001" fromto="0 0 0 -0.62606299978524793 0 0.54322209927988108"/>
            <site name="0/1/2/3/end3" class="0/1/2/3/" size="0.0050000000000000001" pos="-0.62606299978524793 0 0.54322209927988108"/>
          </body>
          <site name="0/1/2/attach4" class="0/1/2/" size="9.9999999999999995e-07 9.9999999999999995e-07 9.9999999999999995e-07" pos="0.061738590623726407 0 0.15072314006586573"/>
          <body pos="0.061738590623726407 0 0.15072314006586573" name="0/1/2/4/">
            <joint name="0/1/2/4/joint/" class="0/1/2/" type="hinge" axis="0 1 0" limited="true" stiffness="100" range="-32.669762618796071 32.669762618796071" armature="0.20000000000000001" damping="3.5"/>
            <geom name="0/1/2/4/geom" class="0/1/2/4/" type="capsule" contype="1" conaffinity="1" condim="3" size="0.044268332925390806" rgba="0.68153670468044936 0.85852556221708076 0.29632679112224625 1" friction="0.59999999999999998 0.10000000000000001 0.10000000000000001" fromto="0 0 0 -0.51255079219457211 0 0.46192132412555287"/>
            <site name="0/1/2/4/end4" class="0/1/2/4/" size="0.0050000000000000001" pos="-0.51255079219457211 0 0.46192132412555287"/>
            <site name="0/1/2/4/attach5" class="0/1/2/4/" size="9.9999999999999995e-07 9.9999999999999995e-07 9.9999999999999995e-07" pos="-0.43988382130980469 0 0.39643235420792872"/>
            <body pos="-0.43988382130980469 0 0.39643235420792872" name="0/1/2/4/5/">
              <joint name="0/1/2/4/5/joint/" class="0/1/2/4/" type="hinge" axis="0 1 0" limited="true" stiffness="100" range="-49.788959233953278 49.788959233953278" armature="0.20000000000000001" damping="3.5"/>
              <geom name="0/1/2/4/5/geom" class="0/1/2/4/5/" type="capsule" contype="1" conaffinity="1" condim="3" size="0.045566597225151037" rgba="0.45836375378730387 0.58722550017293662 0.81688864670368244 1" friction="0.59999999999999998 0.10000000000000001 0.10000000000000001" fromto="0 0 0 -0.29108907156514618 0 -0.60383358813007715"/>
              <site name="0/1/2/4/5/end5" class="0/1/2/4/5/" size="0.0050000000000000001" pos="-0.29108907156514618 0 -0.60383358813007715"/>
            </body>
            <site name="0/1/2/4/attach6" class="0/1/2/4/" size="9.9999999999999995e-07 9.9999999999999995e-07 9.9999999999999995e-07" pos="-0.50936559389218961 0 0.45905075785222937"/>
            <body pos="-0.50936559389218961 0 0.45905075785222937" name="0/1/2/4/6/">
              <joint name="0/1/2/4/6/joint/" class="0/1/2/4/" type="hinge" axis="0 1 0" limited="true" stiffness="100" range="-69.204425022310829 69.204425022310829" armature="0.20000000000000001" damping="3.5"/>
              <geom name="0/1/2/4/6/geom" class="0/1/2/4/6/" type="capsule" contype="1" conaffinity="1" condim="3" size="0.068503744037054337" rgba="0.76343289472683762 0.30745559608225637 0.27954172021598511 1" friction="0.59999999999999998 0.10000000000000001 0.10000000000000001" fromto="0 0 0 -0.60126130587521631 0 -0.63958252674042093"/>
              <site name="0/1/2/4/6/end6" class="0/1/2/4/6/" size="0.0050000000000000001" pos="-0.60126130587521631 0 -0.63958252674042093"/>
              <site name="0/1/2/4/6/attach7" class="0/1/2/4/6/" size="9.9999999999999995e-07 9.9999999999999995e-07 9.9999999999999995e-07" pos="-0.21681339341397368 0 -0.23063193429522527"/>
              <body pos="-0.21681339341397368 0 -0.23063193429522527" name="0/1/2/4/6/7/">
                <joint name="0/1/2/4/6/7/joint/" class="0/1/2/4/6/" type="hinge" axis="0 1 0" limited="true" stiffness="100" range="-45.279229914956389 45.279229914956389" armature="0.20000000000000001" damping="3.5"/>
                <geom name="0/1/2/4/6/7/geom" class="0/1/2/4/6/7/" type="capsule" contype="1" conaffinity="1" condim="3" size="0.054952846772951987" rgba="0.011491596648628977 0.85397575743392018 0.42604675606060061 1" friction="0.59999999999999998 0.10000000000000001 0.10000000000000001" fromto="0 0 0 -0.022988064994179491 0 0.56824087181831606"/>
                <site name="0/1/2/4/6/7/end7" class="0/1/2/4/6/7/" size="0.0050000000000000001" pos="-0.022988064994179491 0 0.56824087181831606"/>
                <site name="0/1/2/4/6/7/attach8" class="0/1/2/4/6/7/" size="9.9999999999999995e-07 9.9999999999999995e-07 9.9999999999999995e-07" pos="-0.019305494464262975 0 0.47721158818865705"/>
                <body pos="-0.019305494464262975 0 0.47721158818865705" name="0/1/2/4/6/7/8/">
                  <joint name="0/1/2/4/6/7/8/joint/" class="0/1/2/4/6/7/" type="hinge" axis="0 1 0" limited="true" stiffness="100" range="-45.737149737813667 45.737149737813667" armature="0.20000000000000001" damping="3.5"/>
                  <geom name="0/1/2/4/6/7/8/geom" class="0/1/2/4/6/7/8/" type="capsule" contype="1" conaffinity="1" condim="3" size="0.040586587336272018" rgba="0.48640908667767568 0.82589595408683736 0.60102232281765389 1" friction="0.59999999999999998 0.10000000000000001 0.10000000000000001" fromto="0 0 0 -0.41803841188013574 0 0.31109348854470609"/>
                  <site name="0/1/2/4/6/7/8/end8" class="0/1/2/4/6/7/8/" size="0.0050000000000000001" pos="-0.41803841188013574 0 0.31109348854470609"/>
                  <site name="0/1/2/4/6/7/8/attach9" class="0/1/2/4/6/7/8/" size="9.9999999999999995e-07 9.9999999999999995e-07 9.9999999999999995e-07" pos="-0.10571874180326571 0 0.078673182314081422"/>
                  <body pos="-0.10571874180326571 0 0.078673182314081422" name="0/1/2/4/6/7/8/9/">
                    <joint name="0/1/2/4/6/7/8/9/joint/" class="0/1/2/4/6/7/8/" type="hinge" axis="0 1 0" limited="true" stiffness="100" range="-68.154439622176611 68.154439622176611" armature="0.20000000000000001" damping="3.5"/>
                    <geom name="0/1/2/4/6/7/8/9/geom" class="0/1/2/4/6/7/8/9/" type="capsule" contype="1" conaffinity="1" condim="3" size="0.052981611847396116" rgba="0.47253640652659168 0.86878966263852364 0.057712404394591355 1" friction="0.59999999999999998 0.10000000000000001 0.10000000000000001" fromto="0 0 0 -0.53955051203150761 0 -0.59323466954748616"/>
                    <site name="0/1/2/4/6/7/8/9/end9" class="0/1/2/4/6/7/8/9/" size="0.0050000000000000001" pos="-0.53955051203150761 0 -0.59323466954748616"/>
                  </body>
                </body>
                <site name="0/1/2/4/6/7/attach10" class="0/1/2/4/6/7/" size="9.9999999999999995e-07 9.9999999999999995e-07 9.9999999999999995e-07" pos="-2.0729909298500896e-05 0 0.0005124216298969626"/>
                <body pos="-2.0729909298500896e-05 0 0.0005124216298969626" name="0/1/2/4/6/7/10/">
                  <geom name="0/1/2/4/6/7/10/geom" class="0/1/2/4/6/7/10/" type="capsule" contype="1" conaffinity="1" condim="3" size="0.063087649717331246" rgba="0.036249110600775847 0.59732675797410206 0.46705720538156714 1" friction="0.59999999999999998 0.10000000000000001 0.10000000000000001" fromto="0 0 0 -0.35823142411678072 0 0.090972064600550739"/>
                  <site name="0/1/2/4/6/7/10/end10" class="0/1/2/4/6/7/10/" size="0.0050000000000000001" pos="-0.35823142411678072 0 0.090972064600550739"/>
                </body>
              </body>
            </body>
          </body>
        </body>
      </body>
      <camera name="0/side" class="0/" mode="trackcom" pos="0.40000000000000002 -4 0.20000000000000001" quat="0.70699999999999996 0.70699999999999996 0 0"/>
    </body>
  </worldbody>
  <actuator>
    <motor name="0/1/motor" class="0/1/" ctrllimited="true" ctrlrange="-1 1" gear="83" joint="0/1/joint/"/>
    <motor name="0/1/2/motor" class="0/1/2/" ctrllimited="true" ctrlrange="-1 1" gear="63" joint="0/1/2/joint/"/>
    <motor name="0/1/2/3/motor" class="0/1/2/3/" ctrllimited="true" ctrlrange="-1 1" gear="72" joint="0/1/2/3/joint/"/>
    <motor name="0/1/2/4/motor" class="0/1/2/4/" ctrllimited="true" ctrlrange="-1 1" gear="83" joint="0/1/2/4/joint/"/>
    <motor name="0/1/2/4/5/motor" class="0/1/2/4/5/" ctrllimited="true" ctrlrange="-1 1" gear="73" joint="0/1/2/4/5/joint/"/>
    <motor name="0/1/2/4/6/motor" class="0/1/2/4/6/" ctrllimited="true" ctrlrange="-1 1" gear="52" joint="0/1/2/4/6/joint/"/>
    <motor name="0/1/2/4/6/7/motor" class="0/1/2/4/6/7/" ctrllimited="true" ctrlrange="-1 1" gear="89" joint="0/1/2/4/6/7/joint/"/>
    <motor name="0/1/2/4/6/7/8/motor" class="0/1/2/4/6/7/8/" ctrllimited="true" ctrlrange="-1 1" gear="63" joint="0/1/2/4/6/7/8/joint/"/>
    <motor name="0/1/2/4/6/7/8/9/motor" class="0/1/2/4/6/7/8/9/" ctrllimited="true" ctrlrange="-1 1" gear="66" joint="0/1/2/4/6/7/8/9/joint/"/>
  </actuator>
  <sensor>
    <subtreelinvel name="velocity" body="0/"/>
  </sensor>
</mujoco>
