<mujoco model="morphology">
  <option timestep="0.01"/>
  <default>
    <default class="/"/>
    <default class="0/"/>
    <default class="0/1/"/>
    <default class="0/1/2/"/>
    <default class="0/1/3/"/>
    <default class="0/1/3/4/"/>
    <default class="0/1/5/"/>
    <default class="0/1/5/6/"/>
    <default class="0/1/5/6/7/"/>
    <default class="0/1/5/6/7/8/"/>
    <default class="0/9/"/>
    <default class="0/9/10/"/>
  </default>
  <asset>
    <texture name="texplane" type="2d" builtin="checker" rgb1="0.10000000000000001 0.20000000000000001 0.29999999999999999" rgb2="0.20000000000000001 0.29999999999999999 0.40000000000000002" width="300" height="300"/>
    <material name="MatPlane" class="/" texture="texplane" texrepeat="20 20" specular="1" shininess="1" reflectance="0.5"/>
  </asset>
  <worldbody>
    <light name="//unnamed_light_0" class="/" directional="true" pos="0 0 1.5" dir="0 0 -1.3" cutoff="100" exponent="1" diffuse="1 1 1" specular="0.10000000000000001 0.10000000000000001 0.10000000000000001"/>
    <geom name="ground" class="/" type="plane" size="15 15 0.5" material="MatPlane" rgba="1 1 1 1"/>
    <site name="body" class="/" size="9.9999999999999995e-07 9.9999999999999995e-07 9.9999999999999995e-07" pos="0 0 1.162085509300232"/>
    <body pos="0 0 1.162085509300232" name="0/">
      <joint name="0/rootx/" class="/" type="slide" axis="1 0 0" limited="false" stiffness="0" armature="0" damping="0"/>
      <joint name="0/rootz/" class="/" type="slide" axis="0 0 1" limited="false" stiffness="0" armature="0" damping="0"/>
      <joint name="0/rooty/" class="/" type="hinge" axis="0 1 0" limited="false" stiffness="0" armature="0" damping="0"/>
      <geom name="0/geom" class="0/" type="capsule" contype="1" conaffinity="1" condim="3" size="0.044213626129993057" rgba="0.43611769171869363 0.72291899142580163 0.68715069064126455 1" friction="0.59999999999999998 0.10000000000000001 0.10000000000000001" fromto="0 0 0 -0.4863334777366311 0 0.38181447527541024"/>
      <site name="0/end0" class="0/" size="0.0050000000000000001" pos="-0.4863334777366311 0 0.38181447527541024"/>
      <site name="0/attach1" class="0/" size="9.9999999999999995e-07 9.9999999999999995e-07 9.9999999999999995e-07" pos="-0.2286960978926651 0 0.17954651409317282"/>
      <body pos="-0.2286960978926651 0 0.17954651409317282" name="0/1/">
        <joint name="0/1/joint/" class="0/" type="hinge" axis="0 1 0" limited="true" range="-38.246310311540078 38.246310311540078"/>
        <geom name="0/1/geom" class="0/1/" type="capsule" contype="1" conaffinity="1" condim="3" size="0.061633629603623286" rgba="0.40808767231598353 0.89652572163585709 0.49359283205904858 1" friction="0.59999999999999998 0.10000000000000001 0.10000000000000001" fromto="0 0 0 -0.5394062059058321 0 -0.65797688318609737"/>
        <site name="0/1/end1" class="0/1/" size="0.0050000000000000001" pos="-0.5394062059058321 0 -0.65797688318609737"/>
        <site name="0/1/attach2" class="0/1/" size="9.9999999999999995e-07 9.9999999999999995e-07 9.9999999999999995e-07" pos="-0.50536355074524908 0 -0.61645107222453432"/>
        <body pos="-0.50536355074524908 0 -0.61645107222453432" name="0/1/2/">
          <joint name="0/1/2/joint/" class="0/1/" type="hinge" axis="0 1 0" limited="true" range="-59.629684333171326 59.629684333171326"/>
          <geom name="0/1/2/geom" class="0/1/2/" type="capsule" contype="1" conaffinity="1" condim="3" size="0.056386735925334566" rgba="0.067178125633119756 0.78494187199011356 0.082319937139273547 1" friction="0.59999999999999998 0.10000000000000001 0.10000000000000001" fromto="0 0 0 -0.30774170414302604 0 0.29995908734921173"/>
          <site name="0/1/2/end2" class="0/1/2/" size="0.0050000000000000001" pos="-0.30774170414302604 0 0.29995908734921173"/>
        </body>
        <site name="0/1/attach3" class="0/1/" size="9.9999999999999995e-07 9.9999999999999995e-07 9.9999999999999995e-07" pos="-0.03719192836601614 0 -0.045367348091327024"/>
        <body pos="-0.03719192836601614 0 -0.045367348091327024" name="0/1/3/">
          <joint name="0/1/3/joint/" class="0/1/" type="hinge" axis="0 1 0" limited="true" range="-61.024093706052582 61.024093706052582"/>
          <geom name="0/1/3/geom" class="0/1/3/" type="capsule" contype="1" conaffinity="1" condim="3" size="0.057741098106566885" rgba="0.075439985106505181 0.24413362490618584 0.42177563625869541 1" friction="0.59999999999999998 0.10000000000000001 0.10000000000000001" fromto="0 0 0 -0.069250124053930051 0 0.01553781449488012"/>
          <site name="0/1/3/end3" class="0/1/3/" size="0.0050000000000000001" pos="-0.069250124053930051 0 0.01553781449488012"/>
          <site name="0/1/3/attach4" class="0/1/3/" size="9.9999999999999995e-07 9.9999999999999995e-07 9.9999999999999995e-07" pos="-0.016904947527017562 0 0.0037930031506647481"/>
          <body pos="-0.016904947527017562 0 0.0037930031506647481" name="0/1/3/4/">
            <joint name="0/1/3/4/joint/" class="0/1/3/" type="hinge" axis="0 1 0" limited="true" range="-38.554357080257823 38.554357080257823"/>
            <geom name="0/1/3/4/geom" class="0/1/3/4/" type="capsule" contype="1" conaffinity="1" condim="3" size="0.051079293495797866" rgba="0.12925743649375099 0.74007739851924448 0.059654641393121044 1" friction="0.59999999999999998 0.10000000000000001 0.10000000000000001" fromto="0 0 0 0.57515577496199466 0 -0.61088787587882565"/>
            <site name="0/1/3/4/end4" class="0/1/3/4/" size="0.0050000000000000001" pos="0.57515577496199466 0 -0.61088787587882565"/>
          </body>
        </body>
        <site name="0/1/attach5" class="0/1/" size="9.9999999999999995e-07 9.9999999999999995e-07 9.9999999999999995e-07" pos="-0.24626816046623809 0 -0.30040209934076523"/>
        <body pos="-0.24626816046623809 0 -0.30040209934076523" name="0/1/5/">
          <joint name="0/1/5/joint/" class="0/1/" type="hinge" axis="0 1 0" limited="true" range="-60.917140854640266 60.917140854640266"/>
          <geom name="0/1/5/geom" class="0/1/5/" type="capsule" contype="1" conaffinity="1" condim="3" size="0.064066215507002977" rgba="0.81053972324756274 0.61211902544544583 0.59587553177024533 1" friction="0.59999999999999998 0.10000000000000001 0.10000000000000001" fromto="0 0 0 0.56913214151053082 0 -0.71589687064657404"/>
          <site name="0/1/5/end5" class="0/1/5/" size="0.0050000000000000001" pos="0.56913214151053082 0 -0.71589687064657404"/>
          <site name="0/1/5/attach6" class="0/1/5/" size="9.9999999999999995e-07 9.9999999999999995e-07 9.9999999999999995e-07" pos="0.14780960788296188 0 -0.18592595289744612"/>
          <body pos="0.14780960788296188 0 -0.18592595289744612" name="0/1/5/6/">
            <joint name="0/1/5/6/joint/" class="0/1/5/" type="hinge" axis="0 1 0" limited="true" range="-31.970463175578221 31.970463175578221"/>
            <geom name="0/1/5/6/geom" class="0/1/5/6/" type="capsule" contype="1" conaffinity="1" condim="3" size="0.042892673717612191" rgba="0.52521016658361952 0.83577594686702605 0.92333151637185484 1" friction="0.59999999999999998 0.10000000000000001 0.10000000000000001" fromto="0 0 0 -0.35918298365266704 0 -0.21365071266820257"/>
            <site name="0/1/5/6/end6" class="0/1/5/6/" size="0.0050000000000000001" pos="-0.35918298365266704 0 -0.21365071266820257"/>
            <site name="0/1/5/6/attach7" class="0/1/5/6/" size="9.9999999999999995e-07 9.9999999999999995e-07 9.9999999999999995e-07" pos="-0.09942316688396953 0 -0.059139300655263655"/>
            <body pos="-0.09942316688396953 0 -0.059139300655263655" name="0/1/5/6/7/">
              <joint name="0/1/5/6/7/joint/" class="0/1/5/6/" type="hinge" axis="0 1 0" limited="true" range="-57.270832031409377 57.270832031409377"/>
              <geom name="0/1/5/6/7/geom" class="0/1/5/6/7/" type="capsule" contype="1" conaffinity="1" condim="3" size="0.056293252388309289" rgba="0.009066488197405298 0.83942967735515683 0.30665381599917241 1" friction="0.59999999999999998 0.10000000000000001 0.10000000000000001" fromto="0 0 0 0.56718696171004601 0 -0.69616462246408495"/>
              <site name="0/1/5/6/7/end7" class="0/1/5/6/7/" size="0.0050000000000000001" pos="0.56718696171004601 0 -0.69616462246408495"/>
              <site name="0/1/5/6/7/attach8" class="0/1/5/6/7/" size="9.9999999999999995e-07 9.9999999999999995e-07 9.9999999999999995e-07" pos="0.51674121907032922 0 -0.6342475761451466"/>
              <body pos="0.51674121907032922 0 -0.6342475761451466" name="0/1/5/6/7/8/">
                <joint name="0/1/5/6/7/8/joint/" class="0/1/5/6/7/" type="hinge" axis="0 1 0" limited="true" range="-69.016583082958491 69.016583082958491"/>
                <geom name="0/1/5/6/7/8/geom" class="0/1/5/6/7/8/" type="capsule" contype="1" conaffinity="1" condim="3" size="0.058851881836423134" rgba="0.43119832598813379 0.11600784896396021 0.25645078459450565 1" friction="0.59999999999999998 0.10000000000000001 0.10000000000000001" fromto="0 0 0 -0.49793368598555876 0 -0.049739186846126104"/>
                <site name="0/1/5/6/7/8/end8" class="0/1/5/6/7/8/" size="0.0050000000000000001" pos="-0.49793368598555876 0 -0.049739186846126104"/>
              </body>
            </body>
          </body>
        </body>
      </body>
      <site name="0/attach9" class="0/" size="9.9999999999999995e-07 9.9999999999999995e-07 9.9999999999999995e-07" pos="-0.40505284685090087 0 0.31800204439748575"/>
      <body pos="-0.40505284685090087 0 0.31800204439748575" name="0/9/">
        <geom name="0/9/geom" class="0/9/" type="capsule" contype="1" conaffinity="1" condim="3" size="0.049675860435743707" rgba="0.47073961311195889 0.14146023949259656 0.98381701817091138 1" friction="0.59999999999999998 0.10000000000000001 0.10000000000000001" fromto="0 0 0 -0.19734702573960961 0 -0.073575670143367855"/>
        <site name="0/9/end9" class="0/9/" size="0.0050000000000000001" pos="-0.19734702573960961 0 -0.073575670143367855"/>
        <site name="0/9/attach10" class="0/9/" size="9.9999999999999995e-07 9.9999999999999995e-07 9.9999999999999995e-07" pos="-0.040845666898188103 0 -0.015228237178766778"/>
        <body pos="-0.040845666898188103 0 -0.015228237178766778" name="0/9/10/">
          <geom name="0/9/10/geom" class="0/9/10/" type="capsule" contype="1" conaffinity="1" condim="3" size="0.044487556284884364" rgba="0.8957004158764611 0.96318014556198395 0.40561987354483542 1" friction="0.59999999999999998 0.10000000000000001 0.10000000000000001" fromto="0 0 0 -0.038852927243991253 0 -0.15771347592576324"/>
          <site name="0/9/10/end10" class="0/9/10/" size="0.0050000000000000001" pos="-0.038852927243991253 0 -0.15771347592576324"/>
        </body>
      </body>
      <camera name="0/side" class="0/" mode="trackcom" pos="0.40000000000000002 -4 0.20000000000000001" quat="0.70699999999999996 0.70699999999999996 0 0"/>
    </body>
  </worldbody>
  <actuator>
    <motor name="0/1/motor" class="0/1/" ctrllimited="true" ctrlrange="-1 1" gear="75" joint="0/1/joint/"/>
    <motor name="0/1/2/motor" class="0/1/2/" ctrllimited="true" ctrlrange="-1 1" gear="58" joint="0/1/2/joint/"/>
    <motor name="0/1/3/motor" class="0/1/3/" ctrllimited="true" ctrlrange="-1 1" gear="66" joint="0/1/3/joint/"/>
    <motor name="0/1/3/4/motor" class="0/1/3/4/" ctrllimited="true" ctrlrange="-1 1" gear="76" joint="0/1/3/4/joint/"/>
    <motor name="0/1/5/motor" class="0/1/5/" ctrllimited="true" ctrlrange="-1 1" gear="51" joint="0/1/5/joint/"/>
    <motor name="0/1/5/6/motor" class="0/1/5/6/" ctrllimited="true" ctrlrange="-1 1" gear="68" joint="0/1/5/6/joint/"/>
    <motor name="0/1/5/6/7/motor" class="0/1/5/6/7/" ctrllimited="true" ctrlrange="-1 1" gear="59" joint="0/1/5/6/7/joint/"/>
    <motor name="0/1/5/6/7/8/motor" class="0/1/5/6/7/8/" ctrllimited="true" ctrlrange="-1 1" gear="57" joint="0/1/5/6/7/8/joint/"/>
  </actuator>
  <sensor>
    <subtreelinvel name="velocity" body="0/"/>
  </sensor>
</mujoco>
