<mujoco model="morphology">
  <option timestep="0.01"/>
  <default>
    <default class="/"/>
    <default class="0/"/>
    <default class="0/1/"/>
    <default class="0/2/"/>
    <default class="0/2/3/"/>
    <default class="0/2/3/4/"/>
    <default class="0/2/3/4/5/"/>
    <default class="0/2/3/4/6/"/>
    <default class="0/2/3/4/6/7/"/>
    <default class="0/2/3/4/6/7/8/"/>
    <default class="0/2/3/4/6/7/8/9/"/>
    <default class="0/2/3/10/"/>
  </default>
  <asset>
    <texture name="texplane" type="2d" builtin="checker" rgb1="0.10000000000000001 0.20000000000000001 0.29999999999999999" rgb2="0.20000000000000001 0.29999999999999999 0.40000000000000002" width="300" height="300"/>
    <material name="MatPlane" class="/" texture="texplane" texrepeat="20 20" specular="1" shininess="1" reflectance="0.5"/>
  </asset>
  <worldbody>
    <light name="//unnamed_light_0" class="/" directional="true" pos="0 0 1.5" dir="0 0 -1.3" cutoff="100" exponent="1" diffuse="1 1 1" specular="0.10000000000000001 0.10000000000000001 0.10000000000000001"/>
    <geom name="ground" class="/" type="plane" size="15 15 0.5" material="MatPlane" rgba="1 1 1 1"/>
    <site name="body" class="/" size="9.9999999999999995e-07 9.9999999999999995e-07 9.9999999999999995e-07" pos="0 0 1.2862610578536988"/>
    <body pos="0 0 1.2862610578536988" name="0/">
      <joint name="0/rootx/" class="/" type="slide" axis="1 0 0" limited="false" stiffness="0" armature="0" damping="0"/>
      <joint name="0/rootz/" class="/" type="slide" axis="0 0 1" limited="false" stiffness="0" armature="0" damping="0"/>
      <joint name="0/rooty/" class="/" type="hinge" axis="0 1 0" limited="false" stiffness="0" armature="0" damping="0"/>
      <geom name="0/geom" class="0/" type="capsule" contype="1" conaffinity="1" condim="3" size="0.057774630866482851" rgba="0.98151633432276808 0.30668370078729978 0.69512300499556878 1" friction="0.59999999999999998 0.10000000000000001 0.10000000000000001" fromto="0 0 0 -0.38623626517202198 0 0.18634600500926646"/>
      <site name="0/end0" class="0/" size="0.0050000000000000001" pos="-0.38623626517202198 0 0.18634600500926646"/>
      <site name="0/attach1" class="0/" size="9.9999999999999995e-07 9.9999999999999995e-07 9.9999999999999995e-07" pos="-0.28282358858586099 0 0.1364528673450347"/>
      <body pos="-0.28282358858586099 0 0.1364528673450347" name="0/1/">
        <joint name="0/1/joint/" class="0/" type="hinge" axis="0 1 0" limited="true" stiffness="100" range="-61.113891474830041 61.113891474830041" armature="0.20000000000000001" damping="3.5"/>
        <geom name="0/1/geom" class="0/1/" type="capsule" contype="1" conaffinity="1" condim="3" size="0.042580480104032072" rgba="0.49418731377885228 0.46916454947501063 0.496617996207673 1" friction="0.59999999999999998 0.10000000000000001 0.10000000000000001" fromto="0 0 0 -0.58397402072253002 0 -0.54434296083361489"/>
        <site name="0/1/end1" class="0/1/" size="0.0050000000000000001" pos="-0.58397402072253002 0 -0.54434296083361489"/>
      </body>
      <site name="0/attach2" class="0/" size="9.9999999999999995e-07 9.9999999999999995e-07 9.9999999999999995e-07" pos="-0.015387793585101539 0 0.0074240927614960825"/>
      <body pos="-0.015387793585101539 0 0.0074240927614960825" name="0/2/">
        <geom name="0/2/geom" class="0/2/" type="capsule" contype="1" conaffinity="1" condim="3" size="0.057621225961935502" rgba="0.91120929006031037 0.90469808745214142 0.44575858257152012 1" friction="0.59999999999999998 0.10000000000000001 0.10000000000000001" fromto="0 0 0 -0.14832700567616053 0 -0.21582790009829589"/>
        <site name="0/2/end2" class="0/2/" size="0.0050000000000000001" pos="-0.14832700567616053 0 -0.21582790009829589"/>
        <site name="0/2/attach3" class="0/2/" size="9.9999999999999995e-07 9.9999999999999995e-07 9.9999999999999995e-07" pos="-0.11432255833566686 0 -0.16634865368564219"/>
        <body pos="-0.11432255833566686 0 -0.16634865368564219" name="0/2/3/">
          <geom name="0/2/3/geom" class="0/2/3/" type="capsule" contype="1" conaffinity="1" condim="3" size="0.067630636601780661" rgba="0.4677564619610427 0.88106254917329641 0.93196335296090915 1" friction="0.59999999999999998 0.10000000000000001 0.10000000000000001" fromto="0 0 0 0.10673355045315724 0 -0.34723254727667835"/>
          <site name="0/2/3/end3" class="0/2/3/" size="0.0050000000000000001" pos="0.10673355045315724 0 -0.34723254727667835"/>
          <site name="0/2/3/attach4" class="0/2/3/" size="9.9999999999999995e-07 9.9999999999999995e-07 9.9999999999999995e-07" pos="0.086338658442418836 0 -0.28088255447446675"/>
          <body pos="0.086338658442418836 0 -0.28088255447446675" name="0/2/3/4/">
            <joint name="0/2/3/4/joint/" class="0/2/3/" type="hinge" axis="0 1 0" limited="true" stiffness="100" range="-56.483084753675499 56.483084753675499" armature="0.20000000000000001" damping="3.5"/>
            <geom name="0/2/3/4/geom" class="0/2/3/4/" type="capsule" contype="1" conaffinity="1" condim="3" size="0.062837835924495544" rgba="0.20754447370557605 0.9259312830282872 0.46371785315854619 1" friction="0.59999999999999998 0.10000000000000001 0.10000000000000001" fromto="0 0 0 -0.18472183589633651 0 -0.079300611487237438"/>
            <site name="0/2/3/4/end4" class="0/2/3/4/" size="0.0050000000000000001" pos="-0.18472183589633651 0 -0.079300611487237438"/>
            <site name="0/2/3/4/attach5" class="0/2/3/4/" size="9.9999999999999995e-07 9.9999999999999995e-07 9.9999999999999995e-07" pos="-0.17483131579641847 0 -0.075054636516035514"/>
            <body pos="-0.17483131579641847 0 -0.075054636516035514" name="0/2/3/4/5/">
              <joint name="0/2/3/4/5/joint/" class="0/2/3/4/" type="hinge" axis="0 1 0" limited="true" stiffness="100" range="-69.752430503523087 69.752430503523087" armature="0.20000000000000001" damping="3.5"/>
              <geom name="0/2/3/4/5/geom" class="0/2/3/4/5/" type="capsule" contype="1" conaffinity="1" condim="3" size="0.050875440242386889" rgba="0.76964265646523977 0.53019448450491169 0.84408485404533429 1" friction="0.59999999999999998 0.10000000000000001 0.10000000000000001" fromto="0 0 0 -0.59056003727005801 0 -0.43668837953609674"/>
              <site name="0/2/3/4/5/end5" class="0/2/3/4/5/" size="0.0050000000000000001" pos="-0.59056003727005801 0 -0.43668837953609674"/>
            </body>
            <site name="0/2/3/4/attach6" class="0/2/3/4/" size="9.9999999999999995e-07 9.9999999999999995e-07 9.9999999999999995e-07" pos="-0.043091674230091054 0 -0.018499145484742466"/>
            <body pos="-0.043091674230091054 0 -0.018499145484742466" name="0/2/3/4/6/">
              <joint name="0/2/3/4/6/joint/" class="0/2/3/4/" type="hinge" axis="0 1 0" limited="true" stiffness="100" range="-51.082137437810481 51.082137437810481" armature="0.20000000000000001" damping="3.5"/>
              <geom name="0/2/3/4/6/geom" class="0/2/3/4/6/" type="capsule" contype="1" conaffinity="1" condim="3" size="0.05861862855721954" rgba="0.38647196884532109 0.73015348474173336 0.87473990530186152 1" friction="0.59999999999999998 0.10000000000000001 0.10000000000000001" fromto="0 0 0 0.026912050274507493 0 -0.72795483292890539"/>
              <site name="0/2/3/4/6/end6" class="0/2/3/4/6/" size="0.0050000000000000001" pos="0.026912050274507493 0 -0.72795483292890539"/>
              <site name="0/2/3/4/6/attach7" class="0/2/3/4/6/" size="9.9999999999999995e-07 9.9999999999999995e-07 9.9999999999999995e-07" pos="0.021967935796814678 0 -0.59421949905880234"/>
              <body pos="0.021967935796814678 0 -0.59421949905880234" name="0/2/3/4/6/7/">
                <joint name="0/2/3/4/6/7/joint/" class="0/2/3/4/6/" type="hinge" axis="0 1 0" limited="true" stiffness="100" range="-59.908569352097928 59.908569352097928" armature="0.20000000000000001" damping="3.5"/>
                <geom name="0/2/3/4/6/7/geom" class="0/2/3/4/6/7/" type="capsule" contype="1" conaffinity="1" condim="3" size="0.068227885050977821" rgba="0.35673834266085114 0.50897515326028053 0.88052043509325606 1" friction="0.59999999999999998 0.10000000000000001 0.10000000000000001" fromto="0 0 0 0.27002405753027103 0 0.034623727101217749"/>
                <site name="0/2/3/4/6/7/end7" class="0/2/3/4/6/7/" size="0.0050000000000000001" pos="0.27002405753027103 0 0.034623727101217749"/>
                <site name="0/2/3/4/6/7/attach8" class="0/2/3/4/6/7/" size="9.9999999999999995e-07 9.9999999999999995e-07 9.9999999999999995e-07" pos="0.17209580201703942 0 0.022066915588197854"/>
                <body pos="0.17209580201703942 0 0.022066915588197854" name="0/2/3/4/6/7/8/">
                  <joint name="0/2/3/4/6/7/8/joint/" class="0/2/3/4/6/7/" type="hinge" axis="0 1 0" limited="true" stiffness="100" range="-65.035960406783701 65.035960406783701" armature="0.20000000000000001" damping="3.5"/>
                  <geom name="0/2/3/4/6/7/8/geom" class="0/2/3/4/6/7/8/" type="capsule" contype="1" conaffinity="1" condim="3" size="0.042746557518743934" rgba="0.20677833670306156 0.27247945336589219 0.092055693737835509 1" friction="0.59999999999999998 0.10000000000000001 0.10000000000000001" fromto="0 0 0 -0.048189906837419305 0 0.073020847978314096"/>
                  <site name="0/2/3/4/6/7/8/end8" class="0/2/3/4/6/7/8/" size="0.0050000000000000001" pos="-0.048189906837419305 0 0.073020847978314096"/>
                  <site name="0/2/3/4/6/7/8/attach9" class="0/2/3/4/6/7/8/" size="9.9999999999999995e-07 9.9999999999999995e-07 9.9999999999999995e-07" pos="-0.042159056451870111 0 0.063882465315137985"/>
                  <body pos="-0.042159056451870111 0 0.063882465315137985" name="0/2/3/4/6/7/8/9/">
                    <geom name="0/2/3/4/6/7/8/9/geom" class="0/2/3/4/6/7/8/9/" type="capsule" contype="1" conaffinity="1" condim="3" size="0.053437304726509767" rgba="0.048349707109863083 0.62217726704370346 0.6825236597048715 1" friction="0.59999999999999998 0.10000000000000001 0.10000000000000001" fromto="0 0 0 0.26840282917830405 0 0.10552798555083087"/>
                    <site name="0/2/3/4/6/7/8/9/end9" class="0/2/3/4/6/7/8/9/" size="0.0050000000000000001" pos="0.26840282917830405 0 0.10552798555083087"/>
                  </body>
                </body>
              </body>
            </body>
          </body>
          <site name="0/2/3/attach10" class="0/2/3/" size="9.9999999999999995e-07 9.9999999999999995e-07 9.9999999999999995e-07" pos="0.02629915401746253 0 -0.085558123026301655"/>
          <body pos="0.02629915401746253 0 -0.085558123026301655" name="0/2/3/10/">
            <joint name="0/2/3/10/joint/" class="0/2/3/" type="hinge" axis="0 1 0" limited="true" stiffness="100" range="-56.13738326595697 56.13738326595697" armature="0.20000000000000001" damping="3.5"/>
            <geom name="0/2/3/10/geom" class="0/2/3/10/" type="capsule" contype="1" conaffinity="1" condim="3" size="0.045975131838571381" rgba="0.9189200698839175 0.83942844187962606 0.081483887253897658 1" friction="0.59999999999999998 0.10000000000000001 0.10000000000000001" fromto="0 0 0 -0.27776024842193897 0 -0.27464282305334359"/>
            <site name="0/2/3/10/end10" class="0/2/3/10/" size="0.0050000000000000001" pos="-0.27776024842193897 0 -0.27464282305334359"/>
          </body>
        </body>
      </body>
      <camera name="0/side" class="0/" mode="trackcom" pos="0.40000000000000002 -4 0.20000000000000001" quat="0.70699999999999996 0.70699999999999996 0 0"/>
    </body>
  </worldbody>
  <actuator>
    <motor name="0/1/motor" class="0/1/" ctrllimited="true" ctrlrange="-1 1" gear="64" joint="0/1/joint/"/>
    <motor name="0/2/3/4/motor" class="0/2/3/4/" ctrllimited="true" ctrlrange="-1 1" gear="78" joint="0/2/3/4/joint/"/>
    <motor name="0/2/3/4/5/motor" class="0/2/3/4/5/" ctrllimited="true" ctrlrange="-1 1" gear="74" joint="0/2/3/4/5/joint/"/>
    <motor name="0/2/3/4/6/motor" class="0/2/3/4/6/" ctrllimited="true" ctrlrange="-1 1" gear="81" joint="0/2/3/4/6/joint/"/>
    <motor name="0/2/3/4/6/7/motor" class="0/2/3/4/6/7/" ctrllimited="true" ctrlrange="-1 1" gear="80" joint="0/2/3/4/6/7/joint/"/>
    <motor name="0/2/3/4/6/7/8/motor" class="0/2/3/4/6/7/8/" ctrllimited="true" ctrlrange="-1 1" gear="73" joint="0/2/3/4/6/7/8/joint/"/>
    <motor name="0/2/3/10/motor" class="0/2/3/10/" ctrllimited="true" ctrlrange="-1 1" gear="68" joint="0/2/3/10/joint/"/>
  </actuator>
  <sensor>
    <subtreelinvel name="velocity" body="0/"/>
  </sensor>
</mujoco>
