<mujoco model="morphology">
  <option timestep="0.01"/>
  <default>
    <default class="/"/>
    <default class="0/"/>
    <default class="0/1/"/>
    <default class="0/1/2/"/>
    <default class="0/1/2/3/"/>
    <default class="0/1/2/3/4/"/>
    <default class="0/1/2/3/4/5/"/>
    <default class="0/1/2/3/4/6/"/>
    <default class="0/1/2/3/7/"/>
    <default class="0/1/2/3/7/8/"/>
  </default>
  <asset>
    <texture name="texplane" type="2d" builtin="checker" rgb1="0.10000000000000001 0.20000000000000001 0.29999999999999999" rgb2="0.20000000000000001 0.29999999999999999 0.40000000000000002" width="300" height="300"/>
    <material name="MatPlane" class="/" texture="texplane" texrepeat="20 20" specular="1" shininess="1" reflectance="0.5"/>
  </asset>
  <worldbody>
    <light name="//unnamed_light_0" class="/" directional="true" pos="0 0 1.5" dir="0 0 -1.3" cutoff="100" exponent="1" diffuse="1 1 1" specular="0.10000000000000001 0.10000000000000001 0.10000000000000001"/>
    <geom name="ground" class="/" type="plane" size="15 15 0.5" material="MatPlane" rgba="1 1 1 1"/>
    <site name="body" class="/" size="9.9999999999999995e-07 9.9999999999999995e-07 9.9999999999999995e-07" pos="0 0 1.6358042716979981"/>
    <body pos="0 0 1.6358042716979981" name="0/">
      <joint name="0/rootx/" class="/" type="slide" axis="1 0 0" limited="false" stiffness="0" armature="0" damping="0"/>
      <joint name="0/rootz/" class="/" type="slide" axis="0 0 1" limited="false" stiffness="0" armature="0" damping="0"/>
      <joint name="0/rooty/" class="/" type="hinge" axis="0 1 0" limited="false" stiffness="0" armature="0" damping="0"/>
      <geom name="0/geom" class="0/" type="capsule" contype="1" conaffinity="1" condim="3" size="0.060418121587579587" rgba="0.095823089553631724 0.011403247385465276 0.12203321594265681 1" friction="0.59999999999999998 0.10000000000000001 0.10000000000000001" fromto="0 0 0 0.013041644865862567 0 -0.36830129531434003"/>
      <site name="0/end0" class="0/" size="0.0050000000000000001" pos="0.013041644865862567 0 -0.36830129531434003"/>
      <site name="0/attach1" class="0/" size="9.9999999999999995e-07 9.9999999999999995e-07 9.9999999999999995e-07" pos="0.01218452464146404 0 -0.34409587551239418"/>
      <body pos="0.01218452464146404 0 -0.34409587551239418" name="0/1/">
        <joint name="0/1/joint/" class="0/" type="hinge" axis="0 1 0" limited="true" stiffness="100" range="-62.253385111008043 62.253385111008043" armature="0.20000000000000001" damping="3.5"/>
        <geom name="0/1/geom" class="0/1/" type="capsule" contype="1" conaffinity="1" condim="3" size="0.049030849282533942" rgba="0.17080332950750632 0.73384620067820983 0.17696611481567559 1" friction="0.59999999999999998 0.10000000000000001 0.10000000000000001" fromto="0 0 0 -0.41964347122136852 0 0.016744295034294865"/>
        <site name="0/1/end1" class="0/1/" size="0.0050000000000000001" pos="-0.41964347122136852 0 0.016744295034294865"/>
        <site name="0/1/attach2" class="0/1/" size="9.9999999999999995e-07 9.9999999999999995e-07 9.9999999999999995e-07" pos="-0.40376479163918749 0 0.016110716022794364"/>
        <body pos="-0.40376479163918749 0 0.016110716022794364" name="0/1/2/">
          <geom name="0/1/2/geom" class="0/1/2/" type="capsule" contype="1" conaffinity="1" condim="3" size="0.05374259302239482" rgba="0.8340325790709604 0.61317366490197345 0.15149089294726137 1" friction="0.59999999999999998 0.10000000000000001 0.10000000000000001" fromto="0 0 0 -0.69106703664502522 0 -0.013252052805418857"/>
          <site name="0/1/2/end2" class="0/1/2/" size="0.0050000000000000001" pos="-0.69106703664502522 0 -0.013252052805418857"/>
          <site name="0/1/2/attach3" class="0/1/2/" size="9.9999999999999995e-07 9.9999999999999995e-07 9.9999999999999995e-07" pos="-0.30999125120886389 0 -0.0059444601064771374"/>
          <body pos="-0.30999125120886389 0 -0.0059444601064771374" name="0/1/2/3/">
            <joint name="0/1/2/3/joint/" class="0/1/2/" type="hinge" axis="0 1 0" limited="true" stiffness="100" range="-48.456996839817037 48.456996839817037" armature="0.20000000000000001" damping="3.5"/>
            <geom name="0/1/2/3/geom" class="0/1/2/3/" type="capsule" contype="1" conaffinity="1" condim="3" size="0.058816580872707594" rgba="0.74642306442300788 0.88944595842674878 0.052077423912625709 1" friction="0.59999999999999998 0.10000000000000001 0.10000000000000001" fromto="0 0 0 -0.075006851993099644 0 -0.73522915707587622"/>
            <site name="0/1/2/3/end3" class="0/1/2/3/" size="0.0050000000000000001" pos="-0.075006851993099644 0 -0.73522915707587622"/>
            <site name="0/1/2/3/attach4" class="0/1/2/3/" size="9.9999999999999995e-07 9.9999999999999995e-07 9.9999999999999995e-07" pos="-0.050356787463953528 0 -0.4936052829357197"/>
            <body pos="-0.050356787463953528 0 -0.4936052829357197" name="0/1/2/3/4/">
              <geom name="0/1/2/3/4/geom" class="0/1/2/3/4/" type="capsule" contype="1" conaffinity="1" condim="3" size="0.052459555724470086" rgba="0.28994149931307001 0.55776590813604332 0.154963874211131 1" friction="0.59999999999999998 0.10000000000000001 0.10000000000000001" fromto="0 0 0 0.45054721524300856 0 -0.17956505318889304"/>
              <site name="0/1/2/3/4/end4" class="0/1/2/3/4/" size="0.0050000000000000001" pos="0.45054721524300856 0 -0.17956505318889304"/>
              <site name="0/1/2/3/4/attach5" class="0/1/2/3/4/" size="9.9999999999999995e-07 9.9999999999999995e-07 9.9999999999999995e-07" pos="0.13028537658268688 0 -0.051925080844605578"/>
              <body pos="0.13028537658268688 0 -0.051925080844605578" name="0/1/2/3/4/5/">
                <geom name="0/1/2/3/4/5/geom" class="0/1/2/3/4/5/" type="capsule" contype="1" conaffinity="1" condim="3" size="0.067100244739317333" rgba="0.44492734437355874 0.52748639964535304 0.58865896010287078 1" friction="0.59999999999999998 0.10000000000000001 0.10000000000000001" fromto="0 0 0 -0.14244403970791708 0 -0.65634429216463264"/>
                <site name="0/1/2/3/4/5/end5" class="0/1/2/3/4/5/" size="0.0050000000000000001" pos="-0.14244403970791708 0 -0.65634429216463264"/>
              </body>
              <site name="0/1/2/3/4/attach6" class="0/1/2/3/4/" size="9.9999999999999995e-07 9.9999999999999995e-07 9.9999999999999995e-07" pos="0.44870770315680419 0 -0.17883191784940872"/>
              <body pos="0.44870770315680419 0 -0.17883191784940872" name="0/1/2/3/4/6/">
                <joint name="0/1/2/3/4/6/joint/" class="0/1/2/3/4/" type="hinge" axis="0 1 0" limited="true" stiffness="100" range="-68.574525651995899 68.574525651995899" armature="0.20000000000000001" damping="3.5"/>
                <geom name="0/1/2/3/4/6/geom" class="0/1/2/3/4/6/" type="capsule" contype="1" conaffinity="1" condim="3" size="0.045214658841884504" rgba="0.84226457257306864 0.47059618212871857 0.76892024603408482 1" friction="0.59999999999999998 0.10000000000000001 0.10000000000000001" fromto="0 0 0 0.069652524157805651 0 -0.38688378430565773"/>
                <site name="0/1/2/3/4/6/end6" class="0/1/2/3/4/6/" size="0.0050000000000000001" pos="0.069652524157805651 0 -0.38688378430565773"/>
              </body>
            </body>
            <site name="0/1/2/3/attach7" class="0/1/2/3/" size="9.9999999999999995e-07 9.9999999999999995e-07 9.9999999999999995e-07" pos="-0.0051433817448602072 0 -0.050416250306584122"/>
            <body pos="-0.0051433817448602072 0 -0.050416250306584122" name="0/1/2/3/7/">
              <joint name="0/1/2/3/7/joint/" class="0/1/2/3/" type="hinge" axis="0 1 0" limited="true" stiffness="100" range="-40.94874535179018 40.94874535179018" armature="0.20000000000000001" damping="3.5"/>
              <geom name="0/1/2/3/7/geom" class="0/1/2/3/7/" type="capsule" contype="1" conaffinity="1" condim="3" size="0.065181099669357381" rgba="0.055714720886961389 0.56073945494839661 0.48649481308656406 1" friction="0.59999999999999998 0.10000000000000001 0.10000000000000001" fromto="0 0 0 0.63557766718921416 0 -0.48034021788544318"/>
              <site name="0/1/2/3/7/end7" class="0/1/2/3/7/" size="0.0050000000000000001" pos="0.63557766718921416 0 -0.48034021788544318"/>
              <site name="0/1/2/3/7/attach8" class="0/1/2/3/7/" size="9.9999999999999995e-07 9.9999999999999995e-07 9.9999999999999995e-07" pos="0.33264045405836151 0 -0.25139427709365814"/>
              <body pos="0.33264045405836151 0 -0.25139427709365814" name="0/1/2/3/7/8/">
                <geom name="0/1/2/3/7/8/geom" class="0/1/2/3/7/8/" type="capsule" contype="1" conaffinity="1" condim="3" size="0.0519343996210593" rgba="0.24137210340120696 0.98311346626158014 0.060968399363813597 1" friction="0.59999999999999998 0.10000000000000001 0.10000000000000001" fromto="0 0 0 -0.21658669701489885 0 -0.12797134062122406"/>
                <site name="0/1/2/3/7/8/end8" class="0/1/2/3/7/8/" size="0.0050000000000000001" pos="-0.21658669701489885 0 -0.12797134062122406"/>
              </body>
            </body>
          </body>
        </body>
      </body>
      <camera name="0/side" class="0/" mode="trackcom" pos="0.40000000000000002 -4 0.20000000000000001" quat="0.70699999999999996 0.70699999999999996 0 0"/>
    </body>
  </worldbody>
  <actuator>
    <motor name="0/1/motor" class="0/1/" ctrllimited="true" ctrlrange="-1 1" gear="82" joint="0/1/joint/"/>
    <motor name="0/1/2/3/motor" class="0/1/2/3/" ctrllimited="true" ctrlrange="-1 1" gear="54" joint="0/1/2/3/joint/"/>
    <motor name="0/1/2/3/4/6/motor" class="0/1/2/3/4/6/" ctrllimited="true" ctrlrange="-1 1" gear="87" joint="0/1/2/3/4/6/joint/"/>
    <motor name="0/1/2/3/7/motor" class="0/1/2/3/7/" ctrllimited="true" ctrlrange="-1 1" gear="69" joint="0/1/2/3/7/joint/"/>
  </actuator>
  <sensor>
    <subtreelinvel name="velocity" body="0/"/>
  </sensor>
</mujoco>
