<mujoco model="morphology">
  <option timestep="0.01"/>
  <default>
    <default class="/"/>
    <default class="0/"/>
    <default class="0/1/"/>
    <default class="0/1/2/"/>
    <default class="0/1/3/"/>
    <default class="0/1/3/4/"/>
    <default class="0/1/3/4/5/"/>
    <default class="0/1/3/4/5/6/"/>
    <default class="0/1/3/4/5/6/7/"/>
    <default class="0/1/3/4/5/8/"/>
    <default class="0/1/3/4/9/"/>
  </default>
  <asset>
    <texture name="texplane" type="2d" builtin="checker" rgb1="0.10000000000000001 0.20000000000000001 0.29999999999999999" rgb2="0.20000000000000001 0.29999999999999999 0.40000000000000002" width="300" height="300"/>
    <material name="MatPlane" class="/" texture="texplane" texrepeat="20 20" specular="1" shininess="1" reflectance="0.5"/>
  </asset>
  <worldbody>
    <light name="//unnamed_light_0" class="/" directional="true" pos="0 0 1.5" dir="0 0 -1.3" cutoff="100" exponent="1" diffuse="1 1 1" specular="0.10000000000000001 0.10000000000000001 0.10000000000000001"/>
    <geom name="ground" class="/" type="plane" size="15 15 0.5" material="MatPlane" rgba="1 1 1 1"/>
    <site name="body" class="/" size="9.9999999999999995e-07 9.9999999999999995e-07 9.9999999999999995e-07" pos="0 0 0.80912814140319822"/>
    <body pos="0 0 0.80912814140319822" name="0/">
      <joint name="0/rootx/" class="/" type="slide" axis="1 0 0" limited="false" stiffness="0" armature="0" damping="0"/>
      <joint name="0/rootz/" class="/" type="slide" axis="0 0 1" limited="false" stiffness="0" armature="0" damping="0"/>
      <joint name="0/rooty/" class="/" type="hinge" axis="0 1 0" limited="false" stiffness="0" armature="0" damping="0"/>
      <geom name="0/geom" class="0/" type="capsule" contype="1" conaffinity="1" condim="3" size="0.048815106930779298" rgba="0.49522148160598389 0.39349949963425968 0.48867673529175271 1" friction="0.59999999999999998 0.10000000000000001 0.10000000000000001" fromto="0 0 0 -0.54710289310605309 0 -0.52064594868006409"/>
      <site name="0/end0" class="0/" size="0.0050000000000000001" pos="-0.54710289310605309 0 -0.52064594868006409"/>
      <site name="0/attach1" class="0/" size="9.9999999999999995e-07 9.9999999999999995e-07 9.9999999999999995e-07" pos="-0.18511883635635593 0 -0.17616681137641405"/>
      <body pos="-0.18511883635635593 0 -0.17616681137641405" name="0/1/">
        <joint name="0/1/joint/" class="0/" type="hinge" axis="0 1 0" limited="true" range="-64.87081465785316 64.87081465785316"/>
        <geom name="0/1/geom" class="0/1/" type="capsule" contype="1" conaffinity="1" condim="3" size="0.069921119057638925" rgba="0.7020025758812044 0.40765866763480219 0.24688018540858792 1" friction="0.59999999999999998 0.10000000000000001 0.10000000000000001" fromto="0 0 0 0.63964047168249838 0 -0.1098166180766017"/>
        <site name="0/1/end1" class="0/1/" size="0.0050000000000000001" pos="0.63964047168249838 0 -0.1098166180766017"/>
        <site name="0/1/attach2" class="0/1/" size="9.9999999999999995e-07 9.9999999999999995e-07 9.9999999999999995e-07" pos="0.56117987754338583 0 -0.096346117878304244"/>
        <body pos="0.56117987754338583 0 -0.096346117878304244" name="0/1/2/">
          <geom name="0/1/2/geom" class="0/1/2/" type="capsule" contype="1" conaffinity="1" condim="3" size="0.066952344589786952" rgba="0.36561100680459679 0.9082259192519484 0.28930254901571673 1" friction="0.59999999999999998 0.10000000000000001 0.10000000000000001" fromto="0 0 0 -0.26451337577801504 0 -0.43661518328303356"/>
          <site name="0/1/2/end2" class="0/1/2/" size="0.0050000000000000001" pos="-0.26451337577801504 0 -0.43661518328303356"/>
        </body>
        <site name="0/1/attach3" class="0/1/" size="9.9999999999999995e-07 9.9999999999999995e-07 9.9999999999999995e-07" pos="0.45610852747122271 0 -0.078306952390046772"/>
        <body pos="0.45610852747122271 0 -0.078306952390046772" name="0/1/3/">
          <joint name="0/1/3/joint/" class="0/1/" type="hinge" axis="0 1 0" limited="true" range="-44.588118126704963 44.588118126704963"/>
          <geom name="0/1/3/geom" class="0/1/3/" type="capsule" contype="1" conaffinity="1" condim="3" size="0.061130751295405225" rgba="0.52147329523998864 0.76232566544576441 0.71500421477446607 1" friction="0.59999999999999998 0.10000000000000001 0.10000000000000001" fromto="0 0 0 0.71523366048806913 0 0.58399454603080825"/>
          <site name="0/1/3/end3" class="0/1/3/" size="0.0050000000000000001" pos="0.71523366048806913 0 0.58399454603080825"/>
          <site name="0/1/3/attach4" class="0/1/3/" size="9.9999999999999995e-07 9.9999999999999995e-07 9.9999999999999995e-07" pos="0.57112356155856225 0 0.4663273884960768"/>
          <body pos="0.57112356155856225 0 0.4663273884960768" name="0/1/3/4/">
            <geom name="0/1/3/4/geom" class="0/1/3/4/" type="capsule" contype="1" conaffinity="1" condim="3" size="0.066893527556024984" rgba="0.7418478450806707 0.053503626459094678 0.70436886687079292 1" friction="0.59999999999999998 0.10000000000000001 0.10000000000000001" fromto="0 0 0 -0.19843321068453745 0 0.23829618064783742"/>
            <site name="0/1/3/4/end4" class="0/1/3/4/" size="0.0050000000000000001" pos="-0.19843321068453745 0 0.23829618064783742"/>
            <site name="0/1/3/4/attach5" class="0/1/3/4/" size="9.9999999999999995e-07 9.9999999999999995e-07 9.9999999999999995e-07" pos="-0.15890194460324603 0 0.19082353385223125"/>
            <body pos="-0.15890194460324603 0 0.19082353385223125" name="0/1/3/4/5/">
              <geom name="0/1/3/4/5/geom" class="0/1/3/4/5/" type="capsule" contype="1" conaffinity="1" condim="3" size="0.066099062699634004" rgba="0.76108399604333576 0.53248463280178004 0.10044474791756741 1" friction="0.59999999999999998 0.10000000000000001 0.10000000000000001" fromto="0 0 0 -0.34094821850184376 0 -0.14075130238806111"/>
              <site name="0/1/3/4/5/end5" class="0/1/3/4/5/" size="0.0050000000000000001" pos="-0.34094821850184376 0 -0.14075130238806111"/>
              <site name="0/1/3/4/5/attach6" class="0/1/3/4/5/" size="9.9999999999999995e-07 9.9999999999999995e-07 9.9999999999999995e-07" pos="-0.11271286992680281 0 -0.046530476996781346"/>
              <body pos="-0.11271286992680281 0 -0.046530476996781346" name="0/1/3/4/5/6/">
                <geom name="0/1/3/4/5/6/geom" class="0/1/3/4/5/6/" type="capsule" contype="1" conaffinity="1" condim="3" size="0.064129702803482236" rgba="0.22051602934373893 0.035652771942122574 0.16956682233079368 1" friction="0.59999999999999998 0.10000000000000001 0.10000000000000001" fromto="0 0 0 0.019492308183523654 0 -0.14134449058485699"/>
                <site name="0/1/3/4/5/6/end6" class="0/1/3/4/5/6/" size="0.0050000000000000001" pos="0.019492308183523654 0 -0.14134449058485699"/>
                <site name="0/1/3/4/5/6/attach7" class="0/1/3/4/5/6/" size="9.9999999999999995e-07 9.9999999999999995e-07 9.9999999999999995e-07" pos="0.0099760667867213448 0 -0.072339410229596557"/>
                <body pos="0.0099760667867213448 0 -0.072339410229596557" name="0/1/3/4/5/6/7/">
                  <joint name="0/1/3/4/5/6/7/joint/" class="0/1/3/4/5/6/" type="hinge" axis="0 1 0" limited="true" range="-40.960630070853135 40.960630070853135"/>
                  <geom name="0/1/3/4/5/6/7/geom" class="0/1/3/4/5/6/7/" type="capsule" contype="1" conaffinity="1" condim="3" size="0.065435865530095755" rgba="0.76702668489690451 0.030120223029504345 0.35436504346318898 1" friction="0.59999999999999998 0.10000000000000001 0.10000000000000001" fromto="0 0 0 -0.41659228180475066 0 -0.28644921213730717"/>
                  <site name="0/1/3/4/5/6/7/end7" class="0/1/3/4/5/6/7/" size="0.0050000000000000001" pos="-0.41659228180475066 0 -0.28644921213730717"/>
                </body>
              </body>
              <site name="0/1/3/4/5/attach8" class="0/1/3/4/5/" size="9.9999999999999995e-07 9.9999999999999995e-07 9.9999999999999995e-07" pos="-0.30303347871668346 0 -0.12509922176445495"/>
              <body pos="-0.30303347871668346 0 -0.12509922176445495" name="0/1/3/4/5/8/">
                <geom name="0/1/3/4/5/8/geom" class="0/1/3/4/5/8/" type="capsule" contype="1" conaffinity="1" condim="3" size="0.062672915134791091" rgba="0.087341941970026982 0.77646181218119659 0.80311820512341148 1" friction="0.59999999999999998 0.10000000000000001 0.10000000000000001" fromto="0 0 0 -0.3473289282050821 0 0.40112549306160927"/>
                <site name="0/1/3/4/5/8/end8" class="0/1/3/4/5/8/" size="0.0050000000000000001" pos="-0.3473289282050821 0 0.40112549306160927"/>
              </body>
            </body>
            <site name="0/1/3/4/attach9" class="0/1/3/4/" size="9.9999999999999995e-07 9.9999999999999995e-07 9.9999999999999995e-07" pos="-0.086873855953834539 0 0.10432582328600253"/>
            <body pos="-0.086873855953834539 0 0.10432582328600253" name="0/1/3/4/9/">
              <geom name="0/1/3/4/9/geom" class="0/1/3/4/9/" type="capsule" contype="1" conaffinity="1" condim="3" size="0.051981237176008221" rgba="0.24589353384551282 0.65142033549991507 0.73183445032476213 1" friction="0.59999999999999998 0.10000000000000001 0.10000000000000001" fromto="0 0 0 0.55982002757071037 0 0.63530391104268746"/>
              <site name="0/1/3/4/9/end9" class="0/1/3/4/9/" size="0.0050000000000000001" pos="0.55982002757071037 0 0.63530391104268746"/>
            </body>
          </body>
        </body>
      </body>
      <camera name="0/side" class="0/" mode="trackcom" pos="0.40000000000000002 -4 0.20000000000000001" quat="0.70699999999999996 0.70699999999999996 0 0"/>
    </body>
  </worldbody>
  <actuator>
    <motor name="0/1/motor" class="0/1/" ctrllimited="true" ctrlrange="-1 1" gear="50" joint="0/1/joint/"/>
    <motor name="0/1/3/motor" class="0/1/3/" ctrllimited="true" ctrlrange="-1 1" gear="78" joint="0/1/3/joint/"/>
    <motor name="0/1/3/4/5/6/7/motor" class="0/1/3/4/5/6/7/" ctrllimited="true" ctrlrange="-1 1" gear="72" joint="0/1/3/4/5/6/7/joint/"/>
  </actuator>
  <sensor>
    <subtreelinvel name="velocity" body="0/"/>
  </sensor>
</mujoco>
