<mujoco model="morphology">
  <option timestep="0.01"/>
  <default>
    <default class="/"/>
    <default class="0/"/>
    <default class="0/1/"/>
    <default class="0/1/2/"/>
    <default class="0/1/2/3/"/>
    <default class="0/1/2/4/"/>
    <default class="0/1/2/4/5/"/>
    <default class="0/1/2/4/5/6/"/>
    <default class="0/1/2/4/5/6/7/"/>
    <default class="0/1/2/4/5/6/8/"/>
    <default class="0/1/2/4/5/6/8/9/"/>
    <default class="0/1/10/"/>
  </default>
  <asset>
    <texture name="texplane" type="2d" builtin="checker" rgb1="0.10000000000000001 0.20000000000000001 0.29999999999999999" rgb2="0.20000000000000001 0.29999999999999999 0.40000000000000002" width="300" height="300"/>
    <material name="MatPlane" class="/" texture="texplane" texrepeat="20 20" specular="1" shininess="1" reflectance="0.5"/>
  </asset>
  <worldbody>
    <light name="//unnamed_light_0" class="/" directional="true" pos="0 0 1.5" dir="0 0 -1.3" cutoff="100" exponent="1" diffuse="1 1 1" specular="0.10000000000000001 0.10000000000000001 0.10000000000000001"/>
    <geom name="ground" class="/" type="plane" size="15 15 0.5" material="MatPlane" rgba="1 1 1 1"/>
    <site name="body" class="/" size="9.9999999999999995e-07 9.9999999999999995e-07 9.9999999999999995e-07" pos="0 0 1.7144728660583497"/>
    <body pos="0 0 1.7144728660583497" name="0/">
      <joint name="0/rootx/" class="/" type="slide" axis="1 0 0" limited="false" stiffness="0" armature="0" damping="0"/>
      <joint name="0/rootz/" class="/" type="slide" axis="0 0 1" limited="false" stiffness="0" armature="0" damping="0"/>
      <joint name="0/rooty/" class="/" type="hinge" axis="0 1 0" limited="false" stiffness="0" armature="0" damping="0"/>
      <geom name="0/geom" class="0/" type="capsule" contype="1" conaffinity="1" condim="3" size="0.042394973949458806" rgba="0.36575017611130889 0.9121519303869714 0.55634195623803606 1" friction="0.59999999999999998 0.10000000000000001 0.10000000000000001" fromto="0 0 0 0.11480495038034277 0 -0.23216352186063083"/>
      <site name="0/end0" class="0/" size="0.0050000000000000001" pos="0.11480495038034277 0 -0.23216352186063083"/>
      <site name="0/attach1" class="0/" size="9.9999999999999995e-07 9.9999999999999995e-07 9.9999999999999995e-07" pos="0.0532063197670085 0 -0.10759611446569323"/>
      <body pos="0.0532063197670085 0 -0.10759611446569323" name="0/1/">
        <joint name="0/1/joint/" class="0/" type="hinge" axis="0 1 0" limited="true" stiffness="100" range="-58.541734808457775 58.541734808457775" armature="0.20000000000000001" damping="3.5"/>
        <geom name="0/1/geom" class="0/1/" type="capsule" contype="1" conaffinity="1" condim="3" size="0.05889470330065287" rgba="0.22041786105778782 0.88101655358240427 0.79046179080035073 1" friction="0.59999999999999998 0.10000000000000001 0.10000000000000001" fromto="0 0 0 0.59320100204026138 0 0.10027017561504126"/>
        <site name="0/1/end1" class="0/1/" size="0.0050000000000000001" pos="0.59320100204026138 0 0.10027017561504126"/>
        <site name="0/1/attach2" class="0/1/" size="9.9999999999999995e-07 9.9999999999999995e-07 9.9999999999999995e-07" pos="0.24734640136451258 0 0.041809550249014664"/>
        <body pos="0.24734640136451258 0 0.041809550249014664" name="0/1/2/">
          <geom name="0/1/2/geom" class="0/1/2/" type="capsule" contype="1" conaffinity="1" condim="3" size="0.06624468204128682" rgba="0.024708675036340555 0.26767790396357805 0.86423691875177333 1" friction="0.59999999999999998 0.10000000000000001 0.10000000000000001" fromto="0 0 0 0.058642635911457908 0 -0.73747158066146856"/>
          <site name="0/1/2/end2" class="0/1/2/" size="0.0050000000000000001" pos="0.058642635911457908 0 -0.73747158066146856"/>
          <site name="0/1/2/attach3" class="0/1/2/" size="9.9999999999999995e-07 9.9999999999999995e-07 9.9999999999999995e-07" pos="0.019789273637063169 0 -0.24886376068262384"/>
          <body pos="0.019789273637063169 0 -0.24886376068262384" name="0/1/2/3/">
            <joint name="0/1/2/3/joint/" class="0/1/2/" type="hinge" axis="0 1 0" limited="true" stiffness="100" range="-68.447487817370302 68.447487817370302" armature="0.20000000000000001" damping="3.5"/>
            <geom name="0/1/2/3/geom" class="0/1/2/3/" type="capsule" contype="1" conaffinity="1" condim="3" size="0.049825084188192093" rgba="0.72966781547429405 0.67936678179308063 0.04284306021930484 1" friction="0.59999999999999998 0.10000000000000001 0.10000000000000001" fromto="0 0 0 0.50789168083553915 0 0.18021668648139921"/>
            <site name="0/1/2/3/end3" class="0/1/2/3/" size="0.0050000000000000001" pos="0.50789168083553915 0 0.18021668648139921"/>
          </body>
          <site name="0/1/2/attach4" class="0/1/2/" size="9.9999999999999995e-07 9.9999999999999995e-07 9.9999999999999995e-07" pos="0.046443112192654422 0 -0.58405415833060703"/>
          <body pos="0.046443112192654422 0 -0.58405415833060703" name="0/1/2/4/">
            <geom name="0/1/2/4/geom" class="0/1/2/4/" type="capsule" contype="1" conaffinity="1" condim="3" size="0.052604746562344588" rgba="0.88429061832310796 0.27745909482670494 0.76303744785701921 1" friction="0.59999999999999998 0.10000000000000001 0.10000000000000001" fromto="0 0 0 0.64001557559822686 0 -0.26079528540403746"/>
            <site name="0/1/2/4/end4" class="0/1/2/4/" size="0.0050000000000000001" pos="0.64001557559822686 0 -0.26079528540403746"/>
            <site name="0/1/2/4/attach5" class="0/1/2/4/" size="9.9999999999999995e-07 9.9999999999999995e-07 9.9999999999999995e-07" pos="0.58476388867899565 0 -0.23828117792206427"/>
            <body pos="0.58476388867899565 0 -0.23828117792206427" name="0/1/2/4/5/">
              <joint name="0/1/2/4/5/joint/" class="0/1/2/4/" type="hinge" axis="0 1 0" limited="true" stiffness="100" range="-43.116988179876024 43.116988179876024" armature="0.20000000000000001" damping="3.5"/>
              <geom name="0/1/2/4/5/geom" class="0/1/2/4/5/" type="capsule" contype="1" conaffinity="1" condim="3" size="0.066177909657550854" rgba="0.095957877178819317 0.94598919180374808 0.90314457727333908 1" friction="0.59999999999999998 0.10000000000000001 0.10000000000000001" fromto="0 0 0 0.19552761044851774 0 0.094504228399465706"/>
              <site name="0/1/2/4/5/end5" class="0/1/2/4/5/" size="0.0050000000000000001" pos="0.19552761044851774 0 0.094504228399465706"/>
              <site name="0/1/2/4/5/attach6" class="0/1/2/4/5/" size="9.9999999999999995e-07 9.9999999999999995e-07 9.9999999999999995e-07" pos="0.16525215906584087 0 0.079871214853183173"/>
              <body pos="0.16525215906584087 0 0.079871214853183173" name="0/1/2/4/5/6/">
                <joint name="0/1/2/4/5/6/joint/" class="0/1/2/4/5/" type="hinge" axis="0 1 0" limited="true" stiffness="100" range="-38.550687494754101 38.550687494754101" armature="0.20000000000000001" damping="3.5"/>
                <geom name="0/1/2/4/5/6/geom" class="0/1/2/4/5/6/" type="capsule" contype="1" conaffinity="1" condim="3" size="0.069746314212362229" rgba="0.62349489355952248 0.52244853010049219 0.4849241740391983 1" friction="0.59999999999999998 0.10000000000000001 0.10000000000000001" fromto="0 0 0 0.30545538478462531 0 -0.57660509966234552"/>
                <site name="0/1/2/4/5/6/end6" class="0/1/2/4/5/6/" size="0.0050000000000000001" pos="0.30545538478462531 0 -0.57660509966234552"/>
                <site name="0/1/2/4/5/6/attach7" class="0/1/2/4/5/6/" size="9.9999999999999995e-07 9.9999999999999995e-07 9.9999999999999995e-07" pos="0.19387383858731089 0 -0.36597372182317023"/>
                <body pos="0.19387383858731089 0 -0.36597372182317023" name="0/1/2/4/5/6/7/">
                  <joint name="0/1/2/4/5/6/7/joint/" class="0/1/2/4/5/6/" type="hinge" axis="0 1 0" limited="true" stiffness="100" range="-62.181140799283213 62.181140799283213" armature="0.20000000000000001" damping="3.5"/>
                  <geom name="0/1/2/4/5/6/7/geom" class="0/1/2/4/5/6/7/" type="capsule" contype="1" conaffinity="1" condim="3" size="0.040922239295541923" rgba="0.68200716301274655 0.72138086031901116 0.62347203037569687 1" friction="0.59999999999999998 0.10000000000000001 0.10000000000000001" fromto="0 0 0 0.68280862316126423 0 -0.19218023318216981"/>
                  <site name="0/1/2/4/5/6/7/end7" class="0/1/2/4/5/6/7/" size="0.0050000000000000001" pos="0.68280862316126423 0 -0.19218023318216981"/>
                </body>
                <site name="0/1/2/4/5/6/attach8" class="0/1/2/4/5/6/" size="9.9999999999999995e-07 9.9999999999999995e-07 9.9999999999999995e-07" pos="0.24223385261457422 0 -0.45726244055871934"/>
                <body pos="0.24223385261457422 0 -0.45726244055871934" name="0/1/2/4/5/6/8/">
                  <joint name="0/1/2/4/5/6/8/joint/" class="0/1/2/4/5/6/" type="hinge" axis="0 1 0" limited="true" stiffness="100" range="-49.322061372303921 49.322061372303921" armature="0.20000000000000001" damping="3.5"/>
                  <geom name="0/1/2/4/5/6/8/geom" class="0/1/2/4/5/6/8/" type="capsule" contype="1" conaffinity="1" condim="3" size="0.061703032274832856" rgba="0.38266067364897305 0.22192972224845819 0.53396818289802894 1" friction="0.59999999999999998 0.10000000000000001 0.10000000000000001" fromto="0 0 0 -0.59645906792401826 0 0.17270981776094652"/>
                  <site name="0/1/2/4/5/6/8/end8" class="0/1/2/4/5/6/8/" size="0.0050000000000000001" pos="-0.59645906792401826 0 0.17270981776094652"/>
                  <site name="0/1/2/4/5/6/8/attach9" class="0/1/2/4/5/6/8/" size="9.9999999999999995e-07 9.9999999999999995e-07 9.9999999999999995e-07" pos="-0.27618749374347101 0 0.079972447863537022"/>
                  <body pos="-0.27618749374347101 0 0.079972447863537022" name="0/1/2/4/5/6/8/9/">
                    <joint name="0/1/2/4/5/6/8/9/joint/" class="0/1/2/4/5/6/8/" type="hinge" axis="0 1 0" limited="true" stiffness="100" range="-68.877726567738819 68.877726567738819" armature="0.20000000000000001" damping="3.5"/>
                    <geom name="0/1/2/4/5/6/8/9/geom" class="0/1/2/4/5/6/8/9/" type="capsule" contype="1" conaffinity="1" condim="3" size="0.045994605382632378" rgba="0.99175333042797442 0.20596508345031783 0.37281346676348204 1" friction="0.59999999999999998 0.10000000000000001 0.10000000000000001" fromto="0 0 0 -0.053619376784174833 0 -0.4289322472069213"/>
                    <site name="0/1/2/4/5/6/8/9/end9" class="0/1/2/4/5/6/8/9/" size="0.0050000000000000001" pos="-0.053619376784174833 0 -0.4289322472069213"/>
                  </body>
                </body>
              </body>
            </body>
          </body>
        </body>
        <site name="0/1/attach10" class="0/1/" size="9.9999999999999995e-07 9.9999999999999995e-07 9.9999999999999995e-07" pos="0.036975034317110411 0 0.0062499779528309108"/>
        <body pos="0.036975034317110411 0 0.0062499779528309108" name="0/1/10/">
          <joint name="0/1/10/joint/" class="0/1/" type="hinge" axis="0 1 0" limited="true" stiffness="100" range="-40.895635754419992 40.895635754419992" armature="0.20000000000000001" damping="3.5"/>
          <geom name="0/1/10/geom" class="0/1/10/" type="capsule" contype="1" conaffinity="1" condim="3" size="0.043162463176857582" rgba="0.29226271951356209 0.67886957143441706 0.70795653139859616 1" friction="0.59999999999999998 0.10000000000000001 0.10000000000000001" fromto="0 0 0 0.34975591203830225 0 0.55880393530930972"/>
          <site name="0/1/10/end10" class="0/1/10/" size="0.0050000000000000001" pos="0.34975591203830225 0 0.55880393530930972"/>
        </body>
      </body>
      <camera name="0/side" class="0/" mode="trackcom" pos="0.40000000000000002 -4 0.20000000000000001" quat="0.70699999999999996 0.70699999999999996 0 0"/>
    </body>
  </worldbody>
  <actuator>
    <motor name="0/1/motor" class="0/1/" ctrllimited="true" ctrlrange="-1 1" gear="73" joint="0/1/joint/"/>
    <motor name="0/1/2/3/motor" class="0/1/2/3/" ctrllimited="true" ctrlrange="-1 1" gear="82" joint="0/1/2/3/joint/"/>
    <motor name="0/1/2/4/5/motor" class="0/1/2/4/5/" ctrllimited="true" ctrlrange="-1 1" gear="81" joint="0/1/2/4/5/joint/"/>
    <motor name="0/1/2/4/5/6/motor" class="0/1/2/4/5/6/" ctrllimited="true" ctrlrange="-1 1" gear="50" joint="0/1/2/4/5/6/joint/"/>
    <motor name="0/1/2/4/5/6/7/motor" class="0/1/2/4/5/6/7/" ctrllimited="true" ctrlrange="-1 1" gear="56" joint="0/1/2/4/5/6/7/joint/"/>
    <motor name="0/1/2/4/5/6/8/motor" class="0/1/2/4/5/6/8/" ctrllimited="true" ctrlrange="-1 1" gear="87" joint="0/1/2/4/5/6/8/joint/"/>
    <motor name="0/1/2/4/5/6/8/9/motor" class="0/1/2/4/5/6/8/9/" ctrllimited="true" ctrlrange="-1 1" gear="74" joint="0/1/2/4/5/6/8/9/joint/"/>
    <motor name="0/1/10/motor" class="0/1/10/" ctrllimited="true" ctrlrange="-1 1" gear="56" joint="0/1/10/joint/"/>
  </actuator>
  <sensor>
    <subtreelinvel name="velocity" body="0/"/>
  </sensor>
</mujoco>
