<mujoco model="morphology">
  <option timestep="0.01"/>
  <default>
    <default class="/"/>
    <default class="0/"/>
    <default class="0/1/"/>
    <default class="0/1/2/"/>
    <default class="0/1/2/3/"/>
    <default class="0/1/2/3/4/"/>
    <default class="0/1/2/3/4/5/"/>
    <default class="0/1/2/3/4/6/"/>
    <default class="0/1/2/3/4/6/7/"/>
    <default class="0/1/2/3/4/6/7/8/"/>
    <default class="0/1/2/3/4/6/7/8/9/"/>
    <default class="0/1/2/3/4/6/7/8/9/10/"/>
  </default>
  <asset>
    <texture name="texplane" type="2d" builtin="checker" rgb1="0.10000000000000001 0.20000000000000001 0.29999999999999999" rgb2="0.20000000000000001 0.29999999999999999 0.40000000000000002" width="300" height="300"/>
    <material name="MatPlane" class="/" texture="texplane" texrepeat="20 20" specular="1" shininess="1" reflectance="0.5"/>
  </asset>
  <worldbody>
    <light name="//unnamed_light_0" class="/" directional="true" pos="0 0 1.5" dir="0 0 -1.3" cutoff="100" exponent="1" diffuse="1 1 1" specular="0.10000000000000001 0.10000000000000001 0.10000000000000001"/>
    <geom name="ground" class="/" type="plane" size="15 15 0.5" material="MatPlane" rgba="1 1 1 1"/>
    <site name="body" class="/" size="9.9999999999999995e-07 9.9999999999999995e-07 9.9999999999999995e-07" pos="0 0 1.7702007055282594"/>
    <body pos="0 0 1.7702007055282594" name="0/">
      <joint name="0/rootx/" class="/" type="slide" axis="1 0 0" limited="false" stiffness="0" armature="0" damping="0"/>
      <joint name="0/rootz/" class="/" type="slide" axis="0 0 1" limited="false" stiffness="0" armature="0" damping="0"/>
      <joint name="0/rooty/" class="/" type="hinge" axis="0 1 0" limited="false" stiffness="0" armature="0" damping="0"/>
      <geom name="0/geom" class="0/" type="capsule" contype="1" conaffinity="1" condim="3" size="0.049760105491296794" rgba="0.76395265650876476 0.62478649806144615 0.079439515522557014 1" friction="0.59999999999999998 0.10000000000000001 0.10000000000000001" fromto="0 0 0 0.33490888481965642 0 0.45470466588194913"/>
      <site name="0/end0" class="0/" size="0.0050000000000000001" pos="0.33490888481965642 0 0.45470466588194913"/>
      <site name="0/attach1" class="0/" size="9.9999999999999995e-07 9.9999999999999995e-07 9.9999999999999995e-07" pos="0.11326453954722956 0 0.15377888418466076"/>
      <body pos="0.11326453954722956 0 0.15377888418466076" name="0/1/">
        <joint name="0/1/joint/" class="0/" type="hinge" axis="0 1 0" limited="true" range="-30.345234659290938 30.345234659290938"/>
        <geom name="0/1/geom" class="0/1/" type="capsule" contype="1" conaffinity="1" condim="3" size="0.062177679534595243" rgba="0.89301078395328271 0.22906135838136799 0.23311906517545156 1" friction="0.59999999999999998 0.10000000000000001 0.10000000000000001" fromto="0 0 0 0.2209425893441519 0 -0.66403291622570504"/>
        <site name="0/1/end1" class="0/1/" size="0.0050000000000000001" pos="0.2209425893441519 0 -0.66403291622570504"/>
        <site name="0/1/attach2" class="0/1/" size="9.9999999999999995e-07 9.9999999999999995e-07 9.9999999999999995e-07" pos="0.080530485192739781 0 -0.24203071524752806"/>
        <body pos="0.080530485192739781 0 -0.24203071524752806" name="0/1/2/">
          <joint name="0/1/2/joint/" class="0/1/" type="hinge" axis="0 1 0" limited="true" range="-55.068405468197739 55.068405468197739"/>
          <geom name="0/1/2/geom" class="0/1/2/" type="capsule" contype="1" conaffinity="1" condim="3" size="0.066674188456869052" rgba="0.45538292545753012 0.9184963265691044 0.60310398099302853 1" friction="0.59999999999999998 0.10000000000000001 0.10000000000000001" fromto="0 0 0 -0.20015174838758898 0 -0.21295602309135342"/>
          <site name="0/1/2/end2" class="0/1/2/" size="0.0050000000000000001" pos="-0.20015174838758898 0 -0.21295602309135342"/>
          <site name="0/1/2/attach3" class="0/1/2/" size="9.9999999999999995e-07 9.9999999999999995e-07 9.9999999999999995e-07" pos="-0.12493396246582808 0 -0.13292634218835991"/>
          <body pos="-0.12493396246582808 0 -0.13292634218835991" name="0/1/2/3/">
            <joint name="0/1/2/3/joint/" class="0/1/2/" type="hinge" axis="0 1 0" limited="true" range="-41.510427473026041 41.510427473026041"/>
            <geom name="0/1/2/3/geom" class="0/1/2/3/" type="capsule" contype="1" conaffinity="1" condim="3" size="0.056864144718680162" rgba="0.13750303117489471 0.86627651509253711 0.77206219812396681 1" friction="0.59999999999999998 0.10000000000000001 0.10000000000000001" fromto="0 0 0 0.095191755588415083 0 -0.36396257606613086"/>
            <site name="0/1/2/3/end3" class="0/1/2/3/" size="0.0050000000000000001" pos="0.095191755588415083 0 -0.36396257606613086"/>
            <site name="0/1/2/3/attach4" class="0/1/2/3/" size="9.9999999999999995e-07 9.9999999999999995e-07 9.9999999999999995e-07" pos="0.058123193034008008 0 -0.2222321348638"/>
            <body pos="0.058123193034008008 0 -0.2222321348638" name="0/1/2/3/4/">
              <joint name="0/1/2/3/4/joint/" class="0/1/2/3/" type="hinge" axis="0 1 0" limited="true" range="-60.093106459761856 60.093106459761856"/>
              <geom name="0/1/2/3/4/geom" class="0/1/2/3/4/" type="capsule" contype="1" conaffinity="1" condim="3" size="0.058809315226498279" rgba="0.27331247689755778 0.0044377690320154262 0.78011381338160102 1" friction="0.59999999999999998 0.10000000000000001 0.10000000000000001" fromto="0 0 0 -0.49090563588854558 0 0.18867960943834172"/>
              <site name="0/1/2/3/4/end4" class="0/1/2/3/4/" size="0.0050000000000000001" pos="-0.49090563588854558 0 0.18867960943834172"/>
              <site name="0/1/2/3/4/attach5" class="0/1/2/3/4/" size="9.9999999999999995e-07 9.9999999999999995e-07 9.9999999999999995e-07" pos="-0.25272297919751857 0 0.097134091615741797"/>
              <body pos="-0.25272297919751857 0 0.097134091615741797" name="0/1/2/3/4/5/">
                <geom name="0/1/2/3/4/5/geom" class="0/1/2/3/4/5/" type="capsule" contype="1" conaffinity="1" condim="3" size="0.068717157742849949" rgba="0.55872827645924716 0.93125144174451113 0.23436743160284568 1" friction="0.59999999999999998 0.10000000000000001 0.10000000000000001" fromto="0 0 0 -0.33831210110264548 0 -0.62321794392284446"/>
                <site name="0/1/2/3/4/5/end5" class="0/1/2/3/4/5/" size="0.0050000000000000001" pos="-0.33831210110264548 0 -0.62321794392284446"/>
              </body>
              <site name="0/1/2/3/4/attach6" class="0/1/2/3/4/" size="9.9999999999999995e-07 9.9999999999999995e-07 9.9999999999999995e-07" pos="-0.42052364550163318 0 0.1616282873779229"/>
              <body pos="-0.42052364550163318 0 0.1616282873779229" name="0/1/2/3/4/6/">
                <joint name="0/1/2/3/4/6/joint/" class="0/1/2/3/4/" type="hinge" axis="0 1 0" limited="true" range="-63.955681810592154 63.955681810592154"/>
                <geom name="0/1/2/3/4/6/geom" class="0/1/2/3/4/6/" type="capsule" contype="1" conaffinity="1" condim="3" size="0.069173096933088332" rgba="0.58816585450215852 0.42628475172619351 0.5160542554559937 1" friction="0.59999999999999998 0.10000000000000001 0.10000000000000001" fromto="0 0 0 -0.48671662785618847 0 -0.61434369175874304"/>
                <site name="0/1/2/3/4/6/end6" class="0/1/2/3/4/6/" size="0.0050000000000000001" pos="-0.48671662785618847 0 -0.61434369175874304"/>
                <site name="0/1/2/3/4/6/attach7" class="0/1/2/3/4/6/" size="9.9999999999999995e-07 9.9999999999999995e-07 9.9999999999999995e-07" pos="-0.46131251228174613 0 -0.58227809700680022"/>
                <body pos="-0.46131251228174613 0 -0.58227809700680022" name="0/1/2/3/4/6/7/">
                  <geom name="0/1/2/3/4/6/7/geom" class="0/1/2/3/4/6/7/" type="capsule" contype="1" conaffinity="1" condim="3" size="0.052204478565990739" rgba="0.80252156913982164 0.86118877478968903 0.73729042413389168 1" friction="0.59999999999999998 0.10000000000000001 0.10000000000000001" fromto="0 0 0 0.47393359151634562 0 -0.52772357946607329"/>
                  <site name="0/1/2/3/4/6/7/end7" class="0/1/2/3/4/6/7/" size="0.0050000000000000001" pos="0.47393359151634562 0 -0.52772357946607329"/>
                  <site name="0/1/2/3/4/6/7/attach8" class="0/1/2/3/4/6/7/" size="9.9999999999999995e-07 9.9999999999999995e-07 9.9999999999999995e-07" pos="0.11771923731159141 0 -0.13108000445236759"/>
                  <body pos="0.11771923731159141 0 -0.13108000445236759" name="0/1/2/3/4/6/7/8/">
                    <geom name="0/1/2/3/4/6/7/8/geom" class="0/1/2/3/4/6/7/8/" type="capsule" contype="1" conaffinity="1" condim="3" size="0.05321099276240443" rgba="0.66666711658701427 0.84535925961362446 0.58568455122631924 1" friction="0.59999999999999998 0.10000000000000001 0.10000000000000001" fromto="0 0 0 -0.038007879026259905 0 -0.39931659416459525"/>
                    <site name="0/1/2/3/4/6/7/8/end8" class="0/1/2/3/4/6/7/8/" size="0.0050000000000000001" pos="-0.038007879026259905 0 -0.39931659416459525"/>
                    <site name="0/1/2/3/4/6/7/8/attach9" class="0/1/2/3/4/6/7/8/" size="9.9999999999999995e-07 9.9999999999999995e-07 9.9999999999999995e-07" pos="-0.010009009281906924 0 -0.1051561833969084"/>
                    <body pos="-0.010009009281906924 0 -0.1051561833969084" name="0/1/2/3/4/6/7/8/9/">
                      <joint name="0/1/2/3/4/6/7/8/9/joint/" class="0/1/2/3/4/6/7/8/" type="hinge" axis="0 1 0" limited="true" range="-48.801592840537879 48.801592840537879"/>
                      <geom name="0/1/2/3/4/6/7/8/9/geom" class="0/1/2/3/4/6/7/8/9/" type="capsule" contype="1" conaffinity="1" condim="3" size="0.048002354332864275" rgba="0.60688135967898671 0.36842985992579591 0.97373754575129412 1" friction="0.59999999999999998 0.10000000000000001 0.10000000000000001" fromto="0 0 0 0.055028330720209406 0 -0.032351761542690483"/>
                      <site name="0/1/2/3/4/6/7/8/9/end9" class="0/1/2/3/4/6/7/8/9/" size="0.0050000000000000001" pos="0.055028330720209406 0 -0.032351761542690483"/>
                      <site name="0/1/2/3/4/6/7/8/9/attach10" class="0/1/2/3/4/6/7/8/9/" size="9.9999999999999995e-07 9.9999999999999995e-07 9.9999999999999995e-07" pos="0.054395079258143159 0 -0.03197946603546363"/>
                      <body pos="0.054395079258143159 0 -0.03197946603546363" name="0/1/2/3/4/6/7/8/9/10/">
                        <joint name="0/1/2/3/4/6/7/8/9/10/joint/" class="0/1/2/3/4/6/7/8/9/" type="hinge" axis="0 1 0" limited="true" range="-52.974882755017269 52.974882755017269"/>
                        <geom name="0/1/2/3/4/6/7/8/9/10/geom" class="0/1/2/3/4/6/7/8/9/10/" type="capsule" contype="1" conaffinity="1" condim="3" size="0.055455526402776956" rgba="0.26934689153178881 0.30336602466071638 0.8731635217176591 1" friction="0.59999999999999998 0.10000000000000001 0.10000000000000001" fromto="0 0 0 0.2042278013252381 0 -0.53792490787038538"/>
                        <site name="0/1/2/3/4/6/7/8/9/10/end10" class="0/1/2/3/4/6/7/8/9/10/" size="0.0050000000000000001" pos="0.2042278013252381 0 -0.53792490787038538"/>
                      </body>
                    </body>
                  </body>
                </body>
              </body>
            </body>
          </body>
        </body>
      </body>
      <camera name="0/side" class="0/" mode="trackcom" pos="0.40000000000000002 -4 0.20000000000000001" quat="0.70699999999999996 0.70699999999999996 0 0"/>
    </body>
  </worldbody>
  <actuator>
    <motor name="0/1/motor" class="0/1/" ctrllimited="true" ctrlrange="-1 1" gear="59" joint="0/1/joint/"/>
    <motor name="0/1/2/motor" class="0/1/2/" ctrllimited="true" ctrlrange="-1 1" gear="76" joint="0/1/2/joint/"/>
    <motor name="0/1/2/3/motor" class="0/1/2/3/" ctrllimited="true" ctrlrange="-1 1" gear="63" joint="0/1/2/3/joint/"/>
    <motor name="0/1/2/3/4/motor" class="0/1/2/3/4/" ctrllimited="true" ctrlrange="-1 1" gear="67" joint="0/1/2/3/4/joint/"/>
    <motor name="0/1/2/3/4/6/motor" class="0/1/2/3/4/6/" ctrllimited="true" ctrlrange="-1 1" gear="67" joint="0/1/2/3/4/6/joint/"/>
    <motor name="0/1/2/3/4/6/7/8/9/motor" class="0/1/2/3/4/6/7/8/9/" ctrllimited="true" ctrlrange="-1 1" gear="70" joint="0/1/2/3/4/6/7/8/9/joint/"/>
    <motor name="0/1/2/3/4/6/7/8/9/10/motor" class="0/1/2/3/4/6/7/8/9/10/" ctrllimited="true" ctrlrange="-1 1" gear="60" joint="0/1/2/3/4/6/7/8/9/10/joint/"/>
  </actuator>
  <sensor>
    <subtreelinvel name="velocity" body="0/"/>
  </sensor>
</mujoco>
