<mujoco model="morphology">
  <option timestep="0.01"/>
  <default>
    <default class="/"/>
    <default class="0/"/>
    <default class="0/1/"/>
    <default class="0/1/2/"/>
    <default class="0/1/2/3/"/>
    <default class="0/1/4/"/>
    <default class="0/5/"/>
  </default>
  <asset>
    <texture name="texplane" type="2d" builtin="checker" rgb1="0.10000000000000001 0.20000000000000001 0.29999999999999999" rgb2="0.20000000000000001 0.29999999999999999 0.40000000000000002" width="300" height="300"/>
    <material name="MatPlane" class="/" texture="texplane" texrepeat="20 20" specular="1" shininess="1" reflectance="0.5"/>
  </asset>
  <worldbody>
    <light name="//unnamed_light_0" class="/" directional="true" pos="0 0 1.5" dir="0 0 -1.3" cutoff="100" exponent="1" diffuse="1 1 1" specular="0.10000000000000001 0.10000000000000001 0.10000000000000001"/>
    <geom name="ground" class="/" type="plane" size="15 15 0.5" material="MatPlane" rgba="1 1 1 1"/>
    <site name="body" class="/" size="9.9999999999999995e-07 9.9999999999999995e-07 9.9999999999999995e-07" pos="0 0 1.0582704901695252"/>
    <body pos="0 0 1.0582704901695252" name="0/">
      <joint name="0/rootx/" class="/" type="slide" axis="1 0 0" limited="false" stiffness="0" armature="0" damping="0"/>
      <joint name="0/rootz/" class="/" type="slide" axis="0 0 1" limited="false" stiffness="0" armature="0" damping="0"/>
      <joint name="0/rooty/" class="/" type="hinge" axis="0 1 0" limited="false" stiffness="0" armature="0" damping="0"/>
      <geom name="0/geom" class="0/" type="capsule" contype="1" conaffinity="1" condim="3" size="0.069460359054520124" rgba="0.57414862806657507 0.45870240132061202 0.25353715799936338 1" friction="0.59999999999999998 0.10000000000000001 0.10000000000000001" fromto="0 0 0 0.31375678299270304 0 0.43176578647815567"/>
      <site name="0/end0" class="0/" size="0.0050000000000000001" pos="0.31375678299270304 0 0.43176578647815567"/>
      <site name="0/attach1" class="0/" size="9.9999999999999995e-07 9.9999999999999995e-07 9.9999999999999995e-07" pos="0.094967880340001559 0 0.13068683696351441"/>
      <body pos="0.094967880340001559 0 0.13068683696351441" name="0/1/">
        <joint name="0/1/joint/" class="0/" type="hinge" axis="0 1 0" limited="true" range="-40.753402435402634 40.753402435402634"/>
        <geom name="0/1/geom" class="0/1/" type="capsule" contype="1" conaffinity="1" condim="3" size="0.049580794322380814" rgba="0.38170799909604936 0.61046335986951628 0.41964594417696854 1" friction="0.59999999999999998 0.10000000000000001 0.10000000000000001" fromto="0 0 0 0.35911418409147489 0 -0.53433147263097092"/>
        <site name="0/1/end1" class="0/1/" size="0.0050000000000000001" pos="0.35911418409147489 0 -0.53433147263097092"/>
        <site name="0/1/attach2" class="0/1/" size="9.9999999999999995e-07 9.9999999999999995e-07 9.9999999999999995e-07" pos="0.20101405482414383 0 -0.29909187854954822"/>
        <body pos="0.20101405482414383 0 -0.29909187854954822" name="0/1/2/">
          <joint name="0/1/2/joint/" class="0/1/" type="hinge" axis="0 1 0" limited="true" range="-61.719152532474972 61.719152532474972"/>
          <geom name="0/1/2/geom" class="0/1/2/" type="capsule" contype="1" conaffinity="1" condim="3" size="0.053432612443258649" rgba="0.2330979670595682 0.34614972070884431 0.82768079715777931 1" friction="0.59999999999999998 0.10000000000000001 0.10000000000000001" fromto="0 0 0 0.34534523471726764 0 0.58974673691139201"/>
          <site name="0/1/2/end2" class="0/1/2/" size="0.0050000000000000001" pos="0.34534523471726764 0 0.58974673691139201"/>
          <site name="0/1/2/attach3" class="0/1/2/" size="9.9999999999999995e-07 9.9999999999999995e-07 9.9999999999999995e-07" pos="0.1705907420556573 0 0.29131814590400223"/>
          <body pos="0.1705907420556573 0 0.29131814590400223" name="0/1/2/3/">
            <joint name="0/1/2/3/joint/" class="0/1/2/" type="hinge" axis="0 1 0" limited="true" range="-49.410497665575832 49.410497665575832"/>
            <geom name="0/1/2/3/geom" class="0/1/2/3/" type="capsule" contype="1" conaffinity="1" condim="3" size="0.060975155400523964" rgba="0.53196207665663808 0.77434867964845466 0.67123300591607205 1" friction="0.59999999999999998 0.10000000000000001 0.10000000000000001" fromto="0 0 0 0.56610140248965646 0 -0.28682878251624244"/>
            <site name="0/1/2/3/end3" class="0/1/2/3/" size="0.0050000000000000001" pos="0.56610140248965646 0 -0.28682878251624244"/>
          </body>
        </body>
        <site name="0/1/attach4" class="0/1/" size="9.9999999999999995e-07 9.9999999999999995e-07 9.9999999999999995e-07" pos="0.31851820919060331 0 -0.47392810230308868"/>
        <body pos="0.31851820919060331 0 -0.47392810230308868" name="0/1/4/">
          <geom name="0/1/4/geom" class="0/1/4/" type="capsule" contype="1" conaffinity="1" condim="3" size="0.043110726785911227" rgba="0.64635259546588431 0.65504917857849487 0.81222946692901787 1" friction="0.59999999999999998 0.10000000000000001 0.10000000000000001" fromto="0 0 0 -0.23272406979629867 0 -0.61502922892054679"/>
          <site name="0/1/4/end4" class="0/1/4/" size="0.0050000000000000001" pos="-0.23272406979629867 0 -0.61502922892054679"/>
        </body>
      </body>
      <site name="0/attach5" class="0/" size="9.9999999999999995e-07 9.9999999999999995e-07 9.9999999999999995e-07" pos="0.087426780474961815 0 0.12030940740459735"/>
      <body pos="0.087426780474961815 0 0.12030940740459735" name="0/5/">
        <joint name="0/5/joint/" class="0/" type="hinge" axis="0 1 0" limited="true" range="-44.700962991635734 44.700962991635734"/>
        <geom name="0/5/geom" class="0/5/" type="capsule" contype="1" conaffinity="1" condim="3" size="0.066902995666053913" rgba="0.065479641411360312 0.54630569359074566 0.31306064080960039 1" friction="0.59999999999999998 0.10000000000000001 0.10000000000000001" fromto="0 0 0 -0.39542292027390374 0 0.34415912515689828"/>
        <site name="0/5/end5" class="0/5/" size="0.0050000000000000001" pos="-0.39542292027390374 0 0.34415912515689828"/>
      </body>
      <camera name="0/side" class="0/" mode="trackcom" pos="0.40000000000000002 -4 0.20000000000000001" quat="0.70699999999999996 0.70699999999999996 0 0"/>
    </body>
  </worldbody>
  <actuator>
    <motor name="0/1/motor" class="0/1/" ctrllimited="true" ctrlrange="-1 1" gear="66" joint="0/1/joint/"/>
    <motor name="0/1/2/motor" class="0/1/2/" ctrllimited="true" ctrlrange="-1 1" gear="88" joint="0/1/2/joint/"/>
    <motor name="0/1/2/3/motor" class="0/1/2/3/" ctrllimited="true" ctrlrange="-1 1" gear="67" joint="0/1/2/3/joint/"/>
    <motor name="0/5/motor" class="0/5/" ctrllimited="true" ctrlrange="-1 1" gear="72" joint="0/5/joint/"/>
  </actuator>
  <sensor>
    <subtreelinvel name="velocity" body="0/"/>
  </sensor>
</mujoco>
