<mujoco model="morphology">
  <option timestep="0.01"/>
  <default>
    <default class="/"/>
    <default class="0/"/>
    <default class="0/1/"/>
    <default class="0/1/2/"/>
    <default class="0/1/2/3/"/>
    <default class="0/1/2/3/4/"/>
    <default class="0/1/2/3/4/5/"/>
    <default class="0/1/2/3/4/5/6/"/>
    <default class="0/1/2/3/4/5/6/7/"/>
    <default class="0/1/2/3/4/5/6/7/8/"/>
    <default class="0/1/2/3/4/5/6/7/8/9/"/>
    <default class="0/1/2/3/4/5/6/7/8/9/10/"/>
  </default>
  <asset>
    <texture name="texplane" type="2d" builtin="checker" rgb1="0.10000000000000001 0.20000000000000001 0.29999999999999999" rgb2="0.20000000000000001 0.29999999999999999 0.40000000000000002" width="300" height="300"/>
    <material name="MatPlane" class="/" texture="texplane" texrepeat="20 20" specular="1" shininess="1" reflectance="0.5"/>
  </asset>
  <worldbody>
    <light name="//unnamed_light_0" class="/" directional="true" pos="0 0 1.5" dir="0 0 -1.3" cutoff="100" exponent="1" diffuse="1 1 1" specular="0.10000000000000001 0.10000000000000001 0.10000000000000001"/>
    <geom name="ground" class="/" type="plane" size="15 15 0.5" material="MatPlane" rgba="1 1 1 1"/>
    <site name="body" class="/" size="9.9999999999999995e-07 9.9999999999999995e-07 9.9999999999999995e-07" pos="0 0 0.83622679710388181"/>
    <body pos="0 0 0.83622679710388181" name="0/">
      <joint name="0/rootx/" class="/" type="slide" axis="1 0 0" limited="false" stiffness="0" armature="0" damping="0"/>
      <joint name="0/rootz/" class="/" type="slide" axis="0 0 1" limited="false" stiffness="0" armature="0" damping="0"/>
      <joint name="0/rooty/" class="/" type="hinge" axis="0 1 0" limited="false" stiffness="0" armature="0" damping="0"/>
      <geom name="0/geom" class="0/" type="capsule" contype="1" conaffinity="1" condim="3" size="0.065966111491291002" rgba="0.74938698299084394 0.0089067964443148018 0.45067120510551362 1" friction="0.59999999999999998 0.10000000000000001 0.10000000000000001" fromto="0 0 0 0.098523210788601268 0 -0.67134279819545495"/>
      <site name="0/end0" class="0/" size="0.0050000000000000001" pos="0.098523210788601268 0 -0.67134279819545495"/>
      <site name="0/attach1" class="0/" size="9.9999999999999995e-07 9.9999999999999995e-07 9.9999999999999995e-07" pos="0.0041337158298564297 0 -0.028167376295878239"/>
      <body pos="0.0041337158298564297 0 -0.028167376295878239" name="0/1/">
        <joint name="0/1/joint/" class="0/" type="hinge" axis="0 1 0" limited="true" range="-39.431742425278237 39.431742425278237"/>
        <geom name="0/1/geom" class="0/1/" type="capsule" contype="1" conaffinity="1" condim="3" size="0.040384933495278295" rgba="0.58162646120481531 0.62107725916094025 0.74451821173828681 1" friction="0.59999999999999998 0.10000000000000001 0.10000000000000001" fromto="0 0 0 -0.29206972600270908 0 -0.20991299877516811"/>
        <site name="0/1/end1" class="0/1/" size="0.0050000000000000001" pos="-0.29206972600270908 0 -0.20991299877516811"/>
        <site name="0/1/attach2" class="0/1/" size="9.9999999999999995e-07 9.9999999999999995e-07 9.9999999999999995e-07" pos="-0.2555723136976798 0 -0.18368199781065409"/>
        <body pos="-0.2555723136976798 0 -0.18368199781065409" name="0/1/2/">
          <joint name="0/1/2/joint/" class="0/1/" type="hinge" axis="0 1 0" limited="true" range="-37.48091462893457 37.48091462893457"/>
          <geom name="0/1/2/geom" class="0/1/2/" type="capsule" contype="1" conaffinity="1" condim="3" size="0.068265717852162039" rgba="0.46790369710184865 0.28513225788892427 0.020353105777315306 1" friction="0.59999999999999998 0.10000000000000001 0.10000000000000001" fromto="0 0 0 -0.6852593306263004 0 0.43312057791191738"/>
          <site name="0/1/2/end2" class="0/1/2/" size="0.0050000000000000001" pos="-0.6852593306263004 0 0.43312057791191738"/>
          <site name="0/1/2/attach3" class="0/1/2/" size="9.9999999999999995e-07 9.9999999999999995e-07 9.9999999999999995e-07" pos="-0.48314771014376512 0 0.30537521501973636"/>
          <body pos="-0.48314771014376512 0 0.30537521501973636" name="0/1/2/3/">
            <joint name="0/1/2/3/joint/" class="0/1/2/" type="hinge" axis="0 1 0" limited="true" range="-48.173068366999864 48.173068366999864"/>
            <geom name="0/1/2/3/geom" class="0/1/2/3/" type="capsule" contype="1" conaffinity="1" condim="3" size="0.048152398509444541" rgba="0.11747104077323889 0.1491402773530589 0.50286263989068092 1" friction="0.59999999999999998 0.10000000000000001 0.10000000000000001" fromto="0 0 0 0.016379837522661478 0 -0.16960818840972258"/>
            <site name="0/1/2/3/end3" class="0/1/2/3/" size="0.0050000000000000001" pos="0.016379837522661478 0 -0.16960818840972258"/>
            <site name="0/1/2/3/attach4" class="0/1/2/3/" size="9.9999999999999995e-07 9.9999999999999995e-07 9.9999999999999995e-07" pos="0.0065967582710242381 0 -0.068307406479296756"/>
            <body pos="0.0065967582710242381 0 -0.068307406479296756" name="0/1/2/3/4/">
              <joint name="0/1/2/3/4/joint/" class="0/1/2/3/" type="hinge" axis="0 1 0" limited="true" range="-49.426046479941931 49.426046479941931"/>
              <geom name="0/1/2/3/4/geom" class="0/1/2/3/4/" type="capsule" contype="1" conaffinity="1" condim="3" size="0.041751561426634817" rgba="0.63613191703115424 0.8121648495129854 0.43578147881542739 1" friction="0.59999999999999998 0.10000000000000001 0.10000000000000001" fromto="0 0 0 -0.25878768541531549 0 0.1669183320106542"/>
              <site name="0/1/2/3/4/end4" class="0/1/2/3/4/" size="0.0050000000000000001" pos="-0.25878768541531549 0 0.1669183320106542"/>
              <site name="0/1/2/3/4/attach5" class="0/1/2/3/4/" size="9.9999999999999995e-07 9.9999999999999995e-07 9.9999999999999995e-07" pos="-0.11618600141695756 0 0.074940094341746893"/>
              <body pos="-0.11618600141695756 0 0.074940094341746893" name="0/1/2/3/4/5/">
                <joint name="0/1/2/3/4/5/joint/" class="0/1/2/3/4/" type="hinge" axis="0 1 0" limited="true" range="-51.636054885358242 51.636054885358242"/>
                <geom name="0/1/2/3/4/5/geom" class="0/1/2/3/4/5/" type="capsule" contype="1" conaffinity="1" condim="3" size="0.045249439519180389" rgba="0.84242278891005684 0.90093967265736619 0.96423003479981895 1" friction="0.59999999999999998 0.10000000000000001 0.10000000000000001" fromto="0 0 0 -0.22356792394257741 0 -0.21038217120555869"/>
                <site name="0/1/2/3/4/5/end5" class="0/1/2/3/4/5/" size="0.0050000000000000001" pos="-0.22356792394257741 0 -0.21038217120555869"/>
                <site name="0/1/2/3/4/5/attach6" class="0/1/2/3/4/5/" size="9.9999999999999995e-07 9.9999999999999995e-07 9.9999999999999995e-07" pos="-0.19761235524118492 0 -0.18595742904229323"/>
                <body pos="-0.19761235524118492 0 -0.18595742904229323" name="0/1/2/3/4/5/6/">
                  <joint name="0/1/2/3/4/5/6/joint/" class="0/1/2/3/4/5/" type="hinge" axis="0 1 0" limited="true" range="-47.558908842157706 47.558908842157706"/>
                  <geom name="0/1/2/3/4/5/6/geom" class="0/1/2/3/4/5/6/" type="capsule" contype="1" conaffinity="1" condim="3" size="0.044125384083045713" rgba="0.1378544570801814 0.65389114579166052 0.7955702848930406 1" friction="0.59999999999999998 0.10000000000000001 0.10000000000000001" fromto="0 0 0 -0.55608303576372231 0 0.070928733799379806"/>
                  <site name="0/1/2/3/4/5/6/end6" class="0/1/2/3/4/5/6/" size="0.0050000000000000001" pos="-0.55608303576372231 0 0.070928733799379806"/>
                  <site name="0/1/2/3/4/5/6/attach7" class="0/1/2/3/4/5/6/" size="9.9999999999999995e-07 9.9999999999999995e-07 9.9999999999999995e-07" pos="-0.14002248173924445 0 0.017859953809904208"/>
                  <body pos="-0.14002248173924445 0 0.017859953809904208" name="0/1/2/3/4/5/6/7/">
                    <joint name="0/1/2/3/4/5/6/7/joint/" class="0/1/2/3/4/5/6/" type="hinge" axis="0 1 0" limited="true" range="-69.948872577406718 69.948872577406718"/>
                    <geom name="0/1/2/3/4/5/6/7/geom" class="0/1/2/3/4/5/6/7/" type="capsule" contype="1" conaffinity="1" condim="3" size="0.051814343722525885" rgba="0.33702252316024373 0.94023026217428274 0.65743646443438453 1" friction="0.59999999999999998 0.10000000000000001 0.10000000000000001" fromto="0 0 0 0.054941138148112412 0 -0.1191983072235735"/>
                    <site name="0/1/2/3/4/5/6/7/end7" class="0/1/2/3/4/5/6/7/" size="0.0050000000000000001" pos="0.054941138148112412 0 -0.1191983072235735"/>
                    <site name="0/1/2/3/4/5/6/7/attach8" class="0/1/2/3/4/5/6/7/" size="9.9999999999999995e-07 9.9999999999999995e-07 9.9999999999999995e-07" pos="0.025265199443291149 0 -0.054814463384205363"/>
                    <body pos="0.025265199443291149 0 -0.054814463384205363" name="0/1/2/3/4/5/6/7/8/">
                      <joint name="0/1/2/3/4/5/6/7/8/joint/" class="0/1/2/3/4/5/6/7/" type="hinge" axis="0 1 0" limited="true" range="-48.226275726377693 48.226275726377693"/>
                      <geom name="0/1/2/3/4/5/6/7/8/geom" class="0/1/2/3/4/5/6/7/8/" type="capsule" contype="1" conaffinity="1" condim="3" size="0.040541639236765271" rgba="0.22942906447036526 0.38093026565945753 0.66491425910398683 1" friction="0.59999999999999998 0.10000000000000001 0.10000000000000001" fromto="0 0 0 -0.21572402754745423 0 -0.54399147996715436"/>
                      <site name="0/1/2/3/4/5/6/7/8/end8" class="0/1/2/3/4/5/6/7/8/" size="0.0050000000000000001" pos="-0.21572402754745423 0 -0.54399147996715436"/>
                      <site name="0/1/2/3/4/5/6/7/8/attach9" class="0/1/2/3/4/5/6/7/8/" size="9.9999999999999995e-07 9.9999999999999995e-07 9.9999999999999995e-07" pos="-0.13743703088759124 0 -0.34657508801788806"/>
                      <body pos="-0.13743703088759124 0 -0.34657508801788806" name="0/1/2/3/4/5/6/7/8/9/">
                        <joint name="0/1/2/3/4/5/6/7/8/9/joint/" class="0/1/2/3/4/5/6/7/8/" type="hinge" axis="0 1 0" limited="true" range="-69.384429799681328 69.384429799681328"/>
                        <geom name="0/1/2/3/4/5/6/7/8/9/geom" class="0/1/2/3/4/5/6/7/8/9/" type="capsule" contype="1" conaffinity="1" condim="3" size="0.065209380473852566" rgba="0.033505199293556553 0.82836733025810794 0.34363914528790274 1" friction="0.59999999999999998 0.10000000000000001 0.10000000000000001" fromto="0 0 0 -0.66523209198796407 0 0.32848394610978526"/>
                        <site name="0/1/2/3/4/5/6/7/8/9/end9" class="0/1/2/3/4/5/6/7/8/9/" size="0.0050000000000000001" pos="-0.66523209198796407 0 0.32848394610978526"/>
                        <site name="0/1/2/3/4/5/6/7/8/9/attach10" class="0/1/2/3/4/5/6/7/8/9/" size="9.9999999999999995e-07 9.9999999999999995e-07 9.9999999999999995e-07" pos="-0.18843239272253814 0 0.093045745510317329"/>
                        <body pos="-0.18843239272253814 0 0.093045745510317329" name="0/1/2/3/4/5/6/7/8/9/10/">
                          <joint name="0/1/2/3/4/5/6/7/8/9/10/joint/" class="0/1/2/3/4/5/6/7/8/9/" type="hinge" axis="0 1 0" limited="true" range="-63.938367116595558 63.938367116595558"/>
                          <geom name="0/1/2/3/4/5/6/7/8/9/10/geom" class="0/1/2/3/4/5/6/7/8/9/10/" type="capsule" contype="1" conaffinity="1" condim="3" size="0.040751236585006317" rgba="0.14451526584453611 0.62103925846408092 0.55207468667464488 1" friction="0.59999999999999998 0.10000000000000001 0.10000000000000001" fromto="0 0 0 -0.73212245476568749 0 -0.35994406625374514"/>
                          <site name="0/1/2/3/4/5/6/7/8/9/10/end10" class="0/1/2/3/4/5/6/7/8/9/10/" size="0.0050000000000000001" pos="-0.73212245476568749 0 -0.35994406625374514"/>
                        </body>
                      </body>
                    </body>
                  </body>
                </body>
              </body>
            </body>
          </body>
        </body>
      </body>
      <camera name="0/side" class="0/" mode="trackcom" pos="0.40000000000000002 -4 0.20000000000000001" quat="0.70699999999999996 0.70699999999999996 0 0"/>
    </body>
  </worldbody>
  <actuator>
    <motor name="0/1/motor" class="0/1/" ctrllimited="true" ctrlrange="-1 1" gear="59" joint="0/1/joint/"/>
    <motor name="0/1/2/motor" class="0/1/2/" ctrllimited="true" ctrlrange="-1 1" gear="76" joint="0/1/2/joint/"/>
    <motor name="0/1/2/3/motor" class="0/1/2/3/" ctrllimited="true" ctrlrange="-1 1" gear="75" joint="0/1/2/3/joint/"/>
    <motor name="0/1/2/3/4/motor" class="0/1/2/3/4/" ctrllimited="true" ctrlrange="-1 1" gear="59" joint="0/1/2/3/4/joint/"/>
    <motor name="0/1/2/3/4/5/motor" class="0/1/2/3/4/5/" ctrllimited="true" ctrlrange="-1 1" gear="67" joint="0/1/2/3/4/5/joint/"/>
    <motor name="0/1/2/3/4/5/6/motor" class="0/1/2/3/4/5/6/" ctrllimited="true" ctrlrange="-1 1" gear="78" joint="0/1/2/3/4/5/6/joint/"/>
    <motor name="0/1/2/3/4/5/6/7/motor" class="0/1/2/3/4/5/6/7/" ctrllimited="true" ctrlrange="-1 1" gear="76" joint="0/1/2/3/4/5/6/7/joint/"/>
    <motor name="0/1/2/3/4/5/6/7/8/motor" class="0/1/2/3/4/5/6/7/8/" ctrllimited="true" ctrlrange="-1 1" gear="65" joint="0/1/2/3/4/5/6/7/8/joint/"/>
    <motor name="0/1/2/3/4/5/6/7/8/9/motor" class="0/1/2/3/4/5/6/7/8/9/" ctrllimited="true" ctrlrange="-1 1" gear="63" joint="0/1/2/3/4/5/6/7/8/9/joint/"/>
    <motor name="0/1/2/3/4/5/6/7/8/9/10/motor" class="0/1/2/3/4/5/6/7/8/9/10/" ctrllimited="true" ctrlrange="-1 1" gear="59" joint="0/1/2/3/4/5/6/7/8/9/10/joint/"/>
  </actuator>
  <sensor>
    <subtreelinvel name="velocity" body="0/"/>
  </sensor>
</mujoco>
