<mujoco model="morphology">
  <option timestep="0.01"/>
  <default>
    <default class="/"/>
    <default class="0/"/>
    <default class="0/1/"/>
    <default class="0/1/2/"/>
    <default class="0/1/2/3/"/>
    <default class="0/1/2/3/4/"/>
    <default class="0/1/2/3/5/"/>
    <default class="0/1/2/3/5/6/"/>
    <default class="0/1/2/3/5/7/"/>
    <default class="0/1/2/3/5/7/8/"/>
    <default class="0/1/2/3/5/7/8/9/"/>
    <default class="0/1/2/10/"/>
  </default>
  <asset>
    <texture name="texplane" type="2d" builtin="checker" rgb1="0.10000000000000001 0.20000000000000001 0.29999999999999999" rgb2="0.20000000000000001 0.29999999999999999 0.40000000000000002" width="300" height="300"/>
    <material name="MatPlane" class="/" texture="texplane" texrepeat="20 20" specular="1" shininess="1" reflectance="0.5"/>
  </asset>
  <worldbody>
    <light name="//unnamed_light_0" class="/" directional="true" pos="0 0 1.5" dir="0 0 -1.3" cutoff="100" exponent="1" diffuse="1 1 1" specular="0.10000000000000001 0.10000000000000001 0.10000000000000001"/>
    <geom name="ground" class="/" type="plane" size="15 15 0.5" material="MatPlane" rgba="1 1 1 1"/>
    <site name="body" class="/" size="9.9999999999999995e-07 9.9999999999999995e-07 9.9999999999999995e-07" pos="0 0 2.7052963733673097"/>
    <body pos="0 0 2.7052963733673097" name="0/">
      <joint name="0/rootx/" class="/" type="slide" axis="1 0 0" limited="false" stiffness="0" armature="0" damping="0"/>
      <joint name="0/rootz/" class="/" type="slide" axis="0 0 1" limited="false" stiffness="0" armature="0" damping="0"/>
      <joint name="0/rooty/" class="/" type="hinge" axis="0 1 0" limited="false" stiffness="0" armature="0" damping="0"/>
      <geom name="0/geom" class="0/" type="capsule" contype="1" conaffinity="1" condim="3" size="0.064236450029939371" rgba="0.14647882675557444 0.81301010000302865 0.04970946637005591 1" friction="0.59999999999999998 0.10000000000000001 0.10000000000000001" fromto="0 0 0 -0.19752637138808526 0 -0.66404987344177346"/>
      <site name="0/end0" class="0/" size="0.0050000000000000001" pos="-0.19752637138808526 0 -0.66404987344177346"/>
      <site name="0/attach1" class="0/" size="9.9999999999999995e-07 9.9999999999999995e-07 9.9999999999999995e-07" pos="-0.19515022202119939 0 -0.65606166571401026"/>
      <body pos="-0.19515022202119939 0 -0.65606166571401026" name="0/1/">
        <joint name="0/1/joint/" class="0/" type="hinge" axis="0 1 0" limited="true" stiffness="100" range="-66.178115511628107 66.178115511628107" armature="0.20000000000000001" damping="3.5"/>
        <geom name="0/1/geom" class="0/1/" type="capsule" contype="1" conaffinity="1" condim="3" size="0.064018299312437729" rgba="0.23110888694564402 0.7299314434353833 0.10949101406477635 1" friction="0.59999999999999998 0.10000000000000001 0.10000000000000001" fromto="0 0 0 -0.53620181410928325 0 -0.55393133184118803"/>
        <site name="0/1/end1" class="0/1/" size="0.0050000000000000001" pos="-0.53620181410928325 0 -0.55393133184118803"/>
        <site name="0/1/attach2" class="0/1/" size="9.9999999999999995e-07 9.9999999999999995e-07 9.9999999999999995e-07" pos="-0.015745499784021091 0 -0.016266124873815378"/>
        <body pos="-0.015745499784021091 0 -0.016266124873815378" name="0/1/2/">
          <joint name="0/1/2/joint/" class="0/1/" type="hinge" axis="0 1 0" limited="true" stiffness="100" range="-43.245156189858164 43.245156189858164" armature="0.20000000000000001" damping="3.5"/>
          <geom name="0/1/2/geom" class="0/1/2/" type="capsule" contype="1" conaffinity="1" condim="3" size="0.040372938916750395" rgba="0.55766409104264536 0.42871162198516366 0.53517249303801495 1" friction="0.59999999999999998 0.10000000000000001 0.10000000000000001" fromto="0 0 0 0.69458472306546581 0 -0.082273393658578553"/>
          <site name="0/1/2/end2" class="0/1/2/" size="0.0050000000000000001" pos="0.69458472306546581 0 -0.082273393658578553"/>
          <site name="0/1/2/attach3" class="0/1/2/" size="9.9999999999999995e-07 9.9999999999999995e-07 9.9999999999999995e-07" pos="0.33644295853339273 0 -0.039851587649251716"/>
          <body pos="0.33644295853339273 0 -0.039851587649251716" name="0/1/2/3/">
            <joint name="0/1/2/3/joint/" class="0/1/2/" type="hinge" axis="0 1 0" limited="true" stiffness="100" range="-37.227923204271356 37.227923204271356" armature="0.20000000000000001" damping="3.5"/>
            <geom name="0/1/2/3/geom" class="0/1/2/3/" type="capsule" contype="1" conaffinity="1" condim="3" size="0.044060777224162448" rgba="0.8897988449524652 0.81327901035345307 0.49891359327065221 1" friction="0.59999999999999998 0.10000000000000001 0.10000000000000001" fromto="0 0 0 -0.54700653369434216 0 -0.50047469289224522"/>
            <site name="0/1/2/3/end3" class="0/1/2/3/" size="0.0050000000000000001" pos="-0.54700653369434216 0 -0.50047469289224522"/>
            <site name="0/1/2/3/attach4" class="0/1/2/3/" size="9.9999999999999995e-07 9.9999999999999995e-07 9.9999999999999995e-07" pos="-0.28080936520476046 0 -0.25692194179649236"/>
            <body pos="-0.28080936520476046 0 -0.25692194179649236" name="0/1/2/3/4/">
              <geom name="0/1/2/3/4/geom" class="0/1/2/3/4/" type="capsule" contype="1" conaffinity="1" condim="3" size="0.058645240055932288" rgba="0.42722601905420365 0.038189939566623421 0.32106264579640731 1" friction="0.59999999999999998 0.10000000000000001 0.10000000000000001" fromto="0 0 0 0.2223780994150566 0 -0.18668520215066287"/>
              <site name="0/1/2/3/4/end4" class="0/1/2/3/4/" size="0.0050000000000000001" pos="0.2223780994150566 0 -0.18668520215066287"/>
            </body>
            <site name="0/1/2/3/attach5" class="0/1/2/3/" size="9.9999999999999995e-07 9.9999999999999995e-07 9.9999999999999995e-07" pos="-0.44212536100770045 0 -0.40451537713047725"/>
            <body pos="-0.44212536100770045 0 -0.40451537713047725" name="0/1/2/3/5/">
              <joint name="0/1/2/3/5/joint/" class="0/1/2/3/" type="hinge" axis="0 1 0" limited="true" stiffness="100" range="-38.636542438257464 38.636542438257464" armature="0.20000000000000001" damping="3.5"/>
              <geom name="0/1/2/3/5/geom" class="0/1/2/3/5/" type="capsule" contype="1" conaffinity="1" condim="3" size="0.051159024436832116" rgba="0.31018204857457476 0.67217453929651882 0.067008741351667789 1" friction="0.59999999999999998 0.10000000000000001 0.10000000000000001" fromto="0 0 0 0.023680510855709436 0 -0.70534017373590197"/>
              <site name="0/1/2/3/5/end5" class="0/1/2/3/5/" size="0.0050000000000000001" pos="0.023680510855709436 0 -0.70534017373590197"/>
              <site name="0/1/2/3/5/attach6" class="0/1/2/3/5/" size="9.9999999999999995e-07 9.9999999999999995e-07 9.9999999999999995e-07" pos="0.013305471403929452 0 -0.39631254447464564"/>
              <body pos="0.013305471403929452 0 -0.39631254447464564" name="0/1/2/3/5/6/">
                <joint name="0/1/2/3/5/6/joint/" class="0/1/2/3/5/" type="hinge" axis="0 1 0" limited="true" stiffness="100" range="-64.675043087103617 64.675043087103617" armature="0.20000000000000001" damping="3.5"/>
                <geom name="0/1/2/3/5/6/geom" class="0/1/2/3/5/6/" type="capsule" contype="1" conaffinity="1" condim="3" size="0.054199491567526778" rgba="0.087501997781607388 0.51156004815493139 0.4391448961386758 1" friction="0.59999999999999998 0.10000000000000001 0.10000000000000001" fromto="0 0 0 -0.67389288156106031 0 -0.22349167872939635"/>
                <site name="0/1/2/3/5/6/end6" class="0/1/2/3/5/6/" size="0.0050000000000000001" pos="-0.67389288156106031 0 -0.22349167872939635"/>
              </body>
              <site name="0/1/2/3/5/attach7" class="0/1/2/3/5/" size="9.9999999999999995e-07 9.9999999999999995e-07 9.9999999999999995e-07" pos="0.015252856963626009 0 -0.45431675212779199"/>
              <body pos="0.015252856963626009 0 -0.45431675212779199" name="0/1/2/3/5/7/">
                <geom name="0/1/2/3/5/7/geom" class="0/1/2/3/5/7/" type="capsule" contype="1" conaffinity="1" condim="3" size="0.063880418323296384" rgba="0.46652794738686465 0.83269367263320981 0.23163479245585272 1" friction="0.59999999999999998 0.10000000000000001 0.10000000000000001" fromto="0 0 0 -0.41284292080299539 0 -0.4178193718865012"/>
                <site name="0/1/2/3/5/7/end7" class="0/1/2/3/5/7/" size="0.0050000000000000001" pos="-0.41284292080299539 0 -0.4178193718865012"/>
                <site name="0/1/2/3/5/7/attach8" class="0/1/2/3/5/7/" size="9.9999999999999995e-07 9.9999999999999995e-07 9.9999999999999995e-07" pos="-0.34097647210546272 0 -0.34508663761528607"/>
                <body pos="-0.34097647210546272 0 -0.34508663761528607" name="0/1/2/3/5/7/8/">
                  <geom name="0/1/2/3/5/7/8/geom" class="0/1/2/3/5/7/8/" type="capsule" contype="1" conaffinity="1" condim="3" size="0.051704694262704395" rgba="0.93779175085462396 0.72293181153194952 0.43972374124417035 1" friction="0.59999999999999998 0.10000000000000001 0.10000000000000001" fromto="0 0 0 0.033013692034416398 0 -0.34902443792549709"/>
                  <site name="0/1/2/3/5/7/8/end8" class="0/1/2/3/5/7/8/" size="0.0050000000000000001" pos="0.033013692034416398 0 -0.34902443792549709"/>
                  <site name="0/1/2/3/5/7/8/attach9" class="0/1/2/3/5/7/8/" size="9.9999999999999995e-07 9.9999999999999995e-07 9.9999999999999995e-07" pos="0.029398403945713882 0 -0.31080320863121813"/>
                  <body pos="0.029398403945713882 0 -0.31080320863121813" name="0/1/2/3/5/7/8/9/">
                    <geom name="0/1/2/3/5/7/8/9/geom" class="0/1/2/3/5/7/8/9/" type="capsule" contype="1" conaffinity="1" condim="3" size="0.061827232455563867" rgba="0.57316699925539583 0.97786289095151813 0.18875658562549213 1" friction="0.59999999999999998 0.10000000000000001 0.10000000000000001" fromto="0 0 0 -0.36508560666431028 0 -0.37839490811511106"/>
                    <site name="0/1/2/3/5/7/8/9/end9" class="0/1/2/3/5/7/8/9/" size="0.0050000000000000001" pos="-0.36508560666431028 0 -0.37839490811511106"/>
                  </body>
                </body>
              </body>
            </body>
          </body>
          <site name="0/1/2/attach10" class="0/1/2/" size="9.9999999999999995e-07 9.9999999999999995e-07 9.9999999999999995e-07" pos="0.10272689264585533 0 -0.012167975766403959"/>
          <body pos="0.10272689264585533 0 -0.012167975766403959" name="0/1/2/10/">
            <joint name="0/1/2/10/joint/" class="0/1/2/" type="hinge" axis="0 1 0" limited="true" stiffness="100" range="-42.52967858241098 42.52967858241098" armature="0.20000000000000001" damping="3.5"/>
            <geom name="0/1/2/10/geom" class="0/1/2/10/" type="capsule" contype="1" conaffinity="1" condim="3" size="0.067433360898788333" rgba="0.16237127235108395 0.39408667724565516 0.1504382164878959 1" friction="0.59999999999999998 0.10000000000000001 0.10000000000000001" fromto="0 0 0 0.58523377849678093 0 0.71249804213581358"/>
            <site name="0/1/2/10/end10" class="0/1/2/10/" size="0.0050000000000000001" pos="0.58523377849678093 0 0.71249804213581358"/>
          </body>
        </body>
      </body>
      <camera name="0/side" class="0/" mode="trackcom" pos="0.40000000000000002 -4 0.20000000000000001" quat="0.70699999999999996 0.70699999999999996 0 0"/>
    </body>
  </worldbody>
  <actuator>
    <motor name="0/1/motor" class="0/1/" ctrllimited="true" ctrlrange="-1 1" gear="70" joint="0/1/joint/"/>
    <motor name="0/1/2/motor" class="0/1/2/" ctrllimited="true" ctrlrange="-1 1" gear="60" joint="0/1/2/joint/"/>
    <motor name="0/1/2/3/motor" class="0/1/2/3/" ctrllimited="true" ctrlrange="-1 1" gear="71" joint="0/1/2/3/joint/"/>
    <motor name="0/1/2/3/5/motor" class="0/1/2/3/5/" ctrllimited="true" ctrlrange="-1 1" gear="80" joint="0/1/2/3/5/joint/"/>
    <motor name="0/1/2/3/5/6/motor" class="0/1/2/3/5/6/" ctrllimited="true" ctrlrange="-1 1" gear="74" joint="0/1/2/3/5/6/joint/"/>
    <motor name="0/1/2/10/motor" class="0/1/2/10/" ctrllimited="true" ctrlrange="-1 1" gear="56" joint="0/1/2/10/joint/"/>
  </actuator>
  <sensor>
    <subtreelinvel name="velocity" body="0/"/>
  </sensor>
</mujoco>
