<mujoco model="morphology">
  <option timestep="0.01"/>
  <default>
    <default class="/"/>
    <default class="0/"/>
    <default class="0/1/"/>
    <default class="0/1/2/"/>
    <default class="0/3/"/>
  </default>
  <asset>
    <texture name="texplane" type="2d" builtin="checker" rgb1="0.10000000000000001 0.20000000000000001 0.29999999999999999" rgb2="0.20000000000000001 0.29999999999999999 0.40000000000000002" width="300" height="300"/>
    <material name="MatPlane" class="/" texture="texplane" texrepeat="20 20" specular="1" shininess="1" reflectance="0.5"/>
  </asset>
  <worldbody>
    <light name="//unnamed_light_0" class="/" directional="true" pos="0 0 1.5" dir="0 0 -1.3" cutoff="100" exponent="1" diffuse="1 1 1" specular="0.10000000000000001 0.10000000000000001 0.10000000000000001"/>
    <geom name="ground" class="/" type="plane" size="15 15 0.5" material="MatPlane" rgba="1 1 1 1"/>
    <site name="body" class="/" size="9.9999999999999995e-07 9.9999999999999995e-07 9.9999999999999995e-07" pos="0 0 0.25190646052360532"/>
    <body pos="0 0 0.25190646052360532" name="0/">
      <joint name="0/rootx/" class="/" type="slide" axis="1 0 0" limited="false" stiffness="0" armature="0" damping="0"/>
      <joint name="0/rootz/" class="/" type="slide" axis="0 0 1" limited="false" stiffness="0" armature="0" damping="0"/>
      <joint name="0/rooty/" class="/" type="hinge" axis="0 1 0" limited="false" stiffness="0" armature="0" damping="0"/>
      <geom name="0/geom" class="0/" type="capsule" contype="1" conaffinity="1" condim="3" size="0.066198427445982658" rgba="0.36230349110804427 0.5406441357465156 0.64420644637722457 1" friction="0.59999999999999998 0.10000000000000001 0.10000000000000001" fromto="0 0 0 -0.65710704720975499 0 0.57472265574835379"/>
      <site name="0/end0" class="0/" size="0.0050000000000000001" pos="-0.65710704720975499 0 0.57472265574835379"/>
      <site name="0/attach1" class="0/" size="9.9999999999999995e-07 9.9999999999999995e-07 9.9999999999999995e-07" pos="-0.43295263144249574 0 0.37867146184545658"/>
      <body pos="-0.43295263144249574 0 0.37867146184545658" name="0/1/">
        <joint name="0/1/joint/" class="0/" type="hinge" axis="0 1 0" limited="true" range="-49.351444690255889 49.351444690255889"/>
        <geom name="0/1/geom" class="0/1/" type="capsule" contype="1" conaffinity="1" condim="3" size="0.04818326079944775" rgba="0.81930993725435453 0.8166304810118874 0.11119640203578507 1" friction="0.59999999999999998 0.10000000000000001 0.10000000000000001" fromto="0 0 0 0.23205028739731537 0 0.60565680619588447"/>
        <site name="0/1/end1" class="0/1/" size="0.0050000000000000001" pos="0.23205028739731537 0 0.60565680619588447"/>
        <site name="0/1/attach2" class="0/1/" size="9.9999999999999995e-07 9.9999999999999995e-07 9.9999999999999995e-07" pos="0.027328944027598133 0 0.071329198261758625"/>
        <body pos="0.027328944027598133 0 0.071329198261758625" name="0/1/2/">
          <joint name="0/1/2/joint/" class="0/1/" type="hinge" axis="0 1 0" limited="true" range="-53.119299073301711 53.119299073301711"/>
          <geom name="0/1/2/geom" class="0/1/2/" type="capsule" contype="1" conaffinity="1" condim="3" size="0.065090658336542609" rgba="0.12396179863064738 0.88590171022669051 0.067716206590793471 1" friction="0.59999999999999998 0.10000000000000001 0.10000000000000001" fromto="0 0 0 0.44123452988786926 0 -0.38549765535508346"/>
          <site name="0/1/2/end2" class="0/1/2/" size="0.0050000000000000001" pos="0.44123452988786926 0 -0.38549765535508346"/>
        </body>
      </body>
      <site name="0/attach3" class="0/" size="9.9999999999999995e-07 9.9999999999999995e-07 9.9999999999999995e-07" pos="-0.093618221991471864 0 0.081880895050274405"/>
      <body pos="-0.093618221991471864 0 0.081880895050274405" name="0/3/">
        <joint name="0/3/joint/" class="0/" type="hinge" axis="0 1 0" limited="true" range="-42.195923909363842 42.195923909363842"/>
        <geom name="0/3/geom" class="0/3/" type="capsule" contype="1" conaffinity="1" condim="3" size="0.061633431422683321" rgba="0.57063193219995545 0.11543743390343808 0.16240958043480547 1" friction="0.59999999999999998 0.10000000000000001 0.10000000000000001" fromto="0 0 0 -0.67983570176323393 0 -0.23378735176310017"/>
        <site name="0/3/end3" class="0/3/" size="0.0050000000000000001" pos="-0.67983570176323393 0 -0.23378735176310017"/>
      </body>
      <camera name="0/side" class="0/" mode="trackcom" pos="0.40000000000000002 -4 0.20000000000000001" quat="0.70699999999999996 0.70699999999999996 0 0"/>
    </body>
  </worldbody>
  <actuator>
    <motor name="0/1/motor" class="0/1/" ctrllimited="true" ctrlrange="-1 1" gear="75" joint="0/1/joint/"/>
    <motor name="0/1/2/motor" class="0/1/2/" ctrllimited="true" ctrlrange="-1 1" gear="79" joint="0/1/2/joint/"/>
    <motor name="0/3/motor" class="0/3/" ctrllimited="true" ctrlrange="-1 1" gear="52" joint="0/3/joint/"/>
  </actuator>
  <sensor>
    <subtreelinvel name="velocity" body="0/"/>
  </sensor>
</mujoco>
