<mujoco model="morphology">
  <option timestep="0.01"/>
  <default>
    <default class="/"/>
    <default class="0/"/>
    <default class="0/1/"/>
    <default class="0/1/2/"/>
    <default class="0/1/2/3/"/>
    <default class="0/1/2/3/4/"/>
    <default class="0/1/2/3/4/5/"/>
    <default class="0/1/2/3/4/5/6/"/>
    <default class="0/1/2/3/4/5/6/7/"/>
    <default class="0/1/2/3/4/5/6/7/8/"/>
    <default class="0/1/2/3/4/5/6/7/8/9/"/>
    <default class="0/1/2/10/"/>
  </default>
  <asset>
    <texture name="texplane" type="2d" builtin="checker" rgb1="0.10000000000000001 0.20000000000000001 0.29999999999999999" rgb2="0.20000000000000001 0.29999999999999999 0.40000000000000002" width="300" height="300"/>
    <material name="MatPlane" class="/" texture="texplane" texrepeat="20 20" specular="1" shininess="1" reflectance="0.5"/>
  </asset>
  <worldbody>
    <light name="//unnamed_light_0" class="/" directional="true" pos="0 0 1.5" dir="0 0 -1.3" cutoff="100" exponent="1" diffuse="1 1 1" specular="0.10000000000000001 0.10000000000000001 0.10000000000000001"/>
    <geom name="ground" class="/" type="plane" size="15 15 0.5" material="MatPlane" rgba="1 1 1 1"/>
    <site name="body" class="/" size="9.9999999999999995e-07 9.9999999999999995e-07 9.9999999999999995e-07" pos="0 0 0.57419503331184385"/>
    <body pos="0 0 0.57419503331184385" name="0/">
      <joint name="0/rootx/" class="/" type="slide" axis="1 0 0" limited="false" stiffness="0" armature="0" damping="0"/>
      <joint name="0/rootz/" class="/" type="slide" axis="0 0 1" limited="false" stiffness="0" armature="0" damping="0"/>
      <joint name="0/rooty/" class="/" type="hinge" axis="0 1 0" limited="false" stiffness="0" armature="0" damping="0"/>
      <geom name="0/geom" class="0/" type="capsule" contype="1" conaffinity="1" condim="3" size="0.054897242197513352" rgba="0.15614758744545831 0.68813081683236932 0.7199678424230922 1" friction="0.59999999999999998 0.10000000000000001 0.10000000000000001" fromto="0 0 0 0.65211244571106075 0 -0.14005695452123978"/>
      <site name="0/end0" class="0/" size="0.0050000000000000001" pos="0.65211244571106075 0 -0.14005695452123978"/>
      <site name="0/attach1" class="0/" size="9.9999999999999995e-07 9.9999999999999995e-07 9.9999999999999995e-07" pos="0.12236427893639316 0 -0.026280694936486829"/>
      <body pos="0.12236427893639316 0 -0.026280694936486829" name="0/1/">
        <joint name="0/1/joint/" class="0/" type="hinge" axis="0 1 0" limited="true" stiffness="100" range="-33.617361653368143 33.617361653368143" armature="0.20000000000000001" damping="3.5"/>
        <geom name="0/1/geom" class="0/1/" type="capsule" contype="1" conaffinity="1" condim="3" size="0.047528624215371629" rgba="0.1835355291420091 0.86293230550811484 0.55174352324557818 1" friction="0.59999999999999998 0.10000000000000001 0.10000000000000001" fromto="0 0 0 -0.67335079630061656 0 -0.4479143411124224"/>
        <site name="0/1/end1" class="0/1/" size="0.0050000000000000001" pos="-0.67335079630061656 0 -0.4479143411124224"/>
        <site name="0/1/attach2" class="0/1/" size="9.9999999999999995e-07 9.9999999999999995e-07 9.9999999999999995e-07" pos="-0.2304871946421925 0 -0.15332055815512485"/>
        <body pos="-0.2304871946421925 0 -0.15332055815512485" name="0/1/2/">
          <joint name="0/1/2/joint/" class="0/1/" type="hinge" axis="0 1 0" limited="true" stiffness="100" range="-31.693278492916789 31.693278492916789" armature="0.20000000000000001" damping="3.5"/>
          <geom name="0/1/2/geom" class="0/1/2/" type="capsule" contype="1" conaffinity="1" condim="3" size="0.061851727785431077" rgba="0.95413894193299698 0.31215836260922303 0.76475093093905389 1" friction="0.59999999999999998 0.10000000000000001 0.10000000000000001" fromto="0 0 0 -0.43749410286235474 0 0.22475029279569092"/>
          <site name="0/1/2/end2" class="0/1/2/" size="0.0050000000000000001" pos="-0.43749410286235474 0 0.22475029279569092"/>
          <site name="0/1/2/attach3" class="0/1/2/" size="9.9999999999999995e-07 9.9999999999999995e-07 9.9999999999999995e-07" pos="-0.074705235996355937 0 0.038377714245064226"/>
          <body pos="-0.074705235996355937 0 0.038377714245064226" name="0/1/2/3/">
            <joint name="0/1/2/3/joint/" class="0/1/2/" type="hinge" axis="0 1 0" limited="true" stiffness="100" range="-33.503303918782805 33.503303918782805" armature="0.20000000000000001" damping="3.5"/>
            <geom name="0/1/2/3/geom" class="0/1/2/3/" type="capsule" contype="1" conaffinity="1" condim="3" size="0.065538412189162648" rgba="0.3155334357527132 0.93246327031665077 0.52786399421762198 1" friction="0.59999999999999998 0.10000000000000001 0.10000000000000001" fromto="0 0 0 0.16983147161201306 0 0.64473698400472501"/>
            <site name="0/1/2/3/end3" class="0/1/2/3/" size="0.0050000000000000001" pos="0.16983147161201306 0 0.64473698400472501"/>
            <site name="0/1/2/3/attach4" class="0/1/2/3/" size="9.9999999999999995e-07 9.9999999999999995e-07 9.9999999999999995e-07" pos="0.12632722124991952 0 0.4795803207337308"/>
            <body pos="0.12632722124991952 0 0.4795803207337308" name="0/1/2/3/4/">
              <joint name="0/1/2/3/4/joint/" class="0/1/2/3/" type="hinge" axis="0 1 0" limited="true" stiffness="100" range="-61.726466201476235 61.726466201476235" armature="0.20000000000000001" damping="3.5"/>
              <geom name="0/1/2/3/4/geom" class="0/1/2/3/4/" type="capsule" contype="1" conaffinity="1" condim="3" size="0.068549178420946336" rgba="0.52786712630234778 0.99637292372049058 0.029047822378028276 1" friction="0.59999999999999998 0.10000000000000001 0.10000000000000001" fromto="0 0 0 0.4446843157608531 0 -0.04623030637239478"/>
              <site name="0/1/2/3/4/end4" class="0/1/2/3/4/" size="0.0050000000000000001" pos="0.4446843157608531 0 -0.04623030637239478"/>
              <site name="0/1/2/3/4/attach5" class="0/1/2/3/4/" size="9.9999999999999995e-07 9.9999999999999995e-07 9.9999999999999995e-07" pos="0.24947078264589576 0 -0.025935501442068541"/>
              <body pos="0.24947078264589576 0 -0.025935501442068541" name="0/1/2/3/4/5/">
                <joint name="0/1/2/3/4/5/joint/" class="0/1/2/3/4/" type="hinge" axis="0 1 0" limited="true" stiffness="100" range="-31.371271280608227 31.371271280608227" armature="0.20000000000000001" damping="3.5"/>
                <geom name="0/1/2/3/4/5/geom" class="0/1/2/3/4/5/" type="capsule" contype="1" conaffinity="1" condim="3" size="0.060969640645145817" rgba="0.060569121902097178 0.096901102531045669 0.082674871492191437 1" friction="0.59999999999999998 0.10000000000000001 0.10000000000000001" fromto="0 0 0 -0.28268400723027381 0 0.72388567098322043"/>
                <site name="0/1/2/3/4/5/end5" class="0/1/2/3/4/5/" size="0.0050000000000000001" pos="-0.28268400723027381 0 0.72388567098322043"/>
                <site name="0/1/2/3/4/5/attach6" class="0/1/2/3/4/5/" size="9.9999999999999995e-07 9.9999999999999995e-07 9.9999999999999995e-07" pos="-0.16838815145551478 0 0.43120150728125572"/>
                <body pos="-0.16838815145551478 0 0.43120150728125572" name="0/1/2/3/4/5/6/">
                  <joint name="0/1/2/3/4/5/6/joint/" class="0/1/2/3/4/5/" type="hinge" axis="0 1 0" limited="true" stiffness="100" range="-60.511279624231953 60.511279624231953" armature="0.20000000000000001" damping="3.5"/>
                  <geom name="0/1/2/3/4/5/6/geom" class="0/1/2/3/4/5/6/" type="capsule" contype="1" conaffinity="1" condim="3" size="0.06330903045519852" rgba="0.32194549687153362 0.72389067531652362 0.4217427894350918 1" friction="0.59999999999999998 0.10000000000000001 0.10000000000000001" fromto="0 0 0 0.46817469003882195 0 0.036030512361026057"/>
                  <site name="0/1/2/3/4/5/6/end6" class="0/1/2/3/4/5/6/" size="0.0050000000000000001" pos="0.46817469003882195 0 0.036030512361026057"/>
                  <site name="0/1/2/3/4/5/6/attach7" class="0/1/2/3/4/5/6/" size="9.9999999999999995e-07 9.9999999999999995e-07 9.9999999999999995e-07" pos="0.24004573371826576 0 0.018473811079429251"/>
                  <body pos="0.24004573371826576 0 0.018473811079429251" name="0/1/2/3/4/5/6/7/">
                    <joint name="0/1/2/3/4/5/6/7/joint/" class="0/1/2/3/4/5/6/" type="hinge" axis="0 1 0" limited="true" stiffness="100" range="-30.836441684476974 30.836441684476974" armature="0.20000000000000001" damping="3.5"/>
                    <geom name="0/1/2/3/4/5/6/7/geom" class="0/1/2/3/4/5/6/7/" type="capsule" contype="1" conaffinity="1" condim="3" size="0.065723971962670977" rgba="0.71034318647586747 0.88395095469124563 0.89760896426306802 1" friction="0.59999999999999998 0.10000000000000001 0.10000000000000001" fromto="0 0 0 -0.023683975313723682 0 -0.2189204107923699"/>
                    <site name="0/1/2/3/4/5/6/7/end7" class="0/1/2/3/4/5/6/7/" size="0.0050000000000000001" pos="-0.023683975313723682 0 -0.2189204107923699"/>
                    <site name="0/1/2/3/4/5/6/7/attach8" class="0/1/2/3/4/5/6/7/" size="9.9999999999999995e-07 9.9999999999999995e-07 9.9999999999999995e-07" pos="-0.010097291707276659 0 -0.093333286290267312"/>
                    <body pos="-0.010097291707276659 0 -0.093333286290267312" name="0/1/2/3/4/5/6/7/8/">
                      <joint name="0/1/2/3/4/5/6/7/8/joint/" class="0/1/2/3/4/5/6/7/" type="hinge" axis="0 1 0" limited="true" stiffness="100" range="-49.829943716928824 49.829943716928824" armature="0.20000000000000001" damping="3.5"/>
                      <geom name="0/1/2/3/4/5/6/7/8/geom" class="0/1/2/3/4/5/6/7/8/" type="capsule" contype="1" conaffinity="1" condim="3" size="0.06181136112095327" rgba="0.51771939465396155 0.4743135589968771 0.37619382346808083 1" friction="0.59999999999999998 0.10000000000000001 0.10000000000000001" fromto="0 0 0 0.17821496878633947 0 -0.15917844101782563"/>
                      <site name="0/1/2/3/4/5/6/7/8/end8" class="0/1/2/3/4/5/6/7/8/" size="0.0050000000000000001" pos="0.17821496878633947 0 -0.15917844101782563"/>
                      <site name="0/1/2/3/4/5/6/7/8/attach9" class="0/1/2/3/4/5/6/7/8/" size="9.9999999999999995e-07 9.9999999999999995e-07 9.9999999999999995e-07" pos="0.14869142811962408 0 -0.13280853949575799"/>
                      <body pos="0.14869142811962408 0 -0.13280853949575799" name="0/1/2/3/4/5/6/7/8/9/">
                        <joint name="0/1/2/3/4/5/6/7/8/9/joint/" class="0/1/2/3/4/5/6/7/8/" type="hinge" axis="0 1 0" limited="true" stiffness="100" range="-62.68259086015626 62.68259086015626" armature="0.20000000000000001" damping="3.5"/>
                        <geom name="0/1/2/3/4/5/6/7/8/9/geom" class="0/1/2/3/4/5/6/7/8/9/" type="capsule" contype="1" conaffinity="1" condim="3" size="0.057973377448440555" rgba="0.40610777856351898 0.1477269766444721 0.58228852462411795 1" friction="0.59999999999999998 0.10000000000000001 0.10000000000000001" fromto="0 0 0 0.68526987346467827 0 0.058693804257534121"/>
                        <site name="0/1/2/3/4/5/6/7/8/9/end9" class="0/1/2/3/4/5/6/7/8/9/" size="0.0050000000000000001" pos="0.68526987346467827 0 0.058693804257534121"/>
                      </body>
                    </body>
                  </body>
                </body>
              </body>
            </body>
          </body>
          <site name="0/1/2/attach10" class="0/1/2/" size="9.9999999999999995e-07 9.9999999999999995e-07 9.9999999999999995e-07" pos="-0.17189906002714461 0 0.088308308202636548"/>
          <body pos="-0.17189906002714461 0 0.088308308202636548" name="0/1/2/10/">
            <joint name="0/1/2/10/joint/" class="0/1/2/" type="hinge" axis="0 1 0" limited="true" stiffness="100" range="-42.746777939087515 42.746777939087515" armature="0.20000000000000001" damping="3.5"/>
            <geom name="0/1/2/10/geom" class="0/1/2/10/" type="capsule" contype="1" conaffinity="1" condim="3" size="0.069611027349672575" rgba="0.91090447896672222 0.66913078436012297 0.84195747112686625 1" friction="0.59999999999999998 0.10000000000000001 0.10000000000000001" fromto="0 0 0 -0.06382554225509729 0 0.47224379360982405"/>
            <site name="0/1/2/10/end10" class="0/1/2/10/" size="0.0050000000000000001" pos="-0.06382554225509729 0 0.47224379360982405"/>
          </body>
        </body>
      </body>
      <camera name="0/side" class="0/" mode="trackcom" pos="0.40000000000000002 -4 0.20000000000000001" quat="0.70699999999999996 0.70699999999999996 0 0"/>
    </body>
  </worldbody>
  <actuator>
    <motor name="0/1/motor" class="0/1/" ctrllimited="true" ctrlrange="-1 1" gear="54" joint="0/1/joint/"/>
    <motor name="0/1/2/motor" class="0/1/2/" ctrllimited="true" ctrlrange="-1 1" gear="61" joint="0/1/2/joint/"/>
    <motor name="0/1/2/3/motor" class="0/1/2/3/" ctrllimited="true" ctrlrange="-1 1" gear="78" joint="0/1/2/3/joint/"/>
    <motor name="0/1/2/3/4/motor" class="0/1/2/3/4/" ctrllimited="true" ctrlrange="-1 1" gear="63" joint="0/1/2/3/4/joint/"/>
    <motor name="0/1/2/3/4/5/motor" class="0/1/2/3/4/5/" ctrllimited="true" ctrlrange="-1 1" gear="61" joint="0/1/2/3/4/5/joint/"/>
    <motor name="0/1/2/3/4/5/6/motor" class="0/1/2/3/4/5/6/" ctrllimited="true" ctrlrange="-1 1" gear="87" joint="0/1/2/3/4/5/6/joint/"/>
    <motor name="0/1/2/3/4/5/6/7/motor" class="0/1/2/3/4/5/6/7/" ctrllimited="true" ctrlrange="-1 1" gear="51" joint="0/1/2/3/4/5/6/7/joint/"/>
    <motor name="0/1/2/3/4/5/6/7/8/motor" class="0/1/2/3/4/5/6/7/8/" ctrllimited="true" ctrlrange="-1 1" gear="52" joint="0/1/2/3/4/5/6/7/8/joint/"/>
    <motor name="0/1/2/3/4/5/6/7/8/9/motor" class="0/1/2/3/4/5/6/7/8/9/" ctrllimited="true" ctrlrange="-1 1" gear="58" joint="0/1/2/3/4/5/6/7/8/9/joint/"/>
    <motor name="0/1/2/10/motor" class="0/1/2/10/" ctrllimited="true" ctrlrange="-1 1" gear="54" joint="0/1/2/10/joint/"/>
  </actuator>
  <sensor>
    <subtreelinvel name="velocity" body="0/"/>
  </sensor>
</mujoco>
