<mujoco model="morphology">
  <option timestep="0.01"/>
  <default>
    <default class="/"/>
    <default class="0/"/>
    <default class="0/1/"/>
    <default class="0/1/2/"/>
    <default class="0/1/2/3/"/>
    <default class="0/1/2/3/4/"/>
    <default class="0/1/5/"/>
    <default class="0/1/6/"/>
    <default class="0/1/6/7/"/>
    <default class="0/1/6/7/8/"/>
    <default class="0/1/6/7/8/9/"/>
    <default class="0/1/6/7/8/9/10/"/>
  </default>
  <asset>
    <texture name="texplane" type="2d" builtin="checker" rgb1="0.10000000000000001 0.20000000000000001 0.29999999999999999" rgb2="0.20000000000000001 0.29999999999999999 0.40000000000000002" width="300" height="300"/>
    <material name="MatPlane" class="/" texture="texplane" texrepeat="20 20" specular="1" shininess="1" reflectance="0.5"/>
  </asset>
  <worldbody>
    <light name="//unnamed_light_0" class="/" directional="true" pos="0 0 1.5" dir="0 0 -1.3" cutoff="100" exponent="1" diffuse="1 1 1" specular="0.10000000000000001 0.10000000000000001 0.10000000000000001"/>
    <geom name="ground" class="/" type="plane" size="15 15 0.5" material="MatPlane" rgba="1 1 1 1"/>
    <site name="body" class="/" size="9.9999999999999995e-07 9.9999999999999995e-07 9.9999999999999995e-07" pos="0 0 0.42505053281784055"/>
    <body pos="0 0 0.42505053281784055" name="0/">
      <joint name="0/rootx/" class="/" type="slide" axis="1 0 0" limited="false" stiffness="0" armature="0" damping="0"/>
      <joint name="0/rootz/" class="/" type="slide" axis="0 0 1" limited="false" stiffness="0" armature="0" damping="0"/>
      <joint name="0/rooty/" class="/" type="hinge" axis="0 1 0" limited="false" stiffness="0" armature="0" damping="0"/>
      <geom name="0/geom" class="0/" type="capsule" contype="1" conaffinity="1" condim="3" size="0.052430943019504878" rgba="0.95718455451807727 0.84661698205237312 0.77945117892688232 1" friction="0.59999999999999998 0.10000000000000001 0.10000000000000001" fromto="0 0 0 -0.74234679306412066 0 0.29253816664621635"/>
      <site name="0/end0" class="0/" size="0.0050000000000000001" pos="-0.74234679306412066 0 0.29253816664621635"/>
      <site name="0/attach1" class="0/" size="9.9999999999999995e-07 9.9999999999999995e-07 9.9999999999999995e-07" pos="-0.016267879368019943 0 0.0064107175379570927"/>
      <body pos="-0.016267879368019943 0 0.0064107175379570927" name="0/1/">
        <joint name="0/1/joint/" class="0/" type="hinge" axis="0 1 0" limited="true" stiffness="100" range="-60.187594394953408 60.187594394953408" armature="0.20000000000000001" damping="3.5"/>
        <geom name="0/1/geom" class="0/1/" type="capsule" contype="1" conaffinity="1" condim="3" size="0.041084215412603216" rgba="0.85674135375507332 0.90265029879819303 0.38739369975382387 1" friction="0.59999999999999998 0.10000000000000001 0.10000000000000001" fromto="0 0 0 0.57981885233801767 0 0.56753032222411148"/>
        <site name="0/1/end1" class="0/1/" size="0.0050000000000000001" pos="0.57981885233801767 0 0.56753032222411148"/>
        <site name="0/1/attach2" class="0/1/" size="9.9999999999999995e-07 9.9999999999999995e-07 9.9999999999999995e-07" pos="0.10952295032798055 0 0.10720174937385113"/>
        <body pos="0.10952295032798055 0 0.10720174937385113" name="0/1/2/">
          <joint name="0/1/2/joint/" class="0/1/" type="hinge" axis="0 1 0" limited="true" stiffness="100" range="-51.740245212800673 51.740245212800673" armature="0.20000000000000001" damping="3.5"/>
          <geom name="0/1/2/geom" class="0/1/2/" type="capsule" contype="1" conaffinity="1" condim="3" size="0.046364580444047211" rgba="0.2391651416853412 0.36436765408522576 0.89644231218343973 1" friction="0.59999999999999998 0.10000000000000001 0.10000000000000001" fromto="0 0 0 -0.7266009664112929 0 0.65724225630595701"/>
          <site name="0/1/2/end2" class="0/1/2/" size="0.0050000000000000001" pos="-0.7266009664112929 0 0.65724225630595701"/>
          <site name="0/1/2/attach3" class="0/1/2/" size="9.9999999999999995e-07 9.9999999999999995e-07 9.9999999999999995e-07" pos="-0.30253152965286795 0 0.27365295993866318"/>
          <body pos="-0.30253152965286795 0 0.27365295993866318" name="0/1/2/3/">
            <joint name="0/1/2/3/joint/" class="0/1/2/" type="hinge" axis="0 1 0" limited="true" stiffness="100" range="-50.69386597163728 50.69386597163728" armature="0.20000000000000001" damping="3.5"/>
            <geom name="0/1/2/3/geom" class="0/1/2/3/" type="capsule" contype="1" conaffinity="1" condim="3" size="0.06421395686905973" rgba="0.47553567937760721 0.68353697173180994 0.91844348413548427 1" friction="0.59999999999999998 0.10000000000000001 0.10000000000000001" fromto="0 0 0 0.13054457285401266 0 0.48750361862987335"/>
            <site name="0/1/2/3/end3" class="0/1/2/3/" size="0.0050000000000000001" pos="0.13054457285401266 0 0.48750361862987335"/>
            <site name="0/1/2/3/attach4" class="0/1/2/3/" size="9.9999999999999995e-07 9.9999999999999995e-07 9.9999999999999995e-07" pos="0.060910309714656864 0 0.2274625114516878"/>
            <body pos="0.060910309714656864 0 0.2274625114516878" name="0/1/2/3/4/">
              <joint name="0/1/2/3/4/joint/" class="0/1/2/3/" type="hinge" axis="0 1 0" limited="true" stiffness="100" range="-45.751889056644593 45.751889056644593" armature="0.20000000000000001" damping="3.5"/>
              <geom name="0/1/2/3/4/geom" class="0/1/2/3/4/" type="capsule" contype="1" conaffinity="1" condim="3" size="0.043515445519544345" rgba="0.54428386320638267 0.029401778327389438 0.81118314354443477 1" friction="0.59999999999999998 0.10000000000000001 0.10000000000000001" fromto="0 0 0 -0.31102087080648011 0 0.18654420829168172"/>
              <site name="0/1/2/3/4/end4" class="0/1/2/3/4/" size="0.0050000000000000001" pos="-0.31102087080648011 0 0.18654420829168172"/>
            </body>
          </body>
        </body>
        <site name="0/1/attach5" class="0/1/" size="9.9999999999999995e-07 9.9999999999999995e-07 9.9999999999999995e-07" pos="0.48571904251307996 0 0.47542483932056284"/>
        <body pos="0.48571904251307996 0 0.47542483932056284" name="0/1/5/">
          <joint name="0/1/5/joint/" class="0/1/" type="hinge" axis="0 1 0" limited="true" stiffness="100" range="-46.33747538800381 46.33747538800381" armature="0.20000000000000001" damping="3.5"/>
          <geom name="0/1/5/geom" class="0/1/5/" type="capsule" contype="1" conaffinity="1" condim="3" size="0.043915232440433383" rgba="0.85798686909786881 0.8703354181249856 0.42834590580157728 1" friction="0.59999999999999998 0.10000000000000001 0.10000000000000001" fromto="0 0 0 0.65136720712572771 0 -0.57533027993266495"/>
          <site name="0/1/5/end5" class="0/1/5/" size="0.0050000000000000001" pos="0.65136720712572771 0 -0.57533027993266495"/>
        </body>
        <site name="0/1/attach6" class="0/1/" size="9.9999999999999995e-07 9.9999999999999995e-07 9.9999999999999995e-07" pos="0.40055965381676123 0 0.39207029658304099"/>
        <body pos="0.40055965381676123 0 0.39207029658304099" name="0/1/6/">
          <geom name="0/1/6/geom" class="0/1/6/" type="capsule" contype="1" conaffinity="1" condim="3" size="0.041191234091603725" rgba="0.74798403309985817 0.38981519409697685 0.99961655749200595 1" friction="0.59999999999999998 0.10000000000000001 0.10000000000000001" fromto="0 0 0 0.038403441167755625 0 -0.034027356771699546"/>
          <site name="0/1/6/end6" class="0/1/6/" size="0.0050000000000000001" pos="0.038403441167755625 0 -0.034027356771699546"/>
          <site name="0/1/6/attach7" class="0/1/6/" size="9.9999999999999995e-07 9.9999999999999995e-07 9.9999999999999995e-07" pos="0.022760159822389828 0 -0.020166632335740294"/>
          <body pos="0.022760159822389828 0 -0.020166632335740294" name="0/1/6/7/">
            <joint name="0/1/6/7/joint/" class="0/1/6/" type="hinge" axis="0 1 0" limited="true" stiffness="100" range="-51.102437093473235 51.102437093473235" armature="0.20000000000000001" damping="3.5"/>
            <geom name="0/1/6/7/geom" class="0/1/6/7/" type="capsule" contype="1" conaffinity="1" condim="3" size="0.069973386302265239" rgba="0.078971860730180587 0.32296559471331632 0.51769755598792844 1" friction="0.59999999999999998 0.10000000000000001 0.10000000000000001" fromto="0 0 0 0.29750160464194852 0 -0.3706987741811254"/>
            <site name="0/1/6/7/end7" class="0/1/6/7/" size="0.0050000000000000001" pos="0.29750160464194852 0 -0.3706987741811254"/>
            <site name="0/1/6/7/attach8" class="0/1/6/7/" size="9.9999999999999995e-07 9.9999999999999995e-07 9.9999999999999995e-07" pos="0.11302745566256986 0 -0.14083668326210519"/>
            <body pos="0.11302745566256986 0 -0.14083668326210519" name="0/1/6/7/8/">
              <joint name="0/1/6/7/8/joint/" class="0/1/6/7/" type="hinge" axis="0 1 0" limited="true" stiffness="100" range="-47.089225707722179 47.089225707722179" armature="0.20000000000000001" damping="3.5"/>
              <geom name="0/1/6/7/8/geom" class="0/1/6/7/8/" type="capsule" contype="1" conaffinity="1" condim="3" size="0.051741930947340246" rgba="0.84328217575768138 0.38430006765261515 0.7736519808829313 1" friction="0.59999999999999998 0.10000000000000001 0.10000000000000001" fromto="0 0 0 -0.5527777435268777 0 -0.56252824383687305"/>
              <site name="0/1/6/7/8/end8" class="0/1/6/7/8/" size="0.0050000000000000001" pos="-0.5527777435268777 0 -0.56252824383687305"/>
              <site name="0/1/6/7/8/attach9" class="0/1/6/7/8/" size="9.9999999999999995e-07 9.9999999999999995e-07 9.9999999999999995e-07" pos="-0.23575302640161741 0 -0.23991149693327249"/>
              <body pos="-0.23575302640161741 0 -0.23991149693327249" name="0/1/6/7/8/9/">
                <joint name="0/1/6/7/8/9/joint/" class="0/1/6/7/8/" type="hinge" axis="0 1 0" limited="true" stiffness="100" range="-43.464871439967141 43.464871439967141" armature="0.20000000000000001" damping="3.5"/>
                <geom name="0/1/6/7/8/9/geom" class="0/1/6/7/8/9/" type="capsule" contype="1" conaffinity="1" condim="3" size="0.054054408218233617" rgba="0.067950263366364227 0.59599509659788263 0.25091092616856214 1" friction="0.59999999999999998 0.10000000000000001 0.10000000000000001" fromto="0 0 0 -0.099912149271813577 0 0.076634390781297634"/>
                <site name="0/1/6/7/8/9/end9" class="0/1/6/7/8/9/" size="0.0050000000000000001" pos="-0.099912149271813577 0 0.076634390781297634"/>
                <site name="0/1/6/7/8/9/attach10" class="0/1/6/7/8/9/" size="9.9999999999999995e-07 9.9999999999999995e-07 9.9999999999999995e-07" pos="-0.050292095011689845 0 0.038574928979365659"/>
                <body pos="-0.050292095011689845 0 0.038574928979365659" name="0/1/6/7/8/9/10/">
                  <joint name="0/1/6/7/8/9/10/joint/" class="0/1/6/7/8/9/" type="hinge" axis="0 1 0" limited="true" stiffness="100" range="-52.295201608351661 52.295201608351661" armature="0.20000000000000001" damping="3.5"/>
                  <geom name="0/1/6/7/8/9/10/geom" class="0/1/6/7/8/9/10/" type="capsule" contype="1" conaffinity="1" condim="3" size="0.068638130454726123" rgba="0.41172375408418072 0.72325899844904129 0.29005328333608682 1" friction="0.59999999999999998 0.10000000000000001 0.10000000000000001" fromto="0 0 0 -0.59959345888439985 0 -0.29971518079820431"/>
                  <site name="0/1/6/7/8/9/10/end10" class="0/1/6/7/8/9/10/" size="0.0050000000000000001" pos="-0.59959345888439985 0 -0.29971518079820431"/>
                </body>
              </body>
            </body>
          </body>
        </body>
      </body>
      <camera name="0/side" class="0/" mode="trackcom" pos="0.40000000000000002 -4 0.20000000000000001" quat="0.70699999999999996 0.70699999999999996 0 0"/>
    </body>
  </worldbody>
  <actuator>
    <motor name="0/1/motor" class="0/1/" ctrllimited="true" ctrlrange="-1 1" gear="87" joint="0/1/joint/"/>
    <motor name="0/1/2/motor" class="0/1/2/" ctrllimited="true" ctrlrange="-1 1" gear="86" joint="0/1/2/joint/"/>
    <motor name="0/1/2/3/motor" class="0/1/2/3/" ctrllimited="true" ctrlrange="-1 1" gear="51" joint="0/1/2/3/joint/"/>
    <motor name="0/1/2/3/4/motor" class="0/1/2/3/4/" ctrllimited="true" ctrlrange="-1 1" gear="88" joint="0/1/2/3/4/joint/"/>
    <motor name="0/1/5/motor" class="0/1/5/" ctrllimited="true" ctrlrange="-1 1" gear="66" joint="0/1/5/joint/"/>
    <motor name="0/1/6/7/motor" class="0/1/6/7/" ctrllimited="true" ctrlrange="-1 1" gear="75" joint="0/1/6/7/joint/"/>
    <motor name="0/1/6/7/8/motor" class="0/1/6/7/8/" ctrllimited="true" ctrlrange="-1 1" gear="70" joint="0/1/6/7/8/joint/"/>
    <motor name="0/1/6/7/8/9/motor" class="0/1/6/7/8/9/" ctrllimited="true" ctrlrange="-1 1" gear="82" joint="0/1/6/7/8/9/joint/"/>
    <motor name="0/1/6/7/8/9/10/motor" class="0/1/6/7/8/9/10/" ctrllimited="true" ctrlrange="-1 1" gear="72" joint="0/1/6/7/8/9/10/joint/"/>
  </actuator>
  <sensor>
    <subtreelinvel name="velocity" body="0/"/>
  </sensor>
</mujoco>
