<mujoco model="morphology">
  <option timestep="0.01"/>
  <default>
    <default class="/"/>
    <default class="0/"/>
    <default class="0/1/"/>
    <default class="0/1/2/"/>
    <default class="0/1/2/3/"/>
    <default class="0/1/2/4/"/>
    <default class="0/1/2/4/5/"/>
    <default class="0/1/2/4/5/6/"/>
    <default class="0/1/2/4/5/7/"/>
    <default class="0/1/2/4/5/7/8/"/>
    <default class="0/1/2/4/5/7/8/9/"/>
    <default class="0/1/10/"/>
  </default>
  <asset>
    <texture name="texplane" type="2d" builtin="checker" rgb1="0.10000000000000001 0.20000000000000001 0.29999999999999999" rgb2="0.20000000000000001 0.29999999999999999 0.40000000000000002" width="300" height="300"/>
    <material name="MatPlane" class="/" texture="texplane" texrepeat="20 20" specular="1" shininess="1" reflectance="0.5"/>
  </asset>
  <worldbody>
    <light name="//unnamed_light_0" class="/" directional="true" pos="0 0 1.5" dir="0 0 -1.3" cutoff="100" exponent="1" diffuse="1 1 1" specular="0.10000000000000001 0.10000000000000001 0.10000000000000001"/>
    <geom name="ground" class="/" type="plane" size="15 15 0.5" material="MatPlane" rgba="1 1 1 1"/>
    <site name="body" class="/" size="9.9999999999999995e-07 9.9999999999999995e-07 9.9999999999999995e-07" pos="0 0 1.3718687057495118"/>
    <body pos="0 0 1.3718687057495118" name="0/">
      <joint name="0/rootx/" class="/" type="slide" axis="1 0 0" limited="false" stiffness="0" armature="0" damping="0"/>
      <joint name="0/rootz/" class="/" type="slide" axis="0 0 1" limited="false" stiffness="0" armature="0" damping="0"/>
      <joint name="0/rooty/" class="/" type="hinge" axis="0 1 0" limited="false" stiffness="0" armature="0" damping="0"/>
      <geom name="0/geom" class="0/" type="capsule" contype="1" conaffinity="1" condim="3" size="0.055966174511568878" rgba="0.44313332524770488 0.19186535641296221 0.064812494364438811 1" friction="0.59999999999999998 0.10000000000000001 0.10000000000000001" fromto="0 0 0 0.35041066005827393 0 -0.15514460153925902"/>
      <site name="0/end0" class="0/" size="0.0050000000000000001" pos="0.35041066005827393 0 -0.15514460153925902"/>
      <site name="0/attach1" class="0/" size="9.9999999999999995e-07 9.9999999999999995e-07 9.9999999999999995e-07" pos="0.012640940844800132 0 -0.0055967867248151474"/>
      <body pos="0.012640940844800132 0 -0.0055967867248151474" name="0/1/">
        <joint name="0/1/joint/" class="0/" type="hinge" axis="0 1 0" limited="true" range="-32.65148809903063 32.65148809903063"/>
        <geom name="0/1/geom" class="0/1/" type="capsule" contype="1" conaffinity="1" condim="3" size="0.054655275985746099" rgba="0.88239396685646609 0.035400947245696757 0.77675995984342194 1" friction="0.59999999999999998 0.10000000000000001 0.10000000000000001" fromto="0 0 0 -0.19394345045389016 0 -0.67455773322658841"/>
        <site name="0/1/end1" class="0/1/" size="0.0050000000000000001" pos="-0.19394345045389016 0 -0.67455773322658841"/>
        <site name="0/1/attach2" class="0/1/" size="9.9999999999999995e-07 9.9999999999999995e-07 9.9999999999999995e-07" pos="-0.030184873931063484 0 -0.10498647976519029"/>
        <body pos="-0.030184873931063484 0 -0.10498647976519029" name="0/1/2/">
          <joint name="0/1/2/joint/" class="0/1/" type="hinge" axis="0 1 0" limited="true" range="-46.513732955999529 46.513732955999529"/>
          <geom name="0/1/2/geom" class="0/1/2/" type="capsule" contype="1" conaffinity="1" condim="3" size="0.042875915051510186" rgba="0.61291097289630381 0.59207551628822441 0.27666223328914741 1" friction="0.59999999999999998 0.10000000000000001 0.10000000000000001" fromto="0 0 0 -0.47428910181173023 0 0.31060182832078143"/>
          <site name="0/1/2/end2" class="0/1/2/" size="0.0050000000000000001" pos="-0.47428910181173023 0 0.31060182832078143"/>
          <site name="0/1/2/attach3" class="0/1/2/" size="9.9999999999999995e-07 9.9999999999999995e-07 9.9999999999999995e-07" pos="-0.2229557531718564 0 0.14600897280853933"/>
          <body pos="-0.2229557531718564 0 0.14600897280853933" name="0/1/2/3/">
            <geom name="0/1/2/3/geom" class="0/1/2/3/" type="capsule" contype="1" conaffinity="1" condim="3" size="0.052159894893671462" rgba="0.70503797566639126 0.8978111968050706 0.50649108196410997 1" friction="0.59999999999999998 0.10000000000000001 0.10000000000000001" fromto="0 0 0 0.21062927907575912 0 0.69484399433204436"/>
            <site name="0/1/2/3/end3" class="0/1/2/3/" size="0.0050000000000000001" pos="0.21062927907575912 0 0.69484399433204436"/>
          </body>
          <site name="0/1/2/attach4" class="0/1/2/" size="9.9999999999999995e-07 9.9999999999999995e-07 9.9999999999999995e-07" pos="-0.46516906894772247 0 0.30462931309518204"/>
          <body pos="-0.46516906894772247 0 0.30462931309518204" name="0/1/2/4/">
            <joint name="0/1/2/4/joint/" class="0/1/2/" type="hinge" axis="0 1 0" limited="true" range="-56.451623428896383 56.451623428896383"/>
            <geom name="0/1/2/4/geom" class="0/1/2/4/" type="capsule" contype="1" conaffinity="1" condim="3" size="0.062519324296496301" rgba="0.17042853284810044 0.23988418711167148 0.43607134567925299 1" friction="0.59999999999999998 0.10000000000000001 0.10000000000000001" fromto="0 0 0 -0.20331127995527165 0 0.72526793102180487"/>
            <site name="0/1/2/4/end4" class="0/1/2/4/" size="0.0050000000000000001" pos="-0.20331127995527165 0 0.72526793102180487"/>
            <site name="0/1/2/4/attach5" class="0/1/2/4/" size="9.9999999999999995e-07 9.9999999999999995e-07 9.9999999999999995e-07" pos="-0.20063036283836866 0 0.71570435338339278"/>
            <body pos="-0.20063036283836866 0 0.71570435338339278" name="0/1/2/4/5/">
              <joint name="0/1/2/4/5/joint/" class="0/1/2/4/" type="hinge" axis="0 1 0" limited="true" range="-51.479990454492238 51.479990454492238"/>
              <geom name="0/1/2/4/5/geom" class="0/1/2/4/5/" type="capsule" contype="1" conaffinity="1" condim="3" size="0.063234646744134926" rgba="0.38942925036996279 0.0023025499771960334 0.78193411980993444 1" friction="0.59999999999999998 0.10000000000000001 0.10000000000000001" fromto="0 0 0 0.2031314431466944 0 0.16034745792692751"/>
              <site name="0/1/2/4/5/end5" class="0/1/2/4/5/" size="0.0050000000000000001" pos="0.2031314431466944 0 0.16034745792692751"/>
              <site name="0/1/2/4/5/attach6" class="0/1/2/4/5/" size="9.9999999999999995e-07 9.9999999999999995e-07 9.9999999999999995e-07" pos="0.021031502261943343 0 0.016601801630738426"/>
              <body pos="0.021031502261943343 0 0.016601801630738426" name="0/1/2/4/5/6/">
                <joint name="0/1/2/4/5/6/joint/" class="0/1/2/4/5/" type="hinge" axis="0 1 0" limited="true" range="-69.462687635668729 69.462687635668729"/>
                <geom name="0/1/2/4/5/6/geom" class="0/1/2/4/5/6/" type="capsule" contype="1" conaffinity="1" condim="3" size="0.065077689734957408" rgba="0.22971863473930809 0.97799617341900968 0.54495322494429932 1" friction="0.59999999999999998 0.10000000000000001 0.10000000000000001" fromto="0 0 0 -0.69657676975862626 0 0.6541337697255114"/>
                <site name="0/1/2/4/5/6/end6" class="0/1/2/4/5/6/" size="0.0050000000000000001" pos="-0.69657676975862626 0 0.6541337697255114"/>
              </body>
              <site name="0/1/2/4/5/attach7" class="0/1/2/4/5/" size="9.9999999999999995e-07 9.9999999999999995e-07 9.9999999999999995e-07" pos="0.030336050332510193 0 0.023946605601814684"/>
              <body pos="0.030336050332510193 0 0.023946605601814684" name="0/1/2/4/5/7/">
                <geom name="0/1/2/4/5/7/geom" class="0/1/2/4/5/7/" type="capsule" contype="1" conaffinity="1" condim="3" size="0.041841429389755339" rgba="0.73365028234825458 0.61710922707836602 0.18572083048370813 1" friction="0.59999999999999998 0.10000000000000001 0.10000000000000001" fromto="0 0 0 0.38744370955424889 0 -0.38553273445973335"/>
                <site name="0/1/2/4/5/7/end7" class="0/1/2/4/5/7/" size="0.0050000000000000001" pos="0.38744370955424889 0 -0.38553273445973335"/>
                <site name="0/1/2/4/5/7/attach8" class="0/1/2/4/5/7/" size="9.9999999999999995e-07 9.9999999999999995e-07 9.9999999999999995e-07" pos="0.11406366163768947 0 -0.11350106941795864"/>
                <body pos="0.11406366163768947 0 -0.11350106941795864" name="0/1/2/4/5/7/8/">
                  <joint name="0/1/2/4/5/7/8/joint/" class="0/1/2/4/5/7/" type="hinge" axis="0 1 0" limited="true" range="-39.277109441606584 39.277109441606584"/>
                  <geom name="0/1/2/4/5/7/8/geom" class="0/1/2/4/5/7/8/" type="capsule" contype="1" conaffinity="1" condim="3" size="0.044777578358063772" rgba="0.1107809974060211 0.58500539598134327 0.78779155174225368 1" friction="0.59999999999999998 0.10000000000000001 0.10000000000000001" fromto="0 0 0 0.46167399686343735 0 0.36662206784685636"/>
                  <site name="0/1/2/4/5/7/8/end8" class="0/1/2/4/5/7/8/" size="0.0050000000000000001" pos="0.46167399686343735 0 0.36662206784685636"/>
                  <site name="0/1/2/4/5/7/8/attach9" class="0/1/2/4/5/7/8/" size="9.9999999999999995e-07 9.9999999999999995e-07 9.9999999999999995e-07" pos="0.41644874991495939 0 0.33070803831999906"/>
                  <body pos="0.41644874991495939 0 0.33070803831999906" name="0/1/2/4/5/7/8/9/">
                    <joint name="0/1/2/4/5/7/8/9/joint/" class="0/1/2/4/5/7/8/" type="hinge" axis="0 1 0" limited="true" range="-58.38737350175888 58.38737350175888"/>
                    <geom name="0/1/2/4/5/7/8/9/geom" class="0/1/2/4/5/7/8/9/" type="capsule" contype="1" conaffinity="1" condim="3" size="0.065927628638102226" rgba="0.55210174367449827 0.022667746201956662 0.31059112664703992 1" friction="0.59999999999999998 0.10000000000000001 0.10000000000000001" fromto="0 0 0 -0.013217076876590017 0 0.40742430161895893"/>
                    <site name="0/1/2/4/5/7/8/9/end9" class="0/1/2/4/5/7/8/9/" size="0.0050000000000000001" pos="-0.013217076876590017 0 0.40742430161895893"/>
                  </body>
                </body>
              </body>
            </body>
          </body>
        </body>
        <site name="0/1/attach10" class="0/1/" size="9.9999999999999995e-07 9.9999999999999995e-07 9.9999999999999995e-07" pos="-0.19384794671648345 0 -0.6742255601912579"/>
        <body pos="-0.19384794671648345 0 -0.6742255601912579" name="0/1/10/">
          <joint name="0/1/10/joint/" class="0/1/" type="hinge" axis="0 1 0" limited="true" range="-43.930565924400518 43.930565924400518"/>
          <geom name="0/1/10/geom" class="0/1/10/" type="capsule" contype="1" conaffinity="1" condim="3" size="0.040711715735526323" rgba="0.40954853361280286 0.53805709185702233 0.16575910656133874 1" friction="0.59999999999999998 0.10000000000000001 0.10000000000000001" fromto="0 0 0 0.32482684309549814 0 -0.5920463837562856"/>
          <site name="0/1/10/end10" class="0/1/10/" size="0.0050000000000000001" pos="0.32482684309549814 0 -0.5920463837562856"/>
        </body>
      </body>
      <camera name="0/side" class="0/" mode="trackcom" pos="0.40000000000000002 -4 0.20000000000000001" quat="0.70699999999999996 0.70699999999999996 0 0"/>
    </body>
  </worldbody>
  <actuator>
    <motor name="0/1/motor" class="0/1/" ctrllimited="true" ctrlrange="-1 1" gear="65" joint="0/1/joint/"/>
    <motor name="0/1/2/motor" class="0/1/2/" ctrllimited="true" ctrlrange="-1 1" gear="61" joint="0/1/2/joint/"/>
    <motor name="0/1/2/4/motor" class="0/1/2/4/" ctrllimited="true" ctrlrange="-1 1" gear="84" joint="0/1/2/4/joint/"/>
    <motor name="0/1/2/4/5/motor" class="0/1/2/4/5/" ctrllimited="true" ctrlrange="-1 1" gear="54" joint="0/1/2/4/5/joint/"/>
    <motor name="0/1/2/4/5/6/motor" class="0/1/2/4/5/6/" ctrllimited="true" ctrlrange="-1 1" gear="80" joint="0/1/2/4/5/6/joint/"/>
    <motor name="0/1/2/4/5/7/8/motor" class="0/1/2/4/5/7/8/" ctrllimited="true" ctrlrange="-1 1" gear="64" joint="0/1/2/4/5/7/8/joint/"/>
    <motor name="0/1/2/4/5/7/8/9/motor" class="0/1/2/4/5/7/8/9/" ctrllimited="true" ctrlrange="-1 1" gear="81" joint="0/1/2/4/5/7/8/9/joint/"/>
    <motor name="0/1/10/motor" class="0/1/10/" ctrllimited="true" ctrlrange="-1 1" gear="83" joint="0/1/10/joint/"/>
  </actuator>
  <sensor>
    <subtreelinvel name="velocity" body="0/"/>
  </sensor>
</mujoco>
