<mujoco model="morphology">
  <option timestep="0.01"/>
  <default>
    <default class="/"/>
    <default class="0/"/>
    <default class="0/1/"/>
    <default class="0/1/2/"/>
    <default class="0/1/2/3/"/>
    <default class="0/1/2/3/4/"/>
    <default class="0/1/2/3/5/"/>
    <default class="0/1/2/3/5/6/"/>
    <default class="0/1/2/7/"/>
    <default class="0/1/2/8/"/>
    <default class="0/1/2/8/9/"/>
    <default class="0/10/"/>
  </default>
  <asset>
    <texture name="texplane" type="2d" builtin="checker" rgb1="0.10000000000000001 0.20000000000000001 0.29999999999999999" rgb2="0.20000000000000001 0.29999999999999999 0.40000000000000002" width="300" height="300"/>
    <material name="MatPlane" class="/" texture="texplane" texrepeat="20 20" specular="1" shininess="1" reflectance="0.5"/>
  </asset>
  <worldbody>
    <light name="//unnamed_light_0" class="/" directional="true" pos="0 0 1.5" dir="0 0 -1.3" cutoff="100" exponent="1" diffuse="1 1 1" specular="0.10000000000000001 0.10000000000000001 0.10000000000000001"/>
    <geom name="ground" class="/" type="plane" size="15 15 0.5" material="MatPlane" rgba="1 1 1 1"/>
    <site name="body" class="/" size="9.9999999999999995e-07 9.9999999999999995e-07 9.9999999999999995e-07" pos="0 0 1.0482953548431397"/>
    <body pos="0 0 1.0482953548431397" name="0/">
      <joint name="0/rootx/" class="/" type="slide" axis="1 0 0" limited="false" stiffness="0" armature="0" damping="0"/>
      <joint name="0/rootz/" class="/" type="slide" axis="0 0 1" limited="false" stiffness="0" armature="0" damping="0"/>
      <joint name="0/rooty/" class="/" type="hinge" axis="0 1 0" limited="false" stiffness="0" armature="0" damping="0"/>
      <geom name="0/geom" class="0/" type="capsule" contype="1" conaffinity="1" condim="3" size="0.059619498212394373" rgba="0.11664460753634087 0.65141572274623827 0.87374278991312249 1" friction="0.59999999999999998 0.10000000000000001 0.10000000000000001" fromto="0 0 0 -0.57529233198034291 0 0.055032538376827089"/>
      <site name="0/end0" class="0/" size="0.0050000000000000001" pos="-0.57529233198034291 0 0.055032538376827089"/>
      <site name="0/attach1" class="0/" size="9.9999999999999995e-07 9.9999999999999995e-07 9.9999999999999995e-07" pos="-0.50789336998613299 0 0.048585145014679157"/>
      <body pos="-0.50789336998613299 0 0.048585145014679157" name="0/1/">
        <joint name="0/1/joint/" class="0/" type="hinge" axis="0 1 0" limited="true" stiffness="100" range="-47.617730223987451 47.617730223987451" armature="0.20000000000000001" damping="3.5"/>
        <geom name="0/1/geom" class="0/1/" type="capsule" contype="1" conaffinity="1" condim="3" size="0.051718690374035453" rgba="0.065233930629535974 0.36681235561159453 0.99604353698268322 1" friction="0.59999999999999998 0.10000000000000001 0.10000000000000001" fromto="0 0 0 -0.18992438005081747 0 0.35555519087567533"/>
        <site name="0/1/end1" class="0/1/" size="0.0050000000000000001" pos="-0.18992438005081747 0 0.35555519087567533"/>
        <site name="0/1/attach2" class="0/1/" size="9.9999999999999995e-07 9.9999999999999995e-07 9.9999999999999995e-07" pos="-0.1036139785239379 0 0.19397450659893992"/>
        <body pos="-0.1036139785239379 0 0.19397450659893992" name="0/1/2/">
          <joint name="0/1/2/joint/" class="0/1/" type="hinge" axis="0 1 0" limited="true" stiffness="100" range="-30.891804441228828 30.891804441228828" armature="0.20000000000000001" damping="3.5"/>
          <geom name="0/1/2/geom" class="0/1/2/" type="capsule" contype="1" conaffinity="1" condim="3" size="0.05621248068003204" rgba="0.68439553289898603 0.98025841812143255 0.87996152337142786 1" friction="0.59999999999999998 0.10000000000000001 0.10000000000000001" fromto="0 0 0 -0.59548189606851154 0 -0.50423810613553832"/>
          <site name="0/1/2/end2" class="0/1/2/" size="0.0050000000000000001" pos="-0.59548189606851154 0 -0.50423810613553832"/>
          <site name="0/1/2/attach3" class="0/1/2/" size="9.9999999999999995e-07 9.9999999999999995e-07 9.9999999999999995e-07" pos="-0.5900877228335567 0 -0.49967046484515104"/>
          <body pos="-0.5900877228335567 0 -0.49967046484515104" name="0/1/2/3/">
            <geom name="0/1/2/3/geom" class="0/1/2/3/" type="capsule" contype="1" conaffinity="1" condim="3" size="0.060648823874858954" rgba="0.5569805401174428 0.67037953330902011 0.22440481118733868 1" friction="0.59999999999999998 0.10000000000000001 0.10000000000000001" fromto="0 0 0 0.53128499336424828 0 -0.42126805090874181"/>
            <site name="0/1/2/3/end3" class="0/1/2/3/" size="0.0050000000000000001" pos="0.53128499336424828 0 -0.42126805090874181"/>
            <site name="0/1/2/3/attach4" class="0/1/2/3/" size="9.9999999999999995e-07 9.9999999999999995e-07 9.9999999999999995e-07" pos="0.01214139353166562 0 -0.0096271892718304084"/>
            <body pos="0.01214139353166562 0 -0.0096271892718304084" name="0/1/2/3/4/">
              <joint name="0/1/2/3/4/joint/" class="0/1/2/3/" type="hinge" axis="0 1 0" limited="true" stiffness="100" range="-44.313698310489123 44.313698310489123" armature="0.20000000000000001" damping="3.5"/>
              <geom name="0/1/2/3/4/geom" class="0/1/2/3/4/" type="capsule" contype="1" conaffinity="1" condim="3" size="0.046408369158919729" rgba="0.98529795282742827 0.45386272314214093 0.33973348525402247 1" friction="0.59999999999999998 0.10000000000000001 0.10000000000000001" fromto="0 0 0 0.18896226457939758 0 0.038954019397251072"/>
              <site name="0/1/2/3/4/end4" class="0/1/2/3/4/" size="0.0050000000000000001" pos="0.18896226457939758 0 0.038954019397251072"/>
            </body>
            <site name="0/1/2/3/attach5" class="0/1/2/3/" size="9.9999999999999995e-07 9.9999999999999995e-07 9.9999999999999995e-07" pos="0.24265228630792557 0 -0.19240456059975095"/>
            <body pos="0.24265228630792557 0 -0.19240456059975095" name="0/1/2/3/5/">
              <geom name="0/1/2/3/5/geom" class="0/1/2/3/5/" type="capsule" contype="1" conaffinity="1" condim="3" size="0.063095246807825356" rgba="0.73963311877101801 0.99017379044396869 0.66333320957083486 1" friction="0.59999999999999998 0.10000000000000001 0.10000000000000001" fromto="0 0 0 -0.052925708486949108 0 -0.4987799564826535"/>
              <site name="0/1/2/3/5/end5" class="0/1/2/3/5/" size="0.0050000000000000001" pos="-0.052925708486949108 0 -0.4987799564826535"/>
              <site name="0/1/2/3/5/attach6" class="0/1/2/3/5/" size="9.9999999999999995e-07 9.9999999999999995e-07 9.9999999999999995e-07" pos="-0.011581083606851131 0 -0.10914189989297125"/>
              <body pos="-0.011581083606851131 0 -0.10914189989297125" name="0/1/2/3/5/6/">
                <geom name="0/1/2/3/5/6/geom" class="0/1/2/3/5/6/" type="capsule" contype="1" conaffinity="1" condim="3" size="0.059239474601051195" rgba="0.19988696160669239 0.80579287350692863 0.22279691614243469 1" friction="0.59999999999999998 0.10000000000000001 0.10000000000000001" fromto="0 0 0 -0.67785168929455819 0 -0.23888496569057538"/>
                <site name="0/1/2/3/5/6/end6" class="0/1/2/3/5/6/" size="0.0050000000000000001" pos="-0.67785168929455819 0 -0.23888496569057538"/>
              </body>
            </body>
          </body>
          <site name="0/1/2/attach7" class="0/1/2/" size="9.9999999999999995e-07 9.9999999999999995e-07 9.9999999999999995e-07" pos="-0.33384683184875696 0 -0.28269254756890044"/>
          <body pos="-0.33384683184875696 0 -0.28269254756890044" name="0/1/2/7/">
            <geom name="0/1/2/7/geom" class="0/1/2/7/" type="capsule" contype="1" conaffinity="1" condim="3" size="0.056540380205881924" rgba="0.79195226191201418 0.61722149399673742 0.99729647398945531 1" friction="0.59999999999999998 0.10000000000000001 0.10000000000000001" fromto="0 0 0 -0.048615024468404044 0 0.74539112662117213"/>
            <site name="0/1/2/7/end7" class="0/1/2/7/" size="0.0050000000000000001" pos="-0.048615024468404044 0 0.74539112662117213"/>
          </body>
          <site name="0/1/2/attach8" class="0/1/2/" size="9.9999999999999995e-07 9.9999999999999995e-07 9.9999999999999995e-07" pos="-0.15846549664046111 0 -0.1341843344715562"/>
          <body pos="-0.15846549664046111 0 -0.1341843344715562" name="0/1/2/8/">
            <joint name="0/1/2/8/joint/" class="0/1/2/" type="hinge" axis="0 1 0" limited="true" stiffness="100" range="-41.927652992179929 41.927652992179929" armature="0.20000000000000001" damping="3.5"/>
            <geom name="0/1/2/8/geom" class="0/1/2/8/" type="capsule" contype="1" conaffinity="1" condim="3" size="0.047953150994816882" rgba="0.27652167681398554 0.43861599767533455 0.2198060579444423 1" friction="0.59999999999999998 0.10000000000000001 0.10000000000000001" fromto="0 0 0 0.082810396412836385 0 -0.14544563153468781"/>
            <site name="0/1/2/8/end8" class="0/1/2/8/" size="0.0050000000000000001" pos="0.082810396412836385 0 -0.14544563153468781"/>
            <site name="0/1/2/8/attach9" class="0/1/2/8/" size="9.9999999999999995e-07 9.9999999999999995e-07 9.9999999999999995e-07" pos="0.012353501775533137 0 -0.021697310304492026"/>
            <body pos="0.012353501775533137 0 -0.021697310304492026" name="0/1/2/8/9/">
              <joint name="0/1/2/8/9/joint/" class="0/1/2/8/" type="hinge" axis="0 1 0" limited="true" stiffness="100" range="-59.145365341741041 59.145365341741041" armature="0.20000000000000001" damping="3.5"/>
              <geom name="0/1/2/8/9/geom" class="0/1/2/8/9/" type="capsule" contype="1" conaffinity="1" condim="3" size="0.042398304477568718" rgba="0.92531573287786861 0.14188639898335775 0.50457126883595216 1" friction="0.59999999999999998 0.10000000000000001 0.10000000000000001" fromto="0 0 0 -0.066164319991296794 0 -0.20819983909854722"/>
              <site name="0/1/2/8/9/end9" class="0/1/2/8/9/" size="0.0050000000000000001" pos="-0.066164319991296794 0 -0.20819983909854722"/>
            </body>
          </body>
        </body>
      </body>
      <site name="0/attach10" class="0/" size="9.9999999999999995e-07 9.9999999999999995e-07 9.9999999999999995e-07" pos="-0.48427836782894912 0 0.046326130874840978"/>
      <body pos="-0.48427836782894912 0 0.046326130874840978" name="0/10/">
        <joint name="0/10/joint/" class="0/" type="hinge" axis="0 1 0" limited="true" stiffness="100" range="-65.793783105857926 65.793783105857926" armature="0.20000000000000001" damping="3.5"/>
        <geom name="0/10/geom" class="0/10/" type="capsule" contype="1" conaffinity="1" condim="3" size="0.053099537148540835" rgba="0.89447822073792593 0.019283623592032173 0.47461984009149416 1" friction="0.59999999999999998 0.10000000000000001 0.10000000000000001" fromto="0 0 0 -0.2321616979135086 0 -0.32224701945110246"/>
        <site name="0/10/end10" class="0/10/" size="0.0050000000000000001" pos="-0.2321616979135086 0 -0.32224701945110246"/>
      </body>
      <camera name="0/side" class="0/" mode="trackcom" pos="0.40000000000000002 -4 0.20000000000000001" quat="0.70699999999999996 0.70699999999999996 0 0"/>
    </body>
  </worldbody>
  <actuator>
    <motor name="0/1/motor" class="0/1/" ctrllimited="true" ctrlrange="-1 1" gear="70" joint="0/1/joint/"/>
    <motor name="0/1/2/motor" class="0/1/2/" ctrllimited="true" ctrlrange="-1 1" gear="52" joint="0/1/2/joint/"/>
    <motor name="0/1/2/3/4/motor" class="0/1/2/3/4/" ctrllimited="true" ctrlrange="-1 1" gear="50" joint="0/1/2/3/4/joint/"/>
    <motor name="0/1/2/8/motor" class="0/1/2/8/" ctrllimited="true" ctrlrange="-1 1" gear="66" joint="0/1/2/8/joint/"/>
    <motor name="0/1/2/8/9/motor" class="0/1/2/8/9/" ctrllimited="true" ctrlrange="-1 1" gear="74" joint="0/1/2/8/9/joint/"/>
    <motor name="0/10/motor" class="0/10/" ctrllimited="true" ctrlrange="-1 1" gear="87" joint="0/10/joint/"/>
  </actuator>
  <sensor>
    <subtreelinvel name="velocity" body="0/"/>
  </sensor>
</mujoco>
