<mujoco model="morphology">
  <option timestep="0.01"/>
  <default>
    <default class="/"/>
    <default class="0/"/>
    <default class="0/1/"/>
    <default class="0/1/2/"/>
    <default class="0/1/2/3/"/>
    <default class="0/1/2/3/4/"/>
    <default class="0/1/2/3/4/5/"/>
    <default class="0/1/2/3/4/6/"/>
    <default class="0/1/2/3/4/6/7/"/>
    <default class="0/1/2/3/4/6/7/8/"/>
    <default class="0/1/2/3/4/6/7/9/"/>
    <default class="0/1/2/3/4/6/7/9/10/"/>
  </default>
  <asset>
    <texture name="texplane" type="2d" builtin="checker" rgb1="0.10000000000000001 0.20000000000000001 0.29999999999999999" rgb2="0.20000000000000001 0.29999999999999999 0.40000000000000002" width="300" height="300"/>
    <material name="MatPlane" class="/" texture="texplane" texrepeat="20 20" specular="1" shininess="1" reflectance="0.5"/>
  </asset>
  <worldbody>
    <light name="//unnamed_light_0" class="/" directional="true" pos="0 0 1.5" dir="0 0 -1.3" cutoff="100" exponent="1" diffuse="1 1 1" specular="0.10000000000000001 0.10000000000000001 0.10000000000000001"/>
    <geom name="ground" class="/" type="plane" size="15 15 0.5" material="MatPlane" rgba="1 1 1 1"/>
    <site name="body" class="/" size="9.9999999999999995e-07 9.9999999999999995e-07 9.9999999999999995e-07" pos="0 0 0.2655503064393997"/>
    <body pos="0 0 0.2655503064393997" name="0/">
      <joint name="0/rootx/" class="/" type="slide" axis="1 0 0" limited="false" stiffness="0" armature="0" damping="0"/>
      <joint name="0/rootz/" class="/" type="slide" axis="0 0 1" limited="false" stiffness="0" armature="0" damping="0"/>
      <joint name="0/rooty/" class="/" type="hinge" axis="0 1 0" limited="false" stiffness="0" armature="0" damping="0"/>
      <geom name="0/geom" class="0/" type="capsule" contype="1" conaffinity="1" condim="3" size="0.05559091210967116" rgba="0.84999864605613684 0.085769879168850705 0.13323185665898141 1" friction="0.59999999999999998 0.10000000000000001 0.10000000000000001" fromto="0 0 0 -0.20353642395621907 0 0.46700880786743415"/>
      <site name="0/end0" class="0/" size="0.0050000000000000001" pos="-0.20353642395621907 0 0.46700880786743415"/>
      <site name="0/attach1" class="0/" size="9.9999999999999995e-07 9.9999999999999995e-07 9.9999999999999995e-07" pos="-0.0063295837435310724 0 0.014523058334754719"/>
      <body pos="-0.0063295837435310724 0 0.014523058334754719" name="0/1/">
        <joint name="0/1/joint/" class="0/" type="hinge" axis="0 1 0" limited="true" range="-43.622563429126821 43.622563429126821"/>
        <geom name="0/1/geom" class="0/1/" type="capsule" contype="1" conaffinity="1" condim="3" size="0.056012604966118595" rgba="0.40485113320221722 0.97321422538380653 0.9370013504540613 1" friction="0.59999999999999998 0.10000000000000001 0.10000000000000001" fromto="0 0 0 0.44651134081668964 0 0.53580261914261285"/>
        <site name="0/1/end1" class="0/1/" size="0.0050000000000000001" pos="0.44651134081668964 0 0.53580261914261285"/>
        <site name="0/1/attach2" class="0/1/" size="9.9999999999999995e-07 9.9999999999999995e-07 9.9999999999999995e-07" pos="0.29977013682197673 0 0.35971678604215868"/>
        <body pos="0.29977013682197673 0 0.35971678604215868" name="0/1/2/">
          <joint name="0/1/2/joint/" class="0/1/" type="hinge" axis="0 1 0" limited="true" range="-62.056243008854672 62.056243008854672"/>
          <geom name="0/1/2/geom" class="0/1/2/" type="capsule" contype="1" conaffinity="1" condim="3" size="0.057164587283926045" rgba="0.073148345982581464 0.16453503711319128 0.70314085299851026 1" friction="0.59999999999999998 0.10000000000000001 0.10000000000000001" fromto="0 0 0 0.53987145109455348 0 -0.53979014660756608"/>
          <site name="0/1/2/end2" class="0/1/2/" size="0.0050000000000000001" pos="0.53987145109455348 0 -0.53979014660756608"/>
          <site name="0/1/2/attach3" class="0/1/2/" size="9.9999999999999995e-07 9.9999999999999995e-07 9.9999999999999995e-07" pos="0.37279018387034901 0 -0.37273404177468522"/>
          <body pos="0.37279018387034901 0 -0.37273404177468522" name="0/1/2/3/">
            <joint name="0/1/2/3/joint/" class="0/1/2/" type="hinge" axis="0 1 0" limited="true" range="-33.245585384753312 33.245585384753312"/>
            <geom name="0/1/2/3/geom" class="0/1/2/3/" type="capsule" contype="1" conaffinity="1" condim="3" size="0.057534179579511555" rgba="0.37538383686521026 0.14770828535362146 0.12244667467059223 1" friction="0.59999999999999998 0.10000000000000001 0.10000000000000001" fromto="0 0 0 0.61168396465316377 0 0.61488425756474463"/>
            <site name="0/1/2/3/end3" class="0/1/2/3/" size="0.0050000000000000001" pos="0.61168396465316377 0 0.61488425756474463"/>
            <site name="0/1/2/3/attach4" class="0/1/2/3/" size="9.9999999999999995e-07 9.9999999999999995e-07 9.9999999999999995e-07" pos="0.22939826804268454 0 0.23059846568324588"/>
            <body pos="0.22939826804268454 0 0.23059846568324588" name="0/1/2/3/4/">
              <joint name="0/1/2/3/4/joint/" class="0/1/2/3/" type="hinge" axis="0 1 0" limited="true" range="-69.859434510156689 69.859434510156689"/>
              <geom name="0/1/2/3/4/geom" class="0/1/2/3/4/" type="capsule" contype="1" conaffinity="1" condim="3" size="0.053137667631138003" rgba="0.27618527393383041 0.43507233126901701 0.56134184257189523 1" friction="0.59999999999999998 0.10000000000000001 0.10000000000000001" fromto="0 0 0 0.082394615095922608 0 -0.18245159043742265"/>
              <site name="0/1/2/3/4/end4" class="0/1/2/3/4/" size="0.0050000000000000001" pos="0.082394615095922608 0 -0.18245159043742265"/>
              <site name="0/1/2/3/4/attach5" class="0/1/2/3/4/" size="9.9999999999999995e-07 9.9999999999999995e-07 9.9999999999999995e-07" pos="0.078266384559632751 0 -0.1733101893135561"/>
              <body pos="0.078266384559632751 0 -0.1733101893135561" name="0/1/2/3/4/5/">
                <joint name="0/1/2/3/4/5/joint/" class="0/1/2/3/4/" type="hinge" axis="0 1 0" limited="true" range="-46.125869359844245 46.125869359844245"/>
                <geom name="0/1/2/3/4/5/geom" class="0/1/2/3/4/5/" type="capsule" contype="1" conaffinity="1" condim="3" size="0.06518622075937705" rgba="0.46806131573465604 0.65386587966538268 0.86238998004959355 1" friction="0.59999999999999998 0.10000000000000001 0.10000000000000001" fromto="0 0 0 0.67897090512126246 0 0.077778886379991752"/>
                <site name="0/1/2/3/4/5/end5" class="0/1/2/3/4/5/" size="0.0050000000000000001" pos="0.67897090512126246 0 0.077778886379991752"/>
              </body>
              <site name="0/1/2/3/4/attach6" class="0/1/2/3/4/" size="9.9999999999999995e-07 9.9999999999999995e-07 9.9999999999999995e-07" pos="0.060497778449198798 0 -0.13396404465433781"/>
              <body pos="0.060497778449198798 0 -0.13396404465433781" name="0/1/2/3/4/6/">
                <joint name="0/1/2/3/4/6/joint/" class="0/1/2/3/4/" type="hinge" axis="0 1 0" limited="true" range="-33.19783907052345 33.19783907052345"/>
                <geom name="0/1/2/3/4/6/geom" class="0/1/2/3/4/6/" type="capsule" contype="1" conaffinity="1" condim="3" size="0.060858993604330211" rgba="0.68292972136655039 0.12427670137235414 0.96419637633776389 1" friction="0.59999999999999998 0.10000000000000001 0.10000000000000001" fromto="0 0 0 0.59078862292731071 0 0.45576706934765943"/>
                <site name="0/1/2/3/4/6/end6" class="0/1/2/3/4/6/" size="0.0050000000000000001" pos="0.59078862292731071 0 0.45576706934765943"/>
                <site name="0/1/2/3/4/6/attach7" class="0/1/2/3/4/6/" size="9.9999999999999995e-07 9.9999999999999995e-07 9.9999999999999995e-07" pos="0.29577512598818961 0 0.22817731609255779"/>
                <body pos="0.29577512598818961 0 0.22817731609255779" name="0/1/2/3/4/6/7/">
                  <joint name="0/1/2/3/4/6/7/joint/" class="0/1/2/3/4/6/" type="hinge" axis="0 1 0" limited="true" range="-60.108343446533283 60.108343446533283"/>
                  <geom name="0/1/2/3/4/6/7/geom" class="0/1/2/3/4/6/7/" type="capsule" contype="1" conaffinity="1" condim="3" size="0.042232977311862777" rgba="0.15305419407328813 0.29966685043525521 0.79303751681887968 1" friction="0.59999999999999998 0.10000000000000001 0.10000000000000001" fromto="0 0 0 0.67149361262726615 0 -0.19223118612873558"/>
                  <site name="0/1/2/3/4/6/7/end7" class="0/1/2/3/4/6/7/" size="0.0050000000000000001" pos="0.67149361262726615 0 -0.19223118612873558"/>
                  <site name="0/1/2/3/4/6/7/attach8" class="0/1/2/3/4/6/7/" size="9.9999999999999995e-07 9.9999999999999995e-07 9.9999999999999995e-07" pos="0.35769147000079965 0 -0.10239778049020978"/>
                  <body pos="0.35769147000079965 0 -0.10239778049020978" name="0/1/2/3/4/6/7/8/">
                    <joint name="0/1/2/3/4/6/7/8/joint/" class="0/1/2/3/4/6/7/" type="hinge" axis="0 1 0" limited="true" range="-32.119180800049421 32.119180800049421"/>
                    <geom name="0/1/2/3/4/6/7/8/geom" class="0/1/2/3/4/6/7/8/" type="capsule" contype="1" conaffinity="1" condim="3" size="0.069733486923444457" rgba="0.73127144152376655 0.077150692270861798 0.47416588179164065 1" friction="0.59999999999999998 0.10000000000000001 0.10000000000000001" fromto="0 0 0 0.55432072138587207 0 0.46543970721298988"/>
                    <site name="0/1/2/3/4/6/7/8/end8" class="0/1/2/3/4/6/7/8/" size="0.0050000000000000001" pos="0.55432072138587207 0 0.46543970721298988"/>
                  </body>
                  <site name="0/1/2/3/4/6/7/attach9" class="0/1/2/3/4/6/7/" size="9.9999999999999995e-07 9.9999999999999995e-07 9.9999999999999995e-07" pos="0.56659037204937912 0 -0.1622001121381198"/>
                  <body pos="0.56659037204937912 0 -0.1622001121381198" name="0/1/2/3/4/6/7/9/">
                    <joint name="0/1/2/3/4/6/7/9/joint/" class="0/1/2/3/4/6/7/" type="hinge" axis="0 1 0" limited="true" range="-68.047415768114064 68.047415768114064"/>
                    <geom name="0/1/2/3/4/6/7/9/geom" class="0/1/2/3/4/6/7/9/" type="capsule" contype="1" conaffinity="1" condim="3" size="0.057557869807208381" rgba="0.11748265765882093 0.26627148037418336 0.67154276188924478 1" friction="0.59999999999999998 0.10000000000000001 0.10000000000000001" fromto="0 0 0 0.61412617585430418 0 0.64489067617704299"/>
                    <site name="0/1/2/3/4/6/7/9/end9" class="0/1/2/3/4/6/7/9/" size="0.0050000000000000001" pos="0.61412617585430418 0 0.64489067617704299"/>
                    <site name="0/1/2/3/4/6/7/9/attach10" class="0/1/2/3/4/6/7/9/" size="9.9999999999999995e-07 9.9999999999999995e-07 9.9999999999999995e-07" pos="0.061476516592666411 0 0.064556167630052966"/>
                    <body pos="0.061476516592666411 0 0.064556167630052966" name="0/1/2/3/4/6/7/9/10/">
                      <joint name="0/1/2/3/4/6/7/9/10/joint/" class="0/1/2/3/4/6/7/9/" type="hinge" axis="0 1 0" limited="true" range="-40.571461013263679 40.571461013263679"/>
                      <geom name="0/1/2/3/4/6/7/9/10/geom" class="0/1/2/3/4/6/7/9/10/" type="capsule" contype="1" conaffinity="1" condim="3" size="0.043120513048313554" rgba="0.91407194740696096 0.030730019939077202 0.18899362887535043 1" friction="0.59999999999999998 0.10000000000000001 0.10000000000000001" fromto="0 0 0 0.36523388012304858 0 -0.13226245301211692"/>
                      <site name="0/1/2/3/4/6/7/9/10/end10" class="0/1/2/3/4/6/7/9/10/" size="0.0050000000000000001" pos="0.36523388012304858 0 -0.13226245301211692"/>
                    </body>
                  </body>
                </body>
              </body>
            </body>
          </body>
        </body>
      </body>
      <camera name="0/side" class="0/" mode="trackcom" pos="0.40000000000000002 -4 0.20000000000000001" quat="0.70699999999999996 0.70699999999999996 0 0"/>
    </body>
  </worldbody>
  <actuator>
    <motor name="0/1/motor" class="0/1/" ctrllimited="true" ctrlrange="-1 1" gear="59" joint="0/1/joint/"/>
    <motor name="0/1/2/motor" class="0/1/2/" ctrllimited="true" ctrlrange="-1 1" gear="65" joint="0/1/2/joint/"/>
    <motor name="0/1/2/3/motor" class="0/1/2/3/" ctrllimited="true" ctrlrange="-1 1" gear="57" joint="0/1/2/3/joint/"/>
    <motor name="0/1/2/3/4/motor" class="0/1/2/3/4/" ctrllimited="true" ctrlrange="-1 1" gear="57" joint="0/1/2/3/4/joint/"/>
    <motor name="0/1/2/3/4/5/motor" class="0/1/2/3/4/5/" ctrllimited="true" ctrlrange="-1 1" gear="67" joint="0/1/2/3/4/5/joint/"/>
    <motor name="0/1/2/3/4/6/motor" class="0/1/2/3/4/6/" ctrllimited="true" ctrlrange="-1 1" gear="84" joint="0/1/2/3/4/6/joint/"/>
    <motor name="0/1/2/3/4/6/7/motor" class="0/1/2/3/4/6/7/" ctrllimited="true" ctrlrange="-1 1" gear="64" joint="0/1/2/3/4/6/7/joint/"/>
    <motor name="0/1/2/3/4/6/7/8/motor" class="0/1/2/3/4/6/7/8/" ctrllimited="true" ctrlrange="-1 1" gear="61" joint="0/1/2/3/4/6/7/8/joint/"/>
    <motor name="0/1/2/3/4/6/7/9/motor" class="0/1/2/3/4/6/7/9/" ctrllimited="true" ctrlrange="-1 1" gear="81" joint="0/1/2/3/4/6/7/9/joint/"/>
    <motor name="0/1/2/3/4/6/7/9/10/motor" class="0/1/2/3/4/6/7/9/10/" ctrllimited="true" ctrlrange="-1 1" gear="60" joint="0/1/2/3/4/6/7/9/10/joint/"/>
  </actuator>
  <sensor>
    <subtreelinvel name="velocity" body="0/"/>
  </sensor>
</mujoco>
