<mujoco model="morphology">
  <option timestep="0.01"/>
  <default>
    <default class="/"/>
    <default class="0/"/>
    <default class="0/1/"/>
    <default class="0/1/2/"/>
    <default class="0/1/2/3/"/>
    <default class="0/1/2/3/4/"/>
    <default class="0/1/2/3/4/5/"/>
    <default class="0/1/2/3/4/5/6/"/>
    <default class="0/1/2/3/4/7/"/>
    <default class="0/1/2/3/4/7/8/"/>
    <default class="0/1/2/3/4/7/8/9/"/>
    <default class="0/1/2/3/4/7/8/9/10/"/>
  </default>
  <asset>
    <texture name="texplane" type="2d" builtin="checker" rgb1="0.10000000000000001 0.20000000000000001 0.29999999999999999" rgb2="0.20000000000000001 0.29999999999999999 0.40000000000000002" width="300" height="300"/>
    <material name="MatPlane" class="/" texture="texplane" texrepeat="20 20" specular="1" shininess="1" reflectance="0.5"/>
  </asset>
  <worldbody>
    <light name="//unnamed_light_0" class="/" directional="true" pos="0 0 1.5" dir="0 0 -1.3" cutoff="100" exponent="1" diffuse="1 1 1" specular="0.10000000000000001 0.10000000000000001 0.10000000000000001"/>
    <geom name="ground" class="/" type="plane" size="15 15 0.5" material="MatPlane" rgba="1 1 1 1"/>
    <site name="body" class="/" size="9.9999999999999995e-07 9.9999999999999995e-07 9.9999999999999995e-07" pos="0 0 1.5937223196029664"/>
    <body pos="0 0 1.5937223196029664" name="0/">
      <joint name="0/rootx/" class="/" type="slide" axis="1 0 0" limited="false" stiffness="0" armature="0" damping="0"/>
      <joint name="0/rootz/" class="/" type="slide" axis="0 0 1" limited="false" stiffness="0" armature="0" damping="0"/>
      <joint name="0/rooty/" class="/" type="hinge" axis="0 1 0" limited="false" stiffness="0" armature="0" damping="0"/>
      <geom name="0/geom" class="0/" type="capsule" contype="1" conaffinity="1" condim="3" size="0.061814718757269627" rgba="0.82457119705670245 0.023491205641625656 0.38584653690992665 1" friction="0.59999999999999998 0.10000000000000001 0.10000000000000001" fromto="0 0 0 0.5795644691687194 0 -0.72140255403867171"/>
      <site name="0/end0" class="0/" size="0.0050000000000000001" pos="0.5795644691687194 0 -0.72140255403867171"/>
      <site name="0/attach1" class="0/" size="9.9999999999999995e-07 9.9999999999999995e-07 9.9999999999999995e-07" pos="0.24312702643350736 0 -0.30262803735454774"/>
      <body pos="0.24312702643350736 0 -0.30262803735454774" name="0/1/">
        <joint name="0/1/joint/" class="0/" type="hinge" axis="0 1 0" limited="true" range="-35.271294893660347 35.271294893660347"/>
        <geom name="0/1/geom" class="0/1/" type="capsule" contype="1" conaffinity="1" condim="3" size="0.064137200323948096" rgba="0.33465027778372225 0.11384248422378174 0.63260252153754204 1" friction="0.59999999999999998 0.10000000000000001 0.10000000000000001" fromto="0 0 0 -0.50792039785211185 0 -0.02119942445548828"/>
        <site name="0/1/end1" class="0/1/" size="0.0050000000000000001" pos="-0.50792039785211185 0 -0.02119942445548828"/>
        <site name="0/1/attach2" class="0/1/" size="9.9999999999999995e-07 9.9999999999999995e-07 9.9999999999999995e-07" pos="-0.24013173848822275 0 -0.010022544223412665"/>
        <body pos="-0.24013173848822275 0 -0.010022544223412665" name="0/1/2/">
          <geom name="0/1/2/geom" class="0/1/2/" type="capsule" contype="1" conaffinity="1" condim="3" size="0.045987058666026592" rgba="0.82778414055767469 0.86680974332060345 0.61635213896684571 1" friction="0.59999999999999998 0.10000000000000001 0.10000000000000001" fromto="0 0 0 -0.032843291983322254 0 -0.7165169607050963"/>
          <site name="0/1/2/end2" class="0/1/2/" size="0.0050000000000000001" pos="-0.032843291983322254 0 -0.7165169607050963"/>
          <site name="0/1/2/attach3" class="0/1/2/" size="9.9999999999999995e-07 9.9999999999999995e-07 9.9999999999999995e-07" pos="-0.022049367318711644 0 -0.48103416870318944"/>
          <body pos="-0.022049367318711644 0 -0.48103416870318944" name="0/1/2/3/">
            <joint name="0/1/2/3/joint/" class="0/1/2/" type="hinge" axis="0 1 0" limited="true" range="-57.09290934808692 57.09290934808692"/>
            <geom name="0/1/2/3/geom" class="0/1/2/3/" type="capsule" contype="1" conaffinity="1" condim="3" size="0.04812817781446211" rgba="0.64241987009919199 0.070497617459212458 0.8468628478177036 1" friction="0.59999999999999998 0.10000000000000001 0.10000000000000001" fromto="0 0 0 -0.4394650411590047 0 0.020073671619084799"/>
            <site name="0/1/2/3/end3" class="0/1/2/3/" size="0.0050000000000000001" pos="-0.4394650411590047 0 0.020073671619084799"/>
            <site name="0/1/2/3/attach4" class="0/1/2/3/" size="9.9999999999999995e-07 9.9999999999999995e-07 9.9999999999999995e-07" pos="-0.4073181238286529 0 0.018605280275933871"/>
            <body pos="-0.4073181238286529 0 0.018605280275933871" name="0/1/2/3/4/">
              <joint name="0/1/2/3/4/joint/" class="0/1/2/3/" type="hinge" axis="0 1 0" limited="true" range="-35.375353892833481 35.375353892833481"/>
              <geom name="0/1/2/3/4/geom" class="0/1/2/3/4/" type="capsule" contype="1" conaffinity="1" condim="3" size="0.060239342640682342" rgba="0.60890403015048877 0.21938454724087542 0.32750648822257744 1" friction="0.59999999999999998 0.10000000000000001 0.10000000000000001" fromto="0 0 0 0.41653768247024781 0 -0.56038537503953156"/>
              <site name="0/1/2/3/4/end4" class="0/1/2/3/4/" size="0.0050000000000000001" pos="0.41653768247024781 0 -0.56038537503953156"/>
              <site name="0/1/2/3/4/attach5" class="0/1/2/3/4/" size="9.9999999999999995e-07 9.9999999999999995e-07 9.9999999999999995e-07" pos="0.12992508985690349 0 -0.17479359796386776"/>
              <body pos="0.12992508985690349 0 -0.17479359796386776" name="0/1/2/3/4/5/">
                <joint name="0/1/2/3/4/5/joint/" class="0/1/2/3/4/" type="hinge" axis="0 1 0" limited="true" range="-41.073199378056074 41.073199378056074"/>
                <geom name="0/1/2/3/4/5/geom" class="0/1/2/3/4/5/" type="capsule" contype="1" conaffinity="1" condim="3" size="0.053722467302398609" rgba="0.70599592656928889 0.53417729328368624 0.59063058269953106 1" friction="0.59999999999999998 0.10000000000000001 0.10000000000000001" fromto="0 0 0 -0.18523284267120688 0 -0.54384926860431937"/>
                <site name="0/1/2/3/4/5/end5" class="0/1/2/3/4/5/" size="0.0050000000000000001" pos="-0.18523284267120688 0 -0.54384926860431937"/>
                <site name="0/1/2/3/4/5/attach6" class="0/1/2/3/4/5/" size="9.9999999999999995e-07 9.9999999999999995e-07 9.9999999999999995e-07" pos="-0.046186086218277397 0 -0.13560375604714861"/>
                <body pos="-0.046186086218277397 0 -0.13560375604714861" name="0/1/2/3/4/5/6/">
                  <joint name="0/1/2/3/4/5/6/joint/" class="0/1/2/3/4/5/" type="hinge" axis="0 1 0" limited="true" range="-42.446897267931625 42.446897267931625"/>
                  <geom name="0/1/2/3/4/5/6/geom" class="0/1/2/3/4/5/6/" type="capsule" contype="1" conaffinity="1" condim="3" size="0.068641359471369873" rgba="0.4542964034038881 0.82832085931233534 0.91168562254193675 1" friction="0.59999999999999998 0.10000000000000001 0.10000000000000001" fromto="0 0 0 -0.4717241051741744 0 -0.15768099426176896"/>
                  <site name="0/1/2/3/4/5/6/end6" class="0/1/2/3/4/5/6/" size="0.0050000000000000001" pos="-0.4717241051741744 0 -0.15768099426176896"/>
                </body>
              </body>
              <site name="0/1/2/3/4/attach7" class="0/1/2/3/4/" size="9.9999999999999995e-07 9.9999999999999995e-07 9.9999999999999995e-07" pos="0.016373427848274322 0 -0.022027849799863646"/>
              <body pos="0.016373427848274322 0 -0.022027849799863646" name="0/1/2/3/4/7/">
                <joint name="0/1/2/3/4/7/joint/" class="0/1/2/3/4/" type="hinge" axis="0 1 0" limited="true" range="-32.818792124034161 32.818792124034161"/>
                <geom name="0/1/2/3/4/7/geom" class="0/1/2/3/4/7/" type="capsule" contype="1" conaffinity="1" condim="3" size="0.056470434853130656" rgba="0.030241961856818267 0.83443289671715482 0.65984533534110257 1" friction="0.59999999999999998 0.10000000000000001 0.10000000000000001" fromto="0 0 0 -0.18386461127816189 0 -0.18455008651390181"/>
                <site name="0/1/2/3/4/7/end7" class="0/1/2/3/4/7/" size="0.0050000000000000001" pos="-0.18386461127816189 0 -0.18455008651390181"/>
                <site name="0/1/2/3/4/7/attach8" class="0/1/2/3/4/7/" size="9.9999999999999995e-07 9.9999999999999995e-07 9.9999999999999995e-07" pos="-0.062725468076674104 0 -0.062959318161896358"/>
                <body pos="-0.062725468076674104 0 -0.062959318161896358" name="0/1/2/3/4/7/8/">
                  <geom name="0/1/2/3/4/7/8/geom" class="0/1/2/3/4/7/8/" type="capsule" contype="1" conaffinity="1" condim="3" size="0.054098699413880943" rgba="0.17681809776735857 0.18253959075211668 0.39476333540521213 1" friction="0.59999999999999998 0.10000000000000001 0.10000000000000001" fromto="0 0 0 -0.30878339073606675 0 0.1263506253689759"/>
                  <site name="0/1/2/3/4/7/8/end8" class="0/1/2/3/4/7/8/" size="0.0050000000000000001" pos="-0.30878339073606675 0 0.1263506253689759"/>
                  <site name="0/1/2/3/4/7/8/attach9" class="0/1/2/3/4/7/8/" size="9.9999999999999995e-07 9.9999999999999995e-07 9.9999999999999995e-07" pos="-0.23004882734113064 0 0.094133344188827614"/>
                  <body pos="-0.23004882734113064 0 0.094133344188827614" name="0/1/2/3/4/7/8/9/">
                    <joint name="0/1/2/3/4/7/8/9/joint/" class="0/1/2/3/4/7/8/" type="hinge" axis="0 1 0" limited="true" range="-64.621969527905463 64.621969527905463"/>
                    <geom name="0/1/2/3/4/7/8/9/geom" class="0/1/2/3/4/7/8/9/" type="capsule" contype="1" conaffinity="1" condim="3" size="0.065903103681442823" rgba="0.76880978845686188 0.67190220364571662 0.98081645555754315 1" friction="0.59999999999999998 0.10000000000000001 0.10000000000000001" fromto="0 0 0 0.14283506380378941 0 0.28808814548865325"/>
                    <site name="0/1/2/3/4/7/8/9/end9" class="0/1/2/3/4/7/8/9/" size="0.0050000000000000001" pos="0.14283506380378941 0 0.28808814548865325"/>
                    <site name="0/1/2/3/4/7/8/9/attach10" class="0/1/2/3/4/7/8/9/" size="9.9999999999999995e-07 9.9999999999999995e-07 9.9999999999999995e-07" pos="0.1124778194035166 0 0.22685974674313192"/>
                    <body pos="0.1124778194035166 0 0.22685974674313192" name="0/1/2/3/4/7/8/9/10/">
                      <joint name="0/1/2/3/4/7/8/9/10/joint/" class="0/1/2/3/4/7/8/9/" type="hinge" axis="0 1 0" limited="true" range="-69.064272482482011 69.064272482482011"/>
                      <geom name="0/1/2/3/4/7/8/9/10/geom" class="0/1/2/3/4/7/8/9/10/" type="capsule" contype="1" conaffinity="1" condim="3" size="0.04384251902296557" rgba="0.35420570909674354 0.99296733958071282 0.87296386594830888 1" friction="0.59999999999999998 0.10000000000000001 0.10000000000000001" fromto="0 0 0 -0.30510145263193794 0 0.51344252842092408"/>
                      <site name="0/1/2/3/4/7/8/9/10/end10" class="0/1/2/3/4/7/8/9/10/" size="0.0050000000000000001" pos="-0.30510145263193794 0 0.51344252842092408"/>
                    </body>
                  </body>
                </body>
              </body>
            </body>
          </body>
        </body>
      </body>
      <camera name="0/side" class="0/" mode="trackcom" pos="0.40000000000000002 -4 0.20000000000000001" quat="0.70699999999999996 0.70699999999999996 0 0"/>
    </body>
  </worldbody>
  <actuator>
    <motor name="0/1/motor" class="0/1/" ctrllimited="true" ctrlrange="-1 1" gear="84" joint="0/1/joint/"/>
    <motor name="0/1/2/3/motor" class="0/1/2/3/" ctrllimited="true" ctrlrange="-1 1" gear="81" joint="0/1/2/3/joint/"/>
    <motor name="0/1/2/3/4/motor" class="0/1/2/3/4/" ctrllimited="true" ctrlrange="-1 1" gear="88" joint="0/1/2/3/4/joint/"/>
    <motor name="0/1/2/3/4/5/motor" class="0/1/2/3/4/5/" ctrllimited="true" ctrlrange="-1 1" gear="85" joint="0/1/2/3/4/5/joint/"/>
    <motor name="0/1/2/3/4/5/6/motor" class="0/1/2/3/4/5/6/" ctrllimited="true" ctrlrange="-1 1" gear="79" joint="0/1/2/3/4/5/6/joint/"/>
    <motor name="0/1/2/3/4/7/motor" class="0/1/2/3/4/7/" ctrllimited="true" ctrlrange="-1 1" gear="51" joint="0/1/2/3/4/7/joint/"/>
    <motor name="0/1/2/3/4/7/8/9/motor" class="0/1/2/3/4/7/8/9/" ctrllimited="true" ctrlrange="-1 1" gear="58" joint="0/1/2/3/4/7/8/9/joint/"/>
    <motor name="0/1/2/3/4/7/8/9/10/motor" class="0/1/2/3/4/7/8/9/10/" ctrllimited="true" ctrlrange="-1 1" gear="68" joint="0/1/2/3/4/7/8/9/10/joint/"/>
  </actuator>
  <sensor>
    <subtreelinvel name="velocity" body="0/"/>
  </sensor>
</mujoco>
