<mujoco model="morphology">
  <option timestep="0.01"/>
  <default>
    <default class="/"/>
    <default class="0/"/>
    <default class="0/1/"/>
    <default class="0/1/2/"/>
    <default class="0/1/2/3/"/>
    <default class="0/1/2/4/"/>
    <default class="0/1/2/4/5/"/>
    <default class="0/6/"/>
    <default class="0/6/7/"/>
    <default class="0/6/7/8/"/>
    <default class="0/6/7/8/9/"/>
    <default class="0/6/7/8/9/10/"/>
  </default>
  <asset>
    <texture name="texplane" type="2d" builtin="checker" rgb1="0.10000000000000001 0.20000000000000001 0.29999999999999999" rgb2="0.20000000000000001 0.29999999999999999 0.40000000000000002" width="300" height="300"/>
    <material name="MatPlane" class="/" texture="texplane" texrepeat="20 20" specular="1" shininess="1" reflectance="0.5"/>
  </asset>
  <worldbody>
    <light name="//unnamed_light_0" class="/" directional="true" pos="0 0 1.5" dir="0 0 -1.3" cutoff="100" exponent="1" diffuse="1 1 1" specular="0.10000000000000001 0.10000000000000001 0.10000000000000001"/>
    <geom name="ground" class="/" type="plane" size="15 15 0.5" material="MatPlane" rgba="1 1 1 1"/>
    <site name="body" class="/" size="9.9999999999999995e-07 9.9999999999999995e-07 9.9999999999999995e-07" pos="0 0 1.484684443473816"/>
    <body pos="0 0 1.484684443473816" name="0/">
      <joint name="0/rootx/" class="/" type="slide" axis="1 0 0" limited="false" stiffness="0" armature="0" damping="0"/>
      <joint name="0/rootz/" class="/" type="slide" axis="0 0 1" limited="false" stiffness="0" armature="0" damping="0"/>
      <joint name="0/rooty/" class="/" type="hinge" axis="0 1 0" limited="false" stiffness="0" armature="0" damping="0"/>
      <geom name="0/geom" class="0/" type="capsule" contype="1" conaffinity="1" condim="3" size="0.045349930694248794" rgba="0.38213763905916753 0.46055035568149205 0.17057271067407387 1" friction="0.59999999999999998 0.10000000000000001 0.10000000000000001" fromto="0 0 0 0.38234995399289695 0 0.41638047031153236"/>
      <site name="0/end0" class="0/" size="0.0050000000000000001" pos="0.38234995399289695 0 0.41638047031153236"/>
      <site name="0/attach1" class="0/" size="9.9999999999999995e-07 9.9999999999999995e-07 9.9999999999999995e-07" pos="0.030049718876742102 0 0.032724251560547202"/>
      <body pos="0.030049718876742102 0 0.032724251560547202" name="0/1/">
        <joint name="0/1/joint/" class="0/" type="hinge" axis="0 1 0" limited="true" range="-44.100263582763468 44.100263582763468"/>
        <geom name="0/1/geom" class="0/1/" type="capsule" contype="1" conaffinity="1" condim="3" size="0.057169407197473779" rgba="0.69712089086652462 0.470167696068027 0.51050984423267787 1" friction="0.59999999999999998 0.10000000000000001 0.10000000000000001" fromto="0 0 0 0.68158334181528701 0 -0.013811460830917666"/>
        <site name="0/1/end1" class="0/1/" size="0.0050000000000000001" pos="0.68158334181528701 0 -0.013811460830917666"/>
        <site name="0/1/attach2" class="0/1/" size="9.9999999999999995e-07 9.9999999999999995e-07 9.9999999999999995e-07" pos="0.21116196127524695 0 -0.0042789413681462917"/>
        <body pos="0.21116196127524695 0 -0.0042789413681462917" name="0/1/2/">
          <joint name="0/1/2/joint/" class="0/1/" type="hinge" axis="0 1 0" limited="true" range="-52.352976973029229 52.352976973029229"/>
          <geom name="0/1/2/geom" class="0/1/2/" type="capsule" contype="1" conaffinity="1" condim="3" size="0.068709625925673215" rgba="0.73776534850314957 0.89022501283597599 0.2981026038657999 1" friction="0.59999999999999998 0.10000000000000001 0.10000000000000001" fromto="0 0 0 0.45773985690016294 0 -0.56012962314215387"/>
          <site name="0/1/2/end2" class="0/1/2/" size="0.0050000000000000001" pos="0.45773985690016294 0 -0.56012962314215387"/>
          <site name="0/1/2/attach3" class="0/1/2/" size="9.9999999999999995e-07 9.9999999999999995e-07 9.9999999999999995e-07" pos="0.45106206727823944 0 -0.55195810884649921"/>
          <body pos="0.45106206727823944 0 -0.55195810884649921" name="0/1/2/3/">
            <joint name="0/1/2/3/joint/" class="0/1/2/" type="hinge" axis="0 1 0" limited="true" range="-68.395919875101896 68.395919875101896"/>
            <geom name="0/1/2/3/geom" class="0/1/2/3/" type="capsule" contype="1" conaffinity="1" condim="3" size="0.069870365538480528" rgba="0.28699454762512056 0.29945835946269805 0.7823068377216964 1" friction="0.59999999999999998 0.10000000000000001 0.10000000000000001" fromto="0 0 0 0.0067142189812920972 0 -0.56158528455453527"/>
            <site name="0/1/2/3/end3" class="0/1/2/3/" size="0.0050000000000000001" pos="0.0067142189812920972 0 -0.56158528455453527"/>
          </body>
          <site name="0/1/2/attach4" class="0/1/2/" size="9.9999999999999995e-07 9.9999999999999995e-07 9.9999999999999995e-07" pos="0.39304474930535727 0 -0.48096315841342618"/>
          <body pos="0.39304474930535727 0 -0.48096315841342618" name="0/1/2/4/">
            <joint name="0/1/2/4/joint/" class="0/1/2/" type="hinge" axis="0 1 0" limited="true" range="-37.955251738079085 37.955251738079085"/>
            <geom name="0/1/2/4/geom" class="0/1/2/4/" type="capsule" contype="1" conaffinity="1" condim="3" size="0.046834654118743928" rgba="0.31470745580214554 0.11636398224264166 0.85792347333272867 1" friction="0.59999999999999998 0.10000000000000001 0.10000000000000001" fromto="0 0 0 -0.29059721163060509 0 -0.34327525497440509"/>
            <site name="0/1/2/4/end4" class="0/1/2/4/" size="0.0050000000000000001" pos="-0.29059721163060509 0 -0.34327525497440509"/>
            <site name="0/1/2/4/attach5" class="0/1/2/4/" size="9.9999999999999995e-07 9.9999999999999995e-07 9.9999999999999995e-07" pos="-0.23987976191082 0 -0.28336399365665471"/>
            <body pos="-0.23987976191082 0 -0.28336399365665471" name="0/1/2/4/5/">
              <joint name="0/1/2/4/5/joint/" class="0/1/2/4/" type="hinge" axis="0 1 0" limited="true" range="-37.978293487855446 37.978293487855446"/>
              <geom name="0/1/2/4/5/geom" class="0/1/2/4/5/" type="capsule" contype="1" conaffinity="1" condim="3" size="0.068316532519975201" rgba="0.95077404104493846 0.64814599056442568 0.13958814320218416 1" friction="0.59999999999999998 0.10000000000000001 0.10000000000000001" fromto="0 0 0 0.28455453612557124 0 -0.64880257826141507"/>
              <site name="0/1/2/4/5/end5" class="0/1/2/4/5/" size="0.0050000000000000001" pos="0.28455453612557124 0 -0.64880257826141507"/>
            </body>
          </body>
        </body>
      </body>
      <site name="0/attach6" class="0/" size="9.9999999999999995e-07 9.9999999999999995e-07 9.9999999999999995e-07" pos="0.29975677204065593 0 0.32643619913623373"/>
      <body pos="0.29975677204065593 0 0.32643619913623373" name="0/6/">
        <geom name="0/6/geom" class="0/6/" type="capsule" contype="1" conaffinity="1" condim="3" size="0.050156387228220058" rgba="0.14370774727712421 0.62358070615829486 0.46215346617376674 1" friction="0.59999999999999998 0.10000000000000001 0.10000000000000001" fromto="0 0 0 -0.27599329187809529 0 0.08117583636090453"/>
        <site name="0/6/end6" class="0/6/" size="0.0050000000000000001" pos="-0.27599329187809529 0 0.08117583636090453"/>
        <site name="0/6/attach7" class="0/6/" size="9.9999999999999995e-07 9.9999999999999995e-07 9.9999999999999995e-07" pos="-0.23108503503596806 0 0.067967307690286791"/>
        <body pos="-0.23108503503596806 0 0.067967307690286791" name="0/6/7/">
          <joint name="0/6/7/joint/" class="0/6/" type="hinge" axis="0 1 0" limited="true" range="-53.801177038626641 53.801177038626641"/>
          <geom name="0/6/7/geom" class="0/6/7/" type="capsule" contype="1" conaffinity="1" condim="3" size="0.066000420468869531" rgba="0.30927299597001789 0.68464531956515151 0.91884715159530639 1" friction="0.59999999999999998 0.10000000000000001 0.10000000000000001" fromto="0 0 0 -0.45615737215504049 0 -0.44035390867186397"/>
          <site name="0/6/7/end7" class="0/6/7/" size="0.0050000000000000001" pos="-0.45615737215504049 0 -0.44035390867186397"/>
          <site name="0/6/7/attach8" class="0/6/7/" size="9.9999999999999995e-07 9.9999999999999995e-07 9.9999999999999995e-07" pos="-0.16267336680562314 0 -0.15703758676801746"/>
          <body pos="-0.16267336680562314 0 -0.15703758676801746" name="0/6/7/8/">
            <geom name="0/6/7/8/geom" class="0/6/7/8/" type="capsule" contype="1" conaffinity="1" condim="3" size="0.051687650711841324" rgba="0.50915549268666249 0.3245171675760925 0.72340054922477637 1" friction="0.59999999999999998 0.10000000000000001 0.10000000000000001" fromto="0 0 0 -0.080279137813001888 0 0.66344828474422601"/>
            <site name="0/6/7/8/end8" class="0/6/7/8/" size="0.0050000000000000001" pos="-0.080279137813001888 0 0.66344828474422601"/>
            <site name="0/6/7/8/attach9" class="0/6/7/8/" size="9.9999999999999995e-07 9.9999999999999995e-07 9.9999999999999995e-07" pos="-0.072509191714093951 0 0.5992353702522536"/>
            <body pos="-0.072509191714093951 0 0.5992353702522536" name="0/6/7/8/9/">
              <joint name="0/6/7/8/9/joint/" class="0/6/7/8/" type="hinge" axis="0 1 0" limited="true" range="-59.20921802161719 59.20921802161719"/>
              <geom name="0/6/7/8/9/geom" class="0/6/7/8/9/" type="capsule" contype="1" conaffinity="1" condim="3" size="0.051465657903719646" rgba="0.46942266515084097 0.40585471127245509 0.97316113175352836 1" friction="0.59999999999999998 0.10000000000000001 0.10000000000000001" fromto="0 0 0 0.66038470145148809 0 -0.099296954173311192"/>
              <site name="0/6/7/8/9/end9" class="0/6/7/8/9/" size="0.0050000000000000001" pos="0.66038470145148809 0 -0.099296954173311192"/>
              <site name="0/6/7/8/9/attach10" class="0/6/7/8/9/" size="9.9999999999999995e-07 9.9999999999999995e-07 9.9999999999999995e-07" pos="0.17053059208778021 0 -0.025641369871939483"/>
              <body pos="0.17053059208778021 0 -0.025641369871939483" name="0/6/7/8/9/10/">
                <joint name="0/6/7/8/9/10/joint/" class="0/6/7/8/9/" type="hinge" axis="0 1 0" limited="true" range="-30.221453250241449 30.221453250241449"/>
                <geom name="0/6/7/8/9/10/geom" class="0/6/7/8/9/10/" type="capsule" contype="1" conaffinity="1" condim="3" size="0.040264532316130509" rgba="0.78062418994861504 0.89143588553388187 0.14672315771627942 1" friction="0.59999999999999998 0.10000000000000001 0.10000000000000001" fromto="0 0 0 0.39632115272980761 0 0.66396366640868121"/>
                <site name="0/6/7/8/9/10/end10" class="0/6/7/8/9/10/" size="0.0050000000000000001" pos="0.39632115272980761 0 0.66396366640868121"/>
              </body>
            </body>
          </body>
        </body>
      </body>
      <camera name="0/side" class="0/" mode="trackcom" pos="0.40000000000000002 -4 0.20000000000000001" quat="0.70699999999999996 0.70699999999999996 0 0"/>
    </body>
  </worldbody>
  <actuator>
    <motor name="0/1/motor" class="0/1/" ctrllimited="true" ctrlrange="-1 1" gear="51" joint="0/1/joint/"/>
    <motor name="0/1/2/motor" class="0/1/2/" ctrllimited="true" ctrlrange="-1 1" gear="86" joint="0/1/2/joint/"/>
    <motor name="0/1/2/3/motor" class="0/1/2/3/" ctrllimited="true" ctrlrange="-1 1" gear="53" joint="0/1/2/3/joint/"/>
    <motor name="0/1/2/4/motor" class="0/1/2/4/" ctrllimited="true" ctrlrange="-1 1" gear="58" joint="0/1/2/4/joint/"/>
    <motor name="0/1/2/4/5/motor" class="0/1/2/4/5/" ctrllimited="true" ctrlrange="-1 1" gear="73" joint="0/1/2/4/5/joint/"/>
    <motor name="0/6/7/motor" class="0/6/7/" ctrllimited="true" ctrlrange="-1 1" gear="70" joint="0/6/7/joint/"/>
    <motor name="0/6/7/8/9/motor" class="0/6/7/8/9/" ctrllimited="true" ctrlrange="-1 1" gear="85" joint="0/6/7/8/9/joint/"/>
    <motor name="0/6/7/8/9/10/motor" class="0/6/7/8/9/10/" ctrllimited="true" ctrlrange="-1 1" gear="64" joint="0/6/7/8/9/10/joint/"/>
  </actuator>
  <sensor>
    <subtreelinvel name="velocity" body="0/"/>
  </sensor>
</mujoco>
