<mujoco model="morphology">
  <option timestep="0.01"/>
  <default>
    <default class="/"/>
    <default class="0/"/>
    <default class="0/1/"/>
    <default class="0/1/2/"/>
    <default class="0/1/3/"/>
    <default class="0/1/3/4/"/>
    <default class="0/1/3/5/"/>
    <default class="0/6/"/>
    <default class="0/6/7/"/>
    <default class="0/6/7/8/"/>
    <default class="0/6/7/8/9/"/>
    <default class="0/6/7/8/9/10/"/>
  </default>
  <asset>
    <texture name="texplane" type="2d" builtin="checker" rgb1="0.10000000000000001 0.20000000000000001 0.29999999999999999" rgb2="0.20000000000000001 0.29999999999999999 0.40000000000000002" width="300" height="300"/>
    <material name="MatPlane" class="/" texture="texplane" texrepeat="20 20" specular="1" shininess="1" reflectance="0.5"/>
  </asset>
  <worldbody>
    <light name="//unnamed_light_0" class="/" directional="true" pos="0 0 1.5" dir="0 0 -1.3" cutoff="100" exponent="1" diffuse="1 1 1" specular="0.10000000000000001 0.10000000000000001 0.10000000000000001"/>
    <geom name="ground" class="/" type="plane" size="15 15 0.5" material="MatPlane" rgba="1 1 1 1"/>
    <site name="body" class="/" size="9.9999999999999995e-07 9.9999999999999995e-07 9.9999999999999995e-07" pos="0 0 0.60827062129974363"/>
    <body pos="0 0 0.60827062129974363" name="0/">
      <joint name="0/rootx/" class="/" type="slide" axis="1 0 0" limited="false" stiffness="0" armature="0" damping="0"/>
      <joint name="0/rootz/" class="/" type="slide" axis="0 0 1" limited="false" stiffness="0" armature="0" damping="0"/>
      <joint name="0/rooty/" class="/" type="hinge" axis="0 1 0" limited="false" stiffness="0" armature="0" damping="0"/>
      <geom name="0/geom" class="0/" type="capsule" contype="1" conaffinity="1" condim="3" size="0.058388962293486057" rgba="0.34844816830550429 0.53182494462294994 0.80556334687986331 1" friction="0.59999999999999998 0.10000000000000001 0.10000000000000001" fromto="0 0 0 -0.64711709590166799 0 -0.39128870918807895"/>
      <site name="0/end0" class="0/" size="0.0050000000000000001" pos="-0.64711709590166799 0 -0.39128870918807895"/>
      <site name="0/attach1" class="0/" size="9.9999999999999995e-07 9.9999999999999995e-07 9.9999999999999995e-07" pos="-0.19236206871985798 0 -0.11631450635879848"/>
      <body pos="-0.19236206871985798 0 -0.11631450635879848" name="0/1/">
        <geom name="0/1/geom" class="0/1/" type="capsule" contype="1" conaffinity="1" condim="3" size="0.045903780264267856" rgba="0.63078168673648483 0.93165969312783492 0.020571919506067959 1" friction="0.59999999999999998 0.10000000000000001 0.10000000000000001" fromto="0 0 0 -0.67392961412215657 0 0.42621611311074714"/>
        <site name="0/1/end1" class="0/1/" size="0.0050000000000000001" pos="-0.67392961412215657 0 0.42621611311074714"/>
        <site name="0/1/attach2" class="0/1/" size="9.9999999999999995e-07 9.9999999999999995e-07 9.9999999999999995e-07" pos="-0.3291179892059074 0 0.20814546085333527"/>
        <body pos="-0.3291179892059074 0 0.20814546085333527" name="0/1/2/">
          <joint name="0/1/2/joint/" class="0/1/" type="hinge" axis="0 1 0" limited="true" range="-42.862007869198777 42.862007869198777"/>
          <geom name="0/1/2/geom" class="0/1/2/" type="capsule" contype="1" conaffinity="1" condim="3" size="0.069897601051103112" rgba="0.31208902356211166 0.29601700255698415 0.13890084506977629 1" friction="0.59999999999999998 0.10000000000000001 0.10000000000000001" fromto="0 0 0 -0.31553184651192312 0 -0.60010155205578342"/>
          <site name="0/1/2/end2" class="0/1/2/" size="0.0050000000000000001" pos="-0.31553184651192312 0 -0.60010155205578342"/>
        </body>
        <site name="0/1/attach3" class="0/1/" size="9.9999999999999995e-07 9.9999999999999995e-07 9.9999999999999995e-07" pos="-0.41804721292299246 0 0.26438734024310451"/>
        <body pos="-0.41804721292299246 0 0.26438734024310451" name="0/1/3/">
          <joint name="0/1/3/joint/" class="0/1/" type="hinge" axis="0 1 0" limited="true" range="-58.013253683163015 58.013253683163015"/>
          <geom name="0/1/3/geom" class="0/1/3/" type="capsule" contype="1" conaffinity="1" condim="3" size="0.068707284318070494" rgba="0.43512596250008306 0.01185354215940182 0.48506013300031614 1" friction="0.59999999999999998 0.10000000000000001 0.10000000000000001" fromto="0 0 0 -0.74816116435416802 0 -0.31607611952107351"/>
          <site name="0/1/3/end3" class="0/1/3/" size="0.0050000000000000001" pos="-0.74816116435416802 0 -0.31607611952107351"/>
          <site name="0/1/3/attach4" class="0/1/3/" size="9.9999999999999995e-07 9.9999999999999995e-07 9.9999999999999995e-07" pos="-0.56561550927544257 0 -0.23895594135395015"/>
          <body pos="-0.56561550927544257 0 -0.23895594135395015" name="0/1/3/4/">
            <joint name="0/1/3/4/joint/" class="0/1/3/" type="hinge" axis="0 1 0" limited="true" range="-63.208135696611208 63.208135696611208"/>
            <geom name="0/1/3/4/geom" class="0/1/3/4/" type="capsule" contype="1" conaffinity="1" condim="3" size="0.061538777664412563" rgba="0.95452426885755315 0.36229622689294272 0.6865254339662934 1" friction="0.59999999999999998 0.10000000000000001 0.10000000000000001" fromto="0 0 0 -0.37056742223333583 0 0.21965385630137213"/>
            <site name="0/1/3/4/end4" class="0/1/3/4/" size="0.0050000000000000001" pos="-0.37056742223333583 0 0.21965385630137213"/>
          </body>
          <site name="0/1/3/attach5" class="0/1/3/" size="9.9999999999999995e-07 9.9999999999999995e-07 9.9999999999999995e-07" pos="-0.60783231305922802 0 -0.25679130110572251"/>
          <body pos="-0.60783231305922802 0 -0.25679130110572251" name="0/1/3/5/">
            <geom name="0/1/3/5/geom" class="0/1/3/5/" type="capsule" contype="1" conaffinity="1" condim="3" size="0.047865427119612017" rgba="0.36677628134805595 0.96401411507001045 0.47701713733514128 1" friction="0.59999999999999998 0.10000000000000001 0.10000000000000001" fromto="0 0 0 0.020510320183211306 0 -0.059474299742288572"/>
            <site name="0/1/3/5/end5" class="0/1/3/5/" size="0.0050000000000000001" pos="0.020510320183211306 0 -0.059474299742288572"/>
          </body>
        </body>
      </body>
      <site name="0/attach6" class="0/" size="9.9999999999999995e-07 9.9999999999999995e-07 9.9999999999999995e-07" pos="-0.16807550447853031 0 -0.10162928411264338"/>
      <body pos="-0.16807550447853031 0 -0.10162928411264338" name="0/6/">
        <joint name="0/6/joint/" class="0/" type="hinge" axis="0 1 0" limited="true" range="-55.883319699112668 55.883319699112668"/>
        <geom name="0/6/geom" class="0/6/" type="capsule" contype="1" conaffinity="1" condim="3" size="0.040410210884809408" rgba="0.96057814675582021 0.37721441764898611 0.29222884070074129 1" friction="0.59999999999999998 0.10000000000000001 0.10000000000000001" fromto="0 0 0 0.0095869538654675956 0 0.10377254255732438"/>
        <site name="0/6/end6" class="0/6/" size="0.0050000000000000001" pos="0.0095869538654675956 0 0.10377254255732438"/>
        <site name="0/6/attach7" class="0/6/" size="9.9999999999999995e-07 9.9999999999999995e-07 9.9999999999999995e-07" pos="0.0046525487666467438 0 0.050360815506368117"/>
        <body pos="0.0046525487666467438 0 0.050360815506368117" name="0/6/7/">
          <joint name="0/6/7/joint/" class="0/6/" type="hinge" axis="0 1 0" limited="true" range="-31.588259220558861 31.588259220558861"/>
          <geom name="0/6/7/geom" class="0/6/7/" type="capsule" contype="1" conaffinity="1" condim="3" size="0.059310144419638763" rgba="0.27974008232897352 0.38809138450272607 0.70683359985106964 1" friction="0.59999999999999998 0.10000000000000001 0.10000000000000001" fromto="0 0 0 -0.4132174906991673 0 0.40858318839553864"/>
          <site name="0/6/7/end7" class="0/6/7/" size="0.0050000000000000001" pos="-0.4132174906991673 0 0.40858318839553864"/>
          <site name="0/6/7/attach8" class="0/6/7/" size="9.9999999999999995e-07 9.9999999999999995e-07 9.9999999999999995e-07" pos="-0.11160071104725268 0 0.11034909066831425"/>
          <body pos="-0.11160071104725268 0 0.11034909066831425" name="0/6/7/8/">
            <geom name="0/6/7/8/geom" class="0/6/7/8/" type="capsule" contype="1" conaffinity="1" condim="3" size="0.064247720002927083" rgba="0.91232187837836964 0.98656266053553721 0.46853410878094348 1" friction="0.59999999999999998 0.10000000000000001 0.10000000000000001" fromto="0 0 0 0.2279441413517278 0 0.63557050855496056"/>
            <site name="0/6/7/8/end8" class="0/6/7/8/" size="0.0050000000000000001" pos="0.2279441413517278 0 0.63557050855496056"/>
            <site name="0/6/7/8/attach9" class="0/6/7/8/" size="9.9999999999999995e-07 9.9999999999999995e-07 9.9999999999999995e-07" pos="0.21943978551011101 0 0.61185804226766782"/>
            <body pos="0.21943978551011101 0 0.61185804226766782" name="0/6/7/8/9/">
              <geom name="0/6/7/8/9/geom" class="0/6/7/8/9/" type="capsule" contype="1" conaffinity="1" condim="3" size="0.052189594459885087" rgba="0.24286743463145044 0.46457209205706973 0.71764707625455681 1" friction="0.59999999999999998 0.10000000000000001 0.10000000000000001" fromto="0 0 0 0.23386537804962382 0 -0.39818756041343861"/>
              <site name="0/6/7/8/9/end9" class="0/6/7/8/9/" size="0.0050000000000000001" pos="0.23386537804962382 0 -0.39818756041343861"/>
              <site name="0/6/7/8/9/attach10" class="0/6/7/8/9/" size="9.9999999999999995e-07 9.9999999999999995e-07 9.9999999999999995e-07" pos="0.12346964281303593 0 -0.21022383161995584"/>
              <body pos="0.12346964281303593 0 -0.21022383161995584" name="0/6/7/8/9/10/">
                <joint name="0/6/7/8/9/10/joint/" class="0/6/7/8/9/" type="hinge" axis="0 1 0" limited="true" range="-39.115906268455888 39.115906268455888"/>
                <geom name="0/6/7/8/9/10/geom" class="0/6/7/8/9/10/" type="capsule" contype="1" conaffinity="1" condim="3" size="0.060635010218465159" rgba="0.6097482257596164 0.51288383737860777 0.81707542728971516 1" friction="0.59999999999999998 0.10000000000000001 0.10000000000000001" fromto="0 0 0 0.53975394552364198 0 0.20940064483779974"/>
                <site name="0/6/7/8/9/10/end10" class="0/6/7/8/9/10/" size="0.0050000000000000001" pos="0.53975394552364198 0 0.20940064483779974"/>
              </body>
            </body>
          </body>
        </body>
      </body>
      <camera name="0/side" class="0/" mode="trackcom" pos="0.40000000000000002 -4 0.20000000000000001" quat="0.70699999999999996 0.70699999999999996 0 0"/>
    </body>
  </worldbody>
  <actuator>
    <motor name="0/1/2/motor" class="0/1/2/" ctrllimited="true" ctrlrange="-1 1" gear="53" joint="0/1/2/joint/"/>
    <motor name="0/1/3/motor" class="0/1/3/" ctrllimited="true" ctrlrange="-1 1" gear="55" joint="0/1/3/joint/"/>
    <motor name="0/1/3/4/motor" class="0/1/3/4/" ctrllimited="true" ctrlrange="-1 1" gear="74" joint="0/1/3/4/joint/"/>
    <motor name="0/6/motor" class="0/6/" ctrllimited="true" ctrlrange="-1 1" gear="87" joint="0/6/joint/"/>
    <motor name="0/6/7/motor" class="0/6/7/" ctrllimited="true" ctrlrange="-1 1" gear="83" joint="0/6/7/joint/"/>
    <motor name="0/6/7/8/9/10/motor" class="0/6/7/8/9/10/" ctrllimited="true" ctrlrange="-1 1" gear="57" joint="0/6/7/8/9/10/joint/"/>
  </actuator>
  <sensor>
    <subtreelinvel name="velocity" body="0/"/>
  </sensor>
</mujoco>
