<mujoco model="morphology">
  <option timestep="0.01"/>
  <default>
    <default class="/"/>
    <default class="0/"/>
    <default class="0/1/"/>
    <default class="0/1/2/"/>
    <default class="0/1/2/3/"/>
    <default class="0/1/2/3/4/"/>
    <default class="0/1/2/3/4/5/"/>
    <default class="0/1/2/3/4/5/6/"/>
    <default class="0/1/2/3/4/5/7/"/>
    <default class="0/1/2/3/4/5/7/8/"/>
    <default class="0/1/2/3/4/5/7/9/"/>
    <default class="0/1/2/3/4/5/7/9/10/"/>
  </default>
  <asset>
    <texture name="texplane" type="2d" builtin="checker" rgb1="0.10000000000000001 0.20000000000000001 0.29999999999999999" rgb2="0.20000000000000001 0.29999999999999999 0.40000000000000002" width="300" height="300"/>
    <material name="MatPlane" class="/" texture="texplane" texrepeat="20 20" specular="1" shininess="1" reflectance="0.5"/>
  </asset>
  <worldbody>
    <light name="//unnamed_light_0" class="/" directional="true" pos="0 0 1.5" dir="0 0 -1.3" cutoff="100" exponent="1" diffuse="1 1 1" specular="0.10000000000000001 0.10000000000000001 0.10000000000000001"/>
    <geom name="ground" class="/" type="plane" size="15 15 0.5" material="MatPlane" rgba="1 1 1 1"/>
    <site name="body" class="/" size="9.9999999999999995e-07 9.9999999999999995e-07 9.9999999999999995e-07" pos="0 0 0.67340836524963377"/>
    <body pos="0 0 0.67340836524963377" name="0/">
      <joint name="0/rootx/" class="/" type="slide" axis="1 0 0" limited="false" stiffness="0" armature="0" damping="0"/>
      <joint name="0/rootz/" class="/" type="slide" axis="0 0 1" limited="false" stiffness="0" armature="0" damping="0"/>
      <joint name="0/rooty/" class="/" type="hinge" axis="0 1 0" limited="false" stiffness="0" armature="0" damping="0"/>
      <geom name="0/geom" class="0/" type="capsule" contype="1" conaffinity="1" condim="3" size="0.050328541545664664" rgba="0.68071507705376688 0.40639063890228799 0.11659290669728695 1" friction="0.59999999999999998 0.10000000000000001 0.10000000000000001" fromto="0 0 0 0.13600209091416149 0 -0.26338564354756244"/>
      <site name="0/end0" class="0/" size="0.0050000000000000001" pos="0.13600209091416149 0 -0.26338564354756244"/>
      <site name="0/attach1" class="0/" size="9.9999999999999995e-07 9.9999999999999995e-07 9.9999999999999995e-07" pos="0.082271685178043022 0 -0.15932976177577993"/>
      <body pos="0.082271685178043022 0 -0.15932976177577993" name="0/1/">
        <geom name="0/1/geom" class="0/1/" type="capsule" contype="1" conaffinity="1" condim="3" size="0.047053934422800078" rgba="0.51981008981476606 0.36594762281117166 0.0020148984997665487 1" friction="0.59999999999999998 0.10000000000000001 0.10000000000000001" fromto="0 0 0 0.57364173188491518 0 0.44675501019873298"/>
        <site name="0/1/end1" class="0/1/" size="0.0050000000000000001" pos="0.57364173188491518 0 0.44675501019873298"/>
        <site name="0/1/attach2" class="0/1/" size="9.9999999999999995e-07 9.9999999999999995e-07 9.9999999999999995e-07" pos="0.1557186621877383 0 0.12127446217210176"/>
        <body pos="0.1557186621877383 0 0.12127446217210176" name="0/1/2/">
          <joint name="0/1/2/joint/" class="0/1/" type="hinge" axis="0 1 0" limited="true" range="-60.533071738254236 60.533071738254236"/>
          <geom name="0/1/2/geom" class="0/1/2/" type="capsule" contype="1" conaffinity="1" condim="3" size="0.058140613239324929" rgba="0.85803268571937974 0.53334148726257069 0.061582822804849613 1" friction="0.59999999999999998 0.10000000000000001 0.10000000000000001" fromto="0 0 0 -0.099767137385749494 0 0.15292466143011563"/>
          <site name="0/1/2/end2" class="0/1/2/" size="0.0050000000000000001" pos="-0.099767137385749494 0 0.15292466143011563"/>
          <site name="0/1/2/attach3" class="0/1/2/" size="9.9999999999999995e-07 9.9999999999999995e-07 9.9999999999999995e-07" pos="-0.0087463533414408427 0 0.013406550077872149"/>
          <body pos="-0.0087463533414408427 0 0.013406550077872149" name="0/1/2/3/">
            <joint name="0/1/2/3/joint/" class="0/1/2/" type="hinge" axis="0 1 0" limited="true" range="-62.354210265455343 62.354210265455343"/>
            <geom name="0/1/2/3/geom" class="0/1/2/3/" type="capsule" contype="1" conaffinity="1" condim="3" size="0.056444789257470929" rgba="0.68250920541811366 0.79095386917239152 0.49319202315235622 1" friction="0.59999999999999998 0.10000000000000001 0.10000000000000001" fromto="0 0 0 0.38154773097267314 0 -0.47893444131955121"/>
            <site name="0/1/2/3/end3" class="0/1/2/3/" size="0.0050000000000000001" pos="0.38154773097267314 0 -0.47893444131955121"/>
            <site name="0/1/2/3/attach4" class="0/1/2/3/" size="9.9999999999999995e-07 9.9999999999999995e-07 9.9999999999999995e-07" pos="0.35559690492645391 0 -0.44635989463690551"/>
            <body pos="0.35559690492645391 0 -0.44635989463690551" name="0/1/2/3/4/">
              <joint name="0/1/2/3/4/joint/" class="0/1/2/3/" type="hinge" axis="0 1 0" limited="true" range="-45.920924584836534 45.920924584836534"/>
              <geom name="0/1/2/3/4/geom" class="0/1/2/3/4/" type="capsule" contype="1" conaffinity="1" condim="3" size="0.048070272915202168" rgba="0.97773418761251685 0.065947238786376206 0.83936248477908904 1" friction="0.59999999999999998 0.10000000000000001 0.10000000000000001" fromto="0 0 0 0.55206393460358538 0 0.34008396571094468"/>
              <site name="0/1/2/3/4/end4" class="0/1/2/3/4/" size="0.0050000000000000001" pos="0.55206393460358538 0 0.34008396571094468"/>
              <site name="0/1/2/3/4/attach5" class="0/1/2/3/4/" size="9.9999999999999995e-07 9.9999999999999995e-07 9.9999999999999995e-07" pos="0.26995545269027932 0 0.16629871136597021"/>
              <body pos="0.26995545269027932 0 0.16629871136597021" name="0/1/2/3/4/5/">
                <joint name="0/1/2/3/4/5/joint/" class="0/1/2/3/4/" type="hinge" axis="0 1 0" limited="true" range="-55.024598535859894 55.024598535859894"/>
                <geom name="0/1/2/3/4/5/geom" class="0/1/2/3/4/5/" type="capsule" contype="1" conaffinity="1" condim="3" size="0.067155140226702034" rgba="0.89395912404685818 0.2186484923520764 0.38777442961525344 1" friction="0.59999999999999998 0.10000000000000001 0.10000000000000001" fromto="0 0 0 -0.065530751752999938 0 0.36712679338039855"/>
                <site name="0/1/2/3/4/5/end5" class="0/1/2/3/4/5/" size="0.0050000000000000001" pos="-0.065530751752999938 0 0.36712679338039855"/>
                <site name="0/1/2/3/4/5/attach6" class="0/1/2/3/4/5/" size="9.9999999999999995e-07 9.9999999999999995e-07 9.9999999999999995e-07" pos="-0.047055329990105976 0 0.26362084896932775"/>
                <body pos="-0.047055329990105976 0 0.26362084896932775" name="0/1/2/3/4/5/6/">
                  <joint name="0/1/2/3/4/5/6/joint/" class="0/1/2/3/4/5/" type="hinge" axis="0 1 0" limited="true" range="-40.969064754472285 40.969064754472285"/>
                  <geom name="0/1/2/3/4/5/6/geom" class="0/1/2/3/4/5/6/" type="capsule" contype="1" conaffinity="1" condim="3" size="0.061361110773859445" rgba="0.9264583074409789 0.65350787266359212 0.29012912116432843 1" friction="0.59999999999999998 0.10000000000000001 0.10000000000000001" fromto="0 0 0 0.39645151506440635 0 0.40357131864323215"/>
                  <site name="0/1/2/3/4/5/6/end6" class="0/1/2/3/4/5/6/" size="0.0050000000000000001" pos="0.39645151506440635 0 0.40357131864323215"/>
                </body>
                <site name="0/1/2/3/4/5/attach7" class="0/1/2/3/4/5/" size="9.9999999999999995e-07 9.9999999999999995e-07 9.9999999999999995e-07" pos="-0.02042679242190365 0 0.11443822328128878"/>
                <body pos="-0.02042679242190365 0 0.11443822328128878" name="0/1/2/3/4/5/7/">
                  <geom name="0/1/2/3/4/5/7/geom" class="0/1/2/3/4/5/7/" type="capsule" contype="1" conaffinity="1" condim="3" size="0.041111915479862926" rgba="0.4388662016446454 0.12223373008885985 0.87893755154685449 1" friction="0.59999999999999998 0.10000000000000001 0.10000000000000001" fromto="0 0 0 0.50376657279393733 0 0.27525714932829182"/>
                  <site name="0/1/2/3/4/5/7/end7" class="0/1/2/3/4/5/7/" size="0.0050000000000000001" pos="0.50376657279393733 0 0.27525714932829182"/>
                  <site name="0/1/2/3/4/5/7/attach8" class="0/1/2/3/4/5/7/" size="9.9999999999999995e-07 9.9999999999999995e-07 9.9999999999999995e-07" pos="0.45804567099024868 0 0.2502753308138071"/>
                  <body pos="0.45804567099024868 0 0.2502753308138071" name="0/1/2/3/4/5/7/8/">
                    <joint name="0/1/2/3/4/5/7/8/joint/" class="0/1/2/3/4/5/7/" type="hinge" axis="0 1 0" limited="true" range="-64.330394304426108 64.330394304426108"/>
                    <geom name="0/1/2/3/4/5/7/8/geom" class="0/1/2/3/4/5/7/8/" type="capsule" contype="1" conaffinity="1" condim="3" size="0.06216188383796474" rgba="0.77587624327036842 0.75957424139527752 0.33146384643090909 1" friction="0.59999999999999998 0.10000000000000001 0.10000000000000001" fromto="0 0 0 0.17675206884421701 0 -0.63341197430816409"/>
                    <site name="0/1/2/3/4/5/7/8/end8" class="0/1/2/3/4/5/7/8/" size="0.0050000000000000001" pos="0.17675206884421701 0 -0.63341197430816409"/>
                  </body>
                  <site name="0/1/2/3/4/5/7/attach9" class="0/1/2/3/4/5/7/" size="9.9999999999999995e-07 9.9999999999999995e-07 9.9999999999999995e-07" pos="0.48566567350038814 0 0.26536685050955922"/>
                  <body pos="0.48566567350038814 0 0.26536685050955922" name="0/1/2/3/4/5/7/9/">
                    <joint name="0/1/2/3/4/5/7/9/joint/" class="0/1/2/3/4/5/7/" type="hinge" axis="0 1 0" limited="true" range="-35.065002053313499 35.065002053313499"/>
                    <geom name="0/1/2/3/4/5/7/9/geom" class="0/1/2/3/4/5/7/9/" type="capsule" contype="1" conaffinity="1" condim="3" size="0.068079716686979569" rgba="0.93881361397658503 0.48752901101154811 0.13033055593910958 1" friction="0.59999999999999998 0.10000000000000001 0.10000000000000001" fromto="0 0 0 0.090417821141390298 0 0.7338423391335549"/>
                    <site name="0/1/2/3/4/5/7/9/end9" class="0/1/2/3/4/5/7/9/" size="0.0050000000000000001" pos="0.090417821141390298 0 0.7338423391335549"/>
                    <site name="0/1/2/3/4/5/7/9/attach10" class="0/1/2/3/4/5/7/9/" size="9.9999999999999995e-07 9.9999999999999995e-07 9.9999999999999995e-07" pos="0.02661012396181819 0 0.21597109249335153"/>
                    <body pos="0.02661012396181819 0 0.21597109249335153" name="0/1/2/3/4/5/7/9/10/">
                      <geom name="0/1/2/3/4/5/7/9/10/geom" class="0/1/2/3/4/5/7/9/10/" type="capsule" contype="1" conaffinity="1" condim="3" size="0.068805563084360713" rgba="0.38105401949605799 0.98063317737473854 0.82211749129568268 1" friction="0.59999999999999998 0.10000000000000001 0.10000000000000001" fromto="0 0 0 0.1298053188529098 0 -0.062581638537922091"/>
                      <site name="0/1/2/3/4/5/7/9/10/end10" class="0/1/2/3/4/5/7/9/10/" size="0.0050000000000000001" pos="0.1298053188529098 0 -0.062581638537922091"/>
                    </body>
                  </body>
                </body>
              </body>
            </body>
          </body>
        </body>
      </body>
      <camera name="0/side" class="0/" mode="trackcom" pos="0.40000000000000002 -4 0.20000000000000001" quat="0.70699999999999996 0.70699999999999996 0 0"/>
    </body>
  </worldbody>
  <actuator>
    <motor name="0/1/2/motor" class="0/1/2/" ctrllimited="true" ctrlrange="-1 1" gear="71" joint="0/1/2/joint/"/>
    <motor name="0/1/2/3/motor" class="0/1/2/3/" ctrllimited="true" ctrlrange="-1 1" gear="81" joint="0/1/2/3/joint/"/>
    <motor name="0/1/2/3/4/motor" class="0/1/2/3/4/" ctrllimited="true" ctrlrange="-1 1" gear="52" joint="0/1/2/3/4/joint/"/>
    <motor name="0/1/2/3/4/5/motor" class="0/1/2/3/4/5/" ctrllimited="true" ctrlrange="-1 1" gear="82" joint="0/1/2/3/4/5/joint/"/>
    <motor name="0/1/2/3/4/5/6/motor" class="0/1/2/3/4/5/6/" ctrllimited="true" ctrlrange="-1 1" gear="86" joint="0/1/2/3/4/5/6/joint/"/>
    <motor name="0/1/2/3/4/5/7/8/motor" class="0/1/2/3/4/5/7/8/" ctrllimited="true" ctrlrange="-1 1" gear="64" joint="0/1/2/3/4/5/7/8/joint/"/>
    <motor name="0/1/2/3/4/5/7/9/motor" class="0/1/2/3/4/5/7/9/" ctrllimited="true" ctrlrange="-1 1" gear="70" joint="0/1/2/3/4/5/7/9/joint/"/>
  </actuator>
  <sensor>
    <subtreelinvel name="velocity" body="0/"/>
  </sensor>
</mujoco>
