<mujoco model="morphology">
  <option timestep="0.01"/>
  <default>
    <default class="/"/>
    <default class="0/"/>
    <default class="0/1/"/>
    <default class="0/2/"/>
    <default class="0/2/3/"/>
    <default class="0/2/4/"/>
    <default class="0/2/4/5/"/>
    <default class="0/2/4/6/"/>
    <default class="0/2/4/7/"/>
    <default class="0/2/4/7/8/"/>
    <default class="0/2/4/7/9/"/>
    <default class="0/2/4/7/10/"/>
  </default>
  <asset>
    <texture name="texplane" type="2d" builtin="checker" rgb1="0.10000000000000001 0.20000000000000001 0.29999999999999999" rgb2="0.20000000000000001 0.29999999999999999 0.40000000000000002" width="300" height="300"/>
    <material name="MatPlane" class="/" texture="texplane" texrepeat="20 20" specular="1" shininess="1" reflectance="0.5"/>
  </asset>
  <worldbody>
    <light name="//unnamed_light_0" class="/" directional="true" pos="0 0 1.5" dir="0 0 -1.3" cutoff="100" exponent="1" diffuse="1 1 1" specular="0.10000000000000001 0.10000000000000001 0.10000000000000001"/>
    <geom name="ground" class="/" type="plane" size="15 15 0.5" material="MatPlane" rgba="1 1 1 1"/>
    <site name="body" class="/" size="9.9999999999999995e-07 9.9999999999999995e-07 9.9999999999999995e-07" pos="0 0 1.8021408081054688"/>
    <body pos="0 0 1.8021408081054688" name="0/">
      <joint name="0/rootx/" class="/" type="slide" axis="1 0 0" limited="false" stiffness="0" armature="0" damping="0"/>
      <joint name="0/rootz/" class="/" type="slide" axis="0 0 1" limited="false" stiffness="0" armature="0" damping="0"/>
      <joint name="0/rooty/" class="/" type="hinge" axis="0 1 0" limited="false" stiffness="0" armature="0" damping="0"/>
      <geom name="0/geom" class="0/" type="capsule" contype="1" conaffinity="1" condim="3" size="0.065851725611316775" rgba="0.6019540935550195 0.99568438558844496 0.36886365825333745 1" friction="0.59999999999999998 0.10000000000000001 0.10000000000000001" fromto="0 0 0 0.57324181037046307 0 -0.63891196064317846"/>
      <site name="0/end0" class="0/" size="0.0050000000000000001" pos="0.57324181037046307 0 -0.63891196064317846"/>
      <site name="0/attach1" class="0/" size="9.9999999999999995e-07 9.9999999999999995e-07 9.9999999999999995e-07" pos="0.048553622168172522 0 -0.054115888573702017"/>
      <body pos="0.048553622168172522 0 -0.054115888573702017" name="0/1/">
        <geom name="0/1/geom" class="0/1/" type="capsule" contype="1" conaffinity="1" condim="3" size="0.05863857999323005" rgba="0.40826750355477448 0.5860958129753584 0.38000231579210364 1" friction="0.59999999999999998 0.10000000000000001 0.10000000000000001" fromto="0 0 0 -0.57698855295602103 0 -0.21161936681133997"/>
        <site name="0/1/end1" class="0/1/" size="0.0050000000000000001" pos="-0.57698855295602103 0 -0.21161936681133997"/>
      </body>
      <site name="0/attach2" class="0/" size="9.9999999999999995e-07 9.9999999999999995e-07 9.9999999999999995e-07" pos="0.12495833440234135 0 -0.13927346712569721"/>
      <body pos="0.12495833440234135 0 -0.13927346712569721" name="0/2/">
        <geom name="0/2/geom" class="0/2/" type="capsule" contype="1" conaffinity="1" condim="3" size="0.063342194159735077" rgba="0.057127197090376614 0.88608265648955342 0.69927034986747283 1" friction="0.59999999999999998 0.10000000000000001 0.10000000000000001" fromto="0 0 0 -0.64046988539078886 0 -0.60292031847234728"/>
        <site name="0/2/end2" class="0/2/" size="0.0050000000000000001" pos="-0.64046988539078886 0 -0.60292031847234728"/>
        <site name="0/2/attach3" class="0/2/" size="9.9999999999999995e-07 9.9999999999999995e-07 9.9999999999999995e-07" pos="-0.049724251586252897 0 -0.046809010518722952"/>
        <body pos="-0.049724251586252897 0 -0.046809010518722952" name="0/2/3/">
          <joint name="0/2/3/joint/" class="0/2/" type="hinge" axis="0 1 0" limited="true" stiffness="100" range="-59.941690648928159 59.941690648928159" armature="0.20000000000000001" damping="3.5"/>
          <geom name="0/2/3/geom" class="0/2/3/" type="capsule" contype="1" conaffinity="1" condim="3" size="0.058111059313510773" rgba="0.018622164176056555 0.46110052858841488 0.62867199897163439 1" friction="0.59999999999999998 0.10000000000000001 0.10000000000000001" fromto="0 0 0 0.21284350017727238 0 -0.27272755160864448"/>
          <site name="0/2/3/end3" class="0/2/3/" size="0.0050000000000000001" pos="0.21284350017727238 0 -0.27272755160864448"/>
        </body>
        <site name="0/2/attach4" class="0/2/" size="9.9999999999999995e-07 9.9999999999999995e-07 9.9999999999999995e-07" pos="-0.50736189490192851 0 -0.47761620371636559"/>
        <body pos="-0.50736189490192851 0 -0.47761620371636559" name="0/2/4/">
          <geom name="0/2/4/geom" class="0/2/4/" type="capsule" contype="1" conaffinity="1" condim="3" size="0.050581886589726309" rgba="0.66930291340979209 0.2900804461160511 0.69547163087870245 1" friction="0.59999999999999998 0.10000000000000001 0.10000000000000001" fromto="0 0 0 0.18336709362252002 0 -0.22919810278440722"/>
          <site name="0/2/4/end4" class="0/2/4/" size="0.0050000000000000001" pos="0.18336709362252002 0 -0.22919810278440722"/>
          <site name="0/2/4/attach5" class="0/2/4/" size="9.9999999999999995e-07 9.9999999999999995e-07 9.9999999999999995e-07" pos="0.097280068711953591 0 -0.12159437523406451"/>
          <body pos="0.097280068711953591 0 -0.12159437523406451" name="0/2/4/5/">
            <joint name="0/2/4/5/joint/" class="0/2/4/" type="hinge" axis="0 1 0" limited="true" stiffness="100" range="-30.851630416678589 30.851630416678589" armature="0.20000000000000001" damping="3.5"/>
            <geom name="0/2/4/5/geom" class="0/2/4/5/" type="capsule" contype="1" conaffinity="1" condim="3" size="0.059851430075905238" rgba="0.24486469644881703 0.053996056238573953 0.34454629749661303 1" friction="0.59999999999999998 0.10000000000000001 0.10000000000000001" fromto="0 0 0 -0.278529405283441 0 -0.27081865465926031"/>
            <site name="0/2/4/5/end5" class="0/2/4/5/" size="0.0050000000000000001" pos="-0.278529405283441 0 -0.27081865465926031"/>
          </body>
          <site name="0/2/4/attach6" class="0/2/4/" size="9.9999999999999995e-07 9.9999999999999995e-07 9.9999999999999995e-07" pos="0.14714508743587557 0 -0.18392272140046861"/>
          <body pos="0.14714508743587557 0 -0.18392272140046861" name="0/2/4/6/">
            <joint name="0/2/4/6/joint/" class="0/2/4/" type="hinge" axis="0 1 0" limited="true" stiffness="100" range="-55.4631684273754 55.4631684273754" armature="0.20000000000000001" damping="3.5"/>
            <geom name="0/2/4/6/geom" class="0/2/4/6/" type="capsule" contype="1" conaffinity="1" condim="3" size="0.067777650915159804" rgba="0.58383449954914357 0.30217313794177869 0.84662871061691491 1" friction="0.59999999999999998 0.10000000000000001 0.10000000000000001" fromto="0 0 0 0.15648806379634861 0 0.29098912886186667"/>
            <site name="0/2/4/6/end6" class="0/2/4/6/" size="0.0050000000000000001" pos="0.15648806379634861 0 0.29098912886186667"/>
          </body>
          <site name="0/2/4/attach7" class="0/2/4/" size="9.9999999999999995e-07 9.9999999999999995e-07 9.9999999999999995e-07" pos="0.058842446761664682 0 -0.073549604209409217"/>
          <body pos="0.058842446761664682 0 -0.073549604209409217" name="0/2/4/7/">
            <joint name="0/2/4/7/joint/" class="0/2/4/" type="hinge" axis="0 1 0" limited="true" stiffness="100" range="-66.903979340994908 66.903979340994908" armature="0.20000000000000001" damping="3.5"/>
            <geom name="0/2/4/7/geom" class="0/2/4/7/" type="capsule" contype="1" conaffinity="1" condim="3" size="0.062088985005766158" rgba="0.64746912686308333 0.86666117939615495 0.05012916720900551 1" friction="0.59999999999999998 0.10000000000000001 0.10000000000000001" fromto="0 0 0 -0.67636846614823454 0 -0.45580372100217081"/>
            <site name="0/2/4/7/end7" class="0/2/4/7/" size="0.0050000000000000001" pos="-0.67636846614823454 0 -0.45580372100217081"/>
            <site name="0/2/4/7/attach8" class="0/2/4/7/" size="9.9999999999999995e-07 9.9999999999999995e-07 9.9999999999999995e-07" pos="-0.51897546592176791 0 -0.34973680813814584"/>
            <body pos="-0.51897546592176791 0 -0.34973680813814584" name="0/2/4/7/8/">
              <geom name="0/2/4/7/8/geom" class="0/2/4/7/8/" type="capsule" contype="1" conaffinity="1" condim="3" size="0.054770768214851384" rgba="0.49608130560395436 0.14454879992179304 0.067662999604651941 1" friction="0.59999999999999998 0.10000000000000001 0.10000000000000001" fromto="0 0 0 0.30628277155290751 0 -0.66196467602071474"/>
              <site name="0/2/4/7/8/end8" class="0/2/4/7/8/" size="0.0050000000000000001" pos="0.30628277155290751 0 -0.66196467602071474"/>
            </body>
            <site name="0/2/4/7/attach9" class="0/2/4/7/" size="9.9999999999999995e-07 9.9999999999999995e-07 9.9999999999999995e-07" pos="-0.34209782669204669 0 -0.23053922552151737"/>
            <body pos="-0.34209782669204669 0 -0.23053922552151737" name="0/2/4/7/9/">
              <joint name="0/2/4/7/9/joint/" class="0/2/4/7/" type="hinge" axis="0 1 0" limited="true" stiffness="100" range="-47.139952930442973 47.139952930442973" armature="0.20000000000000001" damping="3.5"/>
              <geom name="0/2/4/7/9/geom" class="0/2/4/7/9/" type="capsule" contype="1" conaffinity="1" condim="3" size="0.059862544625413475" rgba="0.63383371535525834 0.18812340155941831 0.64974444021276223 1" friction="0.59999999999999998 0.10000000000000001 0.10000000000000001" fromto="0 0 0 -0.38249848362548422 0 0.56471997565752607"/>
              <site name="0/2/4/7/9/end9" class="0/2/4/7/9/" size="0.0050000000000000001" pos="-0.38249848362548422 0 0.56471997565752607"/>
            </body>
            <site name="0/2/4/7/attach10" class="0/2/4/7/" size="9.9999999999999995e-07 9.9999999999999995e-07 9.9999999999999995e-07" pos="-0.45701446998469164 0 -0.30798138351589543"/>
            <body pos="-0.45701446998469164 0 -0.30798138351589543" name="0/2/4/7/10/">
              <joint name="0/2/4/7/10/joint/" class="0/2/4/7/" type="hinge" axis="0 1 0" limited="true" stiffness="100" range="-65.758562854737519 65.758562854737519" armature="0.20000000000000001" damping="3.5"/>
              <geom name="0/2/4/7/10/geom" class="0/2/4/7/10/" type="capsule" contype="1" conaffinity="1" condim="3" size="0.045604928298508075" rgba="0.2616517210911542 0.61661112882642177 0.33358703404627232 1" friction="0.59999999999999998 0.10000000000000001 0.10000000000000001" fromto="0 0 0 -0.4829713792358829 0 0.14396747833721513"/>
              <site name="0/2/4/7/10/end10" class="0/2/4/7/10/" size="0.0050000000000000001" pos="-0.4829713792358829 0 0.14396747833721513"/>
            </body>
          </body>
        </body>
      </body>
      <camera name="0/side" class="0/" mode="trackcom" pos="0.40000000000000002 -4 0.20000000000000001" quat="0.70699999999999996 0.70699999999999996 0 0"/>
    </body>
  </worldbody>
  <actuator>
    <motor name="0/2/3/motor" class="0/2/3/" ctrllimited="true" ctrlrange="-1 1" gear="82" joint="0/2/3/joint/"/>
    <motor name="0/2/4/5/motor" class="0/2/4/5/" ctrllimited="true" ctrlrange="-1 1" gear="85" joint="0/2/4/5/joint/"/>
    <motor name="0/2/4/6/motor" class="0/2/4/6/" ctrllimited="true" ctrlrange="-1 1" gear="84" joint="0/2/4/6/joint/"/>
    <motor name="0/2/4/7/motor" class="0/2/4/7/" ctrllimited="true" ctrlrange="-1 1" gear="50" joint="0/2/4/7/joint/"/>
    <motor name="0/2/4/7/9/motor" class="0/2/4/7/9/" ctrllimited="true" ctrlrange="-1 1" gear="55" joint="0/2/4/7/9/joint/"/>
    <motor name="0/2/4/7/10/motor" class="0/2/4/7/10/" ctrllimited="true" ctrlrange="-1 1" gear="70" joint="0/2/4/7/10/joint/"/>
  </actuator>
  <sensor>
    <subtreelinvel name="velocity" body="0/"/>
  </sensor>
</mujoco>
